[{"op": "mcm", "id": 1, "initialClk": "oBze7/i+Dq4c34iDzA6lHPT518UO", "clk": "AAAAAAAA", "conflateMs": 0, "heartbeatMs": 5000, "pt": 1627622269330, "ct": "SUB_IMAGE", "mc": [{"id": "1.185781621", "marketDefinition": {"bspMarket": true, "turnInPlayEnabled": true, "persistenceEnabled": true, "marketBaseRate": 8, "eventId": "30738609", "eventTypeId": "7", "numberOfWinners": 1, "bettingType": "ODDS", "marketType": "WIN", "marketTime": "2021-07-30T05:23:00.000Z", "suspendTime": "2021-07-30T05:23:00.000Z", "bspReconciled": false, "complete": true, "inPlay": false, "crossMatching": true, "runnersVoidable": false, "numberOfActiveRunners": 10, "betDelay": 0, "status": "OPEN", "runners": [{"adjustmentFactor": 23.981, "status": "ACTIVE", "sortPriority": 1, "id": 40186660}, {"adjustmentFactor": 37.461, "status": "ACTIVE", "sortPriority": 2, "id": 35523828}, {"adjustmentFactor": 3.559, "status": "ACTIVE", "sortPriority": 3, "id": 22347731}, {"adjustmentFactor": 9.699, "status": "ACTIVE", "sortPriority": 4, "id": 642078}, {"adjustmentFactor": 3.798, "status": "ACTIVE", "sortPriority": 5, "id": 38139235}, {"adjustmentFactor": 3.559, "status": "ACTIVE", "sortPriority": 6, "id": 26422127}, {"adjustmentFactor": 3.263, "status": "ACTIVE", "sortPriority": 7, "id": 24517142}, {"adjustmentFactor": 4.065, "status": "ACTIVE", "sortPriority": 8, "id": 22153142}, {"adjustmentFactor": 7.353, "status": "ACTIVE", "sortPriority": 9, "id": 15424563}, {"adjustmentFactor": 3.263, "status": "ACTIVE", "sortPriority": 10, "id": 1117014}], "regulators": ["MR_INT"], "venue": "Wagga", "countryCode": "AU", "discountAllowed": true, "timezone": "Australia/Sydney", "openDate": "2021-07-30T03:03:00.000Z", "version": 3938470450, "raceType": "Flat", "priceLadderDefinition": {"type": "CLASSIC"}}, "rc": [{"atb": [[19.5, 2.12], [19, 3.31], [18.5, 2.43], [18, 0.48], [17.5, 21.21], [4.5, 36], [11, 1.01], [2.62, 83.33], [4.2, 54.69], [1.03, 1.09], [15.5, 1.84], [8.2, 7.4], [6.2, 10.24], [10.5, 2.8], [5.1, 25.97], [1.01, 146.31], [3.5, 4.4], [1.2, 122], [1.14, 2]], "atl": [[32, 1], [34, 2.65], [29, 1.06], [26, 1.27], [170, 2], [36, 0.24], [38, 3], [400, 0.51], [100, 1.37], [200, 0.68], [300, 0.68], [800, 0.18], [900, 1.59], [440, 0.07], [690, 0.03]], "trd": [[19, 2.12], [15.5, 4.06], [13, 1.32], [12.5, 1.3], [19.5, 0.04], [16, 2.77], [22, 0.08]], "spb": [[1000, 181.14]], "batb": [[0, 19.5, 2.12], [9, 5.1, 25.97], [8, 6.2, 10.24], [7, 8.2, 7.4], [6, 10.5, 2.8], [5, 11, 1.01], [4, 15.5, 1.84], [3, 17.5, 21.69], [2, 18.5, 2.43], [1, 19, 3.31]], "batl": [[8, 900, 2.38], [7, 300, 1.36], [6, 170, 2], [5, 100, 1.37], [4, 38, 3.24], [3, 34, 2.65], [2, 32, 1], [1, 29, 1.06], [0, 26, 1.27]], "tv": 11.69, "id": 26422127}, {"atb": [[20, 4], [18, 2.89], [19.5, 5], [1.04, 1.72], [18.5, 0.84], [4.2, 89.69], [17.5, 21.19], [2.62, 83.33], [16.5, 1.92], [6.6, 10.63], [11.5, 2.83], [5.3, 27.69], [8.6, 7.84], [1.03, 1.09], [14, 0.78], [1.01, 146.31], [3.5, 4.4], [1.2, 122], [1.14, 2]], "atl": [[32, 2.65], [29, 1], [30, 1.55], [200, 2], [110, 1.18], [210, 0.61], [410, 0.47], [310, 0.63], [800, 0.18], [55, 2], [900, 0.79], [440, 0.07], [690, 0.03]], "trd": [[22, 0.98], [19.5, 1.64], [19, 1.64]], "spb": [[1000, 143.24]], "spl": [[1.01, 9.01]], "batb": [[0, 20, 4], [9, 4.2, 89.69], [8, 5.3, 27.69], [7, 6.6, 10.63], [6, 8.6, 7.84], [5, 11.5, 3.61], [4, 16.5, 1.92], [3, 17.5, 21.19], [2, 18, 3.73], [1, 19.5, 5]], "batl": [[2, 32, 2.65], [7, 900, 1.54], [6, 310, 1.24], [5, 200, 2], [4, 110, 1.18], [3, 55, 2], [1, 30, 1.55], [0, 29, 1]], "tv": 4.26, "id": 22347731}, {"atb": [[6.8, 26], [17, 0.49], [11, 1.01], [16.5, 0.26], [14, 2.29], [9.8, 2.65], [16, 21.19], [2.62, 83.33], [4.2, 54.69], [7.6, 9.02], [5.8, 12.4], [9.6, 3.46], [4.8, 31.33], [1.01, 146.31], [1.03, 1.09], [2.98, 5.55], [1.2, 122], [1.14, 2]], "atl": [[27, 1], [23, 1.27], [26, 0.32], [25, 1.06], [28, 2.65], [29, 5], [160, 2], [390, 0.5], [95, 1.37], [190, 0.68], [290, 0.67], [800, 0.18], [900, 0.53], [690, 0.03]], "trd": [[18, 12.93], [17, 0.8], [20, 1.08], [19, 1.7], [15.5, 0.1], [18.5, 1.16], [21, 0.08]], "spb": [[1000, 182.01]], "batb": [[9, 4.2, 54.69], [8, 4.8, 31.33], [7, 5.8, 12.4], [6, 6.8, 26], [5, 7.6, 9.02], [4, 9.6, 3.46], [3, 9.8, 2.65], [2, 11, 1.01], [1, 14, 2.29], [0, 16, 21.94]], "batl": [[8, 900, 1.24], [7, 290, 1.35], [6, 160, 2], [5, 95, 1.37], [4, 29, 5], [3, 28, 2.65], [2, 27, 1.32], [0, 23, 1.27], [1, 25, 1.06]], "tv": 17.85, "id": 22153142}, {"atb": [[22, 15.89], [23, 2.84], [13, 2.26], [9.2, 6.62], [18, 1.59], [7.2, 8.75], [5.6, 23.6], [25, 3.72], [24, 2.78], [2.62, 83.33], [4.2, 54.69], [1.01, 146.31], [21, 0.02], [19, 0.8], [20, 0.54], [3.85, 3.86], [1.03, 1.09], [1.2, 122], [1.14, 2]], "atl": [[260, 2], [40, 3.65], [250, 0.54], [450, 0.45], [350, 0.58], [42, 2], [150, 2.93], [34, 1.27], [38, 0.25], [900, 0.53], [690, 0.03]], "trd": [[16.5, 3.19], [22, 0.98], [19.5, 0.91], [19, 5.59]], "spb": [[1000, 182.86]], "batb": [[9, 5.6, 23.6], [3, 22, 15.89], [8, 7.2, 8.75], [7, 9.2, 6.62], [6, 13, 2.26], [5, 18, 1.59], [4, 19, 1.36], [2, 23, 2.84], [1, 24, 2.78], [0, 25, 3.72]], "batl": [[6, 900, 0.56], [5, 450, 1.03], [4, 260, 2.54], [3, 150, 2.93], [1, 40, 3.9], [2, 42, 2], [0, 34, 1.27]], "tv": 10.67, "id": 24517142}, {"atb": [[25, 2], [23, 0.37], [24, 4.37], [21, 2.71], [20, 7.95], [4, 34], [27, 0.27], [1.03, 1.09], [2.62, 83.33], [4.2, 54.69], [17.5, 7.95], [15.5, 2.05], [8.2, 8.27], [6.2, 11.45], [10.5, 3.13], [5.1, 29.04], [19, 0.02], [19.5, 0.02], [1.01, 146.31], [3.55, 4.31], [1.2, 122], [1.14, 2]], "atl": [[65, 1.5], [70, 2.06], [75, 3.06], [38, 0.22], [280, 4], [400, 0.49], [100, 1.3], [200, 0.65], [300, 0.65], [130, 2], [36, 1.27], [800, 0.18], [310, 0.07], [690, 0.03]], "trd": [[21, 1.02], [17.5, 1.72], [17, 2.64]], "spb": [[1000, 183.01]], "spl": [[1.01, 7.95]], "batb": [[2, 21, 3.08], [1, 24, 4.37], [0, 25, 2.27], [9, 5.1, 29.04], [8, 6.2, 11.45], [7, 8.2, 8.27], [6, 10.5, 3.13], [5, 15.5, 2.05], [4, 17.5, 7.99], [3, 20, 7.95]], "batl": [[3, 75, 3.06], [2, 70, 2.06], [1, 65, 1.72], [8, 800, 0.21], [7, 400, 1.21], [6, 280, 4.65], [5, 130, 2], [4, 100, 1.3], [0, 36, 1.27]], "tv": 5.38, "id": 38139235}, {"atb": [[24, 2.96], [1.03, 1.09], [25, 0.29], [26, 3.72], [23, 2.21], [4.5, 35], [22, 16.25], [4.2, 54.69], [2.62, 83.33], [13, 2.48], [9.2, 7.26], [18, 1.75], [7.2, 9.6], [5.6, 25.88], [19.5, 0.02], [1.01, 146.31], [19, 0.8], [3.85, 3.86], [1.2, 122], [1.14, 2]], "atl": [[55, 0.2], [40, 3.33], [42, 2], [46, 2], [60, 0.41], [270, 2], [250, 0.52], [450, 0.43], [350, 0.56], [150, 0.86], [800, 0.18], [75, 2], [900, 0.79], [690, 0.03]], "trd": [[22, 0.26]], "spb": [[1000, 144.89]], "batb": [[1, 24, 3.25], [0, 26, 3.72], [9, 4.5, 35], [8, 5.6, 25.88], [7, 7.2, 9.6], [6, 9.2, 7.26], [5, 13, 2.48], [4, 18, 2.57], [3, 22, 16.25], [2, 23, 2.21]], "batl": [[7, 900, 0.97], [6, 690, 1.02], [5, 270, 2], [4, 250, 1.38], [3, 75, 2.61], [0, 40, 3.33], [2, 46, 2], [1, 42, 2]], "tv": 0.26, "id": 1117014}, {"atb": [[7.8, 3.44], [7.6, 3.09], [7, 31.97], [2.2, 45], [3.5, 23.81], [6, 7.95], [3, 59.53], [5, 7.44], [4, 19.85], [2.62, 83.33], [7.2, 3.8], [6.6, 2.28], [1.01, 146.31], [1.14, 2], [5.4, 0.8], [2.28, 8.59], [1.03, 1.09], [1.2, 122]], "atl": [[12, 2.83], [11.5, 3.19], [12.5, 0.16], [8.8, 1.06], [9.4, 1.28], [13, 5.07], [10, 0.22], [11, 0.21], [10.5, 0.22], [24, 5.61], [38, 3.49], [70, 2.8], [140, 1.39], [150, 2], [18, 0.48], [19, 0.07], [460, 0.01], [800, 0.18], [690, 0.03]], "trd": [[7.4, 21.19], [7.2, 5.69], [6.2, 4.06], [7, 2.09], [6.8, 4.43], [7.6, 0.08]], "spb": [[1000, 135.47]], "batb": [[0, 7.8, 3.44], [1, 7.6, 3.09], [9, 3, 59.53], [8, 3.5, 23.81], [7, 4, 19.85], [6, 5, 8.24], [5, 6, 7.95], [4, 6.6, 2.28], [3, 7, 31.97], [2, 7.2, 3.8]], "batl": [[3, 12, 2.83], [2, 11.5, 3.84], [9, 150, 2], [8, 140, 1.39], [7, 70, 2.8], [6, 38, 3.49], [5, 24, 6.16], [4, 13, 5.23], [1, 9.4, 1.28], [0, 8.8, 1.06]], "tv": 37.54, "id": 642078}, {"atb": [[3.1, 2.06], [1.01, 148.96], [2.56, 1.68], [3.05, 5.58], [1.2, 122], [2.86, 31.79], [2.94, 3.15], [2.9, 0.3], [1.03, 5.43], [3, 10.6], [2.12, 106.3], [2.52, 39.17], [2.32, 45.1], [2.92, 15.5], [2.72, 17.31], [2.5, 0.53], [2.38, 7.97], [1.14, 2]], "atl": [[3.6, 5.64], [3.7, 0.04], [3.55, 1], [3.65, 5.66], [3.75, 0.27], [90, 0.05], [9, 16], [9.2, 15.73], [34, 16.5], [17, 11.5], [3.8, 32.05], [13, 16.12], [18, 11.38], [7.2, 20.8], [6.8, 0.04], [6.4, 2.65], [6.6, 15.89], [6, 1.42], [7.4, 0.07], [900, 1.59], [690, 0.03]], "trd": [[3.4, 7.42], [3.7, 46.5], [4.2, 51.9], [3.35, 8.48], [3.3, 58.02], [3.45, 4]], "spb": [[1000, 107.49]], "spl": [[1.01, 39.73]], "batb": [[9, 2.38, 8.5], [8, 2.52, 39.17], [7, 2.56, 1.68], [6, 2.72, 17.31], [5, 2.86, 32.09], [4, 2.92, 15.5], [3, 2.94, 3.15], [2, 3, 10.6], [1, 3.05, 5.58], [0, 3.1, 2.06]], "batl": [[1, 3.6, 5.64], [9, 9.2, 15.73], [8, 9, 16.07], [7, 7.2, 20.84], [6, 6.6, 15.89], [5, 6.4, 2.65], [4, 6, 1.42], [3, 3.8, 32.36], [2, 3.65, 5.66], [0, 3.55, 1]], "tv": 176.32, "id": 40186660}, {"atb": [[13, 3.27], [12.5, 2.75], [13.5, 0.24], [11.5, 3.02], [8.8, 21.19], [3.5, 52.02], [6, 5.95], [5, 14.88], [4, 19.85], [8, 4.25], [6.6, 25], [2.62, 83.33], [4.2, 54.69], [1.03, 1.09], [1.01, 146.31], [11, 28.61], [10.5, 1.02], [9.6, 0.02], [1.2, 122], [1.14, 2]], "atl": [[26, 1.27], [27, 1], [17, 0.18], [16, 0.18], [16.5, 0.18], [17.5, 0.17], [28, 2.65], [18, 0.17], [19, 0.2], [250, 0.78], [40, 3.31], [75, 1.74], [150, 1.3], [18.5, 0.16], [110, 2], [20, 0.18], [22, 0.17], [29, 2], [34, 0.25], [800, 0.18], [900, 1.32], [690, 0.03]], "trd": [[15.5, 0.94], [15, 4], [12.5, 21.19], [10.5, 0.08]], "spb": [[1000, 141.97]], "spl": [[1.01, 2.65]], "batb": [[0, 13, 3.51], [1, 12.5, 2.75], [9, 5, 14.88], [8, 6, 5.95], [7, 6.6, 25], [6, 8, 4.25], [5, 8.8, 21.21], [4, 10.5, 1.02], [3, 11, 28.61], [2, 11.5, 3.02]], "batl": [[9, 900, 2.31], [8, 150, 1.3], [7, 110, 2], [6, 75, 1.74], [5, 40, 3.56], [4, 29, 2], [3, 28, 2.65], [2, 27, 1], [1, 26, 1.82], [0, 18.5, 1.04]], "tv": 26.21, "id": 15424563}, {"atb": [[2.8, 1.72], [1.91, 21.19], [2.72, 6.5], [2.68, 0.12], [2.78, 0.31], [2.5, 69.23], [1.03, 5.43], [1.65, 91.58], [1.75, 79.37], [1.95, 31.33], [1.85, 83.02], [1.55, 216.47], [1.01, 146.31], [1.86, 10.6], [2.7, 13.24], [1.84, 252.27], [2.14, 13], [2.02, 2], [1.02, 233], [2.4, 0.17], [1.33, 33.33], [1.92, 5.76], [1.14, 2]], "atl": [[3.5, 1.07], [3.55, 1.73], [4.5, 2.65], [3.65, 5.3], [4.4, 1.14], [8.6, 18], [4.6, 35.82], [9.2, 23.59], [7.2, 31.2], [5.6, 28.04], [6.8, 0.04], [34, 16.5], [17, 11.5], [4, 2.13], [900, 1.06], [690, 0.03]], "trd": [[2.76, 5.24], [2.74, 2.18], [2.5, 4]], "spb": [[1000, 206.42]], "spl": [[1.01, 2.65]], "batb": [[9, 1.86, 10.6], [8, 1.91, 21.19], [7, 1.92, 5.76], [6, 1.95, 31.33], [5, 2.02, 2], [4, 2.14, 13.17], [3, 2.5, 69.35], [2, 2.7, 13.24], [1, 2.72, 6.81], [0, 2.8, 1.72]], "batl": [[9, 8.6, 18], [8, 7.2, 31.24], [7, 5.6, 28.04], [6, 4.6, 35.82], [5, 4.5, 2.65], [4, 4.4, 1.14], [3, 4, 2.13], [2, 3.65, 5.3], [1, 3.55, 1.73], [0, 3.5, 1.07]], "tv": 11.42, "id": 35523828}], "img": true, "tv": 301.6}, {"id": "1.185781627", "marketDefinition": {"bspMarket": true, "turnInPlayEnabled": true, "persistenceEnabled": true, "marketBaseRate": 8, "eventId": "30738609", "eventTypeId": "7", "numberOfWinners": 1, "bettingType": "ODDS", "marketType": "WIN", "marketTime": "2021-07-30T07:17:00.000Z", "suspendTime": "2021-07-30T07:17:00.000Z", "bspReconciled": false, "complete": true, "inPlay": false, "crossMatching": true, "runnersVoidable": false, "numberOfActiveRunners": 9, "betDelay": 0, "status": "OPEN", "runners": [{"adjustmentFactor": 0.448, "status": "ACTIVE", "sortPriority": 1, "id": 11415554}, {"adjustmentFactor": 34.799, "status": "ACTIVE", "sortPriority": 2, "id": 2549443}, {"adjustmentFactor": 7.112, "status": "ACTIVE", "sortPriority": 3, "id": 15586698}, {"adjustmentFactor": 6.632, "status": "ACTIVE", "sortPriority": 4, "id": 22361359}, {"adjustmentFactor": 13.328, "status": "ACTIVE", "sortPriority": 5, "id": 20486363}, {"adjustmentFactor": 4.708, "status": "ACTIVE", "sortPriority": 6, "id": 11565397}, {"adjustmentFactor": 3.148, "status": "ACTIVE", "sortPriority": 7, "id": 9675899}, {"adjustmentFactor": 3.148, "status": "ACTIVE", "sortPriority": 8, "id": 18426145}, {"adjustmentFactor": 26.678, "status": "ACTIVE", "sortPriority": 9, "id": 27932766}], "regulators": ["MR_INT"], "venue": "Wagga", "countryCode": "AU", "discountAllowed": true, "timezone": "Australia/Sydney", "openDate": "2021-07-30T03:03:00.000Z", "version": 3938310116, "raceType": "Flat", "priceLadderDefinition": {"type": "CLASSIC"}}, "rc": [{"atb": [[27, 0.39], [13.5, 0.53], [9.4, 0.46], [1.01, 146.31], [5.6, 25.57], [13, 2.45], [9.2, 7.17], [18, 1.73], [7.2, 9.48], [1.2, 122], [1.14, 2]], "atl": [[430, 2], [250, 0.52], [450, 0.43], [350, 0.56], [150, 0.87], [440, 0.07], [690, 0.03]], "spl": [[1.01, 7.95]], "batb": [[7, 1.01, 146.31], [6, 1.14, 2], [5, 1.2, 122], [4, 5.6, 25.57], [0, 18, 2.12], [1, 13, 2.98], [2, 9.2, 7.63], [3, 7.2, 9.48]], "batl": [[2, 690, 0.53], [1, 430, 2.56], [0, 250, 1.39]], "id": 11565397}, {"atb": [[14.5, 0.75], [11.5, 5.72], [3.9, 40.55], [7.6, 4.46], [5.8, 12.25], [4.8, 15.47], [9.6, 3.42], [1.21, 3.56], [1.01, 146.31], [1.2, 122], [1.14, 2]], "atl": [[60, 2], [230, 0.85], [330, 0.59], [130, 1], [65, 2.02], [300, 0.07], [900, 1.06], [690, 0.03]], "spl": [[1.01, 2.65]], "batb": [[9, 1.01, 146.31], [8, 1.14, 2], [7, 1.2, 122], [6, 1.21, 3.56], [5, 3.9, 40.55], [0, 11.5, 6.47], [4, 4.8, 15.47], [3, 5.8, 12.25], [2, 7.6, 4.46], [1, 9.6, 3.42]], "batl": [[4, 900, 1.09], [3, 330, 1.51], [2, 130, 1], [1, 65, 2.02], [0, 60, 2]], "id": 22361359}, {"atb": [[55, 0.2], [15.5, 4.06], [8.2, 16.33], [10.5, 6.19], [21, 1.47], [32, 0.95], [1.21, 3.56], [16, 0.44], [1.01, 146.31], [1.2, 122], [1.14, 2]], "atl": [[500, 0.39], [400, 0.32], [300, 0.43], [600, 0.39], [690, 0.03]], "batb": [[8, 1.01, 146.31], [7, 1.14, 2], [6, 1.2, 122], [5, 1.21, 3.56], [4, 8.2, 16.33], [3, 10.5, 6.19], [2, 15.5, 4.5], [1, 21, 1.47], [0, 32, 1.15]], "batl": [[1, 690, 0.42], [0, 500, 1.14]], "id": 9675899}, {"atb": [[36, 0.3], [1.01, 146.31], [8.4, 7.95], [11, 5.88], [22, 1.4], [6.4, 21.78], [16, 1.96], [1.21, 3.56], [11.5, 0.62], [1.2, 122], [1.14, 2]], "atl": [[500, 0.39], [400, 0.49], [200, 0.65], [300, 0.43], [690, 0.03]], "batb": [[8, 1.01, 146.31], [7, 1.14, 2], [6, 1.2, 122], [5, 1.21, 3.56], [4, 6.4, 21.78], [0, 22, 1.7], [3, 8.4, 7.95], [2, 11, 6.5], [1, 16, 1.96]], "batl": [[1, 690, 0.91], [0, 300, 1.08]], "id": 11415554}, {"atb": [[27, 0.39], [13.5, 0.53], [9.4, 0.46], [1.01, 146.31], [5.6, 25.57], [13, 2.45], [9.2, 7.17], [18, 1.73], [7.2, 9.48], [1.2, 122], [1.14, 2]], "atl": [[440, 2], [250, 0.52], [450, 0.43], [350, 0.56], [150, 0.87], [900, 0.79], [690, 0.03]], "batb": [[7, 1.01, 146.31], [6, 1.14, 2], [5, 1.2, 122], [4, 5.6, 25.57], [0, 18, 2.12], [1, 13, 2.98], [2, 9.2, 7.63], [3, 7.2, 9.48]], "batl": [[2, 900, 1.25], [1, 440, 2.56], [0, 250, 1.39]], "id": 15586698}, {"atb": [[1.03, 5.43], [1.56, 2], [1.42, 7.05], [1.41, 3.06], [1.1, 588.05], [1.3, 98.01], [1.21, 34.16], [1.01, 11907.28], [1.2, 294.02], [1.4, 73.51], [1.14, 2]], "atl": [[2.52, 2.65], [3.5, 77.62], [2.6, 80.86], [3, 97.03], [85, 5], [70, 42.38], [2.8, 71.87], [690, 0.03]], "spl": [[1.01, 108.6], [1.4, 92.71]], "batb": [[9, 1.03, 5.43], [8, 1.1, 588.05], [7, 1.14, 2], [6, 1.2, 294.02], [5, 1.21, 34.16], [4, 1.3, 98.01], [3, 1.4, 73.51], [2, 1.41, 3.06], [1, 1.42, 7.05], [0, 1.56, 2]], "batl": [[7, 690, 0.03], [6, 85, 5], [5, 70, 42.38], [4, 3.5, 77.62], [3, 3, 97.03], [2, 2.8, 71.87], [1, 2.6, 80.86], [0, 2.52, 2.65]], "id": 2549443}, {"atb": [[27, 0.39], [13.5, 0.53], [9.4, 0.46], [1.01, 146.31], [5.6, 25.57], [13, 2.45], [9.2, 7.17], [18, 1.73], [7.2, 9.48], [1.2, 122], [1.14, 2]], "atl": [[430, 2], [250, 0.52], [450, 0.43], [350, 0.56], [150, 0.87], [440, 0.07], [900, 0.79], [690, 0.03]], "batb": [[7, 1.01, 146.31], [6, 1.14, 2], [5, 1.2, 122], [4, 5.6, 25.57], [0, 18, 2.12], [1, 13, 2.98], [2, 9.2, 7.63], [3, 7.2, 9.48]], "batl": [[2, 900, 1.32], [1, 430, 2.56], [0, 250, 1.39]], "id": 18426145}, {"atb": [[5.1, 2], [3.95, 2.9], [1.01, 146.31], [2.56, 75.39], [2.76, 33.41], [2.96, 30], [3.9, 10.14], [3.4, 12.25], [1.2, 122], [1.14, 2]], "atl": [[26, 7.76], [13, 10.78], [42, 4.73], [18, 7.61], [15, 0.07], [900, 0.79], [690, 0.03]], "batb": [[9, 1.01, 146.31], [8, 1.14, 2], [7, 1.2, 122], [6, 2.56, 75.39], [5, 2.76, 33.41], [4, 2.96, 30], [3, 3.4, 12.25], [2, 3.9, 10.14], [1, 3.95, 2.9], [0, 5.1, 2]], "batl": [[4, 900, 0.82], [3, 42, 4.73], [2, 26, 7.76], [1, 18, 7.68], [0, 13, 10.78]], "id": 20486363}, {"atb": [[1.03, 5.43], [3.15, 2.27], [2.84, 15.98], [2.44, 40.83], [2.64, 35.86], [3.1, 14], [2.24, 94.85], [3.65, 1.18], [1.01, 146.31], [1.2, 122], [1.14, 2]], "atl": [[14.5, 14.37], [7.8, 19.02], [9.8, 14.7], [19.5, 10.49], [4, 0.08], [12, 0.07], [900, 2.65], [690, 0.03]], "trd": [[4, 105.79]], "spl": [[1.01, 9.01]], "batb": [[9, 1.03, 5.43], [8, 1.14, 2], [7, 1.2, 122], [6, 2.24, 94.85], [5, 2.44, 40.83], [4, 2.64, 35.86], [3, 2.84, 15.98], [2, 3.1, 14], [1, 3.15, 2.27], [0, 3.65, 1.18]], "batl": [[4, 900, 2.68], [3, 19.5, 10.49], [2, 14.5, 14.44], [1, 9.8, 14.7], [0, 7.8, 19.1]], "tv": 105.79, "id": 27932766}], "img": true, "tv": 105.79}, {"id": "1.185793026", "marketDefinition": {"bspMarket": true, "turnInPlayEnabled": true, "persistenceEnabled": true, "marketBaseRate": 6, "eventId": "30739215", "eventTypeId": "7", "numberOfWinners": 1, "bettingType": "ODDS", "marketType": "WIN", "marketTime": "2021-07-30T11:35:00.000Z", "suspendTime": "2021-07-30T11:35:00.000Z", "bspReconciled": false, "complete": true, "inPlay": false, "crossMatching": true, "runnersVoidable": false, "numberOfActiveRunners": 12, "betDelay": 0, "status": "OPEN", "runners": [{"adjustmentFactor": 1.383, "status": "ACTIVE", "sortPriority": 1, "id": 20587387}, {"adjustmentFactor": 3.676, "status": "ACTIVE", "sortPriority": 2, "id": 9291105}, {"adjustmentFactor": 1.383, "status": "ACTIVE", "sortPriority": 3, "id": 12291589}, {"adjustmentFactor": 3.676, "status": "ACTIVE", "sortPriority": 4, "id": 12446287}, {"adjustmentFactor": 4.628, "status": "ACTIVE", "sortPriority": 5, "id": 17311025}, {"adjustmentFactor": 3.676, "status": "ACTIVE", "sortPriority": 6, "id": 255502}, {"adjustmentFactor": 6.6, "status": "ACTIVE", "sortPriority": 7, "id": 11274440}, {"adjustmentFactor": 22.494, "status": "ACTIVE", "sortPriority": 8, "id": 28368765}, {"adjustmentFactor": 3.676, "status": "ACTIVE", "sortPriority": 9, "id": 10446588}, {"adjustmentFactor": 3.676, "status": "ACTIVE", "sortPriority": 10, "id": 40363511}, {"adjustmentFactor": 23.823, "status": "ACTIVE", "sortPriority": 11, "id": 12862911}, {"adjustmentFactor": 21.305, "status": "ACTIVE", "sortPriority": 12, "id": 25357177}, {"adjustmentFactor": 1.364, "status": "REMOVED", "sortPriority": 13, "removalDate": "2021-07-29T22:58:33.000Z", "id": 19583078}], "regulators": ["MR_INT"], "venue": "Ballarat", "countryCode": "AU", "discountAllowed": true, "timezone": "Australia/Sydney", "openDate": "2021-07-30T08:30:00.000Z", "version": 3938290766, "raceType": "Flat", "priceLadderDefinition": {"type": "CLASSIC"}}, "rc": [{"atb": [[2.56, 4.6], [2.3, 253.8], [2.5, 109.98], [1.01, 156.31], [2.4, 176.75], [2.6, 51.55], [2.62, 2.74], [1.14, 2]], "atl": [[5.5, 2], [9.2, 23.69], [5.6, 28.15], [7.2, 20.88], [13, 16.18], [690, 0.03]], "spl": [[5.4, 5.83]], "batb": [[7, 1.01, 156.31], [6, 1.14, 2], [5, 2.3, 253.8], [4, 2.4, 176.75], [3, 2.5, 109.98], [2, 2.56, 4.6], [1, 2.6, 51.55], [0, 2.62, 2.74]], "batl": [[5, 690, 0.03], [4, 13, 16.18], [3, 9.2, 23.69], [2, 7.2, 20.88], [1, 5.6, 28.15], [0, 5.5, 2]], "id": 12862911}, {"atb": [[46, 5.5], [90, 0.93], [36, 9.42], [65, 2.58], [1.01, 156.31], [44, 0.16], [1.14, 2]], "atl": [[880, 0.22], [780, 0.25], [680, 0.19], [580, 0.22], [690, 0.03]], "batb": [[4, 1.01, 156.31], [3, 1.14, 2], [2, 36, 9.58], [1, 46, 5.5], [0, 65, 3.51]], "batl": [[0, 880, 0.91]], "id": 10446588}, {"atb": [[1.01, 156.31], [15.5, 11.38], [13, 20.62], [10.5, 34.73], [18, 4.85], [17, 3.72], [18.5, 0.39], [1.14, 2]], "atl": [[440, 0.07], [400, 0.49], [200, 0.65], [100, 1.31], [300, 0.65], [690, 0.03]], "spl": [[1.01, 7.95]], "batb": [[6, 1.01, 156.31], [4, 10.5, 34.73], [3, 13, 20.62], [2, 15.5, 11.38], [5, 1.14, 2], [1, 17, 3.72], [0, 18, 5.24]], "batl": [[2, 690, 0.59], [1, 300, 1.3], [0, 100, 1.31]], "id": 9291105}, {"atb": [[6.8, 1.23], [1.01, 156.31], [6.6, 29.46], [7.6, 12.5], [5.3, 76.73], [5.8, 51.55], [8, 3.72], [14, 0.51], [1.14, 2]], "atl": [[28, 4.79], [46, 2.88], [180, 1.09], [90, 2.18], [170, 0.07], [690, 0.03]], "batb": [[7, 1.01, 156.31], [6, 1.14, 2], [5, 5.3, 76.73], [4, 5.8, 51.55], [3, 6.6, 29.46], [2, 6.8, 1.23], [1, 7.6, 12.5], [0, 8, 4.23]], "batl": [[4, 690, 0.03], [3, 180, 1.16], [2, 90, 2.18], [1, 46, 2.88], [0, 28, 4.79]], "id": 12291589}, {"atb": [[46, 0.16], [60, 1.4], [27, 12.69], [44, 3.84], [34, 7.5], [1.01, 156.31], [1.14, 2]], "atl": [[460, 0.28], [360, 0.36], [660, 0.3], [560, 0.35], [600, 0.07], [690, 0.03]], "batb": [[1, 44, 4], [5, 1.01, 156.31], [2, 34, 7.5], [4, 1.14, 2], [3, 27, 12.69], [0, 60, 1.4]], "batl": [[1, 690, 0.33], [0, 600, 1.06]], "id": 255502}, {"atb": [[26, 9.9], [21, 16.5], [42, 2.01], [32, 5.32], [1.01, 156.31], [34, 0.21], [1.14, 2]], "atl": [[500, 0.39], [400, 0.32], [300, 0.43], [600, 0.39], [690, 0.03]], "batb": [[5, 1.01, 156.31], [4, 1.14, 2], [3, 21, 16.5], [2, 26, 9.9], [1, 32, 5.53], [0, 42, 2.01]], "batl": [[1, 690, 0.42], [0, 500, 1.14]], "id": 17311025}, {"atb": [[28, 9.17], [1.01, 156.31], [23, 15], [46, 1.99], [36, 4.71], [1.14, 2]], "atl": [[600, 0.07], [420, 0.31], [320, 0.41], [620, 0.31], [520, 0.38], [690, 0.03]], "batb": [[5, 1.01, 156.31], [2, 28, 9.17], [3, 23, 15], [4, 1.14, 2], [1, 36, 4.71], [0, 46, 1.99]], "batl": [[1, 690, 0.41], [0, 520, 1.1]], "id": 20587387}, {"atb": [[4.6, 1.99], [1.01, 156.31], [3.75, 119.98], [5.3, 1.36], [4, 82.49], [5, 20.62], [4.5, 47.13], [1.14, 2]], "atl": [[16.5, 0.07], [14.5, 9.59], [19.5, 7], [29, 6.93], [48, 4.13], [690, 0.03]], "batb": [[7, 1.01, 156.31], [6, 1.14, 2], [5, 3.75, 119.98], [4, 4, 82.49], [3, 4.5, 47.13], [2, 4.6, 1.99], [0, 5.3, 1.36], [1, 5, 20.62]], "batl": [[1, 19.5, 7.07], [4, 690, 0.03], [0, 14.5, 9.59], [3, 48, 4.13], [2, 29, 6.93]], "id": 11274440}, {"atb": [[1.01, 156.31], [27, 12.69], [44, 3.84], [34, 7.5], [60, 1.4], [46, 0.16], [1.14, 2]], "atl": [[600, 0.07], [460, 0.28], [360, 0.36], [660, 0.3], [560, 0.35], [690, 0.03]], "batb": [[5, 1.01, 156.31], [3, 27, 12.69], [2, 34, 7.5], [1, 44, 4], [4, 1.14, 2], [0, 60, 1.4]], "batl": [[1, 690, 0.33], [0, 600, 1.06]], "id": 12446287}, {"atb": [[3.05, 3.5], [2.76, 187.47], [2.96, 84.17], [3.15, 38.37], [2.86, 133.04], [1.01, 156.31], [3.7, 1.94], [1.14, 2]], "atl": [[6.6, 2.65], [9.4, 15.42], [13.5, 15.54], [7.4, 20.23], [18.5, 11.1], [7.8, 0.07], [70, 42.38], [690, 0.03]], "spl": [[7.6, 4.77], [1.01, 105.95], [4, 92.71]], "batb": [[7, 1.01, 156.31], [6, 1.14, 2], [5, 2.76, 187.47], [4, 2.86, 133.04], [3, 2.96, 84.17], [2, 3.05, 3.5], [1, 3.15, 38.37], [0, 3.7, 1.94]], "batl": [[6, 690, 0.03], [5, 70, 42.38], [4, 18.5, 11.1], [3, 13.5, 15.54], [2, 9.4, 15.49], [1, 7.4, 20.23], [0, 6.6, 2.65]], "id": 28368765}, {"atb": [[4.6, 1.99], [1.01, 156.31], [3.75, 119.98], [5, 20.62], [4.5, 47.13], [4, 82.49], [7.2, 1], [1.14, 2]], "atl": [[29, 6.93], [14.5, 9.59], [48, 4.13], [19.5, 7], [690, 0.03]], "spl": [[9.4, 4.24]], "batb": [[7, 1.01, 156.31], [6, 1.14, 2], [5, 3.75, 119.98], [4, 4, 82.49], [3, 4.5, 47.13], [2, 4.6, 1.99], [1, 5, 20.62], [0, 7.2, 1]], "batl": [[4, 690, 0.03], [3, 48, 4.13], [2, 29, 6.93], [1, 19.5, 7], [0, 14.5, 9.59]], "id": 25357177}, {"atb": [[11, 0.65], [1.01, 156.31], [9.6, 0.83], [8.2, 34.37], [10.5, 8.68], [9.2, 20.12], [7.2, 53.22], [1.14, 2]], "atl": [[110, 1.19], [55, 2.4], [210, 0.93], [310, 0.63], [690, 0.03]], "batb": [[0, 10.5, 9.33], [5, 1.01, 156.31], [4, 1.14, 2], [3, 7.2, 53.22], [2, 8.2, 34.37], [1, 9.2, 20.95]], "batl": [[3, 690, 0.03], [2, 310, 1.56], [1, 110, 1.19], [0, 55, 2.4]], "id": 40363511}], "img": true, "tv": 0}, {"id": "1.185783397", "marketDefinition": {"bspMarket": true, "turnInPlayEnabled": true, "persistenceEnabled": true, "marketBaseRate": 6, "eventId": "30738738", "eventTypeId": "7", "numberOfWinners": 1, "bettingType": "ODDS", "marketType": "WIN", "marketTime": "2021-07-31T02:03:00.000Z", "suspendTime": "2021-07-31T02:03:00.000Z", "bspReconciled": false, "complete": true, "inPlay": false, "crossMatching": false, "runnersVoidable": false, "numberOfActiveRunners": 11, "betDelay": 0, "status": "OPEN", "runners": [{"adjustmentFactor": 23.77, "status": "ACTIVE", "sortPriority": 1, "id": 27341660}, {"adjustmentFactor": 8.41, "status": "ACTIVE", "sortPriority": 2, "id": 28101643}, {"adjustmentFactor": 18.182, "status": "ACTIVE", "sortPriority": 3, "id": 5469097}, {"adjustmentFactor": 14.535, "status": "ACTIVE", "sortPriority": 4, "id": 27541933}, {"adjustmentFactor": 4.202, "status": "ACTIVE", "sortPriority": 5, "id": 396897}, {"adjustmentFactor": 20.375, "status": "ACTIVE", "sortPriority": 6, "id": 27592998}, {"adjustmentFactor": 3.472, "status": "ACTIVE", "sortPriority": 7, "id": 38206776}, {"adjustmentFactor": 1.961, "status": "ACTIVE", "sortPriority": 8, "id": 17552659}, {"adjustmentFactor": 2.353, "status": "ACTIVE", "sortPriority": 9, "id": 22042442}, {"adjustmentFactor": 1.949, "status": "ACTIVE", "sortPriority": 10, "id": 27693084}, {"adjustmentFactor": 0.791, "status": "ACTIVE", "sortPriority": 11, "id": 37584667}], "regulators": ["MR_INT"], "venue": "Eagle Farm", "countryCode": "AU", "discountAllowed": true, "timezone": "Australia/Queensland", "openDate": "2021-07-31T01:28:00.000Z", "version": 3938470576, "raceType": "Flat", "priceLadderDefinition": {"type": "CLASSIC"}}, "rc": [{"atb": [[2.94, 109.47], [2.84, 173.13], [2.74, 183.08], [3.2, 96.54], [3.75, 1.92], [1.01, 166.31], [3.6, 15.89], [1.03, 322], [1.02, 2]], "atl": [[15, 14.66], [20, 10.8], [10, 22.8], [8, 29.32], [5.4, 2.65], [690, 0.03]], "trd": [[3.7, 21.19]], "batb": [[8, 1.01, 166.31], [7, 1.02, 2], [6, 1.03, 322], [5, 2.74, 183.08], [4, 2.84, 173.13], [3, 2.94, 109.47], [2, 3.2, 96.54], [0, 3.75, 1.92], [1, 3.6, 15.89]], "batl": [[5, 690, 0.03], [4, 20, 10.8], [3, 15, 14.66], [2, 10, 22.8], [1, 8, 29.32], [0, 5.4, 2.65]], "tv": 21.19, "id": 27341660}, {"atb": [[1.01, 166.31], [48, 0.15], [26, 12.71], [46, 4.7], [21, 15.88], [32, 6.83], [1.03, 322], [1.02, 2]], "atl": [[690, 0.03], [500, 0.41], [400, 0.51], [600, 0.34], [300, 0.69]], "batb": [[6, 1.01, 166.31], [0, 46, 4.85], [4, 1.03, 322], [5, 1.02, 2], [2, 26, 12.71], [3, 21, 15.88], [1, 32, 6.83]], "batl": [[1, 690, 0.78], [0, 400, 1.2]], "id": 17552659}, {"atb": [[1.01, 166.31], [16.5, 20.5], [26, 0.27], [1.03, 322], [14, 24.44], [25, 8.83], [19, 11.77], [1.02, 2]], "atl": [[460, 0.45], [360, 0.57], [160, 1.29], [260, 0.79], [690, 0.03]], "batb": [[6, 1.01, 166.31], [2, 16.5, 20.5], [0, 25, 9.1], [4, 1.03, 322], [5, 1.02, 2], [3, 14, 24.44], [1, 19, 11.77]], "batl": [[2, 690, 0.48], [1, 360, 1.36], [0, 160, 1.29]], "id": 38206776}, {"atb": [[3.7, 117.67], [3.95, 71.8], [4.6, 58.84], [1.01, 166.31], [3.45, 129.68], [4.7, 1.53], [1.03, 322], [1.02, 2]], "atl": [[13.5, 16.48], [18.5, 11.77], [4.8, 2.65], [27, 7.92], [44, 4.79], [690, 0.03]], "batb": [[7, 1.01, 166.31], [4, 3.45, 129.68], [3, 3.7, 117.67], [2, 3.95, 71.8], [1, 4.6, 58.84], [6, 1.02, 2], [5, 1.03, 322], [0, 4.7, 1.53]], "batl": [[1, 13.5, 16.48], [2, 18.5, 11.77], [5, 690, 0.03], [4, 44, 4.79], [3, 27, 7.92], [0, 4.8, 2.65]], "id": 5469097}, {"atb": [[1.01, 166.31], [46, 7.06], [90, 2.38], [150, 1.42], [65, 4.96], [1.03, 322], [1.02, 2]], "atl": [[930, 0.22], [830, 0.25], [730, 0.28], [630, 0.33], [690, 0.03]], "batb": [[6, 1.01, 166.31], [5, 1.02, 2], [4, 1.03, 322], [3, 46, 7.06], [2, 65, 4.96], [1, 90, 2.38], [0, 150, 1.42]], "batl": [[0, 930, 1.11]], "id": 37584667}, {"atb": [[1.01, 166.31], [4.5, 90.77], [4, 105.9], [5.8, 1.23], [5.7, 45.06], [5, 52.95], [1.03, 322], [1.02, 2]], "atl": [[24, 8.95], [38, 5.57], [70, 2.98], [17, 12.87], [690, 0.03]], "batb": [[7, 1.01, 166.31], [4, 4, 105.9], [3, 4.5, 90.77], [6, 1.02, 2], [5, 1.03, 322], [2, 5, 52.95], [1, 5.7, 45.06], [0, 5.8, 1.23]], "batl": [[4, 690, 0.03], [3, 70, 2.98], [2, 38, 5.57], [1, 24, 8.95], [0, 17, 12.87]], "id": 27541933}, {"atb": [[3.65, 79.93], [3.15, 147.77], [3.4, 132.38], [1.01, 166.31], [4.1, 1.75], [4, 70.6], [1.03, 322], [1.02, 2]], "atl": [[21, 10.3], [10.5, 21.68], [15.5, 14.2], [32, 6.64], [690, 0.03]], "batb": [[7, 1.01, 166.31], [4, 3.15, 147.77], [3, 3.4, 132.38], [2, 3.65, 79.93], [6, 1.02, 2], [5, 1.03, 322], [1, 4, 70.6], [0, 4.1, 1.75]], "batl": [[2, 21, 10.3], [0, 10.5, 21.68], [4, 690, 0.03], [3, 32, 6.64], [1, 15.5, 14.2]], "id": 27592998}, {"atb": [[10.5, 0.68], [1.01, 166.31], [6.6, 56.89], [7.6, 48.27], [10, 23.6], [8.6, 27.95], [1.03, 322], [1.02, 2]], "atl": [[46, 4.56], [180, 1.14], [90, 2.3], [280, 0.74], [690, 0.03]], "batb": [[0, 10, 24.28], [6, 1.01, 166.31], [1, 8.6, 27.95], [5, 1.02, 2], [4, 1.03, 322], [3, 6.6, 56.89], [2, 7.6, 48.27]], "batl": [[3, 690, 0.77], [2, 180, 1.14], [1, 90, 2.3], [0, 46, 4.56]], "id": 28101643}, {"atb": [[15.5, 14.61], [1.01, 166.31], [19.5, 0.37], [1.02, 2], [13, 26.48], [10.5, 33.44], [19, 11.77], [1.03, 322]], "atl": [[230, 0.9], [430, 0.48], [330, 0.63], [130, 1.59], [690, 0.03]], "batb": [[6, 1.01, 166.31], [1, 15.5, 14.61], [0, 19, 12.14], [5, 1.02, 2], [4, 1.03, 322], [3, 10.5, 33.44], [2, 13, 26.48]], "batl": [[2, 690, 0.51], [1, 330, 1.53], [0, 130, 1.59]], "id": 396897}, {"atb": [[1.01, 166.31], [18.5, 18.16], [40, 0.18], [27, 8.15], [22, 15.13], [38, 5.73], [1.03, 322], [1.02, 2]], "atl": [[250, 0.83], [690, 0.03], [450, 0.46], [350, 0.59], [550, 0.38]], "batb": [[6, 1.01, 166.31], [3, 18.5, 18.16], [0, 38, 5.91], [4, 1.03, 322], [5, 1.02, 2], [2, 22, 15.13], [1, 27, 8.15]], "batl": [[0, 350, 1.42], [1, 690, 0.87]], "id": 22042442}, {"atb": [[26, 10.17], [42, 4.13], [32, 8.2], [65, 2.65], [1.01, 166.31], [48, 0.15], [1.03, 322], [1.02, 2]], "atl": [[450, 0.58], [350, 0.74], [650, 0.4], [550, 0.47], [75, 0.32], [690, 0.03]], "trd": [[75, 5.72]], "batb": [[6, 1.01, 166.31], [5, 1.02, 2], [4, 1.03, 322], [3, 26, 10.17], [2, 32, 8.2], [1, 42, 4.28], [0, 65, 2.65]], "batl": [[2, 690, 0.43], [1, 550, 1.05], [0, 350, 1.06]], "tv": 5.72, "id": 27693084}], "img": true, "tv": 26.91}, {"id": "1.185788113", "marketDefinition": {"bspMarket": true, "turnInPlayEnabled": true, "persistenceEnabled": true, "marketBaseRate": 6, "eventId": "30739095", "eventTypeId": "7", "numberOfWinners": 1, "bettingType": "ODDS", "marketType": "WIN", "marketTime": "2021-07-30T12:42:00.000Z", "suspendTime": "2021-07-30T12:42:00.000Z", "bspReconciled": false, "complete": true, "inPlay": false, "crossMatching": true, "runnersVoidable": false, "numberOfActiveRunners": 8, "betDelay": 0, "status": "OPEN", "runners": [{"adjustmentFactor": 6.96, "status": "ACTIVE", "sortPriority": 1, "id": 23402449}, {"adjustmentFactor": 4.526, "status": "ACTIVE", "sortPriority": 2, "id": 12992483}, {"adjustmentFactor": 10.988, "status": "ACTIVE", "sortPriority": 3, "id": 28864911}, {"adjustmentFactor": 3.585, "status": "ACTIVE", "sortPriority": 4, "id": 13224964}, {"adjustmentFactor": 4.526, "status": "ACTIVE", "sortPriority": 5, "id": 19451042}, {"adjustmentFactor": 36.348, "status": "ACTIVE", "sortPriority": 6, "id": 10585390}, {"adjustmentFactor": 28.542, "status": "ACTIVE", "sortPriority": 7, "id": 23294784}, {"adjustmentFactor": 4.526, "status": "ACTIVE", "sortPriority": 8, "id": 18759615}], "regulators": ["MR_INT"], "venue": "Gloucester Park", "countryCode": "AU", "discountAllowed": true, "timezone": "Australia/Perth", "openDate": "2021-07-30T09:15:00.000Z", "version": 3938344236, "raceType": "Flat", "priceLadderDefinition": {"type": "CLASSIC"}}, "rc": [{"atb": [[13, 3.92], [8.2, 26.13], [10.5, 9.9], [9.2, 11.47], [18, 2.77], [1.01, 156.31], [1.14, 2]], "atl": [[250, 0.52], [450, 0.43], [350, 0.56], [150, 0.87], [600, 0.07], [690, 0.03]], "batb": [[6, 1.01, 156.31], [5, 1.14, 2], [4, 8.2, 26.13], [3, 9.2, 11.47], [2, 10.5, 9.9], [1, 13, 3.92], [0, 18, 2.77]], "batl": [[2, 690, 0.03], [1, 600, 1.06], [0, 250, 1.39]], "id": 13224964}, {"atb": [[3.15, 43.76], [2.86, 101.17], [1.01, 156.31], [2.96, 48], [3.9, 16.22], [3.4, 19.6], [1.14, 2]], "atl": [[15, 0.07], [26, 7.77], [42, 4.74], [18, 7.62], [13, 10.79], [690, 0.03]], "batb": [[6, 1.01, 156.31], [4, 2.86, 101.17], [2, 3.15, 43.76], [3, 2.96, 48], [1, 3.4, 19.6], [0, 3.9, 16.22], [5, 1.14, 2]], "batl": [[1, 18, 7.69], [4, 690, 0.03], [3, 42, 4.74], [2, 26, 7.77], [0, 13, 10.79]], "id": 28864911}, {"atb": [[1.01, 156.31], [2.82, 103.39], [3.05, 45.89], [3.3, 20.45], [3.8, 16.8], [2.92, 49], [1.14, 2]], "atl": [[24, 8.44], [17, 8.09], [12, 11.77], [38, 5.25], [690, 0.03]], "batb": [[6, 1.01, 156.31], [4, 2.82, 103.39], [3, 2.92, 49], [2, 3.05, 45.89], [1, 3.3, 20.45], [0, 3.8, 16.8], [5, 1.14, 2]], "batl": [[2, 24, 8.44], [1, 17, 8.09], [3, 38, 5.25], [0, 12, 11.77], [4, 690, 0.03]], "id": 23294784}, {"atb": [[1.01, 156.31], [4.5, 53.77], [6, 9.41], [5.5, 20.91], [5, 23.52], [8.2, 3.72], [8, 6.72], [1.14, 2]], "atl": [[250, 0.78], [40, 3.32], [150, 1.3], [75, 1.75], [690, 0.03]], "batb": [[7, 1.01, 156.31], [5, 4.5, 53.77], [4, 5, 23.52], [3, 5.5, 20.91], [2, 6, 9.41], [6, 1.14, 2], [1, 8, 6.72], [0, 8.2, 3.72]], "batl": [[3, 690, 0.81], [2, 150, 1.3], [1, 75, 1.75], [0, 40, 3.32]], "id": 18759615}, {"atb": [[2.1, 42.77], [1.95, 49.52], [1.9, 104.54], [1.85, 110.69], [1.01, 156.31], [1.8, 235.22], [1.14, 2]], "atl": [[6, 25.9], [10, 21.58], [5, 32.37], [8, 27.74], [690, 0.03]], "batb": [[6, 1.01, 156.31], [4, 1.8, 235.22], [3, 1.85, 110.69], [2, 1.9, 104.54], [1, 1.95, 49.52], [0, 2.1, 42.77], [5, 1.14, 2]], "batl": [[1, 6, 25.9], [3, 10, 21.58], [2, 8, 27.74], [0, 5, 32.37], [4, 690, 0.03]], "id": 10585390}, {"atb": [[2.76, 53.46], [2.96, 24], [2.66, 113.36], [3.4, 19.6], [2.86, 50.58], [1.01, 156.31], [1.14, 2]], "atl": [[7.8, 2.65], [26, 7.77], [13, 10.79], [9.2, 15.79], [18, 11.42], [8.4, 0.07], [690, 0.03]], "spl": [[1.01, 7.95]], "batb": [[6, 1.01, 156.31], [5, 1.14, 2], [4, 2.66, 113.36], [3, 2.76, 53.46], [2, 2.86, 50.58], [1, 2.96, 24], [0, 3.4, 19.6]], "batl": [[5, 690, 0.03], [4, 26, 7.77], [3, 18, 11.42], [2, 13, 10.79], [1, 9.2, 15.86], [0, 7.8, 2.65]], "id": 23402449}, {"atb": [[23, 4.28], [1.01, 156.31], [28, 3.49], [36, 1.35], [19, 10.45], [65, 0.74], [1.14, 2]], "atl": [[880, 0.22], [780, 0.25], [680, 0.19], [580, 0.22], [690, 0.03]], "batb": [[5, 1.01, 156.31], [2, 23, 4.28], [1, 28, 3.49], [0, 36, 2.09], [3, 19, 10.45], [4, 1.14, 2]], "batl": [[0, 880, 0.91]], "id": 19451042}, {"atb": [[1.01, 156.31], [9.2, 22.95], [15.5, 3.24], [13, 7.84], [10.5, 9.9], [21, 2.35], [1.14, 2]], "atl": [[600, 0.07], [490, 0.4], [390, 0.5], [190, 0.68], [290, 0.45], [690, 0.03]], "batb": [[6, 1.01, 156.31], [4, 9.2, 22.95], [5, 1.14, 2], [3, 10.5, 9.9], [2, 13, 7.84], [1, 15.5, 3.24], [0, 21, 2.35]], "batl": [[1, 690, 1], [0, 290, 1.13]], "id": 12992483}], "img": true, "tv": 0}, {"id": "1.185781623", "marketDefinition": {"bspMarket": true, "turnInPlayEnabled": true, "persistenceEnabled": true, "marketBaseRate": 8, "eventId": "30738609", "eventTypeId": "7", "numberOfWinners": 1, "bettingType": "ODDS", "marketType": "WIN", "marketTime": "2021-07-30T06:00:00.000Z", "suspendTime": "2021-07-30T06:00:00.000Z", "bspReconciled": false, "complete": true, "inPlay": false, "crossMatching": true, "runnersVoidable": false, "numberOfActiveRunners": 10, "betDelay": 0, "status": "OPEN", "runners": [{"adjustmentFactor": 2.966, "status": "ACTIVE", "sortPriority": 1, "id": 24540407}, {"adjustmentFactor": 3.604, "status": "ACTIVE", "sortPriority": 2, "id": 22212133}, {"adjustmentFactor": 10.998, "status": "ACTIVE", "sortPriority": 3, "id": 26608805}, {"adjustmentFactor": 4.544, "status": "ACTIVE", "sortPriority": 4, "id": 38338834}, {"adjustmentFactor": 14.2, "status": "ACTIVE", "sortPriority": 5, "id": 7407310}, {"adjustmentFactor": 14.2, "status": "ACTIVE", "sortPriority": 6, "id": 13434605}, {"adjustmentFactor": 7.534, "status": "ACTIVE", "sortPriority": 7, "id": 10948633}, {"adjustmentFactor": 6.065, "status": "ACTIVE", "sortPriority": 8, "id": 10831134}, {"adjustmentFactor": 23.487, "status": "ACTIVE", "sortPriority": 9, "id": 6656423}, {"adjustmentFactor": 12.4, "status": "ACTIVE", "sortPriority": 10, "id": 40363713}], "regulators": ["MR_INT"], "venue": "Wagga", "countryCode": "AU", "discountAllowed": true, "timezone": "Australia/Sydney", "openDate": "2021-07-30T03:03:00.000Z", "version": 3938310124, "raceType": "Flat", "priceLadderDefinition": {"type": "CLASSIC"}}, "rc": [{"atb": [[16.5, 0.44], [16, 2.19], [8.4, 0.97], [4.2, 29.69], [2.62, 52.47], [5.3, 21.4], [8.2, 18.33], [3.5, 4.4], [15.5, 2.07], [6.2, 11.53], [10.5, 3.16], [5.1, 29.26], [1.03, 1.09], [1.01, 146.31], [22, 0.49], [1.2, 122], [1.14, 2]], "atl": [[290, 2], [400, 0.48], [200, 0.65], [100, 1.29], [300, 0.64], [690, 0.03]], "batb": [[0, 16, 3.12], [2, 10.5, 3.16], [3, 8.2, 19.3], [9, 2.62, 52.47], [8, 3.5, 4.4], [7, 4.2, 29.69], [6, 5.1, 29.26], [5, 5.3, 21.4], [4, 6.2, 11.53], [1, 15.5, 2.07]], "batl": [[3, 690, 0.03], [2, 400, 1.12], [1, 290, 2.65], [0, 100, 1.29]], "id": 10831134}, {"atb": [[3.45, 37.55], [9.6, 1.63], [1.01, 146.31], [7.4, 3.72], [8, 1.88], [7, 5], [2.62, 52.47], [4, 24], [3.75, 21.81], [3.25, 53.32], [5.5, 6.66], [4.5, 17.14], [9.2, 1.23], [2.24, 8.87], [1.03, 1.09], [1.2, 122], [1.14, 2]], "atl": [[29, 0.29], [30, 4.42], [200, 0.96], [100, 1.94], [50, 2.62], [27, 2], [690, 0.03]], "batb": [[9, 3.45, 37.55], [8, 3.75, 21.81], [7, 4, 24], [6, 4.5, 17.14], [5, 5.5, 6.66], [4, 7, 5], [3, 7.4, 3.72], [2, 8, 1.88], [1, 9.2, 1.23], [0, 9.6, 1.63]], "batl": [[1, 30, 4.71], [4, 690, 0.99], [3, 100, 1.94], [2, 50, 2.62], [0, 27, 2]], "id": 10948633}, {"atb": [[22, 1.43], [23, 0.96], [4.2, 29.69], [2.62, 52.47], [11.5, 6.86], [7.2, 14.84], [36, 0.3], [8.4, 8.11], [11, 6], [6.4, 22.21], [16, 2], [1.03, 1.09], [1.01, 146.31], [1.2, 122], [1.14, 2]], "atl": [[890, 2], [500, 0.39], [400, 0.48], [200, 0.65], [300, 0.43], [940, 0.07], [900, 0.79], [690, 0.03]], "batb": [[1, 22, 1.43], [9, 2.62, 52.47], [8, 4.2, 29.69], [7, 6.4, 22.21], [6, 7.2, 14.84], [5, 8.4, 8.11], [4, 11, 6], [3, 11.5, 6.86], [2, 16, 2], [0, 23, 1.26]], "batl": [[2, 940, 0.86], [1, 890, 2.9], [0, 300, 1.08]], "id": 24540407}, {"atb": [[3.95, 0.07], [2.54, 4.65], [4.3, 2], [3.75, 5.33], [2.48, 81.06], [2.68, 35.7], [3.7, 11.11], [2.88, 31.9], [3.2, 13.63], [2.34, 8.2], [4.2, 1.71], [1.01, 146.31], [1.03, 1.09], [1.2, 122], [1.14, 2]], "atl": [[10.5, 0.81], [25, 12.2], [19, 7.2], [34, 17.33], [22, 9.15], [11, 12.82], [16, 8.55], [690, 0.03]], "batb": [[2, 3.75, 5.4], [9, 2.34, 8.2], [8, 2.48, 81.06], [7, 2.54, 4.65], [6, 2.68, 35.7], [5, 2.88, 31.9], [4, 3.2, 13.63], [3, 3.7, 11.11], [1, 4.2, 1.71], [0, 4.3, 2]], "batl": [[0, 11, 13.63], [6, 690, 0.03], [5, 34, 17.33], [4, 25, 12.2], [3, 22, 9.15], [2, 19, 7.2], [1, 16, 8.55]], "id": 40363713}, {"atb": [[4.1, 0.06], [4, 3.92], [1.01, 146.31], [3.95, 3.82], [2.48, 81.06], [2.68, 35.7], [3.7, 11.11], [2.88, 31.9], [3.2, 13.63], [4.5, 2], [2.34, 8.2], [1.03, 5.43], [1.2, 122], [1.14, 2]], "atl": [[10.5, 0.81], [22, 9.15], [11, 12.82], [34, 17.33], [16, 8.55], [25, 12.2], [19, 7.2], [900, 1.85], [690, 0.03]], "spl": [[1.01, 9.01]], "batb": [[1, 4, 3.98], [9, 1.2, 122], [8, 2.34, 8.2], [7, 2.48, 81.06], [6, 2.68, 35.7], [5, 2.88, 31.9], [4, 3.2, 13.63], [3, 3.7, 11.11], [2, 3.95, 3.82], [0, 4.5, 2]], "batl": [[0, 11, 13.63], [6, 900, 1.88], [5, 34, 17.33], [4, 25, 12.2], [3, 22, 9.15], [2, 19, 7.2], [1, 16, 8.55]], "id": 6656423}, {"atb": [[15.5, 2.07], [16, 1.38], [8.4, 0.97], [4.2, 29.69], [2.62, 52.47], [5.3, 21.4], [8.2, 18.33], [3.65, 4.15], [6.2, 11.53], [10.5, 3.16], [5.1, 29.26], [1.03, 1.09], [1.01, 146.31], [22, 0.49], [1.2, 122], [1.14, 2]], "atl": [[290, 2], [400, 0.48], [200, 0.65], [100, 1.29], [300, 0.64], [440, 0.07], [900, 0.53], [690, 0.03]], "batb": [[1, 15.5, 2.07], [9, 2.62, 52.47], [8, 3.65, 4.15], [7, 4.2, 29.69], [6, 5.1, 29.26], [5, 5.3, 21.4], [4, 6.2, 11.53], [3, 8.2, 19.3], [2, 10.5, 3.16], [0, 16, 1.87]], "batl": [[3, 900, 0.63], [2, 400, 1.12], [1, 290, 2.65], [0, 100, 1.29]], "id": 22212133}, {"atb": [[5.8, 2], [5.7, 6.47], [1.01, 146.31], [7.4, 1.57], [2.62, 52.47], [2.4, 65.71], [3.35, 30.64], [5.5, 6.66], [5.6, 3.57], [3.75, 21.81], [3.25, 26.66], [2.9, 63.14], [4.5, 8.57], [2.24, 8.87], [1.03, 1.09], [1.2, 122], [1.14, 2]], "atl": [[16.5, 2.59], [30, 7.2], [40, 12.2], [24, 5.57], [38, 5.2], [70, 2.79], [17, 8.01], [690, 0.03]], "spl": [[1.01, 10.6]], "batb": [[9, 2.9, 63.14], [8, 3.25, 26.66], [7, 3.35, 30.64], [6, 3.75, 21.81], [5, 4.5, 8.57], [4, 5.5, 6.66], [3, 5.6, 3.57], [2, 5.7, 6.47], [1, 5.8, 2], [0, 7.4, 1.57]], "batl": [[0, 16.5, 2.59], [7, 690, 0.03], [6, 70, 2.79], [5, 40, 12.2], [4, 38, 5.2], [3, 30, 7.2], [2, 24, 5.57], [1, 17, 8.01]], "id": 13434605}, {"atb": [[3.5, 0.08], [3.65, 9.6], [3.7, 1.94], [1.01, 146.31], [3.6, 2], [1.76, 121.05], [2.26, 57.14], [2.32, 8.33], [2.76, 30.07], [2.96, 13.5], [3.4, 11.02], [2.36, 77.83], [2.56, 33.93], [1.03, 5.43], [2.42, 5.05], [2.8, 2], [1.2, 122], [1.14, 2]], "atl": [[6.8, 1.25], [34, 11.5], [15.5, 12.2], [12, 7.2], [26, 8.12], [13, 11.27], [9.2, 16.49], [18, 11.94], [7, 4.19], [7.8, 0.07], [900, 1.32], [690, 0.03]], "trd": [[6, 11.76]], "spl": [[1.01, 2.65]], "batb": [[3, 3.4, 11.1], [1, 3.65, 9.6], [9, 2.36, 77.83], [8, 2.42, 5.05], [7, 2.56, 33.93], [6, 2.76, 30.07], [5, 2.8, 2], [4, 2.96, 13.5], [2, 3.6, 2], [0, 3.7, 1.94]], "batl": [[9, 900, 1.35], [8, 34, 11.5], [7, 26, 8.12], [6, 18, 11.94], [5, 15.5, 12.2], [4, 13, 11.27], [3, 12, 7.2], [2, 9.2, 16.56], [1, 7, 4.19], [0, 6.8, 1.25]], "tv": 11.76, "id": 26608805}, {"atb": [[8, 1.88], [7.8, 2], [7.4, 0.97], [7, 5], [2.62, 52.47], [2.8, 51.11], [4, 24], [3.75, 21.81], [3.25, 53.32], [5.5, 6.66], [4.5, 17.14], [3.65, 4.15], [1.03, 1.09], [1.01, 146.31], [9.2, 1.23], [1.2, 122], [1.14, 2]], "atl": [[29, 0.29], [30, 4.42], [200, 0.96], [100, 1.94], [50, 2.62], [27, 2], [44, 0.07], [900, 0.53], [690, 0.03]], "batb": [[9, 3.25, 53.32], [8, 3.65, 4.15], [7, 3.75, 21.81], [6, 4, 24], [5, 4.5, 17.14], [4, 5.5, 6.66], [3, 7, 5.97], [2, 7.8, 2], [1, 8, 1.88], [0, 9.2, 1.23]], "batl": [[1, 30, 4.71], [4, 900, 1.52], [3, 100, 1.94], [2, 50, 2.69], [0, 27, 2]], "id": 38338834}, {"atb": [[5.7, 3.72], [6.2, 1.15], [1.01, 146.31], [6, 2.51], [7.2, 1.62], [2.62, 52.47], [2.4, 65.71], [3.35, 30.64], [3.75, 21.81], [3.25, 26.66], [5.5, 6.66], [2.9, 63.14], [4.5, 8.57], [2.22, 9.01], [1.03, 1.09], [1.2, 122], [1.14, 2]], "atl": [[16.5, 2.52], [30, 7.2], [40, 12.2], [24, 5.57], [38, 5.2], [70, 2.79], [17, 8.01], [18.5, 0.07], [900, 1.59], [690, 0.03]], "batb": [[9, 2.9, 63.14], [8, 3.25, 26.66], [7, 3.35, 30.64], [6, 3.75, 21.81], [5, 4.5, 8.57], [4, 5.5, 6.66], [3, 5.7, 3.72], [2, 6, 2.51], [1, 6.2, 1.15], [0, 7.2, 1.62]], "batl": [[0, 16.5, 2.52], [7, 900, 1.62], [6, 70, 2.79], [5, 40, 12.2], [4, 38, 5.2], [3, 30, 7.2], [2, 24, 5.64], [1, 17, 8.01]], "id": 7407310}], "img": true, "tv": 11.76}, {"id": "1.185793024", "marketDefinition": {"bspMarket": true, "turnInPlayEnabled": true, "persistenceEnabled": true, "marketBaseRate": 6, "eventId": "30739215", "eventTypeId": "7", "numberOfWinners": 1, "bettingType": "ODDS", "marketType": "WIN", "marketTime": "2021-07-30T11:06:00.000Z", "suspendTime": "2021-07-30T11:06:00.000Z", "bspReconciled": false, "complete": true, "inPlay": false, "crossMatching": true, "runnersVoidable": false, "numberOfActiveRunners": 7, "betDelay": 0, "status": "OPEN", "runners": [{"adjustmentFactor": 6.495, "status": "ACTIVE", "sortPriority": 1, "id": 733357}, {"adjustmentFactor": 8.19, "status": "ACTIVE", "sortPriority": 2, "id": 28238038}, {"adjustmentFactor": 3.609, "status": "ACTIVE", "sortPriority": 3, "id": 39905490}, {"adjustmentFactor": 11.003, "status": "ACTIVE", "sortPriority": 4, "id": 39539599}, {"adjustmentFactor": 3.609, "status": "ACTIVE", "sortPriority": 5, "id": 1359742}, {"adjustmentFactor": 36.349, "status": "ACTIVE", "sortPriority": 6, "id": 2407530}, {"adjustmentFactor": 30.747, "status": "ACTIVE", "sortPriority": 7, "id": 37258129}], "regulators": ["MR_INT"], "venue": "Ballarat", "countryCode": "AU", "discountAllowed": true, "timezone": "Australia/Sydney", "openDate": "2021-07-30T08:30:00.000Z", "version": 3938290770, "raceType": "Flat", "priceLadderDefinition": {"type": "CLASSIC"}}, "rc": [{"atb": [[1.01, 156.31], [27, 12.69], [44, 3.84], [34, 7.5], [60, 1.4], [46, 0.16], [1.14, 2]], "atl": [[460, 0.28], [360, 0.36], [660, 0.3], [560, 0.35], [690, 0.03]], "batb": [[5, 1.01, 156.31], [3, 27, 12.69], [2, 34, 7.5], [1, 44, 4], [4, 1.14, 2], [0, 60, 1.4]], "batl": [[1, 690, 0.03], [0, 660, 1.29]], "id": 1359742}, {"atb": [[1.01, 156.31], [26, 9.9], [21, 16.5], [42, 2.01], [32, 5.32], [34, 0.21], [1.14, 2]], "atl": [[600, 0.39], [500, 0.39], [400, 0.32], [300, 0.43], [690, 0.03]], "batb": [[5, 1.01, 156.31], [3, 21, 16.5], [2, 26, 9.9], [4, 1.14, 2], [1, 32, 5.53], [0, 42, 2.01]], "batl": [[1, 690, 0.42], [0, 500, 1.14]], "id": 39905490}, {"atb": [[1.99, 7.24], [1.95, 86.82], [1.9, 183.3], [1.85, 291.13], [1.8, 412.43], [2, 3.59], [1.01, 156.31], [1.14, 2]], "atl": [[3.4, 2.65], [8.2, 26.98], [4.1, 41.77], [6.2, 37.35], [5.1, 31.58], [690, 0.03]], "spl": [[2.9, 9.54], [1.01, 7.95]], "batb": [[7, 1.01, 156.31], [6, 1.14, 2], [5, 1.8, 412.43], [4, 1.85, 291.13], [3, 1.9, 183.3], [2, 1.95, 86.82], [1, 1.99, 7.24], [0, 2, 3.59]], "batl": [[5, 690, 0.03], [4, 8.2, 26.98], [3, 6.2, 37.35], [2, 5.1, 31.58], [1, 4.1, 41.77], [0, 3.4, 2.65]], "id": 2407530}, {"atb": [[4.6, 1.99], [1.01, 156.31], [3.75, 119.98], [5.1, 1.41], [4, 82.49], [5, 20.62], [4.5, 47.13], [1.14, 2]], "atl": [[16.5, 0.07], [14.5, 9.59], [19.5, 7], [29, 6.93], [48, 4.13], [690, 0.03]], "batb": [[7, 1.01, 156.31], [6, 1.14, 2], [5, 3.75, 119.98], [4, 4, 82.49], [3, 4.5, 47.13], [2, 4.6, 1.99], [0, 5.1, 1.41], [1, 5, 20.62]], "batl": [[1, 19.5, 7.07], [4, 690, 0.03], [0, 14.5, 9.59], [3, 48, 4.13], [2, 29, 6.93]], "id": 28238038}, {"atb": [[2.2, 5.97], [2.16, 71.11], [1.93, 354.78], [1.98, 252.51], [2.06, 155.63], [2.38, 3.01], [1.01, 156.31], [1.14, 2]], "atl": [[5.9, 26.43], [7.8, 28.56], [9.8, 22.07], [4.9, 33.2], [690, 0.03]], "spl": [[4, 7.42]], "batb": [[7, 1.01, 156.31], [6, 1.14, 2], [5, 1.93, 354.78], [4, 1.98, 252.51], [3, 2.06, 155.63], [2, 2.16, 71.11], [1, 2.2, 5.97], [0, 2.38, 3.01]], "batl": [[4, 690, 0.03], [3, 9.8, 22.07], [2, 7.8, 28.56], [1, 5.9, 26.43], [0, 4.9, 33.2]], "id": 37258129}, {"atb": [[6.8, 1.23], [1.01, 156.31], [6.6, 29.46], [7.6, 12.5], [5.3, 76.73], [5.8, 51.55], [8.8, 0.82], [1.14, 2]], "atl": [[28, 4.79], [46, 2.88], [180, 1.09], [90, 2.18], [690, 0.03]], "spl": [[16, 3.18]], "batb": [[6, 1.01, 156.31], [5, 1.14, 2], [4, 5.3, 76.73], [3, 5.8, 51.55], [2, 6.6, 29.46], [1, 6.8, 1.23], [0, 7.6, 13.32]], "batl": [[4, 690, 0.03], [3, 180, 1.09], [2, 90, 2.18], [1, 46, 2.88], [0, 28, 4.79]], "id": 39539599}, {"atb": [[15.5, 9.41], [9.6, 0.83], [1.01, 156.31], [13, 13.75], [10.5, 26.05], [9.2, 40.24], [16, 0.44], [1.14, 2]], "atl": [[380, 0.51], [180, 0.73], [90, 1.46], [280, 0.69], [320, 0.07], [690, 0.03]], "batb": [[0, 15.5, 9.85], [5, 1.01, 156.31], [4, 1.14, 2], [3, 9.2, 41.07], [2, 10.5, 26.05], [1, 13, 13.75]], "batl": [[2, 690, 0.61], [1, 280, 1.42], [0, 90, 1.46]], "id": 733357}], "img": true, "tv": 0}, {"id": "1.185781631", "marketDefinition": {"bspMarket": true, "turnInPlayEnabled": true, "persistenceEnabled": true, "marketBaseRate": 8, "eventId": "30738618", "eventTypeId": "7", "numberOfWinners": 1, "bettingType": "ODDS", "marketType": "WIN", "marketTime": "2021-07-30T07:10:00.000Z", "suspendTime": "2021-07-30T07:10:00.000Z", "bspReconciled": false, "complete": true, "inPlay": false, "crossMatching": true, "runnersVoidable": false, "numberOfActiveRunners": 8, "betDelay": 0, "status": "OPEN", "runners": [{"adjustmentFactor": 38, "status": "ACTIVE", "sortPriority": 1, "id": 23401729}, {"adjustmentFactor": 4.188, "status": "ACTIVE", "sortPriority": 2, "id": 27132929}, {"adjustmentFactor": 4.188, "status": "ACTIVE", "sortPriority": 3, "id": 27290030}, {"adjustmentFactor": 35.625, "status": "ACTIVE", "sortPriority": 4, "id": 1309906}, {"adjustmentFactor": 4.188, "status": "ACTIVE", "sortPriority": 5, "id": 20232649}, {"adjustmentFactor": 6.79, "status": "ACTIVE", "sortPriority": 6, "id": 573934}, {"adjustmentFactor": 1.538, "status": "ACTIVE", "sortPriority": 7, "id": 22847092}, {"adjustmentFactor": 5.482, "status": "ACTIVE", "sortPriority": 8, "id": 11866087}, {"adjustmentFactor": 28.933, "status": "REMOVED", "sortPriority": 9, "removalDate": "2021-07-29T09:41:35.000Z", "id": 26921837}], "regulators": ["MR_INT"], "venue": "Newcastle", "countryCode": "AU", "discountAllowed": true, "timezone": "Australia/Sydney", "openDate": "2021-07-30T07:10:00.000Z", "version": 3938308190, "raceType": "Flat", "priceLadderDefinition": {"type": "CLASSIC"}}, "rc": [{"atb": [[3.7, 4.07], [3.5, 47.04], [6, 5.88], [5, 14.7], [4, 19.6], [8, 4.2], [1.03, 1.09], [8.2, 0.88], [1.01, 146.31], [11.5, 0.96], [1.14, 2]], "atl": [[250, 0.78], [40, 3.32], [150, 1.3], [75, 1.75], [65, 0.05], [900, 1.32], [690, 0.03]], "batb": [[9, 1.01, 146.31], [8, 1.03, 1.09], [7, 1.14, 2], [6, 3.5, 47.04], [5, 3.7, 4.07], [4, 4, 19.6], [3, 5, 14.7], [2, 6, 5.88], [1, 8, 4.2], [0, 8.2, 1.84]], "batl": [[3, 900, 2.13], [2, 150, 1.3], [1, 75, 1.8], [0, 40, 3.32]], "id": 27132929}, {"atb": [[1.44, 25], [2.32, 3.09], [2.1, 26.73], [1.75, 156.81], [1.95, 61.9], [1.85, 69.18], [2.3, 22.62], [1.03, 5.43], [2.52, 2], [1.01, 146.31], [1.14, 2]], "atl": [[6.6, 23.12], [11.5, 18.49], [5.3, 30.11], [8.6, 25.56], [5.1, 0.67], [5.5, 0.07], [690, 0.03]], "spl": [[4.4, 6.89]], "batb": [[9, 1.03, 5.43], [8, 1.14, 2], [7, 1.44, 25], [6, 1.75, 156.81], [5, 1.85, 69.18], [4, 1.95, 61.9], [3, 2.1, 26.73], [2, 2.3, 22.62], [1, 2.32, 3.09], [0, 2.52, 2]], "batl": [[4, 690, 0.03], [3, 11.5, 18.49], [2, 8.6, 25.56], [1, 6.6, 23.19], [0, 5.3, 30.78]], "id": 1309906}, {"atb": [[4.3, 3.33], [7.8, 0.92], [3.9, 20.28], [3.4, 49], [7.6, 4.46], [5.8, 6.12], [4.8, 15.47], [1.03, 1.09], [10.5, 1.06], [1.01, 146.31], [1.14, 2]], "atl": [[230, 0.85], [36, 3.8], [130, 1.5], [65, 2.02], [900, 0.53], [44, 0.07], [690, 0.03]], "batb": [[9, 1.01, 146.31], [8, 1.03, 1.09], [7, 1.14, 2], [6, 3.4, 49], [5, 3.9, 20.28], [4, 4.3, 3.33], [1, 7.6, 5.38], [3, 4.8, 15.47], [2, 5.8, 6.12], [0, 10.5, 1.06]], "batl": [[3, 900, 1.41], [2, 130, 1.5], [1, 65, 2.09], [0, 36, 3.8]], "id": 11866087}, {"atb": [[9.4, 14], [13.5, 4.7], [27, 1.13], [44, 0.68], [18.5, 3.36], [85, 0.13], [1.01, 146.31], [1.14, 2]], "atl": [[460, 0.28], [360, 0.36], [660, 0.31], [560, 0.35], [600, 0.07], [690, 0.03]], "batb": [[5, 1.01, 146.31], [4, 1.14, 2], [3, 9.4, 14], [2, 13.5, 4.7], [1, 18.5, 3.36], [0, 27, 1.94]], "batl": [[1, 690, 0.34], [0, 600, 1.06]], "id": 22847092}, {"atb": [[4.3, 3.33], [3.9, 40.55], [7.6, 4.46], [5.8, 12.25], [4.8, 15.47], [9.6, 3.42], [1.03, 1.09], [9.8, 0.73], [1.01, 146.31], [13.5, 0.81], [4, 2.39], [1.14, 2]], "atl": [[230, 0.85], [330, 0.59], [130, 1], [65, 2.07], [900, 1.06], [170, 0.07], [690, 0.03]], "batb": [[9, 1.03, 1.09], [8, 1.14, 2], [7, 3.9, 40.55], [6, 4, 2.39], [5, 4.3, 3.33], [4, 4.8, 15.47], [3, 5.8, 12.25], [2, 7.6, 4.46], [1, 9.6, 3.42], [0, 9.8, 1.54]], "batl": [[3, 900, 1.09], [2, 330, 1.51], [1, 130, 1], [0, 65, 2.07]], "id": 20232649}, {"atb": [[3.35, 4.68], [5.4, 13.37], [4.4, 17.3], [8.8, 3.77], [6.8, 5.07], [3.7, 43.56], [1.03, 1.09], [9, 0.8], [1.01, 146.31], [12.5, 0.88], [1.14, 2]], "atl": [[48, 2.82], [190, 1.03], [95, 1.38], [290, 0.67], [900, 1.06], [65, 0.07], [690, 0.03]], "batb": [[9, 1.01, 146.31], [8, 1.03, 1.09], [7, 1.14, 2], [6, 3.35, 4.68], [5, 3.7, 43.56], [4, 4.4, 17.3], [3, 5.4, 13.37], [2, 6.8, 5.07], [1, 8.8, 3.77], [0, 9, 1.68]], "batl": [[3, 900, 1.76], [2, 190, 1.03], [1, 95, 1.45], [0, 48, 2.82]], "id": 573934}, {"atb": [[1.34, 32.35], [1.99, 3.61], [1.68, 86.48], [1.78, 75.39], [1.88, 33.41], [1.58, 202.78], [1.98, 30], [1.03, 5.43], [2.16, 2], [1.71, 10.1], [1.01, 146.31], [1.14, 2]], "atl": [[9.4, 23.12], [4.7, 34.99], [5.7, 27.55], [7.4, 30.35], [900, 1.32], [3.45, 3.65], [690, 0.03]], "spl": [[3.9, 7.42]], "batb": [[9, 1.14, 2], [8, 1.34, 32.35], [7, 1.58, 202.78], [6, 1.68, 86.48], [5, 1.71, 10.1], [4, 1.78, 75.39], [3, 1.88, 33.41], [2, 1.98, 30], [1, 1.99, 3.61], [0, 2.16, 2]], "batl": [[5, 900, 1.35], [4, 9.4, 23.12], [3, 7.4, 30.35], [2, 5.7, 27.55], [1, 4.7, 34.99], [0, 3.45, 3.65]], "id": 23401729}, {"atb": [[3.05, 5.36], [3.9, 40.55], [7.6, 4.46], [5.8, 12.25], [4.8, 15.47], [9.6, 3.42], [1.03, 1.09], [9.8, 0.73], [1.01, 146.31], [13.5, 0.81], [4, 2.39], [1.14, 2]], "atl": [[230, 0.85], [330, 0.59], [130, 1], [65, 2.07], [900, 1.06], [690, 0.03]], "spl": [[1.01, 7.95]], "batb": [[9, 1.03, 1.09], [8, 1.14, 2], [7, 3.05, 5.36], [6, 3.9, 40.55], [5, 4, 2.39], [4, 4.8, 15.47], [3, 5.8, 12.25], [2, 7.6, 4.46], [1, 9.6, 3.42], [0, 9.8, 1.54]], "batl": [[3, 900, 1.09], [2, 330, 1.44], [1, 130, 1], [0, 65, 2.07]], "id": 27290030}], "img": true, "tv": 0}, {"id": "1.185781625", "marketDefinition": {"bspMarket": true, "turnInPlayEnabled": true, "persistenceEnabled": true, "marketBaseRate": 8, "eventId": "30738609", "eventTypeId": "7", "numberOfWinners": 1, "bettingType": "ODDS", "marketType": "WIN", "marketTime": "2021-07-30T06:40:00.000Z", "suspendTime": "2021-07-30T06:40:00.000Z", "bspReconciled": false, "complete": true, "inPlay": false, "crossMatching": true, "runnersVoidable": false, "numberOfActiveRunners": 10, "betDelay": 0, "status": "OPEN", "runners": [{"adjustmentFactor": 1.26, "status": "ACTIVE", "sortPriority": 1, "id": 24796689}, {"adjustmentFactor": 20.963, "status": "ACTIVE", "sortPriority": 2, "id": 3170090}, {"adjustmentFactor": 3.503, "status": "ACTIVE", "sortPriority": 3, "id": 16723088}, {"adjustmentFactor": 6.885, "status": "ACTIVE", "sortPriority": 4, "id": 26801352}, {"adjustmentFactor": 2.574, "status": "ACTIVE", "sortPriority": 5, "id": 17636540}, {"adjustmentFactor": 3.503, "status": "ACTIVE", "sortPriority": 6, "id": 27483333}, {"adjustmentFactor": 4.444, "status": "ACTIVE", "sortPriority": 7, "id": 8949255}, {"adjustmentFactor": 24.93, "status": "ACTIVE", "sortPriority": 8, "id": 37717808}, {"adjustmentFactor": 22.139, "status": "ACTIVE", "sortPriority": 9, "id": 39575126}, {"adjustmentFactor": 9.798, "status": "ACTIVE", "sortPriority": 10, "id": 27290355}], "regulators": ["MR_INT"], "venue": "Wagga", "countryCode": "AU", "discountAllowed": true, "timezone": "Australia/Sydney", "openDate": "2021-07-30T03:03:00.000Z", "version": 3938310120, "raceType": "Flat", "priceLadderDefinition": {"type": "CLASSIC"}}, "rc": [{"atb": [[1.81, 13.58], [1.53, 173.58], [1.89, 80.9], [2.12, 104.44], [2.52, 38.48], [2.32, 44.3], [2.72, 17], [2.92, 15.23], [1.03, 5.43], [2.94, 2.44], [1.01, 146.31], [2.16, 6.18], [1.2, 122], [1.14, 2]], "atl": [[34, 11.5], [16, 12.2], [12.5, 7.2], [13, 16.21], [9.2, 15.88], [18, 11.44], [7.2, 20.92], [55, 0.08], [900, 1.32], [690, 0.03]], "trd": [[3.05, 2.83], [2.94, 4], [2.92, 14.36], [3.4, 24.5]], "spl": [[1.01, 2.65]], "batb": [[8, 1.81, 13.58], [9, 1.53, 173.58], [7, 1.89, 80.9], [6, 2.12, 104.44], [5, 2.16, 6.18], [4, 2.32, 44.3], [3, 2.52, 38.48], [2, 2.72, 17], [1, 2.92, 15.23], [0, 2.94, 2.44]], "batl": [[7, 900, 1.43], [6, 34, 11.5], [5, 18, 11.44], [4, 16, 12.2], [3, 13, 16.21], [2, 12.5, 7.2], [1, 9.2, 15.88], [0, 7.2, 20.92]], "tv": 45.69, "id": 37717808}, {"atb": [[4.2, 29.69], [2.62, 52.47], [6, 18.4], [9.4, 8.57], [13, 5.22], [26, 1.26], [9.2, 7.64], [18, 1.84], [7.2, 20.22], [1.03, 1.09], [13.5, 0.53], [42, 0.25], [1.01, 146.31], [1.2, 122], [1.14, 2]], "atl": [[890, 2], [250, 0.5], [450, 0.42], [350, 0.36], [550, 0.34], [900, 0.53], [690, 0.03]], "batb": [[9, 1.2, 122], [8, 2.62, 52.47], [7, 4.2, 29.69], [6, 6, 18.4], [5, 7.2, 20.22], [4, 9.2, 7.64], [3, 9.4, 8.57], [2, 13, 5.75], [1, 18, 1.84], [0, 26, 1.51]], "batl": [[2, 900, 0.53], [1, 890, 2.37], [0, 450, 1.28]], "id": 24796689}, {"atb": [[2.94, 2.44], [2.12, 111.93], [2.52, 41.24], [2.32, 47.48], [2.72, 18.22], [2.92, 16.32], [1.03, 5.43], [2.2, 9.16], [3.35, 2], [1.01, 146.31], [3.05, 1.41], [1.2, 122], [1.14, 2]], "atl": [[11.5, 12.2], [34, 11.5], [8.8, 7.2], [17, 7.5], [13, 15.69], [9.2, 15.31], [18, 11.07], [7.2, 20.24], [5.3, 2.65], [6, 0.07], [900, 1.06], [690, 0.03]], "spl": [[1.01, 7.95]], "batb": [[9, 1.2, 122], [8, 2.12, 111.93], [7, 2.2, 9.16], [6, 2.32, 47.48], [5, 2.52, 41.24], [4, 2.72, 18.22], [3, 2.92, 16.32], [2, 2.94, 2.44], [1, 3.05, 1.41], [0, 3.35, 2]], "batl": [[9, 900, 1.09], [8, 34, 11.5], [7, 18, 11.07], [6, 17, 7.5], [5, 13, 15.69], [4, 11.5, 12.2], [3, 9.2, 15.31], [2, 8.8, 7.2], [1, 7.2, 20.31], [0, 5.3, 2.65]], "id": 27290355}, {"atb": [[8.4, 1.48], [4.2, 29.69], [2.62, 52.47], [5.3, 21.4], [8.2, 18.7], [15.5, 2.16], [6.2, 12.05], [10.5, 3.3], [5.1, 30.57], [1.03, 1.09], [16, 0.44], [22, 0.49], [1.01, 146.31], [1.2, 122], [1.14, 2]], "atl": [[290, 2], [400, 0.47], [200, 0.63], [100, 1.27], [300, 0.63], [440, 0.07], [690, 0.03]], "batb": [[9, 1.2, 122], [8, 2.62, 52.47], [7, 4.2, 29.69], [6, 5.1, 30.57], [5, 5.3, 21.4], [4, 6.2, 12.05], [3, 8.2, 18.7], [2, 8.4, 1.48], [1, 10.5, 3.3], [0, 15.5, 3.09]], "batl": [[3, 690, 0.1], [2, 400, 1.1], [1, 290, 2.63], [0, 100, 1.27]], "id": 8949255}, {"atb": [[4.2, 29.69], [2.62, 52.47], [6, 18.4], [9.4, 8.57], [13, 5.22], [26, 1.26], [9.2, 7.64], [18, 1.84], [7.2, 20.22], [1.03, 1.09], [13.5, 0.53], [42, 0.25], [1.01, 146.31], [1.2, 122], [1.14, 2]], "atl": [[890, 2], [250, 0.5], [450, 0.42], [350, 0.36], [550, 0.34], [400, 0.07], [900, 0.53], [690, 0.03]], "batb": [[9, 1.2, 122], [8, 2.62, 52.47], [7, 4.2, 29.69], [6, 6, 18.4], [5, 7.2, 20.22], [4, 9.2, 7.64], [3, 9.4, 8.57], [2, 13, 5.75], [1, 18, 1.84], [0, 26, 1.51]], "batl": [[2, 900, 0.53], [1, 890, 2.37], [0, 450, 1.35]], "id": 17636540}, {"atb": [[2.62, 52.47], [3.05, 44.88], [4.5, 20.57], [8.2, 0.88], [1.01, 146.31], [3.5, 50.14], [6, 6.27], [5, 15.67], [4, 20.89], [8, 4.48], [1.03, 1.09], [2.34, 8.2], [10.5, 1.06], [5.1, 0.85], [1.2, 122], [1.14, 2]], "atl": [[60, 7.2], [80, 12.2], [250, 0.76], [40, 3.22], [150, 1.26], [75, 1.7], [20, 2], [21, 10.6], [48, 0.07], [900, 0.79], [690, 0.03]], "batb": [[9, 2.34, 8.2], [8, 2.62, 52.47], [7, 3.05, 44.88], [6, 3.5, 50.14], [5, 4, 20.89], [4, 4.5, 20.57], [1, 8, 5.36], [3, 5, 16.52], [2, 6, 6.27], [0, 10.5, 1.06]], "batl": [[7, 900, 1.58], [6, 150, 1.26], [5, 80, 12.2], [4, 75, 1.7], [3, 60, 7.27], [2, 40, 3.22], [1, 21, 10.6], [0, 20, 2]], "id": 27483333}, {"atb": [[3.25, 2], [2.22, 59.02], [1.73, 126.03], [2.76, 30.91], [2.96, 13.87], [3.4, 11.33], [2.36, 79.99], [2.56, 34.86], [1.03, 1.09], [1.81, 13.58], [3.45, 2.08], [1.01, 146.31], [2.42, 5.05], [3.35, 1.28], [1.2, 122], [1.14, 2]], "atl": [[34, 11.5], [21, 12.2], [16, 7.2], [26, 8.03], [13, 11.15], [9.2, 16.32], [18, 11.8], [9.6, 0.07], [900, 1.59], [690, 0.03]], "trd": [[3.4, 24.37]], "spl": [[1.01, 2.65]], "batb": [[9, 2.22, 59.02], [8, 2.36, 79.99], [7, 2.42, 5.05], [6, 2.56, 34.86], [5, 2.76, 30.91], [4, 2.96, 13.87], [3, 3.25, 2], [2, 3.35, 1.28], [1, 3.4, 11.33], [0, 3.45, 2.08]], "batl": [[7, 900, 1.62], [6, 34, 11.5], [5, 26, 8.03], [4, 21, 12.2], [3, 18, 11.8], [2, 16, 7.2], [1, 13, 11.22], [0, 9.2, 16.32]], "tv": 24.37, "id": 39575126}, {"atb": [[2.62, 52.47], [2.74, 52.87], [3.9, 24.83], [3.5, 25.07], [6, 6.27], [3, 62.68], [5, 7.84], [4, 20.89], [6.8, 1.05], [6.6, 3.72], [1.03, 1.09], [2.24, 8.87], [8.2, 1.4], [4.9, 0.88], [1.01, 146.31], [1.2, 122], [1.14, 2]], "atl": [[95, 12.2], [65, 7.2], [24, 5.46], [38, 3.39], [140, 1.36], [70, 2.73], [23, 2], [900, 1.06], [690, 0.03]], "batb": [[9, 2.74, 52.87], [8, 3, 62.68], [7, 3.5, 25.07], [6, 3.9, 24.83], [5, 4, 21.77], [4, 5, 7.84], [3, 6, 6.27], [2, 6.6, 3.72], [1, 6.8, 1.05], [0, 8.2, 1.4]], "batl": [[7, 900, 1.09], [6, 140, 1.36], [5, 95, 12.2], [4, 70, 2.73], [3, 65, 7.2], [2, 38, 3.39], [1, 24, 5.46], [0, 23, 2]], "id": 16723088}, {"atb": [[4.2, 29.69], [18.5, 0.58], [7, 12.62], [4.6, 60.38], [13.5, 0.53], [1.03, 1.09], [2.62, 52.47], [1.01, 146.31], [13, 2.61], [9.2, 3.82], [7.2, 10.11], [5.6, 13.63], [3.85, 3.86], [1.2, 122], [1.14, 2]], "atl": [[170, 2], [380, 0.5], [180, 0.7], [90, 1.41], [280, 0.67], [310, 0.07], [690, 0.03]], "batb": [[9, 2.62, 52.47], [8, 3.85, 3.86], [7, 4.2, 29.69], [6, 4.6, 60.38], [5, 5.6, 13.63], [4, 7, 12.62], [3, 7.2, 10.11], [2, 9.2, 3.82], [1, 13, 2.61], [0, 13.5, 1.11]], "batl": [[3, 690, 0.6], [2, 280, 1.37], [1, 170, 2], [0, 90, 1.41]], "id": 26801352}, {"atb": [[2.62, 52.47], [3.05, 44.88], [4.5, 20.57], [8.2, 0.88], [1.01, 146.31], [3.5, 50.14], [6, 6.27], [5, 15.67], [4, 20.89], [8, 4.48], [1.03, 1.09], [2.34, 8.2], [10.5, 1.06], [4.9, 0.88], [1.2, 122], [1.14, 2]], "atl": [[150, 13.46], [110, 7.2], [250, 0.76], [40, 3.22], [75, 1.7], [38, 2], [900, 1.32], [690, 0.03]], "spl": [[1.01, 9.01]], "batb": [[9, 2.34, 8.2], [8, 2.62, 52.47], [7, 3.05, 44.88], [6, 3.5, 50.14], [5, 4, 20.89], [4, 4.5, 21.45], [1, 8, 5.36], [3, 5, 15.67], [2, 6, 6.27], [0, 10.5, 1.06]], "batl": [[4, 150, 13.46], [5, 900, 2.11], [3, 110, 7.2], [2, 75, 1.7], [1, 40, 3.22], [0, 38, 2]], "id": 3170090}], "img": true, "tv": 70.06}, {"id": "1.185784051", "marketDefinition": {"bspMarket": true, "turnInPlayEnabled": true, "persistenceEnabled": true, "marketBaseRate": 6, "eventId": "30738903", "eventTypeId": "7", "numberOfWinners": 1, "bettingType": "ODDS", "marketType": "WIN", "marketTime": "2021-07-31T04:18:00.000Z", "suspendTime": "2021-07-31T04:18:00.000Z", "bspReconciled": false, "complete": true, "inPlay": false, "crossMatching": false, "runnersVoidable": false, "numberOfActiveRunners": 5, "betDelay": 0, "status": "OPEN", "runners": [{"adjustmentFactor": 3.226, "status": "ACTIVE", "sortPriority": 1, "id": 11266998}, {"adjustmentFactor": 16.667, "status": "ACTIVE", "sortPriority": 2, "id": 8461425}, {"adjustmentFactor": 48.361, "status": "ACTIVE", "sortPriority": 3, "id": 24783295}, {"adjustmentFactor": 13.889, "status": "ACTIVE", "sortPriority": 4, "id": 35609632}, {"adjustmentFactor": 17.857, "status": "ACTIVE", "sortPriority": 5, "id": 27342054}], "regulators": ["MR_INT"], "venue": "Belmont", "countryCode": "AU", "discountAllowed": true, "timezone": "Australia/Perth", "openDate": "2021-07-31T04:18:00.000Z", "version": 3938452056, "raceType": "Flat", "priceLadderDefinition": {"type": "CLASSIC"}}, "rc": [{"atb": [[5.6, 2.97], [1.01, 166.31], [3.75, 153.96], [4, 105.85], [5, 52.92], [5.5, 7.63], [1.03, 322], [1.02, 2]], "atl": [[22, 9.81], [60, 3.49], [34, 6.24], [16, 13.73], [690, 0.03]], "trd": [[5.5, 31.79]], "batb": [[0, 5.6, 2.97], [7, 1.01, 166.31], [4, 3.75, 153.96], [3, 4, 105.85], [2, 5, 52.92], [6, 1.02, 2], [5, 1.03, 322], [1, 5.5, 7.63]], "batl": [[1, 22, 9.81], [3, 60, 3.49], [2, 34, 6.24], [0, 16, 13.73], [4, 690, 0.03]], "tv": 31.79, "id": 8461425}, {"atb": [[1.81, 3.96], [1.01, 168.01], [1.65, 488.53], [1.75, 282.26], [1.6, 705.66], [1.8, 105.82], [1.02, 2]], "atl": [[2, 105.95], [5.4, 46.81], [3.7, 76.28], [3.2, 93.61], [4.4, 60.57], [50, 2.65], [20, 2.65], [5, 2.65], [85, 5], [690, 0.03]], "trd": [[1.8, 52.98]], "batb": [[6, 1.01, 168.01], [5, 1.02, 2], [4, 1.6, 705.66], [3, 1.65, 488.53], [2, 1.75, 282.26], [1, 1.8, 105.82], [0, 1.81, 3.96]], "batl": [[9, 690, 0.03], [8, 85, 5], [7, 50, 2.65], [6, 20, 2.65], [5, 5.4, 46.81], [4, 5, 2.65], [3, 4.4, 60.57], [2, 3.7, 76.28], [1, 3.2, 93.61], [0, 2, 105.95]], "tv": 52.98, "id": 24783295}, {"atb": [[34, 0.21], [1.03, 322], [1.01, 166.31], [15.5, 30.73], [18, 19.66], [26, 8.91], [32, 3.59], [1.02, 2]], "atl": [[500, 0.39], [400, 0.48], [200, 0.96], [300, 0.64], [690, 0.03]], "batb": [[0, 32, 3.8], [4, 1.03, 322], [6, 1.01, 166.31], [3, 15.5, 30.73], [2, 18, 19.66], [5, 1.02, 2], [1, 26, 8.91]], "batl": [[1, 690, 0.9], [0, 300, 1.6]], "id": 11266998}, {"atb": [[7.2, 2.52], [1.02, 2], [5, 83.56], [1.01, 166.31], [4.5, 127.33], [7, 18.57], [6, 44.56], [1.03, 322]], "atl": [[27, 7.39], [44, 4.47], [85, 2.29], [18.5, 10.97], [690, 0.03]], "batb": [[0, 7.2, 2.52], [6, 1.02, 2], [7, 1.01, 166.31], [4, 4.5, 127.33], [3, 5, 83.56], [2, 6, 44.56], [1, 7, 18.57], [5, 1.03, 322]], "batl": [[1, 27, 7.39], [2, 44, 4.47], [4, 690, 0.03], [3, 85, 2.29], [0, 18.5, 10.97]], "id": 35609632}, {"atb": [[5.4, 1.33], [1.01, 166.31], [3.65, 158.37], [3.9, 108.54], [5.3, 15.35], [4.8, 55.22], [1.03, 322], [1.02, 2]], "atl": [[21, 10.42], [15.5, 15.7], [55, 3.86], [32, 6.72], [690, 0.03]], "trd": [[5.4, 3.08], [5.3, 18.11], [4.9, 26.49]], "batb": [[7, 1.01, 166.31], [6, 1.02, 2], [5, 1.03, 322], [4, 3.65, 158.37], [3, 3.9, 108.54], [2, 4.8, 55.22], [1, 5.3, 15.35], [0, 5.4, 1.33]], "batl": [[1, 21, 10.42], [0, 15.5, 15.7], [3, 55, 3.86], [2, 32, 6.72], [4, 690, 0.03]], "tv": 47.68, "id": 27342054}], "img": true, "tv": 132.45}, {"id": "1.185783395", "marketDefinition": {"bspMarket": true, "turnInPlayEnabled": true, "persistenceEnabled": true, "marketBaseRate": 6, "eventId": "30738738", "eventTypeId": "7", "numberOfWinners": 1, "bettingType": "ODDS", "marketType": "WIN", "marketTime": "2021-07-31T01:28:00.000Z", "suspendTime": "2021-07-31T01:28:00.000Z", "bspReconciled": false, "complete": true, "inPlay": false, "crossMatching": false, "runnersVoidable": false, "numberOfActiveRunners": 10, "betDelay": 0, "status": "OPEN", "runners": [{"adjustmentFactor": 6.098, "status": "ACTIVE", "sortPriority": 1, "id": 39000356}, {"adjustmentFactor": 2.326, "status": "ACTIVE", "sortPriority": 2, "id": 17103564}, {"adjustmentFactor": 19.763, "status": "ACTIVE", "sortPriority": 3, "id": 25887511}, {"adjustmentFactor": 5.65, "status": "ACTIVE", "sortPriority": 4, "id": 19376209}, {"adjustmentFactor": 8.333, "status": "ACTIVE", "sortPriority": 5, "id": 512763}, {"adjustmentFactor": 3.759, "status": "ACTIVE", "sortPriority": 6, "id": 24313744}, {"adjustmentFactor": 7.905, "status": "ACTIVE", "sortPriority": 7, "id": 40363951}, {"adjustmentFactor": 6.579, "status": "ACTIVE", "sortPriority": 8, "id": 24405475}, {"adjustmentFactor": 1.923, "status": "ACTIVE", "sortPriority": 9, "id": 40363952}, {"adjustmentFactor": 37.664, "status": "ACTIVE", "sortPriority": 10, "id": 40363953}, {"adjustmentFactor": 4.547, "status": "REMOVED", "sortPriority": 11, "removalDate": "2021-07-28T05:58:04.000Z", "id": 22757556}, {"adjustmentFactor": 9.384, "status": "REMOVED", "sortPriority": 12, "removalDate": "2021-07-28T10:28:57.000Z", "id": 18673998}, {"adjustmentFactor": 2.499, "status": "REMOVED", "sortPriority": 13, "removalDate": "2021-07-29T04:49:15.000Z", "id": 11278269}], "regulators": ["MR_INT"], "venue": "Eagle Farm", "countryCode": "AU", "discountAllowed": true, "timezone": "Australia/Queensland", "openDate": "2021-07-31T01:28:00.000Z", "version": 3938468937, "raceType": "Flat", "priceLadderDefinition": {"type": "CLASSIC"}}, "rc": [{"atb": [[1.01, 166.31], [48, 0.15], [30, 6.36], [26, 12.9], [21, 16.12], [46, 4.78], [32, 6.93], [1.02, 2]], "atl": [[500, 0.4], [400, 0.51], [600, 0.34], [300, 0.68], [690, 0.03]], "spl": [[1.01, 10.6]], "batb": [[6, 1.01, 166.31], [0, 46, 4.93], [5, 1.02, 2], [4, 21, 16.12], [3, 26, 12.9], [2, 30, 6.36], [1, 32, 6.93]], "batl": [[1, 690, 0.77], [0, 400, 1.19]], "id": 40363952}, {"atb": [[1.93, 340.86], [2.2, 176.11], [1.98, 323.47], [2.06, 199.37], [1.01, 166.31], [2.16, 42.38], [2.32, 3.09], [2.26, 21.19], [1.02, 2]], "atl": [[11, 20.66], [3.35, 2.65], [8.4, 27.91], [5.2, 49.17], [6.4, 38.25], [3.6, 2.65], [4.6, 15.89], [690, 0.03]], "trd": [[2.4, 52.98], [2.32, 2.91], [2.3, 19.11]], "batb": [[8, 1.01, 166.31], [6, 1.93, 340.86], [5, 1.98, 323.47], [4, 2.06, 199.37], [2, 2.2, 176.11], [7, 1.02, 2], [3, 2.16, 42.38], [1, 2.26, 21.19], [0, 2.32, 3.09]], "batl": [[6, 11, 20.66], [7, 690, 0.03], [5, 8.4, 27.91], [4, 6.4, 38.25], [3, 5.2, 49.17], [2, 4.6, 15.89], [1, 3.6, 2.65], [0, 3.35, 2.65]], "tv": 75, "id": 40363953}, {"atb": [[7.8, 47.59], [8.8, 41.49], [13, 17.98], [1.01, 166.31], [13.5, 2], [9.8, 24.51], [11.5, 6.36], [10, 6.36], [1.02, 2]], "atl": [[240, 0.84], [340, 0.59], [140, 1.45], [70, 2.91], [690, 0.03]], "batb": [[8, 1.01, 166.31], [6, 7.8, 47.59], [5, 8.8, 41.49], [1, 13, 17.98], [7, 1.02, 2], [4, 9.8, 24.51], [3, 10, 6.36], [2, 11.5, 6.36], [0, 13.5, 2]], "batl": [[3, 690, 0.03], [2, 340, 1.43], [1, 140, 1.45], [0, 70, 2.91]], "id": 24405475}, {"atb": [[1.01, 166.31], [11.5, 2.2], [7, 51.81], [11, 20.72], [9, 32.26], [8, 44.41], [1.02, 2]], "atl": [[200, 1.06], [100, 2.14], [50, 4.32], [300, 0.71], [690, 0.03]], "trd": [[10, 8.48], [10.5, 12.71]], "batb": [[6, 1.01, 166.31], [5, 1.02, 2], [4, 7, 51.81], [3, 8, 44.41], [2, 9, 32.26], [1, 11, 20.72], [0, 11.5, 2.2]], "batl": [[3, 690, 0.74], [2, 200, 1.06], [1, 100, 2.14], [0, 50, 4.32]], "tv": 21.19, "id": 40363951}, {"atb": [[10.5, 22.63], [1.01, 166.31], [15, 1.89], [14.5, 6.36], [8.2, 44.78], [9.2, 39.32], [14, 16.53], [1.02, 2]], "atl": [[360, 0.56], [160, 1.27], [80, 2.56], [260, 0.78], [690, 0.03]], "batb": [[7, 1.01, 166.31], [3, 10.5, 22.63], [0, 15, 1.89], [6, 1.02, 2], [5, 8.2, 44.78], [4, 9.2, 39.32], [1, 14.5, 6.36], [2, 14, 16.53]], "batl": [[3, 690, 0.03], [2, 360, 1.34], [1, 160, 1.27], [0, 80, 2.56]], "id": 39000356}, {"atb": [[1.01, 166.31], [40, 0.18], [30, 6.36], [22, 12.36], [18.5, 14.83], [32, 1.48], [27, 6.65], [38, 4.68], [1.02, 2]], "atl": [[250, 1.02], [450, 0.57], [350, 0.73], [550, 0.46], [690, 0.03]], "trd": [[36, 11.66]], "batb": [[7, 1.01, 166.31], [0, 38, 4.86], [6, 1.02, 2], [5, 18.5, 14.83], [4, 22, 12.36], [2, 30, 6.36], [3, 27, 6.65], [1, 32, 1.48]], "batl": [[2, 690, 0.49], [1, 450, 1.3], [0, 250, 1.02]], "tv": 11.66, "id": 17103564}, {"atb": [[1.01, 166.31], [8.6, 28.39], [6.6, 57.78], [7.6, 49.03], [10, 23.97], [15, 0.48], [14.5, 6.36], [1.02, 2]], "atl": [[46, 4.47], [180, 1.12], [90, 2.26], [280, 0.72], [15.5, 2.65], [690, 0.03]], "batb": [[6, 1.01, 166.31], [2, 8.6, 28.39], [5, 1.02, 2], [4, 6.6, 57.78], [3, 7.6, 49.03], [1, 10, 23.97], [0, 14.5, 6.84]], "batl": [[4, 690, 0.75], [3, 180, 1.12], [2, 90, 2.26], [1, 46, 4.47], [0, 15.5, 2.65]], "id": 512763}, {"atb": [[15.5, 1.99], [1.01, 166.31], [8.6, 42.58], [15, 15.41], [11.5, 20.54], [9.6, 37.62], [12.5, 6.36], [1.02, 2]], "atl": [[380, 0.53], [180, 1.12], [90, 2.26], [280, 0.72], [690, 0.03]], "batb": [[7, 1.01, 166.31], [6, 1.02, 2], [5, 8.6, 42.58], [4, 9.6, 37.62], [3, 11.5, 20.54], [2, 12.5, 6.36], [1, 15, 15.41], [0, 15.5, 1.99]], "batl": [[3, 690, 0.03], [2, 380, 1.25], [1, 180, 1.12], [0, 90, 2.26]], "id": 19376209}, {"atb": [[12.5, 28.14], [1.01, 166.31], [23, 1.76], [1.02, 2], [15, 23.11], [22, 10.27], [17.5, 13.07], [19, 6.36]], "atl": [[250, 0.81], [450, 0.45], [350, 0.58], [150, 1.35], [690, 0.03]], "batb": [[7, 1.01, 166.31], [5, 12.5, 28.14], [6, 1.02, 2], [4, 15, 23.11], [3, 17.5, 13.07], [2, 19, 6.36], [1, 22, 10.27], [0, 23, 1.76]], "batl": [[2, 690, 0.48], [1, 350, 1.39], [0, 150, 1.35]], "id": 24313744}, {"atb": [[3.75, 78.45], [3.5, 129.43], [3.25, 143.82], [1.01, 166.31], [4.3, 3.25], [4.2, 67.41], [3.4, 45.03], [3.6, 8.48], [1.02, 2]], "atl": [[11.5, 19.15], [23, 9.14], [36, 5.74], [16.5, 12.97], [5.5, 4.77], [690, 0.03]], "batb": [[8, 1.01, 166.31], [6, 3.25, 143.82], [4, 3.5, 129.43], [2, 3.75, 78.45], [0, 4.3, 3.25], [7, 1.02, 2], [5, 3.4, 45.03], [3, 3.6, 8.48], [1, 4.2, 67.41]], "batl": [[1, 11.5, 19.15], [5, 690, 0.03], [4, 36, 5.74], [3, 23, 9.14], [2, 16.5, 12.97], [0, 5.5, 4.77]], "id": 25887511}], "img": true, "tv": 107.85}, {"id": "1.185781641", "marketDefinition": {"bspMarket": true, "turnInPlayEnabled": true, "persistenceEnabled": true, "marketBaseRate": 8, "eventId": "30738618", "eventTypeId": "7", "numberOfWinners": 1, "bettingType": "ODDS", "marketType": "WIN", "marketTime": "2021-07-30T09:42:00.000Z", "suspendTime": "2021-07-30T09:42:00.000Z", "bspReconciled": false, "complete": true, "inPlay": false, "crossMatching": true, "runnersVoidable": false, "numberOfActiveRunners": 8, "betDelay": 0, "status": "OPEN", "runners": [{"adjustmentFactor": 5.59, "status": "ACTIVE", "sortPriority": 1, "id": 28309627}, {"adjustmentFactor": 0.351, "status": "ACTIVE", "sortPriority": 2, "id": 21912599}, {"adjustmentFactor": 0.461, "status": "ACTIVE", "sortPriority": 3, "id": 11037032}, {"adjustmentFactor": 22.134, "status": "ACTIVE", "sortPriority": 4, "id": 13283260}, {"adjustmentFactor": 26.599, "status": "ACTIVE", "sortPriority": 5, "id": 17668168}, {"adjustmentFactor": 39.965, "status": "ACTIVE", "sortPriority": 6, "id": 16124583}, {"adjustmentFactor": 0.461, "status": "ACTIVE", "sortPriority": 7, "id": 9465534}, {"adjustmentFactor": 4.439, "status": "ACTIVE", "sortPriority": 8, "id": 8528034}], "regulators": ["MR_INT"], "venue": "Newcastle", "countryCode": "AU", "discountAllowed": true, "timezone": "Australia/Sydney", "openDate": "2021-07-30T07:10:00.000Z", "version": 3938308170, "raceType": "Flat", "priceLadderDefinition": {"type": "CLASSIC"}}, "rc": [{"atb": [[1.52, 13.79], [1.3, 392.03], [1.5, 117.61], [1.7, 42.01], [1.6, 49], [1.4, 147.01], [1.01, 146.31], [1.14, 2]], "atl": [[2.8, 0.07], [3.75, 47.08], [3.25, 57.54], [5.5, 43.16], [4.5, 55.49], [85, 5], [690, 0.03]], "spl": [[2.5, 10.6]], "batb": [[7, 1.01, 146.31], [6, 1.14, 2], [5, 1.3, 392.03], [4, 1.4, 147.01], [3, 1.5, 117.61], [2, 1.52, 13.79], [1, 1.6, 49], [0, 1.7, 42.01]], "batl": [[5, 690, 0.03], [4, 85, 5], [3, 5.5, 43.16], [2, 4.5, 55.49], [1, 3.75, 47.08], [0, 3.25, 57.61]], "id": 16124583}, {"atb": [[7.4, 1.12], [13, 4.9], [26, 1.18], [9.2, 7.17], [18, 1.73], [7.2, 18.97], [1.01, 146.31], [1.14, 2]], "atl": [[250, 0.52], [450, 0.43], [350, 0.37], [550, 0.35], [690, 0.03]], "batb": [[7, 1.01, 146.31], [6, 1.14, 2], [5, 7.2, 18.97], [4, 7.4, 1.12], [3, 9.2, 7.17], [2, 13, 4.9], [1, 18, 1.73], [0, 26, 1.18]], "batl": [[1, 690, 0.38], [0, 450, 1.32]], "id": 21912599}, {"atb": [[7.4, 3.72], [3.25, 3.18], [3.65, 22.19], [6.6, 5.25], [3.15, 54.7], [5.3, 6.84], [4.3, 17.82], [1.01, 146.31], [1.14, 2]], "atl": [[28, 4.79], [46, 2.88], [180, 1.09], [90, 2.18], [690, 0.03]], "batb": [[8, 1.01, 146.31], [7, 1.14, 2], [6, 3.15, 54.7], [5, 3.25, 3.18], [4, 3.65, 22.19], [3, 4.3, 17.82], [2, 5.3, 6.84], [1, 6.6, 5.25], [0, 7.4, 3.72]], "batl": [[4, 690, 0.03], [3, 180, 1.09], [2, 90, 2.18], [1, 46, 2.88], [0, 28, 4.79]], "id": 28309627}, {"atb": [[1.71, 10.1], [2.16, 25.34], [1.68, 172.96], [1.78, 75.39], [1.88, 66.83], [1.98, 30], [1.01, 146.31], [1.14, 2]], "atl": [[8.2, 26.98], [10.5, 20.44], [6.2, 24.9], [5.1, 31.58], [5.3, 0.07], [690, 0.03]], "spl": [[5.4, 5.83]], "batb": [[7, 1.01, 146.31], [6, 1.14, 2], [5, 1.68, 172.96], [4, 1.71, 10.1], [3, 1.78, 75.39], [2, 1.88, 66.83], [1, 1.98, 30], [0, 2.16, 25.34]], "batl": [[4, 690, 0.03], [3, 10.5, 20.44], [2, 8.2, 26.98], [1, 6.2, 24.97], [0, 5.1, 31.58]], "id": 17668168}, {"atb": [[6.6, 1.28], [1.01, 146.31], [8.4, 7.95], [11, 5.88], [22, 1.4], [6.4, 21.78], [16, 1.96], [1.14, 2]], "atl": [[500, 0.39], [400, 0.49], [200, 0.65], [300, 0.43], [690, 0.03]], "batb": [[7, 1.01, 146.31], [6, 1.14, 2], [5, 6.4, 21.78], [4, 6.6, 1.28], [3, 8.4, 7.95], [2, 11, 5.88], [1, 16, 1.96], [0, 22, 1.4]], "batl": [[1, 690, 0.91], [0, 300, 1.08]], "id": 11037032}, {"atb": [[4, 2.39], [3.9, 40.55], [7.6, 4.46], [5.8, 12.25], [4.8, 15.47], [9.6, 3.42], [1.01, 146.31], [1.14, 2]], "atl": [[230, 0.85], [330, 0.59], [130, 1], [65, 2.09], [690, 0.03]], "spl": [[10, 4.24]], "batb": [[7, 1.01, 146.31], [6, 1.14, 2], [5, 3.9, 40.55], [4, 4, 2.39], [3, 4.8, 15.47], [2, 5.8, 12.25], [1, 7.6, 4.46], [0, 9.6, 3.42]], "batl": [[3, 690, 0.03], [2, 330, 1.44], [1, 130, 1], [0, 65, 2.09]], "id": 13283260}, {"atb": [[5.3, 1.67], [1.01, 146.31], [15.5, 2.03], [8.2, 8.17], [6.2, 11.31], [10.5, 3.09], [5.1, 28.69], [1.14, 2]], "atl": [[400, 0.49], [200, 0.65], [100, 1.31], [300, 0.65], [320, 0.07], [690, 0.03]], "batb": [[7, 1.01, 146.31], [6, 1.14, 2], [5, 5.1, 28.69], [4, 5.3, 1.67], [3, 6.2, 11.31], [2, 8.2, 8.17], [1, 10.5, 3.09], [0, 15.5, 2.03]], "batl": [[2, 690, 0.59], [1, 300, 1.3], [0, 100, 1.31]], "id": 8528034}, {"atb": [[1.01, 146.31], [5.1, 28.69], [5.3, 1.67], [15.5, 2.03], [8.2, 8.17], [6.2, 11.31], [10.5, 3.09], [1.14, 2]], "atl": [[440, 0.07], [400, 0.49], [200, 0.65], [100, 1.31], [300, 0.65], [690, 0.03]], "spl": [[1.01, 7.95]], "batb": [[7, 1.01, 146.31], [5, 5.1, 28.69], [6, 1.14, 2], [4, 5.3, 1.67], [3, 6.2, 11.31], [2, 8.2, 8.17], [1, 10.5, 3.09], [0, 15.5, 2.03]], "batl": [[2, 690, 0.59], [1, 300, 1.3], [0, 100, 1.31]], "id": 9465534}], "img": true, "tv": 0}, {"id": "1.185788099", "marketDefinition": {"bspMarket": true, "turnInPlayEnabled": true, "persistenceEnabled": true, "marketBaseRate": 6, "eventId": "30739095", "eventTypeId": "7", "numberOfWinners": 1, "bettingType": "ODDS", "marketType": "WIN", "marketTime": "2021-07-30T09:15:00.000Z", "suspendTime": "2021-07-30T09:15:00.000Z", "bspReconciled": false, "complete": true, "inPlay": false, "crossMatching": true, "runnersVoidable": false, "numberOfActiveRunners": 10, "betDelay": 0, "status": "OPEN", "runners": [{"adjustmentFactor": 38.092, "status": "ACTIVE", "sortPriority": 1, "id": 18294721}, {"adjustmentFactor": 7.613, "status": "ACTIVE", "sortPriority": 2, "id": 24783800}, {"adjustmentFactor": 3.705, "status": "ACTIVE", "sortPriority": 3, "id": 12247499}, {"adjustmentFactor": 5.779, "status": "ACTIVE", "sortPriority": 4, "id": 12326722}, {"adjustmentFactor": 11.717, "status": "ACTIVE", "sortPriority": 5, "id": 11988741}, {"adjustmentFactor": 3.705, "status": "ACTIVE", "sortPriority": 6, "id": 28161181}, {"adjustmentFactor": 13.294, "status": "ACTIVE", "sortPriority": 7, "id": 12502278}, {"adjustmentFactor": 9.025, "status": "ACTIVE", "sortPriority": 8, "id": 19647792}, {"adjustmentFactor": 1.29, "status": "ACTIVE", "sortPriority": 9, "id": 11565371}, {"adjustmentFactor": 5.779, "status": "ACTIVE", "sortPriority": 10, "id": 10561631}], "regulators": ["MR_INT"], "venue": "Gloucester Park", "countryCode": "AU", "discountAllowed": true, "timezone": "Australia/Perth", "openDate": "2021-07-30T09:15:00.000Z", "version": 3938344264, "raceType": "Flat", "priceLadderDefinition": {"type": "CLASSIC"}}, "rc": [{"atb": [[13, 3.92], [8.2, 26.13], [10.5, 9.9], [9.2, 11.47], [18, 2.77], [1.01, 258.54], [1.14, 2]], "atl": [[250, 0.52], [450, 0.43], [350, 0.56], [150, 0.87], [690, 0.03]], "batb": [[6, 1.01, 258.54], [5, 1.14, 2], [4, 8.2, 26.13], [3, 9.2, 11.47], [2, 10.5, 9.9], [1, 13, 3.92], [0, 18, 2.77]], "batl": [[1, 690, 1.02], [0, 250, 1.39]], "id": 10561631}, {"atb": [[2.62, 116.16], [1.01, 258.54], [2.82, 51.7], [3.3, 20.45], [2.72, 54.7], [2.92, 24.5], [1.14, 2]], "atl": [[9.6, 0.07], [8.8, 16.6], [17, 12.14], [6, 2.65], [24, 8.44], [12, 11.77], [690, 0.03]], "spl": [[1.01, 7.95]], "batb": [[6, 1.01, 258.54], [4, 2.62, 116.16], [2, 2.82, 51.7], [3, 2.72, 54.7], [1, 2.92, 24.5], [0, 3.3, 20.45], [5, 1.14, 2]], "batl": [[2, 12, 11.84], [5, 690, 0.03], [3, 17, 12.14], [1, 8.8, 16.6], [4, 24, 8.44], [0, 6, 2.65]], "id": 24783800}, {"atb": [[3.65, 35.51], [3.4, 78.41], [1.01, 258.54], [4.3, 14.26], [3.9, 32.44], [5.3, 10.94], [1.14, 2]], "atl": [[23, 5.89], [36, 5.55], [65, 3.04], [16.5, 8.35], [690, 0.03]], "batb": [[6, 1.01, 258.54], [4, 3.4, 78.41], [3, 3.65, 35.51], [1, 4.3, 14.26], [2, 3.9, 32.44], [0, 5.3, 10.94], [5, 1.14, 2]], "batl": [[3, 65, 3.04], [2, 36, 5.55], [1, 23, 5.89], [4, 690, 0.03], [0, 16.5, 8.35]], "id": 12502278}, {"atb": [[1.01, 258.54], [8.2, 13.07], [7.2, 30.35], [15.5, 3.24], [10.5, 4.95], [9.2, 11.47], [1.14, 2]], "atl": [[440, 0.07], [400, 0.49], [200, 0.65], [100, 1.31], [300, 0.65], [690, 0.03]], "batb": [[6, 1.01, 258.54], [4, 7.2, 30.35], [3, 8.2, 13.07], [5, 1.14, 2], [2, 9.2, 11.47], [1, 10.5, 4.95], [0, 15.5, 3.24]], "batl": [[2, 690, 0.59], [1, 300, 1.3], [0, 100, 1.31]], "id": 12247499}, {"atb": [[26, 3.76], [21, 9.41], [42, 1.15], [80, 0.59], [32, 3.04], [1.01, 258.54], [1.14, 2]], "atl": [[1000, 0.2], [940, 0.21], [840, 0.15], [740, 0.17], [690, 0.03]], "batb": [[5, 1.01, 258.54], [4, 1.14, 2], [3, 21, 9.41], [2, 26, 3.76], [1, 32, 3.04], [0, 42, 1.74]], "batl": [[0, 1000, 0.76]], "id": 11565371}, {"atb": [[3.9, 64.89], [1.01, 258.54], [5.3, 10.94], [4.3, 28.51], [4.8, 24.76], [6.6, 8.4], [1.14, 2]], "atl": [[34, 0.07], [28, 4.79], [46, 2.88], [180, 1.09], [90, 2.18], [690, 0.03]], "batb": [[6, 1.01, 258.54], [4, 3.9, 64.89], [3, 4.3, 28.51], [2, 4.8, 24.76], [1, 5.3, 10.94], [5, 1.14, 2], [0, 6.6, 8.4]], "batl": [[1, 46, 2.95], [4, 690, 0.03], [3, 180, 1.09], [2, 90, 2.18], [0, 28, 4.79]], "id": 12326722}, {"atb": [[2.96, 48], [3.9, 16.22], [3.15, 43.76], [3.4, 19.6], [2.86, 101.17], [1.01, 258.54], [1.14, 2]], "atl": [[26, 7.77], [13, 10.79], [42, 4.74], [18, 7.62], [15, 0.07], [690, 0.03]], "batb": [[6, 1.01, 258.54], [5, 1.14, 2], [4, 2.86, 101.17], [3, 2.96, 48], [2, 3.15, 43.76], [1, 3.4, 19.6], [0, 3.9, 16.22]], "batl": [[4, 690, 0.03], [3, 42, 4.74], [2, 26, 7.77], [1, 18, 7.69], [0, 13, 10.79]], "id": 11988741}, {"atb": [[3.75, 17.11], [3.5, 37.64], [3.25, 41.82], [3, 94.09], [1.01, 258.54], [4.5, 13.44], [1.14, 2]], "atl": [[14.5, 9.59], [19.5, 7], [29, 6.93], [48, 4.13], [690, 0.03]], "batb": [[6, 1.01, 258.54], [4, 3, 94.09], [3, 3.25, 41.82], [2, 3.5, 37.64], [1, 3.75, 17.11], [0, 4.5, 13.44], [5, 1.14, 2]], "batl": [[1, 19.5, 7], [0, 14.5, 9.59], [4, 690, 0.03], [3, 48, 4.13], [2, 29, 6.93]], "id": 19647792}, {"atb": [[1.01, 258.54], [8.2, 13.07], [7.2, 30.35], [15.5, 3.24], [10.5, 4.95], [9.2, 11.47], [1.14, 2]], "atl": [[440, 0.07], [400, 0.49], [200, 0.65], [100, 1.31], [300, 0.65], [690, 0.03]], "batb": [[6, 1.01, 258.54], [4, 7.2, 30.35], [3, 8.2, 13.07], [5, 1.14, 2], [2, 9.2, 11.47], [1, 10.5, 4.95], [0, 15.5, 3.24]], "batl": [[2, 690, 0.59], [1, 300, 1.3], [0, 100, 1.31]], "id": 28161181}, {"atb": [[2.62, 116.16], [1.01, 258.54], [2.82, 51.7], [3.3, 20.45], [2.72, 54.7], [2.92, 24.5], [1.14, 2]], "atl": [[9.6, 0.07], [8.8, 16.6], [17, 12.14], [24, 8.44], [12, 11.77], [690, 0.03]], "batb": [[6, 1.01, 258.54], [4, 2.62, 116.16], [2, 2.82, 51.7], [3, 2.72, 54.7], [1, 2.92, 24.5], [0, 3.3, 20.45], [5, 1.14, 2]], "batl": [[1, 12, 11.84], [4, 690, 0.03], [2, 17, 12.14], [0, 8.8, 16.6], [3, 24, 8.44]], "id": 18294721}], "img": true, "tv": 0}, {"id": "1.185784053", "marketDefinition": {"bspMarket": true, "turnInPlayEnabled": true, "persistenceEnabled": true, "marketBaseRate": 6, "eventId": "30738903", "eventTypeId": "7", "numberOfWinners": 1, "bettingType": "ODDS", "marketType": "WIN", "marketTime": "2021-07-31T04:57:00.000Z", "suspendTime": "2021-07-31T04:57:00.000Z", "bspReconciled": false, "complete": true, "inPlay": false, "crossMatching": false, "runnersVoidable": false, "numberOfActiveRunners": 8, "betDelay": 0, "status": "OPEN", "runners": [{"adjustmentFactor": 26.179, "status": "ACTIVE", "sortPriority": 1, "id": 28763798}, {"adjustmentFactor": 15.707, "status": "ACTIVE", "sortPriority": 2, "id": 26336638}, {"adjustmentFactor": 23.81, "status": "ACTIVE", "sortPriority": 3, "id": 28209253}, {"adjustmentFactor": 7.143, "status": "ACTIVE", "sortPriority": 4, "id": 28763801}, {"adjustmentFactor": 6.667, "status": "ACTIVE", "sortPriority": 5, "id": 24526475}, {"adjustmentFactor": 12.5, "status": "ACTIVE", "sortPriority": 6, "id": 38017198}, {"adjustmentFactor": 2.439, "status": "ACTIVE", "sortPriority": 7, "id": 39880663}, {"adjustmentFactor": 5.556, "status": "ACTIVE", "sortPriority": 8, "id": 2562223}], "regulators": ["MR_INT"], "venue": "Belmont", "countryCode": "AU", "discountAllowed": true, "timezone": "Australia/Perth", "openDate": "2021-07-31T04:18:00.000Z", "version": 3938452128, "raceType": "Flat", "priceLadderDefinition": {"type": "CLASSIC"}}, "rc": [{"atb": [[3.65, 38.49], [2.96, 156.13], [3.4, 85.01], [2.86, 219.37], [1.01, 166.31], [1.03, 322], [1.02, 2]], "atl": [[7, 23.84], [8.4, 29.13], [22, 10.27], [11, 21.56], [16, 14.37], [690, 0.03]], "trd": [[3.75, 31.79]], "batb": [[6, 1.01, 166.31], [5, 1.02, 2], [4, 1.03, 322], [3, 2.86, 219.37], [2, 2.96, 156.13], [1, 3.4, 85.01], [0, 3.65, 38.49]], "batl": [[5, 690, 0.03], [4, 22, 10.27], [3, 16, 14.37], [2, 11, 21.56], [1, 8.4, 29.13], [0, 7, 23.84]], "tv": 31.79, "id": 28209253}, {"atb": [[15.5, 7.45], [13, 18], [8.2, 59.98], [9.2, 39.5], [1.01, 166.31], [1.03, 322], [1.02, 2]], "atl": [[360, 0.56], [160, 1.26], [80, 2.54], [260, 0.77], [690, 0.03]], "batb": [[6, 1.01, 166.31], [5, 1.02, 2], [4, 1.03, 322], [3, 8.2, 59.98], [2, 9.2, 39.5], [1, 13, 18], [0, 15.5, 7.45]], "batl": [[3, 690, 0.03], [2, 360, 1.33], [1, 160, 1.26], [0, 80, 2.54]], "id": 24526475}, {"atb": [[3.55, 169.36], [3.8, 115.68], [4.6, 59.98], [5.1, 26.34], [1.01, 166.31], [1.03, 322], [1.02, 2]], "atl": [[13, 3.18], [29, 7.17], [14.5, 14.87], [48, 4.27], [19.5, 10.84], [690, 0.03]], "batb": [[6, 1.01, 166.31], [5, 1.02, 2], [4, 1.03, 322], [3, 3.55, 169.36], [2, 3.8, 115.68], [1, 4.6, 59.98], [0, 5.1, 26.34]], "batl": [[5, 690, 0.03], [4, 48, 4.27], [3, 29, 7.17], [2, 19.5, 10.84], [1, 14.5, 14.87], [0, 13, 3.18]], "id": 26336638}, {"atb": [[22, 15.42], [44, 2.51], [18.5, 24.68], [34, 6.54], [1.01, 166.31], [1.03, 322], [1.02, 2]], "atl": [[100, 1.06], [250, 0.81], [450, 0.45], [350, 0.58], [550, 0.37], [690, 0.03]], "batb": [[6, 1.01, 166.31], [5, 1.02, 2], [4, 1.03, 322], [3, 18.5, 24.68], [2, 22, 15.42], [1, 34, 6.54], [0, 44, 2.51]], "batl": [[0, 100, 1.06], [2, 690, 0.85], [1, 350, 1.39]], "id": 39880663}, {"atb": [[6.6, 38.56], [7.6, 16.36], [5.3, 75.33], [4.8, 113.65], [1.01, 166.31], [1.03, 322], [1.02, 2]], "atl": [[14, 8.48], [28, 7.43], [46, 4.46], [90, 2.26], [19, 11.15], [690, 0.03]], "batb": [[6, 1.01, 166.31], [5, 1.02, 2], [4, 1.03, 322], [3, 4.8, 113.65], [2, 5.3, 75.33], [1, 6.6, 38.56], [0, 7.6, 16.36]], "batl": [[5, 690, 0.03], [4, 90, 2.26], [3, 46, 4.46], [2, 28, 7.43], [1, 19, 11.15], [0, 14, 8.48]], "id": 38017198}, {"atb": [[8.4, 43.77], [13.5, 8.64], [7.4, 67.48], [11, 21.59], [1.01, 166.31], [1.03, 322], [1.02, 2]], "atl": [[40, 2.65], [110, 1.84], [55, 3.71], [210, 0.96], [310, 0.65], [690, 0.03]], "batb": [[6, 1.01, 166.31], [5, 1.02, 2], [4, 1.03, 322], [3, 7.4, 67.48], [2, 8.4, 43.77], [1, 11, 21.59], [0, 13.5, 8.64]], "batl": [[4, 690, 0.03], [3, 310, 1.61], [2, 110, 1.84], [1, 55, 3.71], [0, 40, 2.65]], "id": 28763801}, {"atb": [[2.2, 352.83], [2.6, 66.16], [2.3, 244.27], [2.5, 141.13], [1.01, 166.31], [2.64, 39.73], [1.03, 322], [1.02, 2]], "atl": [[4.5, 8.48], [4.6, 2.65], [5.8, 42.91], [9.6, 23.95], [14, 15.84], [7.6, 31.2], [690, 0.03]], "batb": [[7, 1.01, 166.31], [4, 2.2, 352.83], [3, 2.3, 244.27], [2, 2.5, 141.13], [1, 2.6, 66.16], [0, 2.64, 39.73], [6, 1.02, 2], [5, 1.03, 322]], "batl": [[6, 690, 0.03], [5, 14, 15.84], [4, 9.6, 23.95], [3, 7.6, 31.2], [2, 5.8, 42.91], [1, 4.6, 2.65], [0, 4.5, 8.48]], "id": 28763798}, {"atb": [[15, 14.25], [10, 33.25], [9, 49.88], [17.5, 6.04], [1.01, 166.31], [1.03, 322], [1.02, 2]], "atl": [[400, 0.56], [200, 1.11], [100, 2.24], [300, 0.74], [24, 1.19], [690, 0.03]], "trd": [[15.5, 10.6]], "batb": [[6, 1.01, 166.31], [5, 1.02, 2], [4, 1.03, 322], [3, 9, 49.88], [2, 10, 33.25], [1, 15, 14.25], [0, 17.5, 6.04]], "batl": [[4, 690, 0.03], [3, 400, 1.3], [2, 200, 1.11], [1, 100, 2.24], [0, 24, 1.19]], "tv": 10.6, "id": 2562223}], "img": true, "tv": 42.39}, {"id": "1.185793028", "marketDefinition": {"bspMarket": true, "turnInPlayEnabled": true, "persistenceEnabled": true, "marketBaseRate": 6, "eventId": "30739215", "eventTypeId": "7", "numberOfWinners": 1, "bettingType": "ODDS", "marketType": "WIN", "marketTime": "2021-07-30T12:02:00.000Z", "suspendTime": "2021-07-30T12:02:00.000Z", "bspReconciled": false, "complete": true, "inPlay": false, "crossMatching": true, "runnersVoidable": false, "numberOfActiveRunners": 5, "betDelay": 0, "status": "OPEN", "runners": [{"adjustmentFactor": 6.843, "status": "ACTIVE", "sortPriority": 1, "id": 13029162}, {"adjustmentFactor": 18.053, "status": "ACTIVE", "sortPriority": 2, "id": 11659824}, {"adjustmentFactor": 23.441, "status": "ACTIVE", "sortPriority": 3, "id": 27355843}, {"adjustmentFactor": 30.715, "status": "ACTIVE", "sortPriority": 4, "id": 19180638}, {"adjustmentFactor": 20.948, "status": "ACTIVE", "sortPriority": 5, "id": 26921063}], "regulators": ["MR_INT"], "venue": "Ballarat", "countryCode": "AU", "discountAllowed": true, "timezone": "Australia/Sydney", "openDate": "2021-07-30T08:30:00.000Z", "version": 3938290762, "raceType": "Flat", "priceLadderDefinition": {"type": "CLASSIC"}}, "rc": [{"atb": [[1.78, 9.2], [1.65, 380.71], [1.75, 109.98], [1.7, 235.67], [2.12, 3.39], [1.01, 156.31], [1.6, 549.9], [1.14, 2]], "atl": [[2.88, 2.65], [4.5, 55.49], [85, 5], [3.75, 47.08], [3.25, 57.54], [5.5, 43.16], [690, 0.03]], "spl": [[1.7, 14.3]], "batb": [[7, 1.01, 156.31], [6, 1.14, 2], [5, 1.6, 549.9], [4, 1.65, 380.71], [3, 1.7, 235.67], [2, 1.75, 109.98], [1, 1.78, 9.2], [0, 2.12, 3.39]], "batl": [[6, 690, 0.03], [5, 85, 5], [4, 5.5, 43.16], [3, 4.5, 55.49], [2, 3.75, 47.08], [1, 3.25, 57.54], [0, 2.88, 2.65]], "id": 19180638}, {"atb": [[9.6, 0.83], [1.01, 156.31], [9.2, 40.24], [13, 13.75], [10.5, 26.05], [16, 0.44], [15.5, 5.69], [1.14, 2]], "atl": [[320, 0.07], [380, 0.51], [180, 0.73], [90, 1.46], [280, 0.69], [690, 0.03]], "batb": [[3, 9.2, 41.07], [5, 1.01, 156.31], [2, 10.5, 26.05], [1, 13, 13.75], [0, 15.5, 6.13], [4, 1.14, 2]], "batl": [[2, 690, 0.61], [1, 280, 1.42], [0, 90, 1.46]], "id": 13029162}, {"atb": [[4.6, 1.99], [1.01, 156.31], [3.75, 119.98], [5.1, 1.41], [4, 82.49], [5, 20.62], [4.5, 47.13], [1.14, 2]], "atl": [[14.5, 9.59], [19.5, 7], [29, 6.93], [48, 4.13], [690, 0.03]], "spl": [[1.01, 7.95]], "batb": [[7, 1.01, 156.31], [6, 1.14, 2], [5, 3.75, 119.98], [4, 4, 82.49], [3, 4.5, 47.13], [2, 4.6, 1.99], [0, 5.1, 1.41], [1, 5, 20.62]], "batl": [[1, 19.5, 7], [0, 14.5, 9.59], [4, 690, 0.03], [3, 48, 4.13], [2, 29, 6.93]], "id": 26921063}, {"atb": [[2.48, 2.89], [2.46, 4.91], [2.1, 299.95], [2.2, 206.21], [2.3, 126.9], [1.01, 156.31], [2.4, 58.92], [1.14, 2]], "atl": [[8.6, 25.56], [6.6, 23.12], [5.3, 30.11], [11.5, 18.49], [690, 0.03]], "spl": [[6.4, 5.3]], "batb": [[7, 1.01, 156.31], [6, 1.14, 2], [5, 2.1, 299.95], [4, 2.2, 206.21], [3, 2.3, 126.9], [2, 2.4, 58.92], [1, 2.46, 4.91], [0, 2.48, 2.89]], "batl": [[2, 8.6, 25.56], [1, 6.6, 23.12], [0, 5.3, 30.11], [4, 690, 0.03], [3, 11.5, 18.49]], "id": 27355843}, {"atb": [[9.8, 0.82], [1.01, 156.31], [8.4, 44.59], [9.4, 29.46], [11, 16.5], [14, 0.51], [13.5, 6.6], [1.14, 2]], "atl": [[360, 0.54], [160, 0.82], [80, 1.64], [260, 0.75], [690, 0.03]], "batb": [[2, 9.4, 30.28], [5, 1.01, 156.31], [3, 8.4, 44.59], [1, 11, 16.5], [0, 13.5, 7.11], [4, 1.14, 2]], "batl": [[2, 690, 0.57], [1, 260, 1.57], [0, 80, 1.64]], "id": 11659824}], "img": true, "tv": 0}, {"id": "1.185788101", "marketDefinition": {"bspMarket": true, "turnInPlayEnabled": true, "persistenceEnabled": true, "marketBaseRate": 6, "eventId": "30739095", "eventTypeId": "7", "numberOfWinners": 1, "bettingType": "ODDS", "marketType": "WIN", "marketTime": "2021-07-30T09:47:00.000Z", "suspendTime": "2021-07-30T09:47:00.000Z", "bspReconciled": false, "complete": true, "inPlay": false, "crossMatching": true, "runnersVoidable": false, "numberOfActiveRunners": 10, "betDelay": 0, "status": "OPEN", "runners": [{"adjustmentFactor": 8.196, "status": "ACTIVE", "sortPriority": 1, "id": 22758644}, {"adjustmentFactor": 12.411, "status": "ACTIVE", "sortPriority": 2, "id": 12757854}, {"adjustmentFactor": 33.321, "status": "ACTIVE", "sortPriority": 3, "id": 7630945}, {"adjustmentFactor": 3.615, "status": "ACTIVE", "sortPriority": 4, "id": 5783414}, {"adjustmentFactor": 3.615, "status": "ACTIVE", "sortPriority": 5, "id": 15920934}, {"adjustmentFactor": 8.964, "status": "ACTIVE", "sortPriority": 6, "id": 22487608}, {"adjustmentFactor": 11.009, "status": "ACTIVE", "sortPriority": 7, "id": 22989535}, {"adjustmentFactor": 1.68, "status": "ACTIVE", "sortPriority": 8, "id": 25295611}, {"adjustmentFactor": 2.977, "status": "ACTIVE", "sortPriority": 9, "id": 11282704}, {"adjustmentFactor": 14.211, "status": "ACTIVE", "sortPriority": 10, "id": 25422157}], "regulators": ["MR_INT"], "venue": "Gloucester Park", "countryCode": "AU", "discountAllowed": true, "timezone": "Australia/Perth", "openDate": "2021-07-30T09:15:00.000Z", "version": 3938344260, "raceType": "Flat", "priceLadderDefinition": {"type": "CLASSIC"}}, "rc": [{"atb": [[1.01, 156.31], [4.5, 53.77], [4.6, 1.99], [6, 9.41], [5.5, 20.91], [5, 23.52], [8, 6.72], [1.14, 2]], "atl": [[15, 15.89], [48, 0.07], [250, 0.78], [40, 3.32], [150, 1.3], [75, 1.75], [690, 0.03]], "batb": [[7, 1.01, 156.31], [5, 4.5, 53.77], [6, 1.14, 2], [4, 4.6, 1.99], [3, 5, 23.52], [2, 5.5, 20.91], [1, 6, 9.41], [0, 8, 6.72]], "batl": [[4, 690, 0.81], [3, 150, 1.3], [2, 75, 1.82], [1, 40, 3.32], [0, 15, 15.89]], "id": 22758644}, {"atb": [[1.01, 156.31], [9.6, 0.83], [9.2, 22.95], [13, 7.84], [10.5, 9.9], [15.5, 3.24], [21, 2.35], [1.14, 2]], "atl": [[600, 0.07], [490, 0.4], [390, 0.5], [190, 0.68], [290, 0.45], [690, 0.03]], "batb": [[6, 1.01, 156.31], [4, 9.2, 23.78], [3, 10.5, 9.9], [2, 13, 7.84], [1, 15.5, 3.24], [5, 1.14, 2], [0, 21, 2.35]], "batl": [[1, 690, 1], [0, 290, 1.13]], "id": 15920934}, {"atb": [[2.7, 55.35], [2.5, 125.45], [1.01, 156.31], [2.76, 4.07], [2.6, 58.8], [3, 23.52], [2.8, 26.13], [1.14, 2]], "atl": [[9.4, 15.42], [8.2, 0.07], [13.5, 15.54], [7.4, 20.23], [18.5, 11.1], [690, 0.03]], "spl": [[1.01, 7.95]], "batb": [[7, 1.01, 156.31], [5, 2.5, 125.45], [3, 2.7, 55.35], [6, 1.14, 2], [4, 2.6, 58.8], [2, 2.76, 4.07], [1, 2.8, 26.13], [0, 3, 23.52]], "batl": [[1, 9.4, 15.49], [4, 690, 0.03], [3, 18.5, 11.1], [2, 13.5, 15.54], [0, 7.4, 20.23]], "id": 12757854}, {"atb": [[1.01, 156.31], [32, 1.52], [18, 11.07], [55, 0.87], [26, 3.76], [21, 4.7], [1.14, 2]], "atl": [[600, 0.07], [480, 0.27], [780, 0.25], [680, 0.29], [580, 0.22], [690, 0.03]], "batb": [[5, 1.01, 156.31], [0, 32, 2.39], [3, 18, 11.07], [4, 1.14, 2], [2, 21, 4.7], [1, 26, 3.76]], "batl": [[0, 780, 1.13]], "id": 5783414}, {"atb": [[3.5, 37.64], [3.25, 83.64], [3.35, 3.06], [1.01, 156.31], [3.75, 34.21], [4, 15.68], [5, 11.76], [1.14, 2]], "atl": [[18, 0.07], [22, 6.17], [34, 5.89], [60, 3.29], [16, 8.63], [690, 0.03]], "batb": [[7, 1.01, 156.31], [5, 3.25, 83.64], [4, 3.35, 3.06], [3, 3.5, 37.64], [6, 1.14, 2], [2, 3.75, 34.21], [1, 4, 15.68], [0, 5, 11.76]], "batl": [[1, 22, 6.24], [4, 690, 0.03], [2, 34, 5.89], [3, 60, 3.29], [0, 16, 8.63]], "id": 22487608}, {"atb": [[3.75, 17.11], [3.5, 37.64], [3.25, 41.82], [3, 94.09], [1.01, 156.31], [3.1, 3.41], [4.5, 13.44], [1.14, 2]], "atl": [[14.5, 9.59], [19.5, 7], [29, 6.93], [48, 4.13], [690, 0.03]], "batb": [[7, 1.01, 156.31], [5, 3, 94.09], [3, 3.25, 41.82], [2, 3.5, 37.64], [1, 3.75, 17.11], [6, 1.14, 2], [4, 3.1, 3.41], [0, 4.5, 13.44]], "batl": [[1, 19.5, 7], [0, 14.5, 9.59], [2, 29, 6.93], [3, 48, 4.13], [4, 690, 0.03]], "id": 22989535}, {"atb": [[3.15, 43.76], [2.86, 101.17], [1.01, 156.31], [3.25, 3.18], [2.96, 48], [3.9, 16.22], [3.4, 19.6], [1.14, 2]], "atl": [[15, 0.07], [26, 7.77], [42, 4.74], [18, 7.62], [13, 10.79], [690, 0.03]], "batb": [[7, 1.01, 156.31], [5, 2.86, 101.17], [3, 3.15, 43.76], [6, 1.14, 2], [4, 2.96, 48], [2, 3.25, 3.18], [1, 3.4, 19.6], [0, 3.9, 16.22]], "batl": [[1, 18, 7.69], [4, 690, 0.03], [3, 42, 4.74], [2, 26, 7.77], [0, 13, 10.79]], "id": 7630945}, {"atb": [[1.01, 156.31], [7.8, 1.05], [7.6, 28.51], [8.6, 12.38], [9.6, 10.94], [16.5, 3.04], [11.5, 4.48], [1.14, 2]], "atl": [[110, 1.19], [210, 0.62], [410, 0.48], [310, 0.63], [690, 0.03]], "batb": [[7, 1.01, 156.31], [6, 1.14, 2], [5, 7.6, 28.51], [4, 7.8, 1.05], [3, 8.6, 12.38], [2, 9.6, 10.94], [0, 16.5, 3.04], [1, 11.5, 4.48]], "batl": [[0, 110, 1.19], [2, 690, 0.51], [1, 310, 1.25]], "id": 11282704}, {"atb": [[23, 4.28], [1.01, 156.31], [28, 3.49], [36, 1.35], [19, 10.45], [65, 0.74], [1.14, 2]], "atl": [[880, 0.22], [780, 0.25], [680, 0.19], [580, 0.22], [690, 0.03]], "batb": [[5, 1.01, 156.31], [2, 23, 4.28], [1, 28, 3.49], [0, 36, 2.09], [3, 19, 10.45], [4, 1.14, 2]], "batl": [[0, 880, 0.91]], "id": 25295611}, {"atb": [[3.15, 3.34], [1.01, 156.31], [2.82, 103.39], [3.05, 45.89], [3.3, 20.45], [3.8, 16.8], [2.92, 49], [1.14, 2]], "atl": [[24, 8.44], [12, 11.77], [38, 5.25], [17, 8.09], [690, 0.03]], "batb": [[7, 1.01, 156.31], [5, 2.82, 103.39], [2, 3.15, 3.34], [6, 1.14, 2], [4, 2.92, 49], [3, 3.05, 45.89], [1, 3.3, 20.45], [0, 3.8, 16.8]], "batl": [[4, 690, 0.03], [3, 38, 5.25], [2, 24, 8.44], [1, 17, 8.09], [0, 12, 11.77]], "id": 25422157}], "img": true, "tv": 0}, {"id": "1.185798781", "marketDefinition": {"bspMarket": true, "turnInPlayEnabled": true, "persistenceEnabled": true, "marketBaseRate": 8, "eventId": "30739923", "eventTypeId": "7", "numberOfWinners": 1, "bettingType": "ODDS", "marketType": "WIN", "marketTime": "2021-07-30T10:28:00.000Z", "suspendTime": "2021-07-30T10:28:00.000Z", "bspReconciled": false, "complete": true, "inPlay": false, "crossMatching": true, "runnersVoidable": false, "numberOfActiveRunners": 8, "betDelay": 0, "status": "OPEN", "runners": [{"adjustmentFactor": 0.637, "status": "ACTIVE", "sortPriority": 1, "id": 28392584}, {"adjustmentFactor": 5.968, "status": "ACTIVE", "sortPriority": 2, "id": 28101797}, {"adjustmentFactor": 6.394, "status": "ACTIVE", "sortPriority": 3, "id": 24527158}, {"adjustmentFactor": 9.795, "status": "ACTIVE", "sortPriority": 4, "id": 39088101}, {"adjustmentFactor": 20.959, "status": "ACTIVE", "sortPriority": 5, "id": 11659898}, {"adjustmentFactor": 6.394, "status": "ACTIVE", "sortPriority": 6, "id": 23814289}, {"adjustmentFactor": 24.926, "status": "ACTIVE", "sortPriority": 7, "id": 28170421}, {"adjustmentFactor": 24.926, "status": "ACTIVE", "sortPriority": 8, "id": 12975956}], "regulators": ["MR_INT"], "venue": "Parkes", "countryCode": "AU", "discountAllowed": true, "timezone": "Australia/Sydney", "openDate": "2021-07-30T08:55:00.000Z", "version": 3938311448, "raceType": "Flat", "priceLadderDefinition": {"type": "CLASSIC"}}, "rc": [{"atb": [[5.2, 1.71], [1.01, 146.31], [15, 2.1], [6, 11.76], [5, 29.4], [10, 3.27], [8, 8.4], [1.2, 122], [1.14, 2]], "atl": [[400, 0.49], [200, 0.65], [100, 1.31], [300, 0.65], [330, 0.07], [690, 0.03]], "batb": [[8, 1.01, 146.31], [7, 1.14, 2], [6, 1.2, 122], [5, 5, 29.4], [4, 5.2, 1.71], [3, 6, 11.76], [2, 8, 8.4], [1, 10, 3.27], [0, 15, 2.1]], "batl": [[2, 690, 0.59], [1, 300, 1.3], [0, 100, 1.31]], "id": 28101797}, {"atb": [[17.5, 3.72], [5.2, 1.71], [1.01, 146.31], [15, 2.1], [6, 11.76], [5, 29.4], [10, 3.27], [8, 8.4], [1.2, 122], [1.14, 2]], "atl": [[400, 0.49], [200, 0.65], [100, 1.31], [300, 0.65], [690, 0.03]], "batb": [[9, 1.01, 146.31], [8, 1.14, 2], [7, 1.2, 122], [6, 5, 29.4], [5, 5.2, 1.71], [4, 6, 11.76], [3, 8, 8.4], [2, 10, 3.27], [1, 15, 2.1], [0, 17.5, 3.72]], "batl": [[2, 690, 0.52], [1, 300, 1.3], [0, 100, 1.31]], "id": 23814289}, {"atb": [[1.73, 9.83], [1.7, 84.01], [1.9, 32.67], [1.6, 196.02], [1.8, 73.51], [2, 29.4], [1.01, 146.31], [1.2, 122], [1.14, 2]], "atl": [[7.6, 29.43], [5.8, 26.98], [9.6, 22.58], [4.8, 34.08], [70, 42.38], [3.6, 2.65], [690, 0.03]], "spl": [[1.01, 113.9], [1.8, 79.47]], "batb": [[8, 1.01, 146.31], [7, 1.14, 2], [6, 1.2, 122], [5, 1.6, 196.02], [4, 1.7, 84.01], [3, 1.73, 9.83], [2, 1.8, 73.51], [1, 1.9, 32.67], [0, 2, 29.4]], "batl": [[6, 690, 0.03], [5, 70, 42.38], [4, 9.6, 22.58], [3, 7.6, 29.43], [2, 5.8, 26.98], [1, 4.8, 34.08], [0, 3.6, 2.65]], "id": 28170421}, {"atb": [[2.42, 5.05], [2.76, 33.41], [2.96, 15], [3.4, 12.25], [2.36, 86.48], [2.56, 37.69], [1.01, 146.31], [1.2, 122], [1.14, 2]], "atl": [[26, 7.77], [13, 10.79], [9.2, 15.79], [18, 11.42], [690, 0.03]], "batb": [[8, 1.01, 146.31], [7, 1.14, 2], [6, 1.2, 122], [5, 2.36, 86.48], [4, 2.42, 5.05], [3, 2.56, 37.69], [2, 2.76, 33.41], [1, 2.96, 15], [0, 3.4, 12.25]], "batl": [[4, 690, 0.03], [3, 26, 7.77], [2, 18, 11.42], [1, 13, 10.79], [0, 9.2, 15.79]], "id": 12975956}, {"atb": [[4, 2.39], [3.9, 40.55], [7.6, 4.46], [5.8, 12.25], [4.8, 15.47], [9.6, 3.42], [1.01, 146.31], [1.2, 122], [1.14, 2]], "atl": [[230, 0.85], [330, 0.59], [130, 1], [65, 2.02], [150, 0.07], [690, 0.03]], "batb": [[8, 1.01, 146.31], [7, 1.14, 2], [6, 1.2, 122], [5, 3.9, 40.55], [4, 4, 2.39], [3, 4.8, 15.47], [2, 5.8, 12.25], [1, 7.6, 4.46], [0, 9.6, 3.42]], "batl": [[3, 690, 0.03], [2, 330, 1.51], [1, 130, 1], [0, 65, 2.02]], "id": 39088101}, {"atb": [[3.3, 12.78], [3.8, 10.5], [2.52, 77.37], [2.72, 34.19], [2.92, 30.63], [1.01, 146.31], [1.2, 122], [1.14, 2]], "atl": [[24, 8.44], [12, 11.77], [38, 5.25], [17, 8.09], [13, 15.89], [23, 0.07], [690, 0.03]], "batb": [[7, 1.01, 146.31], [6, 1.14, 2], [5, 1.2, 122], [4, 2.52, 77.37], [3, 2.72, 34.19], [2, 2.92, 30.63], [1, 3.3, 12.78], [0, 3.8, 10.5]], "batl": [[5, 690, 0.03], [4, 38, 5.25], [3, 24, 8.51], [2, 17, 8.09], [1, 13, 15.89], [0, 12, 11.77]], "id": 24527158}, {"atb": [[2.42, 5.05], [2.76, 33.41], [2.96, 15], [3.4, 12.25], [2.36, 86.48], [2.56, 37.69], [1.01, 146.31], [1.2, 122], [1.14, 2]], "atl": [[26, 7.77], [13, 10.79], [9.2, 15.79], [18, 11.42], [690, 0.03]], "batb": [[8, 1.01, 146.31], [7, 1.14, 2], [6, 1.2, 122], [5, 2.36, 86.48], [4, 2.42, 5.05], [3, 2.56, 37.69], [2, 2.76, 33.41], [1, 2.96, 15], [0, 3.4, 12.25]], "batl": [[4, 690, 0.03], [3, 26, 7.77], [2, 18, 11.42], [1, 13, 10.79], [0, 9.2, 15.79]], "id": 11659898}, {"atb": [[5.8, 1.49], [1.01, 146.31], [13, 2.45], [9.2, 7.17], [18, 1.73], [7.2, 9.48], [5.6, 25.57], [1.2, 122], [1.14, 2]], "atl": [[250, 0.52], [450, 0.43], [350, 0.56], [150, 0.87], [600, 0.07], [690, 0.03]], "batb": [[8, 1.01, 146.31], [7, 1.14, 2], [6, 1.2, 122], [5, 5.6, 25.57], [4, 5.8, 1.49], [3, 7.2, 9.48], [2, 9.2, 7.17], [1, 13, 2.45], [0, 18, 1.73]], "batl": [[2, 690, 0.03], [1, 600, 1.06], [0, 250, 1.39]], "id": 28392584}], "img": true, "tv": 0}, {"id": "1.185788109", "marketDefinition": {"bspMarket": true, "turnInPlayEnabled": true, "persistenceEnabled": true, "marketBaseRate": 6, "eventId": "30739095", "eventTypeId": "7", "numberOfWinners": 1, "bettingType": "ODDS", "marketType": "WIN", "marketTime": "2021-07-30T11:43:00.000Z", "suspendTime": "2021-07-30T11:43:00.000Z", "bspReconciled": false, "complete": true, "inPlay": false, "crossMatching": true, "runnersVoidable": false, "numberOfActiveRunners": 12, "betDelay": 0, "status": "OPEN", "runners": [{"adjustmentFactor": 36.366, "status": "ACTIVE", "sortPriority": 1, "id": 28364530}, {"adjustmentFactor": 1.889, "status": "ACTIVE", "sortPriority": 2, "id": 21570820}, {"adjustmentFactor": 1.889, "status": "ACTIVE", "sortPriority": 3, "id": 2417218}, {"adjustmentFactor": 11.758, "status": "ACTIVE", "sortPriority": 4, "id": 23651564}, {"adjustmentFactor": 1.889, "status": "ACTIVE", "sortPriority": 5, "id": 28230742}, {"adjustmentFactor": 1.144, "status": "ACTIVE", "sortPriority": 6, "id": 28170544}, {"adjustmentFactor": 1.144, "status": "ACTIVE", "sortPriority": 7, "id": 23103599}, {"adjustmentFactor": 1.889, "status": "ACTIVE", "sortPriority": 8, "id": 23814209}, {"adjustmentFactor": 1.889, "status": "ACTIVE", "sortPriority": 9, "id": 24368842}, {"adjustmentFactor": 1.889, "status": "ACTIVE", "sortPriority": 10, "id": 17567710}, {"adjustmentFactor": 36.366, "status": "ACTIVE", "sortPriority": 11, "id": 39446989}, {"adjustmentFactor": 1.889, "status": "ACTIVE", "sortPriority": 12, "id": 27355816}], "regulators": ["MR_INT"], "venue": "Gloucester Park", "countryCode": "AU", "discountAllowed": true, "timezone": "Australia/Perth", "openDate": "2021-07-30T09:15:00.000Z", "version": 3938344244, "raceType": "Flat", "priceLadderDefinition": {"type": "CLASSIC"}}, "rc": [{"atb": [[1.01, 156.31], [21, 9.41], [32, 3.04], [26, 3.76], [42, 1.15], [80, 0.59], [34, 0.21], [1.2, 122], [1.14, 2]], "atl": [[600, 0.07], [1000, 0.2], [940, 0.21], [840, 0.15], [740, 0.17], [690, 0.03]], "batb": [[6, 1.01, 156.31], [3, 21, 9.41], [1, 32, 3.25], [5, 1.14, 2], [4, 1.2, 122], [2, 26, 3.76], [0, 42, 1.74]], "batl": [[0, 1000, 0.83]], "id": 23814209}, {"atb": [[8.4, 0.97], [1.01, 156.31], [8.2, 26.13], [18, 2.77], [22, 0.32], [21, 3.72], [13, 3.92], [10.5, 9.9], [9.2, 11.47], [1.2, 122], [1.14, 2]], "atl": [[250, 0.52], [450, 0.43], [350, 0.56], [150, 0.87], [690, 0.03]], "batb": [[5, 8.2, 27.1], [8, 1.01, 156.31], [1, 18, 2.77], [0, 21, 4.04], [7, 1.14, 2], [6, 1.2, 122], [4, 9.2, 11.47], [3, 10.5, 9.9], [2, 13, 3.92]], "batl": [[1, 690, 1.02], [0, 250, 1.39]], "id": 24368842}, {"atb": [[1.01, 156.31], [21, 9.41], [32, 3.04], [26, 3.76], [42, 1.15], [80, 0.59], [34, 0.21], [1.2, 122], [1.14, 2]], "atl": [[600, 0.07], [1000, 0.2], [940, 0.21], [840, 0.15], [740, 0.17], [690, 0.03]], "batb": [[6, 1.01, 156.31], [3, 21, 9.41], [1, 32, 3.25], [5, 1.14, 2], [4, 1.2, 122], [2, 26, 3.76], [0, 42, 1.74]], "batl": [[0, 1000, 0.83]], "id": 23103599}, {"atb": [[7.8, 1.05], [1.01, 156.31], [7.6, 28.51], [8.6, 12.38], [9.6, 10.94], [16.5, 3.04], [11.5, 4.48], [17.5, 0.41], [17, 3.72], [1.2, 122], [1.14, 2]], "atl": [[450, 0.07], [110, 1.19], [210, 0.62], [410, 0.48], [310, 0.63], [690, 0.03]], "batb": [[9, 1.01, 156.31], [8, 1.14, 2], [7, 1.2, 122], [6, 7.6, 28.51], [5, 7.8, 1.05], [4, 8.6, 12.38], [3, 9.6, 10.94], [1, 16.5, 3.04], [2, 11.5, 4.48], [0, 17, 4.13]], "batl": [[2, 690, 0.58], [1, 310, 1.25], [0, 110, 1.19]], "id": 28230742}, {"atb": [[1.01, 156.31], [36, 1.35], [14, 14.47], [23, 2.14], [19, 5.23], [16.5, 6.07], [22, 0.32], [1.2, 122], [1.14, 2]], "atl": [[420, 0.31], [320, 0.41], [620, 0.31], [520, 0.38], [690, 0.03]], "batb": [[7, 1.01, 156.31], [0, 36, 1.35], [6, 1.14, 2], [5, 1.2, 122], [4, 14, 14.47], [3, 16.5, 6.07], [2, 19, 5.55], [1, 23, 2.14]], "batl": [[1, 690, 0.34], [0, 520, 1.1]], "id": 27355816}, {"atb": [[2.9, 3.77], [2.62, 116.16], [1.01, 156.31], [2.82, 51.7], [3.3, 20.45], [2.72, 54.7], [2.92, 24.5], [3.45, 2.08], [1.2, 122], [1.14, 2]], "atl": [[9.6, 0.07], [8.8, 16.6], [17, 12.14], [24, 8.44], [12, 11.77], [690, 0.03]], "batb": [[9, 1.01, 156.31], [8, 1.14, 2], [7, 1.2, 122], [6, 2.62, 116.16], [5, 2.72, 54.7], [4, 2.82, 51.7], [3, 2.9, 3.77], [2, 2.92, 24.5], [1, 3.3, 20.45], [0, 3.45, 2.08]], "batl": [[1, 12, 11.84], [4, 690, 0.03], [2, 17, 12.14], [0, 8.8, 16.6], [3, 24, 8.44]], "id": 23651564}, {"atb": [[1.01, 156.31], [10.5, 19.81], [18, 2.77], [15.5, 6.49], [13, 7.84], [18.5, 0.39], [26, 1.88], [1.2, 122], [1.14, 2]], "atl": [[600, 0.07], [550, 0.35], [250, 0.52], [450, 0.43], [350, 0.37], [690, 0.03]], "batb": [[7, 1.01, 156.31], [4, 10.5, 19.81], [1, 18, 3.16], [3, 13, 7.84], [2, 15.5, 6.49], [6, 1.14, 2], [5, 1.2, 122], [0, 26, 1.88]], "batl": [[1, 690, 0.45], [0, 450, 1.32]], "id": 21570820}, {"atb": [[9.8, 0.82], [1.01, 156.31], [9.4, 22.4], [13.5, 7.53], [11, 9.41], [16, 3.14], [22, 2.56], [1.2, 122], [1.14, 2]], "atl": [[500, 0.39], [400, 0.49], [200, 0.65], [300, 0.43], [690, 0.03]], "batb": [[4, 9.4, 23.22], [7, 1.01, 156.31], [3, 11, 9.41], [2, 13.5, 7.53], [1, 16, 3.14], [6, 1.14, 2], [5, 1.2, 122], [0, 22, 2.56]], "batl": [[1, 690, 0.91], [0, 300, 1.08]], "id": 17567710}, {"atb": [[2.6, 4.48], [2.34, 140.43], [2.84, 25.57], [2.44, 65.34], [2.64, 28.69], [1.01, 156.31], [2.54, 61.09], [2.9, 2.47], [1.2, 122], [1.14, 2]], "atl": [[7.8, 0.07], [7, 21.58], [12.5, 16.89], [9, 16.18], [17.5, 11.77], [690, 0.03]], "batb": [[9, 1.01, 156.31], [8, 1.14, 2], [7, 1.2, 122], [6, 2.34, 140.43], [5, 2.44, 65.34], [4, 2.54, 61.09], [3, 2.6, 4.48], [2, 2.64, 28.69], [1, 2.84, 25.57], [0, 2.9, 2.47]], "batl": [[1, 9, 16.25], [4, 690, 0.03], [2, 12.5, 16.89], [0, 7, 21.58], [3, 17.5, 11.77]], "id": 28364530}, {"atb": [[1.73, 9.83], [1.65, 144.75], [1.75, 62.73], [1.7, 134.41], [1.85, 55.35], [1.01, 156.31], [1.6, 313.63], [1.86, 3.86], [1.14, 2]], "atl": [[85, 5], [3.75, 47.08], [7, 32.37], [5.5, 43.16], [4.5, 36.99], [3.1, 2.65], [690, 0.03]], "spl": [[1.01, 7.95]], "batb": [[8, 1.01, 156.31], [7, 1.14, 2], [6, 1.6, 313.63], [5, 1.65, 144.75], [4, 1.7, 134.41], [3, 1.73, 9.83], [2, 1.75, 62.73], [1, 1.85, 55.35], [0, 1.86, 3.86]], "batl": [[6, 690, 0.03], [5, 85, 5], [4, 7, 32.37], [3, 5.5, 43.16], [2, 4.5, 36.99], [1, 3.75, 47.08], [0, 3.1, 2.65]], "id": 39446989}, {"atb": [[23, 4.28], [1.01, 156.31], [28, 3.49], [36, 1.35], [29, 0.24], [19, 10.45], [65, 0.74], [1.2, 122], [1.14, 2]], "atl": [[600, 0.07], [880, 0.22], [780, 0.25], [680, 0.19], [580, 0.22], [690, 0.03]], "batb": [[6, 1.01, 156.31], [2, 23, 4.28], [1, 28, 3.73], [0, 36, 2.09], [5, 1.14, 2], [4, 1.2, 122], [3, 19, 10.45]], "batl": [[0, 880, 0.98]], "id": 2417218}, {"atb": [[1.01, 156.31], [21, 9.41], [32, 3.04], [26, 3.76], [42, 1.15], [80, 0.59], [34, 0.21], [1.2, 122], [1.14, 2]], "atl": [[600, 0.07], [1000, 0.2], [940, 0.21], [840, 0.15], [740, 0.17], [690, 0.03]], "batb": [[6, 1.01, 156.31], [3, 21, 9.41], [1, 32, 3.25], [5, 1.14, 2], [4, 1.2, 122], [2, 26, 3.76], [0, 42, 1.74]], "batl": [[0, 1000, 0.83]], "id": 28170544}], "img": true, "tv": 0}, {"id": "1.185783403", "marketDefinition": {"bspMarket": true, "turnInPlayEnabled": true, "persistenceEnabled": true, "marketBaseRate": 6, "eventId": "30738738", "eventTypeId": "7", "numberOfWinners": 1, "bettingType": "ODDS", "marketType": "WIN", "marketTime": "2021-07-31T03:48:00.000Z", "suspendTime": "2021-07-31T03:48:00.000Z", "bspReconciled": false, "complete": true, "inPlay": false, "crossMatching": false, "runnersVoidable": false, "numberOfActiveRunners": 11, "betDelay": 0, "status": "OPEN", "runners": [{"adjustmentFactor": 3.745, "status": "ACTIVE", "sortPriority": 1, "id": 27768630}, {"adjustmentFactor": 8.181, "status": "ACTIVE", "sortPriority": 2, "id": 37548317}, {"adjustmentFactor": 14.508, "status": "ACTIVE", "sortPriority": 3, "id": 26896410}, {"adjustmentFactor": 14.508, "status": "ACTIVE", "sortPriority": 4, "id": 7603225}, {"adjustmentFactor": 12.287, "status": "ACTIVE", "sortPriority": 5, "id": 28365110}, {"adjustmentFactor": 3.064, "status": "ACTIVE", "sortPriority": 6, "id": 28092753}, {"adjustmentFactor": 5.618, "status": "ACTIVE", "sortPriority": 7, "id": 40363965}, {"adjustmentFactor": 7.223, "status": "ACTIVE", "sortPriority": 8, "id": 39078263}, {"adjustmentFactor": 12.287, "status": "ACTIVE", "sortPriority": 9, "id": 40363966}, {"adjustmentFactor": 16.632, "status": "ACTIVE", "sortPriority": 10, "id": 40363967}, {"adjustmentFactor": 1.945, "status": "ACTIVE", "sortPriority": 11, "id": 40363968}, {"adjustmentFactor": 1.111, "status": "REMOVED", "sortPriority": 12, "removalDate": "2021-07-29T23:46:00.000Z", "id": 40363969}], "regulators": ["MR_INT"], "venue": "Eagle Farm", "countryCode": "AU", "discountAllowed": true, "timezone": "Australia/Queensland", "openDate": "2021-07-31T01:28:00.000Z", "version": 3938309406, "raceType": "Flat", "priceLadderDefinition": {"type": "CLASSIC"}}, "rc": [{"atb": [[15.5, 0.47], [1.03, 322], [15, 15.58], [11.5, 20.78], [8.6, 43.06], [9.6, 38.05], [1.01, 166.31], [1.02, 2]], "atl": [[380, 0.52], [180, 1.11], [90, 2.23], [280, 0.71], [85, 4.5], [690, 0.03]], "batb": [[0, 15, 16.05], [4, 1.03, 322], [6, 1.01, 166.31], [5, 1.02, 2], [3, 8.6, 43.06], [2, 9.6, 38.05], [1, 11.5, 20.78]], "batl": [[4, 690, 0.03], [3, 380, 1.23], [2, 180, 1.11], [1, 90, 2.23], [0, 85, 4.5]], "id": 40363965}, {"atb": [[7.6, 0.95], [1.02, 2], [7.4, 34.09], [5.5, 72.72], [5, 81.81], [1.01, 166.31], [6, 43.63], [1.03, 322]], "atl": [[29, 7.07], [48, 4.21], [95, 2.11], [19.5, 10.7], [12.5, 12.71], [690, 0.03]], "batb": [[0, 7.4, 35.04], [5, 1.02, 2], [6, 1.01, 166.31], [3, 5, 81.81], [2, 5.5, 72.72], [4, 1.03, 322], [1, 6, 43.63]], "batl": [[5, 690, 0.03], [4, 95, 2.11], [3, 48, 4.21], [2, 29, 7.07], [1, 19.5, 10.7], [0, 12.5, 12.71]], "id": 28365110}, {"atb": [[29, 0.24], [1.03, 322], [15.5, 19.28], [28, 6.9], [21, 9.32], [18, 16.44], [1.01, 166.31], [1.02, 2]], "atl": [[500, 0.48], [400, 0.59], [200, 1.2], [300, 0.79], [140, 4.24], [690, 0.03]], "trd": [[20, 15.89]], "batb": [[0, 28, 7.14], [4, 1.03, 322], [6, 1.01, 166.31], [5, 1.02, 2], [3, 15.5, 19.28], [2, 18, 16.44], [1, 21, 9.32]], "batl": [[3, 690, 0.51], [2, 400, 1.38], [1, 200, 1.2], [0, 140, 4.24]], "tv": 15.89, "id": 27768630}, {"atb": [[5.9, 1.21], [1.01, 166.31], [5, 53.35], [5.8, 11.66], [4, 106.7], [5.7, 45.4], [4.5, 91.45], [1.03, 322], [1.02, 2]], "atl": [[17, 12.75], [24, 8.87], [70, 2.96], [38, 5.51], [690, 0.03]], "batb": [[8, 1.01, 166.31], [7, 1.02, 2], [6, 1.03, 322], [5, 4, 106.7], [4, 4.5, 91.45], [3, 5, 53.35], [2, 5.7, 45.4], [1, 5.8, 11.66], [0, 5.9, 1.21]], "batl": [[0, 17, 12.75], [3, 70, 2.96], [1, 24, 8.87], [2, 38, 5.51], [4, 690, 0.03]], "id": 7603225}, {"atb": [[40, 0.18], [27, 8.39], [22, 15.58], [38, 5.9], [18.5, 18.7], [1.01, 166.31], [1.03, 322], [1.02, 2]], "atl": [[250, 0.79], [450, 0.44], [350, 0.57], [550, 0.36], [690, 0.03]], "batb": [[0, 38, 6.08], [4, 1.03, 322], [6, 1.01, 166.31], [5, 1.02, 2], [3, 18.5, 18.7], [2, 22, 15.58], [1, 27, 8.39]], "batl": [[1, 690, 0.83], [0, 350, 1.36]], "id": 40363968}, {"atb": [[6.6, 1.09], [1.02, 2], [5.5, 42.87], [5, 72.35], [6.4, 35.73], [4.5, 82.69], [1.01, 166.31], [1.03, 322]], "atl": [[27, 8.83], [44, 5.34], [85, 2.73], [18.5, 13.12], [8, 9.27], [690, 0.03]], "trd": [[5.7, 21.19], [6.2, 21.19]], "batb": [[7, 1.01, 166.31], [6, 1.02, 2], [5, 1.03, 322], [4, 4.5, 82.69], [3, 5, 72.35], [2, 5.5, 42.87], [1, 6.4, 35.73], [0, 6.6, 1.09]], "batl": [[5, 690, 0.03], [4, 85, 2.73], [3, 44, 5.34], [2, 27, 8.83], [1, 18.5, 13.12], [0, 8, 9.27]], "tv": 42.38, "id": 26896410}, {"atb": [[8.6, 0.83], [1.01, 166.31], [8.4, 28.69], [7, 35.39], [6, 63.7], [5.5, 70.78], [1.03, 322], [1.02, 2]], "atl": [[29, 7.33], [48, 4.37], [190, 1.09], [95, 2.18], [690, 0.03]], "trd": [[11, 5.3]], "batb": [[0, 8.4, 29.52], [6, 1.01, 166.31], [5, 1.02, 2], [4, 1.03, 322], [3, 5.5, 70.78], [2, 6, 63.7], [1, 7, 35.39]], "batl": [[4, 690, 0.03], [3, 190, 1.09], [2, 95, 2.18], [1, 48, 4.37], [0, 29, 7.33]], "tv": 5.3, "id": 37548317}, {"atb": [[7.4, 0.97], [1.02, 2], [5.7, 46.42], [5, 54.54], [4.5, 93.5], [4, 109.08], [1.01, 166.31], [7.2, 9.01], [1.03, 322]], "atl": [[24, 8.61], [38, 5.35], [70, 2.87], [17, 12.38], [690, 0.03]], "batb": [[0, 7.2, 9.98], [6, 1.02, 2], [7, 1.01, 166.31], [5, 1.03, 322], [4, 4, 109.08], [3, 4.5, 93.5], [2, 5, 54.54], [1, 5.7, 46.42]], "batl": [[4, 690, 0.03], [3, 70, 2.87], [2, 38, 5.35], [1, 24, 8.61], [0, 17, 12.38]], "id": 40363966}, {"atb": [[5.4, 1.33], [1.01, 166.31], [3.65, 123.48], [3.9, 112.84], [5, 54.54], [4.3, 66.11], [5.2, 26.49], [5.3, 13.77], [1.03, 322], [1.02, 2]], "atl": [[15.5, 13.66], [55, 3.67], [21, 9.9], [32, 6.39], [8, 2.65], [690, 0.03]], "batb": [[9, 1.01, 166.31], [8, 1.02, 2], [7, 1.03, 322], [6, 3.65, 123.48], [5, 3.9, 112.84], [4, 4.3, 66.11], [3, 5, 54.54], [2, 5.2, 26.49], [1, 5.3, 13.77], [0, 5.4, 1.33]], "batl": [[5, 690, 0.03], [4, 55, 3.67], [3, 32, 6.39], [2, 21, 9.9], [1, 15.5, 13.66], [0, 8, 2.65]], "id": 40363967}, {"atb": [[29, 0.24], [1.03, 322], [15.5, 22.08], [1.01, 166.31], [21, 10.67], [18, 18.83], [28, 7.9], [1.02, 2]], "atl": [[50, 3.18], [55, 2.65], [500, 0.41], [400, 0.51], [200, 1.02], [300, 0.68], [690, 0.03]], "batb": [[0, 28, 8.14], [4, 1.03, 322], [6, 1.01, 166.31], [3, 15.5, 22.08], [2, 18, 18.83], [1, 21, 10.67], [5, 1.02, 2]], "batl": [[4, 690, 0.44], [3, 400, 1.19], [2, 200, 1.02], [1, 55, 2.65], [0, 50, 3.18]], "id": 28092753}, {"atb": [[11.5, 0.62], [1.01, 166.31], [7, 54.54], [11, 21.82], [8, 46.75], [9, 27.27], [1.03, 322], [1.02, 2]], "atl": [[200, 1], [100, 2], [50, 4.04], [300, 0.66], [690, 0.03]], "batb": [[0, 11, 22.44], [6, 1.01, 166.31], [3, 7, 54.54], [2, 8, 46.75], [1, 9, 27.27], [5, 1.02, 2], [4, 1.03, 322]], "batl": [[3, 690, 0.69], [2, 200, 1], [1, 100, 2], [0, 50, 4.04]], "id": 39078263}], "img": true, "tv": 63.57}, {"id": "1.185781647", "marketDefinition": {"bspMarket": true, "turnInPlayEnabled": true, "persistenceEnabled": true, "marketBaseRate": 8, "eventId": "30738618", "eventTypeId": "7", "numberOfWinners": 1, "bettingType": "ODDS", "marketType": "WIN", "marketTime": "2021-07-30T11:12:00.000Z", "suspendTime": "2021-07-30T11:12:00.000Z", "bspReconciled": false, "complete": true, "inPlay": false, "crossMatching": true, "runnersVoidable": false, "numberOfActiveRunners": 8, "betDelay": 0, "status": "OPEN", "runners": [{"adjustmentFactor": 0.356, "status": "ACTIVE", "sortPriority": 1, "id": 38848100}, {"adjustmentFactor": 19.735, "status": "ACTIVE", "sortPriority": 2, "id": 39879766}, {"adjustmentFactor": 1.067, "status": "ACTIVE", "sortPriority": 3, "id": 40363513}, {"adjustmentFactor": 12.957, "status": "ACTIVE", "sortPriority": 4, "id": 40186642}, {"adjustmentFactor": 11.354, "status": "ACTIVE", "sortPriority": 5, "id": 40363514}, {"adjustmentFactor": 49.929, "status": "ACTIVE", "sortPriority": 6, "id": 38416643}, {"adjustmentFactor": 0.436, "status": "ACTIVE", "sortPriority": 7, "id": 40363515}, {"adjustmentFactor": 4.166, "status": "ACTIVE", "sortPriority": 8, "id": 40363516}], "regulators": ["MR_INT"], "venue": "Newcastle", "countryCode": "AU", "discountAllowed": true, "timezone": "Australia/Sydney", "openDate": "2021-07-30T07:10:00.000Z", "version": 3938308156, "raceType": "Flat", "priceLadderDefinition": {"type": "CLASSIC"}}, "rc": [{"atb": [[3.9, 2.47], [3.8, 42.01], [1.01, 146.31], [9.2, 3.59], [4.6, 16.33], [7.2, 4.74], [5.6, 12.78], [1.14, 2]], "atl": [[150, 0.07], [110, 1.19], [55, 2.4], [210, 0.93], [310, 0.63], [690, 0.03]], "batb": [[7, 1.01, 146.31], [6, 1.14, 2], [5, 3.8, 42.01], [4, 3.9, 2.47], [0, 9.2, 3.59], [3, 4.6, 16.33], [2, 5.6, 12.78], [1, 7.2, 4.74]], "batl": [[3, 690, 0.66], [2, 210, 1], [1, 110, 1.19], [0, 55, 2.4]], "id": 40363516}, {"atb": [[1.01, 146.31], [10.5, 6.19], [15.5, 4.06], [8.2, 16.33], [21, 1.47], [32, 0.95], [1.14, 2]], "atl": [[600, 0.39], [500, 0.39], [400, 0.32], [300, 0.43], [690, 0.03]], "batb": [[5, 1.01, 146.31], [2, 10.5, 6.19], [4, 1.14, 2], [3, 8.2, 16.33], [1, 15.5, 4.06], [0, 21, 2.42]], "batl": [[1, 690, 0.42], [0, 500, 1.14]], "id": 40363515}, {"atb": [[2.76, 4.07], [1.01, 146.31], [2.7, 69.18], [3.25, 26.13], [2.9, 30.95], [3.75, 10.69], [4.5, 8.4], [1.14, 2]], "atl": [[16.5, 0.07], [14.5, 9.59], [19.5, 7], [29, 6.93], [48, 4.13], [690, 0.03]], "batb": [[7, 1.01, 146.31], [6, 1.14, 2], [5, 2.7, 69.18], [4, 2.76, 4.07], [3, 2.9, 30.95], [2, 3.25, 26.13], [1, 3.75, 10.69], [0, 4.5, 8.4]], "batl": [[1, 19.5, 7.07], [4, 690, 0.03], [0, 14.5, 9.59], [3, 48, 4.13], [2, 29, 6.93]], "id": 40363514}, {"atb": [[3.9, 2.47], [3.8, 42.01], [1.01, 146.31], [9.2, 3.59], [4.6, 16.33], [7.2, 4.74], [5.6, 12.78], [1.14, 2]], "atl": [[110, 1.19], [55, 2.4], [210, 0.93], [310, 0.63], [690, 0.03]], "batb": [[7, 1.01, 146.31], [6, 1.14, 2], [5, 3.8, 42.01], [4, 3.9, 2.47], [0, 9.2, 3.59], [3, 4.6, 16.33], [2, 5.6, 12.78], [1, 7.2, 4.74]], "batl": [[3, 690, 0.03], [2, 310, 1.56], [1, 110, 1.19], [0, 55, 2.4]], "id": 38848100}, {"atb": [[1.52, 13.79], [1.3, 392.03], [1.5, 117.61], [1.7, 42.01], [1.01, 146.31], [1.4, 147.01], [1.6, 49], [1.14, 2]], "atl": [[4.5, 55.49], [3.1, 0.07], [3.75, 47.08], [3.25, 57.54], [5.5, 43.16], [2.96, 2.65], [85, 5], [690, 0.03]], "spl": [[2.1, 12.18]], "batb": [[7, 1.01, 146.31], [6, 1.14, 2], [5, 1.3, 392.03], [4, 1.4, 147.01], [3, 1.5, 117.61], [2, 1.52, 13.79], [0, 1.7, 42.01], [1, 1.6, 49]], "batl": [[3, 4.5, 55.49], [1, 3.25, 57.61], [6, 690, 0.03], [4, 5.5, 43.16], [2, 3.75, 47.08], [5, 85, 5], [0, 2.96, 2.65]], "id": 38416643}, {"atb": [[2.16, 6.18], [2.12, 105.01], [2.32, 44.55], [1.01, 146.31], [2.72, 17.1], [2.92, 15.32], [2.52, 38.69], [1.14, 2]], "atl": [[9.2, 15.79], [7.2, 20.88], [13, 16.18], [18, 11.42], [690, 0.03]], "spl": [[12, 3.71]], "batb": [[7, 1.01, 146.31], [6, 1.14, 2], [5, 2.12, 105.01], [4, 2.16, 6.18], [3, 2.32, 44.55], [1, 2.72, 17.1], [0, 2.92, 15.32], [2, 2.52, 38.69]], "batl": [[1, 9.2, 15.79], [0, 7.2, 20.88], [4, 690, 0.03], [3, 18, 11.42], [2, 13, 16.18]], "id": 39879766}, {"atb": [[7.4, 1.12], [1.01, 146.31], [7.2, 18.97], [13, 4.9], [26, 1.18], [9.2, 7.17], [18, 1.73], [1.14, 2]], "atl": [[250, 0.52], [450, 0.43], [350, 0.37], [550, 0.35], [690, 0.03]], "batb": [[7, 1.01, 146.31], [6, 1.14, 2], [5, 7.2, 18.97], [4, 7.4, 1.12], [3, 9.2, 7.17], [2, 13, 4.9], [1, 18, 1.73], [0, 26, 1.18]], "batl": [[1, 690, 0.38], [0, 450, 1.32]], "id": 40363513}, {"atb": [[3.7, 2.65], [1.01, 146.31], [4.2, 18.38], [6.4, 5.45], [3.6, 45.23], [8.4, 3.97], [5.2, 14], [9, 3.72], [1.14, 2]], "atl": [[50, 0.07], [42, 3.16], [160, 1.22], [80, 1.64], [260, 0.75], [690, 0.03]], "spl": [[16, 3.18]], "batb": [[8, 1.01, 146.31], [7, 1.14, 2], [6, 3.6, 45.23], [5, 3.7, 2.65], [4, 4.2, 18.38], [2, 6.4, 5.45], [3, 5.2, 14], [1, 8.4, 3.97], [0, 9, 3.72]], "batl": [[1, 80, 1.71], [3, 690, 0.78], [2, 160, 1.22], [0, 42, 3.16]], "id": 40186642}], "img": true, "tv": 0}, {"id": "1.185781645", "marketDefinition": {"bspMarket": true, "turnInPlayEnabled": true, "persistenceEnabled": true, "marketBaseRate": 8, "eventId": "30738618", "eventTypeId": "7", "numberOfWinners": 1, "bettingType": "ODDS", "marketType": "WIN", "marketTime": "2021-07-30T10:42:00.000Z", "suspendTime": "2021-07-30T10:42:00.000Z", "bspReconciled": false, "complete": true, "inPlay": false, "crossMatching": true, "runnersVoidable": false, "numberOfActiveRunners": 9, "betDelay": 0, "status": "OPEN", "runners": [{"adjustmentFactor": 6.746, "status": "ACTIVE", "sortPriority": 1, "id": 35695577}, {"adjustmentFactor": 25.396, "status": "ACTIVE", "sortPriority": 2, "id": 23202290}, {"adjustmentFactor": 1.005, "status": "ACTIVE", "sortPriority": 3, "id": 11612913}, {"adjustmentFactor": 33.862, "status": "ACTIVE", "sortPriority": 4, "id": 20044650}, {"adjustmentFactor": 3.855, "status": "ACTIVE", "sortPriority": 5, "id": 38707079}, {"adjustmentFactor": 7.793, "status": "ACTIVE", "sortPriority": 6, "id": 21695366}, {"adjustmentFactor": 3.855, "status": "ACTIVE", "sortPriority": 7, "id": 19463916}, {"adjustmentFactor": 12.691, "status": "ACTIVE", "sortPriority": 8, "id": 12822256}, {"adjustmentFactor": 4.796, "status": "ACTIVE", "sortPriority": 9, "id": 11298337}, {"adjustmentFactor": 1.545, "status": "REMOVED", "sortPriority": 10, "removalDate": "2021-07-29T23:43:08.000Z", "id": 498387}], "regulators": ["MR_INT"], "venue": "Newcastle", "countryCode": "AU", "discountAllowed": true, "timezone": "Australia/Sydney", "openDate": "2021-07-30T07:10:00.000Z", "version": 3938308160, "raceType": "Flat", "priceLadderDefinition": {"type": "CLASSIC"}}, "rc": [{"atb": [[3.8, 42.01], [1.01, 146.31], [3.9, 2.47], [9.2, 3.59], [4.6, 16.33], [7.2, 4.74], [5.6, 12.78], [1.14, 2]], "atl": [[150, 0.07], [110, 1.19], [55, 2.4], [210, 0.93], [310, 0.63], [690, 0.03]], "spl": [[1.01, 7.95]], "batb": [[7, 1.01, 146.31], [5, 3.8, 42.01], [6, 1.14, 2], [4, 3.9, 2.47], [0, 9.2, 3.59], [3, 4.6, 16.33], [2, 5.6, 12.78], [1, 7.2, 4.74]], "batl": [[3, 690, 0.66], [2, 210, 1], [1, 110, 1.19], [0, 55, 2.4]], "id": 11298337}, {"atb": [[2.6, 36.76], [1.01, 146.31], [2.4, 84.01], [2.46, 4.91], [3, 14.7], [2.8, 32.67], [3.5, 11.76], [1.14, 2]], "atl": [[9.6, 15.06], [14, 9.96], [28, 7.19], [19, 10.79], [690, 0.03]], "spl": [[8.4, 4.77]], "batb": [[7, 1.01, 146.31], [5, 2.4, 84.01], [3, 2.6, 36.76], [6, 1.14, 2], [4, 2.46, 4.91], [2, 2.8, 32.67], [1, 3, 14.7], [0, 3.5, 11.76]], "batl": [[0, 9.6, 15.06], [1, 14, 9.96], [3, 28, 7.19], [2, 19, 10.79], [4, 690, 0.03]], "id": 23202290}, {"atb": [[5.3, 11.94], [2.86, 63.23], [1.01, 146.31], [2.94, 3.69], [3.65, 22.19], [3.15, 27.35], [4.3, 8.91], [1.14, 2]], "atl": [[18.5, 0.07], [23, 5.89], [36, 5.55], [65, 3.04], [16.5, 8.35], [690, 0.03]], "spl": [[16, 3.18]], "batb": [[7, 1.01, 146.31], [5, 2.86, 63.23], [0, 5.3, 11.94], [6, 1.14, 2], [4, 2.94, 3.69], [3, 3.15, 27.35], [2, 3.65, 22.19], [1, 4.3, 8.91]], "batl": [[1, 23, 5.96], [4, 690, 0.03], [3, 65, 3.04], [2, 36, 5.55], [0, 16.5, 8.35]], "id": 12822256}, {"atb": [[3.8, 42.01], [1.01, 146.31], [3.9, 2.47], [9.2, 3.59], [4.6, 16.33], [7.2, 4.74], [5.6, 12.78], [1.14, 2]], "atl": [[150, 0.07], [110, 1.19], [55, 2.4], [210, 0.93], [310, 0.63], [690, 0.03]], "batb": [[7, 1.01, 146.31], [5, 3.8, 42.01], [6, 1.14, 2], [4, 3.9, 2.47], [0, 9.2, 3.59], [3, 4.6, 16.33], [2, 5.6, 12.78], [1, 7.2, 4.74]], "batl": [[3, 690, 0.66], [2, 210, 1], [1, 110, 1.19], [0, 55, 2.4]], "id": 19463916}, {"atb": [[1.01, 146.31], [9.4, 14], [13.5, 4.7], [27, 1.13], [44, 0.68], [18.5, 3.36], [1.14, 2]], "atl": [[460, 0.28], [360, 0.36], [660, 0.3], [560, 0.35], [690, 0.03]], "batb": [[5, 1.01, 146.31], [4, 1.14, 2], [3, 9.4, 14], [2, 13.5, 4.7], [1, 18.5, 3.36], [0, 27, 1.81]], "batl": [[1, 690, 0.03], [0, 660, 1.29]], "id": 11612913}, {"atb": [[1.01, 146.31], [3.1, 3.41], [3.5, 23.52], [3, 58.8], [4, 19.6], [6, 5.88], [5, 7.35], [6.6, 3.72], [1.14, 2]], "atl": [[24, 5.63], [38, 3.5], [140, 1.4], [70, 2.81], [690, 0.03]], "batb": [[8, 1.01, 146.31], [7, 1.14, 2], [6, 3, 58.8], [5, 3.1, 3.41], [4, 3.5, 23.52], [3, 4, 19.6], [2, 5, 7.35], [1, 6, 5.88], [0, 6.6, 3.72]], "batl": [[4, 690, 0.03], [3, 140, 1.4], [2, 70, 2.81], [1, 38, 3.5], [0, 24, 5.63]], "id": 35695577}, {"atb": [[1.01, 146.31], [4.7, 1.94], [4.6, 32.67], [9.2, 3.59], [13, 2.45], [7.2, 9.48], [5.6, 12.78], [1.14, 2]], "atl": [[320, 0.07], [380, 0.51], [180, 0.73], [90, 1.46], [280, 0.69], [690, 0.03]], "batb": [[7, 1.01, 146.31], [6, 1.14, 2], [5, 4.6, 32.67], [4, 4.7, 1.94], [1, 9.2, 3.59], [3, 5.6, 12.78], [2, 7.2, 9.48], [0, 13, 2.45]], "batl": [[2, 690, 0.61], [1, 280, 1.42], [0, 90, 1.46]], "id": 21695366}, {"atb": [[1.7, 84.01], [1.01, 146.31], [1.6, 196.02], [1.8, 73.51], [1.73, 9.83], [1.9, 32.67], [2, 29.4], [1.14, 2]], "atl": [[5.8, 26.98], [4.8, 34.08], [5.2, 0.07], [7.6, 29.43], [9.6, 22.58], [3.5, 2.65], [690, 0.03]], "spl": [[3.4, 8.48]], "batb": [[7, 1.01, 146.31], [5, 1.6, 196.02], [4, 1.7, 84.01], [3, 1.73, 9.83], [2, 1.8, 73.51], [6, 1.14, 2], [1, 1.9, 32.67], [0, 2, 29.4]], "batl": [[2, 5.8, 27.05], [1, 4.8, 34.08], [5, 690, 0.03], [4, 9.6, 22.58], [3, 7.6, 29.43], [0, 3.5, 2.65]], "id": 20044650}, {"atb": [[1.01, 146.31], [3.6, 2.76], [3.5, 47.04], [5, 14.7], [4, 19.6], [6, 5.88], [8, 4.2], [1.14, 2]], "atl": [[48, 0.07], [250, 0.78], [40, 3.32], [150, 1.3], [75, 1.75], [690, 0.03]], "batb": [[7, 1.01, 146.31], [6, 1.14, 2], [5, 3.5, 47.04], [4, 3.6, 2.76], [3, 4, 19.6], [2, 5, 14.7], [1, 6, 5.88], [0, 8, 4.2]], "batl": [[1, 75, 1.82], [3, 690, 0.81], [2, 150, 1.3], [0, 40, 3.32]], "id": 38707079}], "img": true, "tv": 0}, {"id": "1.185798785", "marketDefinition": {"bspMarket": true, "turnInPlayEnabled": true, "persistenceEnabled": true, "marketBaseRate": 8, "eventId": "30739923", "eventTypeId": "7", "numberOfWinners": 1, "bettingType": "ODDS", "marketType": "WIN", "marketTime": "2021-07-30T11:29:00.000Z", "suspendTime": "2021-07-30T11:29:00.000Z", "bspReconciled": false, "complete": true, "inPlay": false, "crossMatching": true, "runnersVoidable": false, "numberOfActiveRunners": 10, "betDelay": 0, "status": "OPEN", "runners": [{"adjustmentFactor": 12.422, "status": "ACTIVE", "sortPriority": 1, "id": 28246583}, {"adjustmentFactor": 8.213, "status": "ACTIVE", "sortPriority": 2, "id": 11338384}, {"adjustmentFactor": 0.464, "status": "ACTIVE", "sortPriority": 3, "id": 28091438}, {"adjustmentFactor": 8.213, "status": "ACTIVE", "sortPriority": 4, "id": 29059570}, {"adjustmentFactor": 6.097, "status": "ACTIVE", "sortPriority": 5, "id": 22970859}, {"adjustmentFactor": 1.376, "status": "ACTIVE", "sortPriority": 6, "id": 23390459}, {"adjustmentFactor": 24.973, "status": "ACTIVE", "sortPriority": 7, "id": 38553684}, {"adjustmentFactor": 6.521, "status": "ACTIVE", "sortPriority": 8, "id": 36386736}, {"adjustmentFactor": 30.751, "status": "ACTIVE", "sortPriority": 9, "id": 26608798}, {"adjustmentFactor": 0.969, "status": "ACTIVE", "sortPriority": 10, "id": 40365326}], "regulators": ["MR_INT"], "venue": "Parkes", "countryCode": "AU", "discountAllowed": true, "timezone": "Australia/Sydney", "openDate": "2021-07-30T08:55:00.000Z", "version": 3938311440, "raceType": "Flat", "priceLadderDefinition": {"type": "CLASSIC"}}, "rc": [{"atb": [[2.84, 31.96], [2.44, 81.68], [2.64, 35.86], [3.1, 14], [3.6, 11.31], [1.01, 146.31], [1.2, 122], [1.14, 2]], "atl": [[30, 6.7], [15, 9.25], [20, 10.22], [10, 14.39], [13, 0.07], [690, 0.03]], "spl": [[1.01, 7.95]], "batb": [[7, 1.01, 146.31], [6, 1.14, 2], [5, 1.2, 122], [4, 2.44, 81.68], [3, 2.64, 35.86], [2, 2.84, 31.96], [1, 3.1, 14], [0, 3.6, 11.31]], "batl": [[4, 690, 0.03], [3, 30, 6.7], [2, 20, 10.22], [1, 15, 9.32], [0, 10, 14.39]], "id": 38553684}, {"atb": [[3.5, 23.52], [3, 58.8], [6, 5.88], [5, 7.35], [4, 19.6], [1.01, 146.31], [1.2, 122], [1.14, 2]], "atl": [[24, 5.63], [38, 3.5], [140, 1.4], [70, 2.81], [690, 0.03]], "batb": [[7, 1.01, 146.31], [6, 1.14, 2], [5, 1.2, 122], [4, 3, 58.8], [3, 3.5, 23.52], [2, 4, 19.6], [1, 5, 7.35], [0, 6, 5.88]], "batl": [[4, 690, 0.03], [3, 140, 1.4], [2, 70, 2.81], [1, 38, 3.5], [0, 24, 5.63]], "id": 11338384}, {"atb": [[1.01, 146.31], [9.4, 14], [13.5, 4.7], [27, 1.13], [44, 0.68], [18.5, 3.36], [1.2, 122], [1.14, 2]], "atl": [[460, 0.28], [360, 0.36], [660, 0.3], [560, 0.35], [690, 0.03]], "batb": [[6, 1.01, 146.31], [5, 1.14, 2], [4, 1.2, 122], [3, 9.4, 14], [2, 13.5, 4.7], [1, 18.5, 3.36], [0, 27, 1.81]], "batl": [[1, 690, 0.03], [0, 660, 1.29]], "id": 28091438}, {"atb": [[13, 2.45], [9.2, 7.17], [18, 1.73], [7.2, 9.48], [5.6, 25.57], [1.01, 146.31], [1.2, 122], [1.14, 2]], "atl": [[250, 0.52], [450, 0.43], [350, 0.56], [150, 0.87], [600, 0.07], [690, 0.03]], "batb": [[7, 1.01, 146.31], [6, 1.14, 2], [5, 1.2, 122], [4, 5.6, 25.57], [3, 7.2, 9.48], [2, 9.2, 7.17], [1, 13, 2.45], [0, 18, 1.73]], "batl": [[2, 690, 0.03], [1, 600, 1.06], [0, 250, 1.39]], "id": 40365326}, {"atb": [[14, 3.72], [3.9, 40.55], [7.6, 4.46], [5.8, 12.25], [4.8, 15.47], [9.6, 3.42], [1.01, 146.31], [1.2, 122], [1.14, 2]], "atl": [[230, 0.85], [330, 0.59], [130, 1], [65, 2.02], [170, 0.07], [690, 0.03]], "batb": [[8, 1.01, 146.31], [7, 1.14, 2], [6, 1.2, 122], [5, 3.9, 40.55], [4, 4.8, 15.47], [3, 5.8, 12.25], [2, 7.6, 4.46], [1, 9.6, 3.42], [0, 14, 3.72]], "batl": [[3, 690, 0.03], [2, 330, 1.51], [1, 130, 1], [0, 65, 2.02]], "id": 22970859}, {"atb": [[2.12, 105.01], [2.52, 38.69], [2.32, 44.55], [2.72, 17.1], [2.92, 15.32], [1.01, 146.31], [3.2, 26.49], [1.2, 122], [1.14, 2]], "atl": [[13, 16.18], [9.2, 15.79], [18, 11.42], [7.2, 20.88], [5.4, 2.65], [6, 0.07], [690, 0.03]], "batb": [[8, 1.01, 146.31], [7, 1.14, 2], [6, 1.2, 122], [5, 2.12, 105.01], [4, 2.32, 44.55], [3, 2.52, 38.69], [2, 2.72, 17.1], [1, 2.92, 15.32], [0, 3.2, 26.49]], "batl": [[5, 690, 0.03], [4, 18, 11.42], [3, 13, 16.18], [2, 9.2, 15.79], [1, 7.2, 20.95], [0, 5.4, 2.65]], "id": 26608798}, {"atb": [[19.5, 3.72], [14, 2.26], [7.6, 8.91], [5.8, 12.25], [4.8, 30.95], [9.6, 3.42], [1.01, 146.31], [1.2, 122], [1.14, 2]], "atl": [[390, 0.5], [190, 0.68], [95, 1.38], [290, 0.67], [330, 0.07], [690, 0.03]], "batb": [[8, 1.01, 146.31], [7, 1.14, 2], [6, 1.2, 122], [5, 4.8, 30.95], [4, 5.8, 12.25], [3, 7.6, 8.91], [2, 9.6, 3.42], [1, 14, 2.26], [0, 19.5, 3.72]], "batl": [[2, 690, 0.6], [1, 290, 1.35], [0, 95, 1.38]], "id": 36386736}, {"atb": [[2.76, 16.7], [2.16, 101.39], [2.96, 15], [2.36, 43.24], [2.56, 37.69], [1.01, 146.31], [1.2, 122], [1.14, 2]], "atl": [[9.4, 15.42], [13.5, 15.54], [7.4, 20.23], [18.5, 11.1], [7, 15.89], [690, 0.03]], "batb": [[7, 1.01, 146.31], [6, 1.14, 2], [5, 1.2, 122], [4, 2.16, 101.39], [3, 2.36, 43.24], [2, 2.56, 37.69], [1, 2.76, 16.7], [0, 2.96, 15]], "batl": [[5, 690, 0.03], [4, 18.5, 11.1], [3, 13.5, 15.54], [2, 9.4, 15.42], [1, 7.4, 20.23], [0, 7, 15.89]], "id": 28246583}, {"atb": [[2.84, 31.96], [2.44, 81.68], [2.64, 35.86], [3.1, 14], [3.6, 11.31], [1.01, 146.31], [1.2, 122], [1.14, 2]], "atl": [[30, 6.7], [15, 9.25], [20, 10.22], [10, 14.39], [13, 0.07], [690, 0.03]], "batb": [[7, 1.01, 146.31], [6, 1.14, 2], [5, 1.2, 122], [4, 2.44, 81.68], [3, 2.64, 35.86], [2, 2.84, 31.96], [1, 3.1, 14], [0, 3.6, 11.31]], "batl": [[4, 690, 0.03], [3, 30, 6.7], [2, 20, 10.22], [1, 15, 9.32], [0, 10, 14.39]], "id": 29059570}, {"atb": [[15.5, 2.03], [8.2, 8.17], [6.2, 11.31], [10.5, 3.09], [5.1, 28.69], [1.01, 146.31], [1.2, 122], [1.14, 2]], "atl": [[400, 0.49], [200, 0.65], [100, 1.31], [300, 0.65], [440, 0.07], [690, 0.03]], "batb": [[7, 1.01, 146.31], [6, 1.14, 2], [5, 1.2, 122], [4, 5.1, 28.69], [3, 6.2, 11.31], [2, 8.2, 8.17], [1, 10.5, 3.09], [0, 15.5, 2.03]], "batl": [[2, 690, 0.59], [1, 300, 1.3], [0, 100, 1.31]], "id": 23390459}], "img": true, "tv": 0}, {"id": "1.185781643", "marketDefinition": {"bspMarket": true, "turnInPlayEnabled": true, "persistenceEnabled": true, "marketBaseRate": 8, "eventId": "30738618", "eventTypeId": "7", "numberOfWinners": 1, "bettingType": "ODDS", "marketType": "WIN", "marketTime": "2021-07-30T10:12:00.000Z", "suspendTime": "2021-07-30T10:12:00.000Z", "bspReconciled": false, "complete": true, "inPlay": false, "crossMatching": true, "runnersVoidable": false, "numberOfActiveRunners": 10, "betDelay": 0, "status": "OPEN", "runners": [{"adjustmentFactor": 2.881, "status": "ACTIVE", "sortPriority": 1, "id": 28253040}, {"adjustmentFactor": 4.46, "status": "ACTIVE", "sortPriority": 2, "id": 38848065}, {"adjustmentFactor": 33.294, "status": "ACTIVE", "sortPriority": 3, "id": 28737944}, {"adjustmentFactor": 6.9, "status": "ACTIVE", "sortPriority": 4, "id": 12462445}, {"adjustmentFactor": 4.46, "status": "ACTIVE", "sortPriority": 5, "id": 37454805}, {"adjustmentFactor": 23.459, "status": "ACTIVE", "sortPriority": 6, "id": 12580967}, {"adjustmentFactor": 8.115, "status": "ACTIVE", "sortPriority": 7, "id": 25463716}, {"adjustmentFactor": 4.46, "status": "ACTIVE", "sortPriority": 8, "id": 1417332}, {"adjustmentFactor": 5.986, "status": "ACTIVE", "sortPriority": 9, "id": 9332710}, {"adjustmentFactor": 5.986, "status": "ACTIVE", "sortPriority": 10, "id": 35896596}], "regulators": ["MR_INT"], "venue": "Newcastle", "countryCode": "AU", "discountAllowed": true, "timezone": "Australia/Sydney", "openDate": "2021-07-30T07:10:00.000Z", "version": 3938308166, "raceType": "Flat", "priceLadderDefinition": {"type": "CLASSIC"}}, "rc": [{"atb": [[2.1, 26.73], [1.75, 156.81], [1.95, 61.9], [1.78, 9.2], [2.3, 22.62], [1.01, 248.54], [1.85, 69.18], [1.14, 2]], "atl": [[8.6, 25.56], [6.6, 23.12], [5.3, 30.11], [11.5, 18.49], [4, 2.65], [690, 0.03]], "spl": [[4.4, 6.89]], "batb": [[7, 1.01, 248.54], [5, 1.75, 156.81], [4, 1.78, 9.2], [2, 1.95, 61.9], [1, 2.1, 26.73], [0, 2.3, 22.62], [6, 1.14, 2], [3, 1.85, 69.18]], "batl": [[3, 8.6, 25.56], [2, 6.6, 23.12], [1, 5.3, 30.11], [5, 690, 0.03], [4, 11.5, 18.49], [0, 4, 2.65]], "id": 28737944}, {"atb": [[2.96, 60.01], [1.01, 248.54], [3.05, 3.5], [3.9, 20.28], [3.4, 24.5], [5.8, 6.12], [4.8, 7.74], [6.2, 3.72], [1.14, 2]], "atl": [[23, 0.07], [19.5, 7], [29, 4.62], [48, 4.13], [95, 2.07], [690, 0.03]], "spl": [[1.01, 7.95]], "batb": [[8, 1.01, 248.54], [6, 2.96, 60.01], [7, 1.14, 2], [5, 3.05, 3.5], [4, 3.4, 24.5], [3, 3.9, 20.28], [2, 4.8, 7.74], [1, 5.8, 6.12], [0, 6.2, 3.72]], "batl": [[1, 29, 4.69], [4, 690, 0.03], [0, 19.5, 7], [3, 95, 2.07], [2, 48, 4.13]], "id": 25463716}, {"atb": [[15.5, 3.72], [1.01, 248.54], [5, 1.79], [4.8, 30.95], [14, 2.26], [7.6, 8.91], [5.8, 12.25], [9.6, 3.42], [1.14, 2]], "atl": [[330, 0.07], [390, 0.5], [190, 0.68], [95, 1.38], [290, 0.67], [690, 0.03]], "batb": [[8, 1.01, 248.54], [7, 1.14, 2], [6, 4.8, 30.95], [5, 5, 1.79], [4, 5.8, 12.25], [3, 7.6, 8.91], [2, 9.6, 3.42], [1, 14, 2.26], [0, 15.5, 3.72]], "batl": [[2, 690, 0.6], [1, 290, 1.35], [0, 95, 1.38]], "id": 12462445}, {"atb": [[3.35, 3.06], [1.01, 248.54], [3.75, 21.38], [3.25, 52.27], [4.5, 16.8], [7, 4.9], [5.5, 6.53], [1.14, 2]], "atl": [[38, 0.07], [30, 4.47], [200, 0.97], [100, 1.96], [50, 2.64], [690, 0.03]], "batb": [[7, 1.01, 248.54], [4, 3.35, 3.06], [6, 1.14, 2], [5, 3.25, 52.27], [3, 3.75, 21.38], [2, 4.5, 16.8], [1, 5.5, 6.53], [0, 7, 4.9]], "batl": [[1, 50, 2.71], [0, 30, 4.47], [3, 690, 1], [2, 100, 1.96]], "id": 1417332}, {"atb": [[1.01, 248.54], [2.72, 34.19], [2.92, 30.63], [2.58, 4.54], [2.52, 77.37], [3.3, 12.78], [3.8, 10.5], [1.14, 2]], "atl": [[14, 0.07], [24, 8.44], [12, 11.77], [38, 5.25], [17, 8.09], [690, 0.03]], "spl": [[10, 4.24]], "batb": [[7, 1.01, 248.54], [3, 2.72, 34.19], [2, 2.92, 30.63], [6, 1.14, 2], [5, 2.52, 77.37], [4, 2.58, 4.54], [1, 3.3, 12.78], [0, 3.8, 10.5]], "batl": [[1, 17, 8.16], [4, 690, 0.03], [3, 38, 5.25], [2, 24, 8.44], [0, 12, 11.77]], "id": 12580967}, {"atb": [[3.35, 3.06], [1.01, 248.54], [3.75, 21.38], [3.25, 52.27], [4.5, 16.8], [7, 4.9], [5.5, 6.53], [7.4, 3.72], [1.14, 2]], "atl": [[38, 0.07], [30, 4.47], [200, 0.97], [100, 1.96], [50, 2.64], [690, 0.03]], "batb": [[8, 1.01, 248.54], [5, 3.35, 3.06], [7, 1.14, 2], [6, 3.25, 52.27], [4, 3.75, 21.38], [3, 4.5, 16.8], [2, 5.5, 6.53], [1, 7, 4.9], [0, 7.4, 3.72]], "batl": [[1, 50, 2.71], [0, 30, 4.47], [3, 690, 1], [2, 100, 1.96]], "id": 9332710}, {"atb": [[1.01, 248.54], [6.6, 1.28], [8.4, 7.95], [6.4, 21.78], [11, 5.88], [22, 1.4], [16, 1.96], [1.14, 2]], "atl": [[500, 0.39], [400, 0.49], [200, 0.65], [300, 0.43], [690, 0.03]], "batb": [[7, 1.01, 248.54], [6, 1.14, 2], [5, 6.4, 21.78], [4, 6.6, 1.28], [3, 8.4, 7.95], [2, 11, 5.88], [1, 16, 1.96], [0, 22, 1.4]], "batl": [[1, 690, 0.91], [0, 300, 1.08]], "id": 28253040}, {"atb": [[1.01, 248.54], [5.1, 28.69], [5.3, 1.67], [15.5, 2.03], [8.2, 8.17], [6.2, 11.31], [10.5, 3.09], [17, 3.72], [1.14, 2]], "atl": [[440, 0.07], [400, 0.49], [200, 0.65], [100, 1.31], [300, 0.65], [690, 0.03]], "batb": [[8, 1.01, 248.54], [6, 5.1, 28.69], [7, 1.14, 2], [5, 5.3, 1.67], [4, 6.2, 11.31], [3, 8.2, 8.17], [2, 10.5, 3.09], [1, 15.5, 2.03], [0, 17, 3.72]], "batl": [[2, 690, 0.59], [1, 300, 1.3], [0, 100, 1.31]], "id": 37454805}, {"atb": [[1.01, 248.54], [4.1, 2.32], [5, 14.7], [4, 39.2], [6, 11.76], [10, 3.27], [8, 4.2], [12, 3.72], [1.14, 2]], "atl": [[75, 1.75], [250, 0.78], [350, 0.56], [150, 0.87], [690, 0.03]], "batb": [[8, 1.01, 248.54], [7, 1.14, 2], [6, 4, 39.2], [5, 4.1, 2.32], [4, 5, 14.7], [3, 6, 11.76], [2, 8, 4.2], [1, 10, 3.27], [0, 12, 3.72]], "batl": [[0, 75, 1.75], [2, 690, 0.59], [1, 250, 1.65]], "id": 38848065}, {"atb": [[2.86, 63.23], [1.01, 248.54], [2.94, 3.69], [3.65, 22.19], [3.15, 27.35], [5.3, 10.56], [4.3, 8.91], [1.14, 2]], "atl": [[18.5, 0.07], [23, 5.89], [36, 5.55], [65, 3.04], [16.5, 8.35], [690, 0.03]], "batb": [[7, 1.01, 248.54], [5, 2.86, 63.23], [6, 1.14, 2], [4, 2.94, 3.69], [3, 3.15, 27.35], [2, 3.65, 22.19], [1, 4.3, 8.91], [0, 5.3, 10.56]], "batl": [[1, 23, 5.96], [4, 690, 0.03], [3, 65, 3.04], [2, 36, 5.55], [0, 16.5, 8.35]], "id": 35896596}], "img": true, "tv": 0}, {"id": "1.185781639", "marketDefinition": {"bspMarket": true, "turnInPlayEnabled": true, "persistenceEnabled": true, "marketBaseRate": 8, "eventId": "30738618", "eventTypeId": "7", "numberOfWinners": 1, "bettingType": "ODDS", "marketType": "WIN", "marketTime": "2021-07-30T09:10:00.000Z", "suspendTime": "2021-07-30T09:10:00.000Z", "bspReconciled": false, "complete": true, "inPlay": false, "crossMatching": true, "runnersVoidable": false, "numberOfActiveRunners": 8, "betDelay": 0, "status": "OPEN", "runners": [{"adjustmentFactor": 42.932, "status": "ACTIVE", "sortPriority": 1, "id": 24339254}, {"adjustmentFactor": 2.231, "status": "ACTIVE", "sortPriority": 2, "id": 27767855}, {"adjustmentFactor": 2.231, "status": "ACTIVE", "sortPriority": 3, "id": 35909525}, {"adjustmentFactor": 4.678, "status": "ACTIVE", "sortPriority": 4, "id": 19541699}, {"adjustmentFactor": 33.382, "status": "ACTIVE", "sortPriority": 5, "id": 25190260}, {"adjustmentFactor": 4.678, "status": "ACTIVE", "sortPriority": 6, "id": 5828626}, {"adjustmentFactor": 4.24, "status": "ACTIVE", "sortPriority": 7, "id": 26207247}, {"adjustmentFactor": 5.629, "status": "ACTIVE", "sortPriority": 8, "id": 13488526}, {"adjustmentFactor": 23.516, "status": "REMOVED", "sortPriority": 9, "removalDate": "2021-07-29T09:45:03.000Z", "id": 24632297}, {"adjustmentFactor": 13.021, "status": "REMOVED", "sortPriority": 10, "removalDate": "2021-07-29T23:30:52.000Z", "id": 40272085}], "regulators": ["MR_INT"], "venue": "Newcastle", "countryCode": "AU", "discountAllowed": true, "timezone": "Australia/Sydney", "openDate": "2021-07-30T07:10:00.000Z", "version": 3938308174, "raceType": "Flat", "priceLadderDefinition": {"type": "CLASSIC"}}, "rc": [{"atb": [[1.5, 117.61], [1.7, 42.01], [1.01, 146.31], [1.6, 98.01], [1.8, 36.76], [1.4, 294.02], [1.14, 2]], "atl": [[85, 5], [3.5, 51.79], [6, 38.84], [5, 48.55], [4, 43.16], [690, 0.03]], "spl": [[2.9, 9.54]], "batb": [[6, 1.01, 146.31], [4, 1.4, 294.02], [3, 1.5, 117.61], [2, 1.6, 98.01], [1, 1.7, 42.01], [0, 1.8, 36.76], [5, 1.14, 2]], "batl": [[5, 690, 0.03], [4, 85, 5], [3, 6, 38.84], [2, 5, 48.55], [1, 4, 43.16], [0, 3.5, 51.79]], "id": 24339254}, {"atb": [[2.6, 73.51], [1.01, 146.31], [3, 29.4], [2.8, 32.67], [3.5, 11.76], [4, 9.8], [1.14, 2]], "atl": [[15.5, 0.07], [13.5, 10.36], [27, 7.47], [44, 4.52], [18.5, 7.4], [690, 0.03]], "batb": [[6, 1.01, 146.31], [4, 2.6, 73.51], [3, 2.8, 32.67], [2, 3, 29.4], [5, 1.14, 2], [1, 3.5, 11.76], [0, 4, 9.8]], "batl": [[1, 18.5, 7.47], [4, 690, 0.03], [0, 13.5, 10.36], [3, 44, 4.52], [2, 27, 7.47]], "id": 19541699}, {"atb": [[2.6, 36.76], [1.01, 146.31], [2.4, 84.01], [3, 14.7], [2.8, 32.67], [3.5, 11.76], [1.14, 2]], "atl": [[9.6, 15.06], [11, 0.07], [14, 9.96], [28, 7.19], [19, 10.79], [690, 0.03]], "spl": [[7, 5.3]], "batb": [[6, 1.01, 146.31], [4, 2.4, 84.01], [3, 2.6, 36.76], [2, 2.8, 32.67], [1, 3, 14.7], [5, 1.14, 2], [0, 3.5, 11.76]], "batl": [[0, 9.6, 15.06], [1, 14, 10.03], [4, 690, 0.03], [3, 28, 7.19], [2, 19, 10.79]], "id": 25190260}, {"atb": [[1.01, 146.31], [7.2, 18.97], [13, 4.9], [26, 1.18], [9.2, 7.17], [18, 1.73], [1.14, 2]], "atl": [[250, 0.52], [450, 0.43], [350, 0.37], [550, 0.35], [690, 0.03]], "batb": [[6, 1.01, 146.31], [4, 7.2, 18.97], [5, 1.14, 2], [3, 9.2, 7.17], [2, 13, 4.9], [1, 18, 1.73], [0, 26, 1.18]], "batl": [[1, 690, 0.38], [0, 450, 1.32]], "id": 35909525}, {"atb": [[7.6, 4.46], [1.01, 146.31], [3.9, 20.28], [3.4, 49], [5.8, 6.12], [4.8, 15.47], [1.14, 2]], "atl": [[44, 0.07], [230, 0.85], [36, 3.7], [130, 1.5], [65, 2.02], [690, 0.03]], "batb": [[6, 1.01, 146.31], [0, 7.6, 4.46], [4, 3.4, 49], [3, 3.9, 20.28], [5, 1.14, 2], [2, 4.8, 15.47], [1, 5.8, 6.12]], "batl": [[1, 65, 2.09], [3, 690, 0.88], [2, 130, 1.5], [0, 36, 3.7]], "id": 5828626}, {"atb": [[1.01, 146.31], [3.5, 23.52], [3, 58.8], [4, 19.6], [6, 5.88], [5, 7.35], [1.14, 2]], "atl": [[24, 5.63], [38, 3.5], [140, 1.4], [70, 2.81], [690, 0.03]], "batb": [[6, 1.01, 146.31], [4, 3, 58.8], [3, 3.5, 23.52], [2, 4, 19.6], [5, 1.14, 2], [1, 5, 7.35], [0, 6, 5.88]], "batl": [[4, 690, 0.03], [3, 140, 1.4], [2, 70, 2.81], [1, 38, 3.5], [0, 24, 5.63]], "id": 27767855}, {"atb": [[1.01, 146.31], [4.8, 30.95], [14, 2.26], [7.6, 8.91], [5.8, 12.25], [9.6, 3.42], [1.14, 2]], "atl": [[330, 0.07], [390, 0.5], [190, 0.68], [95, 1.38], [290, 0.67], [690, 0.03]], "batb": [[6, 1.01, 146.31], [4, 4.8, 30.95], [5, 1.14, 2], [3, 5.8, 12.25], [2, 7.6, 8.91], [1, 9.6, 3.42], [0, 14, 2.26]], "batl": [[2, 690, 0.6], [1, 290, 1.35], [0, 95, 1.38]], "id": 26207247}, {"atb": [[7.6, 4.46], [1.01, 146.31], [3.9, 40.55], [5.8, 12.25], [4.8, 15.47], [9.6, 3.42], [1.14, 2]], "atl": [[170, 0.07], [230, 0.85], [330, 0.59], [130, 1], [65, 2.02], [690, 0.03]], "batb": [[6, 1.01, 146.31], [1, 7.6, 4.46], [4, 3.9, 40.55], [5, 1.14, 2], [3, 4.8, 15.47], [2, 5.8, 12.25], [0, 9.6, 3.42]], "batl": [[2, 330, 1.51], [3, 690, 0.03], [1, 130, 1], [0, 65, 2.02]], "id": 13488526}], "img": true, "tv": 0}, {"id": "1.185781637", "marketDefinition": {"bspMarket": true, "turnInPlayEnabled": true, "persistenceEnabled": true, "marketBaseRate": 8, "eventId": "30738618", "eventTypeId": "7", "numberOfWinners": 1, "bettingType": "ODDS", "marketType": "WIN", "marketTime": "2021-07-30T08:42:00.000Z", "suspendTime": "2021-07-30T08:42:00.000Z", "bspReconciled": false, "complete": true, "inPlay": false, "crossMatching": true, "runnersVoidable": false, "numberOfActiveRunners": 10, "betDelay": 0, "status": "OPEN", "runners": [{"adjustmentFactor": 7.038, "status": "ACTIVE", "sortPriority": 1, "id": 24826178}, {"adjustmentFactor": 3.682, "status": "ACTIVE", "sortPriority": 2, "id": 2538478}, {"adjustmentFactor": 23.506, "status": "ACTIVE", "sortPriority": 3, "id": 25091520}, {"adjustmentFactor": 3.682, "status": "ACTIVE", "sortPriority": 4, "id": 17439673}, {"adjustmentFactor": 4.618, "status": "ACTIVE", "sortPriority": 5, "id": 40363512}, {"adjustmentFactor": 0.87, "status": "ACTIVE", "sortPriority": 6, "id": 20482518}, {"adjustmentFactor": 22.196, "status": "ACTIVE", "sortPriority": 7, "id": 13220621}, {"adjustmentFactor": 22.196, "status": "ACTIVE", "sortPriority": 8, "id": 24074958}, {"adjustmentFactor": 4.618, "status": "ACTIVE", "sortPriority": 9, "id": 2316584}, {"adjustmentFactor": 7.594, "status": "ACTIVE", "sortPriority": 10, "id": 17020711}], "regulators": ["MR_INT"], "venue": "Newcastle", "countryCode": "AU", "discountAllowed": true, "timezone": "Australia/Sydney", "openDate": "2021-07-30T07:10:00.000Z", "version": 3938308178, "raceType": "Flat", "priceLadderDefinition": {"type": "CLASSIC"}}, "rc": [{"atb": [[2.6, 73.51], [1.01, 146.31], [3, 29.4], [2.8, 32.67], [3.5, 11.76], [4, 9.8], [1.14, 2]], "atl": [[15.5, 0.07], [13.5, 10.36], [27, 7.47], [44, 4.52], [18.5, 7.4], [690, 0.03]], "batb": [[6, 1.01, 146.31], [4, 2.6, 73.51], [3, 2.8, 32.67], [2, 3, 29.4], [1, 3.5, 11.76], [0, 4, 9.8], [5, 1.14, 2]], "batl": [[1, 18.5, 7.47], [4, 690, 0.03], [0, 13.5, 10.36], [3, 44, 4.52], [2, 27, 7.47]], "id": 24826178}, {"atb": [[1.01, 146.31], [4.8, 30.95], [14, 2.26], [7.6, 8.91], [5.8, 12.25], [9.6, 3.42], [1.14, 2]], "atl": [[330, 0.07], [390, 0.5], [190, 0.68], [95, 1.38], [290, 0.67], [690, 0.03]], "batb": [[6, 1.01, 146.31], [4, 4.8, 30.95], [5, 1.14, 2], [3, 5.8, 12.25], [2, 7.6, 8.91], [1, 9.6, 3.42], [0, 14, 2.26]], "batl": [[2, 690, 0.6], [1, 290, 1.35], [0, 95, 1.38]], "id": 17439673}, {"atb": [[1.01, 146.31], [42, 0.72], [13, 9.8], [18, 3.46], [26, 2.35], [80, 0.37], [1.14, 2]], "atl": [[600, 0.07], [1000, 0.2], [940, 0.21], [840, 0.15], [740, 0.17], [690, 0.03]], "batb": [[5, 1.01, 146.31], [0, 42, 1.09], [3, 13, 9.8], [2, 18, 3.46], [4, 1.14, 2], [1, 26, 2.35]], "batl": [[0, 1000, 0.83]], "id": 20482518}, {"atb": [[1.01, 146.31], [5.6, 25.57], [13, 2.45], [9.2, 7.17], [18, 1.73], [7.2, 9.48], [1.14, 2]], "atl": [[600, 0.07], [250, 0.52], [450, 0.43], [350, 0.56], [150, 0.87], [690, 0.03]], "batb": [[6, 1.01, 146.31], [4, 5.6, 25.57], [5, 1.14, 2], [3, 7.2, 9.48], [2, 9.2, 7.17], [1, 13, 2.45], [0, 18, 1.73]], "batl": [[2, 690, 0.03], [1, 600, 1.06], [0, 250, 1.39]], "id": 2538478}, {"atb": [[2.6, 73.51], [1.01, 146.31], [3, 29.4], [2.8, 32.67], [3.5, 11.76], [4, 9.8], [1.14, 2]], "atl": [[13.5, 10.36], [27, 7.47], [44, 4.52], [18.5, 7.4], [690, 0.03]], "spl": [[10, 4.24], [1.01, 7.95]], "batb": [[6, 1.01, 146.31], [4, 2.6, 73.51], [3, 2.8, 32.67], [2, 3, 29.4], [1, 3.5, 11.76], [0, 4, 9.8], [5, 1.14, 2]], "batl": [[0, 13.5, 10.36], [3, 44, 4.52], [2, 27, 7.47], [1, 18.5, 7.4], [4, 690, 0.03]], "id": 13220621}, {"atb": [[2.9, 61.9], [1.01, 146.31], [5.7, 3.72], [3.75, 21.38], [3.25, 26.13], [5.5, 6.53], [4.5, 8.4], [1.14, 2]], "atl": [[24, 5.63], [38, 5.25], [70, 2.81], [17, 8.09], [690, 0.03]], "batb": [[7, 1.01, 146.31], [5, 2.9, 61.9], [6, 1.14, 2], [4, 3.25, 26.13], [3, 3.75, 21.38], [2, 4.5, 8.4], [1, 5.5, 6.53], [0, 5.7, 3.72]], "batl": [[4, 690, 0.03], [3, 70, 2.81], [2, 38, 5.25], [1, 24, 5.63], [0, 17, 8.09]], "id": 17020711}, {"atb": [[2.32, 89.1], [1.01, 146.31], [2.72, 34.19], [2.92, 15.32], [2.52, 38.69], [3.3, 12.78], [1.14, 2]], "atl": [[9.6, 0.07], [8.8, 16.6], [17, 12.14], [24, 8.44], [12, 11.77], [690, 0.03]], "spl": [[8.4, 4.77]], "batb": [[6, 1.01, 146.31], [4, 2.32, 89.1], [2, 2.72, 34.19], [1, 2.92, 15.32], [3, 2.52, 38.69], [5, 1.14, 2], [0, 3.3, 12.78]], "batl": [[1, 12, 11.84], [4, 690, 0.03], [2, 17, 12.14], [0, 8.8, 16.6], [3, 24, 8.44]], "id": 25091520}, {"atb": [[1.01, 146.31], [3.5, 47.04], [5, 14.7], [4, 19.6], [6, 5.88], [8, 4.2], [1.14, 2]], "atl": [[48, 0.07], [40, 3.32], [75, 1.75], [250, 0.78], [150, 1.3], [690, 0.03]], "batb": [[6, 1.01, 146.31], [4, 3.5, 47.04], [3, 4, 19.6], [2, 5, 14.7], [1, 6, 5.88], [0, 8, 4.2], [5, 1.14, 2]], "batl": [[1, 75, 1.82], [3, 690, 0.81], [0, 40, 3.32], [2, 150, 1.3]], "id": 40363512}, {"atb": [[4.2, 36.76], [1.01, 146.31], [8.4, 3.97], [5.2, 14], [11, 2.94], [6.4, 10.89], [1.14, 2]], "atl": [[360, 0.54], [160, 0.82], [80, 1.64], [260, 0.75], [690, 0.03]], "batb": [[6, 1.01, 146.31], [4, 4.2, 36.76], [5, 1.14, 2], [3, 5.2, 14], [2, 6.4, 10.89], [1, 8.4, 3.97], [0, 11, 2.94]], "batl": [[2, 690, 0.57], [1, 260, 1.57], [0, 80, 1.64]], "id": 2316584}, {"atb": [[2.64, 35.86], [1.01, 146.31], [2.24, 94.85], [2.84, 15.98], [2.44, 40.83], [3.1, 14], [1.14, 2]], "atl": [[6, 2.65], [14.5, 14.39], [7.8, 19.04], [9.8, 14.71], [19.5, 10.5], [690, 0.03]], "spl": [[8.4, 4.77]], "batb": [[6, 1.01, 146.31], [4, 2.24, 94.85], [2, 2.64, 35.86], [3, 2.44, 40.83], [1, 2.84, 15.98], [0, 3.1, 14], [5, 1.14, 2]], "batl": [[5, 690, 0.03], [4, 19.5, 10.5], [3, 14.5, 14.39], [2, 9.8, 14.71], [1, 7.8, 19.04], [0, 6, 2.65]], "id": 24074958}], "img": true, "tv": 0}, {"id": "1.185783407", "marketDefinition": {"bspMarket": true, "turnInPlayEnabled": true, "persistenceEnabled": true, "marketBaseRate": 6, "eventId": "30738738", "eventTypeId": "7", "numberOfWinners": 1, "bettingType": "ODDS", "marketType": "WIN", "marketTime": "2021-07-31T05:02:00.000Z", "suspendTime": "2021-07-31T05:02:00.000Z", "bspReconciled": false, "complete": true, "inPlay": false, "crossMatching": false, "runnersVoidable": false, "numberOfActiveRunners": 10, "betDelay": 0, "status": "OPEN", "runners": [{"adjustmentFactor": 15.898, "status": "ACTIVE", "sortPriority": 1, "id": 40363974}, {"adjustmentFactor": 5.261, "status": "ACTIVE", "sortPriority": 2, "id": 13258585}, {"adjustmentFactor": 5.263, "status": "ACTIVE", "sortPriority": 3, "id": 1426204}, {"adjustmentFactor": 3.448, "status": "ACTIVE", "sortPriority": 4, "id": 40363975}, {"adjustmentFactor": 7.143, "status": "ACTIVE", "sortPriority": 5, "id": 27464631}, {"adjustmentFactor": 3.03, "status": "ACTIVE", "sortPriority": 6, "id": 40363976}, {"adjustmentFactor": 34.602, "status": "ACTIVE", "sortPriority": 7, "id": 36409487}, {"adjustmentFactor": 10.593, "status": "ACTIVE", "sortPriority": 8, "id": 28413834}, {"adjustmentFactor": 4.762, "status": "ACTIVE", "sortPriority": 9, "id": 4678128}, {"adjustmentFactor": 10, "status": "ACTIVE", "sortPriority": 10, "id": 28486260}, {"adjustmentFactor": 16.604, "status": "REMOVED", "sortPriority": 11, "removalDate": "2021-07-28T10:29:42.000Z", "id": 19431888}], "regulators": ["MR_INT"], "venue": "Eagle Farm", "countryCode": "AU", "discountAllowed": true, "timezone": "Australia/Queensland", "openDate": "2021-07-31T01:28:00.000Z", "version": 3937416664, "raceType": "Flat", "priceLadderDefinition": {"type": "CLASSIC"}}, "rc": [{"atb": [[2.08, 105.95], [2.16, 183.5], [1.98, 325.81], [2.06, 301.22], [2.3, 15.41], [1.01, 166.31], [2.24, 13.39], [2.22, 21.19], [1.02, 2]], "atl": [[3.5, 2.65], [3.75, 31.79], [6.8, 35.28], [5.4, 46.5], [8.8, 26.23], [12, 18.6], [690, 0.03]], "trd": [[2.34, 180.12], [2.46, 52.98], [2.3, 296.67]], "batb": [[8, 1.01, 166.31], [6, 1.98, 325.81], [5, 2.06, 301.22], [4, 2.08, 105.95], [3, 2.16, 183.5], [0, 2.3, 15.41], [7, 1.02, 2], [2, 2.22, 21.19], [1, 2.24, 13.39]], "batl": [[6, 690, 0.03], [5, 12, 18.6], [4, 8.8, 26.23], [3, 6.8, 35.28], [2, 5.4, 46.5], [1, 3.75, 31.79], [0, 3.5, 2.65]], "tv": 529.77, "id": 36409487}, {"atb": [[7.4, 49.89], [1.01, 166.31], [12.5, 2.4], [9.4, 25.34], [8.4, 43.15], [12, 19.35], [8.2, 6.36], [10, 6.36], [1.02, 2]], "atl": [[110, 1.88], [55, 3.79], [210, 0.98], [310, 0.66], [690, 0.03]], "batb": [[8, 1.01, 166.31], [6, 7.4, 49.89], [7, 1.02, 2], [5, 8.2, 6.36], [4, 8.4, 43.15], [3, 9.4, 25.34], [2, 10, 6.36], [1, 12, 19.35], [0, 12.5, 2.4]], "batl": [[1, 110, 1.88], [0, 55, 3.79], [3, 690, 0.03], [2, 310, 1.64]], "id": 27464631}, {"atb": [[13, 26.61], [1.01, 166.31], [19.5, 1.54], [15.5, 14.68], [15, 6.36], [10.5, 33.61], [19, 11.82], [1.02, 2]], "atl": [[230, 0.9], [430, 0.48], [330, 0.62], [130, 1.58], [690, 0.03]], "batb": [[7, 1.01, 166.31], [4, 13, 26.61], [6, 1.02, 2], [5, 10.5, 33.61], [3, 15, 6.36], [2, 15.5, 14.68], [1, 19, 11.82], [0, 19.5, 1.54]], "batl": [[1, 330, 1.52], [2, 690, 0.51], [0, 130, 1.58]], "id": 4678128}, {"atb": [[6.6, 57.02], [7.4, 10.6], [5.8, 66.52], [1.01, 166.31], [8.4, 3.57], [7.6, 32.25], [8.2, 6.36], [9, 0.12], [1.02, 2]], "atl": [[230, 0.9], [36, 5.85], [65, 3.2], [130, 1.58], [690, 0.03]], "trd": [[9, 52.98]], "batb": [[7, 1.01, 166.31], [5, 5.8, 66.52], [4, 6.6, 57.02], [3, 7.4, 10.6], [6, 1.02, 2], [2, 7.6, 32.25], [1, 8.2, 6.36], [0, 8.4, 3.69]], "batl": [[3, 690, 0.93], [1, 65, 3.2], [0, 36, 5.85], [2, 130, 1.58]], "tv": 52.98, "id": 28413834}, {"atb": [[1.01, 166.31], [16.5, 1.82], [14, 6.36], [12.5, 18.42], [10, 35.3], [9, 39.71], [16, 14.12], [1.02, 2]], "atl": [[400, 0.51], [200, 1.03], [100, 2.08], [300, 0.69], [18, 1.59], [690, 0.03]], "trd": [[15.01, 12.71]], "batb": [[7, 1.01, 166.31], [6, 1.02, 2], [5, 9, 39.71], [4, 10, 35.3], [3, 12.5, 18.42], [2, 14, 6.36], [1, 16, 14.12], [0, 16.5, 1.82]], "batl": [[4, 690, 0.03], [3, 400, 1.2], [2, 200, 1.03], [1, 100, 2.08], [0, 18, 1.59]], "tv": 12.71, "id": 1426204}, {"atb": [[12.5, 24.78], [1.01, 166.31], [16.5, 1.82], [10, 35.3], [9, 39.71], [16, 11.47], [1.02, 2]], "atl": [[400, 0.51], [200, 1.03], [100, 2.08], [300, 0.69], [690, 0.03]], "trd": [[16, 5.3]], "batb": [[6, 1.01, 166.31], [2, 12.5, 24.78], [5, 1.02, 2], [4, 9, 39.71], [3, 10, 35.3], [1, 16, 11.47], [0, 16.5, 1.82]], "batl": [[3, 690, 0.03], [2, 400, 1.2], [1, 200, 1.03], [0, 100, 2.08]], "tv": 5.3, "id": 13258585}, {"atb": [[1.01, 166.31], [29, 1.03], [15.5, 21.91], [28, 7.85], [18, 25.05], [21, 10.59], [1.02, 2]], "atl": [[500, 0.41], [400, 0.51], [200, 1.03], [300, 0.69], [690, 0.03]], "batb": [[6, 1.01, 166.31], [5, 1.02, 2], [4, 15.5, 21.91], [3, 18, 25.05], [2, 21, 10.59], [1, 28, 7.85], [0, 29, 1.03]], "batl": [[2, 690, 0.44], [1, 400, 1.2], [0, 200, 1.03]], "id": 40363976}, {"atb": [[4.1, 31.79], [5, 53.22], [1.01, 166.31], [4.5, 91.23], [4, 106.43], [5.8, 5.17], [5.7, 45.29], [4.6, 21.19], [1.02, 2]], "atl": [[17, 12.79], [24, 8.89], [38, 5.53], [70, 2.97], [690, 0.03]], "batb": [[8, 1.01, 166.31], [6, 4, 106.43], [5, 4.1, 31.79], [4, 4.5, 91.23], [2, 5, 53.22], [7, 1.02, 2], [3, 4.6, 21.19], [1, 5.7, 45.29], [0, 5.8, 5.17]], "batl": [[0, 17, 12.79], [1, 24, 8.89], [3, 70, 2.97], [2, 38, 5.53], [4, 690, 0.03]], "id": 40363974}, {"atb": [[6.2, 10.6], [5.8, 65.54], [1.01, 166.31], [4.8, 84.03], [7.2, 4.17], [7, 35.48], [5.3, 74.25], [1.02, 2]], "atl": [[46, 4.55], [19, 11.37], [28, 7.58], [90, 2.3], [690, 0.03]], "batb": [[7, 1.01, 166.31], [5, 4.8, 84.03], [3, 5.8, 65.54], [2, 6.2, 10.6], [6, 1.02, 2], [4, 5.3, 74.25], [1, 7, 35.48], [0, 7.2, 4.17]], "batl": [[2, 46, 4.55], [0, 19, 11.37], [3, 90, 2.3], [1, 28, 7.58], [4, 690, 0.03]], "id": 28486260}, {"atb": [[1.01, 166.31], [29, 1.03], [15.5, 19.28], [21, 9.32], [20, 6.36], [18, 16.44], [28, 6.9], [1.02, 2]], "atl": [[200, 1.2], [500, 0.48], [400, 0.59], [300, 0.79], [690, 0.03]], "trd": [[25, 10.6]], "batb": [[7, 1.01, 166.31], [6, 1.02, 2], [5, 15.5, 19.28], [4, 18, 16.44], [3, 20, 6.36], [2, 21, 9.32], [1, 28, 6.9], [0, 29, 1.03]], "batl": [[0, 200, 1.2], [2, 690, 0.51], [1, 400, 1.38]], "tv": 10.6, "id": 40363975}], "img": true, "tv": 611.36}, {"id": "1.185781635", "marketDefinition": {"bspMarket": true, "turnInPlayEnabled": true, "persistenceEnabled": true, "marketBaseRate": 8, "eventId": "30738618", "eventTypeId": "7", "numberOfWinners": 1, "bettingType": "ODDS", "marketType": "WIN", "marketTime": "2021-07-30T08:13:00.000Z", "suspendTime": "2021-07-30T08:13:00.000Z", "bspReconciled": false, "complete": true, "inPlay": false, "crossMatching": true, "runnersVoidable": false, "numberOfActiveRunners": 9, "betDelay": 0, "status": "OPEN", "runners": [{"adjustmentFactor": 1.19, "status": "ACTIVE", "sortPriority": 1, "id": 39519134}, {"adjustmentFactor": 38.555, "status": "ACTIVE", "sortPriority": 2, "id": 38553647}, {"adjustmentFactor": 7.223, "status": "ACTIVE", "sortPriority": 3, "id": 38686828}, {"adjustmentFactor": 35.203, "status": "ACTIVE", "sortPriority": 4, "id": 38848075}, {"adjustmentFactor": 1.19, "status": "ACTIVE", "sortPriority": 5, "id": 19506029}, {"adjustmentFactor": 1.19, "status": "ACTIVE", "sortPriority": 6, "id": 25864991}, {"adjustmentFactor": 1.19, "status": "ACTIVE", "sortPriority": 7, "id": 16385188}, {"adjustmentFactor": 1.609, "status": "ACTIVE", "sortPriority": 8, "id": 26813941}, {"adjustmentFactor": 12.652, "status": "ACTIVE", "sortPriority": 9, "id": 19283335}, {"adjustmentFactor": 1.176, "status": "REMOVED", "sortPriority": 10, "removalDate": "2021-07-29T09:44:32.000Z", "id": 8483357}], "regulators": ["MR_INT"], "venue": "Newcastle", "countryCode": "AU", "discountAllowed": true, "timezone": "Australia/Sydney", "openDate": "2021-07-30T07:10:00.000Z", "version": 3938308182, "raceType": "Flat", "priceLadderDefinition": {"type": "CLASSIC"}}, "rc": [{"atb": [[1.01, 248.54], [8.4, 7.95], [6.4, 21.78], [6.6, 1.28], [11, 5.88], [22, 1.4], [16, 1.96], [1.14, 2], [1.02, 2]], "atl": [[500, 0.39], [400, 0.49], [200, 0.65], [300, 0.43], [290, 0.01], [900, 1.3], [690, 0.03]], "batb": [[8, 1.01, 248.54], [5, 6.4, 21.78], [3, 8.4, 7.95], [7, 1.02, 2], [6, 1.14, 2], [4, 6.6, 1.28], [2, 11, 5.88], [1, 16, 1.96], [0, 22, 1.4]], "batl": [[1, 900, 2.21], [0, 300, 1.09]], "id": 39519134}, {"atb": [[6.2, 22.62], [1.01, 248.54], [10.5, 6.19], [6.4, 1.33], [15.5, 2.03], [8.2, 8.17], [21, 1.47], [1.14, 2]], "atl": [[940, 0.07], [490, 0.4], [390, 0.5], [190, 0.68], [290, 0.45], [110, 0.03], [900, 1.3], [690, 0.03]], "batb": [[7, 1.01, 248.54], [5, 6.2, 22.62], [4, 6.4, 1.33], [2, 10.5, 6.19], [6, 1.14, 2], [3, 8.2, 8.17], [1, 15.5, 2.03], [0, 21, 1.47]], "batl": [[2, 940, 0.07], [1, 900, 2.23], [0, 290, 1.16]], "id": 26813941}, {"atb": [[1.01, 248.54], [10.5, 6.19], [15.5, 4.06], [8.2, 16.33], [21, 1.47], [32, 0.95], [1.14, 2]], "atl": [[940, 0.07], [500, 0.39], [400, 0.32], [600, 0.32], [300, 0.43], [290, 0.01], [900, 1.3], [690, 0.03]], "spl": [[1.01, 7.95]], "batb": [[5, 1.01, 248.54], [2, 10.5, 6.19], [4, 1.14, 2], [3, 8.2, 16.33], [1, 15.5, 4.06], [0, 21, 2.42]], "batl": [[2, 940, 0.07], [1, 900, 1.65], [0, 500, 1.15]], "id": 25864991}, {"atb": [[5.1, 0.85], [1.01, 248.54], [3.5, 23.52], [3, 58.8], [4, 19.6], [3.1, 3.41], [6, 5.88], [5, 7.35], [1.14, 2]], "atl": [[28, 0.07], [24, 5.77], [38, 3.5], [140, 1.4], [70, 2.81], [900, 1.3], [690, 0.03]], "spl": [[16, 3.18]], "batb": [[1, 5, 8.2], [7, 1.01, 248.54], [5, 3, 58.8], [3, 3.5, 23.52], [2, 4, 19.6], [6, 1.14, 2], [4, 3.1, 3.41], [0, 6, 5.88]], "batl": [[1, 38, 3.57], [4, 900, 1.33], [3, 140, 1.4], [2, 70, 2.81], [0, 24, 5.77]], "id": 19283335}, {"atb": [[1.01, 248.54], [9.4, 14], [13.5, 4.7], [27, 1.13], [44, 0.68], [18.5, 3.36], [1.14, 2]], "atl": [[560, 0.42], [460, 0.28], [360, 0.36], [660, 0.3], [540, 0.01], [900, 1.3], [690, 0.03]], "batb": [[5, 1.01, 248.54], [4, 1.14, 2], [3, 9.4, 14], [2, 13.5, 4.7], [1, 18.5, 3.36], [0, 27, 1.81]], "batl": [[0, 560, 1.07], [1, 900, 1.63]], "id": 16385188}, {"atb": [[7.8, 0.55], [1.01, 248.54], [4.8, 30.95], [5, 1.79], [14, 2.26], [7.6, 8.91], [5.8, 12.25], [9.6, 3.42], [1.14, 2]], "atl": [[330, 0.07], [390, 0.5], [190, 0.68], [95, 1.38], [290, 0.67], [85, 0.04], [900, 1.3], [690, 0.03]], "batb": [[2, 7.6, 9.46], [7, 1.01, 248.54], [5, 4.8, 30.95], [6, 1.14, 2], [4, 5, 1.79], [3, 5.8, 12.25], [1, 9.6, 3.42], [0, 14, 2.26]], "batl": [[2, 900, 1.9], [1, 290, 1.35], [0, 95, 1.42]], "id": 19506029}, {"atb": [[1.61, 2.68], [1.42, 17.08], [1.3, 196.02], [1.01, 248.54], [1.2, 588.05], [1.4, 147.01], [1.5, 58.8], [1.6, 49], [1.14, 2]], "atl": [[4.4, 57.12], [3.7, 71.93], [2.88, 68.87], [85, 5], [2, 4.19], [3.2, 58.85], [2.82, 2.65], [2.96, 1.12], [900, 1.3], [690, 0.03]], "spl": [[3.4, 8.48]], "batb": [[8, 1.01, 248.54], [7, 1.14, 2], [6, 1.2, 588.05], [5, 1.3, 196.02], [4, 1.4, 147.01], [3, 1.42, 17.08], [2, 1.5, 58.8], [1, 1.6, 49], [0, 1.61, 2.68]], "batl": [[6, 4.4, 57.12], [5, 3.7, 71.93], [2, 2.88, 68.87], [8, 900, 1.33], [7, 85, 5], [4, 3.2, 58.85], [3, 2.96, 1.12], [1, 2.82, 2.65], [0, 2, 4.19]], "id": 38553647}, {"atb": [[4.1, 1.05], [2.6, 73.51], [1.01, 248.54], [2.66, 4.32], [3, 29.4], [2.8, 32.67], [3.5, 11.76], [4, 9.8], [1.14, 2]], "atl": [[13.5, 10.61], [27, 7.47], [44, 4.52], [18.5, 7.4], [900, 1.3], [690, 0.03]], "batb": [[8, 1.01, 248.54], [7, 1.14, 2], [6, 2.6, 73.51], [5, 2.66, 4.32], [4, 2.8, 32.67], [3, 3, 29.4], [2, 3.5, 11.76], [1, 4, 9.8], [0, 4.1, 1.05]], "batl": [[0, 13.5, 10.61], [4, 900, 1.33], [3, 44, 4.52], [2, 27, 7.47], [1, 18.5, 7.4]], "id": 38686828}, {"atb": [[3.35, 1.28], [1.01, 248.54], [2.32, 89.1], [2.72, 34.19], [2.92, 15.32], [2.38, 5.2], [2.52, 38.69], [3.3, 12.78], [1.14, 2]], "atl": [[9.6, 0.07], [8.8, 16.6], [17, 12.14], [24, 8.44], [12, 11.77], [8.4, 0.4], [900, 1.3], [690, 0.03]], "spl": [[3.9, 7.42]], "batb": [[8, 1.01, 248.54], [7, 1.14, 2], [6, 2.32, 89.1], [5, 2.38, 5.2], [4, 2.52, 38.69], [3, 2.72, 34.19], [2, 2.92, 15.32], [1, 3.3, 12.78], [0, 3.35, 1.28]], "batl": [[1, 12, 11.84], [2, 17, 12.14], [0, 8.8, 17], [4, 900, 1.33], [3, 24, 8.44]], "id": 38848075}], "img": true, "tv": 0}, {"id": "1.185781633", "marketDefinition": {"bspMarket": true, "turnInPlayEnabled": true, "persistenceEnabled": true, "marketBaseRate": 8, "eventId": "30738618", "eventTypeId": "7", "numberOfWinners": 1, "bettingType": "ODDS", "marketType": "WIN", "marketTime": "2021-07-30T07:40:00.000Z", "suspendTime": "2021-07-30T07:40:00.000Z", "bspReconciled": false, "complete": true, "inPlay": false, "crossMatching": true, "runnersVoidable": false, "numberOfActiveRunners": 9, "betDelay": 0, "status": "OPEN", "runners": [{"adjustmentFactor": 24.993, "status": "ACTIVE", "sortPriority": 1, "id": 27592402}, {"adjustmentFactor": 6.608, "status": "ACTIVE", "sortPriority": 2, "id": 14120186}, {"adjustmentFactor": 7.089, "status": "ACTIVE", "sortPriority": 3, "id": 13220616}, {"adjustmentFactor": 6.188, "status": "ACTIVE", "sortPriority": 4, "id": 37228342}, {"adjustmentFactor": 23.521, "status": "ACTIVE", "sortPriority": 5, "id": 27973245}, {"adjustmentFactor": 8.288, "status": "ACTIVE", "sortPriority": 6, "id": 20414156}, {"adjustmentFactor": 3.75, "status": "ACTIVE", "sortPriority": 7, "id": 21530600}, {"adjustmentFactor": 12.474, "status": "ACTIVE", "sortPriority": 8, "id": 31196804}, {"adjustmentFactor": 7.089, "status": "ACTIVE", "sortPriority": 9, "id": 13388425}], "regulators": ["MR_INT"], "venue": "Newcastle", "countryCode": "AU", "discountAllowed": true, "timezone": "Australia/Sydney", "openDate": "2021-07-30T07:10:00.000Z", "version": 3938308186, "raceType": "Flat", "priceLadderDefinition": {"type": "CLASSIC"}}, "rc": [{"atb": [[1.01, 146.31], [3.5, 47.04], [5, 14.7], [4, 19.6], [3.6, 2.76], [8.2, 3.72], [6, 5.88], [8, 4.2], [1.14, 2]], "atl": [[900, 1.32], [40, 3.41], [250, 0.78], [150, 1.3], [75, 1.75], [690, 0.03]], "batb": [[8, 1.01, 146.31], [6, 3.5, 47.04], [4, 4, 19.6], [3, 5, 14.7], [7, 1.14, 2], [5, 3.6, 2.76], [2, 6, 5.88], [1, 8, 4.2], [0, 8.2, 3.72]], "batl": [[3, 900, 2.13], [0, 40, 3.41], [2, 150, 1.3], [1, 75, 1.75]], "id": 14120186}, {"atb": [[1.01, 146.31], [4.7, 1.94], [4.6, 32.67], [9.2, 3.59], [13, 2.45], [7.2, 9.48], [5.6, 12.78], [1.14, 2]], "atl": [[900, 0.79], [320, 0.07], [90, 1.5], [380, 0.51], [180, 0.73], [280, 0.69], [690, 0.03]], "batb": [[7, 1.01, 146.31], [5, 4.6, 32.67], [4, 4.7, 1.94], [1, 9.2, 3.59], [6, 1.14, 2], [3, 5.6, 12.78], [2, 7.2, 9.48], [0, 13, 2.45]], "batl": [[2, 900, 1.4], [0, 90, 1.5], [1, 280, 1.42]], "id": 21530600}, {"atb": [[2.86, 63.23], [1.01, 146.31], [3.65, 22.19], [3.15, 27.35], [2.94, 3.69], [5.3, 6.84], [4.3, 8.91], [5.7, 3.72], [1.14, 2]], "atl": [[18.5, 0.07], [23, 5.89], [36, 5.55], [65, 3.04], [16.5, 8.56], [690, 0.03]], "batb": [[8, 1.01, 146.31], [6, 2.86, 63.23], [4, 3.15, 27.35], [3, 3.65, 22.19], [7, 1.14, 2], [5, 2.94, 3.69], [2, 4.3, 8.91], [1, 5.3, 6.84], [0, 5.7, 3.72]], "batl": [[1, 23, 5.96], [4, 690, 0.03], [3, 65, 3.04], [2, 36, 5.55], [0, 16.5, 8.56]], "id": 37228342}, {"atb": [[1.01, 146.31], [2, 117.61], [2.4, 42.01], [2.2, 49], [2.6, 18.38], [2.04, 6.9], [2.8, 16.33], [1.14, 2]], "atl": [[900, 1.06], [8.8, 16.6], [12, 17.66], [6.8, 22.32], [17, 12.14], [4.7, 3.38], [690, 0.03]], "spl": [[8.4, 4.77]], "batb": [[7, 1.01, 146.31], [5, 2, 117.61], [2, 2.4, 42.01], [4, 2.04, 6.9], [3, 2.2, 49], [1, 2.6, 18.38], [6, 1.14, 2], [0, 2.8, 16.33]], "batl": [[5, 900, 1.09], [4, 17, 12.14], [3, 12, 17.66], [2, 8.8, 16.6], [1, 6.8, 22.32], [0, 4.7, 3.38]], "id": 27592402}, {"atb": [[1.01, 146.31], [5.3, 27.35], [5.5, 1.59], [6.6, 10.5], [11.5, 2.8], [8.6, 7.74], [16.5, 1.9], [1.14, 2]], "atl": [[900, 0.53], [110, 1.22], [210, 0.62], [410, 0.48], [310, 0.63], [690, 0.03]], "batb": [[7, 1.01, 146.31], [5, 5.3, 27.35], [6, 1.14, 2], [4, 5.5, 1.59], [3, 6.6, 10.5], [2, 8.6, 7.74], [1, 11.5, 2.8], [0, 16.5, 1.9]], "batl": [[2, 900, 1.04], [0, 110, 1.22], [1, 310, 1.25]], "id": 13220616}, {"atb": [[1.01, 146.31], [3.5, 23.52], [3, 58.8], [4, 19.6], [3.1, 3.41], [6, 5.88], [5, 7.35], [7, 3.72], [1.14, 2]], "atl": [[900, 1.59], [28, 0.07], [24, 5.77], [38, 3.5], [140, 1.4], [70, 2.81], [690, 0.03]], "batb": [[8, 1.01, 146.31], [6, 3, 58.8], [4, 3.5, 23.52], [3, 4, 19.6], [7, 1.14, 2], [5, 3.1, 3.41], [2, 5, 7.35], [1, 6, 5.88], [0, 7, 3.72]], "batl": [[4, 900, 1.62], [1, 38, 3.57], [0, 24, 5.77], [3, 140, 1.4], [2, 70, 2.81]], "id": 13388425}, {"atb": [[1.01, 146.31], [2.7, 69.18], [3.25, 26.13], [2.9, 30.95], [2.76, 4.07], [3.75, 10.69], [4.5, 8.4], [1.14, 2]], "atl": [[900, 1.06], [16.5, 0.07], [14.5, 9.83], [19.5, 7], [29, 6.93], [48, 4.13], [690, 0.03]], "spl": [[12, 3.71]], "batb": [[7, 1.01, 146.31], [5, 2.7, 69.18], [3, 2.9, 30.95], [2, 3.25, 26.13], [6, 1.14, 2], [4, 2.76, 4.07], [1, 3.75, 10.69], [0, 4.5, 8.4]], "batl": [[4, 900, 1.09], [1, 19.5, 7.07], [0, 14.5, 9.83], [3, 48, 4.13], [2, 29, 6.93]], "id": 31196804}, {"atb": [[2.2, 98.01], [2.6, 36.76], [1.01, 146.31], [2.4, 42.01], [3, 14.7], [2.24, 5.78], [2.8, 16.33], [1.14, 2]], "atl": [[9.4, 15.42], [900, 1.32], [8.2, 0.07], [13.5, 15.54], [7.4, 20.7], [18.5, 11.1], [690, 0.03]], "spl": [[10, 4.24], [1.01, 7.95]], "batb": [[7, 1.01, 146.31], [5, 2.2, 98.01], [3, 2.4, 42.01], [2, 2.6, 36.76], [4, 2.24, 5.78], [0, 3, 14.7], [6, 1.14, 2], [1, 2.8, 16.33]], "batl": [[1, 9.4, 15.49], [4, 900, 1.35], [3, 18.5, 11.1], [2, 13.5, 15.54], [0, 7.4, 20.7]], "id": 27973245}, {"atb": [[7.6, 4.46], [1.01, 146.31], [3.9, 40.55], [4, 2.39], [5.8, 12.25], [4.8, 15.47], [9.6, 3.42], [1.14, 2]], "atl": [[170, 0.07], [65, 2.07], [230, 0.85], [330, 0.59], [130, 1], [690, 0.03]], "batb": [[7, 1.01, 146.31], [1, 7.6, 4.46], [5, 3.9, 40.55], [4, 4, 2.39], [6, 1.14, 2], [3, 4.8, 15.47], [2, 5.8, 12.25], [0, 9.6, 3.42]], "batl": [[2, 330, 1.51], [3, 690, 0.03], [0, 65, 2.07], [1, 130, 1]], "id": 20414156}], "img": true, "tv": 0}, {"id": "1.185793022", "marketDefinition": {"bspMarket": true, "turnInPlayEnabled": true, "persistenceEnabled": true, "marketBaseRate": 6, "eventId": "30739215", "eventTypeId": "7", "numberOfWinners": 1, "bettingType": "ODDS", "marketType": "WIN", "marketTime": "2021-07-30T10:35:00.000Z", "suspendTime": "2021-07-30T10:35:00.000Z", "bspReconciled": false, "complete": true, "inPlay": false, "crossMatching": true, "runnersVoidable": false, "numberOfActiveRunners": 9, "betDelay": 0, "status": "OPEN", "runners": [{"adjustmentFactor": 3.113, "status": "ACTIVE", "sortPriority": 1, "id": 36341786}, {"adjustmentFactor": 7.638, "status": "ACTIVE", "sortPriority": 2, "id": 10862099}, {"adjustmentFactor": 3.746, "status": "ACTIVE", "sortPriority": 3, "id": 31197731}, {"adjustmentFactor": 24.988, "status": "ACTIVE", "sortPriority": 4, "id": 25964773}, {"adjustmentFactor": 7.084, "status": "ACTIVE", "sortPriority": 5, "id": 34975733}, {"adjustmentFactor": 6.183, "status": "ACTIVE", "sortPriority": 6, "id": 28440198}, {"adjustmentFactor": 3.746, "status": "ACTIVE", "sortPriority": 7, "id": 40363510}, {"adjustmentFactor": 19.984, "status": "ACTIVE", "sortPriority": 8, "id": 19769491}, {"adjustmentFactor": 23.517, "status": "ACTIVE", "sortPriority": 9, "id": 26585912}], "regulators": ["MR_INT"], "venue": "Ballarat", "countryCode": "AU", "discountAllowed": true, "timezone": "Australia/Sydney", "openDate": "2021-07-30T08:30:00.000Z", "version": 3938290774, "raceType": "Flat", "priceLadderDefinition": {"type": "CLASSIC"}}, "rc": [{"atb": [[1.01, 156.31], [26, 9.9], [21, 16.5], [34, 0.21], [42, 2.01], [32, 5.32], [1.14, 2]], "atl": [[600, 0.39], [500, 0.39], [400, 0.32], [300, 0.43], [690, 0.03]], "batb": [[5, 1.01, 156.31], [3, 21, 16.5], [2, 26, 9.9], [1, 32, 5.53], [4, 1.14, 2], [0, 42, 2.01]], "batl": [[1, 690, 0.42], [0, 500, 1.14]], "id": 36341786}, {"atb": [[1.01, 156.31], [6.4, 61.1], [8.6, 0.95], [8.4, 22.29], [7.4, 38.66], [9.4, 9.82], [15, 0.48], [1.14, 2]], "atl": [[50, 0.07], [42, 3.16], [160, 1.22], [80, 1.64], [260, 0.75], [690, 0.03]], "spl": [[4.9, 6.36]], "batb": [[5, 1.01, 156.31], [3, 6.4, 61.1], [1, 8.4, 23.24], [2, 7.4, 38.66], [4, 1.14, 2], [0, 9.4, 10.3]], "batl": [[1, 80, 1.71], [3, 690, 0.78], [2, 160, 1.22], [0, 42, 3.16]], "id": 25964773}, {"atb": [[3.05, 40.24], [3, 3.59], [1.01, 156.31], [2.72, 191.83], [2.92, 85.92], [2.82, 135.97], [4, 1.79], [1.14, 2]], "atl": [[7, 2], [9.2, 15.79], [70, 42.38], [7.2, 20.88], [13, 16.18], [18, 11.42], [690, 0.03]], "spl": [[6.4, 5.3], [2.7, 92.71], [1.01, 105.95]], "batb": [[7, 1.01, 156.31], [5, 2.72, 191.83], [4, 2.82, 135.97], [3, 2.92, 85.92], [2, 3, 3.59], [1, 3.05, 40.24], [6, 1.14, 2], [0, 4, 1.79]], "batl": [[6, 690, 0.03], [5, 70, 42.38], [4, 18, 11.42], [3, 13, 16.18], [2, 9.2, 15.79], [1, 7.2, 20.88], [0, 7, 2]], "id": 26585912}, {"atb": [[1.01, 156.31], [7.2, 53.22], [9.6, 0.83], [8.2, 34.37], [9.2, 20.12], [11, 0.65], [10.5, 8.68], [1.14, 2]], "atl": [[110, 1.19], [55, 2.4], [210, 0.93], [310, 0.63], [690, 0.03]], "batb": [[5, 1.01, 156.31], [3, 7.2, 53.22], [1, 9.2, 20.95], [2, 8.2, 34.37], [0, 10.5, 9.33], [4, 1.14, 2]], "batl": [[3, 690, 0.03], [2, 310, 1.56], [1, 110, 1.19], [0, 55, 2.4]], "id": 28440198}, {"atb": [[1.01, 156.31], [4, 109.98], [5.2, 1.71], [5.5, 18.33], [5, 41.24], [4.5, 70.7], [5.6, 1.28], [1.14, 2]], "atl": [[22, 6.17], [34, 5.89], [60, 3.29], [16, 8.63], [690, 0.03]], "spl": [[10, 4.24]], "batb": [[7, 1.01, 156.31], [5, 4, 109.98], [6, 1.14, 2], [4, 4.5, 70.7], [3, 5, 41.24], [2, 5.2, 1.71], [1, 5.5, 18.33], [0, 5.6, 1.28]], "batl": [[2, 34, 5.89], [1, 22, 6.17], [4, 690, 0.03], [3, 60, 3.29], [0, 16, 8.63]], "id": 19769491}, {"atb": [[1.01, 156.31], [25, 13.75], [42, 0.17], [30, 8.53], [50, 1.68], [40, 4.23], [1.14, 2]], "atl": [[500, 0.07], [440, 0.3], [340, 0.38], [640, 0.3], [540, 0.36], [690, 0.03]], "batb": [[5, 1.01, 156.31], [3, 25, 13.75], [1, 40, 4.4], [2, 30, 8.53], [4, 1.14, 2], [0, 50, 1.68]], "batl": [[0, 540, 1.11], [1, 690, 0.33]], "id": 31197731}, {"atb": [[1.01, 156.31], [6.4, 61.1], [8.6, 0.95], [8.4, 22.29], [7.4, 38.66], [9.4, 9.82], [16, 0.44], [1.14, 2]], "atl": [[50, 0.07], [42, 3.16], [160, 1.22], [80, 1.64], [260, 0.75], [690, 0.03]], "spl": [[16, 3.18]], "batb": [[5, 1.01, 156.31], [3, 6.4, 61.1], [1, 8.4, 23.24], [2, 7.4, 38.66], [4, 1.14, 2], [0, 9.4, 10.26]], "batl": [[1, 80, 1.71], [3, 690, 0.78], [2, 160, 1.22], [0, 42, 3.16]], "id": 10862099}, {"atb": [[1.01, 156.31], [4, 109.98], [5.2, 1.71], [5.5, 18.33], [5, 41.24], [4.5, 70.7], [5.6, 1.28], [1.14, 2]], "atl": [[18, 0.07], [22, 6.17], [34, 5.89], [60, 3.29], [16, 8.63], [690, 0.03]], "batb": [[7, 1.01, 156.31], [5, 4, 109.98], [6, 1.14, 2], [4, 4.5, 70.7], [3, 5, 41.24], [2, 5.2, 1.71], [1, 5.5, 18.33], [0, 5.6, 1.28]], "batl": [[1, 22, 6.24], [4, 690, 0.03], [2, 34, 5.89], [3, 60, 3.29], [0, 16, 8.63]], "id": 34975733}, {"atb": [[2.2, 274.95], [2.3, 190.35], [2.5, 54.99], [1.01, 156.31], [2.4, 117.84], [2.56, 4.6], [2.58, 2.78], [1.14, 2]], "atl": [[7, 21.58], [12.5, 16.89], [5.5, 28.77], [9, 24.27], [690, 0.03]], "spl": [[1.01, 7.95]], "batb": [[7, 1.01, 156.31], [5, 2.2, 274.95], [4, 2.3, 190.35], [3, 2.4, 117.84], [2, 2.5, 54.99], [1, 2.56, 4.6], [6, 1.14, 2], [0, 2.58, 2.78]], "batl": [[3, 12.5, 16.89], [2, 9, 24.27], [1, 7, 21.58], [0, 5.5, 28.77], [4, 690, 0.03]], "id": 40363510}], "img": true, "tv": 0}, {"id": "1.185798777", "marketDefinition": {"bspMarket": true, "turnInPlayEnabled": true, "persistenceEnabled": true, "marketBaseRate": 8, "eventId": "30739923", "eventTypeId": "7", "numberOfWinners": 1, "bettingType": "ODDS", "marketType": "WIN", "marketTime": "2021-07-30T09:30:00.000Z", "suspendTime": "2021-07-30T09:30:00.000Z", "bspReconciled": false, "complete": true, "inPlay": false, "crossMatching": true, "runnersVoidable": false, "numberOfActiveRunners": 10, "betDelay": 0, "status": "OPEN", "runners": [{"adjustmentFactor": 3.091, "status": "ACTIVE", "sortPriority": 1, "id": 7948433}, {"adjustmentFactor": 2.799, "status": "ACTIVE", "sortPriority": 2, "id": 27259388}, {"adjustmentFactor": 6.591, "status": "ACTIVE", "sortPriority": 3, "id": 8563571}, {"adjustmentFactor": 23.52, "status": "ACTIVE", "sortPriority": 4, "id": 24527157}, {"adjustmentFactor": 9.953, "status": "ACTIVE", "sortPriority": 5, "id": 25522415}, {"adjustmentFactor": 3.725, "status": "ACTIVE", "sortPriority": 6, "id": 13275893}, {"adjustmentFactor": 3.725, "status": "ACTIVE", "sortPriority": 7, "id": 6920088}, {"adjustmentFactor": 3.091, "status": "ACTIVE", "sortPriority": 8, "id": 13738524}, {"adjustmentFactor": 19.986, "status": "ACTIVE", "sortPriority": 9, "id": 28546212}, {"adjustmentFactor": 23.52, "status": "ACTIVE", "sortPriority": 10, "id": 28350675}], "regulators": ["MR_INT"], "venue": "Parkes", "countryCode": "AU", "discountAllowed": true, "timezone": "Australia/Sydney", "openDate": "2021-07-30T08:55:00.000Z", "version": 3938311456, "raceType": "Flat", "priceLadderDefinition": {"type": "CLASSIC"}}, "rc": [{"atb": [[1.01, 248.54], [5.1, 28.69], [5.3, 1.67], [17, 3.72], [15.5, 2.03], [8.2, 8.17], [6.2, 11.31], [10.5, 3.09], [1.2, 122], [1.14, 2]], "atl": [[400, 0.49], [200, 0.65], [100, 1.31], [300, 0.65], [690, 0.03]], "batb": [[9, 1.01, 248.54], [6, 5.1, 28.69], [8, 1.14, 2], [7, 1.2, 122], [5, 5.3, 1.67], [4, 6.2, 11.31], [3, 8.2, 8.17], [2, 10.5, 3.09], [1, 15.5, 2.03], [0, 17, 3.72]], "batl": [[2, 690, 0.52], [1, 300, 1.3], [0, 100, 1.31]], "id": 6920088}, {"atb": [[2.62, 4.43], [1.01, 248.54], [2.56, 75.39], [2.76, 33.41], [2.96, 30], [3.9, 10.14], [3.4, 12.25], [1.2, 122], [1.14, 2]], "atl": [[26, 7.77], [42, 4.74], [18, 7.62], [13, 10.79], [690, 0.03]], "batb": [[8, 1.01, 248.54], [5, 2.56, 75.39], [4, 2.62, 4.43], [7, 1.14, 2], [6, 1.2, 122], [3, 2.76, 33.41], [2, 2.96, 30], [1, 3.4, 12.25], [0, 3.9, 10.14]], "batl": [[3, 42, 4.74], [2, 26, 7.77], [1, 18, 7.62], [4, 690, 0.03], [0, 13, 10.79]], "id": 28546212}, {"atb": [[3.8, 42.01], [1.01, 248.54], [3.9, 2.47], [9.2, 3.59], [4.6, 16.33], [7.2, 4.74], [5.6, 12.78], [1.2, 122], [1.14, 2]], "atl": [[110, 1.19], [55, 2.4], [210, 0.93], [310, 0.63], [690, 0.03]], "batb": [[8, 1.01, 248.54], [5, 3.8, 42.01], [7, 1.14, 2], [6, 1.2, 122], [4, 3.9, 2.47], [0, 9.2, 3.59], [3, 4.6, 16.33], [2, 5.6, 12.78], [1, 7.2, 4.74]], "batl": [[3, 690, 0.03], [2, 310, 1.56], [1, 110, 1.19], [0, 55, 2.4]], "id": 13738524}, {"atb": [[2.86, 63.23], [1.01, 248.54], [2.94, 3.69], [5.3, 10.56], [3.65, 22.19], [3.15, 27.35], [4.3, 8.91], [1.2, 122], [1.14, 2]], "atl": [[18.5, 0.07], [23, 5.89], [36, 5.55], [65, 3.04], [16.5, 8.35], [690, 0.03]], "spl": [[1.01, 5.3]], "batb": [[8, 1.01, 248.54], [5, 2.86, 63.23], [7, 1.14, 2], [6, 1.2, 122], [4, 2.94, 3.69], [0, 5.3, 10.56], [3, 3.15, 27.35], [2, 3.65, 22.19], [1, 4.3, 8.91]], "batl": [[1, 23, 5.96], [4, 690, 0.03], [3, 65, 3.04], [2, 36, 5.55], [0, 16.5, 8.35]], "id": 25522415}, {"atb": [[16, 3.72], [1.01, 248.54], [5.2, 1.71], [5, 29.4], [15, 2.1], [6, 11.76], [10, 3.27], [8, 8.4], [1.2, 122], [1.14, 2]], "atl": [[440, 0.07], [400, 0.49], [200, 0.65], [100, 1.31], [300, 0.65], [690, 0.03]], "batb": [[9, 1.01, 248.54], [8, 1.14, 2], [7, 1.2, 122], [6, 5, 29.4], [5, 5.2, 1.71], [4, 6, 11.76], [3, 8, 8.4], [2, 10, 3.27], [1, 15, 2.1], [0, 16, 3.72]], "batl": [[2, 690, 0.59], [1, 300, 1.3], [0, 100, 1.31]], "id": 27259388}, {"atb": [[2.44, 81.68], [2.64, 35.86], [1.01, 248.54], [4.6, 26.49], [2.84, 31.96], [3.1, 14], [3.6, 11.31], [1.2, 122], [1.14, 2]], "atl": [[7.6, 0.07], [30, 6.7], [20, 10.22], [10, 14.39], [6.8, 2.65], [15, 9.25], [690, 0.03]], "batb": [[8, 1.01, 248.54], [5, 2.44, 81.68], [4, 2.64, 35.86], [7, 1.14, 2], [6, 1.2, 122], [3, 2.84, 31.96], [2, 3.1, 14], [1, 3.6, 11.31], [0, 4.6, 26.49]], "batl": [[1, 10, 14.46], [5, 690, 0.03], [4, 30, 6.7], [3, 20, 10.22], [2, 15, 9.25], [0, 6.8, 2.65]], "id": 13275893}, {"atb": [[2.5, 78.41], [1.01, 248.54], [2.56, 4.6], [2.7, 34.59], [3.25, 13.07], [2.9, 30.95], [3.75, 10.69], [1.2, 122], [1.14, 2]], "atl": [[23, 8.83], [36, 5.55], [11.5, 12.33], [16.5, 8.35], [690, 0.03]], "spl": [[1.01, 7.95]], "batb": [[8, 1.01, 248.54], [5, 2.5, 78.41], [4, 2.56, 4.6], [7, 1.14, 2], [6, 1.2, 122], [3, 2.7, 34.59], [2, 2.9, 30.95], [1, 3.25, 13.07], [0, 3.75, 10.69]], "batl": [[3, 36, 5.55], [2, 23, 8.83], [4, 690, 0.03], [1, 16.5, 8.35], [0, 11.5, 12.33]], "id": 28350675}, {"atb": [[3.8, 42.01], [1.01, 248.54], [3.9, 2.47], [9.2, 3.59], [4.6, 16.33], [7.2, 4.74], [5.6, 12.78], [1.2, 122], [1.14, 2]], "atl": [[150, 0.07], [110, 1.19], [55, 2.4], [210, 0.93], [310, 0.63], [690, 0.03]], "batb": [[8, 1.01, 248.54], [5, 3.8, 42.01], [7, 1.14, 2], [6, 1.2, 122], [4, 3.9, 2.47], [0, 9.2, 3.59], [3, 4.6, 16.33], [2, 5.6, 12.78], [1, 7.2, 4.74]], "batl": [[3, 690, 0.66], [2, 210, 1], [1, 110, 1.19], [0, 55, 2.4]], "id": 8563571}, {"atb": [[1.01, 248.54], [2.76, 4.07], [2.7, 69.18], [3.25, 26.13], [2.9, 30.95], [3.75, 10.69], [4.5, 8.4], [1.2, 122], [1.14, 2]], "atl": [[9, 15.89], [16.5, 0.07], [14.5, 9.59], [19.5, 7], [29, 6.93], [48, 4.13], [690, 0.03]], "batb": [[8, 1.01, 248.54], [7, 1.14, 2], [6, 1.2, 122], [5, 2.7, 69.18], [4, 2.76, 4.07], [3, 2.9, 30.95], [2, 3.25, 26.13], [1, 3.75, 10.69], [0, 4.5, 8.4]], "batl": [[5, 690, 0.03], [4, 48, 4.13], [3, 29, 6.93], [2, 19.5, 7.07], [1, 14.5, 9.59], [0, 9, 15.89]], "id": 24527157}, {"atb": [[3.8, 42.01], [1.01, 248.54], [3.9, 2.47], [9.2, 3.59], [4.6, 16.33], [7.2, 4.74], [5.6, 12.78], [1.2, 122], [1.14, 2]], "atl": [[150, 0.07], [110, 1.19], [55, 2.4], [210, 0.93], [310, 0.63], [690, 0.03]], "batb": [[8, 1.01, 248.54], [5, 3.8, 42.01], [7, 1.14, 2], [6, 1.2, 122], [4, 3.9, 2.47], [0, 9.2, 3.59], [3, 4.6, 16.33], [2, 5.6, 12.78], [1, 7.2, 4.74]], "batl": [[3, 690, 0.66], [2, 210, 1], [1, 110, 1.19], [0, 55, 2.4]], "id": 7948433}], "img": true, "tv": 0}, {"id": "1.185793020", "marketDefinition": {"bspMarket": true, "turnInPlayEnabled": true, "persistenceEnabled": true, "marketBaseRate": 6, "eventId": "30739215", "eventTypeId": "7", "numberOfWinners": 1, "bettingType": "ODDS", "marketType": "WIN", "marketTime": "2021-07-30T10:05:00.000Z", "suspendTime": "2021-07-30T10:05:00.000Z", "bspReconciled": false, "complete": true, "inPlay": false, "crossMatching": true, "runnersVoidable": false, "numberOfActiveRunners": 9, "betDelay": 0, "status": "OPEN", "runners": [{"adjustmentFactor": 23.51, "status": "ACTIVE", "sortPriority": 1, "id": 25000686}, {"adjustmentFactor": 3.686, "status": "ACTIVE", "sortPriority": 2, "id": 28277002}, {"adjustmentFactor": 3.686, "status": "ACTIVE", "sortPriority": 3, "id": 34140525}, {"adjustmentFactor": 24.983, "status": "ACTIVE", "sortPriority": 4, "id": 28572209}, {"adjustmentFactor": 1.421, "status": "ACTIVE", "sortPriority": 5, "id": 13672313}, {"adjustmentFactor": 1.421, "status": "ACTIVE", "sortPriority": 6, "id": 2545061}, {"adjustmentFactor": 26.652, "status": "ACTIVE", "sortPriority": 7, "id": 37618540}, {"adjustmentFactor": 7.599, "status": "ACTIVE", "sortPriority": 8, "id": 7603748}, {"adjustmentFactor": 7.042, "status": "ACTIVE", "sortPriority": 9, "id": 9005341}], "regulators": ["MR_INT"], "venue": "Ballarat", "countryCode": "AU", "discountAllowed": true, "timezone": "Australia/Sydney", "openDate": "2021-07-30T08:30:00.000Z", "version": 3938290778, "raceType": "Flat", "priceLadderDefinition": {"type": "CLASSIC"}}, "rc": [{"atb": [[3.75, 119.98], [1.01, 156.31], [5.1, 1.41], [4, 82.49], [4.6, 1.99], [5, 20.62], [4.5, 47.13], [1.14, 2]], "atl": [[14.5, 9.59], [19.5, 7], [29, 6.93], [48, 4.13], [690, 0.03]], "batb": [[7, 1.01, 156.31], [5, 3.75, 119.98], [4, 4, 82.49], [0, 5.1, 1.41], [6, 1.14, 2], [3, 4.5, 47.13], [2, 4.6, 1.99], [1, 5, 20.62]], "batl": [[1, 19.5, 7], [0, 14.5, 9.59], [4, 690, 0.03], [3, 48, 4.13], [2, 29, 6.93]], "id": 7603748}, {"atb": [[1.01, 156.31], [15.5, 22.75], [27, 0.27], [21, 8.25], [18, 14.56], [26, 3.3], [1.14, 2]], "atl": [[600, 0.07], [490, 0.4], [390, 0.5], [190, 0.68], [290, 0.45], [690, 0.03]], "batb": [[5, 1.01, 156.31], [3, 15.5, 22.75], [2, 18, 14.56], [1, 21, 8.25], [0, 26, 3.57], [4, 1.14, 2]], "batl": [[1, 690, 1], [0, 290, 1.13]], "id": 34140525}, {"atb": [[5.3, 57.55], [1.01, 156.31], [6, 1.43], [6.6, 14.73], [5.8, 34.37], [4.8, 86.82], [6.8, 1.05], [1.14, 2]], "atl": [[23, 0.07], [19.5, 7], [29, 4.62], [48, 4.13], [95, 2.07], [690, 0.03]], "spl": [[7.6, 4.77]], "batb": [[7, 1.01, 156.31], [4, 5.3, 57.55], [6, 1.14, 2], [5, 4.8, 86.82], [3, 5.8, 34.37], [2, 6, 1.43], [1, 6.6, 14.73], [0, 6.8, 1.05]], "batl": [[1, 29, 4.69], [4, 690, 0.03], [0, 19.5, 7], [3, 95, 2.07], [2, 48, 4.13]], "id": 25000686}, {"atb": [[2.1, 149.97], [1.95, 347.31], [2.2, 68.74], [1.01, 156.31], [2, 247.46], [2.26, 3.17], [2.24, 5.78], [1.14, 2]], "atl": [[6, 25.9], [10, 21.58], [5, 32.37], [8, 27.74], [3.7, 2.65], [690, 0.03]], "spl": [[4.4, 6.89], [1.01, 7.95]], "batb": [[7, 1.01, 156.31], [5, 1.95, 347.31], [4, 2, 247.46], [3, 2.1, 149.97], [2, 2.2, 68.74], [1, 2.24, 5.78], [0, 2.26, 3.17], [6, 1.14, 2]], "batl": [[2, 6, 25.9], [4, 10, 21.58], [3, 8, 27.74], [1, 5, 32.37], [5, 690, 0.03], [0, 3.7, 2.65]], "id": 37618540}, {"atb": [[8.4, 44.59], [1.01, 156.31], [9.8, 0.82], [9.4, 29.46], [11, 16.5], [13.5, 6.6], [14, 0.51], [1.14, 2]], "atl": [[360, 0.54], [160, 0.82], [80, 1.64], [260, 0.75], [690, 0.03]], "batb": [[5, 1.01, 156.31], [3, 8.4, 44.59], [2, 9.4, 30.28], [1, 11, 16.5], [4, 1.14, 2], [0, 13.5, 7.11]], "batl": [[2, 690, 0.57], [1, 260, 1.57], [0, 80, 1.64]], "id": 9005341}, {"atb": [[8.4, 44.59], [1.01, 156.31], [9.8, 0.82], [9.4, 29.46], [11, 16.5], [13.5, 6.6], [22, 0.32], [1.14, 2]], "atl": [[300, 0.07], [360, 0.54], [160, 0.82], [80, 1.64], [260, 0.75], [690, 0.03]], "batb": [[5, 1.01, 156.31], [3, 8.4, 44.59], [2, 9.4, 30.28], [1, 11, 16.5], [4, 1.14, 2], [0, 13.5, 6.92]], "batl": [[2, 690, 0.64], [1, 260, 1.57], [0, 80, 1.64]], "id": 28277002}, {"atb": [[1.01, 156.31], [15.5, 22.75], [27, 0.27], [21, 8.25], [18, 14.56], [26, 3.3], [1.14, 2]], "atl": [[500, 0.07], [490, 0.4], [390, 0.5], [190, 0.68], [290, 0.45], [690, 0.03]], "batb": [[5, 1.01, 156.31], [3, 15.5, 22.75], [2, 18, 14.56], [1, 21, 8.25], [0, 26, 3.57], [4, 1.14, 2]], "batl": [[1, 690, 1], [0, 290, 1.13]], "id": 13672313}, {"atb": [[2.7, 145.56], [2.6, 206.21], [1.01, 156.31], [2.88, 3.82], [2.8, 91.65], [2.9, 43.41], [2.96, 2.42], [1.14, 2]], "atl": [[7.6, 0.07], [8.8, 16.6], [12, 17.66], [6.8, 22.32], [17, 12.14], [690, 0.03]], "spl": [[5.4, 5.83]], "batb": [[7, 1.01, 156.31], [5, 2.6, 206.21], [4, 2.7, 145.56], [3, 2.8, 91.65], [2, 2.88, 3.82], [6, 1.14, 2], [1, 2.9, 43.41], [0, 2.96, 2.42]], "batl": [[1, 8.8, 16.67], [4, 690, 0.03], [3, 17, 12.14], [2, 12, 17.66], [0, 6.8, 22.32]], "id": 28572209}, {"atb": [[1.01, 156.31], [11.5, 31.42], [14, 19.03], [19, 4.58], [16.5, 10.64], [19.5, 0.37], [1.14, 2]], "atl": [[110, 1.19], [210, 0.62], [410, 0.48], [310, 0.63], [690, 0.03]], "batb": [[5, 1.01, 156.31], [3, 11.5, 31.42], [4, 1.14, 2], [2, 14, 19.03], [1, 16.5, 10.64], [0, 19, 4.95]], "batl": [[2, 690, 0.51], [1, 310, 1.25], [0, 110, 1.19]], "id": 2545061}], "img": true, "tv": 0}, {"id": "1.185793016", "marketDefinition": {"bspMarket": true, "turnInPlayEnabled": true, "persistenceEnabled": true, "marketBaseRate": 6, "eventId": "30739215", "eventTypeId": "7", "numberOfWinners": 1, "bettingType": "ODDS", "marketType": "WIN", "marketTime": "2021-07-30T09:00:00.000Z", "suspendTime": "2021-07-30T09:00:00.000Z", "bspReconciled": false, "complete": true, "inPlay": false, "crossMatching": true, "runnersVoidable": false, "numberOfActiveRunners": 10, "betDelay": 0, "status": "OPEN", "runners": [{"adjustmentFactor": 2.955, "status": "ACTIVE", "sortPriority": 1, "id": 28368691}, {"adjustmentFactor": 1.611, "status": "ACTIVE", "sortPriority": 2, "id": 24141128}, {"adjustmentFactor": 1.611, "status": "ACTIVE", "sortPriority": 3, "id": 13313867}, {"adjustmentFactor": 1.611, "status": "ACTIVE", "sortPriority": 4, "id": 38475171}, {"adjustmentFactor": 10.157, "status": "ACTIVE", "sortPriority": 5, "id": 10944797}, {"adjustmentFactor": 31.267, "status": "ACTIVE", "sortPriority": 6, "id": 38448953}, {"adjustmentFactor": 1.611, "status": "ACTIVE", "sortPriority": 7, "id": 40363504}, {"adjustmentFactor": 25.404, "status": "ACTIVE", "sortPriority": 8, "id": 25964771}, {"adjustmentFactor": 22.582, "status": "ACTIVE", "sortPriority": 9, "id": 11727644}, {"adjustmentFactor": 1.19, "status": "ACTIVE", "sortPriority": 10, "id": 38388096}, {"adjustmentFactor": 1.586, "status": "REMOVED", "sortPriority": 11, "removalDate": "2021-07-29T22:57:49.000Z", "id": 29807511}], "regulators": ["MR_INT"], "venue": "Ballarat", "countryCode": "AU", "discountAllowed": true, "timezone": "Australia/Sydney", "openDate": "2021-07-30T08:30:00.000Z", "version": 3938290786, "raceType": "Flat", "priceLadderDefinition": {"type": "CLASSIC"}}, "rc": [{"atb": [[1.01, 156.31], [15.5, 22.75], [27, 0.27], [21, 8.25], [18, 14.56], [26, 3.3], [1.14, 2]], "atl": [[600, 0.07], [490, 0.4], [390, 0.5], [190, 0.68], [290, 0.45], [690, 0.03]], "batb": [[5, 1.01, 156.31], [3, 15.5, 22.75], [2, 18, 14.56], [1, 21, 8.25], [0, 26, 3.57], [4, 1.14, 2]], "batl": [[1, 690, 1], [0, 290, 1.13]], "id": 24141128}, {"atb": [[2.7, 97.04], [2.6, 154.66], [2.5, 219.96], [1.01, 156.31], [2.8, 45.83], [2.76, 4.07], [3.5, 2.05], [1.14, 2]], "atl": [[7, 0.07], [8.2, 17.98], [10.5, 20.44], [6.2, 24.9], [15.5, 13.39], [690, 0.03]], "spl": [[3.4, 8.48], [1.01, 7.95]], "batb": [[7, 1.01, 156.31], [5, 2.5, 219.96], [4, 2.6, 154.66], [3, 2.7, 97.04], [1, 2.8, 45.83], [6, 1.14, 2], [2, 2.76, 4.07], [0, 3.5, 2.05]], "batl": [[4, 690, 0.03], [3, 15.5, 13.39], [2, 10.5, 20.44], [1, 8.2, 18.05], [0, 6.2, 24.9]], "id": 38448953}, {"atb": [[1.01, 156.31], [7.2, 53.22], [9.6, 0.83], [8.2, 34.37], [9.2, 20.12], [10.5, 8.68], [11, 0.65], [1.14, 2]], "atl": [[150, 0.07], [110, 1.19], [55, 2.4], [210, 0.93], [310, 0.63], [690, 0.03]], "batb": [[5, 1.01, 156.31], [3, 7.2, 53.22], [1, 9.2, 20.95], [2, 8.2, 34.37], [4, 1.14, 2], [0, 10.5, 9.33]], "batl": [[3, 690, 0.66], [2, 210, 1], [1, 110, 1.19], [0, 55, 2.4]], "id": 28368691}, {"atb": [[1.01, 156.31], [15.5, 22.75], [27, 0.27], [21, 8.25], [18, 14.56], [26, 3.3], [1.14, 2]], "atl": [[490, 0.4], [390, 0.5], [190, 0.68], [290, 0.45], [690, 0.03]], "batb": [[5, 1.01, 156.31], [3, 15.5, 22.75], [2, 18, 14.56], [1, 21, 8.25], [0, 26, 3.57], [4, 1.14, 2]], "batl": [[1, 690, 0.93], [0, 290, 1.13]], "id": 40363504}, {"atb": [[2.1, 299.95], [2.2, 206.21], [2.3, 126.9], [1.01, 156.31], [2.4, 58.92], [2.46, 4.91], [3.2, 2.24], [1.14, 2]], "atl": [[8.6, 25.56], [6.6, 23.12], [5.3, 30.11], [70, 42.38], [4.4, 2.65], [11.5, 18.49], [690, 0.03]], "spl": [[4.9, 6.36], [2.6, 92.71], [1.01, 105.95]], "batb": [[7, 1.01, 156.31], [5, 2.1, 299.95], [4, 2.2, 206.21], [3, 2.3, 126.9], [2, 2.4, 58.92], [6, 1.14, 2], [1, 2.46, 4.91], [0, 3.2, 2.24]], "batl": [[3, 8.6, 25.56], [5, 70, 42.38], [2, 6.6, 23.12], [1, 5.3, 30.11], [6, 690, 0.03], [4, 11.5, 18.49], [0, 4.4, 2.65]], "id": 25964771}, {"atb": [[1.01, 156.31], [15.5, 22.75], [21, 8.25], [18, 14.56], [26, 3.3], [34, 0.21], [1.14, 2]], "atl": [[600, 0.07], [490, 0.4], [390, 0.5], [190, 0.68], [290, 0.45], [690, 0.03]], "batb": [[5, 1.01, 156.31], [3, 15.5, 22.75], [2, 18, 14.56], [1, 21, 8.25], [4, 1.14, 2], [0, 26, 3.51]], "batl": [[1, 690, 1], [0, 290, 1.13]], "id": 38475171}, {"atb": [[3.75, 30], [3.5, 65.99], [3.9, 1.84], [3.25, 109.98], [3, 164.97], [1.01, 156.31], [3.6, 2.76], [1.14, 2]], "atl": [[9.6, 15.06], [11, 0.07], [14, 9.96], [28, 7.19], [19, 10.79], [690, 0.03]], "spl": [[12, 3.71]], "batb": [[7, 1.01, 156.31], [5, 3, 164.97], [4, 3.25, 109.98], [3, 3.5, 65.99], [1, 3.75, 30], [0, 3.9, 1.84], [6, 1.14, 2], [2, 3.6, 2.76]], "batl": [[0, 9.6, 15.06], [4, 690, 0.03], [3, 28, 7.19], [2, 19, 10.79], [1, 14, 10.03]], "id": 10944797}, {"atb": [[5.3, 38.37], [5.8, 17.19], [1.01, 156.31], [4.3, 99.98], [4.8, 65.12], [5.5, 1.59], [5.9, 1.21], [1.14, 2]], "atl": [[23, 5.89], [36, 5.55], [65, 3.04], [16.5, 8.35], [690, 0.03]], "spl": [[8.4, 4.77]], "batb": [[7, 1.01, 156.31], [5, 4.3, 99.98], [4, 4.8, 65.12], [3, 5.3, 38.37], [1, 5.8, 17.19], [6, 1.14, 2], [2, 5.5, 1.59], [0, 5.9, 1.21]], "batl": [[3, 65, 3.04], [2, 36, 5.55], [1, 23, 5.89], [4, 690, 0.03], [0, 16.5, 8.35]], "id": 11727644}, {"atb": [[1.01, 156.31], [15.5, 22.75], [27, 0.27], [21, 8.25], [18, 14.56], [26, 3.3], [1.14, 2]], "atl": [[600, 0.07], [490, 0.4], [390, 0.5], [190, 0.68], [290, 0.45], [690, 0.03]], "batb": [[5, 1.01, 156.31], [3, 15.5, 22.75], [2, 18, 14.56], [1, 21, 8.25], [0, 26, 3.57], [4, 1.14, 2]], "batl": [[1, 690, 1], [0, 290, 1.13]], "id": 13313867}, {"atb": [[1.01, 156.31], [46, 5.5], [90, 0.93], [36, 9.42], [65, 2.58], [50, 0.14], [1.14, 2]], "atl": [[880, 0.22], [780, 0.25], [680, 0.19], [580, 0.22], [690, 0.03]], "batb": [[4, 1.01, 156.31], [3, 1.14, 2], [2, 36, 9.42], [1, 46, 5.64], [0, 65, 3.51]], "batl": [[0, 880, 0.91]], "id": 38388096}], "img": true, "tv": 0}, {"id": "1.185793014", "marketDefinition": {"bspMarket": true, "turnInPlayEnabled": true, "persistenceEnabled": true, "marketBaseRate": 6, "eventId": "30739215", "eventTypeId": "7", "numberOfWinners": 1, "bettingType": "ODDS", "marketType": "WIN", "marketTime": "2021-07-30T08:30:00.000Z", "suspendTime": "2021-07-30T08:30:00.000Z", "bspReconciled": false, "complete": true, "inPlay": false, "crossMatching": true, "runnersVoidable": false, "numberOfActiveRunners": 10, "betDelay": 0, "status": "OPEN", "runners": [{"adjustmentFactor": 8.123, "status": "ACTIVE", "sortPriority": 1, "id": 39610809}, {"adjustmentFactor": 3.529, "status": "ACTIVE", "sortPriority": 2, "id": 40363500}, {"adjustmentFactor": 26.607, "status": "ACTIVE", "sortPriority": 3, "id": 39989740}, {"adjustmentFactor": 3.529, "status": "ACTIVE", "sortPriority": 4, "id": 28396454}, {"adjustmentFactor": 2.892, "status": "ACTIVE", "sortPriority": 5, "id": 28024171}, {"adjustmentFactor": 23.458, "status": "ACTIVE", "sortPriority": 6, "id": 40363501}, {"adjustmentFactor": 2.892, "status": "ACTIVE", "sortPriority": 7, "id": 39647873}, {"adjustmentFactor": 3.529, "status": "ACTIVE", "sortPriority": 8, "id": 40363502}, {"adjustmentFactor": 20.97, "status": "ACTIVE", "sortPriority": 9, "id": 39317152}, {"adjustmentFactor": 4.47, "status": "ACTIVE", "sortPriority": 10, "id": 40363503}], "regulators": ["MR_INT"], "venue": "Ballarat", "countryCode": "AU", "discountAllowed": true, "timezone": "Australia/Sydney", "openDate": "2021-07-30T08:30:00.000Z", "version": 3938290790, "raceType": "Flat", "priceLadderDefinition": {"type": "CLASSIC"}}, "rc": [{"atb": [[3, 85.35], [2.9, 134.76], [1.01, 156.31], [2.8, 189.66], [3.25, 37.93], [3.1, 3.41], [3.3, 6.06], [3.4, 2.11], [1.14, 2]], "atl": [[7.4, 19.34], [18.5, 10.61], [8.2, 0.07], [13.5, 14.85], [9.4, 14.73], [690, 0.03]], "spl": [[6.4, 5.3]], "batb": [[8, 1.01, 156.31], [6, 2.8, 189.66], [5, 2.9, 134.76], [4, 3, 85.35], [2, 3.25, 37.93], [7, 1.14, 2], [3, 3.1, 3.41], [1, 3.3, 6.06], [0, 3.4, 2.11]], "batl": [[3, 18.5, 10.61], [0, 7.4, 19.34], [1, 9.4, 14.8], [4, 690, 0.03], [2, 13.5, 14.85]], "id": 40363501}, {"atb": [[2.1, 202.72], [2.2, 123.89], [2.3, 65.88], [1.01, 156.31], [2, 297.33], [3.7, 1.94], [2.36, 5.27], [1.14, 2]], "atl": [[6.2, 28.04], [5.1, 35.56], [8.2, 30.37], [10.5, 23.02], [70, 42.38], [3.8, 2], [3.85, 2.65], [690, 0.03]], "trd": [[3.85, 57.22]], "spl": [[4.9, 6.36], [1.01, 105.95], [1.8, 79.47]], "batb": [[7, 1.01, 156.31], [5, 2, 297.33], [4, 2.1, 202.72], [3, 2.2, 123.89], [2, 2.3, 65.88], [1, 2.36, 5.27], [0, 3.7, 1.94], [6, 1.14, 2]], "batl": [[3, 6.2, 28.04], [2, 5.1, 35.56], [6, 70, 42.38], [5, 10.5, 23.02], [4, 8.2, 30.37], [7, 690, 0.03], [1, 3.85, 2.65], [0, 3.8, 2]], "tv": 57.22, "id": 39989740}, {"atb": [[9.8, 29.1], [1.01, 156.31], [8.8, 43.77], [12, 15.52], [10, 0.8], [14.5, 6.32], [15, 1.81], [1.14, 2]], "atl": [[370, 0.5], [170, 0.73], [85, 1.47], [270, 0.69], [690, 0.03]], "batb": [[6, 1.01, 156.31], [3, 9.8, 29.9], [4, 8.8, 43.77], [2, 12, 15.52], [5, 1.14, 2], [1, 14.5, 6.32], [0, 15, 1.81]], "batl": [[2, 690, 0.53], [1, 270, 1.42], [0, 85, 1.47]], "id": 40363500}, {"atb": [[11.5, 24.39], [1.01, 156.31], [9.6, 39.7], [14, 13.13], [10, 0.8], [17, 1.6], [16.5, 5.5], [1.14, 2]], "atl": [[430, 0.07], [390, 0.48], [190, 0.66], [95, 1.32], [290, 0.64], [690, 0.03]], "batb": [[6, 1.01, 156.31], [4, 9.6, 40.5], [3, 11.5, 24.39], [2, 14, 13.13], [5, 1.14, 2], [1, 16.5, 5.5], [0, 17, 1.6]], "batl": [[2, 690, 0.58], [1, 290, 1.3], [0, 95, 1.32]], "id": 39647873}, {"atb": [[11.5, 24.39], [1.01, 156.31], [9.6, 39.7], [14, 13.13], [10, 0.8], [17, 1.6], [16.5, 5.5], [1.14, 2]], "atl": [[430, 0.07], [390, 0.48], [190, 0.66], [95, 1.32], [290, 0.64], [690, 0.03]], "batb": [[6, 1.01, 156.31], [4, 9.6, 40.5], [3, 11.5, 24.39], [2, 14, 13.13], [5, 1.14, 2], [1, 16.5, 5.5], [0, 17, 1.6]], "batl": [[2, 690, 0.58], [1, 290, 1.3], [0, 95, 1.32]], "id": 28396454}, {"atb": [[5.3, 59.55], [1.01, 156.31], [4.8, 89.84], [6.6, 15.24], [7, 1.03], [5.8, 35.56], [6, 1.43], [6.8, 2.94], [1.14, 2]], "atl": [[23, 0.07], [29, 4.42], [48, 3.95], [95, 1.98], [19.5, 6.69], [690, 0.03]], "spl": [[10, 4.24]], "batb": [[8, 1.01, 156.31], [6, 4.8, 89.84], [5, 5.3, 59.55], [4, 5.8, 35.56], [2, 6.6, 15.24], [0, 7, 1.03], [7, 1.14, 2], [3, 6, 1.43], [1, 6.8, 2.94]], "batl": [[1, 29, 4.49], [4, 690, 0.03], [3, 95, 1.98], [2, 48, 3.95], [0, 19.5, 6.69]], "id": 39317152}, {"atb": [[14, 19.7], [1.01, 156.31], [11.5, 32.51], [19.5, 1.4], [19, 4.74], [16.5, 11.01], [1.14, 2]], "atl": [[450, 0.07], [110, 1.13], [210, 0.59], [410, 0.46], [310, 0.6], [690, 0.03]], "batb": [[6, 1.01, 156.31], [3, 14, 19.7], [4, 11.5, 32.51], [5, 1.14, 2], [2, 16.5, 11.01], [1, 19, 4.74], [0, 19.5, 1.4]], "batl": [[2, 690, 0.56], [1, 310, 1.19], [0, 110, 1.13]], "id": 40363503}, {"atb": [[6, 34.14], [5.5, 56.9], [5, 85.35], [1.01, 156.31], [6.2, 1.38], [7, 14.22], [7.2, 3.78], [1.14, 2]], "atl": [[140, 1.34], [28, 0.07], [24, 5.38], [38, 3.34], [70, 2.69], [690, 0.03]], "batb": [[7, 1.01, 156.31], [5, 5, 85.35], [4, 5.5, 56.9], [3, 6, 34.14], [2, 6.2, 1.38], [6, 1.14, 2], [1, 7, 14.22], [0, 7.2, 3.78]], "batl": [[3, 140, 1.34], [1, 38, 3.41], [4, 690, 0.03], [2, 70, 2.69], [0, 24, 5.38]], "id": 40363502}, {"atb": [[6, 51.21], [8.2, 3.32], [1.01, 156.31], [7, 28.45], [5.5, 75.86], [8, 12.19], [7.2, 1.15], [1.14, 2]], "atl": [[100, 1.88], [30, 4.27], [200, 0.93], [50, 2.53], [690, 0.03]], "spl": [[16, 3.18]], "batb": [[7, 1.01, 156.31], [4, 6, 51.21], [0, 8.2, 3.32], [5, 5.5, 75.86], [3, 7, 28.45], [1, 8, 12.19], [6, 1.14, 2], [2, 7.2, 1.15]], "batl": [[2, 100, 1.88], [3, 690, 0.96], [1, 50, 2.53], [0, 30, 4.27]], "id": 39610809}, {"atb": [[1.01, 156.31], [13, 21.33], [10.5, 35.93], [18.5, 1.47], [15.5, 11.77], [18, 5.02], [1.14, 2]], "atl": [[440, 0.07], [400, 0.47], [200, 0.62], [100, 1.25], [300, 0.62], [690, 0.03]], "batb": [[6, 1.01, 156.31], [4, 10.5, 35.93], [3, 13, 21.33], [5, 1.14, 2], [2, 15.5, 11.77], [1, 18, 5.02], [0, 18.5, 1.47]], "batl": [[2, 690, 0.57], [1, 300, 1.24], [0, 100, 1.25]], "id": 28024171}], "img": true, "tv": 57.22}, {"id": "1.185783401", "marketDefinition": {"bspMarket": true, "turnInPlayEnabled": true, "persistenceEnabled": true, "marketBaseRate": 6, "eventId": "30738738", "eventTypeId": "7", "numberOfWinners": 1, "bettingType": "ODDS", "marketType": "WIN", "marketTime": "2021-07-31T03:13:00.000Z", "suspendTime": "2021-07-31T03:13:00.000Z", "bspReconciled": false, "complete": true, "inPlay": false, "crossMatching": false, "runnersVoidable": false, "numberOfActiveRunners": 10, "betDelay": 0, "status": "OPEN", "runners": [{"adjustmentFactor": 19.367, "status": "ACTIVE", "sortPriority": 1, "id": 38178273}, {"adjustmentFactor": 9.485, "status": "ACTIVE", "sortPriority": 2, "id": 37549718}, {"adjustmentFactor": 16.275, "status": "ACTIVE", "sortPriority": 3, "id": 40363957}, {"adjustmentFactor": 5.2, "status": "ACTIVE", "sortPriority": 4, "id": 40041628}, {"adjustmentFactor": 16.275, "status": "ACTIVE", "sortPriority": 5, "id": 40363958}, {"adjustmentFactor": 8, "status": "ACTIVE", "sortPriority": 6, "id": 40363959}, {"adjustmentFactor": 4.333, "status": "ACTIVE", "sortPriority": 7, "id": 40363962}, {"adjustmentFactor": 2.419, "status": "ACTIVE", "sortPriority": 8, "id": 40041166}, {"adjustmentFactor": 3.852, "status": "ACTIVE", "sortPriority": 9, "id": 40363963}, {"adjustmentFactor": 14.794, "status": "ACTIVE", "sortPriority": 10, "id": 40363964}, {"adjustmentFactor": 1.923, "status": "REMOVED", "sortPriority": 11, "removalDate": "2021-07-29T23:31:43.000Z", "id": 40363960}, {"adjustmentFactor": 1.961, "status": "REMOVED", "sortPriority": 12, "removalDate": "2021-07-29T23:31:53.000Z", "id": 40363961}], "regulators": ["MR_INT"], "venue": "Eagle Farm", "countryCode": "AU", "discountAllowed": true, "timezone": "Australia/Queensland", "openDate": "2021-07-31T01:28:00.000Z", "version": 3938301540, "raceType": "Flat", "priceLadderDefinition": {"type": "CLASSIC"}}, "rc": [{"atb": [[5.9, 1.21], [1.01, 166.31], [5, 65.11], [5.8, 8.08], [4.5, 111.62], [4, 130.22], [5.7, 55.41], [1.03, 322], [1.02, 2]], "atl": [[17, 9.08], [10.5, 12.71], [11, 1.35], [38, 3.93], [24, 6.31], [70, 2.1], [690, 0.03]], "batb": [[8, 1.01, 166.31], [7, 1.02, 2], [6, 1.03, 322], [5, 4, 130.22], [4, 4.5, 111.62], [3, 5, 65.11], [2, 5.7, 55.41], [1, 5.8, 8.08], [0, 5.9, 1.21]], "batl": [[2, 17, 9.08], [6, 690, 0.03], [5, 70, 2.1], [4, 38, 3.93], [3, 24, 6.31], [1, 11, 1.35], [0, 10.5, 12.71]], "id": 40363964}, {"atb": [[20, 0.36], [1.02, 2], [1.01, 166.31], [15.5, 17.96], [13, 32.55], [10.5, 41.12], [19, 14.47], [19.5, 4.5], [1.03, 322]], "atl": [[230, 0.64], [430, 0.34], [330, 0.44], [130, 1.12], [990, 1.3], [690, 0.03]], "batb": [[0, 19.5, 4.86], [6, 1.02, 2], [7, 1.01, 166.31], [4, 10.5, 41.12], [3, 13, 32.55], [2, 15.5, 17.96], [1, 19, 14.47], [5, 1.03, 322]], "batl": [[2, 990, 1.67], [1, 330, 1.08], [0, 130, 1.12]], "id": 40363962}, {"atb": [[22, 0.32], [1.02, 2], [14, 28.42], [1.01, 166.31], [11.5, 35.18], [16.5, 15.89], [21, 2.9], [1.04, 1.47], [20, 12.96], [1.03, 322]], "atl": [[75, 4.24], [80, 1.34], [140, 1.17], [240, 0.68], [440, 0.37], [340, 0.48], [690, 0.03]], "batb": [[0, 21, 3.22], [7, 1.02, 2], [8, 1.01, 166.31], [3, 14, 28.42], [4, 11.5, 35.18], [2, 16.5, 15.89], [6, 1.03, 322], [5, 1.04, 1.47], [1, 20, 12.96]], "batl": [[4, 690, 0.4], [3, 340, 1.16], [2, 140, 1.17], [1, 80, 1.34], [0, 75, 4.24]], "id": 40363963}, {"atb": [[17.5, 1.41], [9.4, 46.51], [13.5, 20.84], [11, 39.07], [17, 18.46], [16.5, 1.55], [1.02, 2], [1.01, 166.31], [1.03, 322]], "atl": [[110, 1.33], [210, 0.69], [410, 0.35], [310, 0.47], [60, 5.44], [690, 0.03]], "batb": [[8, 1.01, 166.31], [7, 1.02, 2], [6, 1.03, 322], [5, 9.4, 46.51], [4, 11, 39.07], [3, 13.5, 20.84], [2, 16.5, 1.55], [1, 17, 18.46], [0, 17.5, 1.41]], "batl": [[3, 690, 0.38], [2, 310, 1.16], [1, 110, 1.33], [0, 60, 5.44]], "id": 40041628}, {"atb": [[5.4, 1.33], [1.01, 166.31], [3.75, 134.33], [5.2, 58.64], [4, 123.14], [4.5, 70.36], [5.3, 8.56], [1.03, 322], [1.