{"op":"mcm","id":12345,"initialClk":"yhfXkdfHDMoXgtDFvwzKF9+D78QM","clk":"AAAAAAAA","conflateMs":0,"heartbeatMs":5000,"pt":1478348005395,"ct":"RESUB_DELTA","mc":[{"id":"1.128076835","rc":[{"batb":[[0,2.7,179.35]],"batl":[[0,2.74,151.65]],"id":10868956},{"batb":[[0,9.8,5.71]],"batl":[[0,10.5,7.01]],"id":10396752},{"batb":[[0,10.5,15.18]],"id":10718246},{"batb":[[0,4.8,45.99]],"batl":[[0,5,14.36]],"id":10997981},{"batb":[[0,6.8,35.8]],"batl":[],"id":10738672},{"batb":[[0,23,9.9]],"batl":[[0,25,2]],"id":10884157},{"batb":[[0,22,18.14]],"batl":[[0,24,8]],"id":10856685},{"batb":[[0,90,2.24]],"batl":[[0,250,4.22]],"id":10500774}],"con":true},{"id":"1.128077032","rc":[{"batb":[[0,320,4.54]],"id":391240},{"batb":[[0,3.6,55.98]],"batl":[[0,3.7,15.34]],"id":7859045},{"batb":[[0,3.45,32.91]],"batl":[[0,3.5,38.01]],"id":7172119},{"batb":[[0,80,3.94]],"batl":[],"id":9176905}],"con":true},{"id":"1.128077012","rc":[{"batb":[[0,6,4.66]],"batl":[[0,6.6,6.97]],"id":6077223},{"batb":[[0,2.58,26.41]],"batl":[[0,2.6,45.52]],"id":10412002},{"batb":[[0,7.8,15.01]],"batl":[],"id":9536850},{"batb":[[0,150,3.06]],"batl":[],"id":11070491},{"batb":[[0,10.5,12.28]],"batl":[[0,11.5,12.48]],"id":12059874},{"batb":[[0,12.5,9.82]],"batl":[[0,13,59.34]],"id":33449},{"batb":[],"batl":[[0,60,4.04]],"id":10966440}],"con":true},{"id":"1.128077042","rc":[{"batb":[[0,18,29.5]],"batl":[[0,21,2.39]],"id":10878393},{"batb":[[0,12,7.88]],"batl":[[0,13,30.3]],"id":9421443},{"batb":[[0,80,6.85]],"id":11949956},{"batb":[[0,2.34,39.24]],"batl":[[0,2.44,5.07]],"id":11892815},{"batb":[[0,3.65,5.22]],"batl":[[0,3.85,7.09]],"id":11082747},{"batb":[[0,5,9.44]],"batl":[[0,5.5,4.77]],"id":9456589}],"con":true},{"id":"1.128076855","rc":[{"batb":[[0,5.7,385.99]],"id":7792124},{"batb":[[0,5.8,12.87]],"id":8312151},{"batb":[[0,9.4,35.46]],"id":8124145},{"batl":[[0,25,17.15]],"id":5152139},{"batb":[[0,30,2.84]],"batl":[[0,38,5]],"id":6356120},{"batb":[[0,5.1,46.16]],"id":8882739},{"batb":[[0,6,53.68]],"batl":[],"id":7653364},{"batl":[[0,10.5,734.45]],"id":7772383},{"batb":[[0,29,34.44]],"batl":[[0,34,7]],"id":6284847}],"con":true},{"id":"1.128076865","rc":[{"batb":[[0,2.68,146.9]],"batl":[],"id":11047511},{"batb":[[0,55,7.48]],"batl":[[0,80,2.21]],"id":10814469},{"batl":[[0,13.5,3.93]],"id":11994720},{"batl":[[0,6.8,10.9]],"id":12059870}],"con":true},{"id":"1.128077037","rc":[{"batb":[[0,7.6,4.28]],"batl":[[0,7.8,3.8]],"id":6623876},{"batb":[[0,6.4,5.3]],"id":9375195},{"batb":[[0,17,2.02]],"batl":[[0,19,2.3]],"id":6520535},{"batb":[[0,11.5,9.04]],"batl":[[0,14,2.39]],"id":8315382},{"batl":[[0,20,3.38]],"id":5973679},{"batb":[[0,17,3.32]],"batl":[[0,23,3.22]],"id":8742358},{"batb":[[0,2.54,24.58]],"batl":[[0,2.58,75]],"id":9483271}],"con":true},{"id":"1.128076845","rc":[{"batb":[[0,6.4,60.75]],"batl":[[0,6.8,6]],"id":7286542},{"batb":[[0,17.5,8]],"batl":[[0,18,3.04]],"id":6066164},{"batb":[[0,9.8,6.3]],"batl":[[0,10,9.51]],"id":5972639},{"batb":[[0,6,85.89]],"batl":[],"id":6588143},{"batb":[[0,7.2,27.35]],"batl":[[0,7.4,8.7]],"id":8752430}],"con":true},{"id":"1.128077022","rc":[{"batb":[[0,10.5,21.93]],"batl":[[0,11,10.76]],"id":8163020},{"batb":[[0,9.8,10.83]],"batl":[],"id":10079834},{"batb":[[0,42,3.59]],"batl":[[0,70,3.88]],"id":8902696},{"batb":[[0,16,9.2]],"batl":[[0,17.5,4.94]],"id":7433195},{"batb":[[0,110,2.15]],"id":5945824},{"batb":[[0,23,8.86]],"batl":[],"id":8619567}],"con":true},{"id":"1.128076850","rc":[{"batb":[[0,3.1,121.22]],"id":8947689},{"batb":[],"batl":[[0,7,285.64]],"id":7121863},{"batb":[[0,3.65,42.76]],"batl":[[0,3.7,487.72]],"id":5296412},{"batb":[[0,28,3.05]],"batl":[[0,29,5.65]],"id":8945462},{"batb":[[0,4.3,50.22]],"batl":[[0,4.5,10.11]],"id":6815401}],"con":true},{"id":"1.128076860","rc":[{"batb":[[0,5.4,2.22]],"batl":[[0,5.5,7.58]],"id":6194062},{"batb":[[0,5.2,60.44]],"batl":[[0,5.3,7.28]],"id":6597854},{"batb":[[0,10,39.63]],"batl":[[0,10.5,111.85]],"id":7369654},{"batb":[[0,17.5,2.24]],"batl":[[0,22,2]],"id":3458718},{"batb":[[0,4.5,49.3]],"batl":[],"id":5362530},{"batb":[[0,22,11.1]],"batl":[],"id":7059678},{"batb":[[0,16,3.53]],"batl":[[0,16.5,46.01]],"id":7705516},{"batb":[[0,6.4,26.24]],"batl":[],"id":7743265}],"con":true},{"id":"1.128077017","rc":[{"batb":[[0,75,6.9]],"batl":[],"id":9160053},{"batb":[[0,290,4.18]],"id":8388452},{"batb":[[0,50,2.81]],"batl":[],"id":11070417},{"batb":[[0,65,4.5]],"batl":[[0,150,6.8]],"id":11028054},{"batb":[[0,8.2,27.86]],"batl":[[0,8.6,30.99]],"id":10519070},{"batb":[[0,300,4.52]],"id":9210199},{"batb":[[0,3.9,31.95]],"batl":[[0,3.95,6]],"id":9562589},{"batb":[[0,160,2.71]],"id":1369514},{"batb":[[0,1.85,59.74]],"id":9375201},{"batb":[[0,24,3.95]],"batl":[],"id":12059876}],"con":true},{"id":"1.128077027","rc":[{"batb":[[0,34,4]],"id":8029775},{"batb":[[0,3.45,58.92]],"id":6761526},{"batb":[[0,3.9,41.37]],"batl":[[0,3.95,458.01]],"id":5035723},{"batb":[[0,9.8,9.1]],"batl":[[0,10,2]],"id":7860562},{"batb":[[0,12.5,148.1]],"batl":[[0,13,153]],"id":5937179},{"batb":[[0,5.2,39.46]],"batl":[[0,5.3,28.31]],"id":7122507}],"con":true},{"id":"1.128076840","rc":[{"batb":[[0,3.85,95.21]],"id":8150019},{"batl":[[0,2.92,16.6]],"id":9315491},{"batb":[[0,2.44,7.64]],"batl":[[0,2.5,5.61]],"id":11031127}],"con":true},{"id":"1.128074130","rc":[{"batb":[[0,26,27.98]],"batl":[],"id":12056059},{"batb":[[0,3.85,8.89]],"batl":[[0,3.9,167.1]],"id":12056058},{"batb":[[0,44,2.23]],"batl":[],"id":12056061},{"batb":[[0,130,5.85]],"id":12056060},{"batl":[[0,500,2.11]],"id":11975740},{"batb":[[0,6.2,3]],"batl":[[0,6.4,13.06]],"id":11975737},{"batb":[[0,65,3.46]],"batl":[[0,100,3.56]],"id":11773238},{"batb":[[0,8.2,7.55]],"batl":[],"id":11609539},{"batb":[[0,25,5.54]],"batl":[],"id":12056057},{"batb":[[0,120,3.23]],"id":11768986},{"batb":[[0,20,4]],"batl":[],"id":232874},{"batb":[[0,14,21.26]],"batl":[[0,14.5,88.96]],"id":11851208},{"batb":[[0,3.7,4]],"batl":[[0,4,10.48]],"id":11851207}],"con":true},{"id":"1.128076918","rc":[{"batb":[[0,4.2,36.95]],"batl":[[0,4.7,2]],"id":10566651},{"batb":[[0,23,2.04]],"id":12059878},{"batb":[],"batl":[[0,16,3.67]],"id":11132278},{"batb":[[0,15,8.07]],"id":11418346}],"con":true},{"id":"1.128076893","rc":[{"batb":[[0,28,5.78]],"batl":[[0,36,3.64]],"id":4687752},{"batb":[[0,100,12.28]],"id":6145656},{"batb":[[0,12,2.96]],"batl":[[0,13,9.15]],"id":10685365},{"batb":[[0,5.9,31.74]],"batl":[[0,6.2,37.24]],"id":7860558},{"batb":[[0,3.3,24.27]],"id":8212140},{"batb":[[0,3.65,2.93]],"batl":[[0,3.7,11.58]],"id":6899903},{"batb":[[0,15,9.82]],"batl":[[0,15.5,10]],"id":9281240},{"batb":[[0,60,6.63]],"batl":[],"id":5508015}],"con":true},{"id":"1.128076888","rc":[{"batb":[[0,1000,459.42]],"id":10458783},{"batb":[[0,2.04,91.62]],"batl":[[0,2.06,166.45]],"id":8957637},{"batb":[[0,430,3.11]],"batl":[[0,580,22.18]],"id":530984},{"batb":[[0,28,5.53]],"batl":[[0,29,8.11]],"id":11158583},{"batb":[[0,30,9.4]],"batl":[[0,32,6.65]],"id":5500786},{"batb":[[0,290,3.06]],"batl":[[0,390,6.72]],"id":11257750},{"batb":[[0,9.4,5.74]],"batl":[[0,9.6,14.46]],"id":10566647},{"batb":[[0,50,5.55]],"batl":[[0,55,7.17]],"id":10507450},{"batb":[[0,3.15,50.24]],"batl":[[0,3.25,108.87]],"id":11954822}],"con":true},{"id":"1.128076898","rc":[{"batb":[],"batl":[[0,13.5,3.4]],"id":6669706},{"batb":[[0,7.4,21.04]],"batl":[[0,7.8,29.11]],"id":7860561},{"batb":[],"batl":[[0,11,21.06]],"id":6229612},{"batb":[[0,2.96,30.41]],"batl":[[0,2.98,9.31]],"id":3887611},{"batb":[[0,13,15.82]],"batl":[[0,14,15.29]],"id":6092375},{"batb":[[0,3.35,31.41]],"batl":[[0,3.4,17.53]],"id":8933266}],"con":true},{"id":"1.128074135","rc":[{"batb":[[0,7.2,11.77]],"batl":[[0,7.4,11.24]],"id":5789389},{"batb":[[0,4.6,8.59]],"batl":[[0,4.8,13.96]],"id":10248410},{"batb":[],"batl":[[0,11,10.35]],"id":5892947}],"con":true},{"id":"1.128076913","rc":[{"batb":[[0,50,3.91]],"batl":[],"id":6160751},{"batl":[[0,16.5,9.25]],"id":7270438},{"batb":[[0,9.4,10.6]],"id":9727472},{"batb":[[0,4.2,61.39]],"batl":[[0,4.3,62.65]],"id":9424913}],"con":true},{"id":"1.128076903","rc":[{"batb":[[0,9.2,8.89]],"batl":[],"id":6874015},{"batb":[[0,6.6,4.44]],"batl":[],"id":7165817},{"batl":[[0,5.3,4.22]],"id":6802706}],"con":true},{"id":"1.128074125","rc":[{"batb":[[0,8.6,9.46]],"batl":[[0,8.8,2.6]],"id":8556771},{"batb":[[0,8.4,12.51]],"batl":[[0,8.6,8.64]],"id":7422371},{"batb":[],"batl":[[0,16.5,3.04]],"id":8521295},{"batb":[],"batl":[[0,7,28.55]],"id":3178497}],"con":true},{"id":"1.128074155","rc":[{"batb":[[0,12.5,4.07]],"batl":[],"id":8338757},{"batl":[[0,17,10]],"id":6423579},{"batb":[[0,24,4.52]],"batl":[],"id":8554942},{"batb":[[0,36,4.97]],"id":8638342}],"con":true},{"id":"1.128074150","rc":[{"batb":[[0,50,4.1]],"batl":[],"id":6507757},{"batb":[[0,3.45,34.91]],"batl":[[0,3.5,190.46]],"id":10875301},{"batb":[[0,5.9,24]],"batl":[[0,6.2,16.02]],"id":278971},{"batb":[[0,5.9,26.76]],"batl":[[0,6,6]],"id":9480382}],"con":true},{"id":"1.128074140","rc":[{"batb":[[0,50,2.76]],"batl":[[0,100,3.82]],"id":8530891},{"batb":[[0,3.1,8.22]],"batl":[[0,3.2,19.79]],"id":11015614},{"batl":[[0,7.8,32.17]],"id":8298630},{"batl":[[0,5.7,22]],"id":7344948}],"con":true},{"id":"1.128076908","rc":[{"batb":[[0,15,9.13]],"batl":[[0,16,11.63]],"id":4729605},{"batb":[[0,6.8,3.67]],"id":6936077},{"batb":[[0,7.6,15.22]],"id":4998673},{"batb":[[0,14.5,11.42]],"batl":[[0,15,4.35]],"id":5264109}],"con":true},{"id":"1.128074145","rc":[{"batl":[[0,46,2.38]],"id":11939496}],"con":true},{"id":"1.128049357","marketDefinition":{"bspMarket":true,"turnInPlayEnabled":true,"persistenceEnabled":true,"marketBaseRate":5,"eventId":"28002263","eventTypeId":"7","numberOfWinners":1,"bettingType":"ODDS","marketType":"WIN","marketTime":"2016-11-05T12:40:00.000Z","suspendTime":"2016-11-05T12:40:00.000Z","bspReconciled":false,"complete":true,"inPlay":false,"crossMatching":false,"runnersVoidable":false,"numberOfActiveRunners":11,"betDelay":0,"status":"OPEN","runners":[{"adjustmentFactor":32.355,"status":"ACTIVE","sortPriority":1,"id":11971747},{"adjustmentFactor":29.275,"status":"ACTIVE","sortPriority":2,"id":11374281},{"adjustmentFactor":13.514,"status":"ACTIVE","sortPriority":3,"id":11150039},{"adjustmentFactor":8.224,"status":"ACTIVE","sortPriority":4,"id":12055995},{"adjustmentFactor":6.806,"status":"ACTIVE","sortPriority":5,"id":11694979},{"adjustmentFactor":3.947,"status":"ACTIVE","sortPriority":6,"id":7454950},{"adjustmentFactor":2.467,"status":"ACTIVE","sortPriority":7,"id":11892060},{"adjustmentFactor":1.096,"status":"ACTIVE","sortPriority":8,"id":11985859},{"adjustmentFactor":0.822,"status":"ACTIVE","sortPriority":9,"id":12002488},{"adjustmentFactor":0.789,"status":"ACTIVE","sortPriority":10,"id":11906812},{"adjustmentFactor":0.705,"status":"ACTIVE","sortPriority":11,"id":12055994}],"regulators":["MR_INT"],"venue":"Doncaster","countryCode":"GB","discountAllowed":true,"timezone":"Europe/London","openDate":"2016-11-05T12:10:00.000Z","version":1484342451},"rc":[{"batb":[[0,10,46.35]],"batl":[[0,10.5,8.18]],"id":11150039},{"batb":[[0,11,28.52]],"batl":[[0,11.5,48.32]],"id":12055995},{"batb":[[0,2.7,186.62]],"batl":[[0,2.72,247.72]],"id":11971747},{"batb":[[0,190,2]],"batl":[[0,370,2.18]],"id":12055994},{"batb":[[0,16.5,5.07]],"batl":[[0,19.5,6.53]],"id":11694979},{"batb":[[0,160,5.25]],"batl":[[0,310,2.17]],"id":12002488},{"batb":[[0,140,5.1]],"batl":[[0,250,11.49]],"id":11906812},{"batb":[[0,110,9.28]],"batl":[[0,220,2.01]],"id":11985859},{"batb":[[0,30,12.77]],"batl":[[0,32,60.01]],"id":11892060},{"batb":[[0,3.8,6.15]],"batl":[[0,3.85,30.21]],"id":11374281},{"batb":[[0,13,22.36]],"batl":[[0,14,3.18]],"id":7454950}],"con":true},{"id":"1.128049377","rc":[{"batb":[[0,14.5,4.27]],"batl":[[0,15,5.14]],"id":10058605},{"batb":[[0,46,7.27]],"id":8775441},{"batb":[[0,180,3.65]],"batl":[[0,950,3]],"id":8884821},{"batb":[[0,32,8.57]],"id":267691},{"batb":[[0,9.2,8.44]],"batl":[[0,9.4,207.17]],"id":9048069},{"batb":[[0,5.3,193.99]],"batl":[[0,5.5,444.97]],"id":11248125},{"batb":[[0,11,32.18]],"batl":[],"id":10471417},{"batb":[[0,14.5,11.56]],"batl":[[0,15.5,108.78]],"id":9451258},{"batb":[[0,18.5,4.61]],"id":10391905},{"batb":[[0,15.5,8.05]],"batl":[],"id":9515258},{"batb":[[0,8.8,46.56]],"batl":[[0,9,2.66]],"id":10343385},{"batb":[],"batl":[[0,100,2.19]],"id":10558443},{"batb":[[0,9,660.04]],"batl":[[0,9.2,134.24]],"id":10058008},{"batb":[[0,40,13.01]],"id":7294269},{"batb":[[0,13,23.92]],"batl":[[0,13.5,6.88]],"id":11027938}],"con":true},{"id":"1.128049367","rc":[{"batb":[[0,50,6.11]],"id":4815581},{"batb":[[0,11.5,943.37]],"batl":[[0,12,829.31]],"id":7206255},{"batb":[[0,9.8,38.88]],"batl":[[0,10,86.54]],"id":8642566},{"batb":[[0,14.5,92.87]],"batl":[[0,15.5,50.93]],"id":7277932},{"batb":[[0,21,18.96]],"batl":[],"id":6563609},{"batb":[[0,34,70.29]],"id":9552307},{"batb":[[0,29,13.46]],"batl":[[0,30,4]],"id":5662979},{"batb":[[0,13.5,27.74]],"batl":[[0,14,229.28]],"id":4710727},{"batb":[[0,27,12.95]],"batl":[[0,28,5.4]],"id":9493948},{"batb":[[0,13,189.65]],"batl":[[0,13.5,52.16]],"id":7705524},{"batb":[[0,19.5,23.54]],"batl":[[0,21,15.57]],"id":8787768},{"batb":[[0,26,9.37]],"batl":[[0,27,7.75]],"id":8692300},{"batb":[[0,30,4]],"batl":[[0,34,6.24]],"id":7374498},{"batb":[[0,11,2.55]],"batl":[[0,11.5,21.4]],"id":9523098}],"con":true},{"id":"1.128076925","rc":[{"batb":[[0,6.8,33.18]],"batl":[[0,7,49.73]],"id":7170324},{"batb":[[0,1.17,423.55]],"batl":[[0,1.18,1580.16]],"id":8659866}],"con":true},{"id":"1.128076930","rc":[{"batb":[[0,4.8,12.76]],"batl":[[0,5,9.39]],"id":7294254},{"batb":[[0,1.5,22]],"batl":[[0,1.51,102.69]],"id":8943989},{"batb":[[0,7.6,19.33]],"batl":[[0,7.8,13.39]],"id":6670740}],"con":true},{"id":"1.128049382","rc":[{"batb":[[0,7.8,578.49]],"batl":[[0,8,468.56]],"id":10058445},{"batb":[[0,14.5,71.62]],"batl":[[0,15,30.76]],"id":5481502},{"batb":[[0,48,7.26]],"batl":[],"id":5833120},{"batb":[[0,36,92.22]],"id":8745116},{"batb":[[0,30,14.27]],"batl":[[0,32,78.52]],"id":8698309},{"batb":[[0,5.7,1244.49]],"batl":[[0,5.8,1034.97]],"id":11257764},{"batb":[[0,55,5.21]],"id":7642162},{"batl":[[0,65,10.86]],"id":6504875},{"batb":[[0,27,12.61]],"id":8950534},{"batb":[[0,8.8,16.74]],"batl":[[0,9,511.5]],"id":7882685},{"batb":[[0,85,4.45]],"id":8726678},{"batb":[[0,20,30.67]],"batl":[[0,21,66]],"id":7695604},{"batb":[[0,22,64.48]],"batl":[[0,23,19.06]],"id":12046378},{"batb":[[0,65,6.62]],"batl":[[0,75,2.21]],"id":7655374},{"batb":[[0,12.5,36.08]],"batl":[[0,13,45.74]],"id":8787766},{"batb":[[0,12.5,185.06]],"batl":[[0,13,278.38]],"id":10408352}],"con":true},{"id":"1.128049387","rc":[{"batb":[[0,11.5,6.51]],"id":8452035},{"batb":[[0,21,22.95]],"batl":[[0,25,2]],"id":5097176},{"batb":[[0,17,20.96]],"batl":[[0,18.5,5.7]],"id":7289894},{"batb":[[0,10,22.78]],"id":7767236},{"batb":[[0,28,10.45]],"batl":[],"id":7272347},{"batb":[[0,60,8.99]],"batl":[],"id":7331104},{"batb":[[0,28,7.52]],"id":4186666},{"batb":[[0,12,7.44]],"batl":[[0,12.5,53]],"id":10283027},{"batb":[[0,17.5,26.63]],"batl":[],"id":7214460},{"batb":[[0,55,4.46]],"batl":[],"id":8765242},{"batb":[[0,55,3.94]],"id":6177774},{"batb":[[0,11,77]],"batl":[[0,12,2.28]],"id":8692301}],"con":true},{"id":"1.128049372","rc":[{"batb":[[0,8.6,121.85]],"batl":[[0,9,27.53]],"id":9523111},{"batb":[],"batl":[[0,46,2.47]],"id":8565296},{"batb":[[0,16.5,31.09]],"batl":[[0,17,6.74]],"id":9486525},{"batb":[[0,11,26.71]],"batl":[],"id":464226},{"batb":[[0,11,21.74]],"id":6356569},{"batb":[[0,5.2,166.25]],"batl":[[0,5.3,550.84]],"id":6784147},{"batb":[[0,21,22.16]],"batl":[[0,22,3.09]],"id":10299538},{"batb":[[0,2.58,77.18]],"batl":[[0,2.6,910.9]],"id":2010040}],"con":true},{"id":"1.128076950","rc":[{"batb":[[0,20,25.83]],"batl":[[0,21,3.8]],"id":6996917},{"batb":[[0,16,11.38]],"batl":[[0,16.5,3.2]],"id":6835804},{"batb":[[0,7.6,931.15]],"batl":[[0,7.8,431.89]],"id":5982775},{"batb":[[0,24,20.53]],"id":8922697},{"batb":[[0,30,43.68]],"batl":[[0,40,4.98]],"id":6739276},{"batb":[[0,12.5,209.96]],"batl":[],"id":6842750},{"batl":[[0,8.2,552.77]],"id":9342038},{"batb":[[0,16,10.64]],"batl":[[0,16.5,3.88]],"id":6832508},{"batb":[[0,6.2,563.11]],"batl":[[0,6.6,514.93]],"id":8977686},{"batl":[[0,13,101.42]],"id":7104612},{"batb":[[0,4.9,342.55]],"batl":[],"id":5997638}],"con":true},{"id":"1.128049362","rc":[{"batb":[[0,65,9.61]],"batl":[],"id":11053364},{"batb":[],"batl":[[0,55,16.15]],"id":11378877},{"batb":[[0,17,81.67]],"batl":[[0,18,4.82]],"id":11461784},{"batb":[[0,12,17.24]],"batl":[],"id":11581022},{"batb":[[0,11,80.46]],"batl":[[0,11.5,8.5]],"id":11198792},{"batb":[[0,21,37.63]],"batl":[[0,23,37.95]],"id":11374258},{"batb":[[0,3.9,174.31]],"batl":[[0,3.95,355.39]],"id":11765200},{"batb":[[0,16,86.36]],"batl":[[0,17,5.22]],"id":11208742},{"batb":[[0,13.5,20.16]],"batl":[[0,14.5,20.09]],"id":11432465},{"batb":[[0,48,4.65]],"id":11404382},{"batb":[[0,55,13.1]],"id":11235758},{"batb":[[0,30,10.32]],"batl":[],"id":36161},{"batb":[[0,28,5.18]],"id":11150037},{"batb":[[0,17,63.56]],"batl":[[0,18,32.07]],"id":11466744},{"batb":[[0,27,5.13]],"batl":[[0,29,3.52]],"id":11034952}],"con":true},{"id":"1.128076945","rc":[{"batb":[[0,14.5,11.12]],"batl":[[0,16.5,2]],"id":6672364},{"batb":[[0,5.9,6.36]],"batl":[[0,6,196.34]],"id":7629108},{"batb":[[0,3.9,23.29]],"id":8720215},{"batb":[[0,36,3.3]],"batl":[[0,42,2.34]],"id":7994997},{"batb":[[0,4.8,12.99]],"batl":[[0,4.9,3.17]],"id":10096988}],"con":true},{"id":"1.128076940","rc":[{"batb":[[0,3.7,547.81]],"batl":[[0,3.75,261.16]],"id":10477270},{"batb":[[0,23,9.75]],"batl":[[0,25,3.57]],"id":7565462},{"batb":[],"batl":[[0,5.3,20.12]],"id":10449543},{"batl":[[0,170,3.75]],"id":5099545},{"batb":[[0,2.32,183.68]],"batl":[[0,2.36,115.96]],"id":10400671},{"batb":[[0,15.5,4.74]],"batl":[[0,16.5,9.1]],"id":5623014}],"con":true},{"id":"1.128076955","rc":[{"batb":[[0,5.1,11.5]],"batl":[[0,5.2,13.29]],"id":5779349},{"batl":[[0,15.5,6.04]],"id":11122962},{"batb":[[0,30,4.59]],"id":29796},{"batb":[[0,11.5,6.21]],"batl":[],"id":10477261}],"con":true},{"id":"1.128076935","rc":[{"batb":[[0,3.3,82.49]],"batl":[[0,3.35,21.89]],"id":10709204},{"batb":[[0,3.4,36.51]],"batl":[[0,3.45,33.04]],"id":7862942}],"con":true},{"id":"1.128049352","marketDefinition":{"bspMarket":true,"turnInPlayEnabled":true,"persistenceEnabled":true,"marketBaseRate":5,"eventId":"28002263","eventTypeId":"7","numberOfWinners":1,"bettingType":"ODDS","marketType":"WIN","marketTime":"2016-11-05T12:10:00.000Z","suspendTime":"2016-11-05T12:10:00.000Z","bspReconciled":true,"complete":true,"inPlay":true,"crossMatching":true,"runnersVoidable":false,"numberOfActiveRunners":12,"betDelay":1,"status":"SUSPENDED","runners":[{"adjustmentFactor":20.408,"status":"ACTIVE","sortPriority":1,"bsp":3.9161586776799058,"id":12055992},{"adjustmentFactor":15.252,"status":"ACTIVE","sortPriority":2,"bsp":6,"id":11892059},{"adjustmentFactor":14.116,"status":"ACTIVE","sortPriority":3,"bsp":7.788580259833943,"id":11822601},{"adjustmentFactor":13.5,"status":"ACTIVE","sortPriority":4,"bsp":8.2,"id":11944672},{"adjustmentFactor":12.943,"status":"ACTIVE","sortPriority":5,"bsp":13,"id":11085661},{"adjustmentFactor":10.406,"status":"ACTIVE","sortPriority":6,"bsp":7.798203607578399,"id":116818},{"adjustmentFactor":4.757,"status":"ACTIVE","sortPriority":7,"bsp":20.939782066147025,"id":11930474},{"adjustmentFactor":3.445,"status":"ACTIVE","sortPriority":8,"bsp":22.095759979571486,"id":12055990},{"adjustmentFactor":2.775,"status":"ACTIVE","sortPriority":9,"bsp":55.689639215413486,"id":12055991},{"adjustmentFactor":0.799,"status":"ACTIVE","sortPriority":10,"bsp":150,"id":12055993},{"adjustmentFactor":0.799,"status":"ACTIVE","sortPriority":11,"bsp":95.49626164343442,"id":11985855},{"adjustmentFactor":0.799,"status":"ACTIVE","sortPriority":12,"bsp":66.31727241935673,"id":11975741}],"regulators":["MR_INT"],"venue":"Doncaster","countryCode":"GB","discountAllowed":true,"timezone":"Europe/London","openDate":"2016-11-05T12:10:00.000Z","version":1484342502},"rc":[{"batb":[[0,21,2]],"batl":[[0,0,0]],"id":11822601},{"batb":[[0,0,0]],"batl":[[0,1.01,71.19]],"id":11944672},{"batb":[[0,34,8.61]],"batl":[[0,0,0]],"id":11975741},{"batb":[[0,1000,43.25]],"batl":[[0,0,0]],"id":11985855},{"batb":[[0,29,2.07]],"batl":[[0,0,0]],"id":116818},{"batb":[[0,1000,4.25]],"batl":[[0,0,0]],"id":12055991},{"batb":[[0,21,2.17]],"batl":[[0,0,0]],"id":11930474},{"batb":[[0,21,2]],"batl":[[0,0,0]],"id":12055990},{"batb":[[0,1000,4.25]],"batl":[[0,0,0]],"id":12055993},{"batb":[[0,21,2]],"batl":[[0,0,0]],"id":12055992},{"batb":[[0,21,2]],"batl":[[0,0,0]],"id":11892059},{"batb":[[0,21,2.17]],"batl":[[0,0,0]],"id":11085661}],"con":true}]}
