    "msg": "{\"channel\":\"order_book:1\",\"offset\":6962211,\"order_book\":{\"code\":0,\"asks\":[{\"price\":\"92923.3\",\"size\":\"0.00000\"},{\"price\":\"92949.6\",\"size\":\"0.36697\"},{\"price\":\"92955.9\",\"size\":\"0.00214\"}],\"bids\":[{\"price\":\"92890.0\",\"size\":\"0.00214\"},{\"price\":\"92889.9\",\"size\":\"0.00214\"}],\"offset\":6962211,\"nonce\":3691008464},\"timestamp\":1765394042124,\"type\":\"update/order_book\"}"
    "msg": "{\"channel\":\"order_book:1\",\"offset\":6962212,\"order_book\":{\"code\":0,\"asks\":[{\"price\":\"92926.3\",\"size\":\"0.00000\"},{\"price\":\"92939.0\",\"size\":\"0.00000\"},{\"price\":\"92951.4\",\"size\":\"0.58345\"}],\"bids\":[{\"price\":\"92908.4\",\"size\":\"0.00000\"},{\"price\":\"92905.8\",\"size\":\"0.09807\"},{\"price\":\"92876.4\",\"size\":\"0.00000\"}],\"offset\":6962212,\"nonce\":3691008465},\"timestamp\":1765394042131,\"type\":\"update/order_book\"}"
    "msg": "{\"channel\":\"order_book:1\",\"offset\":6962213,\"order_book\":{\"code\":0,\"asks\":[{\"price\":\"92931.8\",\"size\":\"0.00000\"}],\"bids\":[],\"offset\":6962213,\"nonce\":3691008466},\"timestamp\":1765394042135,\"type\":\"update/order_book\"}"
    "msg": "{\"channel\":\"order_book:1\",\"offset\":6962215,\"order_book\":{\"code\":0,\"asks\":[{\"price\":\"92922.5\",\"size\":\"0.02120\"},{\"price\":\"92933.0\",\"size\":\"0.00000\"}],\"bids\":[{\"price\":\"92899.8\",\"size\":\"0.10780\"},{\"price\":\"92896.0\",\"size\":\"0.00000\"},{\"price\":\"92857.9\",\"size\":\"0.00000\"}],\"offset\":6962215,\"nonce\":3691008470},\"timestamp\":1765394042149,\"type\":\"update/order_book\"}"
    "msg": "{\"channel\":\"order_book:1\",\"offset\":6962216,\"order_book\":{\"code\":0,\"asks\":[{\"price\":\"92926.4\",\"size\":\"0.00020\"}],\"bids\":[],\"offset\":6962216,\"nonce\":3691008472},\"timestamp\":1765394042156,\"type\":\"update/order_book\"}"
    "msg": "{\"channel\":\"order_book:1\",\"offset\":6962217,\"order_book\":{\"code\":0,\"asks\":[],\"bids\":[{\"price\":\"92899.7\",\"size\":\"0.50000\"}],\"offset\":6962217,\"nonce\":3691008473},\"timestamp\":1765394042163,\"type\":\"update/order_book\"}"
    "msg": "{\"channel\":\"order_book:1\",\"offset\":6962218,\"order_book\":{\"code\":0,\"asks\":[],\"bids\":[{\"price\":\"92917.6\",\"size\":\"3.03275\"},{\"price\":\"92852.3\",\"size\":\"0.00000\"}],\"offset\":6962218,\"nonce\":3691008475},\"timestamp\":1765394042167,\"type\":\"update/order_book\"}"
    "msg": "{\"channel\":\"order_book:1\",\"offset\":6962219,\"order_book\":{\"code\":0,\"asks\":[{\"price\":\"92931.0\",\"size\":\"0.00000\"},{\"price\":\"92932.3\",\"size\":\"1.07758\"},{\"price\":\"92934.8\",\"size\":\"0.00000\"},{\"price\":\"93022.3\",\"size\":\"0.00000\"},{\"price\":\"93023.9\",\"size\":\"2.29466\"},{\"price\":\"93042.5\",\"size\":\"0.52400\"},{\"price\":\"93283.9\",\"size\":\"1.04801\"}],\"bids\":[{\"price\":\"92914.5\",\"size\":\"0.00000\"},{\"price\":\"92914.3\",\"size\":\"0.10780\"},{\"price\":\"92910.8\",\"size\":\"0.00000\"},{\"price\":\"92908.6\",\"size\":\"0.00000\"},{\"price\":\"92896.5\",\"size\":\"0.00108\"},{\"price\":\"92896.4\",\"size\":\"0.00000\"},{\"price\":\"92859.2\",\"size\":\"0.00000\"}],\"offset\":6962219,\"nonce\":3691008476},\"timestamp\":1765394042172,\"type\":\"update/order_book\"}"
    "msg": "{\"channel\":\"order_book:1\",\"offset\":6962220,\"order_book\":{\"code\":0,\"asks\":[{\"price\":\"92932.1\",\"size\":\"0.10780\"}],\"bids\":[{\"price\":\"92920.5\",\"size\":\"0.38767\"},{\"price\":\"92913.7\",\"size\":\"0.00000\"},{\"price\":\"92901.9\",\"size\":\"0.00000\"},{\"price\":\"92901.7\",\"size\":\"6.41734\"},{\"price\":\"92871.7\",\"size\":\"0.00000\"}],\"offset\":6962220,\"nonce\":3691008477},\"timestamp\":1765394042180,\"type\":\"update/order_book\"}"
    "msg": "{\"channel\":\"order_book:1\",\"offset\":6962221,\"order_book\":{\"code\":0,\"asks\":[{\"price\":\"92925.5\",\"size\":\"0.00000\"},{\"price\":\"92931.7\",\"size\":\"0.00000\"},{\"price\":\"92935.7\",\"size\":\"0.00500\"}],\"bids\":[{\"price\":\"92908.7\",\"size\":\"0.01076\"}],\"offset\":6962221,\"nonce\":3691008478},\"timestamp\":1765394042188,\"type\":\"update/order_book\"}"
    "msg": "{\"channel\":\"order_book:1\",\"offset\":6962222,\"order_book\":{\"code\":0,\"asks\":[{\"price\":\"92961.6\",\"size\":\"0.05238\"},{\"price\":\"92974.1\",\"size\":\"0.10476\"}],\"bids\":[{\"price\":\"92917.0\",\"size\":\"0.02905\"},{\"price\":\"92902.8\",\"size\":\"0.00000\"},{\"price\":\"92902.2\",\"size\":\"0.11088\"},{\"price\":\"92873.7\",\"size\":\"0.01077\"}],\"offset\":6962222,\"nonce\":3691008479},\"timestamp\":1765394042191,\"type\":\"update/order_book\"}"
    "msg": "{\"channel\":\"order_book:1\",\"offset\":6962223,\"order_book\":{\"code\":0,\"asks\":[{\"price\":\"92926.4\",\"size\":\"0.00000\"},{\"price\":\"92927.2\",\"size\":\"0.00000\"},{\"price\":\"92932.8\",\"size\":\"0.00000\"},{\"price\":\"92943.2\",\"size\":\"0.00000\"}],\"bids\":[{\"price\":\"92897.3\",\"size\":\"0.00000\"}],\"offset\":6962223,\"nonce\":3691008480},\"timestamp\":1765394042194,\"type\":\"update/order_book\"}"
    "msg": "{\"channel\":\"order_book:1\",\"offset\":6962224,\"order_book\":{\"code\":0,\"asks\":[{\"price\":\"92922.5\",\"size\":\"0.00000\"}],\"bids\":[{\"price\":\"92922.4\",\"size\":\"0.00500\"},{\"price\":\"92906.7\",\"size\":\"0.02152\"},{\"price\":\"92851.9\",\"size\":\"0.00000\"}],\"offset\":6962224,\"nonce\":3691008482},\"timestamp\":1765394042197,\"type\":\"update/order_book\"}"
    "msg": "{\"channel\":\"order_book:1\",\"offset\":6962225,\"order_book\":{\"code\":0,\"asks\":[{\"price\":\"92927.4\",\"size\":\"0.00000\"},{\"price\":\"92932.1\",\"size\":\"0.00000\"}],\"bids\":[{\"price\":\"92922.4\",\"size\":\"0.02519\"},{\"price\":\"92908.7\",\"size\":\"0.00000\"}],\"offset\":6962225,\"nonce\":3691008483},\"timestamp\":1765394042203,\"type\":\"update/order_book\"}"
    "msg": "{\"channel\":\"order_book:1\",\"offset\":6962226,\"order_book\":{\"code\":0,\"asks\":[],\"bids\":[{\"price\":\"92922.4\",\"size\":\"0.04001\"},{\"price\":\"92916.3\",\"size\":\"0.00215\"},{\"price\":\"92912.4\",\"size\":\"0.00000\"}],\"offset\":6962226,\"nonce\":3691008484},\"timestamp\":1765394042206,\"type\":\"update/order_book\"}"
    "msg": "{\"channel\":\"order_book:1\",\"offset\":6962227,\"order_book\":{\"code\":0,\"asks\":[{\"price\":\"93023.9\",\"size\":\"0.00000\"},{\"price\":\"93025.1\",\"size\":\"0.00000\"},{\"price\":\"93025.4\",\"size\":\"2.29462\"},{\"price\":\"93032.1\",\"size\":\"0.00000\"},{\"price\":\"93032.4\",\"size\":\"3.04171\"},{\"price\":\"93039.4\",\"size\":\"7.20404\"}],\"bids\":[{\"price\":\"92901.7\",\"size\":\"6.41822\"},{\"price\":\"92894.7\",\"size\":\"6.52715\"},{\"price\":\"92885.7\",\"size\":\"0.00000\"}],\"offset\":6962227,\"nonce\":3691008485},\"timestamp\":1765394042209,\"type\":\"update/order_book\"}"
    "msg": "{\"channel\":\"order_book:1\",\"offset\":6962228,\"order_book\":{\"code\":0,\"asks\":[{\"price\":\"92955.9\",\"size\":\"0.05490\"},{\"price\":\"92982.3\",\"size\":\"0.00000\"}],\"bids\":[{\"price\":\"92922.4\",\"size\":\"0.99424\"},{\"price\":\"92916.5\",\"size\":\"0.08081\"},{\"price\":\"92906.7\",\"size\":\"0.00000\"},{\"price\":\"92887.7\",\"size\":\"15.45904\"},{\"price\":\"92880.9\",\"size\":\"0.05145\"},{\"price\":\"92878.8\",\"size\":\"0.00000\"},{\"price\":\"92835.4\",\"size\":\"0.00000\"}],\"offset\":6962228,\"nonce\":3691008486},\"timestamp\":1765394042219,\"type\":\"update/order_book\"}"
    "msg": "{\"channel\":\"order_book:1\",\"offset\":6962229,\"order_book\":{\"code\":0,\"asks\":[{\"price\":\"92938.4\",\"size\":\"0.00000\"}],\"bids\":[{\"price\":\"92813.4\",\"size\":\"0.00000\"}],\"offset\":6962229,\"nonce\":3691008487},\"timestamp\":1765394042226,\"type\":\"update/order_book\"}"
    "msg": "{\"channel\":\"order_book:1\",\"offset\":6962230,\"order_book\":{\"code\":0,\"asks\":[],\"bids\":[{\"price\":\"92922.4\",\"size\":\"2.06152\"},{\"price\":\"92920.5\",\"size\":\"1.26744\"},{\"price\":\"92914.8\",\"size\":\"0.00201\"},{\"price\":\"92908.8\",\"size\":\"2.69396\"},{\"price\":\"92906.8\",\"size\":\"0.02152\"},{\"price\":\"92876.8\",\"size\":\"0.05235\"}],\"offset\":6962230,\"nonce\":3691008488},\"timestamp\":1765394042228,\"type\":\"update/order_book\"}"
    "msg": "{\"channel\":\"order_book:1\",\"offset\":6962231,\"order_book\":{\"code\":0,\"asks\":[{\"price\":\"92930.4\",\"size\":\"0.02834\"},{\"price\":\"92936.9\",\"size\":\"2.69396\"}],\"bids\":[{\"price\":\"92922.4\",\"size\":\"3.02092\"},{\"price\":\"92900.3\",\"size\":\"0.00108\"},{\"price\":\"92896.5\",\"size\":\"0.00000\"},{\"price\":\"92894.2\",\"size\":\"0.00500\"},{\"price\":\"92883.7\",\"size\":\"0.00000\"}],\"offset\":6962231,\"nonce\":3691008489},\"timestamp\":1765394042234,\"type\":\"update/order_book\"}"
    "msg": "{\"channel\":\"order_book:1\",\"offset\":6962232,\"order_book\":{\"code\":0,\"asks\":[{\"price\":\"92931.7\",\"size\":\"0.00020\"},{\"price\":\"92945.3\",\"size\":\"0.00305\"},{\"price\":\"92946.0\",\"size\":\"0.00000\"},{\"price\":\"92950.0\",\"size\":\"0.00000\"}],\"bids\":[],\"offset\":6962232,\"nonce\":3691008490},\"timestamp\":1765394042236,\"type\":\"update/order_book\"}"
    "msg": "{\"channel\":\"order_book:1\",\"offset\":6962233,\"order_book\":{\"code\":0,\"asks\":[{\"price\":\"92930.6\",\"size\":\"0.10764\"},{\"price\":\"92935.7\",\"size\":\"0.04265\"},{\"price\":\"92947.1\",\"size\":\"0.02818\"}],\"bids\":[{\"price\":\"92910.6\",\"size\":\"0.01076\"},{\"price\":\"92901.6\",\"size\":\"0.00000\"},{\"price\":\"92899.4\",\"size\":\"0.91337\"},{\"price\":\"92877.0\",\"size\":\"0.30345\"}],\"offset\":6962233,\"nonce\":3691008491},\"timestamp\":1765394042241,\"type\":\"update/order_book\"}"
    "msg": "{\"channel\":\"order_book:1\",\"offset\":6962234,\"order_book\":{\"code\":0,\"asks\":[{\"price\":\"92942.5\",\"size\":\"0.00000\"}],\"bids\":[{\"price\":\"92899.4\",\"size\":\"0.00000\"}],\"offset\":6962234,\"nonce\":3691008492},\"timestamp\":1765394042246,\"type\":\"update/order_book\"}"
    "msg": "{\"channel\":\"order_book:1\",\"offset\":6962235,\"order_book\":{\"code\":0,\"asks\":[],\"bids\":[{\"price\":\"92905.5\",\"size\":\"4.61452\"},{\"price\":\"92902.3\",\"size\":\"0.10780\"},{\"price\":\"92901.7\",\"size\":\"1.80449\"},{\"price\":\"92899.8\",\"size\":\"0.00000\"},{\"price\":\"92899.7\",\"size\":\"0.00000\"}],\"offset\":6962235,\"nonce\":3691008493},\"timestamp\":1765394042249,\"type\":\"update/order_book\"}"
    "msg": "{\"channel\":\"order_book:1\",\"offset\":6962236,\"order_book\":{\"code\":0,\"asks\":[{\"price\":\"92930.4\",\"size\":\"0.00000\"}],\"bids\":[{\"price\":\"92920.6\",\"size\":\"0.03765\"},{\"price\":\"92910.6\",\"size\":\"0.00000\"}],\"offset\":6962236,\"nonce\":3691008495},\"timestamp\":1765394042261,\"type\":\"update/order_book\"}"
    "msg": "{\"channel\":\"order_book:1\",\"offset\":6962237,\"order_book\":{\"code\":0,\"asks\":[{\"price\":\"93007.9\",\"size\":\"0.85206\"}],\"bids\":[{\"price\":\"92917.6\",\"size\":\"0.87830\"},{\"price\":\"92917.0\",\"size\":\"0.00000\"},{\"price\":\"92885.1\",\"size\":\"0.00000\"}],\"offset\":6962237,\"nonce\":3691008496},\"timestamp\":1765394042264,\"type\":\"update/order_book\"}"
    "msg": "{\"channel\":\"order_book:1\",\"offset\":6962238,\"order_book\":{\"code\":0,\"asks\":[{\"price\":\"92938.3\",\"size\":\"0.00000\"},{\"price\":\"92961.8\",\"size\":\"0.33727\"}],\"bids\":[{\"price\":\"92922.4\",\"size\":\"1.94334\"},{\"price\":\"92919.6\",\"size\":\"0.02905\"},{\"price\":\"92890.1\",\"size\":\"0.00000\"},{\"price\":\"92859.3\",\"size\":\"0.10553\"},{\"price\":\"92838.9\",\"size\":\"0.83041\"}],\"offset\":6962238,\"nonce\":3691008497},\"timestamp\":1765394042269,\"type\":\"update/order_book\"}"
    "msg": "{\"channel\":\"order_book:1\",\"offset\":6962239,\"order_book\":{\"code\":0,\"asks\":[{\"price\":\"92931.7\",\"size\":\"0.21521\"}],\"bids\":[{\"price\":\"92878.5\",\"size\":\"0.00000\"},{\"price\":\"92873.7\",\"size\":\"0.00000\"}],\"offset\":6962239,\"nonce\":3691008498},\"timestamp\":1765394042276,\"type\":\"update/order_book\"}"
    "msg": "{\"channel\":\"order_book:1\",\"offset\":6962240,\"order_book\":{\"code\":0,\"asks\":[{\"price\":\"92950.5\",\"size\":\"0.00000\"}],\"bids\":[{\"price\":\"92905.8\",\"size\":\"0.00000\"}],\"offset\":6962240,\"nonce\":3691008499},\"timestamp\":1765394042280,\"type\":\"update/order_book\"}"
    "msg": "{\"channel\":\"order_book:1\",\"offset\":6962241,\"order_book\":{\"code\":0,\"asks\":[{\"price\":\"92934.7\",\"size\":\"0.05380\"},{\"price\":\"92940.1\",\"size\":\"0.00000\"},{\"price\":\"92957.5\",\"size\":\"0.00000\"}],\"bids\":[{\"price\":\"92923.5\",\"size\":\"0.38767\"},{\"price\":\"92910.6\",\"size\":\"0.01076\"},{\"price\":\"92899.2\",\"size\":\"0.05382\"},{\"price\":\"92864.4\",\"size\":\"0.00000\"},{\"price\":\"92854.6\",\"size\":\"0.00000\"},{\"price\":\"92838.4\",\"size\":\"0.00000\"},{\"price\":\"92816.3\",\"size\":\"0.00000\"}],\"offset\":6962241,\"nonce\":3691008500},\"timestamp\":1765394042281,\"type\":\"update/order_book\"}"
    "msg": "{\"channel\":\"order_book:1\",\"offset\":6962242,\"order_book\":{\"code\":0,\"asks\":[{\"price\":\"92932.6\",\"size\":\"0.10780\"},{\"price\":\"92942.2\",\"size\":\"0.08808\"},{\"price\":\"92945.3\",\"size\":\"0.00000\"},{\"price\":\"92950.0\",\"size\":\"0.11088\"},{\"price\":\"92953.6\",\"size\":\"0.05287\"},{\"price\":\"93025.4\",\"size\":\"0.00000\"},{\"price\":\"93026.8\",\"size\":\"2.29458\"}],\"bids\":[{\"price\":\"92905.5\",\"size\":\"4.61539\"},{\"price\":\"92875.0\",\"size\":\"0.01077\"},{\"price\":\"92773.2\",\"size\":\"0.41093\"},{\"price\":\"92741.3\",\"size\":\"0.77349\"}],\"offset\":6962242,\"nonce\":3691008501},\"timestamp\":1765394042288,\"type\":\"update/order_book\"}"
    "msg": "{\"channel\":\"order_book:1\",\"offset\":6962243,\"order_book\":{\"code\":0,\"asks\":[{\"price\":\"92932.6\",\"size\":\"0.00000\"}],\"bids\":[{\"price\":\"92917.3\",\"size\":\"0.10801\"},{\"price\":\"92914.3\",\"size\":\"0.00000\"},{\"price\":\"92914.0\",\"size\":\"0.04406\"},{\"price\":\"92908.2\",\"size\":\"0.00000\"}],\"offset\":6962243,\"nonce\":3691008502},\"timestamp\":1765394042297,\"type\":\"update/order_book\"}"
    "msg": "{\"channel\":\"order_book:1\",\"offset\":6962244,\"order_book\":{\"code\":0,\"asks\":[{\"price\":\"92933.6\",\"size\":\"0.02834\"}],\"bids\":[{\"price\":\"92910.6\",\"size\":\"0.00000\"},{\"price\":\"92875.0\",\"size\":\"0.00000\"}],\"offset\":6962244,\"nonce\":3691008503},\"timestamp\":1765394042298,\"type\":\"update/order_book\"}"
    "msg": "{\"channel\":\"order_book:1\",\"offset\":6962245,\"order_book\":{\"code\":0,\"asks\":[],\"bids\":[{\"price\":\"92922.4\",\"size\":\"1.93927\"},{\"price\":\"92914.8\",\"size\":\"0.00000\"},{\"price\":\"92893.6\",\"size\":\"0.00000\"}],\"offset\":6962245,\"nonce\":3691008504},\"timestamp\":1765394042302,\"type\":\"update/order_book\"}"
    "msg": "{\"channel\":\"order_book:1\",\"offset\":6962246,\"order_book\":{\"code\":0,\"asks\":[{\"price\":\"92935.6\",\"size\":\"0.00000\"}],\"bids\":[{\"price\":\"92922.4\",\"size\":\"1.91727\"},{\"price\":\"92901.4\",\"size\":\"0.00108\"},{\"price\":\"92900.3\",\"size\":\"0.00000\"},{\"price\":\"92893.7\",\"size\":\"0.00000\"},{\"price\":\"92861.4\",\"size\":\"0.00000\"}],\"offset\":6962246,\"nonce\":3691008505},\"timestamp\":1765394042307,\"type\":\"update/order_book\"}"
    "msg": "{\"channel\":\"order_book:1\",\"offset\":6962247,\"order_book\":{\"code\":0,\"asks\":[{\"price\":\"92933.6\",\"size\":\"0.00000\"},{\"price\":\"92945.1\",\"size\":\"0.00000\"}],\"bids\":[{\"price\":\"92923.6\",\"size\":\"0.82223\"},{\"price\":\"92923.5\",\"size\":\"1.27479\"},{\"price\":\"92919.6\",\"size\":\"0.00000\"},{\"price\":\"92904.7\",\"size\":\"0.02815\"},{\"price\":\"92902.9\",\"size\":\"0.11979\"},{\"price\":\"92886.5\",\"size\":\"0.00000\"},{\"price\":\"92875.9\",\"size\":\"0.01077\"}],\"offset\":6962247,\"nonce\":3691008506},\"timestamp\":1765394042310,\"type\":\"update/order_book\"}"
    "msg": "{\"channel\":\"order_book:1\",\"offset\":6962248,\"order_book\":{\"code\":0,\"asks\":[{\"price\":\"92955.7\",\"size\":\"0.00000\"}],\"bids\":[{\"price\":\"92908.8\",\"size\":\"0.00000\"},{\"price\":\"92895.8\",\"size\":\"0.11629\"},{\"price\":\"92895.5\",\"size\":\"0.00000\"},{\"price\":\"92869.1\",\"size\":\"0.00000\"}],\"offset\":6962248,\"nonce\":3691008507},\"timestamp\":1765394042315,\"type\":\"update/order_book\"}"
    "msg": "{\"channel\":\"order_book:1\",\"offset\":6962249,\"order_book\":{\"code\":0,\"asks\":[{\"price\":\"92934.7\",\"size\":\"0.00000\"},{\"price\":\"92935.6\",\"size\":\"0.22225\"},{\"price\":\"93026.8\",\"size\":\"0.00000\"},{\"price\":\"93027.4\",\"size\":\"2.29457\"}],\"bids\":[{\"price\":\"92921.3\",\"size\":\"1.07758\"},{\"price\":\"92921.1\",\"size\":\"2.15445\"},{\"price\":\"92899.2\",\"size\":\"0.00000\"},{\"price\":\"92888.6\",\"size\":\"8.07918\"}],\"offset\":6962249,\"nonce\":3691008508},\"timestamp\":1765394042318,\"type\":\"update/order_book\"}"
    "msg": "{\"channel\":\"order_book:1\",\"offset\":6962250,\"order_book\":{\"code\":0,\"asks\":[{\"price\":\"92947.5\",\"size\":\"0.00304\"}],\"bids\":[{\"price\":\"92907.6\",\"size\":\"4.61640\"},{\"price\":\"92905.5\",\"size\":\"0.00000\"},{\"price\":\"92883.1\",\"size\":\"0.11759\"}],\"offset\":6962250,\"nonce\":3691008509},\"timestamp\":1765394042320,\"type\":\"update/order_book\"}"
    "msg": "{\"channel\":\"order_book:1\",\"offset\":6962251,\"order_book\":{\"code\":0,\"asks\":[],\"bids\":[{\"price\":\"92912.1\",\"size\":\"0.39843\"},{\"price\":\"92908.2\",\"size\":\"0.02628\"},{\"price\":\"92890.1\",\"size\":\"0.10778\"}],\"offset\":6962251,\"nonce\":3691008511},\"timestamp\":1765394042329,\"type\":\"update/order_book\"}"
    "msg": "{\"channel\":\"order_book:1\",\"offset\":6962252,\"order_book\":{\"code\":0,\"asks\":[{\"price\":\"92985.5\",\"size\":\"0.34896\"}],\"bids\":[{\"price\":\"92901.7\",\"size\":\"0.00000\"},{\"price\":\"92892.8\",\"size\":\"0.04301\"},{\"price\":\"92866.8\",\"size\":\"0.41942\"}],\"offset\":6962252,\"nonce\":3691008512},\"timestamp\":1765394042334,\"type\":\"update/order_book\"}"
    "msg": "{\"channel\":\"order_book:1\",\"offset\":6962253,\"order_book\":{\"code\":0,\"asks\":[{\"price\":\"92935.6\",\"size\":\"0.00000\"},{\"price\":\"92955.3\",\"size\":\"0.12064\"},{\"price\":\"92966.1\",\"size\":\"0.28101\"}],\"bids\":[{\"price\":\"92923.6\",\"size\":\"1.73042\"},{\"price\":\"92914.4\",\"size\":\"0.00000\"},{\"price\":\"92912.1\",\"size\":\"0.38767\"},{\"price\":\"92881.7\",\"size\":\"0.28581\"},{\"price\":\"92842.9\",\"size\":\"0.85744\"}],\"offset\":6962253,\"nonce\":3691008513},\"timestamp\":1765394042340,\"type\":\"update/order_book\"}"
    "msg": "{\"channel\":\"order_book:1\",\"offset\":6962254,\"order_book\":{\"code\":0,\"asks\":[{\"price\":\"92934.3\",\"size\":\"0.10780\"},{\"price\":\"92950.0\",\"size\":\"0.00000\"}],\"bids\":[{\"price\":\"92919.0\",\"size\":\"0.10780\"},{\"price\":\"92918.7\",\"size\":\"0.10780\"},{\"price\":\"92917.3\",\"size\":\"0.00021\"},{\"price\":\"92910.2\",\"size\":\"0.00000\"}],\"offset\":6962254,\"nonce\":3691008515},\"timestamp\":1765394042350,\"type\":\"update/order_book\"}"
    "msg": "{\"channel\":\"order_book:1\",\"offset\":6962255,\"order_book\":{\"code\":0,\"asks\":[{\"price\":\"92937.3\",\"size\":\"0.10760\"}],\"bids\":[{\"price\":\"92912.7\",\"size\":\"0.09157\"},{\"price\":\"92903.9\",\"size\":\"0.10780\"},{\"price\":\"92902.6\",\"size\":\"0.00108\"},{\"price\":\"92902.3\",\"size\":\"0.00000\"},{\"price\":\"92901.4\",\"size\":\"0.00000\"},{\"price\":\"92892.9\",\"size\":\"1.08034\"}],\"offset\":6962255,\"nonce\":3691008516},\"timestamp\":1765394042354,\"type\":\"update/order_book\"}"
    "msg": "{\"channel\":\"order_book:1\",\"offset\":6962258,\"order_book\":{\"code\":0,\"asks\":[{\"price\":\"92936.7\",\"size\":\"0.05380\"},{\"price\":\"92960.3\",\"size\":\"0.00000\"},{\"price\":\"92982.9\",\"size\":\"0.39924\"}],\"bids\":[{\"price\":\"92903.8\",\"size\":\"2.69396\"},{\"price\":\"92901.2\",\"size\":\"0.05382\"}],\"offset\":6962258,\"nonce\":3691008525},\"timestamp\":1765394042374,\"type\":\"update/order_book\"}"
    "msg": "{\"channel\":\"order_book:1\",\"offset\":6962259,\"order_book\":{\"code\":0,\"asks\":[{\"price\":\"92935.2\",\"size\":\"0.02834\"}],\"bids\":[],\"offset\":6962259,\"nonce\":3691008527},\"timestamp\":1765394042378,\"type\":\"update/order_book\"}"
    "msg": "{\"channel\":\"order_book:1\",\"offset\":6962260,\"order_book\":{\"code\":0,\"asks\":[{\"price\":\"92953.9\",\"size\":\"0.00000\"},{\"price\":\"92974.6\",\"size\":\"0.00538\"}],\"bids\":[{\"price\":\"92836.6\",\"size\":\"0.00538\"},{\"price\":\"92815.8\",\"size\":\"0.00000\"}],\"offset\":6962260,\"nonce\":3691008530},\"timestamp\":1765394042386,\"type\":\"update/order_book\"}"
    "msg": "{\"channel\":\"order_book:1\",\"offset\":6962261,\"order_book\":{\"code\":0,\"asks\":[],\"bids\":[{\"price\":\"92926.4\",\"size\":\"0.83208\"},{\"price\":\"92926.3\",\"size\":\"1.29589\"},{\"price\":\"92912.7\",\"size\":\"0.09157\"}],\"offset\":6962261,\"nonce\":3691008532},\"timestamp\":1765394042389,\"type\":\"update/order_book\"}"
    "msg": "{\"channel\":\"order_book:1\",\"offset\":6962262,\"order_book\":{\"code\":0,\"asks\":[{\"price\":\"92951.3\",\"size\":\"0.11088\"},{\"price\":\"93039.6\",\"size\":\"0.00000\"},{\"price\":\"93053.4\",\"size\":\"0.00000\"},{\"price\":\"93246.6\",\"size\":\"14.93843\"},{\"price\":\"93260.4\",\"size\":\"14.93843\"}],\"bids\":[],\"offset\":6962262,\"nonce\":3691008535},\"timestamp\":1765394042397,\"type\":\"update/order_book\"}"
    "msg": "{\"channel\":\"order_book:1\",\"offset\":6962263,\"order_book\":{\"code\":0,\"asks\":[{\"price\":\"92930.6\",\"size\":\"0.00000\"},{\"price\":\"92930.7\",\"size\":\"0.00000\"},{\"price\":\"92931.7\",\"size\":\"0.10371\"}],\"bids\":[{\"price\":\"92921.7\",\"size\":\"0.02905\"},{\"price\":\"92908.1\",\"size\":\"1.34379\"},{\"price\":\"92829.7\",\"size\":\"0.31922\"},{\"price\":\"92803.8\",\"size\":\"0.00000\"}],\"offset\":6962263,\"nonce\":3691008538},\"timestamp\":1765394042411,\"type\":\"update/order_book\"}"
    "msg": "{\"channel\":\"order_book:1\",\"offset\":6962264,\"order_book\":{\"code\":0,\"asks\":[],\"bids\":[{\"price\":\"92917.6\",\"size\":\"0.00000\"}],\"offset\":6962264,\"nonce\":3691008539},\"timestamp\":1765394042415,\"type\":\"update/order_book\"}"
    "msg": "{\"channel\":\"order_book:1\",\"offset\":6962265,\"order_book\":{\"code\":0,\"asks\":[{\"price\":\"92931.1\",\"size\":\"0.00021\"},{\"price\":\"92972.4\",\"size\":\"0.00000\"},{\"price\":\"92999.3\",\"size\":\"0.31921\"}],\"bids\":[{\"price\":\"92917.3\",\"size\":\"0.00000\"}],\"offset\":6962265,\"nonce\":3691008540},\"timestamp\":1765394042416,\"type\":\"update/order_book\"}"
    "msg": "{\"channel\":\"order_book:1\",\"offset\":6962266,\"order_book\":{\"code\":0,\"asks\":[],\"bids\":[{\"price\":\"92903.7\",\"size\":\"0.00108\"},{\"price\":\"92902.6\",\"size\":\"0.00000\"}],\"offset\":6962266,\"nonce\":3691008541},\"timestamp\":1765394042418,\"type\":\"update/order_book\"}"
    "msg": "{\"channel\":\"order_book:1\",\"offset\":6962267,\"order_book\":{\"code\":0,\"asks\":[{\"price\":\"92969.2\",\"size\":\"0.00000\"},{\"price\":\"92995.6\",\"size\":\"0.31921\"}],\"bids\":[{\"price\":\"92926.4\",\"size\":\"1.69695\"},{\"price\":\"92908.1\",\"size\":\"0.38767\"}],\"offset\":6962267,\"nonce\":3691008542},\"timestamp\":1765394042425,\"type\":\"update/order_book\"}"
    "msg": "{\"channel\":\"order_book:1\",\"offset\":6962268,\"order_book\":{\"code\":0,\"asks\":[{\"price\":\"92931.9\",\"size\":\"0.00000\"}],\"bids\":[{\"price\":\"92909.0\",\"size\":\"0.50000\"}],\"offset\":6962268,\"nonce\":3691008543},\"timestamp\":1765394042431,\"type\":\"update/order_book\"}"
    "msg": "{\"channel\":\"order_book:1\",\"offset\":6962269,\"order_book\":{\"code\":0,\"asks\":[{\"price\":\"93027.1\",\"size\":\"2.29458\"},{\"price\":\"93027.4\",\"size\":\"0.00000\"}],\"bids\":[{\"price\":\"92919.2\",\"size\":\"0.13451\"},{\"price\":\"92877.7\",\"size\":\"0.00000\"}],\"offset\":6962269,\"nonce\":3691008544},\"timestamp\":1765394042434,\"type\":\"update/order_book\"}"
    "msg": "{\"channel\":\"order_book:1\",\"offset\":6962270,\"order_book\":{\"code\":0,\"asks\":[{\"price\":\"92931.1\",\"size\":\"0.00000\"}],\"bids\":[{\"price\":\"92908.8\",\"size\":\"4.61928\"},{\"price\":\"92907.6\",\"size\":\"0.00000\"}],\"offset\":6962270,\"nonce\":3691008546},\"timestamp\":1765394042436,\"type\":\"update/order_book\"}"
    "msg": "{\"channel\":\"order_book:1\",\"offset\":6962271,\"order_book\":{\"code\":0,\"asks\":[{\"price\":\"92951.3\",\"size\":\"0.00000\"}],\"bids\":[{\"price\":\"92920.9\",\"size\":\"0.10780\"},{\"price\":\"92919.0\",\"size\":\"0.00000\"}],\"offset\":6962271,\"nonce\":3691008547},\"timestamp\":1765394042441,\"type\":\"update/order_book\"}"
    "msg": "{\"channel\":\"order_book:1\",\"offset\":6962272,\"order_book\":{\"code\":0,\"asks\":[{\"price\":\"92934.3\",\"size\":\"0.00000\"},{\"price\":\"92935.8\",\"size\":\"0.10780\"}],\"bids\":[{\"price\":\"92921.7\",\"size\":\"0.00000\"}],\"offset\":6962272,\"nonce\":3691008548},\"timestamp\":1765394042446,\"type\":\"update/order_book\"}"
    "msg": "{\"channel\":\"order_book:1\",\"offset\":6962273,\"order_book\":{\"code\":0,\"asks\":[{\"price\":\"92931.3\",\"size\":\"0.10371\"},{\"price\":\"92931.7\",\"size\":\"0.00000\"},{\"price\":\"92935.2\",\"size\":\"0.00000\"},{\"price\":\"92997.5\",\"size\":\"0.11088\"}],\"bids\":[],\"offset\":6962273,\"nonce\":3691008552},\"timestamp\":1765394042451,\"type\":\"update/order_book\"}"
    "msg": "{\"channel\":\"order_book:1\",\"offset\":6962274,\"order_book\":{\"code\":0,\"asks\":[{\"price\":\"92937.3\",\"size\":\"0.00000\"},{\"price\":\"92938.4\",\"size\":\"0.10760\"}],\"bids\":[],\"offset\":6962274,\"nonce\":3691008553},\"timestamp\":1765394042455,\"type\":\"update/order_book\"}"
    "msg": "{\"channel\":\"order_book:1\",\"offset\":6962276,\"order_book\":{\"code\":0,\"asks\":[{\"price\":\"92933.5\",\"size\":\"0.02834\"}],\"bids\":[],\"offset\":6962276,\"nonce\":3691008557},\"timestamp\":1765394042468,\"type\":\"update/order_book\"}"
    "msg": "{\"channel\":\"order_book:1\",\"offset\":6962277,\"order_book\":{\"code\":0,\"asks\":[],\"bids\":[{\"price\":\"92920.6\",\"size\":\"0.06670\"},{\"price\":\"92905.4\",\"size\":\"0.10780\"},{\"price\":\"92903.9\",\"size\":\"0.00000\"}],\"offset\":6962277,\"nonce\":3691008562},\"timestamp\":1765394042482,\"type\":\"update/order_book\"}"
    "msg": "{\"channel\":\"order_book:1\",\"offset\":6962278,\"order_book\":{\"code\":0,\"asks\":[{\"price\":\"92931.3\",\"size\":\"0.09818\"}],\"bids\":[{\"price\":\"92875.9\",\"size\":\"0.00000\"}],\"offset\":6962278,\"nonce\":3691008563},\"timestamp\":1765394042484,\"type\":\"update/order_book\"}"
    "msg": "{\"channel\":\"order_book:1\",\"offset\":6962279,\"order_book\":{\"code\":0,\"asks\":[],\"bids\":[{\"price\":\"92901.8\",\"size\":\"0.00021\"},{\"price\":\"92877.5\",\"size\":\"0.01077\"}],\"offset\":6962279,\"nonce\":3691008564},\"timestamp\":1765394042491,\"type\":\"update/order_book\"}"
    "msg": "{\"channel\":\"order_book:1\",\"offset\":6962280,\"order_book\":{\"code\":0,\"asks\":[{\"price\":\"92947.5\",\"size\":\"0.00000\"}],\"bids\":[],\"offset\":6962280,\"nonce\":3691008567},\"timestamp\":1765394042497,\"type\":\"update/order_book\"}"
    "msg": "{\"channel\":\"order_book:1\",\"offset\":6962281,\"order_book\":{\"code\":0,\"asks\":[{\"price\":\"92934.8\",\"size\":\"0.08084\"},{\"price\":\"92936.8\",\"size\":\"0.08083\"},{\"price\":\"93027.1\",\"size\":\"0.00000\"},{\"price\":\"93030.2\",\"size\":\"2.29450\"}],\"bids\":[{\"price\":\"92908.8\",\"size\":\"4.62117\"}],\"offset\":6962281,\"nonce\":3691008574},\"timestamp\":1765394042511,\"type\":\"update/order_book\"}"
    "msg": "{\"channel\":\"order_book:1\",\"offset\":6962282,\"order_book\":{\"code\":0,\"asks\":[{\"price\":\"92931.3\",\"size\":\"0.09778\"}],\"bids\":[],\"offset\":6962282,\"nonce\":3691008575},\"timestamp\":1765394042522,\"type\":\"update/order_book\"}"
    "msg": "{\"channel\":\"order_book:1\",\"offset\":6962283,\"order_book\":{\"code\":0,\"asks\":[{\"price\":\"92944.9\",\"size\":\"0.08083\"}],\"bids\":[{\"price\":\"92906.9\",\"size\":\"0.00108\"},{\"price\":\"92903.7\",\"size\":\"0.00000\"}],\"offset\":6962283,\"nonce\":3691008576},\"timestamp\":1765394042528,\"type\":\"update/order_book\"}"
    "msg": "{\"channel\":\"order_book:1\",\"offset\":6962284,\"order_book\":{\"code\":0,\"asks\":[],\"bids\":[{\"price\":\"92926.4\",\"size\":\"1.69695\"}],\"offset\":6962284,\"nonce\":3691008577},\"timestamp\":1765394042531,\"type\":\"update/order_book\"}"
    "msg": "{\"channel\":\"order_book:1\",\"offset\":6962285,\"order_book\":{\"code\":0,\"asks\":[],\"bids\":[{\"price\":\"92911.8\",\"size\":\"4.62171\"},{\"price\":\"92908.8\",\"size\":\"0.00000\"}],\"offset\":6962285,\"nonce\":3691008579},\"timestamp\":1765394042536,\"type\":\"update/order_book\"}"
    "msg": "{\"channel\":\"order_book:1\",\"offset\":6962286,\"order_book\":{\"code\":0,\"asks\":[{\"price\":\"92936.9\",\"size\":\"2.80156\"}],\"bids\":[],\"offset\":6962286,\"nonce\":3691008585},\"timestamp\":1765394042544,\"type\":\"update/order_book\"}"
    "msg": "{\"channel\":\"order_book:1\",\"offset\":6962287,\"order_book\":{\"code\":0,\"asks\":[{\"price\":\"92937.5\",\"size\":\"0.10760\"},{\"price\":\"92938.4\",\"size\":\"0.00000\"},{\"price\":\"92949.1\",\"size\":\"0.39071\"}],\"bids\":[{\"price\":\"92914.6\",\"size\":\"0.08084\"}],\"offset\":6962287,\"nonce\":3691008589},\"timestamp\":1765394042555,\"type\":\"update/order_book\"}"
    "msg": "{\"channel\":\"order_book:1\",\"offset\":6962288,\"order_book\":{\"code\":0,\"asks\":[{\"price\":\"92945.2\",\"size\":\"0.08072\"}],\"bids\":[],\"offset\":6962288,\"nonce\":3691008591},\"timestamp\":1765394042557,\"type\":\"update/order_book\"}"
    "msg": "{\"channel\":\"order_book:1\",\"offset\":6962289,\"order_book\":{\"code\":0,\"asks\":[{\"price\":\"92939.2\",\"size\":\"0.08079\"}],\"bids\":[],\"offset\":6962289,\"nonce\":3691008592},\"timestamp\":1765394042560,\"type\":\"update/order_book\"}"
    "msg": "{\"channel\":\"order_book:1\",\"offset\":6962290,\"order_book\":{\"code\":0,\"asks\":[{\"price\":\"92942.1\",\"size\":\"0.16162\"}],\"bids\":[],\"offset\":6962290,\"nonce\":3691008595},\"timestamp\":1765394042566,\"type\":\"update/order_book\"}"
    "msg": "{\"channel\":\"order_book:1\",\"offset\":6962291,\"order_book\":{\"code\":0,\"asks\":[{\"price\":\"92931.3\",\"size\":\"0.09778\"}],\"bids\":[],\"offset\":6962291,\"nonce\":3691008596},\"timestamp\":1765394042570,\"type\":\"update/order_book\"}"
    "msg": "{\"channel\":\"order_book:1\",\"offset\":6962292,\"order_book\":{\"code\":0,\"asks\":[],\"bids\":[{\"price\":\"92877.5\",\"size\":\"0.00000\"},{\"price\":\"92874.7\",\"size\":\"0.00000\"}],\"offset\":6962292,\"nonce\":3691008597},\"timestamp\":1765394042572,\"type\":\"update/order_book\"}"
    "msg": "{\"channel\":\"order_book:1\",\"offset\":6962293,\"order_book\":{\"code\":0,\"asks\":[{\"price\":\"92936.9\",\"size\":\"0.10760\"}],\"bids\":[],\"offset\":6962293,\"nonce\":3691008599},\"timestamp\":1765394042580,\"type\":\"update/order_book\"}"
    "msg": "{\"channel\":\"order_book:1\",\"offset\":6962294,\"order_book\":{\"code\":0,\"asks\":[],\"bids\":[{\"price\":\"92878.4\",\"size\":\"0.01077\"}],\"offset\":6962294,\"nonce\":3691008603},\"timestamp\":1765394042593,\"type\":\"update/order_book\"}"
    "msg": "{\"channel\":\"order_book:1\",\"offset\":6962295,\"order_book\":{\"code\":0,\"asks\":[],\"bids\":[{\"price\":\"92919.1\",\"size\":\"0.10780\"},{\"price\":\"92918.7\",\"size\":\"0.00000\"}],\"offset\":6962295,\"nonce\":3691008606},\"timestamp\":1765394042595,\"type\":\"update/order_book\"}"
    "msg": "{\"channel\":\"order_book:1\",\"offset\":6962296,\"order_book\":{\"code\":0,\"asks\":[],\"bids\":[{\"price\":\"92911.8\",\"size\":\"0.00000\"},{\"price\":\"92911.7\",\"size\":\"4.62356\"}],\"offset\":6962296,\"nonce\":3691008611},\"timestamp\":1765394042606,\"type\":\"update/order_book\"}"
    "msg": "{\"channel\":\"order_book:1\",\"offset\":6962297,\"order_book\":{\"code\":0,\"asks\":[{\"price\":\"93024.5\",\"size\":\"2.29465\"},{\"price\":\"93030.2\",\"size\":\"0.00000\"}],\"bids\":[],\"offset\":6962297,\"nonce\":3691008612},\"timestamp\":1765394042612,\"type\":\"update/order_book\"}"
    "msg": "{\"channel\":\"order_book:1\",\"offset\":6962298,\"order_book\":{\"code\":0,\"asks\":[{\"price\":\"92949.1\",\"size\":\"0.38767\"}],\"bids\":[{\"price\":\"92926.4\",\"size\":\"1.69695\"},{\"price\":\"92908.6\",\"size\":\"0.00108\"},{\"price\":\"92906.9\",\"size\":\"0.00000\"}],\"offset\":6962298,\"nonce\":3691008615},\"timestamp\":1765394042624,\"type\":\"update/order_book\"}"
    "msg": "{\"channel\":\"order_book:1\",\"offset\":6962299,\"order_book\":{\"code\":0,\"asks\":[{\"price\":\"92931.2\",\"size\":\"2.69396\"},{\"price\":\"93020.6\",\"size\":\"2.29475\"},{\"price\":\"93024.5\",\"size\":\"0.00000\"}],\"bids\":[{\"price\":\"92913.6\",\"size\":\"4.62426\"},{\"price\":\"92911.7\",\"size\":\"0.00000\"}],\"offset\":6962299,\"nonce\":3691008622},\"timestamp\":1765394042646,\"type\":\"update/order_book\"}"
    "msg": "{\"channel\":\"order_book:1\",\"offset\":6962300,\"order_book\":{\"code\":0,\"asks\":[{\"price\":\"92932.4\",\"size\":\"0.00860\"},{\"price\":\"92936.0\",\"size\":\"0.10780\"},{\"price\":\"92936.9\",\"size\":\"0.00000\"}],\"bids\":[],\"offset\":6962300,\"nonce\":3691008623},\"timestamp\":1765394042654,\"type\":\"update/order_book\"}"
    "msg": "{\"channel\":\"order_book:1\",\"offset\":6962301,\"order_book\":{\"code\":0,\"asks\":[{\"price\":\"92950.2\",\"size\":\"0.00304\"}],\"bids\":[{\"price\":\"92833.9\",\"size\":\"0.00000\"}],\"offset\":6962301,\"nonce\":3691008625},\"timestamp\":1765394042666,\"type\":\"update/order_book\"}"
    "msg": "{\"channel\":\"order_book:1\",\"offset\":6962302,\"order_book\":{\"code\":0,\"asks\":[],\"bids\":[{\"price\":\"92909.9\",\"size\":\"0.00860\"}],\"offset\":6962302,\"nonce\":3691008626},\"timestamp\":1765394042667,\"type\":\"update/order_book\"}"
    "msg": "{\"channel\":\"order_book:1\",\"offset\":6962303,\"order_book\":{\"code\":0,\"asks\":[],\"bids\":[{\"price\":\"92878.4\",\"size\":\"0.00000\"}],\"offset\":6962303,\"nonce\":3691008627},\"timestamp\":1765394042669,\"type\":\"update/order_book\"}"
    "msg": "{\"channel\":\"order_book:1\",\"offset\":6962304,\"order_book\":{\"code\":0,\"asks\":[{\"price\":\"92934.5\",\"size\":\"0.10780\"},{\"price\":\"92935.8\",\"size\":\"0.00000\"},{\"price\":\"92938.3\",\"size\":\"0.25155\"}],\"bids\":[{\"price\":\"92926.4\",\"size\":\"1.69695\"},{\"price\":\"92881.2\",\"size\":\"0.01077\"}],\"offset\":6962304,\"nonce\":3691008629},\"timestamp\":1765394042681,\"type\":\"update/order_book\"}"
    "msg": "{\"channel\":\"order_book:1\",\"offset\":6962305,\"order_book\":{\"code\":0,\"asks\":[{\"price\":\"92950.2\",\"size\":\"0.00000\"}],\"bids\":[],\"offset\":6962305,\"nonce\":3691008631},\"timestamp\":1765394042686,\"type\":\"update/order_book\"}"
    "msg": "{\"channel\":\"order_book:1\",\"offset\":6962306,\"order_book\":{\"code\":0,\"asks\":[],\"bids\":[{\"price\":\"92905.4\",\"size\":\"0.00000\"},{\"price\":\"92903.9\",\"size\":\"0.10780\"},{\"price\":\"92781.8\",\"size\":\"0.00000\"}],\"offset\":6962306,\"nonce\":3691008642},\"timestamp\":1765394042707,\"type\":\"update/order_book\"}"
    "msg": "{\"channel\":\"order_book:1\",\"offset\":6962307,\"order_book\":{\"code\":0,\"asks\":[],\"bids\":[{\"price\":\"92926.4\",\"size\":\"1.69495\"}],\"offset\":6962307,\"nonce\":3691008644},\"timestamp\":1765394042719,\"type\":\"update/order_book\"}"
    "msg": "{\"channel\":\"order_book:1\",\"offset\":6962308,\"order_book\":{\"code\":0,\"asks\":[{\"price\":\"93010.3\",\"size\":\"2.29502\"},{\"price\":\"93020.6\",\"size\":\"0.00000\"}],\"bids\":[{\"price\":\"92913.6\",\"size\":\"0.00000\"},{\"price\":\"92913.5\",\"size\":\"4.62655\"},{\"price\":\"92908.6\",\"size\":\"0.00000\"},{\"price\":\"92908.5\",\"size\":\"0.00108\"}],\"offset\":6962308,\"nonce\":3691008647},\"timestamp\":1765394042735,\"type\":\"update/order_book\"}"
    "msg": "{\"channel\":\"order_book:1\",\"offset\":6962309,\"order_book\":{\"code\":0,\"asks\":[{\"price\":\"92936.6\",\"size\":\"0.10780\"},{\"price\":\"92937.5\",\"size\":\"0.00000\"},{\"price\":\"92952.8\",\"size\":\"0.00304\"}],\"bids\":[{\"price\":\"92926.4\",\"size\":\"1.69495\"},{\"price\":\"92807.2\",\"size\":\"0.52090\"}],\"offset\":6962309,\"nonce\":3691008649},\"timestamp\":1765394042737,\"type\":\"update/order_book\"}"
    "msg": "{\"channel\":\"order_book:1\",\"offset\":6962310,\"order_book\":{\"code\":0,\"asks\":[],\"bids\":[{\"price\":\"92920.9\",\"size\":\"0.00000\"},{\"price\":\"92919.3\",\"size\":\"0.10780\"},{\"price\":\"92919.1\",\"size\":\"0.00000\"},{\"price\":\"92917.4\",\"size\":\"0.10780\"}],\"offset\":6962310,\"nonce\":3691008664},\"timestamp\":1765394042777,\"type\":\"update/order_book\"}"
    "msg": "{\"channel\":\"order_book:1\",\"offset\":6962311,\"order_book\":{\"code\":0,\"asks\":[{\"price\":\"92931.2\",\"size\":\"2.69296\"},{\"price\":\"92934.2\",\"size\":\"0.10780\"},{\"price\":\"92936.0\",\"size\":\"0.00000\"}],\"bids\":[],\"offset\":6962311,\"nonce\":3691008668},\"timestamp\":1765394042784,\"type\":\"update/order_book\"}"
    "msg": "{\"channel\":\"order_book:1\",\"offset\":6962312,\"order_book\":{\"code\":0,\"asks\":[],\"bids\":[{\"price\":\"92881.2\",\"size\":\"0.00000\"}],\"offset\":6962312,\"nonce\":3691008675},\"timestamp\":1765394042793,\"type\":\"update/order_book\"}"
    "msg": "{\"channel\":\"order_book:1\",\"offset\":6962313,\"order_book\":{\"code\":0,\"asks\":[{\"price\":\"92933.3\",\"size\":\"0.10780\"},{\"price\":\"92934.5\",\"size\":\"0.00000\"}],\"bids\":[],\"offset\":6962313,\"nonce\":3691008677},\"timestamp\":1765394042798,\"type\":\"update/order_book\"}"
    "msg": "{\"channel\":\"order_book:1\",\"offset\":6962314,\"order_book\":{\"code\":0,\"asks\":[],\"bids\":[{\"price\":\"92883.5\",\"size\":\"0.01077\"}],\"offset\":6962314,\"nonce\":3691008678},\"timestamp\":1765394042802,\"type\":\"update/order_book\"}"
    "msg": "{\"channel\":\"order_book:1\",\"offset\":6962315,\"order_book\":{\"code\":0,\"asks\":[{\"price\":\"92952.8\",\"size\":\"0.00000\"}],\"bids\":[],\"offset\":6962315,\"nonce\":3691008680},\"timestamp\":1765394042807,\"type\":\"update/order_book\"}"
    "msg": "{\"channel\":\"order_book:1\",\"offset\":6962316,\"order_book\":{\"code\":0,\"asks\":[{\"price\":\"92938.3\",\"size\":\"0.00000\"}],\"bids\":[{\"price\":\"92908.6\",\"size\":\"0.00108\"},{\"price\":\"92908.5\",\"size\":\"0.00000\"}],\"offset\":6962316,\"nonce\":3691008683},\"timestamp\":1765394042821,\"type\":\"update/order_book\"}"
    "msg": "{\"channel\":\"order_book:1\",\"offset\":6962317,\"order_book\":{\"code\":0,\"asks\":[],\"bids\":[{\"price\":\"92913.6\",\"size\":\"4.62877\"},{\"price\":\"92913.5\",\"size\":\"0.00000\"}],\"offset\":6962317,\"nonce\":3691008684},\"timestamp\":1765394042822,\"type\":\"update/order_book\"}"
    "msg": "{\"channel\":\"order_book:1\",\"offset\":6962318,\"order_book\":{\"code\":0,\"asks\":[{\"price\":\"92999.4\",\"size\":\"2.29530\"},{\"price\":\"93010.3\",\"size\":\"0.00000\"}],\"bids\":[],\"offset\":6962318,\"nonce\":3691008685},\"timestamp\":1765394042824,\"type\":\"update/order_book\"}"
    "msg": "{\"channel\":\"order_book:1\",\"offset\":6962319,\"order_book\":{\"code\":0,\"asks\":[],\"bids\":[{\"price\":\"92903.9\",\"size\":\"0.00000\"},{\"price\":\"92902.4\",\"size\":\"0.10780\"}],\"offset\":6962319,\"nonce\":3691008688},\"timestamp\":1765394042830,\"type\":\"update/order_book\"}"
    "msg": "{\"channel\":\"order_book:1\",\"offset\":6962320,\"order_book\":{\"code\":0,\"asks\":[{\"price\":\"92935.1\",\"size\":\"0.10780\"},{\"price\":\"92936.6\",\"size\":\"0.00000\"}],\"bids\":[],\"offset\":6962320,\"nonce\":3691008692},\"timestamp\":1765394042836,\"type\":\"update/order_book\"}"
    "msg": "{\"channel\":\"order_book:1\",\"offset\":6962322,\"order_book\":{\"code\":0,\"asks\":[{\"price\":\"92931.2\",\"size\":\"0.00000\"}],\"bids\":[],\"offset\":6962322,\"nonce\":3691008729},\"timestamp\":1765394042910,\"type\":\"update/order_book\"}"
    "msg": "{\"channel\":\"order_book:1\",\"offset\":6962323,\"order_book\":{\"code\":0,\"asks\":[{\"price\":\"92933.3\",\"size\":\"0.00000\"},{\"price\":\"92934.7\",\"size\":\"0.10780\"}],\"bids\":[],\"offset\":6962323,\"nonce\":3691008734},\"timestamp\":1765394042921,\"type\":\"update/order_book\"}"
    "msg": "{\"channel\":\"order_book:1\",\"offset\":6962324,\"order_book\":{\"code\":0,\"asks\":[{\"price\":\"92934.2\",\"size\":\"0.00000\"},{\"price\":\"92934.5\",\"size\":\"0.00021\"},{\"price\":\"92935.4\",\"size\":\"0.10780\"}],\"bids\":[{\"price\":\"92920.4\",\"size\":\"0.10780\"},{\"price\":\"92919.3\",\"size\":\"0.00000\"}],\"offset\":6962324,\"nonce\":3691008735},\"timestamp\":1765394042927,\"type\":\"update/order_book\"}"
    "msg": "{\"channel\":\"order_book:1\",\"offset\":6962325,\"order_book\":{\"code\":0,\"asks\":[],\"bids\":[{\"price\":\"92927.9\",\"size\":\"0.26095\"},{\"price\":\"92918.5\",\"size\":\"0.10780\"},{\"price\":\"92917.4\",\"size\":\"0.00000\"}],\"offset\":6962325,\"nonce\":3691008737},\"timestamp\":1765394042931,\"type\":\"update/order_book\"}"
    "msg": "{\"channel\":\"order_book:1\",\"offset\":6962326,\"order_book\":{\"code\":0,\"asks\":[{\"price\":\"92935.1\",\"size\":\"0.00000\"},{\"price\":\"92936.8\",\"size\":\"0.18863\"},{\"price\":\"92990.9\",\"size\":\"2.29551\"},{\"price\":\"92999.4\",\"size\":\"0.00000\"}],\"bids\":[{\"price\":\"92913.6\",\"size\":\"0.00000\"},{\"price\":\"92908.6\",\"size\":\"0.00000\"},{\"price\":\"92904.5\",\"size\":\"0.10780\"},{\"price\":\"92902.4\",\"size\":\"0.00000\"},{\"price\":\"92895.4\",\"size\":\"4.63253\"},{\"price\":\"92890.4\",\"size\":\"0.00108\"}],\"offset\":6962326,\"nonce\":3691008740},\"timestamp\":1765394042961,\"type\":\"update/order_book\"}"
    "msg": "{\"channel\":\"order_book:1\",\"offset\":6962327,\"order_book\":{\"code\":0,\"asks\":[],\"bids\":[{\"price\":\"92927.9\",\"size\":\"0.82673\"},{\"price\":\"92926.4\",\"size\":\"1.69495\"}],\"offset\":6962327,\"nonce\":3691008741},\"timestamp\":1765394042994,\"type\":\"update/order_book\"}"
    "msg": "{\"channel\":\"order_book:1\",\"offset\":6962329,\"order_book\":{\"code\":0,\"asks\":[{\"price\":\"92932.0\",\"size\":\"0.00021\"}],\"bids\":[{\"price\":\"92921.3\",\"size\":\"0.00000\"},{\"price\":\"92903.8\",\"size\":\"0.00000\"}],\"offset\":6962329,\"nonce\":3691008743},\"timestamp\":1765394043032,\"type\":\"update/order_book\"}"
    "msg": "{\"channel\":\"order_book:1\",\"offset\":6962330,\"order_book\":{\"code\":0,\"asks\":[{\"price\":\"92930.6\",\"size\":\"0.10000\"}],\"bids\":[],\"offset\":6962330,\"nonce\":3691008745},\"timestamp\":1765394043057,\"type\":\"update/order_book\"}"
    "msg": "{\"channel\":\"order_book:1\",\"offset\":6962331,\"order_book\":{\"code\":0,\"asks\":[{\"price\":\"92932.4\",\"size\":\"0.00000\"}],\"bids\":[{\"price\":\"92917.7\",\"size\":\"0.38567\"}],\"offset\":6962331,\"nonce\":3691008746},\"timestamp\":1765394043065,\"type\":\"update/order_book\"}"
    "msg": "{\"channel\":\"order_book:1\",\"offset\":6962332,\"order_book\":{\"code\":0,\"asks\":[{\"price\":\"92933.5\",\"size\":\"0.00000\"},{\"price\":\"92981.2\",\"size\":\"2.29576\"},{\"price\":\"92990.9\",\"size\":\"0.00000\"}],\"bids\":[{\"price\":\"92920.6\",\"size\":\"0.03765\"},{\"price\":\"92912.7\",\"size\":\"0.08081\"},{\"price\":\"92906.9\",\"size\":\"4.63392\"},{\"price\":\"92901.9\",\"size\":\"0.00108\"},{\"price\":\"92895.4\",\"size\":\"0.00000\"},{\"price\":\"92890.4\",\"size\":\"0.00000\"}],\"offset\":6962332,\"nonce\":3691008749},\"timestamp\":1765394043081,\"type\":\"update/order_book\"}"
    "msg": "{\"channel\":\"order_book:1\",\"offset\":6962333,\"order_book\":{\"code\":0,\"asks\":[{\"price\":\"92931.1\",\"size\":\"0.09778\"},{\"price\":\"92931.3\",\"size\":\"0.00000\"},{\"price\":\"92936.2\",\"size\":\"0.00000\"}],\"bids\":[{\"price\":\"92922.3\",\"size\":\"0.02905\"},{\"price\":\"92913.2\",\"size\":\"0.01076\"}],\"offset\":6962333,\"nonce\":3691008750},\"timestamp\":1765394043087,\"type\":\"update/order_book\"}"
    "msg": "{\"channel\":\"order_book:1\",\"offset\":6962335,\"order_book\":{\"code\":0,\"asks\":[],\"bids\":[{\"price\":\"92913.2\",\"size\":\"0.00000\"},{\"price\":\"92869.6\",\"size\":\"0.00020\"}],\"offset\":6962335,\"nonce\":3691008752},\"timestamp\":1765394043098,\"type\":\"update/order_book\"}"
    "msg": "{\"channel\":\"order_book:1\",\"offset\":6962338,\"order_book\":{\"code\":0,\"asks\":[{\"price\":\"92932.3\",\"size\":\"0.00000\"},{\"price\":\"93005.1\",\"size\":\"0.13460\"},{\"price\":\"93060.7\",\"size\":\"0.00000\"}],\"bids\":[{\"price\":\"92916.3\",\"size\":\"0.00000\"},{\"price\":\"92913.3\",\"size\":\"0.00000\"},{\"price\":\"92906.8\",\"size\":\"0.00000\"},{\"price\":\"92883.5\",\"size\":\"0.00000\"},{\"price\":\"92853.4\",\"size\":\"0.00020\"}],\"offset\":6962338,\"nonce\":3691008755},\"timestamp\":1765394043109,\"type\":\"update/order_book\"}"
    "msg": "{\"channel\":\"order_book:1\",\"offset\":6962339,\"order_book\":{\"code\":0,\"asks\":[{\"price\":\"92934.7\",\"size\":\"0.00000\"},{\"price\":\"92936.1\",\"size\":\"0.10780\"}],\"bids\":[{\"price\":\"92924.9\",\"size\":\"0.00000\"},{\"price\":\"92922.1\",\"size\":\"0.10780\"},{\"price\":\"92920.4\",\"size\":\"0.00000\"},{\"price\":\"92885.7\",\"size\":\"0.01077\"}],\"offset\":6962339,\"nonce\":3691008756},\"timestamp\":1765394043114,\"type\":\"update/order_book\"}"
    "msg": "{\"channel\":\"order_book:1\",\"offset\":6962340,\"order_book\":{\"code\":0,\"asks\":[{\"price\":\"92930.6\",\"size\":\"0.00000\"},{\"price\":\"92936.8\",\"size\":\"0.08083\"},{\"price\":\"92938.4\",\"size\":\"0.10760\"},{\"price\":\"92955.1\",\"size\":\"0.00000\"}],\"bids\":[{\"price\":\"92928.0\",\"size\":\"1.92088\"}],\"offset\":6962340,\"nonce\":3691008757},\"timestamp\":1765394043120,\"type\":\"update/order_book\"}"
    "msg": "{\"channel\":\"order_book:1\",\"offset\":6962341,\"order_book\":{\"code\":0,\"asks\":[{\"price\":\"92931.1\",\"size\":\"0.00000\"},{\"price\":\"92937.1\",\"size\":\"0.00000\"},{\"price\":\"92952.2\",\"size\":\"0.00000\"}],\"bids\":[{\"price\":\"92921.1\",\"size\":\"0.00000\"},{\"price\":\"92913.3\",\"size\":\"0.01076\"},{\"price\":\"92912.8\",\"size\":\"0.02152\"},{\"price\":\"92908.2\",\"size\":\"0.02628\"},{\"price\":\"92906.1\",\"size\":\"0.10780\"},{\"price\":\"92904.5\",\"size\":\"0.00000\"},{\"price\":\"92888.6\",\"size\":\"0.00000\"},{\"price\":\"92885.7\",\"size\":\"0.00000\"}],\"offset\":6962341,\"nonce\":3691008758},\"timestamp\":1765394043123,\"type\":\"update/order_book\"}"
    "msg": "{\"channel\":\"order_book:1\",\"offset\":6962342,\"order_book\":{\"code\":0,\"asks\":[{\"price\":\"92934.8\",\"size\":\"0.00000\"},{\"price\":\"92935.4\",\"size\":\"0.00000\"},{\"price\":\"92936.7\",\"size\":\"0.00000\"},{\"price\":\"92936.8\",\"size\":\"0.00000\"},{\"price\":\"92939.2\",\"size\":\"0.00000\"},{\"price\":\"92942.7\",\"size\":\"0.00000\"},{\"price\":\"92944.9\",\"size\":\"0.00000\"}],\"bids\":[{\"price\":\"92912.8\",\"size\":\"0.00000\"},{\"price\":\"92901.2\",\"size\":\"0.00000\"}],\"offset\":6962342,\"nonce\":3691008759},\"timestamp\":1765394043132,\"type\":\"update/order_book\"}"
    "msg": "{\"channel\":\"order_book:1\",\"offset\":6962343,\"order_book\":{\"code\":0,\"asks\":[{\"price\":\"92932.0\",\"size\":\"0.00019\"},{\"price\":\"92942.1\",\"size\":\"0.00000\"},{\"price\":\"92945.2\",\"size\":\"0.00000\"},{\"price\":\"92981.2\",\"size\":\"0.00000\"},{\"price\":\"92985.7\",\"size\":\"2.29564\"}],\"bids\":[{\"price\":\"92913.3\",\"size\":\"0.00000\"}],\"offset\":6962343,\"nonce\":3691008760},\"timestamp\":1765394043138,\"type\":\"update/order_book\"}"
    "msg": "{\"channel\":\"order_book:1\",\"offset\":6962344,\"order_book\":{\"code\":0,\"asks\":[{\"price\":\"92938.4\",\"size\":\"0.00000\"}],\"bids\":[{\"price\":\"92929.5\",\"size\":\"0.38767\"},{\"price\":\"92917.4\",\"size\":\"0.01076\"},{\"price\":\"92913.6\",\"size\":\"0.02152\"},{\"price\":\"92906.9\",\"size\":\"4.63591\"},{\"price\":\"92895.7\",\"size\":\"0.00000\"}],\"offset\":6962344,\"nonce\":3691008761},\"timestamp\":1765394043145,\"type\":\"update/order_book\"}"
    "msg": "{\"channel\":\"order_book:1\",\"offset\":6962345,\"order_book\":{\"code\":0,\"asks\":[{\"price\":\"92935.7\",\"size\":\"0.03765\"},{\"price\":\"92936.1\",\"size\":\"0.00000\"},{\"price\":\"92936.7\",\"size\":\"0.02834\"},{\"price\":\"92945.7\",\"size\":\"0.00500\"}],\"bids\":[{\"price\":\"92920.5\",\"size\":\"0.38767\"}],\"offset\":6962345,\"nonce\":3691008762},\"timestamp\":1765394043151,\"type\":\"update/order_book\"}"
    "msg": "{\"channel\":\"order_book:1\",\"offset\":6962346,\"order_book\":{\"code\":0,\"asks\":[],\"bids\":[{\"price\":\"92907.2\",\"size\":\"0.00108\"},{\"price\":\"92901.9\",\"size\":\"0.00000\"},{\"price\":\"92869.6\",\"size\":\"0.13451\"}],\"offset\":6962346,\"nonce\":3691008763},\"timestamp\":1765394043156,\"type\":\"update/order_book\"}"
    "msg": "{\"channel\":\"order_book:1\",\"offset\":6962347,\"order_book\":{\"code\":0,\"asks\":[],\"bids\":[{\"price\":\"92917.4\",\"size\":\"0.00000\"}],\"offset\":6962347,\"nonce\":3691008764},\"timestamp\":1765394043172,\"type\":\"update/order_book\"}"
    "msg": "{\"channel\":\"order_book:1\",\"offset\":6962348,\"order_book\":{\"code\":0,\"asks\":[{\"price\":\"92941.8\",\"size\":\"0.00000\"},{\"price\":\"92984.7\",\"size\":\"0.00000\"}],\"bids\":[{\"price\":\"92918.1\",\"size\":\"0.01076\"}],\"offset\":6962348,\"nonce\":3691008766},\"timestamp\":1765394043179,\"type\":\"update/order_book\"}"
    "msg": "{\"channel\":\"order_book:1\",\"offset\":6962349,\"order_book\":{\"code\":0,\"asks\":[{\"price\":\"92932.0\",\"size\":\"0.00000\"},{\"price\":\"92949.6\",\"size\":\"0.00000\"}],\"bids\":[{\"price\":\"92930.5\",\"size\":\"1.07758\"},{\"price\":\"92924.0\",\"size\":\"0.00215\"},{\"price\":\"92890.0\",\"size\":\"0.00000\"},{\"price\":\"92887.9\",\"size\":\"0.12165\"},{\"price\":\"92821.3\",\"size\":\"0.00000\"}],\"offset\":6962349,\"nonce\":3691008767},\"timestamp\":1765394043186,\"type\":\"update/order_book\"}"
    "msg": "{\"channel\":\"order_book:1\",\"offset\":6962350,\"order_book\":{\"code\":0,\"asks\":[{\"price\":\"92942.2\",\"size\":\"0.00000\"},{\"price\":\"92959.0\",\"size\":\"0.00000\"}],\"bids\":[{\"price\":\"92918.1\",\"size\":\"0.00000\"}],\"offset\":6962350,\"nonce\":3691008768},\"timestamp\":1765394043190,\"type\":\"update/order_book\"}"
    "msg": "{\"channel\":\"order_book:1\",\"offset\":6962351,\"order_book\":{\"code\":0,\"asks\":[{\"price\":\"92955.9\",\"size\":\"0.05276\"}],\"bids\":[{\"price\":\"92930.5\",\"size\":\"3.23203\"},{\"price\":\"92924.5\",\"size\":\"0.02905\"},{\"price\":\"92918.9\",\"size\":\"2.69396\"},{\"price\":\"92896.8\",\"size\":\"0.36718\"},{\"price\":\"92889.9\",\"size\":\"0.00000\"}],\"offset\":6962351,\"nonce\":3691008769},\"timestamp\":1765394043195,\"type\":\"update/order_book\"}"
    "msg": "{\"channel\":\"order_book:1\",\"offset\":6962352,\"order_book\":{\"code\":0,\"asks\":[{\"price\":\"92966.1\",\"size\":\"0.28315\"}],\"bids\":[{\"price\":\"92922.3\",\"size\":\"0.00000\"},{\"price\":\"92915.1\",\"size\":\"0.00000\"},{\"price\":\"92725.1\",\"size\":\"0.00000\"}],\"offset\":6962352,\"nonce\":3691008770},\"timestamp\":1765394043199,\"type\":\"update/order_book\"}"
    "msg": "{\"channel\":\"order_book:1\",\"offset\":6962353,\"order_book\":{\"code\":0,\"asks\":[{\"price\":\"92951.4\",\"size\":\"0.00000\"}],\"bids\":[{\"price\":\"92919.0\",\"size\":\"0.01076\"},{\"price\":\"92917.5\",\"size\":\"0.09806\"}],\"offset\":6962353,\"nonce\":3691008772},\"timestamp\":1765394043211,\"type\":\"update/order_book\"}"
    "msg": "{\"channel\":\"order_book:1\",\"offset\":6962354,\"order_book\":{\"code\":0,\"asks\":[{\"price\":\"92959.6\",\"size\":\"0.00304\"},{\"price\":\"92977.0\",\"size\":\"0.38767\"},{\"price\":\"92985.4\",\"size\":\"2.29564\"},{\"price\":\"92985.7\",\"size\":\"0.00000\"}],\"bids\":[{\"price\":\"92931.9\",\"size\":\"0.80229\"},{\"price\":\"92920.6\",\"size\":\"0.00000\"},{\"price\":\"92912.2\",\"size\":\"4.63731\"},{\"price\":\"92906.9\",\"size\":\"0.00000\"}],\"offset\":6962354,\"nonce\":3691008773},\"timestamp\":1765394043214,\"type\":\"update/order_book\"}"
    "msg": "{\"channel\":\"order_book:1\",\"offset\":6962355,\"order_book\":{\"code\":0,\"asks\":[{\"price\":\"92950.1\",\"size\":\"0.00000\"}],\"bids\":[{\"price\":\"92931.9\",\"size\":\"0.80729\"},{\"price\":\"92929.5\",\"size\":\"1.34539\"},{\"price\":\"92919.0\",\"size\":\"0.00000\"}],\"offset\":6962355,\"nonce\":3691008774},\"timestamp\":1765394043220,\"type\":\"update/order_book\"}"
    "msg": "{\"channel\":\"order_book:1\",\"offset\":6962356,\"order_book\":{\"code\":0,\"asks\":[{\"price\":\"92935.7\",\"size\":\"0.00000\"},{\"price\":\"92940.5\",\"size\":\"0.00000\"},{\"price\":\"93098.6\",\"size\":\"0.00000\"}],\"bids\":[{\"price\":\"92931.9\",\"size\":\"0.81229\"},{\"price\":\"92913.6\",\"size\":\"0.00000\"}],\"offset\":6962356,\"nonce\":3691008775},\"timestamp\":1765394043227,\"type\":\"update/order_book\"}"
    "msg": "{\"channel\":\"order_book:1\",\"offset\":6962357,\"order_book\":{\"code\":0,\"asks\":[{\"price\":\"92934.5\",\"size\":\"0.00000\"},{\"price\":\"92936.7\",\"size\":\"0.01855\"},{\"price\":\"92943.0\",\"size\":\"0.00299\"},{\"price\":\"92986.3\",\"size\":\"0.00000\"}],\"bids\":[{\"price\":\"92931.9\",\"size\":\"0.81836\"},{\"price\":\"92929.6\",\"size\":\"0.23175\"},{\"price\":\"92904.8\",\"size\":\"0.00500\"},{\"price\":\"92894.2\",\"size\":\"0.00000\"},{\"price\":\"92887.9\",\"size\":\"0.11088\"},{\"price\":\"92573.0\",\"size\":\"0.00000\"}],\"offset\":6962357,\"nonce\":3691008776},\"timestamp\":1765394043232,\"type\":\"update/order_book\"}"
    "msg": "{\"channel\":\"order_book:1\",\"offset\":6962358,\"order_book\":{\"code\":0,\"asks\":[{\"price\":\"92947.9\",\"size\":\"0.15402\"},{\"price\":\"92948.2\",\"size\":\"2.69396\"},{\"price\":\"92968.3\",\"size\":\"2.15445\"},{\"price\":\"93000.8\",\"size\":\"8.07918\"},{\"price\":\"93056.4\",\"size\":\"8.07918\"}],\"bids\":[{\"price\":\"92918.5\",\"size\":\"0.00000\"},{\"price\":\"92916.9\",\"size\":\"0.02152\"}],\"offset\":6962358,\"nonce\":3691008777},\"timestamp\":1765394043234,\"type\":\"update/order_book\"}"
    "msg": "{\"channel\":\"order_book:1\",\"offset\":6962359,\"order_book\":{\"code\":0,\"asks\":[{\"price\":\"92936.7\",\"size\":\"0.00000\"},{\"price\":\"92945.0\",\"size\":\"1.07758\"}],\"bids\":[{\"price\":\"92931.0\",\"size\":\"0.02000\"},{\"price\":\"92920.7\",\"size\":\"0.01076\"},{\"price\":\"92889.0\",\"size\":\"0.01077\"}],\"offset\":6962359,\"nonce\":3691008778},\"timestamp\":1765394043240,\"type\":\"update/order_book\"}"
    "msg": "{\"channel\":\"order_book:1\",\"offset\":6962360,\"order_book\":{\"code\":0,\"asks\":[{\"price\":\"92949.1\",\"size\":\"0.00000\"},{\"price\":\"92982.6\",\"size\":\"0.38767\"}],\"bids\":[{\"price\":\"92928.1\",\"size\":\"0.10780\"},{\"price\":\"92922.1\",\"size\":\"0.00000\"},{\"price\":\"92863.9\",\"size\":\"2.15445\"}],\"offset\":6962360,\"nonce\":3691008779},\"timestamp\":1765394043244,\"type\":\"update/order_book\"}"
    "msg": "{\"channel\":\"order_book:1\",\"offset\":6962361,\"order_book\":{\"code\":0,\"asks\":[{\"price\":\"92959.6\",\"size\":\"0.00000\"}],\"bids\":[{\"price\":\"92924.5\",\"size\":\"0.00000\"},{\"price\":\"92914.0\",\"size\":\"0.01500\"}],\"offset\":6962361,\"nonce\":3691008780},\"timestamp\":1765394043257,\"type\":\"update/order_book\"}"
    "msg": "{\"channel\":\"order_book:1\",\"offset\":6962362,\"order_book\":{\"code\":0,\"asks\":[{\"price\":\"92944.3\",\"size\":\"0.05379\"},{\"price\":\"92945.0\",\"size\":\"0.00000\"}],\"bids\":[{\"price\":\"92926.5\",\"size\":\"0.02905\"},{\"price\":\"92920.7\",\"size\":\"0.00000\"},{\"price\":\"92920.3\",\"size\":\"0.02906\"},{\"price\":\"92916.9\",\"size\":\"0.00000\"},{\"price\":\"92908.8\",\"size\":\"0.05381\"},{\"price\":\"92889.0\",\"size\":\"0.00000\"},{\"price\":\"92575.6\",\"size\":\"0.00000\"}],\"offset\":6962362,\"nonce\":3691008781},\"timestamp\":1765394043262,\"type\":\"update/order_book\"}"
    "msg": "{\"channel\":\"order_book:1\",\"offset\":6962363,\"order_book\":{\"code\":0,\"asks\":[{\"price\":\"92948.8\",\"size\":\"0.00000\"}],\"bids\":[],\"offset\":6962363,\"nonce\":3691008782},\"timestamp\":1765394043265,\"type\":\"update/order_book\"}"
    "msg": "{\"channel\":\"order_book:1\",\"offset\":6962364,\"order_book\":{\"code\":0,\"asks\":[{\"price\":\"92941.0\",\"size\":\"0.01612\"},{\"price\":\"92943.7\",\"size\":\"0.00000\"},{\"price\":\"92948.2\",\"size\":\"0.00000\"}],\"bids\":[{\"price\":\"92926.5\",\"size\":\"0.00000\"},{\"price\":\"92919.4\",\"size\":\"0.02152\"},{\"price\":\"92726.9\",\"size\":\"0.00000\"}],\"offset\":6962364,\"nonce\":3691008783},\"timestamp\":1765394043270,\"type\":\"update/order_book\"}"
    "msg": "{\"channel\":\"order_book:1\",\"offset\":6962365,\"order_book\":{\"code\":0,\"asks\":[{\"price\":\"92945.7\",\"size\":\"0.11260\"}],\"bids\":[{\"price\":\"92928.0\",\"size\":\"1.94993\"},{\"price\":\"92908.2\",\"size\":\"0.02736\"},{\"price\":\"92907.2\",\"size\":\"0.00000\"},{\"price\":\"92898.5\",\"size\":\"0.00000\"}],\"offset\":6962365,\"nonce\":3691008784},\"timestamp\":1765394043272,\"type\":\"update/order_book\"}"
    "msg": "{\"channel\":\"order_book:1\",\"offset\":6962366,\"order_book\":{\"code\":0,\"asks\":[{\"price\":\"92945.7\",\"size\":\"0.10760\"}],\"bids\":[{\"price\":\"92918.9\",\"size\":\"0.00000\"},{\"price\":\"92866.8\",\"size\":\"0.38706\"}],\"offset\":6962366,\"nonce\":3691008785},\"timestamp\":1765394043277,\"type\":\"update/order_book\"}"
    "msg": "{\"channel\":\"order_book:1\",\"offset\":6962367,\"order_book\":{\"code\":0,\"asks\":[{\"price\":\"92947.9\",\"size\":\"0.04642\"},{\"price\":\"92982.9\",\"size\":\"0.08000\"}],\"bids\":[{\"price\":\"92933.4\",\"size\":\"0.38767\"},{\"price\":\"92930.5\",\"size\":\"4.16923\"},{\"price\":\"92924.0\",\"size\":\"0.00000\"},{\"price\":\"92923.2\",\"size\":\"0.01076\"},{\"price\":\"92905.6\",\"size\":\"0.08942\"},{\"price\":\"92904.7\",\"size\":\"0.00000\"},{\"price\":\"92902.9\",\"size\":\"0.00000\"}],\"offset\":6962367,\"nonce\":3691008786},\"timestamp\":1765394043282,\"type\":\"update/order_book\"}"
    "msg": "{\"channel\":\"order_book:1\",\"offset\":6962368,\"order_book\":{\"code\":0,\"asks\":[],\"bids\":[{\"price\":\"92922.4\",\"size\":\"0.00000\"}],\"offset\":6962368,\"nonce\":3691008787},\"timestamp\":1765394043287,\"type\":\"update/order_book\"}"
    "msg": "{\"channel\":\"order_book:1\",\"offset\":6962369,\"order_book\":{\"code\":0,\"asks\":[{\"price\":\"92973.9\",\"size\":\"0.08081\"}],\"bids\":[{\"price\":\"92919.4\",\"size\":\"0.00000\"},{\"price\":\"92916.7\",\"size\":\"0.02815\"},{\"price\":\"92914.4\",\"size\":\"0.11979\"}],\"offset\":6962369,\"nonce\":3691008788},\"timestamp\":1765394043292,\"type\":\"update/order_book\"}"
    "msg": "{\"channel\":\"order_book:1\",\"offset\":6962370,\"order_book\":{\"code\":0,\"asks\":[{\"price\":\"92945.8\",\"size\":\"0.00000\"},{\"price\":\"92970.1\",\"size\":\"0.00000\"},{\"price\":\"92991.6\",\"size\":\"0.02092\"}],\"bids\":[{\"price\":\"92923.5\",\"size\":\"0.38767\"},{\"price\":\"92923.2\",\"size\":\"0.00000\"}],\"offset\":6962370,\"nonce\":3691008789},\"timestamp\":1765394043298,\"type\":\"update/order_book\"}"
    "msg": "{\"channel\":\"order_book:1\",\"offset\":6962371,\"order_book\":{\"code\":0,\"asks\":[{\"price\":\"92985.4\",\"size\":\"0.00000\"},{\"price\":\"92988.7\",\"size\":\"0.00000\"},{\"price\":\"92996.7\",\"size\":\"2.29534\"}],\"bids\":[{\"price\":\"92933.4\",\"size\":\"0.38767\"},{\"price\":\"92928.0\",\"size\":\"1.92088\"},{\"price\":\"92923.6\",\"size\":\"0.82223\"},{\"price\":\"92922.8\",\"size\":\"0.02152\"},{\"price\":\"92912.5\",\"size\":\"0.11088\"},{\"price\":\"92912.2\",\"size\":\"4.63882\"}],\"offset\":6962371,\"nonce\":3691008790},\"timestamp\":1765394043304,\"type\":\"update/order_book\"}"
    "msg": "{\"channel\":\"order_book:1\",\"offset\":6962372,\"order_book\":{\"code\":0,\"asks\":[{\"price\":\"92961.5\",\"size\":\"0.00000\"},{\"price\":\"92966.1\",\"size\":\"0.28101\"}],\"bids\":[{\"price\":\"92906.0\",\"size\":\"0.11629\"},{\"price\":\"92855.2\",\"size\":\"0.00000\"}],\"offset\":6962372,\"nonce\":3691008791},\"timestamp\":1765394043307,\"type\":\"update/order_book\"}"
    "msg": "{\"channel\":\"order_book:1\",\"offset\":6962373,\"order_book\":{\"code\":0,\"asks\":[{\"price\":\"92954.7\",\"size\":\"0.00000\"},{\"price\":\"92985.4\",\"size\":\"0.38767\"}],\"bids\":[{\"price\":\"92934.4\",\"size\":\"0.03764\"},{\"price\":\"92930.6\",\"size\":\"0.02905\"},{\"price\":\"92920.3\",\"size\":\"0.00000\"},{\"price\":\"92854.8\",\"size\":\"0.00000\"}],\"offset\":6962373,\"nonce\":3691008792},\"timestamp\":1765394043312,\"type\":\"update/order_book\"}"
    "msg": "{\"channel\":\"order_book:1\",\"offset\":6962374,\"order_book\":{\"code\":0,\"asks\":[{\"price\":\"92934.8\",\"size\":\"0.00127\"}],\"bids\":[{\"price\":\"92929.6\",\"size\":\"0.00000\"},{\"price\":\"92925.9\",\"size\":\"0.02906\"},{\"price\":\"92922.8\",\"size\":\"0.00000\"},{\"price\":\"92917.5\",\"size\":\"0.00000\"},{\"price\":\"92915.0\",\"size\":\"0.10780\"},{\"price\":\"92906.1\",\"size\":\"0.00000\"}],\"offset\":6962374,\"nonce\":3691008793},\"timestamp\":1765394043316,\"type\":\"update/order_book\"}"
    "msg": "{\"channel\":\"order_book:1\",\"offset\":6962375,\"order_book\":{\"code\":0,\"asks\":[{\"price\":\"92965.9\",\"size\":\"0.00000\"},{\"price\":\"92969.7\",\"size\":\"0.36689\"},{\"price\":\"92978.9\",\"size\":\"0.11088\"}],\"bids\":[{\"price\":\"92926.5\",\"size\":\"0.01076\"},{\"price\":\"92907.3\",\"size\":\"0.00214\"},{\"price\":\"92902.1\",\"size\":\"0.00000\"},{\"price\":\"92873.5\",\"size\":\"0.12098\"}],\"offset\":6962375,\"nonce\":3691008794},\"timestamp\":1765394043318,\"type\":\"update/order_book\"}"
    "msg": "{\"channel\":\"order_book:1\",\"offset\":6962376,\"order_book\":{\"code\":0,\"asks\":[{\"price\":\"92943.0\",\"size\":\"0.00000\"},{\"price\":\"92969.6\",\"size\":\"0.00000\"},{\"price\":\"92976.0\",\"size\":\"0.00214\"}],\"bids\":[{\"price\":\"92924.4\",\"size\":\"0.08000\"},{\"price\":\"92907.1\",\"size\":\"0.00214\"},{\"price\":\"92904.9\",\"size\":\"0.00000\"},{\"price\":\"92689.1\",\"size\":\"0.00000\"}],\"offset\":6962376,\"nonce\":3691008795},\"timestamp\":1765394043323,\"type\":\"update/order_book\"}"
    "msg": "{\"channel\":\"order_book:1\",\"offset\":6962377,\"order_book\":{\"code\":0,\"asks\":[{\"price\":\"92956.2\",\"size\":\"0.08807\"}],\"bids\":[{\"price\":\"92926.4\",\"size\":\"1.71647\"},{\"price\":\"92896.8\",\"size\":\"0.00000\"},{\"price\":\"92757.9\",\"size\":\"2.24326\"}],\"offset\":6962377,\"nonce\":3691008796},\"timestamp\":1765394043325,\"type\":\"update/order_book\"}"
    "msg": "{\"channel\":\"order_book:1\",\"offset\":6962378,\"order_book\":{\"code\":0,\"asks\":[{\"price\":\"93109.8\",\"size\":\"0.00000\"}],\"bids\":[{\"price\":\"92926.5\",\"size\":\"0.00000\"}],\"offset\":6962378,\"nonce\":3691008797},\"timestamp\":1765394043336,\"type\":\"update/order_book\"}"
    "msg": "{\"channel\":\"order_book:1\",\"offset\":6962379,\"order_book\":{\"code\":0,\"asks\":[{\"price\":\"92934.8\",\"size\":\"0.00127\"},{\"price\":\"92947.9\",\"size\":\"0.00000\"},{\"price\":\"92955.3\",\"size\":\"0.00000\"},{\"price\":\"92956.2\",\"size\":\"0.00000\"},{\"price\":\"92961.6\",\"size\":\"0.00000\"},{\"price\":\"92974.1\",\"size\":\"0.00000\"},{\"price\":\"93139.3\",\"size\":\"0.00000\"}],\"bids\":[{\"price\":\"92895.8\",\"size\":\"0.12705\"},{\"price\":\"92892.8\",\"size\":\"0.00000\"},{\"price\":\"92864.8\",\"size\":\"0.00000\"}],\"offset\":6962379,\"nonce\":3691008798},\"timestamp\":1765394043340,\"type\":\"update/order_book\"}"
    "msg": "{\"channel\":\"order_book:1\",\"offset\":6962380,\"order_book\":{\"code\":0,\"asks\":[{\"price\":\"92941.0\",\"size\":\"0.00000\"},{\"price\":\"92968.3\",\"size\":\"0.00000\"},{\"price\":\"93001.8\",\"size\":\"0.00000\"},{\"price\":\"93132.2\",\"size\":\"2.19025\"}],\"bids\":[{\"price\":\"92931.9\",\"size\":\"0.81429\"},{\"price\":\"92930.5\",\"size\":\"3.09165\"},{\"price\":\"92926.4\",\"size\":\"1.69495\"}],\"offset\":6962380,\"nonce\":3691008799},\"timestamp\":1765394043344,\"type\":\"update/order_book\"}"
    "msg": "{\"channel\":\"order_book:1\",\"offset\":6962381,\"order_book\":{\"code\":0,\"asks\":[],\"bids\":[{\"price\":\"92934.4\",\"size\":\"0.03764\"}],\"offset\":6962381,\"nonce\":3691008800},\"timestamp\":1765394043345,\"type\":\"update/order_book\"}"
    "msg": "{\"channel\":\"order_book:1\",\"offset\":6962383,\"order_book\":{\"code\":0,\"asks\":[{\"price\":\"92961.9\",\"size\":\"0.00500\"},{\"price\":\"93016.1\",\"size\":\"0.11088\"}],\"bids\":[{\"price\":\"92931.9\",\"size\":\"0.81229\"},{\"price\":\"92930.6\",\"size\":\"0.11088\"},{\"price\":\"92930.1\",\"size\":\"0.01076\"},{\"price\":\"92916.3\",\"size\":\"0.00500\"},{\"price\":\"92908.2\",\"size\":\"0.00108\"},{\"price\":\"92904.8\",\"size\":\"0.00000\"}],\"offset\":6962383,\"nonce\":3691008802},\"timestamp\":1765394043356,\"type\":\"update/order_book\"}"
    "msg": "{\"channel\":\"order_book:1\",\"offset\":6962384,\"order_book\":{\"code\":0,\"asks\":[],\"bids\":[{\"price\":\"92931.0\",\"size\":\"0.00000\"},{\"price\":\"92868.5\",\"size\":\"0.00000\"}],\"offset\":6962384,\"nonce\":3691008803},\"timestamp\":1765394043358,\"type\":\"update/order_book\"}"
    "msg": "{\"channel\":\"order_book:1\",\"offset\":6962385,\"order_book\":{\"code\":0,\"asks\":[{\"price\":\"92961.8\",\"size\":\"0.00000\"},{\"price\":\"92967.9\",\"size\":\"0.00303\"}],\"bids\":[{\"price\":\"92932.0\",\"size\":\"0.10780\"},{\"price\":\"92930.1\",\"size\":\"0.00000\"},{\"price\":\"92928.1\",\"size\":\"0.00000\"},{\"price\":\"92886.0\",\"size\":\"0.00000\"}],\"offset\":6962385,\"nonce\":3691008804},\"timestamp\":1765394043363,\"type\":\"update/order_book\"}"
    "msg": "{\"channel\":\"order_book:1\",\"offset\":6962386,\"order_book\":{\"code\":0,\"asks\":[{\"price\":\"93059.5\",\"size\":\"0.00000\"}],\"bids\":[{\"price\":\"92926.4\",\"size\":\"1.71647\"}],\"offset\":6962386,\"nonce\":3691008805},\"timestamp\":1765394043368,\"type\":\"update/order_book\"}"
    "msg": "{\"channel\":\"order_book:1\",\"offset\":6962387,\"order_book\":{\"code\":0,\"asks\":[{\"price\":\"92945.7\",\"size\":\"0.00000\"},{\"price\":\"92947.1\",\"size\":\"0.00000\"},{\"price\":\"93007.9\",\"size\":\"0.00000\"}],\"bids\":[{\"price\":\"92932.0\",\"size\":\"0.13685\"},{\"price\":\"92931.9\",\"size\":\"0.80729\"},{\"price\":\"92885.9\",\"size\":\"0.00000\"}],\"offset\":6962387,\"nonce\":3691008806},\"timestamp\":1765394043371,\"type\":\"update/order_book\"}"
    "msg": "{\"channel\":\"order_book:1\",\"offset\":6962388,\"order_book\":{\"code\":0,\"asks\":[{\"price\":\"92985.8\",\"size\":\"0.00000\"}],\"bids\":[{\"price\":\"92926.3\",\"size\":\"0.38767\"},{\"price\":\"92925.9\",\"size\":\"0.00000\"},{\"price\":\"92923.6\",\"size\":\"0.00000\"},{\"price\":\"92622.7\",\"size\":\"2.57004\"}],\"offset\":6962388,\"nonce\":3691008807},\"timestamp\":1765394043376,\"type\":\"update/order_book\"}"
    "msg": "{\"channel\":\"order_book:1\",\"offset\":6962389,\"order_book\":{\"code\":0,\"asks\":[{\"price\":\"92953.6\",\"size\":\"0.00000\"},{\"price\":\"92955.9\",\"size\":\"0.00000\"},{\"price\":\"93042.5\",\"size\":\"0.00000\"}],\"bids\":[{\"price\":\"92931.9\",\"size\":\"0.80229\"},{\"price\":\"92929.9\",\"size\":\"2.69396\"},{\"price\":\"92880.9\",\"size\":\"0.00000\"},{\"price\":\"92866.6\",\"size\":\"5.92473\"}],\"offset\":6962389,\"nonce\":3691008808},\"timestamp\":1765394043383,\"type\":\"update/order_book\"}"
    "msg": "{\"channel\":\"order_book:1\",\"offset\":6962390,\"order_book\":{\"code\":0,\"asks\":[{\"price\":\"92934.8\",\"size\":\"0.00000\"},{\"price\":\"92965.1\",\"size\":\"0.16288\"}],\"bids\":[{\"price\":\"92932.0\",\"size\":\"0.10780\"}],\"offset\":6962390,\"nonce\":3691008809},\"timestamp\":1765394043395,\"type\":\"update/order_book\"}"
    "msg": "{\"channel\":\"order_book:1\",\"offset\":6962391,\"order_book\":{\"code\":0,\"asks\":[{\"price\":\"92957.0\",\"size\":\"0.10760\"},{\"price\":\"93283.9\",\"size\":\"0.00000\"}],\"bids\":[{\"price\":\"92934.4\",\"size\":\"0.03764\"},{\"price\":\"92931.9\",\"size\":\"1.59904\"},{\"price\":\"92930.1\",\"size\":\"0.01076\"},{\"price\":\"92895.8\",\"size\":\"0.00000\"}],\"offset\":6962391,\"nonce\":3691008810},\"timestamp\":1765394043399,\"type\":\"update/order_book\"}"
    "msg": "{\"channel\":\"order_book:1\",\"offset\":6962392,\"order_book\":{\"code\":0,\"asks\":[{\"price\":\"92944.3\",\"size\":\"0.00000\"},{\"price\":\"92957.0\",\"size\":\"0.00000\"}],\"bids\":[{\"price\":\"92921.3\",\"size\":\"0.02628\"},{\"price\":\"92908.8\",\"size\":\"0.00000\"}],\"offset\":6962392,\"nonce\":3691008811},\"timestamp\":1765394043404,\"type\":\"update/order_book\"}"
    "msg": "{\"channel\":\"order_book:1\",\"offset\":6962393,\"order_book\":{\"code\":0,\"asks\":[{\"price\":\"92943.1\",\"size\":\"0.00000\"},{\"price\":\"92952.5\",\"size\":\"1.07758\"},{\"price\":\"92955.5\",\"size\":\"2.69396\"},{\"price\":\"92957.1\",\"size\":\"0.12484\"},{\"price\":\"92996.7\",\"size\":\"0.00000\"},{\"price\":\"93006.0\",\"size\":\"2.29510\"}],\"bids\":[{\"price\":\"92623.8\",\"size\":\"1.04936\"}],\"offset\":6962393,\"nonce\":3691008812},\"timestamp\":1765394043408,\"type\":\"update/order_book\"}"
    "msg": "{\"channel\":\"order_book:1\",\"offset\":6962394,\"order_book\":{\"code\":0,\"asks\":[],\"bids\":[{\"price\":\"92940.9\",\"size\":\"0.73515\"},{\"price\":\"92935.6\",\"size\":\"0.00215\"},{\"price\":\"92932.0\",\"size\":\"0.13686\"},{\"price\":\"92914.4\",\"size\":\"4.76056\"},{\"price\":\"92912.2\",\"size\":\"0.00000\"},{\"price\":\"92877.0\",\"size\":\"0.00000\"},{\"price\":\"92876.8\",\"size\":\"0.00000\"}],\"offset\":6962394,\"nonce\":3691008813},\"timestamp\":1765394043412,\"type\":\"update/order_book\"}"
    "msg": "{\"channel\":\"order_book:1\",\"offset\":6962395,\"order_book\":{\"code\":0,\"asks\":[],\"bids\":[{\"price\":\"92933.5\",\"size\":\"0.02905\"},{\"price\":\"92928.0\",\"size\":\"2.02868\"},{\"price\":\"92915.0\",\"size\":\"0.00000\"},{\"price\":\"92908.2\",\"size\":\"0.00000\"},{\"price\":\"92892.4\",\"size\":\"0.00108\"},{\"price\":\"92844.3\",\"size\":\"0.31918\"},{\"price\":\"92817.1\",\"size\":\"0.00000\"}],\"offset\":6962395,\"nonce\":3691008814},\"timestamp\":1765394043412,\"type\":\"update/order_book\"}"
    "msg": "{\"channel\":\"order_book:1\",\"offset\":6962396,\"order_book\":{\"code\":0,\"asks\":[{\"price\":\"93256.1\",\"size\":\"0.00000\"}],\"bids\":[{\"price\":\"92914.4\",\"size\":\"4.64077\"},{\"price\":\"92896.8\",\"size\":\"0.01076\"},{\"price\":\"92741.3\",\"size\":\"0.00000\"}],\"offset\":6962396,\"nonce\":3691008815},\"timestamp\":1765394043415,\"type\":\"update/order_book\"}"
    "msg": "{\"channel\":\"order_book:1\",\"offset\":6962397,\"order_book\":{\"code\":0,\"asks\":[{\"price\":\"92967.9\",\"size\":\"0.00000\"},{\"price\":\"92995.3\",\"size\":\"0.10778\"}],\"bids\":[{\"price\":\"92934.4\",\"size\":\"0.87204\"},{\"price\":\"92883.1\",\"size\":\"0.00000\"}],\"offset\":6962397,\"nonce\":3691008816},\"timestamp\":1765394043418,\"type\":\"update/order_book\"}"
    "msg": "{\"channel\":\"order_book:1\",\"offset\":6962398,\"order_book\":{\"code\":0,\"asks\":[{\"price\":\"92952.5\",\"size\":\"1.05377\"},{\"price\":\"92978.9\",\"size\":\"0.00000\"}],\"bids\":[{\"price\":\"92773.2\",\"size\":\"0.00000\"},{\"price\":\"92770.4\",\"size\":\"1.89946\"}],\"offset\":6962398,\"nonce\":3691008818},\"timestamp\":1765394043428,\"type\":\"update/order_book\"}"
    "msg": "{\"channel\":\"order_book:1\",\"offset\":6962399,\"order_book\":{\"code\":0,\"asks\":[],\"bids\":[{\"price\":\"92933.5\",\"size\":\"0.05811\"},{\"price\":\"92930.1\",\"size\":\"0.00000\"},{\"price\":\"92896.8\",\"size\":\"0.00000\"},{\"price\":\"92890.1\",\"size\":\"0.00000\"}],\"offset\":6962399,\"nonce\":3691008819},\"timestamp\":1765394043431,\"type\":\"update/order_book\"}"
    "msg": "{\"channel\":\"order_book:1\",\"offset\":6962400,\"order_book\":{\"code\":0,\"asks\":[{\"price\":\"92971.7\",\"size\":\"0.08081\"}],\"bids\":[{\"price\":\"92933.5\",\"size\":\"0.00000\"},{\"price\":\"92898.8\",\"size\":\"0.11759\"}],\"offset\":6962400,\"nonce\":3691008820},\"timestamp\":1765394043437,\"type\":\"update/order_book\"}"
    "msg": "{\"channel\":\"order_book:1\",\"offset\":6962401,\"order_book\":{\"code\":0,\"asks\":[],\"bids\":[{\"price\":\"92934.5\",\"size\":\"0.02905\"},{\"price\":\"92934.4\",\"size\":\"0.83440\"},{\"price\":\"92931.8\",\"size\":\"0.01076\"},{\"price\":\"92923.4\",\"size\":\"0.11979\"}],\"offset\":6962401,\"nonce\":3691008821},\"timestamp\":1765394043442,\"type\":\"update/order_book\"}"
    "msg": "{\"channel\":\"order_book:1\",\"offset\":6962402,\"order_book\":{\"code\":0,\"asks\":[{\"price\":\"92952.5\",\"size\":\"1.04877\"}],\"bids\":[{\"price\":\"92940.9\",\"size\":\"0.74422\"},{\"price\":\"92934.7\",\"size\":\"0.00500\"},{\"price\":\"92932.0\",\"size\":\"0.10780\"},{\"price\":\"92912.7\",\"size\":\"0.00000\"}],\"offset\":6962402,\"nonce\":3691008822},\"timestamp\":1765394043444,\"type\":\"update/order_book\"}"
    "msg": "{\"channel\":\"order_book:1\",\"offset\":6962403,\"order_book\":{\"code\":0,\"asks\":[],\"bids\":[{\"price\":\"92940.9\",\"size\":\"1.84380\"},{\"price\":\"92934.5\",\"size\":\"0.05811\"},{\"price\":\"92931.8\",\"size\":\"0.00000\"},{\"price\":\"92928.0\",\"size\":\"1.92088\"}],\"offset\":6962403,\"nonce\":3691008823},\"timestamp\":1765394043448,\"type\":\"update/order_book\"}"
    "msg": "{\"channel\":\"order_book:1\",\"offset\":6962404,\"order_book\":{\"code\":0,\"asks\":[],\"bids\":[{\"price\":\"92864.2\",\"size\":\"0.02092\"},{\"price\":\"92842.6\",\"size\":\"0.00000\"}],\"offset\":6962404,\"nonce\":3691008824},\"timestamp\":1765394043454,\"type\":\"update/order_book\"}"
    "msg": "{\"channel\":\"order_book:1\",\"offset\":6962405,\"order_book\":{\"code\":0,\"asks\":[{\"price\":\"93014.2\",\"size\":\"0.11731\"}],\"bids\":[{\"price\":\"92930.5\",\"size\":\"0.93720\"},{\"price\":\"92896.7\",\"size\":\"0.00000\"},{\"price\":\"92854.7\",\"size\":\"0.31917\"},{\"price\":\"92832.4\",\"size\":\"0.00000\"},{\"price\":\"92802.2\",\"size\":\"0.00000\"}],\"offset\":6962405,\"nonce\":3691008826},\"timestamp\":1765394043461,\"type\":\"update/order_book\"}"
    "msg": "{\"channel\":\"order_book:1\",\"offset\":6962407,\"order_book\":{\"code\":0,\"asks\":[{\"price\":\"92966.1\",\"size\":\"0.00000\"},{\"price\":\"93145.8\",\"size\":\"1.76369\"}],\"bids\":[{\"price\":\"92933.4\",\"size\":\"0.98786\"}],\"offset\":6962407,\"nonce\":3691008828},\"timestamp\":1765394043466,\"type\":\"update/order_book\"}"
    "msg": "{\"channel\":\"order_book:1\",\"offset\":6962408,\"order_book\":{\"code\":0,\"asks\":[{\"price\":\"92975.9\",\"size\":\"0.03707\"},{\"price\":\"92983.6\",\"size\":\"0.12233\"},{\"price\":\"92997.5\",\"size\":\"0.22507\"},{\"price\":\"93011.6\",\"size\":\"0.50000\"},{\"price\":\"93036.6\",\"size\":\"1.00080\"}],\"bids\":[{\"price\":\"92934.5\",\"size\":\"0.08439\"},{\"price\":\"92930.6\",\"size\":\"0.00000\"}],\"offset\":6962408,\"nonce\":3691008829},\"timestamp\":1765394043470,\"type\":\"update/order_book\"}"
    "msg": "{\"channel\":\"order_book:1\",\"offset\":6962409,\"order_book\":{\"code\":0,\"asks\":[{\"price\":\"92975.2\",\"size\":\"2.15445\"}],\"bids\":[{\"price\":\"92934.5\",\"size\":\"0.19219\"},{\"price\":\"92932.0\",\"size\":\"0.00000\"}],\"offset\":6962409,\"nonce\":3691008830},\"timestamp\":1765394043475,\"type\":\"update/order_book\"}"
    "msg": "{\"channel\":\"order_book:1\",\"offset\":6962410,\"order_book\":{\"code\":0,\"asks\":[],\"bids\":[{\"price\":\"92926.4\",\"size\":\"0.85160\"},{\"price\":\"92859.3\",\"size\":\"0.00000\"}],\"offset\":6962410,\"nonce\":3691008831},\"timestamp\":1765394043483,\"type\":\"update/order_book\"}"
    "msg": "{\"channel\":\"order_book:1\",\"offset\":6962411,\"order_book\":{\"code\":0,\"asks\":[{\"price\":\"92953.0\",\"size\":\"0.10760\"}],\"bids\":[{\"price\":\"92921.3\",\"size\":\"0.00000\"},{\"price\":\"92909.0\",\"size\":\"0.00000\"}],\"offset\":6962411,\"nonce\":3691008832},\"timestamp\":1765394043487,\"type\":\"update/order_book\"}"
    "msg": "{\"channel\":\"order_book:1\",\"offset\":6962412,\"order_book\":{\"code\":0,\"asks\":[{\"price\":\"92990.3\",\"size\":\"0.29759\"}],\"bids\":[{\"price\":\"92940.9\",\"size\":\"0.76622\"},{\"price\":\"92915.7\",\"size\":\"0.03108\"},{\"price\":\"92908.1\",\"size\":\"0.00000\"}],\"offset\":6962412,\"nonce\":3691008833},\"timestamp\":1765394043491,\"type\":\"update/order_book\"}"
    "msg": "{\"channel\":\"order_book:1\",\"offset\":6962413,\"order_book\":{\"code\":0,\"asks\":[{\"price\":\"93006.0\",\"size\":\"0.00000\"},{\"price\":\"93006.3\",\"size\":\"2.29235\"}],\"bids\":[{\"price\":\"92914.4\",\"size\":\"0.00000\"},{\"price\":\"92909.0\",\"size\":\"4.64355\"}],\"offset\":6962413,\"nonce\":3691008834},\"timestamp\":1765394043493,\"type\":\"update/order_book\"}"
    "msg": "{\"channel\":\"order_book:1\",\"offset\":6962415,\"order_book\":{\"code\":0,\"asks\":[],\"bids\":[{\"price\":\"92940.9\",\"size\":\"1.57459\"},{\"price\":\"92940.2\",\"size\":\"0.38767\"},{\"price\":\"92937.4\",\"size\":\"0.38767\"},{\"price\":\"92932.2\",\"size\":\"0.01076\"},{\"price\":\"92926.4\",\"size\":\"0.02152\"},{\"price\":\"92915.4\",\"size\":\"0.11629\"},{\"price\":\"92906.0\",\"size\":\"0.00000\"}],\"offset\":6962415,\"nonce\":3691008836},\"timestamp\":1765394043505,\"type\":\"update/order_book\"}"
    "msg": "{\"channel\":\"order_book:1\",\"offset\":6962416,\"order_book\":{\"code\":0,\"asks\":[{\"price\":\"92975.9\",\"size\":\"0.06435\"},{\"price\":\"93036.8\",\"size\":\"0.73646\"}],\"bids\":[{\"price\":\"92945.1\",\"size\":\"0.26071\"},{\"price\":\"92943.0\",\"size\":\"0.38938\"},{\"price\":\"92937.3\",\"size\":\"0.01061\"},{\"price\":\"92932.2\",\"size\":\"0.00000\"},{\"price\":\"92914.9\",\"size\":\"0.03038\"},{\"price\":\"92902.2\",\"size\":\"8.19006\"},{\"price\":\"92853.9\",\"size\":\"0.31915\"},{\"price\":\"92829.7\",\"size\":\"0.00000\"}],\"offset\":6962416,\"nonce\":3691008837},\"timestamp\":1765394043510,\"type\":\"update/order_book\"}"
    "msg": "{\"channel\":\"order_book:1\",\"offset\":6962417,\"order_book\":{\"code\":0,\"asks\":[{\"price\":\"92974.6\",\"size\":\"0.00000\"},{\"price\":\"92995.3\",\"size\":\"0.11316\"}],\"bids\":[{\"price\":\"92942.9\",\"size\":\"0.00547\"},{\"price\":\"92927.4\",\"size\":\"0.00468\"},{\"price\":\"92897.8\",\"size\":\"0.01076\"},{\"price\":\"92857.5\",\"size\":\"0.00538\"},{\"price\":\"92836.6\",\"size\":\"0.00000\"}],\"offset\":6962417,\"nonce\":3691008838},\"timestamp\":1765394043518,\"type\":\"update/order_book\"}"
    "msg": "{\"channel\":\"order_book:1\",\"offset\":6962418,\"order_book\":{\"code\":0,\"asks\":[],\"bids\":[{\"price\":\"92940.9\",\"size\":\"1.56852\"},{\"price\":\"92904.0\",\"size\":\"0.00108\"},{\"price\":\"92892.4\",\"size\":\"0.00000\"}],\"offset\":6962418,\"nonce\":3691008839},\"timestamp\":1765394043521,\"type\":\"update/order_book\"}"
    "msg": "{\"channel\":\"order_book:1\",\"offset\":6962419,\"order_book\":{\"code\":0,\"asks\":[{\"price\":\"92956.6\",\"size\":\"0.00021\"},{\"price\":\"92979.4\",\"size\":\"0.05173\"},{\"price\":\"92981.4\",\"size\":\"0.04254\"},{\"price\":\"92985.4\",\"size\":\"0.43940\"},{\"price\":\"93073.9\",\"size\":\"0.51731\"}],\"bids\":[{\"price\":\"92941.0\",\"size\":\"0.02905\"},{\"price\":\"92940.9\",\"size\":\"1.54852\"},{\"price\":\"92934.7\",\"size\":\"0.04679\"},{\"price\":\"92897.8\",\"size\":\"0.00000\"},{\"price\":\"92894.2\",\"size\":\"0.05099\"}],\"offset\":6962419,\"nonce\":3691008840},\"timestamp\":1765394043528,\"type\":\"update/order_book\"}"
    "msg": "{\"channel\":\"order_book:1\",\"offset\":6962421,\"order_book\":{\"code\":0,\"asks\":[{\"price\":\"93093.5\",\"size\":\"1.18928\"}],\"bids\":[{\"price\":\"92939.1\",\"size\":\"0.10760\"},{\"price\":\"92934.5\",\"size\":\"0.05534\"},{\"price\":\"92916.5\",\"size\":\"0.00000\"}],\"offset\":6962421,\"nonce\":3691008842},\"timestamp\":1765394043533,\"type\":\"update/order_book\"}"
    "msg": "{\"channel\":\"order_book:1\",\"offset\":6962422,\"order_book\":{\"code\":0,\"asks\":[{\"price\":\"92952.5\",\"size\":\"1.04831\"},{\"price\":\"92970.7\",\"size\":\"0.00303\"}],\"bids\":[{\"price\":\"92940.5\",\"size\":\"0.03764\"},{\"price\":\"92929.9\",\"size\":\"0.00000\"}],\"offset\":6962422,\"nonce\":3691008844},\"timestamp\":1765394043542,\"type\":\"update/order_book\"}"
    "msg": "{\"channel\":\"order_book:1\",\"offset\":6962425,\"order_book\":{\"code\":0,\"asks\":[{\"price\":\"92991.5\",\"size\":\"0.05094\"},{\"price\":\"93004.1\",\"size\":\"0.10189\"},{\"price\":\"93178.9\",\"size\":\"0.76662\"}],\"bids\":[],\"offset\":6962425,\"nonce\":3691008847},\"timestamp\":1765394043561,\"type\":\"update/order_book\"}"
    "msg": "{\"channel\":\"order_book:1\",\"offset\":6962426,\"order_book\":{\"code\":0,\"asks\":[],\"bids\":[{\"price\":\"92940.9\",\"size\":\"1.54352\"}],\"offset\":6962426,\"nonce\":3691008848},\"timestamp\":1765394043564,\"type\":\"update/order_book\"}"
    "msg": "{\"channel\":\"order_book:1\",\"offset\":6962427,\"order_book\":{\"code\":0,\"asks\":[{\"price\":\"92953.3\",\"size\":\"0.08084\"},{\"price\":\"93086.8\",\"size\":\"8.07918\"},{\"price\":\"93318.9\",\"size\":\"1.02455\"}],\"bids\":[],\"offset\":6962427,\"nonce\":3691008849},\"timestamp\":1765394043567,\"type\":\"update/order_book\"}"
    "msg": "{\"channel\":\"order_book:1\",\"offset\":6962428,\"order_book\":{\"code\":0,\"asks\":[{\"price\":\"92955.3\",\"size\":\"0.08083\"}],\"bids\":[{\"price\":\"92930.3\",\"size\":\"0.08083\"},{\"price\":\"92909.0\",\"size\":\"0.00000\"}],\"offset\":6962428,\"nonce\":3691008850},\"timestamp\":1765394043574,\"type\":\"update/order_book\"}"
    "msg": "{\"channel\":\"order_book:1\",\"offset\":6962429,\"order_book\":{\"code\":0,\"asks\":[{\"price\":\"93000.2\",\"size\":\"2.29251\"},{\"price\":\"93006.3\",\"size\":\"0.00000\"}],\"bids\":[{\"price\":\"92945.1\",\"size\":\"0.26071\"},{\"price\":\"92943.1\",\"size\":\"0.80845\"},{\"price\":\"92943.0\",\"size\":\"1.23436\"},{\"price\":\"92931.3\",\"size\":\"4.64462\"},{\"price\":\"92928.0\",\"size\":\"0.98673\"},{\"price\":\"92927.9\",\"size\":\"0.00000\"}],\"offset\":6962429,\"nonce\":3691008851},\"timestamp\":1765394043574,\"type\":\"update/order_book\"}"
    "msg": "{\"channel\":\"order_book:1\",\"offset\":6962430,\"order_book\":{\"code\":0,\"asks\":[{\"price\":\"92954.7\",\"size\":\"0.00860\"},{\"price\":\"92988.7\",\"size\":\"0.27859\"}],\"bids\":[{\"price\":\"92945.1\",\"size\":\"0.00000\"},{\"price\":\"92943.1\",\"size\":\"0.83750\"}],\"offset\":6962430,\"nonce\":3691008853},\"timestamp\":1765394043581,\"type\":\"update/order_book\"}"
    "msg": "{\"channel\":\"order_book:1\",\"offset\":6962431,\"order_book\":{\"code\":0,\"asks\":[],\"bids\":[{\"price\":\"92945.2\",\"size\":\"0.79643\"},{\"price\":\"92941.0\",\"size\":\"1.07758\"},{\"price\":\"92940.8\",\"size\":\"2.15445\"},{\"price\":\"92901.8\",\"size\":\"0.00000\"},{\"price\":\"92893.0\",\"size\":\"0.00000\"}],\"offset\":6962431,\"nonce\":3691008854},\"timestamp\":1765394043584,\"type\":\"update/order_book\"}"
    "msg": "{\"channel\":\"order_book:1\",\"offset\":6962432,\"order_book\":{\"code\":0,\"asks\":[],\"bids\":[{\"price\":\"92945.1\",\"size\":\"0.83368\"},{\"price\":\"92883.0\",\"size\":\"0.10563\"}],\"offset\":6962432,\"nonce\":3691008855},\"timestamp\":1765394043589,\"type\":\"update/order_book\"}"
    "msg": "{\"channel\":\"order_book:1\",\"offset\":6962433,\"order_book\":{\"code\":0,\"asks\":[{\"price\":\"92952.5\",\"size\":\"1.99196\"},{\"price\":\"92963.8\",\"size\":\"0.00021\"},{\"price\":\"93011.6\",\"size\":\"0.00000\"}],\"bids\":[{\"price\":\"92935.9\",\"size\":\"0.00860\"},{\"price\":\"92914.6\",\"size\":\"0.00000\"},{\"price\":\"92218.0\",\"size\":\"0.00000\"}],\"offset\":6962433,\"nonce\":3691008856},\"timestamp\":1765394043595,\"type\":\"update/order_book\"}"
    "msg": "{\"channel\":\"order_book:1\",\"offset\":6962434,\"order_book\":{\"code\":0,\"asks\":[{\"price\":\"92957.4\",\"size\":\"0.00000\"},{\"price\":\"92971.6\",\"size\":\"0.08084\"}],\"bids\":[{\"price\":\"92932.8\",\"size\":\"0.08072\"},{\"price\":\"92887.8\",\"size\":\"15.06414\"},{\"price\":\"92874.0\",\"size\":\"15.06414\"},{\"price\":\"92860.2\",\"size\":\"15.06414\"},{\"price\":\"92680.8\",\"size\":\"0.00000\"},{\"price\":\"92667.0\",\"size\":\"0.00000\"},{\"price\":\"92653.2\",\"size\":\"0.00000\"}],\"offset\":6962434,\"nonce\":3691008857},\"timestamp\":1765394043599,\"type\":\"update/order_book\"}"
    "msg": "{\"channel\":\"order_book:1\",\"offset\":6962435,\"order_book\":{\"code\":0,\"asks\":[{\"price\":\"92952.5\",\"size\":\"1.04794\"},{\"price\":\"92955.0\",\"size\":\"0.00021\"},{\"price\":\"92959.4\",\"size\":\"0.08079\"},{\"price\":\"92961.9\",\"size\":\"0.08581\"},{\"price\":\"92963.6\",\"size\":\"0.08081\"}],\"bids\":[{\"price\":\"92943.0\",\"size\":\"1.23265\"},{\"price\":\"92942.9\",\"size\":\"0.00000\"},{\"price\":\"92936.3\",\"size\":\"0.02153\"},{\"price\":\"92929.5\",\"size\":\"0.38767\"},{\"price\":\"92928.0\",\"size\":\"0.00000\"},{\"price\":\"92927.4\",\"size\":\"0.00000\"},{\"price\":\"92924.6\",\"size\":\"2.69396\"}],\"offset\":6962435,\"nonce\":3691008858},\"timestamp\":1765394043603,\"type\":\"update/order_book\"}"
    "msg": "{\"channel\":\"order_book:1\",\"offset\":6962436,\"order_book\":{\"code\":0,\"asks\":[],\"bids\":[{\"price\":\"92914.0\",\"size\":\"0.00000\"}],\"offset\":6962436,\"nonce\":3691008859},\"timestamp\":1765394043610,\"type\":\"update/order_book\"}"
    "msg": "{\"channel\":\"order_book:1\",\"offset\":6962437,\"order_book\":{\"code\":0,\"asks\":[{\"price\":\"92952.4\",\"size\":\"0.84773\"},{\"price\":\"92954.0\",\"size\":\"0.10760\"},{\"price\":\"92954.9\",\"size\":\"0.00000\"}],\"bids\":[{\"price\":\"92926.3\",\"size\":\"0.38875\"},{\"price\":\"92904.0\",\"size\":\"0.00000\"}],\"offset\":6962437,\"nonce\":3691008860},\"timestamp\":1765394043612,\"type\":\"update/order_book\"}"
    "msg": "{\"channel\":\"order_book:1\",\"offset\":6962438,\"order_book\":{\"code\":0,\"asks\":[],\"bids\":[{\"price\":\"92945.2\",\"size\":\"0.79643\"},{\"price\":\"92900.2\",\"size\":\"0.01076\"}],\"offset\":6962438,\"nonce\":3691008861},\"timestamp\":1765394043621,\"type\":\"update/order_book\"}"
    "msg": "{\"channel\":\"order_book:1\",\"offset\":6962439,\"order_book\":{\"code\":0,\"asks\":[{\"price\":\"92970.7\",\"size\":\"0.00000\"},{\"price\":\"93000.2\",\"size\":\"0.00000\"},{\"price\":\"93005.9\",\"size\":\"2.29236\"}],\"bids\":[{\"price\":\"92939.1\",\"size\":\"0.00000\"},{\"price\":\"92937.5\",\"size\":\"0.10760\"},{\"price\":\"92931.3\",\"size\":\"4.64643\"},{\"price\":\"83069.6\",\"size\":\"0.00060\"}],\"offset\":6962439,\"nonce\":3691008862},\"timestamp\":1765394043625,\"type\":\"update/order_book\"}"
    "msg": "{\"channel\":\"order_book:1\",\"offset\":6962440,\"order_book\":{\"code\":0,\"asks\":[{\"price\":\"92952.5\",\"size\":\"1.04828\"}],\"bids\":[],\"offset\":6962440,\"nonce\":3691008864},\"timestamp\":1765394043636,\"type\":\"update/order_book\"}"
    "msg": "{\"channel\":\"order_book:1\",\"offset\":6962441,\"order_book\":{\"code\":0,\"asks\":[{\"price\":\"92952.5\",\"size\":\"1.93452\"},{\"price\":\"92953.1\",\"size\":\"0.03764\"}],\"bids\":[{\"price\":\"92945.2\",\"size\":\"1.60162\"},{\"price\":\"92945.1\",\"size\":\"0.00000\"}],\"offset\":6962441,\"nonce\":3691008865},\"timestamp\":1765394043644,\"type\":\"update/order_book\"}"
    "msg": "{\"channel\":\"order_book:1\",\"offset\":6962442,\"order_book\":{\"code\":0,\"asks\":[],\"bids\":[{\"price\":\"92945.2\",\"size\":\"0.80519\"},{\"price\":\"92943.1\",\"size\":\"0.00000\"},{\"price\":\"92943.0\",\"size\":\"0.00000\"},{\"price\":\"92940.9\",\"size\":\"0.00000\"},{\"price\":\"92940.2\",\"size\":\"0.00000\"},{\"price\":\"92937.5\",\"size\":\"0.00000\"},{\"price\":\"92935.6\",\"size\":\"0.00000\"}],\"offset\":6962442,\"nonce\":3691008866},\"timestamp\":1765394043645,\"type\":\"update/order_book\"}"
    "msg": "{\"channel\":\"order_book:1\",\"offset\":6962443,\"order_book\":{\"code\":0,\"asks\":[{\"price\":\"92952.4\",\"size\":\"1.73937\"}],\"bids\":[{\"price\":\"92937.4\",\"size\":\"0.00000\"},{\"price\":\"92926.7\",\"size\":\"1.06403\"}],\"offset\":6962443,\"nonce\":3691008867},\"timestamp\":1765394043653,\"type\":\"update/order_book\"}"
    "msg": "{\"channel\":\"order_book:1\",\"offset\":6962444,\"order_book\":{\"code\":0,\"asks\":[{\"price\":\"92952.5\",\"size\":\"0.88658\"}],\"bids\":[{\"price\":\"92900.2\",\"size\":\"0.00000\"},{\"price\":\"92851.4\",\"size\":\"5.92473\"}],\"offset\":6962444,\"nonce\":3691008868},\"timestamp\":1765394043658,\"type\":\"update/order_book\"}"
    "msg": "{\"channel\":\"order_book:1\",\"offset\":6962445,\"order_book\":{\"code\":0,\"asks\":[],\"bids\":[{\"price\":\"92756.8\",\"size\":\"0.10759\"}],\"offset\":6962445,\"nonce\":3691008869},\"timestamp\":1765394043660,\"type\":\"update/order_book\"}"
    "msg": "{\"channel\":\"order_book:1\",\"offset\":6962446,\"order_book\":{\"code\":0,\"asks\":[{\"price\":\"92952.4\",\"size\":\"1.73975\"},{\"price\":\"92955.4\",\"size\":\"0.38767\"}],\"bids\":[{\"price\":\"92945.2\",\"size\":\"0.00000\"},{\"price\":\"92932.8\",\"size\":\"4.72836\"},{\"price\":\"92931.3\",\"size\":\"0.00000\"},{\"price\":\"92916.3\",\"size\":\"0.00000\"},{\"price\":\"92906.3\",\"size\":\"0.00500\"},{\"price\":\"92903.1\",\"size\":\"0.01076\"}],\"offset\":6962446,\"nonce\":3691008870},\"timestamp\":1765394043662,\"type\":\"update/order_book\"}"
    "msg": "{\"channel\":\"order_book:1\",\"offset\":6962447,\"order_book\":{\"code\":0,\"asks\":[{\"price\":\"92974.7\",\"size\":\"0.00303\"},{\"price\":\"92992.3\",\"size\":\"2.29271\"},{\"price\":\"93005.9\",\"size\":\"0.00000\"}],\"bids\":[{\"price\":\"92937.3\",\"size\":\"0.00000\"}],\"offset\":6962447,\"nonce\":3691008871},\"timestamp\":1765394043668,\"type\":\"update/order_book\"}"
    "msg": "{\"channel\":\"order_book:1\",\"offset\":6962448,\"order_book\":{\"code\":0,\"asks\":[],\"bids\":[{\"price\":\"92941.6\",\"size\":\"0.02905\"},{\"price\":\"92927.8\",\"size\":\"0.00108\"},{\"price\":\"92926.3\",\"size\":\"0.38767\"}],\"offset\":6962448,\"nonce\":3691008873},\"timestamp\":1765394043674,\"type\":\"update/order_book\"}"
    "msg": "{\"channel\":\"order_book:1\",\"offset\":6962449,\"order_book\":{\"code\":0,\"asks\":[{\"price\":\"92953.1\",\"size\":\"0.00000\"}],\"bids\":[],\"offset\":6962449,\"nonce\":3691008875},\"timestamp\":1765394043677,\"type\":\"update/order_book\"}"
    "msg": "{\"channel\":\"order_book:1\",\"offset\":6962451,\"order_book\":{\"code\":0,\"asks\":[{\"price\":\"92952.3\",\"size\":\"0.21520\"},{\"price\":\"92954.0\",\"size\":\"0.00000\"}],\"bids\":[{\"price\":\"92935.3\",\"size\":\"0.10780\"}],\"offset\":6962451,\"nonce\":3691008881},\"timestamp\":1765394043688,\"type\":\"update/order_book\"}"
    "msg": "{\"channel\":\"order_book:1\",\"offset\":6962452,\"order_book\":{\"code\":0,\"asks\":[],\"bids\":[{\"price\":\"92935.3\",\"size\":\"0.34791\"}],\"offset\":6962452,\"nonce\":3691008884},\"timestamp\":1765394043692,\"type\":\"update/order_book\"}"
    "msg": "{\"channel\":\"order_book:1\",\"offset\":6962453,\"order_book\":{\"code\":0,\"asks\":[],\"bids\":[{\"price\":\"92932.2\",\"size\":\"0.00000\"}],\"offset\":6962453,\"nonce\":3691008885},\"timestamp\":1765394043695,\"type\":\"update/order_book\"}"
    "msg": "{\"channel\":\"order_book:1\",\"offset\":6962454,\"order_book\":{\"code\":0,\"asks\":[{\"price\":\"92947.3\",\"size\":\"1.07758\"}],\"bids\":[],\"offset\":6962454,\"nonce\":3691008887},\"timestamp\":1765394043702,\"type\":\"update/order_book\"}"
    "msg": "{\"channel\":\"order_book:1\",\"offset\":6962456,\"order_book\":{\"code\":0,\"asks\":[{\"price\":\"92952.2\",\"size\":\"0.00040\"},{\"price\":\"92952.3\",\"size\":\"1.15988\"}],\"bids\":[],\"offset\":6962456,\"nonce\":3691008891},\"timestamp\":1765394043713,\"type\":\"update/order_book\"}"
    "msg": "{\"channel\":\"order_book:1\",\"offset\":6962457,\"order_book\":{\"code\":0,\"asks\":[],\"bids\":[{\"price\":\"92941.6\",\"size\":\"0.00000\"},{\"price\":\"92941.0\",\"size\":\"1.07758\"},{\"price\":\"92934.5\",\"size\":\"0.02906\"},{\"price\":\"92932.3\",\"size\":\"0.00000\"}],\"offset\":6962457,\"nonce\":3691008894},\"timestamp\":1765394043715,\"type\":\"update/order_book\"}"
    "msg": "{\"channel\":\"order_book:1\",\"offset\":6962459,\"order_book\":{\"code\":0,\"asks\":[{\"price\":\"92947.2\",\"size\":\"0.00035\"},{\"price\":\"92947.3\",\"size\":\"1.07791\"},{\"price\":\"92955.5\",\"size\":\"0.00000\"},{\"price\":\"92992.2\",\"size\":\"2.29271\"},{\"price\":\"92992.3\",\"size\":\"0.00000\"}],\"bids\":[{\"price\":\"92934.6\",\"size\":\"0.00000\"},{\"price\":\"92920.4\",\"size\":\"4.64970\"}],\"offset\":6962459,\"nonce\":3691008896},\"timestamp\":1765394043732,\"type\":\"update/order_book\"}"
    "msg": "{\"channel\":\"order_book:1\",\"offset\":6962460,\"order_book\":{\"code\":0,\"asks\":[{\"price\":\"92947.2\",\"size\":\"0.93900\"},{\"price\":\"92947.3\",\"size\":\"1.87988\"},{\"price\":\"93023.3\",\"size\":\"0.50000\"}],\"bids\":[{\"price\":\"92934.5\",\"size\":\"0.00000\"},{\"price\":\"92932.3\",\"size\":\"0.01076\"}],\"offset\":6962460,\"nonce\":3691008897},\"timestamp\":1765394043739,\"type\":\"update/order_book\"}"
    "msg": "{\"channel\":\"order_book:1\",\"offset\":6962461,\"order_book\":{\"code\":0,\"asks\":[],\"bids\":[{\"price\":\"92934.7\",\"size\":\"0.07084\"},{\"price\":\"92917.6\",\"size\":\"0.10780\"}],\"offset\":6962461,\"nonce\":3691008899},\"timestamp\":1765394043741,\"type\":\"update/order_book\"}"
    "msg": "{\"channel\":\"order_book:1\",\"offset\":6962462,\"order_book\":{\"code\":0,\"asks\":[],\"bids\":[{\"price\":\"92941.0\",\"size\":\"1.07758\"},{\"price\":\"92919.0\",\"size\":\"0.02628\"}],\"offset\":6962462,\"nonce\":3691008900},\"timestamp\":1765394043749,\"type\":\"update/order_book\"}"
    "msg": "{\"channel\":\"order_book:1\",\"offset\":6962463,\"order_book\":{\"code\":0,\"asks\":[],\"bids\":[{\"price\":\"92851.4\",\"size\":\"0.00000\"}],\"offset\":6962463,\"nonce\":3691008901},\"timestamp\":1765394043751,\"type\":\"update/order_book\"}"
    "msg": "{\"channel\":\"order_book:1\",\"offset\":6962465,\"order_book\":{\"code\":0,\"asks\":[],\"bids\":[{\"price\":\"92916.5\",\"size\":\"0.00500\"},{\"price\":\"92906.3\",\"size\":\"0.00000\"}],\"offset\":6962465,\"nonce\":3691008907},\"timestamp\":1765394043773,\"type\":\"update/order_book\"}"
    "msg": "{\"channel\":\"order_book:1\",\"offset\":6962466,\"order_book\":{\"code\":0,\"asks\":[],\"bids\":[{\"price\":\"92941.0\",\"size\":\"2.02593\"},{\"price\":\"92940.5\",\"size\":\"0.00000\"},{\"price\":\"92928.6\",\"size\":\"0.02906\"}],\"offset\":6962466,\"nonce\":3691008909},\"timestamp\":1765394043788,\"type\":\"update/order_book\"}"
    "msg": "{\"channel\":\"order_book:1\",\"offset\":6962467,\"order_book\":{\"code\":0,\"asks\":[{\"price\":\"92952.3\",\"size\":\"1.05228\"},{\"price\":\"92953.4\",\"size\":\"0.10760\"}],\"bids\":[{\"price\":\"92941.0\",\"size\":\"2.02593\"},{\"price\":\"92934.8\",\"size\":\"0.10780\"},{\"price\":\"92932.9\",\"size\":\"0.00000\"}],\"offset\":6962467,\"nonce\":3691008910},\"timestamp\":1765394043827,\"type\":\"update/order_book\"}"
    "msg": "{\"channel\":\"order_book:1\",\"offset\":6962468,\"order_book\":{\"code\":0,\"asks\":[{\"price\":\"92951.9\",\"size\":\"2.69396\"},{\"price\":\"92973.0\",\"size\":\"0.00000\"},{\"price\":\"92983.6\",\"size\":\"0.00000\"}],\"bids\":[{\"price\":\"92937.0\",\"size\":\"0.10760\"},{\"price\":\"92935.3\",\"size\":\"0.00000\"},{\"price\":\"92934.7\",\"size\":\"0.04179\"},{\"price\":\"92915.4\",\"size\":\"0.00000\"}],\"offset\":6962468,\"nonce\":3691008911},\"timestamp\":1765394043843,\"type\":\"update/order_book\"}"
    "msg": "{\"channel\":\"order_book:1\",\"offset\":6962469,\"order_book\":{\"code\":0,\"asks\":[{\"price\":\"92947.2\",\"size\":\"0.00000\"},{\"price\":\"92947.3\",\"size\":\"1.07791\"},{\"price\":\"92950.0\",\"size\":\"0.10760\"},{\"price\":\"92951.4\",\"size\":\"0.10760\"},{\"price\":\"92952.3\",\"size\":\"0.94468\"},{\"price\":\"92953.0\",\"size\":\"0.00000\"},{\"price\":\"92963.0\",\"size\":\"0.12064\"},{\"price\":\"92973.6\",\"size\":\"0.12233\"}],\"bids\":[{\"price\":\"92880.7\",\"size\":\"8.07918\"}],\"offset\":6962469,\"nonce\":3691008912},\"timestamp\":1765394043866,\"type\":\"update/order_book\"}"
    "msg": "{\"channel\":\"order_book:1\",\"offset\":6962471,\"order_book\":{\"code\":0,\"asks\":[{\"price\":\"92955.0\",\"size\":\"0.00881\"}],\"bids\":[{\"price\":\"92935.1\",\"size\":\"0.03764\"},{\"price\":\"92927.8\",\"size\":\"0.00000\"},{\"price\":\"92915.4\",\"size\":\"0.00108\"},{\"price\":\"92914.0\",\"size\":\"0.00000\"},{\"price\":\"92866.6\",\"size\":\"0.00000\"}],\"offset\":6962471,\"nonce\":3691008914},\"timestamp\":1765394043888,\"type\":\"update/order_book\"}"
    "msg": "{\"channel\":\"order_book:1\",\"offset\":6962472,\"order_book\":{\"code\":0,\"asks\":[],\"bids\":[{\"price\":\"92941.1\",\"size\":\"1.27496\"},{\"price\":\"92921.1\",\"size\":\"0.10780\"},{\"price\":\"92917.6\",\"size\":\"0.00000\"},{\"price\":\"92913.0\",\"size\":\"0.08086\"},{\"price\":\"92824.7\",\"size\":\"0.41540\"},{\"price\":\"92792.8\",\"size\":\"0.78736\"}],\"offset\":6962472,\"nonce\":3691008915},\"timestamp\":1765394043892,\"type\":\"update/order_book\"}"
    "msg": "{\"channel\":\"order_book:1\",\"offset\":6962473,\"order_book\":{\"code\":0,\"asks\":[{\"price\":\"92950.0\",\"size\":\"0.00000\"},{\"price\":\"92953.4\",\"size\":\"0.00000\"},{\"price\":\"92955.4\",\"size\":\"0.00000\"}],\"bids\":[],\"offset\":6962473,\"nonce\":3691008916},\"timestamp\":1765394043901,\"type\":\"update/order_book\"}"
    "msg": "{\"channel\":\"order_book:1\",\"offset\":6962474,\"order_book\":{\"code\":0,\"asks\":[],\"bids\":[{\"price\":\"92936.2\",\"size\":\"0.00860\"}],\"offset\":6962474,\"nonce\":3691008917},\"timestamp\":1765394043911,\"type\":\"update/order_book\"}"
    "msg": "{\"channel\":\"order_book:1\",\"offset\":6962475,\"order_book\":{\"code\":0,\"asks\":[{\"price\":\"92951.4\",\"size\":\"0.00000\"}],\"bids\":[{\"price\":\"92932.3\",\"size\":\"0.00000\"}],\"offset\":6962475,\"nonce\":3691008918},\"timestamp\":1765394043916,\"type\":\"update/order_book\"}"
    "msg": "{\"channel\":\"order_book:1\",\"offset\":6962476,\"order_book\":{\"code\":0,\"asks\":[],\"bids\":[{\"price\":\"92941.1\",\"size\":\"1.27496\"},{\"price\":\"92932.4\",\"size\":\"0.01076\"}],\"offset\":6962476,\"nonce\":3691008919},\"timestamp\":1765394043921,\"type\":\"update/order_book\"}"
    "msg": "{\"channel\":\"order_book:1\",\"offset\":6962477,\"order_book\":{\"code\":0,\"asks\":[{\"price\":\"92952.3\",\"size\":\"0.00000\"},{\"price\":\"92952.4\",\"size\":\"0.00038\"},{\"price\":\"92952.5\",\"size\":\"0.00000\"}],\"bids\":[{\"price\":\"92937.3\",\"size\":\"0.10760\"},{\"price\":\"92934.8\",\"size\":\"0.00000\"},{\"price\":\"92933.2\",\"size\":\"0.02905\"},{\"price\":\"92904.7\",\"size\":\"0.11629\"}],\"offset\":6962477,\"nonce\":3691008920},\"timestamp\":1765394043930,\"type\":\"update/order_book\"}"
    "msg": "{\"channel\":\"order_book:1\",\"offset\":6962478,\"order_book\":{\"code\":0,\"asks\":[{\"price\":\"92947.2\",\"size\":\"0.00000\"},{\"price\":\"92952.2\",\"size\":\"0.00000\"},{\"price\":\"92952.4\",\"size\":\"0.00000\"},{\"price\":\"92956.0\",\"size\":\"0.16138\"},{\"price\":\"92986.3\",\"size\":\"0.00000\"}],\"bids\":[{\"price\":\"92939.6\",\"size\":\"0.10760\"},{\"price\":\"92937.3\",\"size\":\"0.13665\"},{\"price\":\"92937.0\",\"size\":\"0.00000\"},{\"price\":\"92933.2\",\"size\":\"0.00000\"},{\"price\":\"92932.4\",\"size\":\"0.01076\"}],\"offset\":6962478,\"nonce\":3691008921},\"timestamp\":1765394043935,\"type\":\"update/order_book\"}"
    "msg": "{\"channel\":\"order_book:1\",\"offset\":6962481,\"order_book\":{\"code\":0,\"asks\":[],\"bids\":[{\"price\":\"92940.8\",\"size\":\"2.18350\"},{\"price\":\"92937.3\",\"size\":\"0.10760\"},{\"price\":\"92928.6\",\"size\":\"0.00000\"},{\"price\":\"92922.1\",\"size\":\"0.11088\"}],\"offset\":6962481,\"nonce\":3691008924},\"timestamp\":1765394043959,\"type\":\"update/order_book\"}"
    "msg": "{\"channel\":\"order_book:1\",\"offset\":6962482,\"order_book\":{\"code\":0,\"asks\":[],\"bids\":[{\"price\":\"92943.9\",\"size\":\"0.38767\"},{\"price\":\"92937.1\",\"size\":\"0.00215\"},{\"price\":\"92934.7\",\"size\":\"0.07085\"}],\"offset\":6962482,\"nonce\":3691008925},\"timestamp\":1765394043961,\"type\":\"update/order_book\"}"
    "msg": "{\"channel\":\"order_book:1\",\"offset\":6962483,\"order_book\":{\"code\":0,\"asks\":[{\"price\":\"92947.3\",\"size\":\"0.00000\"},{\"price\":\"92951.9\",\"size\":\"0.00000\"},{\"price\":\"92956.0\",\"size\":\"0.05378\"},{\"price\":\"92958.0\",\"size\":\"0.00860\"},{\"price\":\"92992.2\",\"size\":\"0.00000\"}],\"bids\":[{\"price\":\"92943.9\",\"size\":\"0.38567\"},{\"price\":\"92941.0\",\"size\":\"0.95373\"},{\"price\":\"92915.4\",\"size\":\"0.00000\"},{\"price\":\"92915.2\",\"size\":\"0.00108\"},{\"price\":\"92912.3\",\"size\":\"0.00000\"}],\"offset\":6962483,\"nonce\":3691008926},\"timestamp\":1765394043971,\"type\":\"update/order_book\"}"
    "msg": "{\"channel\":\"order_book:1\",\"offset\":6962484,\"order_book\":{\"code\":0,\"asks\":[{\"price\":\"92993.3\",\"size\":\"2.29268\"}],\"bids\":[{\"price\":\"92924.6\",\"size\":\"0.00000\"},{\"price\":\"92923.8\",\"size\":\"0.10780\"},{\"price\":\"92921.1\",\"size\":\"0.00000\"},{\"price\":\"92920.4\",\"size\":\"0.00000\"},{\"price\":\"92920.2\",\"size\":\"4.65452\"}],\"offset\":6962484,\"nonce\":3691008927},\"timestamp\":1765394043974,\"type\":\"update/order_book\"}"
    "msg": "{\"channel\":\"order_book:1\",\"offset\":6962485,\"order_book\":{\"code\":0,\"asks\":[{\"price\":\"92953.7\",\"size\":\"0.00000\"}],\"bids\":[{\"price\":\"92946.2\",\"size\":\"0.22482\"},{\"price\":\"92940.8\",\"size\":\"2.15445\"},{\"price\":\"92926.4\",\"size\":\"0.00000\"},{\"price\":\"92903.1\",\"size\":\"0.00000\"}],\"offset\":6962485,\"nonce\":3691008928},\"timestamp\":1765394043980,\"type\":\"update/order_book\"}"
    "msg": "{\"channel\":\"order_book:1\",\"offset\":6962486,\"order_book\":{\"code\":0,\"asks\":[{\"price\":\"92955.0\",\"size\":\"0.00021\"},{\"price\":\"92958.0\",\"size\":\"0.00000\"}],\"bids\":[{\"price\":\"92946.9\",\"size\":\"0.38767\"},{\"price\":\"92935.5\",\"size\":\"0.00860\"},{\"price\":\"92932.4\",\"size\":\"0.00000\"},{\"price\":\"92912.1\",\"size\":\"0.00000\"}],\"offset\":6962486,\"nonce\":3691008929},\"timestamp\":1765394043984,\"type\":\"update/order_book\"}"
    "msg": "{\"channel\":\"order_book:1\",\"offset\":6962487,\"order_book\":{\"code\":0,\"asks\":[{\"price\":\"92956.0\",\"size\":\"0.00000\"},{\"price\":\"92956.6\",\"size\":\"0.00000\"},{\"price\":\"92974.7\",\"size\":\"0.00000\"}],\"bids\":[{\"price\":\"92941.2\",\"size\":\"0.02905\"},{\"price\":\"92929.9\",\"size\":\"0.02152\"},{\"price\":\"92920.5\",\"size\":\"0.38767\"},{\"price\":\"92904.3\",\"size\":\"0.01076\"}],\"offset\":6962487,\"nonce\":3691008930},\"timestamp\":1765394043990,\"type\":\"update/order_book\"}"
    "msg": "{\"channel\":\"order_book:1\",\"offset\":6962488,\"order_book\":{\"code\":0,\"asks\":[],\"bids\":[{\"price\":\"92936.5\",\"size\":\"0.00021\"},{\"price\":\"92936.3\",\"size\":\"0.00000\"},{\"price\":\"92933.4\",\"size\":\"0.99862\"},{\"price\":\"92929.9\",\"size\":\"0.00000\"}],\"offset\":6962488,\"nonce\":3691008931},\"timestamp\":1765394043993,\"type\":\"update/order_book\"}"
    "msg": "{\"channel\":\"order_book:1\",\"offset\":6962489,\"order_book\":{\"code\":0,\"asks\":[{\"price\":\"92963.0\",\"size\":\"0.00000\"},{\"price\":\"92973.6\",\"size\":\"0.00000\"}],\"bids\":[{\"price\":\"92933.4\",\"size\":\"0.98786\"},{\"price\":\"92904.7\",\"size\":\"0.00000\"},{\"price\":\"92904.3\",\"size\":\"0.00000\"}],\"offset\":6962489,\"nonce\":3691008932},\"timestamp\":1765394044000,\"type\":\"update/order_book\"}"
    "msg": "{\"channel\":\"order_book:1\",\"offset\":6962490,\"order_book\":{\"code\":0,\"asks\":[],\"bids\":[{\"price\":\"92931.0\",\"size\":\"0.02152\"},{\"price\":\"92914.2\",\"size\":\"0.11629\"}],\"offset\":6962490,\"nonce\":3691008933},\"timestamp\":1765394044003,\"type\":\"update/order_book\"}"
    "msg": "{\"channel\":\"order_book:1\",\"offset\":6962491,\"order_book\":{\"code\":0,\"asks\":[{\"price\":\"92969.7\",\"size\":\"0.00000\"},{\"price\":\"92976.0\",\"size\":\"0.00000\"}],\"bids\":[{\"price\":\"92947.2\",\"size\":\"0.86505\"},{\"price\":\"92943.9\",\"size\":\"1.34341\"},{\"price\":\"92941.2\",\"size\":\"0.13665\"},{\"price\":\"92937.3\",\"size\":\"0.00000\"},{\"price\":\"92907.3\",\"size\":\"0.00000\"},{\"price\":\"92907.1\",\"size\":\"0.00000\"}],\"offset\":6962491,\"nonce\":3691008934},\"timestamp\":1765394044008,\"type\":\"update/order_book\"}"
    "msg": "{\"channel\":\"order_book:1\",\"offset\":6962492,\"order_book\":{\"code\":0,\"asks\":[{\"price\":\"92951.6\",\"size\":\"0.00210\"},{\"price\":\"92960.8\",\"size\":\"0.10760\"},{\"price\":\"92964.1\",\"size\":\"0.00000\"},{\"price\":\"92965.8\",\"size\":\"0.47573\"}],\"bids\":[{\"price\":\"92941.2\",\"size\":\"0.24425\"},{\"price\":\"92939.6\",\"size\":\"0.00000\"},{\"price\":\"92935.1\",\"size\":\"0.00000\"},{\"price\":\"92934.1\",\"size\":\"0.09804\"}],\"offset\":6962492,\"nonce\":3691008935},\"timestamp\":1765394044009,\"type\":\"update/order_book\"}"
    "msg": "{\"channel\":\"order_book:1\",\"offset\":6962493,\"order_book\":{\"code\":0,\"asks\":[{\"price\":\"92957.8\",\"size\":\"2.69396\"},{\"price\":\"92983.1\",\"size\":\"0.00214\"},{\"price\":\"92993.3\",\"size\":\"0.00000\"},{\"price\":\"92996.3\",\"size\":\"2.29259\"}],\"bids\":[{\"price\":\"92947.2\",\"size\":\"0.86505\"},{\"price\":\"92946.4\",\"size\":\"1.07758\"},{\"price\":\"92941.2\",\"size\":\"0.21520\"},{\"price\":\"92936.1\",\"size\":\"0.01076\"},{\"price\":\"92920.2\",\"size\":\"0.00000\"},{\"price\":\"92913.1\",\"size\":\"0.36711\"}],\"offset\":6962493,\"nonce\":3691008937},\"timestamp\":1765394044017,\"type\":\"update/order_book\"}"
    "msg": "{\"channel\":\"order_book:1\",\"offset\":6962494,\"order_book\":{\"code\":0,\"asks\":[{\"price\":\"92958.4\",\"size\":\"0.10760\"}],\"bids\":[{\"price\":\"92942.6\",\"size\":\"0.02905\"},{\"price\":\"92937.1\",\"size\":\"0.00000\"},{\"price\":\"92936.1\",\"size\":\"0.00000\"},{\"price\":\"92929.5\",\"size\":\"3.08163\"},{\"price\":\"92920.2\",\"size\":\"4.65585\"}],\"offset\":6962494,\"nonce\":3691008938},\"timestamp\":1765394044021,\"type\":\"update/order_book\"}"
    "msg": "{\"channel\":\"order_book:1\",\"offset\":6962495,\"order_book\":{\"code\":0,\"asks\":[{\"price\":\"92951.6\",\"size\":\"0.00000\"},{\"price\":\"92953.3\",\"size\":\"0.07794\"}],\"bids\":[{\"price\":\"92946.2\",\"size\":\"1.14898\"}],\"offset\":6962495,\"nonce\":3691008939},\"timestamp\":1765394044028,\"type\":\"update/order_book\"}"
    "msg": "{\"channel\":\"order_book:1\",\"offset\":6962496,\"order_book\":{\"code\":0,\"asks\":[],\"bids\":[{\"price\":\"92946.9\",\"size\":\"1.29602\"}],\"offset\":6962496,\"nonce\":3691008940},\"timestamp\":1765394044034,\"type\":\"update/order_book\"}"
    "msg": "{\"channel\":\"order_book:1\",\"offset\":6962497,\"order_book\":{\"code\":0,\"asks\":[],\"bids\":[{\"price\":\"92936.5\",\"size\":\"0.01097\"}],\"offset\":6962497,\"nonce\":3691008941},\"timestamp\":1765394044040,\"type\":\"update/order_book\"}"
    "msg": "{\"channel\":\"order_book:1\",\"offset\":6962498,\"order_book\":{\"code\":0,\"asks\":[{\"price\":\"92954.7\",\"size\":\"0.00000\"},{\"price\":\"93021.2\",\"size\":\"0.08000\"}],\"bids\":[{\"price\":\"92906.1\",\"size\":\"0.01076\"}],\"offset\":6962498,\"nonce\":3691008942},\"timestamp\":1765394044041,\"type\":\"update/order_book\"}"
    "msg": "{\"channel\":\"order_book:1\",\"offset\":6962499,\"order_book\":{\"code\":0,\"asks\":[{\"price\":\"92977.8\",\"size\":\"0.00303\"}],\"bids\":[{\"price\":\"92936.5\",\"size\":\"0.00021\"},{\"price\":\"92930.5\",\"size\":\"0.00000\"},{\"price\":\"92840.5\",\"size\":\"0.00000\"}],\"offset\":6962499,\"nonce\":3691008944},\"timestamp\":1765394044059,\"type\":\"update/order_book\"}"
    "msg": "{\"channel\":\"order_book:1\",\"offset\":6962500,\"order_book\":{\"code\":0,\"asks\":[{\"price\":\"92952.2\",\"size\":\"0.00020\"}],\"bids\":[{\"price\":\"92947.2\",\"size\":\"1.74075\"},{\"price\":\"92942.6\",\"size\":\"0.00000\"}],\"offset\":6962500,\"nonce\":3691008945},\"timestamp\":1765394044063,\"type\":\"update/order_book\"}"
    "msg": "{\"channel\":\"order_book:1\",\"offset\":6962501,\"order_book\":{\"code\":0,\"asks\":[{\"price\":\"92972.5\",\"size\":\"0.12064\"},{\"price\":\"92996.3\",\"size\":\"0.00000\"},{\"price\":\"92997.3\",\"size\":\"2.29257\"}],\"bids\":[{\"price\":\"92944.6\",\"size\":\"0.02905\"},{\"price\":\"92936.5\",\"size\":\"0.01097\"},{\"price\":\"92931.9\",\"size\":\"0.80229\"},{\"price\":\"92920.2\",\"size\":\"4.65711\"}],\"offset\":6962501,\"nonce\":3691008946},\"timestamp\":1765394044068,\"type\":\"update/order_book\"}"
    "msg": "{\"channel\":\"order_book:1\",\"offset\":6962502,\"order_book\":{\"code\":0,\"asks\":[{\"price\":\"92983.1\",\"size\":\"0.12447\"}],\"bids\":[{\"price\":\"92942.1\",\"size\":\"0.00215\"},{\"price\":\"92929.0\",\"size\":\"0.10780\"},{\"price\":\"92923.8\",\"size\":\"0.00000\"},{\"price\":\"92880.7\",\"size\":\"0.00000\"}],\"offset\":6962502,\"nonce\":3691008947},\"timestamp\":1765394044070,\"type\":\"update/order_book\"}"
    "msg": "{\"channel\":\"order_book:1\",\"offset\":6962503,\"order_book\":{\"code\":0,\"asks\":[],\"bids\":[{\"price\":\"92913.0\",\"size\":\"0.00000\"}],\"offset\":6962503,\"nonce\":3691008948},\"timestamp\":1765394044073,\"type\":\"update/order_book\"}"
    "msg": "{\"channel\":\"order_book:1\",\"offset\":6962504,\"order_book\":{\"code\":0,\"asks\":[{\"price\":\"92968.1\",\"size\":\"0.08082\"}],\"bids\":[{\"price\":\"92940.8\",\"size\":\"0.00000\"},{\"price\":\"92451.4\",\"size\":\"19.20598\"}],\"offset\":6962504,\"nonce\":3691008949},\"timestamp\":1765394044079,\"type\":\"update/order_book\"}"
    "msg": "{\"channel\":\"order_book:1\",\"offset\":6962505,\"order_book\":{\"code\":0,\"asks\":[{\"price\":\"92959.6\",\"size\":\"1.07758\"},{\"price\":\"92985.2\",\"size\":\"0.08081\"},{\"price\":\"92985.3\",\"size\":\"0.08086\"}],\"bids\":[{\"price\":\"92911.9\",\"size\":\"0.00000\"}],\"offset\":6962505,\"nonce\":3691008950},\"timestamp\":1765394044082,\"type\":\"update/order_book\"}"
    "msg": "{\"channel\":\"order_book:1\",\"offset\":6962506,\"order_book\":{\"code\":0,\"asks\":[{\"price\":\"92955.0\",\"size\":\"0.00000\"}],\"bids\":[{\"price\":\"92942.0\",\"size\":\"0.03764\"},{\"price\":\"92905.6\",\"size\":\"0.00860\"}],\"offset\":6962506,\"nonce\":3691008951},\"timestamp\":1765394044084,\"type\":\"update/order_book\"}"
    "msg": "{\"channel\":\"order_book:1\",\"offset\":6962507,\"order_book\":{\"code\":0,\"asks\":[{\"price\":\"93029.3\",\"size\":\"0.00020\"}],\"bids\":[{\"price\":\"92936.5\",\"size\":\"0.00021\"},{\"price\":\"92906.1\",\"size\":\"0.00000\"}],\"offset\":6962507,\"nonce\":3691008952},\"timestamp\":1765394044090,\"type\":\"update/order_book\"}"
    "msg": "{\"channel\":\"order_book:1\",\"offset\":6962508,\"order_book\":{\"code\":0,\"asks\":[{\"price\":\"92953.2\",\"size\":\"0.00021\"}],\"bids\":[],\"offset\":6962508,\"nonce\":3691008953},\"timestamp\":1765394044097,\"type\":\"update/order_book\"}"
    "msg": "{\"channel\":\"order_book:1\",\"offset\":6962509,\"order_book\":{\"code\":0,\"asks\":[{\"price\":\"92952.2\",\"size\":\"0.00000\"},{\"price\":\"92957.2\",\"size\":\"0.03764\"},{\"price\":\"92961.0\",\"size\":\"0.05378\"},{\"price\":\"92977.8\",\"size\":\"0.00000\"},{\"price\":\"93021.2\",\"size\":\"0.08020\"}],\"bids\":[{\"price\":\"92946.4\",\"size\":\"1.18518\"},{\"price\":\"92941.2\",\"size\":\"0.10760\"},{\"price\":\"92934.5\",\"size\":\"0.13448\"},{\"price\":\"92925.5\",\"size\":\"0.05380\"},{\"price\":\"92920.2\",\"size\":\"4.65793\"},{\"price\":\"92877.7\",\"size\":\"0.13448\"},{\"price\":\"92861.5\",\"size\":\"0.13448\"},{\"price\":\"92853.4\",\"size\":\"0.00000\"}],\"offset\":6962509,\"nonce\":3691008954},\"timestamp\":1765394044101,\"type\":\"update/order_book\"}"
    "msg": "{\"channel\":\"order_book:1\",\"offset\":6962510,\"order_book\":{\"code\":0,\"asks\":[{\"price\":\"92960.8\",\"size\":\"0.00000\"},{\"price\":\"92962.8\",\"size\":\"0.10760\"},{\"price\":\"92970.7\",\"size\":\"0.00021\"},{\"price\":\"92997.3\",\"size\":\"0.00000\"},{\"price\":\"93001.4\",\"size\":\"2.29246\"}],\"bids\":[{\"price\":\"92947.2\",\"size\":\"1.74075\"},{\"price\":\"92943.7\",\"size\":\"0.10760\"},{\"price\":\"92941.2\",\"size\":\"0.00000\"}],\"offset\":6962510,\"nonce\":3691008955},\"timestamp\":1765394044106,\"type\":\"update/order_book\"}"
    "msg": "{\"channel\":\"order_book:1\",\"offset\":6962511,\"order_book\":{\"code\":0,\"asks\":[],\"bids\":[{\"price\":\"92907.4\",\"size\":\"0.01076\"}],\"offset\":6962511,\"nonce\":3691008956},\"timestamp\":1765394044113,\"type\":\"update/order_book\"}"
    "msg": "{\"channel\":\"order_book:1\",\"offset\":6962512,\"order_book\":{\"code\":0,\"asks\":[{\"price\":\"92959.6\",\"size\":\"0.00000\"}],\"bids\":[],\"offset\":6962512,\"nonce\":3691008958},\"timestamp\":1765394044122,\"type\":\"update/order_book\"}"
    "msg": "{\"channel\":\"order_book:1\",\"offset\":6962513,\"order_book\":{\"code\":0,\"asks\":[{\"price\":\"92958.4\",\"size\":\"0.00000\"},{\"price\":\"92960.2\",\"size\":\"0.49527\"}],\"bids\":[],\"offset\":6962513,\"nonce\":3691008959},\"timestamp\":1765394044126,\"type\":\"update/order_book\"}"
    "msg": "{\"channel\":\"order_book:1\",\"offset\":6962514,\"order_book\":{\"code\":0,\"asks\":[],\"bids\":[{\"price\":\"92945.3\",\"size\":\"2.15445\"},{\"price\":\"92937.5\",\"size\":\"0.01075\"}],\"offset\":6962514,\"nonce\":3691008960},\"timestamp\":1765394044130,\"type\":\"update/order_book\"}"
    "msg": "{\"channel\":\"order_book:1\",\"offset\":6962515,\"order_book\":{\"code\":0,\"asks\":[{\"price\":\"92953.2\",\"size\":\"0.00000\"}],\"bids\":[{\"price\":\"92947.2\",\"size\":\"1.74075\"},{\"price\":\"92917.1\",\"size\":\"0.00108\"},{\"price\":\"92915.2\",\"size\":\"0.00000\"}],\"offset\":6962515,\"nonce\":3691008961},\"timestamp\":1765394044138,\"type\":\"update/order_book\"}"
    "msg": "{\"channel\":\"order_book:1\",\"offset\":6962516,\"order_book\":{\"code\":0,\"asks\":[],\"bids\":[{\"price\":\"92885.0\",\"size\":\"8.07918\"}],\"offset\":6962516,\"nonce\":3691008962},\"timestamp\":1765394044146,\"type\":\"update/order_book\"}"
    "msg": "{\"channel\":\"order_book:1\",\"offset\":6962517,\"order_book\":{\"code\":0,\"asks\":[{\"price\":\"93029.3\",\"size\":\"0.13448\"}],\"bids\":[{\"price\":\"92937.5\",\"size\":\"0.00000\"}],\"offset\":6962517,\"nonce\":3691008963},\"timestamp\":1765394044155,\"type\":\"update/order_book\"}"
    "msg": "{\"channel\":\"order_book:1\",\"offset\":6962518,\"order_book\":{\"code\":0,\"asks\":[{\"price\":\"92991.6\",\"size\":\"0.00000\"},{\"price\":\"92999.2\",\"size\":\"2.29252\"},{\"price\":\"93001.4\",\"size\":\"0.00000\"},{\"price\":\"93013.2\",\"size\":\"0.02092\"}],\"bids\":[{\"price\":\"92922.1\",\"size\":\"4.76977\"},{\"price\":\"92920.2\",\"size\":\"0.00000\"},{\"price\":\"92807.9\",\"size\":\"0.00269\"},{\"price\":\"92773.4\",\"size\":\"0.00000\"}],\"offset\":6962518,\"nonce\":3691008964},\"timestamp\":1765394044158,\"type\":\"update/order_book\"}"
    "msg": "{\"channel\":\"order_book:1\",\"offset\":6962519,\"order_book\":{\"code\":0,\"asks\":[{\"price\":\"92979.0\",\"size\":\"0.00303\"}],\"bids\":[{\"price\":\"92937.5\",\"size\":\"0.01075\"},{\"price\":\"92926.9\",\"size\":\"0.02815\"},{\"price\":\"92916.7\",\"size\":\"0.00000\"}],\"offset\":6962519,\"nonce\":3691008967},\"timestamp\":1765394044170,\"type\":\"update/order_book\"}"
    "msg": "{\"channel\":\"order_book:1\",\"offset\":6962520,\"order_book\":{\"code\":0,\"asks\":[{\"price\":\"93021.2\",\"size\":\"0.21448\"}],\"bids\":[],\"offset\":6962520,\"nonce\":3691008968},\"timestamp\":1765394044174,\"type\":\"update/order_book\"}"
    "msg": "{\"channel\":\"order_book:1\",\"offset\":6962521,\"order_book\":{\"code\":0,\"asks\":[{\"price\":\"92958.4\",\"size\":\"1.07758\"}],\"bids\":[{\"price\":\"92930.3\",\"size\":\"0.18863\"},{\"price\":\"92929.0\",\"size\":\"0.00000\"}],\"offset\":6962521,\"nonce\":3691008969},\"timestamp\":1765394044183,\"type\":\"update/order_book\"}"
    "msg": "{\"channel\":\"order_book:1\",\"offset\":6962522,\"order_book\":{\"code\":0,\"asks\":[],\"bids\":[{\"price\":\"92931.0\",\"size\":\"0.00000\"}],\"offset\":6962522,\"nonce\":3691008970},\"timestamp\":1765394044190,\"type\":\"update/order_book\"}"
    "msg": "{\"channel\":\"order_book:1\",\"offset\":6962523,\"order_book\":{\"code\":0,\"asks\":[{\"price\":\"92957.1\",\"size\":\"0.00000\"}],\"bids\":[{\"price\":\"92917.7\",\"size\":\"0.00000\"},{\"price\":\"92907.4\",\"size\":\"0.00000\"}],\"offset\":6962523,\"nonce\":3691008971},\"timestamp\":1765394044196,\"type\":\"update/order_book\"}"
    "msg": "{\"channel\":\"order_book:1\",\"offset\":6962524,\"order_book\":{\"code\":0,\"asks\":[{\"price\":\"92999.2\",\"size\":\"0.00000\"},{\"price\":\"93003.6\",\"size\":\"2.29241\"}],\"bids\":[{\"price\":\"92934.8\",\"size\":\"0.02152\"},{\"price\":\"92922.1\",\"size\":\"4.77065\"}],\"offset\":6962524,\"nonce\":3691008972},\"timestamp\":1765394044199,\"type\":\"update/order_book\"}"
    "msg": "{\"channel\":\"order_book:1\",\"offset\":6962525,\"order_book\":{\"code\":0,\"asks\":[{\"price\":\"92961.0\",\"size\":\"0.00000\"},{\"price\":\"92962.8\",\"size\":\"0.00000\"},{\"price\":\"92964.2\",\"size\":\"0.10760\"}],\"bids\":[{\"price\":\"92949.8\",\"size\":\"0.38767\"},{\"price\":\"92945.1\",\"size\":\"0.10760\"},{\"price\":\"92943.7\",\"size\":\"0.00000\"},{\"price\":\"92937.5\",\"size\":\"0.00000\"},{\"price\":\"92925.5\",\"size\":\"0.00000\"},{\"price\":\"92908.6\",\"size\":\"0.01076\"}],\"offset\":6962525,\"nonce\":3691008973},\"timestamp\":1765394044206,\"type\":\"update/order_book\"}"
    "msg": "{\"channel\":\"order_book:1\",\"offset\":6962526,\"order_book\":{\"code\":0,\"asks\":[{\"price\":\"92961.8\",\"size\":\"0.10760\"},{\"price\":\"92979.0\",\"size\":\"0.00000\"}],\"bids\":[{\"price\":\"92943.2\",\"size\":\"0.13448\"},{\"price\":\"92937.6\",\"size\":\"0.01075\"},{\"price\":\"92934.8\",\"size\":\"0.00000\"},{\"price\":\"92861.5\",\"size\":\"0.00000\"}],\"offset\":6962526,\"nonce\":3691008974},\"timestamp\":1765394044211,\"type\":\"update/order_book\"}"
    "msg": "{\"channel\":\"order_book:1\",\"offset\":6962527,\"order_book\":{\"code\":0,\"asks\":[],\"bids\":[{\"price\":\"92946.4\",\"size\":\"1.07758\"},{\"price\":\"92945.2\",\"size\":\"0.10760\"},{\"price\":\"92935.9\",\"size\":\"0.03012\"}],\"offset\":6962527,\"nonce\":3691008976},\"timestamp\":1765394044219,\"type\":\"update/order_book\"}"
    "msg": "{\"channel\":\"order_book:1\",\"offset\":6962528,\"order_book\":{\"code\":0,\"asks\":[{\"price\":\"92958.8\",\"size\":\"0.34449\"},{\"price\":\"92960.2\",\"size\":\"0.38767\"}],\"bids\":[{\"price\":\"92949.8\",\"size\":\"0.38767\"},{\"price\":\"92946.2\",\"size\":\"0.92416\"},{\"price\":\"92939.6\",\"size\":\"0.01075\"},{\"price\":\"92937.6\",\"size\":\"0.00000\"},{\"price\":\"92937.3\",\"size\":\"0.08081\"}],\"offset\":6962528,\"nonce\":3691008977},\"timestamp\":1765394044222,\"type\":\"update/order_book\"}"
    "msg": "{\"channel\":\"order_book:1\",\"offset\":6962529,\"order_book\":{\"code\":0,\"asks\":[{\"price\":\"92956.0\",\"size\":\"0.00127\"}],\"bids\":[{\"price\":\"92919.1\",\"size\":\"0.00108\"},{\"price\":\"92917.1\",\"size\":\"0.00000\"}],\"offset\":6962529,\"nonce\":3691008978},\"timestamp\":1765394044228,\"type\":\"update/order_book\"}"
    "msg": "{\"channel\":\"order_book:1\",\"offset\":6962530,\"order_book\":{\"code\":0,\"asks\":[],\"bids\":[{\"price\":\"92946.0\",\"size\":\"0.02905\"},{\"price\":\"92945.1\",\"size\":\"0.00000\"},{\"price\":\"92944.6\",\"size\":\"0.00000\"},{\"price\":\"92939.6\",\"size\":\"0.00000\"}],\"offset\":6962530,\"nonce\":3691008979},\"timestamp\":1765394044233,\"type\":\"update/order_book\"}"
    "msg": "{\"channel\":\"order_book:1\",\"offset\":6962531,\"order_book\":{\"code\":0,\"asks\":[],\"bids\":[{\"price\":\"92949.8\",\"size\":\"1.27797\"}],\"offset\":6962531,\"nonce\":3691008981},\"timestamp\":1765394044245,\"type\":\"update/order_book\"}"
    "msg": "{\"channel\":\"order_book:1\",\"offset\":6962532,\"order_book\":{\"code\":0,\"asks\":[{\"price\":\"92958.8\",\"size\":\"0.10760\"},{\"price\":\"92996.3\",\"size\":\"2.29260\"},{\"price\":\"93003.6\",\"size\":\"0.00000\"}],\"bids\":[{\"price\":\"92924.1\",\"size\":\"4.66112\"},{\"price\":\"92922.1\",\"size\":\"0.11088\"}],\"offset\":6962532,\"nonce\":3691008982},\"timestamp\":1765394044248,\"type\":\"update/order_book\"}"
    "msg": "{\"channel\":\"order_book:1\",\"offset\":6962533,\"order_book\":{\"code\":0,\"asks\":[],\"bids\":[{\"price\":\"92944.1\",\"size\":\"0.00201\"},{\"price\":\"92934.7\",\"size\":\"0.04179\"}],\"offset\":6962533,\"nonce\":3691008983},\"timestamp\":1765394044251,\"type\":\"update/order_book\"}"
    "msg": "{\"channel\":\"order_book:1\",\"offset\":6962534,\"order_book\":{\"code\":0,\"asks\":[{\"price\":\"92960.2\",\"size\":\"0.00000\"},{\"price\":\"92980.4\",\"size\":\"0.00302\"}],\"bids\":[{\"price\":\"92940.2\",\"size\":\"0.02906\"},{\"price\":\"92939.7\",\"size\":\"0.01075\"}],\"offset\":6962534,\"nonce\":3691008985},\"timestamp\":1765394044261,\"type\":\"update/order_book\"}"
    "msg": "{\"channel\":\"order_book:1\",\"offset\":6962535,\"order_book\":{\"code\":0,\"asks\":[{\"price\":\"92959.9\",\"size\":\"0.02834\"},{\"price\":\"92991.0\",\"size\":\"0.38767\"}],\"bids\":[{\"price\":\"92933.4\",\"size\":\"0.38767\"},{\"price\":\"92931.9\",\"size\":\"0.00000\"},{\"price\":\"92930.3\",\"size\":\"0.08083\"},{\"price\":\"92927.8\",\"size\":\"0.10780\"}],\"offset\":6962535,\"nonce\":3691008986},\"timestamp\":1765394044268,\"type\":\"update/order_book\"}"
    "msg": "{\"channel\":\"order_book:1\",\"offset\":6962536,\"order_book\":{\"code\":0,\"asks\":[{\"price\":\"92967.1\",\"size\":\"0.01448\"}],\"bids\":[],\"offset\":6962536,\"nonce\":3691008988},\"timestamp\":1765394044273,\"type\":\"update/order_book\"}"
    "msg": "{\"channel\":\"order_book:1\",\"offset\":6962537,\"order_book\":{\"code\":0,\"asks\":[],\"bids\":[{\"price\":\"92949.9\",\"size\":\"0.86452\"},{\"price\":\"92944.1\",\"size\":\"0.00000\"}],\"offset\":6962537,\"nonce\":3691008990},\"timestamp\":1765394044280,\"type\":\"update/order_book\"}"
    "msg": "{\"channel\":\"order_book:1\",\"offset\":6962539,\"order_book\":{\"code\":0,\"asks\":[],\"bids\":[{\"price\":\"92885.0\",\"size\":\"0.00000\"}],\"offset\":6962539,\"nonce\":3691008995},\"timestamp\":1765394044289,\"type\":\"update/order_book\"}"
    "msg": "{\"channel\":\"order_book:1\",\"offset\":6962540,\"order_book\":{\"code\":0,\"asks\":[],\"bids\":[{\"price\":\"92945.0\",\"size\":\"0.10760\"}],\"offset\":6962540,\"nonce\":3691008996},\"timestamp\":1765394044290,\"type\":\"update/order_book\"}"
    "msg": "{\"channel\":\"order_book:1\",\"offset\":6962541,\"order_book\":{\"code\":0,\"asks\":[{\"price\":\"92950.9\",\"size\":\"0.00000\"},{\"price\":\"92958.8\",\"size\":\"0.00000\"},{\"price\":\"92964.2\",\"size\":\"0.00000\"},{\"price\":\"92965.2\",\"size\":\"0.10760\"}],\"bids\":[{\"price\":\"92946.4\",\"size\":\"0.00000\"}],\"offset\":6962541,\"nonce\":3691008997},\"timestamp\":1765394044296,\"type\":\"update/order_book\"}"
    "msg": "{\"channel\":\"order_book:1\",\"offset\":6962542,\"order_book\":{\"code\":0,\"asks\":[],\"bids\":[{\"price\":\"92949.9\",\"size\":\"0.86279\"}],\"offset\":6962542,\"nonce\":3691008998},\"timestamp\":1765394044298,\"type\":\"update/order_book\"}"
    "msg": "{\"channel\":\"order_book:1\",\"offset\":6962543,\"order_book\":{\"code\":0,\"asks\":[{\"price\":\"92961.8\",\"size\":\"0.00000\"},{\"price\":\"92962.8\",\"size\":\"0.10760\"},{\"price\":\"92963.1\",\"size\":\"0.05378\"}],\"bids\":[{\"price\":\"92929.5\",\"size\":\"0.38767\"},{\"price\":\"92927.6\",\"size\":\"0.05380\"}],\"offset\":6962543,\"nonce\":3691008999},\"timestamp\":1765394044307,\"type\":\"update/order_book\"}"
    "msg": "{\"channel\":\"order_book:1\",\"offset\":6962544,\"order_book\":{\"code\":0,\"asks\":[{\"price\":\"92953.3\",\"size\":\"0.00000\"},{\"price\":\"92959.4\",\"size\":\"0.00000\"},{\"price\":\"92971.6\",\"size\":\"0.00000\"},{\"price\":\"92995.3\",\"size\":\"0.00538\"},{\"price\":\"92996.3\",\"size\":\"0.00000\"},{\"price\":\"93003.9\",\"size\":\"2.29239\"},{\"price\":\"93056.4\",\"size\":\"0.00000\"}],\"bids\":[{\"price\":\"92948.5\",\"size\":\"0.10760\"},{\"price\":\"92945.2\",\"size\":\"0.00000\"},{\"price\":\"92942.1\",\"size\":\"0.00000\"},{\"price\":\"92924.1\",\"size\":\"4.66251\"}],\"offset\":6962544,\"nonce\":3691009000},\"timestamp\":1765394044312,\"type\":\"update/order_book\"}"
    "msg": "{\"channel\":\"order_book:1\",\"offset\":6962545,\"order_book\":{\"code\":0,\"asks\":[{\"price\":\"92955.3\",\"size\":\"0.00000\"}],\"bids\":[{\"price\":\"92949.9\",\"size\":\"1.75344\"},{\"price\":\"92919.0\",\"size\":\"0.00000\"},{\"price\":\"92908.6\",\"size\":\"0.00000\"}],\"offset\":6962545,\"nonce\":3691009001},\"timestamp\":1765394044317,\"type\":\"update/order_book\"}"
    "msg": "{\"channel\":\"order_book:1\",\"offset\":6962546,\"order_book\":{\"code\":0,\"asks\":[{\"price\":\"92957.8\",\"size\":\"0.00000\"},{\"price\":\"93000.8\",\"size\":\"0.00000\"}],\"bids\":[{\"price\":\"92935.9\",\"size\":\"0.00860\"},{\"price\":\"92934.4\",\"size\":\"0.00000\"},{\"price\":\"92931.1\",\"size\":\"0.02628\"}],\"offset\":6962546,\"nonce\":3691009002},\"timestamp\":1765394044322,\"type\":\"update/order_book\"}"
    "msg": "{\"channel\":\"order_book:1\",\"offset\":6962547,\"order_book\":{\"code\":0,\"asks\":[{\"price\":\"92961.9\",\"size\":\"0.00500\"},{\"price\":\"92973.9\",\"size\":\"0.00000\"},{\"price\":\"92985.5\",\"size\":\"0.00000\"}],\"bids\":[{\"price\":\"92946.0\",\"size\":\"0.00000\"},{\"price\":\"92939.7\",\"size\":\"0.00000\"},{\"price\":\"92910.9\",\"size\":\"0.01076\"}],\"offset\":6962547,\"nonce\":3691009003},\"timestamp\":1765394044326,\"type\":\"update/order_book\"}"
    "msg": "{\"channel\":\"order_book:1\",\"offset\":6962548,\"order_book\":{\"code\":0,\"asks\":[{\"price\":\"92959.9\",\"size\":\"0.00000\"},{\"price\":\"92980.4\",\"size\":\"0.00000\"}],\"bids\":[{\"price\":\"92939.7\",\"size\":\"0.02151\"},{\"price\":\"92922.2\",\"size\":\"0.10778\"}],\"offset\":6962548,\"nonce\":3691009004},\"timestamp\":1765394044334,\"type\":\"update/order_book\"}"
    "msg": "{\"channel\":\"order_book:1\",\"offset\":6962549,\"order_book\":{\"code\":0,\"asks\":[{\"price\":\"92956.0\",\"size\":\"0.00000\"}],\"bids\":[{\"price\":\"92948.1\",\"size\":\"0.02905\"},{\"price\":\"92943.5\",\"size\":\"0.01075\"}],\"offset\":6962549,\"nonce\":3691009005},\"timestamp\":1765394044342,\"type\":\"update/order_book\"}"
    "msg": "{\"channel\":\"order_book:1\",\"offset\":6962550,\"order_book\":{\"code\":0,\"asks\":[{\"price\":\"93003.9\",\"size\":\"0.00000\"},{\"price\":\"93005.7\",\"size\":\"2.29235\"}],\"bids\":[{\"price\":\"92924.1\",\"size\":\"4.66310\"}],\"offset\":6962550,\"nonce\":3691009006},\"timestamp\":1765394044344,\"type\":\"update/order_book\"}"
    "msg": "{\"channel\":\"order_book:1\",\"offset\":6962551,\"order_book\":{\"code\":0,\"asks\":[{\"price\":\"92958.4\",\"size\":\"0.00000\"},{\"price\":\"92996.6\",\"size\":\"0.38767\"}],\"bids\":[{\"price\":\"92953.2\",\"size\":\"0.00500\"},{\"price\":\"92943.5\",\"size\":\"0.00000\"},{\"price\":\"92939.7\",\"size\":\"0.00000\"},{\"price\":\"92920.1\",\"size\":\"8.07918\"},{\"price\":\"92910.9\",\"size\":\"0.00000\"}],\"offset\":6962551,\"nonce\":3691009007},\"timestamp\":1765394044356,\"type\":\"update/order_book\"}"
    "msg": "{\"channel\":\"order_book:1\",\"offset\":6962552,\"order_book\":{\"code\":0,\"asks\":[{\"price\":\"92963.6\",\"size\":\"0.00000\"},{\"price\":\"92975.2\",\"size\":\"0.00000\"}],\"bids\":[{\"price\":\"92953.2\",\"size\":\"0.00700\"},{\"price\":\"92950.8\",\"size\":\"0.00500\"}],\"offset\":6962552,\"nonce\":3691009008},\"timestamp\":1765394044359,\"type\":\"update/order_book\"}"
    "msg": "{\"channel\":\"order_book:1\",\"offset\":6962553,\"order_book\":{\"code\":0,\"asks\":[{\"price\":\"92971.7\",\"size\":\"0.00000\"},{\"price\":\"92982.5\",\"size\":\"0.00000\"}],\"bids\":[{\"price\":\"92953.2\",\"size\":\"1.10865\"},{\"price\":\"92952.9\",\"size\":\"0.38767\"},{\"price\":\"92947.9\",\"size\":\"0.00215\"},{\"price\":\"92940.6\",\"size\":\"0.02151\"},{\"price\":\"92920.5\",\"size\":\"0.00000\"},{\"price\":\"92912.1\",\"size\":\"0.01076\"}],\"offset\":6962553,\"nonce\":3691009009},\"timestamp\":1765394044366,\"type\":\"update/order_book\"}"
    "msg": "{\"channel\":\"order_book:1\",\"offset\":6962554,\"order_book\":{\"code\":0,\"asks\":[{\"price\":\"92965.8\",\"size\":\"0.38767\"},{\"price\":\"92981.0\",\"size\":\"0.36684\"},{\"price\":\"92987.3\",\"size\":\"0.00214\"}],\"bids\":[{\"price\":\"92948.5\",\"size\":\"0.00000\"},{\"price\":\"92944.4\",\"size\":\"0.01075\"},{\"price\":\"92934.1\",\"size\":\"0.00000\"},{\"price\":\"92925.1\",\"size\":\"0.00214\"},{\"price\":\"92924.9\",\"size\":\"0.00214\"}],\"offset\":6962554,\"nonce\":3691009010},\"timestamp\":1765394044370,\"type\":\"update/order_book\"}"
    "msg": "{\"channel\":\"order_book:1\",\"offset\":6962555,\"order_book\":{\"code\":0,\"asks\":[{\"price\":\"92961.6\",\"size\":\"0.02834\"},{\"price\":\"92963.1\",\"size\":\"0.00000\"},{\"price\":\"92983.8\",\"size\":\"0.00302\"}],\"bids\":[{\"price\":\"92953.2\",\"size\":\"0.03107\"},{\"price\":\"92949.8\",\"size\":\"0.89030\"},{\"price\":\"92947.9\",\"size\":\"0.00000\"},{\"price\":\"92946.9\",\"size\":\"0.90835\"},{\"price\":\"92944.4\",\"size\":\"0.00000\"},{\"price\":\"92943.0\",\"size\":\"0.08081\"},{\"price\":\"92927.6\",\"size\":\"0.00000\"},{\"price\":\"92902.2\",\"size\":\"0.11088\"},{\"price\":\"92509.0\",\"size\":\"0.14334\"},{\"price\":\"91637.7\",\"size\":\"0.00000\"}],\"offset\":6962555,\"nonce\":3691009011},\"timestamp\":1765394044373,\"type\":\"update/order_book\"}"
    "msg": "{\"channel\":\"order_book:1\",\"offset\":6962556,\"order_book\":{\"code\":0,\"asks\":[{\"price\":\"92964.1\",\"size\":\"2.69396\"}],\"bids\":[{\"price\":\"92943.9\",\"size\":\"0.95774\"},{\"price\":\"92941.1\",\"size\":\"1.84753\"},{\"price\":\"92935.7\",\"size\":\"2.69396\"},{\"price\":\"92933.4\",\"size\":\"0.49547\"},{\"price\":\"92927.8\",\"size\":\"0.00000\"},{\"price\":\"92838.9\",\"size\":\"0.00000\"}],\"offset\":6962556,\"nonce\":3691009012},\"timestamp\":1765394044380,\"type\":\"update/order_book\"}"
    "msg": "{\"channel\":\"order_book:1\",\"offset\":6962557,\"order_book\":{\"code\":0,\"asks\":[{\"price\":\"93014.1\",\"size\":\"0.36804\"}],\"bids\":[{\"price\":\"92953.2\",\"size\":\"0.88728\"},{\"price\":\"92551.0\",\"size\":\"0.00000\"}],\"offset\":6962557,\"nonce\":3691009013},\"timestamp\":1765394044384,\"type\":\"update/order_book\"}"
    "msg": "{\"channel\":\"order_book:1\",\"offset\":6962558,\"order_book\":{\"code\":0,\"asks\":[],\"bids\":[{\"price\":\"92948.8\",\"size\":\"0.00215\"},{\"price\":\"92944.3\",\"size\":\"0.01075\"}],\"offset\":6962558,\"nonce\":3691009017},\"timestamp\":1765394044399,\"type\":\"update/order_book\"}"
    "msg": "{\"channel\":\"order_book:1\",\"offset\":6962559,\"order_book\":{\"code\":0,\"asks\":[],\"bids\":[{\"price\":\"92944.3\",\"size\":\"0.00000\"}],\"offset\":6962559,\"nonce\":3691009020},\"timestamp\":1765394044401,\"type\":\"update/order_book\"}"
    "msg": "{\"channel\":\"order_book:1\",\"offset\":6962560,\"order_book\":{\"code\":0,\"asks\":[{\"price\":\"92963.6\",\"size\":\"0.10760\"},{\"price\":\"92965.2\",\"size\":\"0.00000\"}],\"bids\":[{\"price\":\"92941.0\",\"size\":\"0.00000\"}],\"offset\":6962560,\"nonce\":3691009022},\"timestamp\":1765394044404,\"type\":\"update/order_book\"}"
    "msg": "{\"channel\":\"order_book:1\",\"offset\":6962562,\"order_book\":{\"code\":0,\"asks\":[{\"price\":\"93010.7\",\"size\":\"8.07918\"}],\"bids\":[{\"price\":\"92952.9\",\"size\":\"0.00000\"},{\"price\":\"92947.2\",\"size\":\"1.84835\"},{\"price\":\"92944.3\",\"size\":\"0.01075\"},{\"price\":\"92929.6\",\"size\":\"4.66464\"},{\"price\":\"92924.1\",\"size\":\"0.00000\"}],\"offset\":6962562,\"nonce\":3691009026},\"timestamp\":1765394044419,\"type\":\"update/order_book\"}"
    "msg": "{\"channel\":\"order_book:1\",\"offset\":6962563,\"order_book\":{\"code\":0,\"asks\":[{\"price\":\"93005.4\",\"size\":\"2.29236\"},{\"price\":\"93005.7\",\"size\":\"0.00000\"}],\"bids\":[],\"offset\":6962563,\"nonce\":3691009027},\"timestamp\":1765394044422,\"type\":\"update/order_book\"}"
    "msg": "{\"channel\":\"order_book:1\",\"offset\":6962564,\"order_book\":{\"code\":0,\"asks\":[],\"bids\":[{\"price\":\"92948.8\",\"size\":\"0.00000\"}],\"offset\":6962564,\"nonce\":3691009028},\"timestamp\":1765394044427,\"type\":\"update/order_book\"}"
    "msg": "{\"channel\":\"order_book:1\",\"offset\":6962565,\"order_book\":{\"code\":0,\"asks\":[],\"bids\":[{\"price\":\"92948.0\",\"size\":\"1.07758\"}],\"offset\":6962565,\"nonce\":3691009029},\"timestamp\":1765394044429,\"type\":\"update/order_book\"}"
    "msg": "{\"channel\":\"order_book:1\",\"offset\":6962566,\"order_book\":{\"code\":0,\"asks\":[],\"bids\":[{\"price\":\"92945.9\",\"size\":\"0.38767\"}],\"offset\":6962566,\"nonce\":3691009032},\"timestamp\":1765394044437,\"type\":\"update/order_book\"}"
    "msg": "{\"channel\":\"order_book:1\",\"offset\":6962567,\"order_book\":{\"code\":0,\"asks\":[],\"bids\":[{\"price\":\"92953.2\",\"size\":\"0.88321\"},{\"price\":\"92941.2\",\"size\":\"0.38767\"}],\"offset\":6962567,\"nonce\":3691009033},\"timestamp\":1765394044445,\"type\":\"update/order_book\"}"
    "msg": "{\"channel\":\"order_book:1\",\"offset\":6962568,\"order_book\":{\"code\":0,\"asks\":[],\"bids\":[{\"price\":\"92953.2\",\"size\":\"0.88121\"}],\"offset\":6962568,\"nonce\":3691009035},\"timestamp\":1765394044448,\"type\":\"update/order_book\"}"
    "msg": "{\"channel\":\"order_book:1\",\"offset\":6962569,\"order_book\":{\"code\":0,\"asks\":[{\"price\":\"92957.3\",\"size\":\"1.07758\"},{\"price\":\"92960.4\",\"size\":\"0.10760\"}],\"bids\":[],\"offset\":6962569,\"nonce\":3691009036},\"timestamp\":1765394044450,\"type\":\"update/order_book\"}"
    "msg": "{\"channel\":\"order_book:1\",\"offset\":6962570,\"order_book\":{\"code\":0,\"asks\":[],\"bids\":[{\"price\":\"92953.2\",\"size\":\"0.85621\"},{\"price\":\"92864.3\",\"size\":\"0.91326\"}],\"offset\":6962570,\"nonce\":3691009037},\"timestamp\":1765394044453,\"type\":\"update/order_book\"}"
    "msg": "{\"channel\":\"order_book:1\",\"offset\":6962571,\"order_book\":{\"code\":0,\"asks\":[],\"bids\":[{\"price\":\"92950.8\",\"size\":\"0.00000\"}],\"offset\":6962571,\"nonce\":3691009038},\"timestamp\":1765394044464,\"type\":\"update/order_book\"}"
    "msg": "{\"channel\":\"order_book:1\",\"offset\":6962573,\"order_book\":{\"code\":0,\"asks\":[],\"bids\":[{\"price\":\"92948.1\",\"size\":\"0.00000\"},{\"price\":\"92925.5\",\"size\":\"0.00215\"}],\"offset\":6962573,\"nonce\":3691009041},\"timestamp\":1765394044482,\"type\":\"update/order_book\"}"
    "msg": "{\"channel\":\"order_book:1\",\"offset\":6962574,\"order_book\":{\"code\":0,\"asks\":[{\"price\":\"92957.1\",\"size\":\"0.09500\"},{\"price\":\"92995.6\",\"size\":\"0.00000\"},{\"price\":\"93020.3\",\"size\":\"0.31913\"}],\"bids\":[],\"offset\":6962574,\"nonce\":3691009042},\"timestamp\":1765394044484,\"type\":\"update/order_book\"}"
    "msg": "{\"channel\":\"order_book:1\",\"offset\":6962575,\"order_book\":{\"code\":0,\"asks\":[{\"price\":\"92959.4\",\"size\":\"0.02834\"}],\"bids\":[],\"offset\":6962575,\"nonce\":3691009043},\"timestamp\":1765394044491,\"type\":\"update/order_book\"}"
    "msg": "{\"channel\":\"order_book:1\",\"offset\":6962576,\"order_book\":{\"code\":0,\"asks\":[],\"bids\":[{\"price\":\"92936.5\",\"size\":\"0.00000\"}],\"offset\":6962576,\"nonce\":3691009044},\"timestamp\":1765394044498,\"type\":\"update/order_book\"}"
    "msg": "{\"channel\":\"order_book:1\",\"offset\":6962577,\"order_book\":{\"code\":0,\"asks\":[{\"price\":\"92963.6\",\"size\":\"0.00000\"},{\"price\":\"92964.9\",\"size\":\"0.10760\"}],\"bids\":[{\"price\":\"92950.1\",\"size\":\"0.21525\"}],\"offset\":6962577,\"nonce\":3691009046},\"timestamp\":1765394044505,\"type\":\"update/order_book\"}"
    "msg": "{\"channel\":\"order_book:1\",\"offset\":6962580,\"order_book\":{\"code\":0,\"asks\":[{\"price\":\"92970.4\",\"size\":\"0.08083\"}],\"bids\":[],\"offset\":6962580,\"nonce\":3691009049},\"timestamp\":1765394044521,\"type\":\"update/order_book\"}"
    "msg": "{\"channel\":\"order_book:1\",\"offset\":6962581,\"order_book\":{\"code\":0,\"asks\":[],\"bids\":[{\"price\":\"92945.9\",\"size\":\"0.41672\"},{\"price\":\"92927.6\",\"size\":\"0.00108\"},{\"price\":\"92919.1\",\"size\":\"0.00000\"}],\"offset\":6962581,\"nonce\":3691009051},\"timestamp\":1765394044531,\"type\":\"update/order_book\"}"
    "msg": "{\"channel\":\"order_book:1\",\"offset\":6962582,\"order_book\":{\"code\":0,\"asks\":[{\"price\":\"93005.4\",\"size\":\"2.29235\"}],\"bids\":[{\"price\":\"92929.6\",\"size\":\"0.00000\"},{\"price\":\"92921.5\",\"size\":\"4.66749\"}],\"offset\":6962582,\"nonce\":3691009052},\"timestamp\":1765394044535,\"type\":\"update/order_book\"}"
    "msg": "{\"channel\":\"order_book:1\",\"offset\":6962583,\"order_book\":{\"code\":0,\"asks\":[{\"price\":\"92957.1\",\"size\":\"0.09000\"}],\"bids\":[],\"offset\":6962583,\"nonce\":3691009054},\"timestamp\":1765394044544,\"type\":\"update/order_book\"}"
    "msg": "{\"channel\":\"order_book:1\",\"offset\":6962584,\"order_book\":{\"code\":0,\"asks\":[{\"price\":\"92960.4\",\"size\":\"0.08084\"},{\"price\":\"92962.4\",\"size\":\"0.10760\"}],\"bids\":[],\"offset\":6962584,\"nonce\":3691009055},\"timestamp\":1765394044553,\"type\":\"update/order_book\"}"
    "msg": "{\"channel\":\"order_book:1\",\"offset\":6962585,\"order_book\":{\"code\":0,\"asks\":[],\"bids\":[{\"price\":\"92941.4\",\"size\":\"0.08084\"},{\"price\":\"92646.4\",\"size\":\"23.62578\"}],\"offset\":6962585,\"nonce\":3691009057},\"timestamp\":1765394044565,\"type\":\"update/order_book\"}"
    "msg": "{\"channel\":\"order_book:1\",\"offset\":6962586,\"order_book\":{\"code\":0,\"asks\":[{\"price\":\"92965.6\",\"size\":\"0.08079\"},{\"price\":\"92967.8\",\"size\":\"0.08081\"},{\"price\":\"92974.3\",\"size\":\"0.08072\"}],\"bids\":[],\"offset\":6962586,\"nonce\":3691009058},\"timestamp\":1765394044566,\"type\":\"update/order_book\"}"
    "msg": "{\"channel\":\"order_book:1\",\"offset\":6962588,\"order_book\":{\"code\":0,\"asks\":[],\"bids\":[{\"price\":\"92941.1\",\"size\":\"0.00000\"},{\"price\":\"92887.7\",\"size\":\"23.53822\"}],\"offset\":6962588,\"nonce\":3691009071},\"timestamp\":1765394044593,\"type\":\"update/order_book\"}"
    "msg": "{\"channel\":\"order_book:1\",\"offset\":6962589,\"order_book\":{\"code\":0,\"asks\":[],\"bids\":[{\"price\":\"92953.3\",\"size\":\"1.82360\"},{\"price\":\"92941.1\",\"size\":\"0.00188\"}],\"offset\":6962589,\"nonce\":3691009072},\"timestamp\":1765394044595,\"type\":\"update/order_book\"}"
    "msg": "{\"channel\":\"order_book:1\",\"offset\":6962590,\"order_book\":{\"code\":0,\"asks\":[{\"price\":\"92961.7\",\"size\":\"0.10760\"},{\"price\":\"92962.8\",\"size\":\"0.00000\"}],\"bids\":[],\"offset\":6962590,\"nonce\":3691009074},\"timestamp\":1765394044600,\"type\":\"update/order_book\"}"
    "msg": "{\"channel\":\"order_book:1\",\"offset\":6962591,\"order_book\":{\"code\":0,\"asks\":[],\"bids\":[{\"price\":\"92945.0\",\"size\":\"0.00000\"},{\"price\":\"92943.8\",\"size\":\"0.10760\"},{\"price\":\"92929.4\",\"size\":\"0.00021\"}],\"offset\":6962591,\"nonce\":3691009077},\"timestamp\":1765394044620,\"type\":\"update/order_book\"}"
    "msg": "{\"channel\":\"order_book:1\",\"offset\":6962592,\"order_book\":{\"code\":0,\"asks\":[],\"bids\":[{\"price\":\"92927.6\",\"size\":\"0.00000\"},{\"price\":\"92916.5\",\"size\":\"0.00608\"}],\"offset\":6962592,\"nonce\":3691009078},\"timestamp\":1765394044633,\"type\":\"update/order_book\"}"
    "msg": "{\"channel\":\"order_book:1\",\"offset\":6962593,\"order_book\":{\"code\":0,\"asks\":[{\"price\":\"92961.6\",\"size\":\"0.00000\"},{\"price\":\"92978.2\",\"size\":\"2.15445\"},{\"price\":\"92982.4\",\"size\":\"0.11088\"}],\"bids\":[],\"offset\":6962593,\"nonce\":3691009079},\"timestamp\":1765394044661,\"type\":\"update/order_book\"}"
    "msg": "{\"channel\":\"order_book:1\",\"offset\":6962594,\"order_book\":{\"code\":0,\"asks\":[{\"price\":\"92957.8\",\"size\":\"0.00021\"}],\"bids\":[],\"offset\":6962594,\"nonce\":3691009081},\"timestamp\":1765394044700,\"type\":\"update/order_book\"}"
    "msg": "{\"channel\":\"order_book:1\",\"offset\":6962595,\"order_book\":{\"code\":0,\"asks\":[{\"price\":\"92961.7\",\"size\":\"0.00000\"},{\"price\":\"92963.0\",\"size\":\"0.10760\"}],\"bids\":[],\"offset\":6962595,\"nonce\":3691009083},\"timestamp\":1765394044735,\"type\":\"update/order_book\"}"
    "msg": "{\"channel\":\"order_book:1\",\"offset\":6962596,\"order_book\":{\"code\":0,\"asks\":[{\"price\":\"92963.4\",\"size\":\"0.00860\"}],\"bids\":[],\"offset\":6962596,\"nonce\":3691009085},\"timestamp\":1765394044764,\"type\":\"update/order_book\"}"
    "msg": "{\"channel\":\"order_book:1\",\"offset\":6962597,\"order_book\":{\"code\":0,\"asks\":[],\"bids\":[{\"price\":\"92946.7\",\"size\":\"0.10760\"},{\"price\":\"92943.8\",\"size\":\"0.00000\"},{\"price\":\"92909.9\",\"size\":\"0.00000\"}],\"offset\":6962597,\"nonce\":3691009086},\"timestamp\":1765394044772,\"type\":\"update/order_book\"}"
    "msg": "{\"channel\":\"order_book:1\",\"offset\":6962598,\"order_book\":{\"code\":0,\"asks\":[],\"bids\":[{\"price\":\"92940.9\",\"size\":\"0.00860\"}],\"offset\":6962598,\"nonce\":3691009087},\"timestamp\":1765394044779,\"type\":\"update/order_book\"}"
    "msg": "{\"channel\":\"order_book:1\",\"offset\":6962599,\"order_book\":{\"code\":0,\"asks\":[],\"bids\":[{\"price\":\"92932.5\",\"size\":\"0.10780\"},{\"price\":\"92931.2\",\"size\":\"0.00000\"}],\"offset\":6962599,\"nonce\":3691009089},\"timestamp\":1765394044793,\"type\":\"update/order_book\"}"
    "msg": "{\"channel\":\"order_book:1\",\"offset\":6962600,\"order_book\":{\"code\":0,\"asks\":[{\"price\":\"92982.4\",\"size\":\"0.00000\"}],\"bids\":[],\"offset\":6962600,\"nonce\":3691009090},\"timestamp\":1765394044798,\"type\":\"update/order_book\"}"
    "msg": "{\"channel\":\"order_book:1\",\"offset\":6962601,\"order_book\":{\"code\":0,\"asks\":[],\"bids\":[{\"price\":\"92931.9\",\"size\":\"0.11088\"},{\"price\":\"92877.8\",\"size\":\"0.00000\"}],\"offset\":6962601,\"nonce\":3691009091},\"timestamp\":1765394044799,\"type\":\"update/order_book\"}"
    "msg": "{\"channel\":\"order_book:1\",\"offset\":6962602,\"order_book\":{\"code\":0,\"asks\":[{\"price\":\"92957.1\",\"size\":\"0.09000\"}],\"bids\":[{\"price\":\"92953.3\",\"size\":\"1.82330\"},{\"price\":\"92925.5\",\"size\":\"0.00000\"}],\"offset\":6962602,\"nonce\":3691009093},\"timestamp\":1765394044810,\"type\":\"update/order_book\"}"
    "msg": "{\"channel\":\"order_book:1\",\"offset\":6962603,\"order_book\":{\"code\":0,\"asks\":[],\"bids\":[{\"price\":\"92948.7\",\"size\":\"0.49527\"},{\"price\":\"92942.0\",\"size\":\"0.00000\"}],\"offset\":6962603,\"nonce\":3691009094},\"timestamp\":1765394044818,\"type\":\"update/order_book\"}"
    "msg": "{\"channel\":\"order_book:1\",\"offset\":6962604,\"order_book\":{\"code\":0,\"asks\":[{\"price\":\"92957.2\",\"size\":\"0.00000\"},{\"price\":\"93010.9\",\"size\":\"0.00000\"},{\"price\":\"93045.4\",\"size\":\"0.00269\"}],\"bids\":[],\"offset\":6962604,\"nonce\":3691009095},\"timestamp\":1765394044823,\"type\":\"update/order_book\"}"
    "msg": "{\"channel\":\"order_book:1\",\"offset\":6962605,\"order_book\":{\"code\":0,\"asks\":[{\"price\":\"92962.4\",\"size\":\"0.00000\"},{\"price\":\"92964.9\",\"size\":\"0.00000\"},{\"price\":\"92965.6\",\"size\":\"0.18839\"},{\"price\":\"92966.1\",\"size\":\"0.10760\"},{\"price\":\"92971.3\",\"size\":\"0.00000\"}],\"bids\":[],\"offset\":6962605,\"nonce\":3691009096},\"timestamp\":1765394044829,\"type\":\"update/order_book\"}"
    "msg": "{\"channel\":\"order_book:1\",\"offset\":6962606,\"order_book\":{\"code\":0,\"asks\":[{\"price\":\"92966.1\",\"size\":\"0.33398\"},{\"price\":\"92983.2\",\"size\":\"0.00215\"}],\"bids\":[{\"price\":\"92957.0\",\"size\":\"0.03107\"},{\"price\":\"92953.3\",\"size\":\"1.81299\"},{\"price\":\"92949.8\",\"size\":\"0.99790\"},{\"price\":\"92948.7\",\"size\":\"0.38767\"},{\"price\":\"92944.3\",\"size\":\"0.00000\"}],\"offset\":6962606,\"nonce\":3691009097},\"timestamp\":1765394044832,\"type\":\"update/order_book\"}"
    "msg": "{\"channel\":\"order_book:1\",\"offset\":6962607,\"order_book\":{\"code\":0,\"asks\":[],\"bids\":[{\"price\":\"92957.0\",\"size\":\"0.03607\"},{\"price\":\"92944.6\",\"size\":\"0.01075\"},{\"price\":\"92763.1\",\"size\":\"0.00000\"}],\"offset\":6962607,\"nonce\":3691009098},\"timestamp\":1765394044835,\"type\":\"update/order_book\"}"
    "msg": "{\"channel\":\"order_book:1\",\"offset\":6962608,\"order_book\":{\"code\":0,\"asks\":[],\"bids\":[{\"price\":\"92957.0\",\"size\":\"0.00000\"},{\"price\":\"92953.3\",\"size\":\"1.74906\"}],\"offset\":6962608,\"nonce\":3691009099},\"timestamp\":1765394044839,\"type\":\"update/order_book\"}"
    "msg": "{\"channel\":\"order_book:1\",\"offset\":6962609,\"order_book\":{\"code\":0,\"asks\":[{\"price\":\"92959.4\",\"size\":\"0.00000\"}],\"bids\":[{\"price\":\"92948.0\",\"size\":\"0.00000\"}],\"offset\":6962609,\"nonce\":3691009102},\"timestamp\":1765394044854,\"type\":\"update/order_book\"}"
    "msg": "{\"channel\":\"order_book:1\",\"offset\":6962610,\"order_book\":{\"code\":0,\"asks\":[],\"bids\":[{\"price\":\"92948.0\",\"size\":\"0.02905\"},{\"price\":\"92945.9\",\"size\":\"0.38767\"}],\"offset\":6962610,\"nonce\":3691009103},\"timestamp\":1765394044859,\"type\":\"update/order_book\"}"
    "msg": "{\"channel\":\"order_book:1\",\"offset\":6962611,\"order_book\":{\"code\":0,\"asks\":[{\"price\":\"92963.0\",\"size\":\"0.00000\"},{\"price\":\"92964.3\",\"size\":\"0.10760\"}],\"bids\":[{\"price\":\"92948.6\",\"size\":\"0.00215\"}],\"offset\":6962611,\"nonce\":3691009104},\"timestamp\":1765394044866,\"type\":\"update/order_book\"}"
    "msg": "{\"channel\":\"order_book:1\",\"offset\":6962612,\"order_book\":{\"code\":0,\"asks\":[{\"price\":\"92965.8\",\"size\":\"0.00000\"},{\"price\":\"92966.1\",\"size\":\"0.10760\"}],\"bids\":[{\"price\":\"92943.9\",\"size\":\"0.00000\"}],\"offset\":6962612,\"nonce\":3691009105},\"timestamp\":1765394044869,\"type\":\"update/order_book\"}"
    "msg": "{\"channel\":\"order_book:1\",\"offset\":6962614,\"order_book\":{\"code\":0,\"asks\":[{\"price\":\"92957.1\",\"size\":\"0.08000\"},{\"price\":\"93023.3\",\"size\":\"0.00000\"}],\"bids\":[{\"price\":\"92957.0\",\"size\":\"0.88733\"}],\"offset\":6962614,\"nonce\":3691009107},\"timestamp\":1765394044882,\"type\":\"update/order_book\"}"
    "msg": "{\"channel\":\"order_book:1\",\"offset\":6962615,\"order_book\":{\"code\":0,\"asks\":[],\"bids\":[{\"price\":\"92953.6\",\"size\":\"0.38767\"},{\"price\":\"92912.1\",\"size\":\"0.00000\"}],\"offset\":6962615,\"nonce\":3691009109},\"timestamp\":1765394044891,\"type\":\"update/order_book\"}"
    "msg": "{\"channel\":\"order_book:1\",\"offset\":6962616,\"order_book\":{\"code\":0,\"asks\":[{\"price\":\"92963.4\",\"size\":\"0.04624\"}],\"bids\":[{\"price\":\"92934.3\",\"size\":\"0.10780\"},{\"price\":\"92932.5\",\"size\":\"0.00000\"}],\"offset\":6962616,\"nonce\":3691009110},\"timestamp\":1765394044895,\"type\":\"update/order_book\"}"
    "msg": "{\"channel\":\"order_book:1\",\"offset\":6962617,\"order_book\":{\"code\":0,\"asks\":[{\"price\":\"92962.4\",\"size\":\"0.02834\"},{\"price\":\"92983.8\",\"size\":\"0.00000\"}],\"bids\":[{\"price\":\"92913.1\",\"size\":\"0.37787\"}],\"offset\":6962617,\"nonce\":3691009111},\"timestamp\":1765394044905,\"type\":\"update/order_book\"}"
    "msg": "{\"channel\":\"order_book:1\",\"offset\":6962618,\"order_book\":{\"code\":0,\"asks\":[{\"price\":\"92957.1\",\"size\":\"0.00000\"}],\"bids\":[{\"price\":\"92951.4\",\"size\":\"1.07758\"},{\"price\":\"92950.9\",\"size\":\"0.10760\"},{\"price\":\"92949.8\",\"size\":\"0.89030\"}],\"offset\":6962618,\"nonce\":3691009112},\"timestamp\":1765394044908,\"type\":\"update/order_book\"}"
    "msg": "{\"channel\":\"order_book:1\",\"offset\":6962619,\"order_book\":{\"code\":0,\"asks\":[{\"price\":\"92957.3\",\"size\":\"1.07758\"},{\"price\":\"92966.1\",\"size\":\"0.00000\"},{\"price\":\"92967.1\",\"size\":\"0.12208\"}],\"bids\":[],\"offset\":6962619,\"nonce\":3691009113},\"timestamp\":1765394044910,\"type\":\"update/order_book\"}"
    "msg": "{\"channel\":\"order_book:1\",\"offset\":6962620,\"order_book\":{\"code\":0,\"asks\":[],\"bids\":[{\"price\":\"92957.0\",\"size\":\"0.00000\"}],\"offset\":6962620,\"nonce\":3691009114},\"timestamp\":1765394044918,\"type\":\"update/order_book\"}"
    "msg": "{\"channel\":\"order_book:1\",\"offset\":6962621,\"order_book\":{\"code\":0,\"asks\":[{\"price\":\"92957.3\",\"size\":\"0.00000\"},{\"price\":\"92975.5\",\"size\":\"0.02828\"},{\"price\":\"92988.9\",\"size\":\"0.57650\"},{\"price\":\"93086.8\",\"size\":\"0.00000\"}],\"bids\":[{\"price\":\"92780.7\",\"size\":\"0.00000\"}],\"offset\":6962621,\"nonce\":3691009115},\"timestamp\":1765394044922,\"type\":\"update/order_book\"}"
    "msg": "{\"channel\":\"order_book:1\",\"offset\":6962622,\"order_book\":{\"code\":0,\"asks\":[{\"price\":\"92964.3\",\"size\":\"0.00000\"},{\"price\":\"92965.3\",\"size\":\"0.10760\"}],\"bids\":[],\"offset\":6962622,\"nonce\":3691009117},\"timestamp\":1765394044932,\"type\":\"update/order_book\"}"
    "msg": "{\"channel\":\"order_book:1\",\"offset\":6962623,\"order_book\":{\"code\":0,\"asks\":[{\"price\":\"92961.9\",\"size\":\"0.00000\"},{\"price\":\"92971.2\",\"size\":\"0.00500\"}],\"bids\":[{\"price\":\"92957.2\",\"size\":\"0.83043\"}],\"offset\":6962623,\"nonce\":3691009119},\"timestamp\":1765394044942,\"type\":\"update/order_book\"}"
    "msg": "{\"channel\":\"order_book:1\",\"offset\":6962624,\"order_book\":{\"code\":0,\"asks\":[{\"price\":\"92957.8\",\"size\":\"0.00000\"}],\"bids\":[],\"offset\":6962624,\"nonce\":3691009120},\"timestamp\":1765394044947,\"type\":\"update/order_book\"}"
    "msg": "{\"channel\":\"order_book:1\",\"offset\":6962625,\"order_book\":{\"code\":0,\"asks\":[],\"bids\":[{\"price\":\"92957.2\",\"size\":\"0.29182\"},{\"price\":\"92953.6\",\"size\":\"1.19176\"}],\"offset\":6962625,\"nonce\":3691009121},\"timestamp\":1765394044951,\"type\":\"update/order_book\"}"
    "msg": "{\"channel\":\"order_book:1\",\"offset\":6962626,\"order_book\":{\"code\":0,\"asks\":[],\"bids\":[{\"price\":\"92946.2\",\"size\":\"0.00000\"}],\"offset\":6962626,\"nonce\":3691009124},\"timestamp\":1765394044962,\"type\":\"update/order_book\"}"
    "msg": "{\"channel\":\"order_book:1\",\"offset\":6962627,\"order_book\":{\"code\":0,\"asks\":[{\"price\":\"92960.4\",\"size\":\"0.08084\"},{\"price\":\"92984.8\",\"size\":\"0.00302\"},{\"price\":\"93098.2\",\"size\":\"8.07918\"}],\"bids\":[{\"price\":\"92957.2\",\"size\":\"1.08420\"},{\"price\":\"92946.9\",\"size\":\"0.00000\"}],\"offset\":6962627,\"nonce\":3691009127},\"timestamp\":1765394044980,\"type\":\"update/order_book\"}"
    "msg": "{\"channel\":\"order_book:1\",\"offset\":6962628,\"order_book\":{\"code\":0,\"asks\":[],\"bids\":[{\"price\":\"92935.9\",\"size\":\"0.11640\"},{\"price\":\"92934.3\",\"size\":\"0.00000\"}],\"offset\":6962628,\"nonce\":3691009128},\"timestamp\":1765394044985,\"type\":\"update/order_book\"}"
    "msg": "{\"channel\":\"order_book:1\",\"offset\":6962629,\"order_book\":{\"code\":0,\"asks\":[],\"bids\":[{\"price\":\"92952.1\",\"size\":\"0.10760\"},{\"price\":\"92950.9\",\"size\":\"0.00000\"}],\"offset\":6962629,\"nonce\":3691009129},\"timestamp\":1765394044987,\"type\":\"update/order_book\"}"
    "msg": "{\"channel\":\"order_book:1\",\"offset\":6962630,\"order_book\":{\"code\":0,\"asks\":[{\"price\":\"92961.0\",\"size\":\"1.07758\"},{\"price\":\"92967.1\",\"size\":\"0.01448\"},{\"price\":\"92968.3\",\"size\":\"0.10760\"}],\"bids\":[],\"offset\":6962630,\"nonce\":3691009130},\"timestamp\":1765394044997,\"type\":\"update/order_book\"}"
    "msg": "{\"channel\":\"order_book:1\",\"offset\":6962631,\"order_book\":{\"code\":0,\"asks\":[{\"price\":\"92965.3\",\"size\":\"0.00000\"},{\"price\":\"92966.6\",\"size\":\"0.10760\"}],\"bids\":[],\"offset\":6962631,\"nonce\":3691009131},\"timestamp\":1765394045001,\"type\":\"update/order_book\"}"
    "msg": "{\"channel\":\"order_book:1\",\"offset\":6962632,\"order_book\":{\"code\":0,\"asks\":[],\"bids\":[{\"price\":\"92948.0\",\"size\":\"0.00000\"},{\"price\":\"92711.9\",\"size\":\"0.00000\"}],\"offset\":6962632,\"nonce\":3691009132},\"timestamp\":1765394045006,\"type\":\"update/order_book\"}"
    "msg": "{\"channel\":\"order_book:1\",\"offset\":6962633,\"order_book\":{\"code\":0,\"asks\":[],\"bids\":[{\"price\":\"92949.9\",\"size\":\"1.78249\"}],\"offset\":6962633,\"nonce\":3691009133},\"timestamp\":1765394045016,\"type\":\"update/order_book\"}"
    "msg": "{\"channel\":\"order_book:1\",\"offset\":6962634,\"order_book\":{\"code\":0,\"asks\":[{\"price\":\"92960.3\",\"size\":\"0.10000\"}],\"bids\":[],\"offset\":6962634,\"nonce\":3691009135},\"timestamp\":1765394045022,\"type\":\"update/order_book\"}"
    "msg": "{\"channel\":\"order_book:1\",\"offset\":6962635,\"order_book\":{\"code\":0,\"asks\":[],\"bids\":[{\"price\":\"92812.7\",\"size\":\"1.08933\"}],\"offset\":6962635,\"nonce\":3691009136},\"timestamp\":1765394045023,\"type\":\"update/order_book\"}"
    "msg": "{\"channel\":\"order_book:1\",\"offset\":6962636,\"order_book\":{\"code\":0,\"asks\":[{\"price\":\"92959.5\",\"size\":\"0.00020\"},{\"price\":\"93000.5\",\"size\":\"2.29247\"},{\"price\":\"93005.4\",\"size\":\"0.00000\"}],\"bids\":[{\"price\":\"92926.6\",\"size\":\"4.67752\"},{\"price\":\"92921.5\",\"size\":\"0.00108\"},{\"price\":\"92916.5\",\"size\":\"0.00500\"}],\"offset\":6962636,\"nonce\":3691009137},\"timestamp\":1765394045031,\"type\":\"update/order_book\"}"
    "msg": "{\"channel\":\"order_book:1\",\"offset\":6962637,\"order_book\":{\"code\":0,\"asks\":[],\"bids\":[{\"price\":\"92950.2\",\"size\":\"0.10760\"},{\"price\":\"92946.7\",\"size\":\"0.00000\"}],\"offset\":6962637,\"nonce\":3691009141},\"timestamp\":1765394045040,\"type\":\"update/order_book\"}"
    "msg": "{\"channel\":\"order_book:1\",\"offset\":6962638,\"order_book\":{\"code\":0,\"asks\":[],\"bids\":[{\"price\":\"92957.2\",\"size\":\"1.07253\"},{\"price\":\"92951.3\",\"size\":\"0.13446\"},{\"price\":\"92869.6\",\"size\":\"0.00000\"}],\"offset\":6962638,\"nonce\":3691009142},\"timestamp\":1765394045049,\"type\":\"update/order_book\"}"
    "msg": "{\"channel\":\"order_book:1\",\"offset\":6962640,\"order_book\":{\"code\":0,\"asks\":[{\"price\":\"92959.5\",\"size\":\"0.00000\"},{\"price\":\"92966.1\",\"size\":\"0.25166\"}],\"bids\":[{\"price\":\"92957.2\",\"size\":\"0.00000\"}],\"offset\":6962640,\"nonce\":3691009147},\"timestamp\":1765394045061,\"type\":\"update/order_book\"}"
    "msg": "{\"channel\":\"order_book:1\",\"offset\":6962641,\"order_book\":{\"code\":0,\"asks\":[],\"bids\":[{\"price\":\"92953.6\",\"size\":\"0.38767\"},{\"price\":\"92953.3\",\"size\":\"0.90517\"},{\"price\":\"92952.1\",\"size\":\"0.00000\"},{\"price\":\"92950.2\",\"size\":\"0.00000\"},{\"price\":\"92947.4\",\"size\":\"0.08081\"},{\"price\":\"92941.9\",\"size\":\"0.08086\"},{\"price\":\"92941.6\",\"size\":\"0.08082\"}],\"offset\":6962641,\"nonce\":3691009148},\"timestamp\":1765394045071,\"type\":\"update/order_book\"}"
    "msg": "{\"channel\":\"order_book:1\",\"offset\":6962642,\"order_book\":{\"code\":0,\"asks\":[{\"price\":\"92963.7\",\"size\":\"0.10760\"},{\"price\":\"92965.6\",\"size\":\"0.08079\"},{\"price\":\"92968.5\",\"size\":\"0.38767\"}],\"bids\":[{\"price\":\"92953.6\",\"size\":\"0.00000\"},{\"price\":\"92953.3\",\"size\":\"0.00000\"},{\"price\":\"92953.2\",\"size\":\"0.00000\"},{\"price\":\"92950.1\",\"size\":\"0.00000\"},{\"price\":\"92935.9\",\"size\":\"0.00860\"}],\"offset\":6962642,\"nonce\":3691009149},\"timestamp\":1765394045077,\"type\":\"update/order_book\"}"
    "msg": "{\"channel\":\"order_book:1\",\"offset\":6962643,\"order_book\":{\"code\":0,\"asks\":[{\"price\":\"92957.3\",\"size\":\"0.87916\"},{\"price\":\"92959.5\",\"size\":\"0.94686\"}],\"bids\":[{\"price\":\"92928.1\",\"size\":\"0.00500\"},{\"price\":\"92916.5\",\"size\":\"0.00000\"},{\"price\":\"92840.0\",\"size\":\"0.00538\"},{\"price\":\"92803.1\",\"size\":\"0.00000\"}],\"offset\":6962643,\"nonce\":3691009150},\"timestamp\":1765394045079,\"type\":\"update/order_book\"}"
    "msg": "{\"channel\":\"order_book:1\",\"offset\":6962644,\"order_book\":{\"code\":0,\"asks\":[{\"price\":\"92999.3\",\"size\":\"0.00000\"},{\"price\":\"93025.0\",\"size\":\"0.31912\"}],\"bids\":[],\"offset\":6962644,\"nonce\":3691009151},\"timestamp\":1765394045083,\"type\":\"update/order_book\"}"
    "msg": "{\"channel\":\"order_book:1\",\"offset\":6962645,\"order_book\":{\"code\":0,\"asks\":[{\"price\":\"92960.0\",\"size\":\"0.10760\"},{\"price\":\"92960.3\",\"size\":\"0.91531\"},{\"price\":\"92966.6\",\"size\":\"0.00000\"},{\"price\":\"93048.9\",\"size\":\"0.00000\"},{\"price\":\"93086.0\",\"size\":\"0.00538\"}],\"bids\":[{\"price\":\"92948.7\",\"size\":\"0.00000\"}],\"offset\":6962645,\"nonce\":3691009154},\"timestamp\":1765394045087,\"type\":\"update/order_book\"}"
    "msg": "{\"channel\":\"order_book:1\",\"offset\":6962646,\"order_book\":{\"code\":0,\"asks\":[{\"price\":\"92957.3\",\"size\":\"0.87833\"},{\"price\":\"92960.2\",\"size\":\"0.00020\"},{\"price\":\"92962.2\",\"size\":\"0.10760\"},{\"price\":\"92965.5\",\"size\":\"0.38767\"},{\"price\":\"92968.3\",\"size\":\"0.00000\"},{\"price\":\"92981.4\",\"size\":\"0.00000\"}],\"bids\":[{\"price\":\"92945.9\",\"size\":\"0.49527\"}],\"offset\":6962646,\"nonce\":3691009155},\"timestamp\":1765394045091,\"type\":\"update/order_book\"}"
    "msg": "{\"channel\":\"order_book:1\",\"offset\":6962647,\"order_book\":{\"code\":0,\"asks\":[{\"price\":\"92957.3\",\"size\":\"0.87586\"}],\"bids\":[],\"offset\":6962647,\"nonce\":3691009156},\"timestamp\":1765394045096,\"type\":\"update/order_book\"}"
    "msg": "{\"channel\":\"order_book:1\",\"offset\":6962648,\"order_book\":{\"code\":0,\"asks\":[{\"price\":\"92957.3\",\"size\":\"1.81382\"}],\"bids\":[],\"offset\":6962648,\"nonce\":3691009161},\"timestamp\":1765394045106,\"type\":\"update/order_book\"}"
    "msg": "{\"channel\":\"order_book:1\",\"offset\":6962649,\"order_book\":{\"code\":0,\"asks\":[],\"bids\":[{\"price\":\"92930.0\",\"size\":\"0.00108\"},{\"price\":\"92921.5\",\"size\":\"0.00000\"}],\"offset\":6962649,\"nonce\":3691009167},\"timestamp\":1765394045126,\"type\":\"update/order_book\"}"
    "msg": "{\"channel\":\"order_book:1\",\"offset\":6962650,\"order_book\":{\"code\":0,\"asks\":[{\"price\":\"92970.7\",\"size\":\"0.00000\"},{\"price\":\"92998.3\",\"size\":\"2.29253\"},{\"price\":\"93000.5\",\"size\":\"0.00000\"}],\"bids\":[{\"price\":\"92935.1\",\"size\":\"4.67913\"},{\"price\":\"92926.6\",\"size\":\"0.00000\"}],\"offset\":6962650,\"nonce\":3691009168},\"timestamp\":1765394045135,\"type\":\"update/order_book\"}"
    "msg": "{\"channel\":\"order_book:1\",\"offset\":6962651,\"order_book\":{\"code\":0,\"asks\":[{\"price\":\"92960.2\",\"size\":\"0.21514\"},{\"price\":\"92963.8\",\"size\":\"0.00000\"}],\"bids\":[{\"price\":\"92949.9\",\"size\":\"0.89184\"},{\"price\":\"92949.8\",\"size\":\"0.00000\"}],\"offset\":6962651,\"nonce\":3691009169},\"timestamp\":1765394045140,\"type\":\"update/order_book\"}"
    "msg": "{\"channel\":\"order_book:1\",\"offset\":6962653,\"order_book\":{\"code\":0,\"asks\":[],\"bids\":[{\"price\":\"92952.1\",\"size\":\"0.38767\"}],\"offset\":6962653,\"nonce\":3691009171},\"timestamp\":1765394045154,\"type\":\"update/order_book\"}"
    "msg": "{\"channel\":\"order_book:1\",\"offset\":6962654,\"order_book\":{\"code\":0,\"asks\":[],\"bids\":[{\"price\":\"92951.4\",\"size\":\"1.07758\"}],\"offset\":6962654,\"nonce\":3691009173},\"timestamp\":1765394045170,\"type\":\"update/order_book\"}"
    "msg": "{\"channel\":\"order_book:1\",\"offset\":6962655,\"order_book\":{\"code\":0,\"asks\":[{\"price\":\"92959.5\",\"size\":\"1.05446\"},{\"price\":\"92963.7\",\"size\":\"0.00000\"}],\"bids\":[{\"price\":\"92950.5\",\"size\":\"0.00021\"}],\"offset\":6962655,\"nonce\":3691009174},\"timestamp\":1765394045174,\"type\":\"update/order_book\"}"
    "msg": "{\"channel\":\"order_book:1\",\"offset\":6962656,\"order_book\":{\"code\":0,\"asks\":[{\"price\":\"92957.3\",\"size\":\"0.87626\"}],\"bids\":[],\"offset\":6962656,\"nonce\":3691009175},\"timestamp\":1765394045175,\"type\":\"update/order_book\"}"
    "msg": "{\"channel\":\"order_book:1\",\"offset\":6962657,\"order_book\":{\"code\":0,\"asks\":[{\"price\":\"92957.3\",\"size\":\"0.00000\"},{\"price\":\"92959.5\",\"size\":\"0.10760\"},{\"price\":\"92960.3\",\"size\":\"0.10000\"}],\"bids\":[{\"price\":\"92952.1\",\"size\":\"0.00000\"},{\"price\":\"92930.1\",\"size\":\"0.10780\"}],\"offset\":6962657,\"nonce\":3691009176},\"timestamp\":1765394045183,\"type\":\"update/order_book\"}"
    "msg": "{\"channel\":\"order_book:1\",\"offset\":6962658,\"order_book\":{\"code\":0,\"asks\":[{\"price\":\"92960.0\",\"size\":\"0.00000\"},{\"price\":\"92961.1\",\"size\":\"0.10760\"}],\"bids\":[{\"price\":\"92947.2\",\"size\":\"1.84835\"},{\"price\":\"92945.9\",\"size\":\"0.38767\"}],\"offset\":6962658,\"nonce\":3691009177},\"timestamp\":1765394045186,\"type\":\"update/order_book\"}"
    "msg": "{\"channel\":\"order_book:1\",\"offset\":6962659,\"order_book\":{\"code\":0,\"asks\":[{\"price\":\"92962.2\",\"size\":\"0.00000\"},{\"price\":\"92963.4\",\"size\":\"0.15384\"}],\"bids\":[{\"price\":\"92951.4\",\"size\":\"1.07558\"}],\"offset\":6962659,\"nonce\":3691009179},\"timestamp\":1765394045191,\"type\":\"update/order_book\"}"
    "msg": "{\"channel\":\"order_book:1\",\"offset\":6962660,\"order_book\":{\"code\":0,\"asks\":[{\"price\":\"92959.5\",\"size\":\"0.00000\"},{\"price\":\"92961.1\",\"size\":\"0.00000\"},{\"price\":\"92963.4\",\"size\":\"0.04624\"}],\"bids\":[{\"price\":\"92952.2\",\"size\":\"0.88962\"},{\"price\":\"92952.1\",\"size\":\"0.91246\"}],\"offset\":6962660,\"nonce\":3691009180},\"timestamp\":1765394045193,\"type\":\"update/order_book\"}"
    "msg": "{\"channel\":\"order_book:1\",\"offset\":6962661,\"order_book\":{\"code\":0,\"asks\":[{\"price\":\"92960.2\",\"size\":\"0.00000\"},{\"price\":\"92963.4\",\"size\":\"0.03764\"},{\"price\":\"92965.5\",\"size\":\"0.00000\"}],\"bids\":[],\"offset\":6962661,\"nonce\":3691009183},\"timestamp\":1765394045199,\"type\":\"update/order_book\"}"
    "msg": "{\"channel\":\"order_book:1\",\"offset\":6962662,\"order_book\":{\"code\":0,\"asks\":[],\"bids\":[{\"price\":\"92944.6\",\"size\":\"0.00000\"}],\"offset\":6962662,\"nonce\":3691009186},\"timestamp\":1765394045203,\"type\":\"update/order_book\"}"
    "msg": "{\"channel\":\"order_book:1\",\"offset\":6962663,\"order_book\":{\"code\":0,\"asks\":[{\"price\":\"92965.1\",\"size\":\"0.00000\"}],\"bids\":[{\"price\":\"92951.4\",\"size\":\"1.87795\"}],\"offset\":6962663,\"nonce\":3691009187},\"timestamp\":1765394045212,\"type\":\"update/order_book\"}"
    "msg": "{\"channel\":\"order_book:1\",\"offset\":6962664,\"order_book\":{\"code\":0,\"asks\":[],\"bids\":[{\"price\":\"92944.9\",\"size\":\"0.01075\"}],\"offset\":6962664,\"nonce\":3691009188},\"timestamp\":1765394045215,\"type\":\"update/order_book\"}"
    "msg": "{\"channel\":\"order_book:1\",\"offset\":6962665,\"order_book\":{\"code\":0,\"asks\":[{\"price\":\"92985.7\",\"size\":\"0.08081\"},{\"price\":\"92990.9\",\"size\":\"2.29272\"},{\"price\":\"92998.3\",\"size\":\"0.00000\"}],\"bids\":[{\"price\":\"92952.6\",\"size\":\"0.38767\"},{\"price\":\"92952.2\",\"size\":\"1.77971\"},{\"price\":\"92930.5\",\"size\":\"0.00108\"},{\"price\":\"92930.0\",\"size\":\"0.00000\"},{\"price\":\"92913.1\",\"size\":\"0.36711\"}],\"offset\":6962665,\"nonce\":3691009191},\"timestamp\":1765394045228,\"type\":\"update/order_book\"}"
    "msg": "{\"channel\":\"order_book:1\",\"offset\":6962666,\"order_book\":{\"code\":0,\"asks\":[],\"bids\":[{\"price\":\"92935.6\",\"size\":\"4.68108\"},{\"price\":\"92935.1\",\"size\":\"0.00000\"}],\"offset\":6962666,\"nonce\":3691009192},\"timestamp\":1765394045230,\"type\":\"update/order_book\"}"
    "msg": "{\"channel\":\"order_book:1\",\"offset\":6962667,\"order_book\":{\"code\":0,\"asks\":[{\"price\":\"92955.8\",\"size\":\"0.01060\"}],\"bids\":[{\"price\":\"92944.9\",\"size\":\"0.00000\"}],\"offset\":6962667,\"nonce\":3691009193},\"timestamp\":1765394045233,\"type\":\"update/order_book\"}"
    "msg": "{\"channel\":\"order_book:1\",\"offset\":6962669,\"order_book\":{\"code\":0,\"asks\":[],\"bids\":[{\"price\":\"92952.7\",\"size\":\"0.84393\"},{\"price\":\"92945.5\",\"size\":\"0.00000\"},{\"price\":\"92905.6\",\"size\":\"0.00000\"}],\"offset\":6962669,\"nonce\":3691009196},\"timestamp\":1765394045251,\"type\":\"update/order_book\"}"
    "msg": "{\"channel\":\"order_book:1\",\"offset\":6962670,\"order_book\":{\"code\":0,\"asks\":[],\"bids\":[{\"price\":\"92923.4\",\"size\":\"0.00000\"}],\"offset\":6962670,\"nonce\":3691009198},\"timestamp\":1765394045255,\"type\":\"update/order_book\"}"
    "msg": "{\"channel\":\"order_book:1\",\"offset\":6962672,\"order_book\":{\"code\":0,\"asks\":[{\"price\":\"92960.3\",\"size\":\"0.17520\"},{\"price\":\"92967.3\",\"size\":\"0.00000\"}],\"bids\":[],\"offset\":6962672,\"nonce\":3691009202},\"timestamp\":1765394045274,\"type\":\"update/order_book\"}"
    "msg": "{\"channel\":\"order_book:1\",\"offset\":6962673,\"order_book\":{\"code\":0,\"asks\":[{\"price\":\"92955.8\",\"size\":\"0.08580\"}],\"bids\":[{\"price\":\"92932.5\",\"size\":\"0.10780\"},{\"price\":\"92930.1\",\"size\":\"0.00000\"},{\"price\":\"92774.9\",\"size\":\"0.00000\"}],\"offset\":6962673,\"nonce\":3691009204},\"timestamp\":1765394045281,\"type\":\"update/order_book\"}"
    "msg": "{\"channel\":\"order_book:1\",\"offset\":6962674,\"order_book\":{\"code\":0,\"asks\":[{\"price\":\"92965.5\",\"size\":\"0.10760\"}],\"bids\":[],\"offset\":6962674,\"nonce\":3691009206},\"timestamp\":1765394045283,\"type\":\"update/order_book\"}"
    "msg": "{\"channel\":\"order_book:1\",\"offset\":6962676,\"order_book\":{\"code\":0,\"asks\":[{\"price\":\"92955.8\",\"size\":\"0.06967\"}],\"bids\":[],\"offset\":6962676,\"nonce\":3691009213},\"timestamp\":1765394045297,\"type\":\"update/order_book\"}"
    "msg": "{\"channel\":\"order_book:1\",\"offset\":6962677,\"order_book\":{\"code\":0,\"asks\":[],\"bids\":[{\"price\":\"92952.7\",\"size\":\"1.73619\"}],\"offset\":6962677,\"nonce\":3691009214},\"timestamp\":1765394045299,\"type\":\"update/order_book\"}"
    "msg": "{\"channel\":\"order_book:1\",\"offset\":6962678,\"order_book\":{\"code\":0,\"asks\":[],\"bids\":[{\"price\":\"92950.3\",\"size\":\"0.22512\"}],\"offset\":6962678,\"nonce\":3691009219},\"timestamp\":1765394045306,\"type\":\"update/order_book\"}"
    "msg": "{\"channel\":\"order_book:1\",\"offset\":6962679,\"order_book\":{\"code\":0,\"asks\":[],\"bids\":[{\"price\":\"92803.5\",\"size\":\"0.00000\"}],\"offset\":6962679,\"nonce\":3691009226},\"timestamp\":1765394045316,\"type\":\"update/order_book\"}"
    "msg": "{\"channel\":\"order_book:1\",\"offset\":6962680,\"order_book\":{\"code\":0,\"asks\":[{\"price\":\"92965.4\",\"size\":\"0.38767\"}],\"bids\":[],\"offset\":6962680,\"nonce\":3691009229},\"timestamp\":1765394045319,\"type\":\"update/order_book\"}"
    "msg": "{\"channel\":\"order_book:1\",\"offset\":6962681,\"order_book\":{\"code\":0,\"asks\":[{\"price\":\"93001.1\",\"size\":\"2.16068\"}],\"bids\":[],\"offset\":6962681,\"nonce\":3691009233},\"timestamp\":1765394045331,\"type\":\"update/order_book\"}"
    "msg": "{\"channel\":\"order_book:1\",\"offset\":6962682,\"order_book\":{\"code\":0,\"asks\":[{\"price\":\"93004.2\",\"size\":\"0.10778\"}],\"bids\":[],\"offset\":6962682,\"nonce\":3691009234},\"timestamp\":1765394045341,\"type\":\"update/order_book\"}"
    "msg": "{\"channel\":\"order_book:1\",\"offset\":6962683,\"order_book\":{\"code\":0,\"asks\":[{\"price\":\"92962.3\",\"size\":\"0.00000\"}],\"bids\":[],\"offset\":6962683,\"nonce\":3691009235},\"timestamp\":1765394045344,\"type\":\"update/order_book\"}"
    "msg": "{\"channel\":\"order_book:1\",\"offset\":6962684,\"order_book\":{\"code\":0,\"asks\":[{\"price\":\"92960.3\",\"size\":\"0.10000\"},{\"price\":\"92977.4\",\"size\":\"0.08081\"}],\"bids\":[],\"offset\":6962684,\"nonce\":3691009236},\"timestamp\":1765394045363,\"type\":\"update/order_book\"}"
    "msg": "{\"channel\":\"order_book:1\",\"offset\":6962685,\"order_book\":{\"code\":0,\"asks\":[],\"bids\":[{\"price\":\"92952.2\",\"size\":\"0.88962\"},{\"price\":\"92952.1\",\"size\":\"0.00000\"}],\"offset\":6962685,\"nonce\":3691009238},\"timestamp\":1765394045375,\"type\":\"update/order_book\"}"
    "msg": "{\"channel\":\"order_book:1\",\"offset\":6962686,\"order_book\":{\"code\":0,\"asks\":[{\"price\":\"92961.0\",\"size\":\"0.00000\"},{\"price\":\"92964.1\",\"size\":\"0.00000\"}],\"bids\":[{\"price\":\"92952.7\",\"size\":\"0.00000\"},{\"price\":\"92952.6\",\"size\":\"0.00000\"},{\"price\":\"92952.2\",\"size\":\"0.00000\"},{\"price\":\"92951.4\",\"size\":\"0.00000\"},{\"price\":\"92950.3\",\"size\":\"0.00000\"},{\"price\":\"92949.2\",\"size\":\"0.00000\"},{\"price\":\"92935.7\",\"size\":\"0.00000\"}],\"offset\":6962686,\"nonce\":3691009239},\"timestamp\":1765394045387,\"type\":\"update/order_book\"}"
    "msg": "{\"channel\":\"order_book:1\",\"offset\":6962687,\"order_book\":{\"code\":0,\"asks\":[{\"price\":\"92955.7\",\"size\":\"0.97632\"},{\"price\":\"92955.8\",\"size\":\"0.93040\"},{\"price\":\"92961.3\",\"size\":\"0.10760\"},{\"price\":\"92962.9\",\"size\":\"0.00000\"}],\"bids\":[{\"price\":\"92948.6\",\"size\":\"0.00000\"},{\"price\":\"92945.5\",\"size\":\"0.00000\"},{\"price\":\"92932.5\",\"size\":\"0.00000\"}],\"offset\":6962687,\"nonce\":3691009241},\"timestamp\":1765394045392,\"type\":\"update/order_book\"}"
    "msg": "{\"channel\":\"order_book:1\",\"offset\":6962688,\"order_book\":{\"code\":0,\"asks\":[],\"bids\":[{\"price\":\"92945.5\",\"size\":\"0.01075\"}],\"offset\":6962688,\"nonce\":3691009246},\"timestamp\":1765394045401,\"type\":\"update/order_book\"}"
    "msg": "{\"channel\":\"order_book:1\",\"offset\":6962689,\"order_book\":{\"code\":0,\"asks\":[{\"price\":\"92958.5\",\"size\":\"0.10760\"},{\"price\":\"92960.5\",\"size\":\"0.10760\"},{\"price\":\"92963.5\",\"size\":\"0.00000\"},{\"price\":\"92965.5\",\"size\":\"0.00000\"}],\"bids\":[{\"price\":\"92947.2\",\"size\":\"0.00000\"},{\"price\":\"92944.2\",\"size\":\"0.10760\"}],\"offset\":6962689,\"nonce\":3691009252},\"timestamp\":1765394045406,\"type\":\"update/order_book\"}"
    "msg": "{\"channel\":\"order_book:1\",\"offset\":6962690,\"order_book\":{\"code\":0,\"asks\":[],\"bids\":[{\"price\":\"92949.9\",\"size\":\"0.00000\"}],\"offset\":6962690,\"nonce\":3691009254},\"timestamp\":1765394045413,\"type\":\"update/order_book\"}"
    "msg": "{\"channel\":\"order_book:1\",\"offset\":6962691,\"order_book\":{\"code\":0,\"asks\":[{\"price\":\"92962.4\",\"size\":\"0.00000\"}],\"bids\":[{\"price\":\"92945.5\",\"size\":\"0.00000\"}],\"offset\":6962691,\"nonce\":3691009256},\"timestamp\":1765394045416,\"type\":\"update/order_book\"}"
    "msg": "{\"channel\":\"order_book:1\",\"offset\":6962692,\"order_book\":{\"code\":0,\"asks\":[{\"price\":\"92955.7\",\"size\":\"1.77527\"}],\"bids\":[],\"offset\":6962692,\"nonce\":3691009257},\"timestamp\":1765394045421,\"type\":\"update/order_book\"}"
    "msg": "{\"channel\":\"order_book:1\",\"offset\":6962693,\"order_book\":{\"code\":0,\"asks\":[{\"price\":\"92960.4\",\"size\":\"0.10918\"}],\"bids\":[],\"offset\":6962693,\"nonce\":3691009259},\"timestamp\":1765394045427,\"type\":\"update/order_book\"}"
    "msg": "{\"channel\":\"order_book:1\",\"offset\":6962695,\"order_book\":{\"code\":0,\"asks\":[{\"price\":\"92958.5\",\"size\":\"0.00000\"},{\"price\":\"92960.5\",\"size\":\"0.00000\"}],\"bids\":[{\"price\":\"92946.9\",\"size\":\"0.02905\"}],\"offset\":6962695,\"nonce\":3691009268},\"timestamp\":1765394045455,\"type\":\"update/order_book\"}"
    "msg": "{\"channel\":\"order_book:1\",\"offset\":6962696,\"order_book\":{\"code\":0,\"asks\":[],\"bids\":[{\"price\":\"92951.4\",\"size\":\"0.38767\"}],\"offset\":6962696,\"nonce\":3691009282},\"timestamp\":1765394045488,\"type\":\"update/order_book\"}"
    "msg": "{\"channel\":\"order_book:1\",\"offset\":6962697,\"order_book\":{\"code\":0,\"asks\":[{\"price\":\"92967.1\",\"size\":\"0.02308\"}],\"bids\":[],\"offset\":6962697,\"nonce\":3691009283},\"timestamp\":1765394045493,\"type\":\"update/order_book\"}"
    "msg": "{\"channel\":\"order_book:1\",\"offset\":6962698,\"order_book\":{\"code\":0,\"asks\":[{\"price\":\"92955.7\",\"size\":\"0.79895\"},{\"price\":\"92964.6\",\"size\":\"0.10760\"}],\"bids\":[{\"price\":\"92935.9\",\"size\":\"0.00000\"},{\"price\":\"92931.8\",\"size\":\"0.10780\"}],\"offset\":6962698,\"nonce\":3691009284},\"timestamp\":1765394045495,\"type\":\"update/order_book\"}"
    "msg": "{\"channel\":\"order_book:1\",\"offset\":6962699,\"order_book\":{\"code\":0,\"asks\":[{\"price\":\"92955.7\",\"size\":\"0.00000\"},{\"price\":\"92955.8\",\"size\":\"0.06967\"},{\"price\":\"92964.6\",\"size\":\"0.00000\"}],\"bids\":[],\"offset\":6962699,\"nonce\":3691009286},\"timestamp\":1765394045503,\"type\":\"update/order_book\"}"
    "msg": "{\"channel\":\"order_book:1\",\"offset\":6962700,\"order_book\":{\"code\":0,\"asks\":[],\"bids\":[{\"price\":\"92948.3\",\"size\":\"0.14524\"},{\"price\":\"92944.2\",\"size\":\"0.00000\"}],\"offset\":6962700,\"nonce\":3691009290},\"timestamp\":1765394045507,\"type\":\"update/order_book\"}"
    "msg": "{\"channel\":\"order_book:1\",\"offset\":6962701,\"order_book\":{\"code\":0,\"asks\":[{\"price\":\"92961.3\",\"size\":\"0.00000\"},{\"price\":\"92963.8\",\"size\":\"0.10760\"}],\"bids\":[{\"price\":\"92951.5\",\"size\":\"0.78666\"},{\"price\":\"92948.3\",\"size\":\"0.15384\"},{\"price\":\"92945.5\",\"size\":\"0.00000\"}],\"offset\":6962701,\"nonce\":3691009293},\"timestamp\":1765394045513,\"type\":\"update/order_book\"}"
    "msg": "{\"channel\":\"order_book:1\",\"offset\":6962702,\"order_book\":{\"code\":0,\"asks\":[{\"price\":\"92958.7\",\"size\":\"0.00000\"}],\"bids\":[{\"price\":\"92951.4\",\"size\":\"1.24023\"},{\"price\":\"92950.0\",\"size\":\"0.00000\"},{\"price\":\"92934.9\",\"size\":\"0.08084\"},{\"price\":\"92930.3\",\"size\":\"0.00000\"},{\"price\":\"92920.1\",\"size\":\"0.00000\"}],\"offset\":6962702,\"nonce\":3691009296},\"timestamp\":1765394045518,\"type\":\"update/order_book\"}"
    "msg": "{\"channel\":\"order_book:1\",\"offset\":6962703,\"order_book\":{\"code\":0,\"asks\":[{\"price\":\"92955.8\",\"size\":\"0.04336\"}],\"bids\":[{\"price\":\"92945.3\",\"size\":\"0.00000\"},{\"price\":\"92940.8\",\"size\":\"0.08083\"}],\"offset\":6962703,\"nonce\":3691009299},\"timestamp\":1765394045521,\"type\":\"update/order_book\"}"
    "msg": "{\"channel\":\"order_book:1\",\"offset\":6962704,\"order_book\":{\"code\":0,\"asks\":[],\"bids\":[{\"price\":\"92945.6\",\"size\":\"0.01075\"}],\"offset\":6962704,\"nonce\":3691009302},\"timestamp\":1765394045524,\"type\":\"update/order_book\"}"
    "msg": "{\"channel\":\"order_book:1\",\"offset\":6962705,\"order_book\":{\"code\":0,\"asks\":[],\"bids\":[{\"price\":\"92945.6\",\"size\":\"0.00000\"}],\"offset\":6962705,\"nonce\":3691009303},\"timestamp\":1765394045536,\"type\":\"update/order_book\"}"
    "msg": "{\"channel\":\"order_book:1\",\"offset\":6962706,\"order_book\":{\"code\":0,\"asks\":[{\"price\":\"92961.5\",\"size\":\"0.00000\"},{\"price\":\"92990.9\",\"size\":\"0.00000\"},{\"price\":\"92991.1\",\"size\":\"2.56199\"}],\"bids\":[{\"price\":\"92951.5\",\"size\":\"1.56981\"},{\"price\":\"92948.0\",\"size\":\"0.10760\"},{\"price\":\"92941.7\",\"size\":\"0.00000\"},{\"price\":\"92935.9\",\"size\":\"4.68719\"},{\"price\":\"92935.6\",\"size\":\"0.00000\"},{\"price\":\"92930.8\",\"size\":\"0.00108\"},{\"price\":\"92930.5\",\"size\":\"0.00000\"},{\"price\":\"92928.9\",\"size\":\"6.52474\"},{\"price\":\"92922.0\",\"size\":\"15.45334\"},{\"price\":\"92894.7\",\"size\":\"0.00000\"},{\"price\":\"92887.7\",\"size\":\"8.07918\"}],\"offset\":6962706,\"nonce\":3691009304},\"timestamp\":1765394045542,\"type\":\"update/order_book\"}"
    "msg": "{\"channel\":\"order_book:1\",\"offset\":6962707,\"order_book\":{\"code\":0,\"asks\":[{\"price\":\"92978.2\",\"size\":\"0.00000\"},{\"price\":\"92998.0\",\"size\":\"3.39613\"},{\"price\":\"93005.0\",\"size\":\"8.04346\"},{\"price\":\"93032.4\",\"size\":\"0.00000\"},{\"price\":\"93039.4\",\"size\":\"0.00000\"}],\"bids\":[{\"price\":\"92948.3\",\"size\":\"0.11620\"},{\"price\":\"92946.9\",\"size\":\"0.00000\"}],\"offset\":6962707,\"nonce\":3691009306},\"timestamp\":1765394045547,\"type\":\"update/order_book\"}"
    "msg": "{\"channel\":\"order_book:1\",\"offset\":6962708,\"order_book\":{\"code\":0,\"asks\":[{\"price\":\"92963.4\",\"size\":\"0.00000\"}],\"bids\":[{\"price\":\"92948.3\",\"size\":\"0.14525\"},{\"price\":\"92945.6\",\"size\":\"0.01075\"},{\"price\":\"92933.2\",\"size\":\"0.00000\"}],\"offset\":6962708,\"nonce\":3691009309},\"timestamp\":1765394045556,\"type\":\"update/order_book\"}"
    "msg": "{\"channel\":\"order_book:1\",\"offset\":6962709,\"order_book\":{\"code\":0,\"asks\":[{\"price\":\"92963.8\",\"size\":\"0.00000\"}],\"bids\":[{\"price\":\"92932.8\",\"size\":\"0.00000\"}],\"offset\":6962709,\"nonce\":3691009310},\"timestamp\":1765394045560,\"type\":\"update/order_book\"}"
    "msg": "{\"channel\":\"order_book:1\",\"offset\":6962711,\"order_book\":{\"code\":0,\"asks\":[],\"bids\":[{\"price\":\"92955.7\",\"size\":\"0.04136\"},{\"price\":\"92951.9\",\"size\":\"0.23481\"},{\"price\":\"92948.6\",\"size\":\"0.08079\"},{\"price\":\"92946.5\",\"size\":\"0.08083\"},{\"price\":\"92945.4\",\"size\":\"0.08081\"},{\"price\":\"92944.9\",\"size\":\"0.08081\"}],\"offset\":6962711,\"nonce\":3691009316},\"timestamp\":1765394045574,\"type\":\"update/order_book\"}"
    "msg": "{\"channel\":\"order_book:1\",\"offset\":6962712,\"order_book\":{\"code\":0,\"asks\":[{\"price\":\"92991.1\",\"size\":\"0.00000\"},{\"price\":\"92996.9\",\"size\":\"2.65788\"},{\"price\":\"92998.0\",\"size\":\"0.00000\"},{\"price\":\"93003.8\",\"size\":\"3.52324\"}],\"bids\":[],\"offset\":6962712,\"nonce\":3691009317},\"timestamp\":1765394045579,\"type\":\"update/order_book\"}"
    "msg": "{\"channel\":\"order_book:1\",\"offset\":6962713,\"order_book\":{\"code\":0,\"asks\":[{\"price\":\"93005.0\",\"size\":\"0.00000\"},{\"price\":\"93010.8\",\"size\":\"8.34451\"}],\"bids\":[],\"offset\":6962713,\"nonce\":3691009318},\"timestamp\":1765394045580,\"type\":\"update/order_book\"}"
    "msg": "{\"channel\":\"order_book:1\",\"offset\":6962714,\"order_book\":{\"code\":0,\"asks\":[],\"bids\":[{\"price\":\"92935.9\",\"size\":\"4.68787\"}],\"offset\":6962714,\"nonce\":3691009319},\"timestamp\":1765394045583,\"type\":\"update/order_book\"}"
    "msg": "{\"channel\":\"order_book:1\",\"offset\":6962715,\"order_book\":{\"code\":0,\"asks\":[{\"price\":\"92955.8\",\"size\":\"0.00000\"},{\"price\":\"92964.9\",\"size\":\"1.07758\"}],\"bids\":[{\"price\":\"92955.7\",\"size\":\"3.27339\"}],\"offset\":6962715,\"nonce\":3691009320},\"timestamp\":1765394045586,\"type\":\"update/order_book\"}"
    "msg": "{\"channel\":\"order_book:1\",\"offset\":6962716,\"order_book\":{\"code\":0,\"asks\":[{\"price\":\"92960.3\",\"size\":\"0.09960\"},{\"price\":\"92960.4\",\"size\":\"0.08084\"}],\"bids\":[{\"price\":\"92951.9\",\"size\":\"0.00000\"},{\"price\":\"92923.2\",\"size\":\"8.07918\"}],\"offset\":6962716,\"nonce\":3691009323},\"timestamp\":1765394045592,\"type\":\"update/order_book\"}"
    "msg": "{\"channel\":\"order_book:1\",\"offset\":6962717,\"order_book\":{\"code\":0,\"asks\":[],\"bids\":[{\"price\":\"92955.7\",\"size\":\"4.05455\"}],\"offset\":6962717,\"nonce\":3691009324},\"timestamp\":1765394045598,\"type\":\"update/order_book\"}"
    "msg": "{\"channel\":\"order_book:1\",\"offset\":6962719,\"order_book\":{\"code\":0,\"asks\":[{\"price\":\"92984.8\",\"size\":\"0.00000\"}],\"bids\":[],\"offset\":6962719,\"nonce\":3691009327},\"timestamp\":1765394045613,\"type\":\"update/order_book\"}"
    "msg": "{\"channel\":\"order_book:1\",\"offset\":6962720,\"order_book\":{\"code\":0,\"asks\":[{\"price\":\"92987.2\",\"size\":\"2.15445\"}],\"bids\":[],\"offset\":6962720,\"nonce\":3691009329},\"timestamp\":1765394045618,\"type\":\"update/order_book\"}"
    "msg": "{\"channel\":\"order_book:1\",\"offset\":6962721,\"order_book\":{\"code\":0,\"asks\":[{\"price\":\"92967.4\",\"size\":\"2.69396\"},{\"price\":\"92975.2\",\"size\":\"0.03762\"}],\"bids\":[{\"price\":\"92939.1\",\"size\":\"2.69396\"},{\"price\":\"92935.4\",\"size\":\"0.10780\"},{\"price\":\"92931.8\",\"size\":\"0.00000\"}],\"offset\":6962721,\"nonce\":3691009331},\"timestamp\":1765394045621,\"type\":\"update/order_book\"}"
    "msg": "{\"channel\":\"order_book:1\",\"offset\":6962723,\"order_book\":{\"code\":0,\"asks\":[{\"price\":\"92960.3\",\"size\":\"0.86957\"},{\"price\":\"92962.0\",\"size\":\"0.02834\"},{\"price\":\"92964.2\",\"size\":\"0.10760\"}],\"bids\":[{\"price\":\"92955.7\",\"size\":\"3.27339\"},{\"price\":\"92946.5\",\"size\":\"0.16155\"},{\"price\":\"92831.4\",\"size\":\"0.00000\"}],\"offset\":6962723,\"nonce\":3691009334},\"timestamp\":1765394045632,\"type\":\"update/order_book\"}"
    "msg": "{\"channel\":\"order_book:1\",\"offset\":6962726,\"order_book\":{\"code\":0,\"asks\":[{\"price\":\"92964.0\",\"size\":\"0.00021\"},{\"price\":\"92966.1\",\"size\":\"0.00000\"}],\"bids\":[{\"price\":\"92955.7\",\"size\":\"3.14497\"},{\"price\":\"92943.2\",\"size\":\"0.13469\"},{\"price\":\"92881.7\",\"size\":\"0.00000\"}],\"offset\":6962726,\"nonce\":3691009337},\"timestamp\":1765394045689,\"type\":\"update/order_book\"}"
    "msg": "{\"channel\":\"order_book:1\",\"offset\":6962727,\"order_book\":{\"code\":0,\"asks\":[{\"price\":\"92980.9\",\"size\":\"0.00000\"},{\"price\":\"93007.3\",\"size\":\"0.00000\"}],\"bids\":[{\"price\":\"92958.0\",\"size\":\"0.03762\"},{\"price\":\"92950.5\",\"size\":\"0.10781\"},{\"price\":\"92948.0\",\"size\":\"0.00000\"}],\"offset\":6962727,\"nonce\":3691009338},\"timestamp\":1765394045698,\"type\":\"update/order_book\"}"
    "msg": "{\"channel\":\"order_book:1\",\"offset\":6962728,\"order_book\":{\"code\":0,\"asks\":[{\"price\":\"92960.4\",\"size\":\"0.00000\"},{\"price\":\"92962.5\",\"size\":\"0.00000\"},{\"price\":\"92964.9\",\"size\":\"0.00000\"},{\"price\":\"92965.3\",\"size\":\"0.00000\"},{\"price\":\"92965.6\",\"size\":\"0.00000\"},{\"price\":\"92967.2\",\"size\":\"0.00000\"},{\"price\":\"92967.8\",\"size\":\"0.00000\"},{\"price\":\"92970.4\",\"size\":\"0.00000\"},{\"price\":\"92977.4\",\"size\":\"0.00000\"}],\"bids\":[{\"price\":\"92869.4\",\"size\":\"5.92473\"}],\"offset\":6962728,\"nonce\":3691009339},\"timestamp\":1765394045720,\"type\":\"update/order_book\"}"
    "msg": "{\"channel\":\"order_book:1\",\"offset\":6962729,\"order_book\":{\"code\":0,\"asks\":[{\"price\":\"92964.2\",\"size\":\"0.00000\"}],\"bids\":[{\"price\":\"92955.8\",\"size\":\"0.87383\"},{\"price\":\"92949.4\",\"size\":\"0.01613\"},{\"price\":\"92948.3\",\"size\":\"0.00860\"}],\"offset\":6962729,\"nonce\":3691009340},\"timestamp\":1765394045732,\"type\":\"update/order_book\"}"
    "msg": "{\"channel\":\"order_book:1\",\"offset\":6962730,\"order_book\":{\"code\":0,\"asks\":[{\"price\":\"92962.0\",\"size\":\"0.00000\"},{\"price\":\"92965.4\",\"size\":\"0.00000\"},{\"price\":\"92967.4\",\"size\":\"0.00000\"},{\"price\":\"92968.1\",\"size\":\"0.00000\"},{\"price\":\"92968.5\",\"size\":\"0.00000\"},{\"price\":\"92970.9\",\"size\":\"0.00000\"},{\"price\":\"92974.3\",\"size\":\"0.00000\"},{\"price\":\"92985.2\",\"size\":\"0.00000\"},{\"price\":\"93010.7\",\"size\":\"0.00000\"},{\"price\":\"93066.3\",\"size\":\"0.00000\"}],\"bids\":[{\"price\":\"92950.5\",\"size\":\"0.13686\"},{\"price\":\"92935.9\",\"size\":\"4.69006\"}],\"offset\":6962730,\"nonce\":3691009341},\"timestamp\":1765394045740,\"type\":\"update/order_book\"}"
    "msg": "{\"channel\":\"order_book:1\",\"offset\":6962731,\"order_book\":{\"code\":0,\"asks\":[{\"price\":\"92971.4\",\"size\":\"0.00000\"},{\"price\":\"92985.3\",\"size\":\"0.00000\"}],\"bids\":[{\"price\":\"92939.1\",\"size\":\"0.00000\"},{\"price\":\"92928.9\",\"size\":\"6.52475\"}],\"offset\":6962731,\"nonce\":3691009342},\"timestamp\":1765394045746,\"type\":\"update/order_book\"}"
    "msg": "{\"channel\":\"order_book:1\",\"offset\":6962732,\"order_book\":{\"code\":0,\"asks\":[{\"price\":\"92977.0\",\"size\":\"0.00000\"},{\"price\":\"92996.8\",\"size\":\"2.97828\"},{\"price\":\"92996.9\",\"size\":\"0.00000\"}],\"bids\":[{\"price\":\"92949.4\",\"size\":\"0.00000\"},{\"price\":\"92925.9\",\"size\":\"0.00000\"},{\"price\":\"92914.1\",\"size\":\"0.00000\"}],\"offset\":6962732,\"nonce\":3691009344},\"timestamp\":1765394045759,\"type\":\"update/order_book\"}"
    "msg": "{\"channel\":\"order_book:1\",\"offset\":6962733,\"order_book\":{\"code\":0,\"asks\":[{\"price\":\"92967.1\",\"size\":\"0.00860\"},{\"price\":\"92972.5\",\"size\":\"0.00000\"},{\"price\":\"92983.1\",\"size\":\"0.00214\"},{\"price\":\"93001.0\",\"size\":\"0.38767\"},{\"price\":\"93003.8\",\"size\":\"3.94795\"},{\"price\":\"93004.2\",\"size\":\"0.00000\"}],\"bids\":[{\"price\":\"92950.5\",\"size\":\"0.10781\"},{\"price\":\"92940.2\",\"size\":\"0.00000\"},{\"price\":\"92922.0\",\"size\":\"0.00000\"},{\"price\":\"92921.9\",\"size\":\"15.45335\"},{\"price\":\"92914.2\",\"size\":\"0.00000\"}],\"offset\":6962733,\"nonce\":3691009345},\"timestamp\":1765394045762,\"type\":\"update/order_book\"}"
    "msg": "{\"channel\":\"order_book:1\",\"offset\":6962734,\"order_book\":{\"code\":0,\"asks\":[{\"price\":\"92973.1\",\"size\":\"0.24220\"},{\"price\":\"92983.2\",\"size\":\"0.00000\"},{\"price\":\"93006.6\",\"size\":\"0.38767\"},{\"price\":\"93010.8\",\"size\":\"9.35040\"}],\"bids\":[{\"price\":\"92956.3\",\"size\":\"0.38767\"},{\"price\":\"92950.5\",\"size\":\"0.10760\"},{\"price\":\"92945.6\",\"size\":\"0.00000\"},{\"price\":\"92940.6\",\"size\":\"0.00000\"}],\"offset\":6962734,\"nonce\":3691009346},\"timestamp\":1765394045770,\"type\":\"update/order_book\"}"
    "msg": "{\"channel\":\"order_book:1\",\"offset\":6962735,\"order_book\":{\"code\":0,\"asks\":[{\"price\":\"92960.5\",\"size\":\"0.00021\"},{\"price\":\"98708.2\",\"size\":\"0.00000\"}],\"bids\":[{\"price\":\"92955.8\",\"size\":\"0.98143\"},{\"price\":\"92952.1\",\"size\":\"0.02905\"},{\"price\":\"92950.8\",\"size\":\"0.00000\"},{\"price\":\"92946.0\",\"size\":\"0.02906\"},{\"price\":\"92939.7\",\"size\":\"0.10760\"},{\"price\":\"92935.4\",\"size\":\"0.00000\"},{\"price\":\"92926.9\",\"size\":\"0.00000\"},{\"price\":\"92923.7\",\"size\":\"0.11629\"},{\"price\":\"92915.9\",\"size\":\"0.01076\"},{\"price\":\"92873.5\",\"size\":\"0.00000\"},{\"price\":\"92864.2\",\"size\":\"0.00000\"}],\"offset\":6962735,\"nonce\":3691009347},\"timestamp\":1765394045774,\"type\":\"update/order_book\"}"
    "msg": "{\"channel\":\"order_book:1\",\"offset\":6962736,\"order_book\":{\"code\":0,\"asks\":[{\"price\":\"92960.3\",\"size\":\"0.00000\"},{\"price\":\"92965.8\",\"size\":\"0.00215\"},{\"price\":\"92967.7\",\"size\":\"0.00000\"},{\"price\":\"92973.5\",\"size\":\"0.10760\"},{\"price\":\"92975.2\",\"size\":\"0.14522\"},{\"price\":\"92978.8\",\"size\":\"0.08805\"},{\"price\":\"92981.0\",\"size\":\"0.00000\"},{\"price\":\"92983.1\",\"size\":\"0.00000\"},{\"price\":\"92985.7\",\"size\":\"0.00000\"},{\"price\":\"92986.1\",\"size\":\"0.00000\"},{\"price\":\"92987.3\",\"size\":\"0.00000\"},{\"price\":\"92997.5\",\"size\":\"0.11088\"}],\"bids\":[{\"price\":\"92960.2\",\"size\":\"0.38767\"},{\"price\":\"92955.7\",\"size\":\"1.94916\"},{\"price\":\"92947.1\",\"size\":\"0.09803\"},{\"price\":\"92946.5\",\"size\":\"0.17230\"},{\"price\":\"92946.1\",\"size\":\"0.02151\"},{\"price\":\"92937.7\",\"size\":\"0.02815\"},{\"price\":\"92932.2\",\"size\":\"0.00000\"},{\"price\":\"92925.1\",\"size\":\"0.00000\"},{\"price\":\"92924.9\",\"size\":\"0.00000\"},{\"price\":\"92915.9\",\"size\":\"0.00000\"},{\"price\":\"92913.1\",\"size\":\"0.00000\"},{\"price\":\"92898.8\",\"size\":\"0.00000\"},{\"price\":\"92866.8\",\"size\":\"0.00000\"},{\"price\":\"92854.4\",\"size\":\"0.00000\"},{\"price\":\"92842.9\",\"size\":\"0.00000\"}],\"offset\":6962736,\"nonce\":3691009350},\"timestamp\":1765394045796,\"type\":\"update/order_book\"}"
    "msg": "{\"channel\":\"order_book:1\",\"offset\":6962737,\"order_book\":{\"code\":0,\"asks\":[],\"bids\":[{\"price\":\"92946.5\",\"size\":\"0.16155\"},{\"price\":\"92946.1\",\"size\":\"0.00000\"},{\"price\":\"92946.0\",\"size\":\"0.00000\"},{\"price\":\"92893.3\",\"size\":\"0.12098\"},{\"price\":\"92807.2\",\"size\":\"0.00000\"}],\"offset\":6962737,\"nonce\":3691009351},\"timestamp\":1765394045799,\"type\":\"update/order_book\"}"
    "msg": "{\"channel\":\"order_book:1\",\"offset\":6962738,\"order_book\":{\"code\":0,\"asks\":[{\"price\":\"92965.8\",\"size\":\"0.00000\"},{\"price\":\"92967.1\",\"size\":\"0.00000\"}],\"bids\":[{\"price\":\"92960.2\",\"size\":\"1.12676\"},{\"price\":\"92958.0\",\"size\":\"0.86782\"},{\"price\":\"92955.8\",\"size\":\"1.01048\"},{\"price\":\"92947.1\",\"size\":\"0.11954\"},{\"price\":\"92913.0\",\"size\":\"0.11759\"},{\"price\":\"92912.3\",\"size\":\"0.28174\"}],\"offset\":6962738,\"nonce\":3691009352},\"timestamp\":1765394045800,\"type\":\"update/order_book\"}"
    "msg": "{\"channel\":\"order_book:1\",\"offset\":6962739,\"order_book\":{\"code\":0,\"asks\":[],\"bids\":[{\"price\":\"92955.8\",\"size\":\"0.98143\"},{\"price\":\"92951.0\",\"size\":\"0.01075\"}],\"offset\":6962739,\"nonce\":3691009353},\"timestamp\":1765394045803,\"type\":\"update/order_book\"}"
    "msg": "{\"channel\":\"order_book:1\",\"offset\":6962740,\"order_book\":{\"code\":0,\"asks\":[{\"price\":\"92960.5\",\"size\":\"0.00000\"},{\"price\":\"92964.0\",\"size\":\"0.00000\"},{\"price\":\"92971.2\",\"size\":\"0.00042\"}],\"bids\":[{\"price\":\"92951.9\",\"size\":\"0.02906\"}],\"offset\":6962740,\"nonce\":3691009354},\"timestamp\":1765394045810,\"type\":\"update/order_book\"}"
    "msg": "{\"channel\":\"order_book:1\",\"offset\":6962741,\"order_book\":{\"code\":0,\"asks\":[],\"bids\":[{\"price\":\"92951.0\",\"size\":\"0.00000\"},{\"price\":\"92944.7\",\"size\":\"0.08000\"}],\"offset\":6962741,\"nonce\":3691009355},\"timestamp\":1765394045816,\"type\":\"update/order_book\"}"
    "msg": "{\"channel\":\"order_book:1\",\"offset\":6962743,\"order_book\":{\"code\":0,\"asks\":[{\"price\":\"92972.8\",\"size\":\"1.07758\"},{\"price\":\"93012.4\",\"size\":\"0.00000\"}],\"bids\":[{\"price\":\"92951.0\",\"size\":\"0.01075\"}],\"offset\":6962743,\"nonce\":3691009357},\"timestamp\":1765394045822,\"type\":\"update/order_book\"}"
    "msg": "{\"channel\":\"order_book:1\",\"offset\":6962744,\"order_book\":{\"code\":0,\"asks\":[{\"price\":\"93034.7\",\"size\":\"0.11088\"}],\"bids\":[{\"price\":\"92931.1\",\"size\":\"0.00000\"},{\"price\":\"92926.7\",\"size\":\"0.56403\"}],\"offset\":6962744,\"nonce\":3691009358},\"timestamp\":1765394045830,\"type\":\"update/order_book\"}"
    "msg": "{\"channel\":\"order_book:1\",\"offset\":6962745,\"order_book\":{\"code\":0,\"asks\":[{\"price\":\"92973.1\",\"size\":\"0.13460\"},{\"price\":\"92975.5\",\"size\":\"0.00000\"},{\"price\":\"92987.6\",\"size\":\"0.00000\"},{\"price\":\"92989.0\",\"size\":\"0.00000\"},{\"price\":\"93001.1\",\"size\":\"0.00000\"}],\"bids\":[{\"price\":\"92943.4\",\"size\":\"0.02628\"},{\"price\":\"92932.4\",\"size\":\"0.00000\"}],\"offset\":6962745,\"nonce\":3691009360},\"timestamp\":1765394045836,\"type\":\"update/order_book\"}"
    "msg": "{\"channel\":\"order_book:1\",\"offset\":6962746,\"order_book\":{\"code\":0,\"asks\":[{\"price\":\"92973.2\",\"size\":\"0.02834\"},{\"price\":\"92973.5\",\"size\":\"0.00000\"},{\"price\":\"92977.0\",\"size\":\"2.69396\"},{\"price\":\"93132.2\",\"size\":\"0.00000\"}],\"bids\":[{\"price\":\"92941.8\",\"size\":\"0.11979\"}],\"offset\":6962746,\"nonce\":3691009361},\"timestamp\":1765394045839,\"type\":\"update/order_book\"}"
    "msg": "{\"channel\":\"order_book:1\",\"offset\":6962747,\"order_book\":{\"code\":0,\"asks\":[],\"bids\":[{\"price\":\"92951.0\",\"size\":\"0.00000\"},{\"price\":\"92949.5\",\"size\":\"2.69396\"},{\"price\":\"92947.1\",\"size\":\"0.09803\"}],\"offset\":6962747,\"nonce\":3691009362},\"timestamp\":1765394045841,\"type\":\"update/order_book\"}"
    "msg": "{\"channel\":\"order_book:1\",\"offset\":6962748,\"order_book\":{\"code\":0,\"asks\":[{\"price\":\"92972.8\",\"size\":\"0.00000\"},{\"price\":\"92975.2\",\"size\":\"0.03762\"},{\"price\":\"92988.9\",\"size\":\"0.00000\"}],\"bids\":[{\"price\":\"92951.7\",\"size\":\"0.02151\"}],\"offset\":6962748,\"nonce\":3691009363},\"timestamp\":1765394045847,\"type\":\"update/order_book\"}"
    "msg": "{\"channel\":\"order_book:1\",\"offset\":6962749,\"order_book\":{\"code\":0,\"asks\":[{\"price\":\"92973.1\",\"size\":\"0.00000\"},{\"price\":\"92982.6\",\"size\":\"0.00000\"},{\"price\":\"93010.7\",\"size\":\"0.38767\"}],\"bids\":[{\"price\":\"92955.6\",\"size\":\"0.01075\"},{\"price\":\"92946.2\",\"size\":\"0.10760\"},{\"price\":\"92939.7\",\"size\":\"0.00000\"}],\"offset\":6962749,\"nonce\":3691009364},\"timestamp\":1765394045852,\"type\":\"update/order_book\"}"
    "msg": "{\"channel\":\"order_book:1\",\"offset\":6962750,\"order_book\":{\"code\":0,\"asks\":[{\"price\":\"92980.7\",\"size\":\"0.01433\"},{\"price\":\"92985.4\",\"size\":\"0.05173\"},{\"price\":\"93000.4\",\"size\":\"0.12233\"},{\"price\":\"93014.2\",\"size\":\"0.00000\"}],\"bids\":[{\"price\":\"92958.1\",\"size\":\"0.13665\"},{\"price\":\"92955.8\",\"size\":\"0.87383\"},{\"price\":\"92951.7\",\"size\":\"0.00000\"},{\"price\":\"92946.4\",\"size\":\"0.64609\"}],\"offset\":6962750,\"nonce\":3691009365},\"timestamp\":1765394045853,\"type\":\"update/order_book\"}"
    "msg": "{\"channel\":\"order_book:1\",\"offset\":6962751,\"order_book\":{\"code\":0,\"asks\":[{\"price\":\"92989.8\",\"size\":\"0.12064\"},{\"price\":\"93016.3\",\"size\":\"0.38767\"}],\"bids\":[{\"price\":\"92958.7\",\"size\":\"0.00215\"},{\"price\":\"92955.6\",\"size\":\"0.00000\"},{\"price\":\"92952.1\",\"size\":\"0.00000\"}],\"offset\":6962751,\"nonce\":3691009366},\"timestamp\":1765394045859,\"type\":\"update/order_book\"}"
    "msg": "{\"channel\":\"order_book:1\",\"offset\":6962752,\"order_book\":{\"code\":0,\"asks\":[{\"price\":\"92977.0\",\"size\":\"2.69595\"},{\"price\":\"92978.3\",\"size\":\"0.10760\"},{\"price\":\"92978.8\",\"size\":\"0.00000\"},{\"price\":\"92996.8\",\"size\":\"0.00000\"},{\"price\":\"93003.8\",\"size\":\"0.00000\"},{\"price\":\"93009.4\",\"size\":\"2.29230\"},{\"price\":\"93016.4\",\"size\":\"3.03863\"}],\"bids\":[{\"price\":\"92960.2\",\"size\":\"1.14176\"}],\"offset\":6962752,\"nonce\":3691009367},\"timestamp\":1765394045864,\"type\":\"update/order_book\"}"
    "msg": "{\"channel\":\"order_book:1\",\"offset\":6962753,\"order_book\":{\"code\":0,\"asks\":[{\"price\":\"92971.2\",\"size\":\"0.00000\"},{\"price\":\"92980.8\",\"size\":\"0.00500\"},{\"price\":\"93010.8\",\"size\":\"0.00000\"},{\"price\":\"93023.3\",\"size\":\"7.19676\"}],\"bids\":[{\"price\":\"92960.2\",\"size\":\"1.15176\"},{\"price\":\"92952.7\",\"size\":\"0.02151\"},{\"price\":\"92935.9\",\"size\":\"4.69230\"}],\"offset\":6962753,\"nonce\":3691009368},\"timestamp\":1765394045874,\"type\":\"update/order_book\"}"
    "msg": "{\"channel\":\"order_book:1\",\"offset\":6962755,\"order_book\":{\"code\":0,\"asks\":[{\"price\":\"92978.6\",\"size\":\"0.00000\"},{\"price\":\"92982.9\",\"size\":\"0.00000\"}],\"bids\":[{\"price\":\"92960.2\",\"size\":\"1.98782\"},{\"price\":\"92958.1\",\"size\":\"0.36874\"},{\"price\":\"92955.7\",\"size\":\"0.87158\"}],\"offset\":6962755,\"nonce\":3691009370},\"timestamp\":1765394045883,\"type\":\"update/order_book\"}"
    "msg": "{\"channel\":\"order_book:1\",\"offset\":6962756,\"order_book\":{\"code\":0,\"asks\":[{\"price\":\"92978.3\",\"size\":\"0.00000\"},{\"price\":\"93013.2\",\"size\":\"0.00000\"}],\"bids\":[{\"price\":\"92956.6\",\"size\":\"0.00000\"},{\"price\":\"92941.3\",\"size\":\"0.11088\"},{\"price\":\"92930.9\",\"size\":\"0.00108\"},{\"price\":\"92930.8\",\"size\":\"0.00000\"}],\"offset\":6962756,\"nonce\":3691009371},\"timestamp\":1765394045891,\"type\":\"update/order_book\"}"
    "msg": "{\"channel\":\"order_book:1\",\"offset\":6962757,\"order_book\":{\"code\":0,\"asks\":[],\"bids\":[{\"price\":\"92952.7\",\"size\":\"0.00000\"},{\"price\":\"92952.3\",\"size\":\"2.15445\"},{\"price\":\"92925.1\",\"size\":\"0.01076\"},{\"price\":\"92923.7\",\"size\":\"0.00000\"},{\"price\":\"92887.9\",\"size\":\"0.00000\"},{\"price\":\"92836.4\",\"size\":\"8.07918\"}],\"offset\":6962757,\"nonce\":3691009372},\"timestamp\":1765394045895,\"type\":\"update/order_book\"}"
    "msg": "{\"channel\":\"order_book:1\",\"offset\":6962758,\"order_book\":{\"code\":0,\"asks\":[{\"price\":\"92973.2\",\"size\":\"0.00000\"},{\"price\":\"92997.5\",\"size\":\"0.00000\"},{\"price\":\"93025.0\",\"size\":\"0.00000\"}],\"bids\":[{\"price\":\"92958.1\",\"size\":\"0.33969\"},{\"price\":\"92936.2\",\"size\":\"0.00000\"}],\"offset\":6962758,\"nonce\":3691009373},\"timestamp\":1765394045903,\"type\":\"update/order_book\"}"
    "msg": "{\"channel\":\"order_book:1\",\"offset\":6962759,\"order_book\":{\"code\":0,\"asks\":[{\"price\":\"92996.8\",\"size\":\"0.00302\"}],\"bids\":[{\"price\":\"92956.3\",\"size\":\"0.40918\"},{\"price\":\"92903.4\",\"size\":\"0.36669\"},{\"price\":\"92876.4\",\"size\":\"0.31910\"},{\"price\":\"92854.7\",\"size\":\"0.00000\"}],\"offset\":6962759,\"nonce\":3691009374},\"timestamp\":1765394045909,\"type\":\"update/order_book\"}"
    "msg": "{\"channel\":\"order_book:1\",\"offset\":6962760,\"order_book\":{\"code\":0,\"asks\":[],\"bids\":[{\"price\":\"92958.2\",\"size\":\"0.00860\"},{\"price\":\"92951.6\",\"size\":\"0.11088\"},{\"price\":\"92923.5\",\"size\":\"0.00000\"},{\"price\":\"92880.1\",\"size\":\"0.83006\"},{\"price\":\"92871.2\",\"size\":\"0.31910\"},{\"price\":\"92844.3\",\"size\":\"0.00000\"}],\"offset\":6962760,\"nonce\":3691009375},\"timestamp\":1765394045914,\"type\":\"update/order_book\"}"
    "msg": "{\"channel\":\"order_book:1\",\"offset\":6962761,\"order_book\":{\"code\":0,\"asks\":[{\"price\":\"93014.9\",\"size\":\"0.11419\"},{\"price\":\"93040.4\",\"size\":\"0.08000\"}],\"bids\":[{\"price\":\"92960.3\",\"size\":\"0.02905\"},{\"price\":\"92951.9\",\"size\":\"0.00000\"},{\"price\":\"92926.3\",\"size\":\"0.00000\"},{\"price\":\"92925.1\",\"size\":\"0.00000\"},{\"price\":\"92902.2\",\"size\":\"0.00000\"}],\"offset\":6962761,\"nonce\":3691009376},\"timestamp\":1765394045919,\"type\":\"update/order_book\"}"
    "msg": "{\"channel\":\"order_book:1\",\"offset\":6962762,\"order_book\":{\"code\":0,\"asks\":[{\"price\":\"92977.0\",\"size\":\"0.00000\"},{\"price\":\"92980.8\",\"size\":\"0.00000\"}],\"bids\":[{\"price\":\"92967.2\",\"size\":\"0.38767\"},{\"price\":\"92960.9\",\"size\":\"0.01075\"},{\"price\":\"92958.7\",\"size\":\"0.00000\"},{\"price\":\"92958.0\",\"size\":\"0.83020\"},{\"price\":\"92949.5\",\"size\":\"0.00000\"}],\"offset\":6962762,\"nonce\":3691009377},\"timestamp\":1765394045926,\"type\":\"update/order_book\"}"
