    "msg": "{\"channel\":\"order_book:1\",\"offset\":6961736,\"order_book\":{\"code\":0,\"asks\":[{\"price\":\"92864.6\",\"size\":\"0.36730\"}],\"bids\":[],\"offset\":6961736,\"nonce\":3691007577},\"timestamp\":1765394039003,\"type\":\"update/order_book\"}"
    "msg": "{\"channel\":\"order_book:1\",\"offset\":6961737,\"order_book\":{\"code\":0,\"asks\":[{\"price\":\"92832.5\",\"size\":\"0.21544\"},{\"price\":\"92837.5\",\"size\":\"0.10780\"},{\"price\":\"92838.4\",\"size\":\"0.00000\"},{\"price\":\"92839.9\",\"size\":\"0.00000\"}],\"bids\":[{\"price\":\"92815.2\",\"size\":\"0.00000\"},{\"price\":\"92814.2\",\"size\":\"0.10780\"}],\"offset\":6961737,\"nonce\":3691007586},\"timestamp\":1765394039023,\"type\":\"update/order_book\"}"
    "msg": "{\"channel\":\"order_book:1\",\"offset\":6961738,\"order_book\":{\"code\":0,\"asks\":[{\"price\":\"92835.3\",\"size\":\"0.10780\"},{\"price\":\"92837.3\",\"size\":\"0.00000\"}],\"bids\":[],\"offset\":6961738,\"nonce\":3691007589},\"timestamp\":1765394039028,\"type\":\"update/order_book\"}"
    "msg": "{\"channel\":\"order_book:1\",\"offset\":6961739,\"order_book\":{\"code\":0,\"asks\":[],\"bids\":[{\"price\":\"92821.6\",\"size\":\"0.00000\"},{\"price\":\"92820.5\",\"size\":\"0.10780\"}],\"offset\":6961739,\"nonce\":3691007590},\"timestamp\":1765394039032,\"type\":\"update/order_book\"}"
    "msg": "{\"channel\":\"order_book:1\",\"offset\":6961740,\"order_book\":{\"code\":0,\"asks\":[{\"price\":\"92834.8\",\"size\":\"1.97924\"}],\"bids\":[],\"offset\":6961740,\"nonce\":3691007594},\"timestamp\":1765394039041,\"type\":\"update/order_book\"}"
    "msg": "{\"channel\":\"order_book:1\",\"offset\":6961741,\"order_book\":{\"code\":0,\"asks\":[],\"bids\":[{\"price\":\"92821.8\",\"size\":\"0.08081\"},{\"price\":\"92815.4\",\"size\":\"0.08082\"}],\"offset\":6961741,\"nonce\":3691007602},\"timestamp\":1765394039052,\"type\":\"update/order_book\"}"
    "msg": "{\"channel\":\"order_book:1\",\"offset\":6961742,\"order_book\":{\"code\":0,\"asks\":[],\"bids\":[{\"price\":\"92816.2\",\"size\":\"0.08086\"}],\"offset\":6961742,\"nonce\":3691007605},\"timestamp\":1765394039055,\"type\":\"update/order_book\"}"
    "msg": "{\"channel\":\"order_book:1\",\"offset\":6961743,\"order_book\":{\"code\":0,\"asks\":[],\"bids\":[{\"price\":\"92827.1\",\"size\":\"0.00021\"}],\"offset\":6961743,\"nonce\":3691007611},\"timestamp\":1765394039068,\"type\":\"update/order_book\"}"
    "msg": "{\"channel\":\"order_book:1\",\"offset\":6961744,\"order_book\":{\"code\":0,\"asks\":[{\"price\":\"92865.9\",\"size\":\"4.59758\"}],\"bids\":[],\"offset\":6961744,\"nonce\":3691007613},\"timestamp\":1765394039071,\"type\":\"update/order_book\"}"
    "msg": "{\"channel\":\"order_book:1\",\"offset\":6961745,\"order_book\":{\"code\":0,\"asks\":[],\"bids\":[{\"price\":\"92829.1\",\"size\":\"1.73750\"},{\"price\":\"92823.8\",\"size\":\"4.60596\"}],\"offset\":6961745,\"nonce\":3691007616},\"timestamp\":1765394039077,\"type\":\"update/order_book\"}"
    "msg": "{\"channel\":\"order_book:1\",\"offset\":6961746,\"order_book\":{\"code\":0,\"asks\":[],\"bids\":[{\"price\":\"92826.0\",\"size\":\"0.00000\"}],\"offset\":6961746,\"nonce\":3691007621},\"timestamp\":1765394039088,\"type\":\"update/order_book\"}"
    "msg": "{\"channel\":\"order_book:1\",\"offset\":6961747,\"order_book\":{\"code\":0,\"asks\":[{\"price\":\"92834.8\",\"size\":\"1.95770\"}],\"bids\":[],\"offset\":6961747,\"nonce\":3691007635},\"timestamp\":1765394039115,\"type\":\"update/order_book\"}"
    "msg": "{\"channel\":\"order_book:1\",\"offset\":6961748,\"order_book\":{\"code\":0,\"asks\":[{\"price\":\"92834.9\",\"size\":\"0.10780\"},{\"price\":\"92836.1\",\"size\":\"0.00000\"},{\"price\":\"92836.5\",\"size\":\"0.10780\"},{\"price\":\"92837.5\",\"size\":\"0.00000\"},{\"price\":\"92853.3\",\"size\":\"0.00021\"}],\"bids\":[],\"offset\":6961748,\"nonce\":3691007643},\"timestamp\":1765394039130,\"type\":\"update/order_book\"}"
    "msg": "{\"channel\":\"order_book:1\",\"offset\":6961749,\"order_book\":{\"code\":0,\"asks\":[{\"price\":\"92834.8\",\"size\":\"0.91292\"},{\"price\":\"92835.6\",\"size\":\"0.02834\"}],\"bids\":[],\"offset\":6961749,\"nonce\":3691007654},\"timestamp\":1765394039152,\"type\":\"update/order_book\"}"
    "msg": "{\"channel\":\"order_book:1\",\"offset\":6961750,\"order_book\":{\"code\":0,\"asks\":[],\"bids\":[{\"price\":\"92825.6\",\"size\":\"0.00000\"}],\"offset\":6961750,\"nonce\":3691007655},\"timestamp\":1765394039155,\"type\":\"update/order_book\"}"
    "msg": "{\"channel\":\"order_book:1\",\"offset\":6961751,\"order_book\":{\"code\":0,\"asks\":[{\"price\":\"92832.5\",\"size\":\"0.00000\"},{\"price\":\"92864.2\",\"size\":\"4.59767\"},{\"price\":\"92865.9\",\"size\":\"0.00000\"},{\"price\":\"92901.6\",\"size\":\"14.96489\"},{\"price\":\"92915.4\",\"size\":\"14.96489\"},{\"price\":\"92929.2\",\"size\":\"14.96489\"},{\"price\":\"93108.6\",\"size\":\"0.00000\"},{\"price\":\"93122.4\",\"size\":\"0.00000\"},{\"price\":\"93136.2\",\"size\":\"0.00000\"}],\"bids\":[{\"price\":\"92824.7\",\"size\":\"4.52790\"},{\"price\":\"92823.8\",\"size\":\"0.08079\"},{\"price\":\"92819.0\",\"size\":\"0.00108\"},{\"price\":\"92818.1\",\"size\":\"0.00000\"}],\"offset\":6961751,\"nonce\":3691007656},\"timestamp\":1765394039163,\"type\":\"update/order_book\"}"
    "msg": "{\"channel\":\"order_book:1\",\"offset\":6961752,\"order_book\":{\"code\":0,\"asks\":[{\"price\":\"92834.9\",\"size\":\"0.00000\"},{\"price\":\"92835.3\",\"size\":\"0.00000\"},{\"price\":\"92836.5\",\"size\":\"0.00000\"},{\"price\":\"92837.5\",\"size\":\"0.10780\"}],\"bids\":[{\"price\":\"92821.7\",\"size\":\"0.10780\"},{\"price\":\"92820.5\",\"size\":\"0.00000\"},{\"price\":\"92815.4\",\"size\":\"0.18862\"},{\"price\":\"92814.2\",\"size\":\"0.00000\"}],\"offset\":6961752,\"nonce\":3691007657},\"timestamp\":1765394039167,\"type\":\"update/order_book\"}"
    "msg": "{\"channel\":\"order_book:1\",\"offset\":6961753,\"order_book\":{\"code\":0,\"asks\":[{\"price\":\"92835.9\",\"size\":\"0.82906\"}],\"bids\":[],\"offset\":6961753,\"nonce\":3691007659},\"timestamp\":1765394039172,\"type\":\"update/order_book\"}"
    "msg": "{\"channel\":\"order_book:1\",\"offset\":6961754,\"order_book\":{\"code\":0,\"asks\":[{\"price\":\"92834.8\",\"size\":\"0.00000\"},{\"price\":\"92835.9\",\"size\":\"0.00000\"},{\"price\":\"92839.1\",\"size\":\"0.04736\"},{\"price\":\"92839.2\",\"size\":\"0.00000\"},{\"price\":\"92839.3\",\"size\":\"0.00000\"},{\"price\":\"92839.4\",\"size\":\"0.00000\"}],\"bids\":[],\"offset\":6961754,\"nonce\":3691007660},\"timestamp\":1765394039176,\"type\":\"update/order_book\"}"
    "msg": "{\"channel\":\"order_book:1\",\"offset\":6961755,\"order_book\":{\"code\":0,\"asks\":[{\"price\":\"92847.1\",\"size\":\"0.09805\"}],\"bids\":[{\"price\":\"92829.2\",\"size\":\"0.25583\"},{\"price\":\"92807.7\",\"size\":\"0.22759\"},{\"price\":\"92806.4\",\"size\":\"0.00000\"}],\"offset\":6961755,\"nonce\":3691007661},\"timestamp\":1765394039179,\"type\":\"update/order_book\"}"
    "msg": "{\"channel\":\"order_book:1\",\"offset\":6961757,\"order_book\":{\"code\":0,\"asks\":[{\"price\":\"92839.6\",\"size\":\"0.00000\"}],\"bids\":[],\"offset\":6961757,\"nonce\":3691007667},\"timestamp\":1765394039196,\"type\":\"update/order_book\"}"
    "msg": "{\"channel\":\"order_book:1\",\"offset\":6961758,\"order_book\":{\"code\":0,\"asks\":[{\"price\":\"92834.8\",\"size\":\"0.00173\"},{\"price\":\"92839.9\",\"size\":\"0.00020\"},{\"price\":\"92842.4\",\"size\":\"0.00040\"},{\"price\":\"92845.2\",\"size\":\"0.00000\"},{\"price\":\"92856.2\",\"size\":\"0.00000\"}],\"bids\":[{\"price\":\"92823.2\",\"size\":\"0.08953\"},{\"price\":\"92809.0\",\"size\":\"0.00000\"}],\"offset\":6961758,\"nonce\":3691007668},\"timestamp\":1765394039204,\"type\":\"update/order_book\"}"
    "msg": "{\"channel\":\"order_book:1\",\"offset\":6961759,\"order_book\":{\"code\":0,\"asks\":[{\"price\":\"92840.4\",\"size\":\"0.00000\"},{\"price\":\"92842.7\",\"size\":\"0.00000\"}],\"bids\":[{\"price\":\"92810.6\",\"size\":\"0.00000\"},{\"price\":\"92793.5\",\"size\":\"0.00000\"}],\"offset\":6961759,\"nonce\":3691007669},\"timestamp\":1765394039208,\"type\":\"update/order_book\"}"
    "msg": "{\"channel\":\"order_book:1\",\"offset\":6961760,\"order_book\":{\"code\":0,\"asks\":[{\"price\":\"92835.6\",\"size\":\"0.00000\"}],\"bids\":[{\"price\":\"92832.1\",\"size\":\"0.38767\"},{\"price\":\"92826.4\",\"size\":\"0.08081\"},{\"price\":\"92809.8\",\"size\":\"0.00861\"}],\"offset\":6961760,\"nonce\":3691007670},\"timestamp\":1765394039212,\"type\":\"update/order_book\"}"
    "msg": "{\"channel\":\"order_book:1\",\"offset\":6961761,\"order_book\":{\"code\":0,\"asks\":[{\"price\":\"92837.5\",\"size\":\"0.00000\"},{\"price\":\"92843.2\",\"size\":\"0.08084\"},{\"price\":\"92845.2\",\"size\":\"1.07758\"},{\"price\":\"92846.3\",\"size\":\"0.08082\"},{\"price\":\"92854.0\",\"size\":\"0.00000\"}],\"bids\":[{\"price\":\"92829.2\",\"size\":\"1.59642\"},{\"price\":\"92824.4\",\"size\":\"0.02905\"},{\"price\":\"92822.2\",\"size\":\"0.00000\"}],\"offset\":6961761,\"nonce\":3691007671},\"timestamp\":1765394039220,\"type\":\"update/order_book\"}"
    "msg": "{\"channel\":\"order_book:1\",\"offset\":6961762,\"order_book\":{\"code\":0,\"asks\":[{\"price\":\"92839.1\",\"size\":\"0.00000\"}],\"bids\":[],\"offset\":6961762,\"nonce\":3691007672},\"timestamp\":1765394039226,\"type\":\"update/order_book\"}"
    "msg": "{\"channel\":\"order_book:1\",\"offset\":6961763,\"order_book\":{\"code\":0,\"asks\":[{\"price\":\"92835.6\",\"size\":\"0.02154\"},{\"price\":\"92839.9\",\"size\":\"0.00000\"}],\"bids\":[],\"offset\":6961763,\"nonce\":3691007674},\"timestamp\":1765394039228,\"type\":\"update/order_book\"}"
    "msg": "{\"channel\":\"order_book:1\",\"offset\":6961764,\"order_book\":{\"code\":0,\"asks\":[{\"price\":\"92834.8\",\"size\":\"0.00000\"},{\"price\":\"92835.6\",\"size\":\"0.01267\"},{\"price\":\"92838.3\",\"size\":\"0.00127\"},{\"price\":\"92843.3\",\"size\":\"0.03015\"},{\"price\":\"92845.1\",\"size\":\"0.10780\"},{\"price\":\"92846.4\",\"size\":\"0.01098\"}],\"bids\":[{\"price\":\"92824.4\",\"size\":\"0.00000\"}],\"offset\":6961764,\"nonce\":3691007675},\"timestamp\":1765394039234,\"type\":\"update/order_book\"}"
    "msg": "{\"channel\":\"order_book:1\",\"offset\":6961766,\"order_book\":{\"code\":0,\"asks\":[{\"price\":\"92838.3\",\"size\":\"0.00000\"},{\"price\":\"92840.0\",\"size\":\"0.02834\"},{\"price\":\"92843.3\",\"size\":\"0.00861\"},{\"price\":\"92846.4\",\"size\":\"0.00021\"}],\"bids\":[{\"price\":\"92834.7\",\"size\":\"0.80117\"},{\"price\":\"92832.1\",\"size\":\"1.31298\"},{\"price\":\"92829.7\",\"size\":\"0.00215\"}],\"offset\":6961766,\"nonce\":3691007678},\"timestamp\":1765394039245,\"type\":\"update/order_book\"}"
    "msg": "{\"channel\":\"order_book:1\",\"offset\":6961767,\"order_book\":{\"code\":0,\"asks\":[{\"price\":\"92834.8\",\"size\":\"0.02154\"}],\"bids\":[],\"offset\":6961767,\"nonce\":3691007681},\"timestamp\":1765394039251,\"type\":\"update/order_book\"}"
    "msg": "{\"channel\":\"order_book:1\",\"offset\":6961769,\"order_book\":{\"code\":0,\"asks\":[{\"price\":\"92843.1\",\"size\":\"0.38767\"},{\"price\":\"92843.3\",\"size\":\"0.03015\"},{\"price\":\"92846.4\",\"size\":\"0.01098\"},{\"price\":\"92846.5\",\"size\":\"0.00020\"},{\"price\":\"92848.6\",\"size\":\"2.77475\"}],\"bids\":[{\"price\":\"92834.7\",\"size\":\"2.95562\"},{\"price\":\"92826.6\",\"size\":\"0.00000\"},{\"price\":\"92819.9\",\"size\":\"2.69396\"},{\"price\":\"92807.7\",\"size\":\"0.10780\"}],\"offset\":6961769,\"nonce\":3691007686},\"timestamp\":1765394039262,\"type\":\"update/order_book\"}"
    "msg": "{\"channel\":\"order_book:1\",\"offset\":6961770,\"order_book\":{\"code\":0,\"asks\":[{\"price\":\"92835.6\",\"size\":\"0.00000\"},{\"price\":\"92864.3\",\"size\":\"0.04190\"}],\"bids\":[{\"price\":\"92822.6\",\"size\":\"0.10780\"},{\"price\":\"92815.4\",\"size\":\"0.08082\"},{\"price\":\"92813.6\",\"size\":\"0.11979\"}],\"offset\":6961770,\"nonce\":3691007687},\"timestamp\":1765394039267,\"type\":\"update/order_book\"}"
    "msg": "{\"channel\":\"order_book:1\",\"offset\":6961771,\"order_book\":{\"code\":0,\"asks\":[],\"bids\":[{\"price\":\"92834.7\",\"size\":\"3.89280\"},{\"price\":\"92828.0\",\"size\":\"0.02905\"}],\"offset\":6961771,\"nonce\":3691007689},\"timestamp\":1765394039268,\"type\":\"update/order_book\"}"
    "msg": "{\"channel\":\"order_book:1\",\"offset\":6961772,\"order_book\":{\"code\":0,\"asks\":[{\"price\":\"92840.0\",\"size\":\"0.00000\"},{\"price\":\"92843.7\",\"size\":\"0.00000\"},{\"price\":\"92886.5\",\"size\":\"0.00000\"},{\"price\":\"92969.9\",\"size\":\"0.00000\"}],\"bids\":[],\"offset\":6961772,\"nonce\":3691007693},\"timestamp\":1765394039275,\"type\":\"update/order_book\"}"
    "msg": "{\"channel\":\"order_book:1\",\"offset\":6961773,\"order_book\":{\"code\":0,\"asks\":[],\"bids\":[{\"price\":\"92834.7\",\"size\":\"4.97038\"}],\"offset\":6961773,\"nonce\":3691007694},\"timestamp\":1765394039277,\"type\":\"update/order_book\"}"
    "msg": "{\"channel\":\"order_book:1\",\"offset\":6961775,\"order_book\":{\"code\":0,\"asks\":[{\"price\":\"92864.2\",\"size\":\"0.00000\"},{\"price\":\"92864.6\",\"size\":\"4.96492\"}],\"bids\":[{\"price\":\"92825.6\",\"size\":\"4.53212\"},{\"price\":\"92824.7\",\"size\":\"0.00000\"},{\"price\":\"92819.9\",\"size\":\"2.69504\"},{\"price\":\"92819.0\",\"size\":\"0.00000\"}],\"offset\":6961775,\"nonce\":3691007698},\"timestamp\":1765394039285,\"type\":\"update/order_book\"}"
    "msg": "{\"channel\":\"order_book:1\",\"offset\":6961776,\"order_book\":{\"code\":0,\"asks\":[{\"price\":\"92843.1\",\"size\":\"0.00000\"},{\"price\":\"92843.3\",\"size\":\"0.02154\"},{\"price\":\"92850.4\",\"size\":\"0.00000\"}],\"bids\":[{\"price\":\"92816.4\",\"size\":\"0.00000\"},{\"price\":\"92795.2\",\"size\":\"0.00000\"}],\"offset\":6961776,\"nonce\":3691007699},\"timestamp\":1765394039288,\"type\":\"update/order_book\"}"
    "msg": "{\"channel\":\"order_book:1\",\"offset\":6961778,\"order_book\":{\"code\":0,\"asks\":[{\"price\":\"92847.1\",\"size\":\"0.08944\"},{\"price\":\"92847.3\",\"size\":\"0.00000\"}],\"bids\":[{\"price\":\"92814.8\",\"size\":\"0.10780\"},{\"price\":\"92807.7\",\"size\":\"0.00000\"},{\"price\":\"92796.1\",\"size\":\"0.01078\"}],\"offset\":6961778,\"nonce\":3691007704},\"timestamp\":1765394039300,\"type\":\"update/order_book\"}"
    "msg": "{\"channel\":\"order_book:1\",\"offset\":6961779,\"order_book\":{\"code\":0,\"asks\":[{\"price\":\"92834.8\",\"size\":\"0.04308\"},{\"price\":\"92842.3\",\"size\":\"0.02834\"},{\"price\":\"92843.3\",\"size\":\"0.00000\"},{\"price\":\"92846.8\",\"size\":\"0.01077\"},{\"price\":\"92847.6\",\"size\":\"0.00500\"},{\"price\":\"92850.5\",\"size\":\"0.02828\"},{\"price\":\"92866.7\",\"size\":\"0.00000\"}],\"bids\":[{\"price\":\"92812.1\",\"size\":\"0.00000\"}],\"offset\":6961779,\"nonce\":3691007705},\"timestamp\":1765394039305,\"type\":\"update/order_book\"}"
    "msg": "{\"channel\":\"order_book:1\",\"offset\":6961780,\"order_book\":{\"code\":0,\"asks\":[],\"bids\":[{\"price\":\"92829.5\",\"size\":\"0.10780\"},{\"price\":\"92821.7\",\"size\":\"0.00000\"},{\"price\":\"92796.1\",\"size\":\"0.00000\"}],\"offset\":6961780,\"nonce\":3691007706},\"timestamp\":1765394039308,\"type\":\"update/order_book\"}"
    "msg": "{\"channel\":\"order_book:1\",\"offset\":6961781,\"order_book\":{\"code\":0,\"asks\":[{\"price\":\"92843.0\",\"size\":\"0.38767\"},{\"price\":\"92843.8\",\"size\":\"0.02154\"}],\"bids\":[],\"offset\":6961781,\"nonce\":3691007707},\"timestamp\":1765394039311,\"type\":\"update/order_book\"}"
    "msg": "{\"channel\":\"order_book:1\",\"offset\":6961782,\"order_book\":{\"code\":0,\"asks\":[{\"price\":\"92846.8\",\"size\":\"0.00000\"}],\"bids\":[{\"price\":\"92797.8\",\"size\":\"0.01078\"}],\"offset\":6961782,\"nonce\":3691007709},\"timestamp\":1765394039319,\"type\":\"update/order_book\"}"
    "msg": "{\"channel\":\"order_book:1\",\"offset\":6961783,\"order_book\":{\"code\":0,\"asks\":[{\"price\":\"92842.3\",\"size\":\"0.00000\"},{\"price\":\"92843.8\",\"size\":\"0.00000\"},{\"price\":\"92847.1\",\"size\":\"0.08083\"}],\"bids\":[],\"offset\":6961783,\"nonce\":3691007712},\"timestamp\":1765394039325,\"type\":\"update/order_book\"}"
    "msg": "{\"channel\":\"order_book:1\",\"offset\":6961784,\"order_book\":{\"code\":0,\"asks\":[{\"price\":\"92842.6\",\"size\":\"0.10780\"},{\"price\":\"92844.6\",\"size\":\"0.10780\"},{\"price\":\"92845.1\",\"size\":\"0.00000\"},{\"price\":\"92845.8\",\"size\":\"0.00000\"},{\"price\":\"92847.0\",\"size\":\"0.00000\"},{\"price\":\"92848.9\",\"size\":\"0.01077\"},{\"price\":\"92869.4\",\"size\":\"0.00309\"},{\"price\":\"92896.4\",\"size\":\"8.07918\"}],\"bids\":[{\"price\":\"92828.0\",\"size\":\"0.00000\"}],\"offset\":6961784,\"nonce\":3691007713},\"timestamp\":1765394039336,\"type\":\"update/order_book\"}"
    "msg": "{\"channel\":\"order_book:1\",\"offset\":6961785,\"order_book\":{\"code\":0,\"asks\":[{\"price\":\"92834.8\",\"size\":\"0.02154\"}],\"bids\":[{\"price\":\"92831.2\",\"size\":\"0.02905\"},{\"price\":\"92825.0\",\"size\":\"0.02906\"},{\"price\":\"92817.5\",\"size\":\"0.00000\"}],\"offset\":6961785,\"nonce\":3691007714},\"timestamp\":1765394039337,\"type\":\"update/order_book\"}"
    "msg": "{\"channel\":\"order_book:1\",\"offset\":6961786,\"order_book\":{\"code\":0,\"asks\":[{\"price\":\"92843.0\",\"size\":\"0.00000\"},{\"price\":\"92844.6\",\"size\":\"0.13614\"},{\"price\":\"92846.2\",\"size\":\"0.00000\"},{\"price\":\"92848.9\",\"size\":\"0.00000\"}],\"bids\":[{\"price\":\"92823.7\",\"size\":\"0.08081\"}],\"offset\":6961786,\"nonce\":3691007716},\"timestamp\":1765394039351,\"type\":\"update/order_book\"}"
    "msg": "{\"channel\":\"order_book:1\",\"offset\":6961788,\"order_book\":{\"code\":0,\"asks\":[{\"price\":\"92845.8\",\"size\":\"0.02154\"}],\"bids\":[],\"offset\":6961788,\"nonce\":3691007720},\"timestamp\":1765394039363,\"type\":\"update/order_book\"}"
    "msg": "{\"channel\":\"order_book:1\",\"offset\":6961789,\"order_book\":{\"code\":0,\"asks\":[{\"price\":\"92851.6\",\"size\":\"0.02479\"}],\"bids\":[{\"price\":\"92829.5\",\"size\":\"0.00000\"},{\"price\":\"92827.6\",\"size\":\"0.10780\"},{\"price\":\"92822.6\",\"size\":\"0.00000\"},{\"price\":\"92820.9\",\"size\":\"0.10780\"}],\"offset\":6961789,\"nonce\":3691007722},\"timestamp\":1765394039368,\"type\":\"update/order_book\"}"
    "msg": "{\"channel\":\"order_book:1\",\"offset\":6961790,\"order_book\":{\"code\":0,\"asks\":[{\"price\":\"92843.4\",\"size\":\"0.10780\"},{\"price\":\"92845.2\",\"size\":\"1.07758\"}],\"bids\":[{\"price\":\"92814.8\",\"size\":\"0.00000\"},{\"price\":\"92813.0\",\"size\":\"0.10780\"}],\"offset\":6961790,\"nonce\":3691007725},\"timestamp\":1765394039372,\"type\":\"update/order_book\"}"
    "msg": "{\"channel\":\"order_book:1\",\"offset\":6961791,\"order_book\":{\"code\":0,\"asks\":[],\"bids\":[{\"price\":\"92820.0\",\"size\":\"0.38875\"},{\"price\":\"92819.9\",\"size\":\"2.69396\"}],\"offset\":6961791,\"nonce\":3691007733},\"timestamp\":1765394039388,\"type\":\"update/order_book\"}"
    "msg": "{\"channel\":\"order_book:1\",\"offset\":6961792,\"order_book\":{\"code\":0,\"asks\":[{\"price\":\"92842.5\",\"size\":\"0.38767\"},{\"price\":\"92842.6\",\"size\":\"0.00000\"},{\"price\":\"92843.4\",\"size\":\"0.00000\"},{\"price\":\"92876.7\",\"size\":\"0.00000\"}],\"bids\":[],\"offset\":6961792,\"nonce\":3691007735},\"timestamp\":1765394039401,\"type\":\"update/order_book\"}"
    "msg": "{\"channel\":\"order_book:1\",\"offset\":6961793,\"order_book\":{\"code\":0,\"asks\":[],\"bids\":[{\"price\":\"92829.7\",\"size\":\"0.00000\"},{\"price\":\"92797.8\",\"size\":\"0.00000\"}],\"offset\":6961793,\"nonce\":3691007736},\"timestamp\":1765394039409,\"type\":\"update/order_book\"}"
    "msg": "{\"channel\":\"order_book:1\",\"offset\":6961794,\"order_book\":{\"code\":0,\"asks\":[{\"price\":\"92844.6\",\"size\":\"0.02834\"},{\"price\":\"92845.8\",\"size\":\"0.00000\"},{\"price\":\"92847.7\",\"size\":\"0.00000\"},{\"price\":\"92848.9\",\"size\":\"0.00000\"},{\"price\":\"92872.6\",\"size\":\"0.38767\"}],\"bids\":[],\"offset\":6961794,\"nonce\":3691007737},\"timestamp\":1765394039413,\"type\":\"update/order_book\"}"
    "msg": "{\"channel\":\"order_book:1\",\"offset\":6961795,\"order_book\":{\"code\":0,\"asks\":[{\"price\":\"92864.6\",\"size\":\"0.36730\"},{\"price\":\"92870.0\",\"size\":\"4.73195\"}],\"bids\":[{\"price\":\"92825.7\",\"size\":\"4.53617\"},{\"price\":\"92825.6\",\"size\":\"0.00000\"},{\"price\":\"92798.8\",\"size\":\"0.01078\"}],\"offset\":6961795,\"nonce\":3691007738},\"timestamp\":1765394039419,\"type\":\"update/order_book\"}"
    "msg": "{\"channel\":\"order_book:1\",\"offset\":6961796,\"order_book\":{\"code\":0,\"asks\":[{\"price\":\"92846.3\",\"size\":\"0.00000\"},{\"price\":\"92847.4\",\"size\":\"0.02154\"}],\"bids\":[],\"offset\":6961796,\"nonce\":3691007739},\"timestamp\":1765394039420,\"type\":\"update/order_book\"}"
    "msg": "{\"channel\":\"order_book:1\",\"offset\":6961797,\"order_book\":{\"code\":0,\"asks\":[{\"price\":\"92840.9\",\"size\":\"0.00000\"},{\"price\":\"92844.6\",\"size\":\"0.00000\"},{\"price\":\"92845.2\",\"size\":\"0.00000\"},{\"price\":\"92846.5\",\"size\":\"0.00000\"},{\"price\":\"92848.3\",\"size\":\"0.00000\"},{\"price\":\"92850.4\",\"size\":\"0.01077\"},{\"price\":\"92852.4\",\"size\":\"0.38767\"},{\"price\":\"92863.7\",\"size\":\"0.00000\"},{\"price\":\"92869.4\",\"size\":\"0.00000\"}],\"bids\":[{\"price\":\"92831.2\",\"size\":\"0.00000\"}],\"offset\":6961797,\"nonce\":3691007740},\"timestamp\":1765394039426,\"type\":\"update/order_book\"}"
    "msg": "{\"channel\":\"order_book:1\",\"offset\":6961798,\"order_book\":{\"code\":0,\"asks\":[{\"price\":\"92842.5\",\"size\":\"0.00000\"}],\"bids\":[{\"price\":\"92798.8\",\"size\":\"0.00000\"}],\"offset\":6961798,\"nonce\":3691007741},\"timestamp\":1765394039434,\"type\":\"update/order_book\"}"
    "msg": "{\"channel\":\"order_book:1\",\"offset\":6961799,\"order_book\":{\"code\":0,\"asks\":[],\"bids\":[{\"price\":\"92827.8\",\"size\":\"0.00000\"}],\"offset\":6961799,\"nonce\":3691007742},\"timestamp\":1765394039441,\"type\":\"update/order_book\"}"
    "msg": "{\"channel\":\"order_book:1\",\"offset\":6961800,\"order_book\":{\"code\":0,\"asks\":[{\"price\":\"92847.4\",\"size\":\"0.00000\"},{\"price\":\"92850.4\",\"size\":\"0.00000\"}],\"bids\":[],\"offset\":6961800,\"nonce\":3691007743},\"timestamp\":1765394039447,\"type\":\"update/order_book\"}"
    "msg": "{\"channel\":\"order_book:1\",\"offset\":6961801,\"order_book\":{\"code\":0,\"asks\":[],\"bids\":[{\"price\":\"92833.2\",\"size\":\"0.02905\"}],\"offset\":6961801,\"nonce\":3691007744},\"timestamp\":1765394039455,\"type\":\"update/order_book\"}"
    "msg": "{\"channel\":\"order_book:1\",\"offset\":6961802,\"order_book\":{\"code\":0,\"asks\":[{\"price\":\"92847.6\",\"size\":\"0.00000\"},{\"price\":\"92859.6\",\"size\":\"0.00500\"}],\"bids\":[{\"price\":\"92833.2\",\"size\":\"0.00000\"},{\"price\":\"92814.7\",\"size\":\"0.00000\"},{\"price\":\"92813.6\",\"size\":\"0.00000\"}],\"offset\":6961802,\"nonce\":3691007745},\"timestamp\":1765394039457,\"type\":\"update/order_book\"}"
    "msg": "{\"channel\":\"order_book:1\",\"offset\":6961804,\"order_book\":{\"code\":0,\"asks\":[{\"price\":\"92853.0\",\"size\":\"0.00000\"}],\"bids\":[],\"offset\":6961804,\"nonce\":3691007747},\"timestamp\":1765394039464,\"type\":\"update/order_book\"}"
    "msg": "{\"channel\":\"order_book:1\",\"offset\":6961806,\"order_book\":{\"code\":0,\"asks\":[{\"price\":\"92834.8\",\"size\":\"0.02154\"},{\"price\":\"92848.9\",\"size\":\"0.00000\"},{\"price\":\"92851.3\",\"size\":\"0.10780\"}],\"bids\":[],\"offset\":6961806,\"nonce\":3691007749},\"timestamp\":1765394039474,\"type\":\"update/order_book\"}"
    "msg": "{\"channel\":\"order_book:1\",\"offset\":6961807,\"order_book\":{\"code\":0,\"asks\":[{\"price\":\"92843.2\",\"size\":\"0.00000\"},{\"price\":\"92846.3\",\"size\":\"0.03768\"},{\"price\":\"92848.6\",\"size\":\"0.00000\"},{\"price\":\"92850.9\",\"size\":\"0.00000\"},{\"price\":\"92851.4\",\"size\":\"0.00000\"},{\"price\":\"92853.1\",\"size\":\"0.00000\"},{\"price\":\"92860.2\",\"size\":\"0.00021\"}],\"bids\":[{\"price\":\"92822.2\",\"size\":\"0.66099\"},{\"price\":\"92821.0\",\"size\":\"0.11979\"},{\"price\":\"92819.9\",\"size\":\"0.00000\"},{\"price\":\"92818.2\",\"size\":\"0.00000\"},{\"price\":\"92810.4\",\"size\":\"0.13464\"}],\"offset\":6961807,\"nonce\":3691007750},\"timestamp\":1765394039477,\"type\":\"update/order_book\"}"
    "msg": "{\"channel\":\"order_book:1\",\"offset\":6961808,\"order_book\":{\"code\":0,\"asks\":[{\"price\":\"92850.1\",\"size\":\"0.07539\"},{\"price\":\"92852.0\",\"size\":\"0.00000\"},{\"price\":\"92872.3\",\"size\":\"0.00309\"}],\"bids\":[{\"price\":\"92821.1\",\"size\":\"0.00000\"}],\"offset\":6961808,\"nonce\":3691007751},\"timestamp\":1765394039482,\"type\":\"update/order_book\"}"
    "msg": "{\"channel\":\"order_book:1\",\"offset\":6961809,\"order_book\":{\"code\":0,\"asks\":[{\"price\":\"92848.7\",\"size\":\"0.02834\"}],\"bids\":[{\"price\":\"92831.9\",\"size\":\"0.03768\"},{\"price\":\"92820.1\",\"size\":\"0.18861\"},{\"price\":\"92813.0\",\"size\":\"0.00000\"}],\"offset\":6961809,\"nonce\":3691007752},\"timestamp\":1765394039490,\"type\":\"update/order_book\"}"
    "msg": "{\"channel\":\"order_book:1\",\"offset\":6961810,\"order_book\":{\"code\":0,\"asks\":[{\"price\":\"92850.1\",\"size\":\"0.05385\"},{\"price\":\"92850.4\",\"size\":\"0.10780\"},{\"price\":\"92851.1\",\"size\":\"1.07758\"},{\"price\":\"92853.1\",\"size\":\"0.00861\"},{\"price\":\"92853.2\",\"size\":\"0.01076\"}],\"bids\":[],\"offset\":6961810,\"nonce\":3691007753},\"timestamp\":1765394039497,\"type\":\"update/order_book\"}"
    "msg": "{\"channel\":\"order_book:1\",\"offset\":6961811,\"order_book\":{\"code\":0,\"asks\":[{\"price\":\"92853.2\",\"size\":\"0.00000\"},{\"price\":\"92861.9\",\"size\":\"0.12064\"}],\"bids\":[],\"offset\":6961811,\"nonce\":3691007754},\"timestamp\":1765394039498,\"type\":\"update/order_book\"}"
    "msg": "{\"channel\":\"order_book:1\",\"offset\":6961812,\"order_book\":{\"code\":0,\"asks\":[{\"price\":\"92834.8\",\"size\":\"0.04308\"},{\"price\":\"92850.5\",\"size\":\"0.00000\"},{\"price\":\"92853.3\",\"size\":\"0.10801\"}],\"bids\":[{\"price\":\"92834.3\",\"size\":\"0.00861\"}],\"offset\":6961812,\"nonce\":3691007755},\"timestamp\":1765394039506,\"type\":\"update/order_book\"}"
    "msg": "{\"channel\":\"order_book:1\",\"offset\":6961813,\"order_book\":{\"code\":0,\"asks\":[{\"price\":\"92850.1\",\"size\":\"0.07539\"},{\"price\":\"92853.2\",\"size\":\"0.01076\"}],\"bids\":[{\"price\":\"92827.7\",\"size\":\"0.10780\"},{\"price\":\"92820.9\",\"size\":\"0.00000\"}],\"offset\":6961813,\"nonce\":3691007756},\"timestamp\":1765394039512,\"type\":\"update/order_book\"}"
    "msg": "{\"channel\":\"order_book:1\",\"offset\":6961814,\"order_book\":{\"code\":0,\"asks\":[{\"price\":\"92865.4\",\"size\":\"0.08072\"}],\"bids\":[],\"offset\":6961814,\"nonce\":3691007757},\"timestamp\":1765394039517,\"type\":\"update/order_book\"}"
    "msg": "{\"channel\":\"order_book:1\",\"offset\":6961815,\"order_book\":{\"code\":0,\"asks\":[{\"price\":\"92987.4\",\"size\":\"8.07918\"}],\"bids\":[{\"price\":\"92806.8\",\"size\":\"0.00000\"}],\"offset\":6961815,\"nonce\":3691007758},\"timestamp\":1765394039525,\"type\":\"update/order_book\"}"
    "msg": "{\"channel\":\"order_book:1\",\"offset\":6961818,\"order_book\":{\"code\":0,\"asks\":[{\"price\":\"92858.7\",\"size\":\"0.08079\"},{\"price\":\"92861.4\",\"size\":\"0.16162\"}],\"bids\":[],\"offset\":6961818,\"nonce\":3691007761},\"timestamp\":1765394039540,\"type\":\"update/order_book\"}"
    "msg": "{\"channel\":\"order_book:1\",\"offset\":6961819,\"order_book\":{\"code\":0,\"asks\":[{\"price\":\"92846.9\",\"size\":\"0.10780\"},{\"price\":\"92851.3\",\"size\":\"0.00000\"},{\"price\":\"92857.5\",\"size\":\"0.02828\"}],\"bids\":[{\"price\":\"92827.7\",\"size\":\"0.00000\"}],\"offset\":6961819,\"nonce\":3691007762},\"timestamp\":1765394039545,\"type\":\"update/order_book\"}"
    "msg": "{\"channel\":\"order_book:1\",\"offset\":6961820,\"order_book\":{\"code\":0,\"asks\":[],\"bids\":[{\"price\":\"92834.6\",\"size\":\"0.10780\"},{\"price\":\"92827.6\",\"size\":\"0.00000\"}],\"offset\":6961820,\"nonce\":3691007765},\"timestamp\":1765394039560,\"type\":\"update/order_book\"}"
    "msg": "{\"channel\":\"order_book:1\",\"offset\":6961821,\"order_book\":{\"code\":0,\"asks\":[{\"price\":\"92870.0\",\"size\":\"0.13460\"},{\"price\":\"92873.9\",\"size\":\"4.59715\"}],\"bids\":[],\"offset\":6961821,\"nonce\":3691007766},\"timestamp\":1765394039566,\"type\":\"update/order_book\"}"
    "msg": "{\"channel\":\"order_book:1\",\"offset\":6961822,\"order_book\":{\"code\":0,\"asks\":[],\"bids\":[{\"price\":\"92825.7\",\"size\":\"0.00000\"},{\"price\":\"92825.6\",\"size\":\"4.54108\"}],\"offset\":6961822,\"nonce\":3691007767},\"timestamp\":1765394039569,\"type\":\"update/order_book\"}"
    "msg": "{\"channel\":\"order_book:1\",\"offset\":6961823,\"order_book\":{\"code\":0,\"asks\":[{\"price\":\"92846.7\",\"size\":\"0.10780\"},{\"price\":\"92850.4\",\"size\":\"0.00000\"}],\"bids\":[{\"price\":\"92824.3\",\"size\":\"0.10780\"}],\"offset\":6961823,\"nonce\":3691007768},\"timestamp\":1765394039577,\"type\":\"update/order_book\"}"
    "msg": "{\"channel\":\"order_book:1\",\"offset\":6961824,\"order_book\":{\"code\":0,\"asks\":[{\"price\":\"92848.9\",\"size\":\"0.10780\"},{\"price\":\"92853.3\",\"size\":\"0.00021\"}],\"bids\":[{\"price\":\"92834.6\",\"size\":\"0.00000\"}],\"offset\":6961824,\"nonce\":3691007771},\"timestamp\":1765394039587,\"type\":\"update/order_book\"}"
    "msg": "{\"channel\":\"order_book:1\",\"offset\":6961825,\"order_book\":{\"code\":0,\"asks\":[],\"bids\":[{\"price\":\"92820.1\",\"size\":\"0.08081\"}],\"offset\":6961825,\"nonce\":3691007772},\"timestamp\":1765394039590,\"type\":\"update/order_book\"}"
    "msg": "{\"channel\":\"order_book:1\",\"offset\":6961826,\"order_book\":{\"code\":0,\"asks\":[{\"price\":\"92834.8\",\"size\":\"0.00000\"},{\"price\":\"92851.1\",\"size\":\"0.00000\"}],\"bids\":[],\"offset\":6961826,\"nonce\":3691007774},\"timestamp\":1765394039601,\"type\":\"update/order_book\"}"
    "msg": "{\"channel\":\"order_book:1\",\"offset\":6961827,\"order_book\":{\"code\":0,\"asks\":[{\"price\":\"92850.1\",\"size\":\"0.02154\"}],\"bids\":[{\"price\":\"92814.6\",\"size\":\"0.00000\"}],\"offset\":6961827,\"nonce\":3691007775},\"timestamp\":1765394039605,\"type\":\"update/order_book\"}"
    "msg": "{\"channel\":\"order_book:1\",\"offset\":6961828,\"order_book\":{\"code\":0,\"asks\":[],\"bids\":[{\"price\":\"92821.3\",\"size\":\"0.00108\"},{\"price\":\"92820.0\",\"size\":\"0.38767\"}],\"offset\":6961828,\"nonce\":3691007776},\"timestamp\":1765394039608,\"type\":\"update/order_book\"}"
    "msg": "{\"channel\":\"order_book:1\",\"offset\":6961829,\"order_book\":{\"code\":0,\"asks\":[{\"price\":\"92842.4\",\"size\":\"0.00000\"},{\"price\":\"92846.2\",\"size\":\"0.38727\"}],\"bids\":[],\"offset\":6961829,\"nonce\":3691007780},\"timestamp\":1765394039622,\"type\":\"update/order_book\"}"
    "msg": "{\"channel\":\"order_book:1\",\"offset\":6961830,\"order_book\":{\"code\":0,\"asks\":[{\"price\":\"92842.3\",\"size\":\"0.83445\"},{\"price\":\"92842.4\",\"size\":\"0.84088\"}],\"bids\":[{\"price\":\"92793.1\",\"size\":\"0.00000\"}],\"offset\":6961830,\"nonce\":3691007781},\"timestamp\":1765394039626,\"type\":\"update/order_book\"}"
    "msg": "{\"channel\":\"order_book:1\",\"offset\":6961831,\"order_book\":{\"code\":0,\"asks\":[],\"bids\":[{\"price\":\"92836.1\",\"size\":\"0.38767\"}],\"offset\":6961831,\"nonce\":3691007782},\"timestamp\":1765394039629,\"type\":\"update/order_book\"}"
    "msg": "{\"channel\":\"order_book:1\",\"offset\":6961832,\"order_book\":{\"code\":0,\"asks\":[],\"bids\":[{\"price\":\"92827.1\",\"size\":\"1.50888\"}],\"offset\":6961832,\"nonce\":3691007784},\"timestamp\":1765394039634,\"type\":\"update/order_book\"}"
    "msg": "{\"channel\":\"order_book:1\",\"offset\":6961833,\"order_book\":{\"code\":0,\"asks\":[],\"bids\":[{\"price\":\"92834.7\",\"size\":\"4.95961\"}],\"offset\":6961833,\"nonce\":3691007786},\"timestamp\":1765394039642,\"type\":\"update/order_book\"}"
    "msg": "{\"channel\":\"order_book:1\",\"offset\":6961834,\"order_book\":{\"code\":0,\"asks\":[{\"price\":\"92842.3\",\"size\":\"0.00000\"},{\"price\":\"92842.4\",\"size\":\"0.00000\"},{\"price\":\"92846.2\",\"size\":\"1.33517\"}],\"bids\":[{\"price\":\"92834.8\",\"size\":\"0.02905\"},{\"price\":\"92833.6\",\"size\":\"0.00021\"},{\"price\":\"92828.8\",\"size\":\"0.00000\"}],\"offset\":6961834,\"nonce\":3691007789},\"timestamp\":1765394039653,\"type\":\"update/order_book\"}"
    "msg": "{\"channel\":\"order_book:1\",\"offset\":6961836,\"order_book\":{\"code\":0,\"asks\":[{\"price\":\"92842.2\",\"size\":\"0.00040\"},{\"price\":\"92848.9\",\"size\":\"0.00000\"},{\"price\":\"92849.9\",\"size\":\"0.10780\"},{\"price\":\"92854.4\",\"size\":\"0.05384\"}],\"bids\":[{\"price\":\"92818.9\",\"size\":\"0.05407\"},{\"price\":\"92818.4\",\"size\":\"0.10780\"}],\"offset\":6961836,\"nonce\":3691007791},\"timestamp\":1765394039669,\"type\":\"update/order_book\"}"
    "msg": "{\"channel\":\"order_book:1\",\"offset\":6961837,\"order_book\":{\"code\":0,\"asks\":[],\"bids\":[{\"price\":\"92825.2\",\"size\":\"0.10780\"},{\"price\":\"92824.3\",\"size\":\"0.00000\"}],\"offset\":6961837,\"nonce\":3691007792},\"timestamp\":1765394039673,\"type\":\"update/order_book\"}"
    "msg": "{\"channel\":\"order_book:1\",\"offset\":6961838,\"order_book\":{\"code\":0,\"asks\":[{\"price\":\"92846.7\",\"size\":\"0.00000\"},{\"price\":\"92848.7\",\"size\":\"0.13614\"}],\"bids\":[],\"offset\":6961838,\"nonce\":3691007793},\"timestamp\":1765394039677,\"type\":\"update/order_book\"}"
    "msg": "{\"channel\":\"order_book:1\",\"offset\":6961839,\"order_book\":{\"code\":0,\"asks\":[],\"bids\":[{\"price\":\"92832.8\",\"size\":\"0.10780\"}],\"offset\":6961839,\"nonce\":3691007794},\"timestamp\":1765394039679,\"type\":\"update/order_book\"}"
    "msg": "{\"channel\":\"order_book:1\",\"offset\":6961840,\"order_book\":{\"code\":0,\"asks\":[{\"price\":\"92842.3\",\"size\":\"0.00000\"}],\"bids\":[],\"offset\":6961840,\"nonce\":3691007795},\"timestamp\":1765394039689,\"type\":\"update/order_book\"}"
    "msg": "{\"channel\":\"order_book:1\",\"offset\":6961841,\"order_book\":{\"code\":0,\"asks\":[{\"price\":\"92847.6\",\"size\":\"0.23269\"}],\"bids\":[],\"offset\":6961841,\"nonce\":3691007796},\"timestamp\":1765394039690,\"type\":\"update/order_book\"}"
    "msg": "{\"channel\":\"order_book:1\",\"offset\":6961842,\"order_book\":{\"code\":0,\"asks\":[{\"price\":\"92842.2\",\"size\":\"0.00000\"},{\"price\":\"92842.3\",\"size\":\"0.01794\"},{\"price\":\"92846.4\",\"size\":\"0.00000\"},{\"price\":\"92853.3\",\"size\":\"0.00000\"}],\"bids\":[{\"price\":\"92818.9\",\"size\":\"0.05386\"}],\"offset\":6961842,\"nonce\":3691007801},\"timestamp\":1765394039700,\"type\":\"update/order_book\"}"
    "msg": "{\"channel\":\"order_book:1\",\"offset\":6961843,\"order_book\":{\"code\":0,\"asks\":[],\"bids\":[{\"price\":\"92836.1\",\"size\":\"1.36743\"}],\"offset\":6961843,\"nonce\":3691007807},\"timestamp\":1765394039707,\"type\":\"update/order_book\"}"
    "msg": "{\"channel\":\"order_book:1\",\"offset\":6961844,\"order_book\":{\"code\":0,\"asks\":[{\"price\":\"92874.7\",\"size\":\"0.00000\"}],\"bids\":[],\"offset\":6961844,\"nonce\":3691007813},\"timestamp\":1765394039719,\"type\":\"update/order_book\"}"
    "msg": "{\"channel\":\"order_book:1\",\"offset\":6961846,\"order_book\":{\"code\":0,\"asks\":[{\"price\":\"92842.3\",\"size\":\"0.02154\"}],\"bids\":[],\"offset\":6961846,\"nonce\":3691007821},\"timestamp\":1765394039739,\"type\":\"update/order_book\"}"
    "msg": "{\"channel\":\"order_book:1\",\"offset\":6961847,\"order_book\":{\"code\":0,\"asks\":[{\"price\":\"92842.2\",\"size\":\"0.04348\"}],\"bids\":[],\"offset\":6961847,\"nonce\":3691007822},\"timestamp\":1765394039742,\"type\":\"update/order_book\"}"
    "msg": "{\"channel\":\"order_book:1\",\"offset\":6961848,\"order_book\":{\"code\":0,\"asks\":[],\"bids\":[{\"price\":\"92836.2\",\"size\":\"1.78727\"}],\"offset\":6961848,\"nonce\":3691007828},\"timestamp\":1765394039753,\"type\":\"update/order_book\"}"
    "msg": "{\"channel\":\"order_book:1\",\"offset\":6961849,\"order_book\":{\"code\":0,\"asks\":[],\"bids\":[{\"price\":\"92826.9\",\"size\":\"4.54758\"},{\"price\":\"92825.6\",\"size\":\"0.00000\"}],\"offset\":6961849,\"nonce\":3691007836},\"timestamp\":1765394039764,\"type\":\"update/order_book\"}"
    "msg": "{\"channel\":\"order_book:1\",\"offset\":6961850,\"order_book\":{\"code\":0,\"asks\":[{\"price\":\"92842.2\",\"size\":\"0.06502\"}],\"bids\":[],\"offset\":6961850,\"nonce\":3691007837},\"timestamp\":1765394039766,\"type\":\"update/order_book\"}"
    "msg": "{\"channel\":\"order_book:1\",\"offset\":6961851,\"order_book\":{\"code\":0,\"asks\":[{\"price\":\"92842.2\",\"size\":\"0.05937\"}],\"bids\":[],\"offset\":6961851,\"nonce\":3691007844},\"timestamp\":1765394039802,\"type\":\"update/order_book\"}"
    "msg": "{\"channel\":\"order_book:1\",\"offset\":6961852,\"order_book\":{\"code\":0,\"asks\":[],\"bids\":[{\"price\":\"92836.2\",\"size\":\"0.00000\"},{\"price\":\"92836.1\",\"size\":\"0.38567\"},{\"price\":\"92834.7\",\"size\":\"3.23203\"},{\"price\":\"92829.2\",\"size\":\"1.34059\"}],\"offset\":6961852,\"nonce\":3691007848},\"timestamp\":1765394039810,\"type\":\"update/order_book\"}"
    "msg": "{\"channel\":\"order_book:1\",\"offset\":6961853,\"order_book\":{\"code\":0,\"asks\":[{\"price\":\"92852.5\",\"size\":\"0.00000\"},{\"price\":\"92853.3\",\"size\":\"0.00861\"}],\"bids\":[{\"price\":\"92832.1\",\"size\":\"0.38767\"},{\"price\":\"92827.1\",\"size\":\"0.00000\"},{\"price\":\"92825.2\",\"size\":\"0.00000\"},{\"price\":\"92823.8\",\"size\":\"0.08079\"}],\"offset\":6961853,\"nonce\":3691007850},\"timestamp\":1765394039813,\"type\":\"update/order_book\"}"
    "msg": "{\"channel\":\"order_book:1\",\"offset\":6961854,\"order_book\":{\"code\":0,\"asks\":[{\"price\":\"92845.9\",\"size\":\"0.10780\"},{\"price\":\"92846.9\",\"size\":\"0.00000\"},{\"price\":\"92848.7\",\"size\":\"0.10780\"},{\"price\":\"92848.8\",\"size\":\"0.10780\"},{\"price\":\"92849.9\",\"size\":\"0.00000\"}],\"bids\":[],\"offset\":6961854,\"nonce\":3691007853},\"timestamp\":1765394039817,\"type\":\"update/order_book\"}"
    "msg": "{\"channel\":\"order_book:1\",\"offset\":6961855,\"order_book\":{\"code\":0,\"asks\":[{\"price\":\"92847.3\",\"size\":\"0.10780\"},{\"price\":\"92848.7\",\"size\":\"0.00000\"}],\"bids\":[{\"price\":\"92834.8\",\"size\":\"0.00000\"},{\"price\":\"92834.5\",\"size\":\"0.00861\"},{\"price\":\"92832.8\",\"size\":\"0.00000\"},{\"price\":\"92818.4\",\"size\":\"0.00000\"}],\"offset\":6961855,\"nonce\":3691007855},\"timestamp\":1765394039819,\"type\":\"update/order_book\"}"
    "msg": "{\"channel\":\"order_book:1\",\"offset\":6961856,\"order_book\":{\"code\":0,\"asks\":[{\"price\":\"92842.1\",\"size\":\"0.89454\"},{\"price\":\"92842.2\",\"size\":\"1.01665\"},{\"price\":\"92846.3\",\"size\":\"0.06602\"},{\"price\":\"92850.1\",\"size\":\"0.00000\"},{\"price\":\"92853.2\",\"size\":\"0.00000\"}],\"bids\":[],\"offset\":6961856,\"nonce\":3691007857},\"timestamp\":1765394039827,\"type\":\"update/order_book\"}"
    "msg": "{\"channel\":\"order_book:1\",\"offset\":6961858,\"order_book\":{\"code\":0,\"asks\":[],\"bids\":[{\"price\":\"92836.1\",\"size\":\"0.00000\"}],\"offset\":6961858,\"nonce\":3691007861},\"timestamp\":1765394039839,\"type\":\"update/order_book\"}"
    "msg": "{\"channel\":\"order_book:1\",\"offset\":6961859,\"order_book\":{\"code\":0,\"asks\":[{\"price\":\"92838.0\",\"size\":\"0.00188\"},{\"price\":\"92853.1\",\"size\":\"0.00861\"}],\"bids\":[],\"offset\":6961859,\"nonce\":3691007862},\"timestamp\":1765394039843,\"type\":\"update/order_book\"}"
    "msg": "{\"channel\":\"order_book:1\",\"offset\":6961860,\"order_book\":{\"code\":0,\"asks\":[{\"price\":\"92842.1\",\"size\":\"1.75385\"},{\"price\":\"92850.0\",\"size\":\"0.00000\"}],\"bids\":[{\"price\":\"92832.9\",\"size\":\"0.02905\"}],\"offset\":6961860,\"nonce\":3691007865},\"timestamp\":1765394039851,\"type\":\"update/order_book\"}"
    "msg": "{\"channel\":\"order_book:1\",\"offset\":6961861,\"order_book\":{\"code\":0,\"asks\":[{\"price\":\"92850.0\",\"size\":\"0.02154\"},{\"price\":\"92853.1\",\"size\":\"0.01937\"}],\"bids\":[],\"offset\":6961861,\"nonce\":3691007868},\"timestamp\":1765394039859,\"type\":\"update/order_book\"}"
    "msg": "{\"channel\":\"order_book:1\",\"offset\":6961863,\"order_book\":{\"code\":0,\"asks\":[{\"price\":\"92837.9\",\"size\":\"0.81680\"},{\"price\":\"92838.0\",\"size\":\"0.92047\"}],\"bids\":[],\"offset\":6961863,\"nonce\":3691007872},\"timestamp\":1765394039881,\"type\":\"update/order_book\"}"
    "msg": "{\"channel\":\"order_book:1\",\"offset\":6961864,\"order_book\":{\"code\":0,\"asks\":[{\"price\":\"92838.0\",\"size\":\"0.94201\"},{\"price\":\"92856.4\",\"size\":\"0.00861\"},{\"price\":\"92864.5\",\"size\":\"0.00000\"}],\"bids\":[],\"offset\":6961864,\"nonce\":3691007873},\"timestamp\":1765394039886,\"type\":\"update/order_book\"}"
    "msg": "{\"channel\":\"order_book:1\",\"offset\":6961865,\"order_book\":{\"code\":0,\"asks\":[],\"bids\":[{\"price\":\"92833.9\",\"size\":\"0.00861\"}],\"offset\":6961865,\"nonce\":3691007874},\"timestamp\":1765394039930,\"type\":\"update/order_book\"}"
    "msg": "{\"channel\":\"order_book:1\",\"offset\":6961866,\"order_book\":{\"code\":0,\"asks\":[{\"price\":\"92838.0\",\"size\":\"0.92047\"},{\"price\":\"92843.8\",\"size\":\"2.80176\"},{\"price\":\"92844.2\",\"size\":\"0.10780\"},{\"price\":\"92845.3\",\"size\":\"0.10780\"},{\"price\":\"92845.9\",\"size\":\"0.00000\"},{\"price\":\"92847.3\",\"size\":\"0.00000\"},{\"price\":\"92848.8\",\"size\":\"0.00000\"},{\"price\":\"92866.9\",\"size\":\"0.14392\"}],\"bids\":[{\"price\":\"92834.9\",\"size\":\"0.38767\"},{\"price\":\"92828.4\",\"size\":\"0.10780\"},{\"price\":\"92822.2\",\"size\":\"0.76879\"},{\"price\":\"92813.9\",\"size\":\"0.10780\"}],\"offset\":6961866,\"nonce\":3691007875},\"timestamp\":1765394039944,\"type\":\"update/order_book\"}"
    "msg": "{\"channel\":\"order_book:1\",\"offset\":6961867,\"order_book\":{\"code\":0,\"asks\":[{\"price\":\"92837.9\",\"size\":\"0.00000\"},{\"price\":\"92838.0\",\"size\":\"0.00188\"},{\"price\":\"92843.8\",\"size\":\"2.69396\"},{\"price\":\"92844.2\",\"size\":\"0.00000\"},{\"price\":\"92844.3\",\"size\":\"0.02834\"},{\"price\":\"92845.3\",\"size\":\"0.00000\"},{\"price\":\"92846.3\",\"size\":\"0.03768\"}],\"bids\":[{\"price\":\"92832.9\",\"size\":\"0.00000\"},{\"price\":\"92831.7\",\"size\":\"0.23029\"}],\"offset\":6961867,\"nonce\":3691007876},\"timestamp\":1765394039973,\"type\":\"update/order_book\"}"
    "msg": "{\"channel\":\"order_book:1\",\"offset\":6961869,\"order_book\":{\"code\":0,\"asks\":[],\"bids\":[{\"price\":\"92834.9\",\"size\":\"1.33038\"}],\"offset\":6961869,\"nonce\":3691007878},\"timestamp\":1765394040007,\"type\":\"update/order_book\"}"
    "msg": "{\"channel\":\"order_book:1\",\"offset\":6961870,\"order_book\":{\"code\":0,\"asks\":[{\"price\":\"92842.1\",\"size\":\"0.85931\"}],\"bids\":[{\"price\":\"92831.7\",\"size\":\"0.00000\"},{\"price\":\"92830.8\",\"size\":\"0.02905\"}],\"offset\":6961870,\"nonce\":3691007879},\"timestamp\":1765394040011,\"type\":\"update/order_book\"}"
    "msg": "{\"channel\":\"order_book:1\",\"offset\":6961871,\"order_book\":{\"code\":0,\"asks\":[{\"price\":\"92837.9\",\"size\":\"0.04308\"},{\"price\":\"92842.1\",\"size\":\"0.00000\"}],\"bids\":[],\"offset\":6961871,\"nonce\":3691007880},\"timestamp\":1765394040014,\"type\":\"update/order_book\"}"
    "msg": "{\"channel\":\"order_book:1\",\"offset\":6961872,\"order_book\":{\"code\":0,\"asks\":[{\"price\":\"92846.1\",\"size\":\"0.10780\"},{\"price\":\"92847.2\",\"size\":\"0.10780\"}],\"bids\":[{\"price\":\"92830.4\",\"size\":\"0.10780\"},{\"price\":\"92828.4\",\"size\":\"0.00000\"},{\"price\":\"92824.2\",\"size\":\"0.10780\"},{\"price\":\"92822.2\",\"size\":\"0.66099\"},{\"price\":\"92815.8\",\"size\":\"0.10780\"},{\"price\":\"92813.9\",\"size\":\"0.00000\"}],\"offset\":6961872,\"nonce\":3691007883},\"timestamp\":1765394040020,\"type\":\"update/order_book\"}"
    "msg": "{\"channel\":\"order_book:1\",\"offset\":6961874,\"order_book\":{\"code\":0,\"asks\":[{\"price\":\"92842.2\",\"size\":\"1.00096\"}],\"bids\":[],\"offset\":6961874,\"nonce\":3691007891},\"timestamp\":1765394040039,\"type\":\"update/order_book\"}"
    "msg": "{\"channel\":\"order_book:1\",\"offset\":6961875,\"order_book\":{\"code\":0,\"asks\":[],\"bids\":[{\"price\":\"92829.8\",\"size\":\"0.13464\"},{\"price\":\"92785.5\",\"size\":\"0.00000\"}],\"offset\":6961875,\"nonce\":3691007894},\"timestamp\":1765394040050,\"type\":\"update/order_book\"}"
    "msg": "{\"channel\":\"order_book:1\",\"offset\":6961877,\"order_book\":{\"code\":0,\"asks\":[{\"price\":\"92853.9\",\"size\":\"0.08082\"}],\"bids\":[],\"offset\":6961877,\"nonce\":3691007896},\"timestamp\":1765394040060,\"type\":\"update/order_book\"}"
    "msg": "{\"channel\":\"order_book:1\",\"offset\":6961878,\"order_book\":{\"code\":0,\"asks\":[{\"price\":\"92842.2\",\"size\":\"1.00076\"},{\"price\":\"92842.3\",\"size\":\"0.23695\"},{\"price\":\"92871.3\",\"size\":\"0.08081\"}],\"bids\":[],\"offset\":6961878,\"nonce\":3691007897},\"timestamp\":1765394040064,\"type\":\"update/order_book\"}"
    "msg": "{\"channel\":\"order_book:1\",\"offset\":6961879,\"order_book\":{\"code\":0,\"asks\":[{\"price\":\"92837.9\",\"size\":\"0.08616\"}],\"bids\":[],\"offset\":6961879,\"nonce\":3691007907},\"timestamp\":1765394040086,\"type\":\"update/order_book\"}"
    "msg": "{\"channel\":\"order_book:1\",\"offset\":6961880,\"order_book\":{\"code\":0,\"asks\":[{\"price\":\"92837.9\",\"size\":\"0.06462\"}],\"bids\":[],\"offset\":6961880,\"nonce\":3691007908},\"timestamp\":1765394040090,\"type\":\"update/order_book\"}"
    "msg": "{\"channel\":\"order_book:1\",\"offset\":6961881,\"order_book\":{\"code\":0,\"asks\":[],\"bids\":[{\"price\":\"92835.0\",\"size\":\"0.00000\"},{\"price\":\"92834.9\",\"size\":\"0.38767\"}],\"offset\":6961881,\"nonce\":3691007909},\"timestamp\":1765394040096,\"type\":\"update/order_book\"}"
    "msg": "{\"channel\":\"order_book:1\",\"offset\":6961882,\"order_book\":{\"code\":0,\"asks\":[],\"bids\":[{\"price\":\"92834.7\",\"size\":\"3.23203\"},{\"price\":\"92830.4\",\"size\":\"0.00000\"},{\"price\":\"92824.2\",\"size\":\"0.00000\"}],\"offset\":6961882,\"nonce\":3691007912},\"timestamp\":1765394040100,\"type\":\"update/order_book\"}"
    "msg": "{\"channel\":\"order_book:1\",\"offset\":6961883,\"order_book\":{\"code\":0,\"asks\":[{\"price\":\"92837.9\",\"size\":\"0.04308\"}],\"bids\":[{\"price\":\"92815.8\",\"size\":\"0.00000\"}],\"offset\":6961883,\"nonce\":3691007915},\"timestamp\":1765394040102,\"type\":\"update/order_book\"}"
    "msg": "{\"channel\":\"order_book:1\",\"offset\":6961884,\"order_book\":{\"code\":0,\"asks\":[{\"price\":\"92837.9\",\"size\":\"0.98201\"},{\"price\":\"92842.2\",\"size\":\"1.10856\"},{\"price\":\"92842.5\",\"size\":\"0.10780\"},{\"price\":\"92845.8\",\"size\":\"0.00000\"},{\"price\":\"92846.1\",\"size\":\"0.00000\"}],\"bids\":[{\"price\":\"92821.3\",\"size\":\"0.00000\"},{\"price\":\"92821.2\",\"size\":\"0.00108\"},{\"price\":\"92820.6\",\"size\":\"0.18861\"}],\"offset\":6961884,\"nonce\":3691007920},\"timestamp\":1765394040114,\"type\":\"update/order_book\"}"
    "msg": "{\"channel\":\"order_book:1\",\"offset\":6961885,\"order_book\":{\"code\":0,\"asks\":[{\"price\":\"92843.6\",\"size\":\"0.10780\"},{\"price\":\"92847.2\",\"size\":\"0.00000\"}],\"bids\":[{\"price\":\"92826.8\",\"size\":\"0.18864\"}],\"offset\":6961885,\"nonce\":3691007924},\"timestamp\":1765394040119,\"type\":\"update/order_book\"}"
    "msg": "{\"channel\":\"order_book:1\",\"offset\":6961886,\"order_book\":{\"code\":0,\"asks\":[{\"price\":\"92837.9\",\"size\":\"0.04308\"}],\"bids\":[],\"offset\":6961886,\"nonce\":3691007930},\"timestamp\":1765394040137,\"type\":\"update/order_book\"}"
    "msg": "{\"channel\":\"order_book:1\",\"offset\":6961887,\"order_book\":{\"code\":0,\"asks\":[],\"bids\":[{\"price\":\"92831.5\",\"size\":\"0.00021\"}],\"offset\":6961887,\"nonce\":3691007937},\"timestamp\":1765394040165,\"type\":\"update/order_book\"}"
    "msg": "{\"channel\":\"order_book:1\",\"offset\":6961888,\"order_book\":{\"code\":0,\"asks\":[{\"price\":\"92837.9\",\"size\":\"0.06462\"}],\"bids\":[],\"offset\":6961888,\"nonce\":3691007946},\"timestamp\":1765394040179,\"type\":\"update/order_book\"}"
    "msg": "{\"channel\":\"order_book:1\",\"offset\":6961889,\"order_book\":{\"code\":0,\"asks\":[{\"price\":\"92837.9\",\"size\":\"0.04308\"},{\"price\":\"92842.2\",\"size\":\"0.15128\"},{\"price\":\"92847.6\",\"size\":\"0.00000\"}],\"bids\":[],\"offset\":6961889,\"nonce\":3691007957},\"timestamp\":1765394040197,\"type\":\"update/order_book\"}"
    "msg": "{\"channel\":\"order_book:1\",\"offset\":6961890,\"order_book\":{\"code\":0,\"asks\":[{\"price\":\"92842.2\",\"size\":\"0.04348\"},{\"price\":\"92842.3\",\"size\":\"0.02154\"},{\"price\":\"92842.5\",\"size\":\"0.00000\"},{\"price\":\"92843.6\",\"size\":\"0.00000\"}],\"bids\":[],\"offset\":6961890,\"nonce\":3691007960},\"timestamp\":1765394040202,\"type\":\"update/order_book\"}"
    "msg": "{\"channel\":\"order_book:1\",\"offset\":6961891,\"order_book\":{\"code\":0,\"asks\":[{\"price\":\"92843.8\",\"size\":\"0.00000\"},{\"price\":\"92869.4\",\"size\":\"0.08081\"}],\"bids\":[{\"price\":\"92831.5\",\"size\":\"0.23273\"},{\"price\":\"92815.2\",\"size\":\"0.00000\"},{\"price\":\"92813.3\",\"size\":\"0.00000\"}],\"offset\":6961891,\"nonce\":3691007962},\"timestamp\":1765394040209,\"type\":\"update/order_book\"}"
    "msg": "{\"channel\":\"order_book:1\",\"offset\":6961894,\"order_book\":{\"code\":0,\"asks\":[{\"price\":\"92845.2\",\"size\":\"0.00020\"},{\"price\":\"92850.0\",\"size\":\"0.00000\"},{\"price\":\"92853.1\",\"size\":\"0.00861\"}],\"bids\":[],\"offset\":6961894,\"nonce\":3691007969},\"timestamp\":1765394040232,\"type\":\"update/order_book\"}"
    "msg": "{\"channel\":\"order_book:1\",\"offset\":6961895,\"order_book\":{\"code\":0,\"asks\":[{\"price\":\"92844.3\",\"size\":\"0.00000\"}],\"bids\":[{\"price\":\"92830.8\",\"size\":\"0.00000\"}],\"offset\":6961895,\"nonce\":3691007971},\"timestamp\":1765394040234,\"type\":\"update/order_book\"}"
    "msg": "{\"channel\":\"order_book:1\",\"offset\":6961897,\"order_book\":{\"code\":0,\"asks\":[{\"price\":\"92837.9\",\"size\":\"0.00000\"},{\"price\":\"92838.0\",\"size\":\"0.00000\"},{\"price\":\"92840.8\",\"size\":\"0.00000\"},{\"price\":\"92842.2\",\"size\":\"0.01471\"}],\"bids\":[{\"price\":\"92831.8\",\"size\":\"0.10942\"}],\"offset\":6961897,\"nonce\":3691007975},\"timestamp\":1765394040245,\"type\":\"update/order_book\"}"
    "msg": "{\"channel\":\"order_book:1\",\"offset\":6961898,\"order_book\":{\"code\":0,\"asks\":[],\"bids\":[{\"price\":\"92837.8\",\"size\":\"1.69801\"}],\"offset\":6961898,\"nonce\":3691007979},\"timestamp\":1765394040256,\"type\":\"update/order_book\"}"
    "msg": "{\"channel\":\"order_book:1\",\"offset\":6961899,\"order_book\":{\"code\":0,\"asks\":[{\"price\":\"92845.2\",\"size\":\"0.00000\"},{\"price\":\"92846.1\",\"size\":\"0.38767\"},{\"price\":\"92846.2\",\"size\":\"0.00000\"},{\"price\":\"92846.5\",\"size\":\"0.00000\"}],\"bids\":[],\"offset\":6961899,\"nonce\":3691007981},\"timestamp\":1765394040262,\"type\":\"update/order_book\"}"
    "msg": "{\"channel\":\"order_book:1\",\"offset\":6961900,\"order_book\":{\"code\":0,\"asks\":[{\"price\":\"92846.8\",\"size\":\"0.02834\"},{\"price\":\"92847.1\",\"size\":\"0.00000\"},{\"price\":\"92849.6\",\"size\":\"0.00000\"},{\"price\":\"92851.0\",\"size\":\"2.69396\"},{\"price\":\"92856.4\",\"size\":\"0.00000\"},{\"price\":\"92866.9\",\"size\":\"0.03304\"},{\"price\":\"92873.9\",\"size\":\"0.00000\"},{\"price\":\"92877.1\",\"size\":\"4.59698\"},{\"price\":\"92878.5\",\"size\":\"0.00000\"}],\"bids\":[{\"price\":\"92834.7\",\"size\":\"2.15445\"},{\"price\":\"92827.1\",\"size\":\"4.56299\"},{\"price\":\"92826.9\",\"size\":\"0.00000\"},{\"price\":\"92822.4\",\"size\":\"2.69396\"},{\"price\":\"92821.5\",\"size\":\"0.00108\"},{\"price\":\"92821.2\",\"size\":\"0.00000\"},{\"price\":\"92800.7\",\"size\":\"0.00000\"}],\"offset\":6961900,\"nonce\":3691007982},\"timestamp\":1765394040266,\"type\":\"update/order_book\"}"
    "msg": "{\"channel\":\"order_book:1\",\"offset\":6961901,\"order_book\":{\"code\":0,\"asks\":[{\"price\":\"92842.2\",\"size\":\"0.00000\"}],\"bids\":[{\"price\":\"92838.2\",\"size\":\"0.38767\"},{\"price\":\"92835.0\",\"size\":\"0.02905\"},{\"price\":\"92831.8\",\"size\":\"0.10780\"},{\"price\":\"92802.4\",\"size\":\"0.01078\"},{\"price\":\"92799.1\",\"size\":\"0.00000\"},{\"price\":\"92798.7\",\"size\":\"0.00000\"},{\"price\":\"92710.1\",\"size\":\"0.00000\"}],\"offset\":6961901,\"nonce\":3691007983},\"timestamp\":1765394040269,\"type\":\"update/order_book\"}"
    "msg": "{\"channel\":\"order_book:1\",\"offset\":6961902,\"order_book\":{\"code\":0,\"asks\":[{\"price\":\"92850.0\",\"size\":\"0.00000\"},{\"price\":\"92853.2\",\"size\":\"0.00000\"},{\"price\":\"92854.4\",\"size\":\"0.00000\"},{\"price\":\"92872.3\",\"size\":\"0.00000\"}],\"bids\":[{\"price\":\"92832.4\",\"size\":\"0.00000\"},{\"price\":\"92818.9\",\"size\":\"0.00000\"},{\"price\":\"92808.5\",\"size\":\"0.11629\"}],\"offset\":6961902,\"nonce\":3691007985},\"timestamp\":1765394040275,\"type\":\"update/order_book\"}"
    "msg": "{\"channel\":\"order_book:1\",\"offset\":6961903,\"order_book\":{\"code\":0,\"asks\":[{\"price\":\"92842.2\",\"size\":\"0.02154\"},{\"price\":\"92853.1\",\"size\":\"0.00000\"},{\"price\":\"92853.3\",\"size\":\"0.00000\"}],\"bids\":[{\"price\":\"92836.8\",\"size\":\"0.02905\"},{\"price\":\"92825.0\",\"size\":\"0.00000\"}],\"offset\":6961903,\"nonce\":3691007987},\"timestamp\":1765394040279,\"type\":\"update/order_book\"}"
    "msg": "{\"channel\":\"order_book:1\",\"offset\":6961904,\"order_book\":{\"code\":0,\"asks\":[{\"price\":\"92852.1\",\"size\":\"0.02153\"},{\"price\":\"92856.8\",\"size\":\"0.02153\"},{\"price\":\"92868.3\",\"size\":\"0.00000\"}],\"bids\":[{\"price\":\"92835.0\",\"size\":\"0.00000\"}],\"offset\":6961904,\"nonce\":3691007988},\"timestamp\":1765394040285,\"type\":\"update/order_book\"}"
    "msg": "{\"channel\":\"order_book:1\",\"offset\":6961905,\"order_book\":{\"code\":0,\"asks\":[{\"price\":\"92848.0\",\"size\":\"0.00020\"},{\"price\":\"92851.6\",\"size\":\"0.00000\"},{\"price\":\"92855.2\",\"size\":\"0.01076\"}],\"bids\":[{\"price\":\"92838.2\",\"size\":\"1.21611\"},{\"price\":\"92830.6\",\"size\":\"0.02906\"},{\"price\":\"92808.3\",\"size\":\"0.00000\"}],\"offset\":6961905,\"nonce\":3691007990},\"timestamp\":1765394040289,\"type\":\"update/order_book\"}"
    "msg": "{\"channel\":\"order_book:1\",\"offset\":6961906,\"order_book\":{\"code\":0,\"asks\":[{\"price\":\"92846.8\",\"size\":\"0.00000\"},{\"price\":\"92849.5\",\"size\":\"0.38767\"},{\"price\":\"92852.1\",\"size\":\"0.00000\"},{\"price\":\"92856.8\",\"size\":\"0.00000\"}],\"bids\":[{\"price\":\"92838.2\",\"size\":\"1.21000\"},{\"price\":\"92836.8\",\"size\":\"0.00000\"},{\"price\":\"92820.9\",\"size\":\"0.02628\"}],\"offset\":6961906,\"nonce\":3691007993},\"timestamp\":1765394040294,\"type\":\"update/order_book\"}"
    "msg": "{\"channel\":\"order_book:1\",\"offset\":6961907,\"order_book\":{\"code\":0,\"asks\":[{\"price\":\"92842.2\",\"size\":\"0.01654\"},{\"price\":\"92855.2\",\"size\":\"0.00000\"},{\"price\":\"92874.1\",\"size\":\"0.00309\"}],\"bids\":[{\"price\":\"92837.8\",\"size\":\"1.72706\"}],\"offset\":6961907,\"nonce\":3691007994},\"timestamp\":1765394040297,\"type\":\"update/order_book\"}"
    "msg": "{\"channel\":\"order_book:1\",\"offset\":6961909,\"order_book\":{\"code\":0,\"asks\":[{\"price\":\"92855.2\",\"size\":\"0.01076\"}],\"bids\":[],\"offset\":6961909,\"nonce\":3691007999},\"timestamp\":1765394040309,\"type\":\"update/order_book\"}"
    "msg": "{\"channel\":\"order_book:1\",\"offset\":6961910,\"order_book\":{\"code\":0,\"asks\":[{\"price\":\"92847.6\",\"size\":\"0.10780\"},{\"price\":\"92848.0\",\"size\":\"0.21540\"},{\"price\":\"92867.3\",\"size\":\"0.11088\"}],\"bids\":[],\"offset\":6961910,\"nonce\":3691008002},\"timestamp\":1765394040316,\"type\":\"update/order_book\"}"
    "msg": "{\"channel\":\"order_book:1\",\"offset\":6961911,\"order_book\":{\"code\":0,\"asks\":[{\"price\":\"92848.4\",\"size\":\"0.10780\"},{\"price\":\"92848.9\",\"size\":\"1.07758\"},{\"price\":\"92851.1\",\"size\":\"0.02834\"},{\"price\":\"92858.2\",\"size\":\"0.02465\"},{\"price\":\"92878.2\",\"size\":\"0.12233\"}],\"bids\":[{\"price\":\"92832.8\",\"size\":\"0.10780\"},{\"price\":\"92831.8\",\"size\":\"0.00000\"}],\"offset\":6961911,\"nonce\":3691008003},\"timestamp\":1765394040317,\"type\":\"update/order_book\"}"
    "msg": "{\"channel\":\"order_book:1\",\"offset\":6961912,\"order_book\":{\"code\":0,\"asks\":[],\"bids\":[{\"price\":\"92821.5\",\"size\":\"0.00000\"},{\"price\":\"92820.2\",\"size\":\"0.00108\"}],\"offset\":6961912,\"nonce\":3691008005},\"timestamp\":1765394040320,\"type\":\"update/order_book\"}"
    "msg": "{\"channel\":\"order_book:1\",\"offset\":6961913,\"order_book\":{\"code\":0,\"asks\":[{\"price\":\"92842.2\",\"size\":\"0.00000\"},{\"price\":\"92849.6\",\"size\":\"0.10780\"},{\"price\":\"92886.7\",\"size\":\"0.10778\"}],\"bids\":[{\"price\":\"92839.6\",\"size\":\"1.07758\"},{\"price\":\"92838.3\",\"size\":\"0.81950\"},{\"price\":\"92827.1\",\"size\":\"0.00000\"},{\"price\":\"92825.8\",\"size\":\"4.56494\"}],\"offset\":6961913,\"nonce\":3691008006},\"timestamp\":1765394040327,\"type\":\"update/order_book\"}"
    "msg": "{\"channel\":\"order_book:1\",\"offset\":6961914,\"order_book\":{\"code\":0,\"asks\":[{\"price\":\"92877.0\",\"size\":\"4.59698\"},{\"price\":\"92877.1\",\"size\":\"0.00000\"}],\"bids\":[{\"price\":\"92818.4\",\"size\":\"0.10780\"},{\"price\":\"92817.1\",\"size\":\"0.38767\"},{\"price\":\"92722.0\",\"size\":\"8.07918\"}],\"offset\":6961914,\"nonce\":3691008008},\"timestamp\":1765394040327,\"type\":\"update/order_book\"}"
    "msg": "{\"channel\":\"order_book:1\",\"offset\":6961915,\"order_book\":{\"code\":0,\"asks\":[{\"price\":\"92851.1\",\"size\":\"0.00000\"}],\"bids\":[{\"price\":\"92838.3\",\"size\":\"0.84855\"},{\"price\":\"92837.8\",\"size\":\"1.69801\"}],\"offset\":6961915,\"nonce\":3691008016},\"timestamp\":1765394040344,\"type\":\"update/order_book\"}"
    "msg": "{\"channel\":\"order_book:1\",\"offset\":6961916,\"order_book\":{\"code\":0,\"asks\":[{\"price\":\"92865.7\",\"size\":\"0.08081\"}],\"bids\":[],\"offset\":6961916,\"nonce\":3691008018},\"timestamp\":1765394040349,\"type\":\"update/order_book\"}"
    "msg": "{\"channel\":\"order_book:1\",\"offset\":6961917,\"order_book\":{\"code\":0,\"asks\":[],\"bids\":[{\"price\":\"92839.6\",\"size\":\"1.91583\"}],\"offset\":6961917,\"nonce\":3691008022},\"timestamp\":1765394040354,\"type\":\"update/order_book\"}"
    "msg": "{\"channel\":\"order_book:1\",\"offset\":6961918,\"order_book\":{\"code\":0,\"asks\":[],\"bids\":[{\"price\":\"92839.6\",\"size\":\"1.07758\"},{\"price\":\"92838.2\",\"size\":\"0.38156\"}],\"offset\":6961918,\"nonce\":3691008032},\"timestamp\":1765394040373,\"type\":\"update/order_book\"}"
    "msg": "{\"channel\":\"order_book:1\",\"offset\":6961919,\"order_book\":{\"code\":0,\"asks\":[],\"bids\":[{\"price\":\"92825.3\",\"size\":\"0.00000\"},{\"price\":\"92824.3\",\"size\":\"0.10780\"}],\"offset\":6961919,\"nonce\":3691008036},\"timestamp\":1765394040378,\"type\":\"update/order_book\"}"
    "msg": "{\"channel\":\"order_book:1\",\"offset\":6961920,\"order_book\":{\"code\":0,\"asks\":[],\"bids\":[{\"price\":\"92838.3\",\"size\":\"0.02905\"},{\"price\":\"92837.8\",\"size\":\"0.00000\"}],\"offset\":6961920,\"nonce\":3691008037},\"timestamp\":1765394040384,\"type\":\"update/order_book\"}"
    "msg": "{\"channel\":\"order_book:1\",\"offset\":6961922,\"order_book\":{\"code\":0,\"asks\":[{\"price\":\"92842.3\",\"size\":\"0.88843\"}],\"bids\":[],\"offset\":6961922,\"nonce\":3691008050},\"timestamp\":1765394040406,\"type\":\"update/order_book\"}"
    "msg": "{\"channel\":\"order_book:1\",\"offset\":6961923,\"order_book\":{\"code\":0,\"asks\":[{\"price\":\"92842.3\",\"size\":\"0.02154\"},{\"price\":\"92846.1\",\"size\":\"0.10780\"},{\"price\":\"92846.6\",\"size\":\"0.10780\"},{\"price\":\"92847.6\",\"size\":\"0.00000\"},{\"price\":\"92847.7\",\"size\":\"0.10780\"},{\"price\":\"92848.0\",\"size\":\"0.00000\"},{\"price\":\"92848.4\",\"size\":\"0.00000\"},{\"price\":\"92849.5\",\"size\":\"0.00000\"},{\"price\":\"92849.6\",\"size\":\"0.00000\"}],\"bids\":[{\"price\":\"92832.8\",\"size\":\"0.00000\"},{\"price\":\"92818.4\",\"size\":\"0.00000\"},{\"price\":\"92816.3\",\"size\":\"0.15112\"}],\"offset\":6961923,\"nonce\":3691008056},\"timestamp\":1765394040430,\"type\":\"update/order_book\"}"
    "msg": "{\"channel\":\"order_book:1\",\"offset\":6961924,\"order_book\":{\"code\":0,\"asks\":[{\"price\":\"92846.6\",\"size\":\"0.00000\"},{\"price\":\"92847.7\",\"size\":\"0.00000\"}],\"bids\":[{\"price\":\"92842.2\",\"size\":\"0.97130\"},{\"price\":\"92839.6\",\"size\":\"1.96396\"},{\"price\":\"92830.9\",\"size\":\"0.10780\"},{\"price\":\"92820.2\",\"size\":\"0.00000\"},{\"price\":\"92819.1\",\"size\":\"0.00108\"}],\"offset\":6961924,\"nonce\":3691008057},\"timestamp\":1765394040433,\"type\":\"update/order_book\"}"
    "msg": "{\"channel\":\"order_book:1\",\"offset\":6961925,\"order_book\":{\"code\":0,\"asks\":[{\"price\":\"92846.1\",\"size\":\"0.00000\"},{\"price\":\"92852.1\",\"size\":\"0.00000\"},{\"price\":\"92852.2\",\"size\":\"0.00000\"},{\"price\":\"92855.2\",\"size\":\"0.00000\"}],\"bids\":[{\"price\":\"92821.3\",\"size\":\"0.08000\"}],\"offset\":6961925,\"nonce\":3691008060},\"timestamp\":1765394040439,\"type\":\"update/order_book\"}"
    "msg": "{\"channel\":\"order_book:1\",\"offset\":6961926,\"order_book\":{\"code\":0,\"asks\":[],\"bids\":[{\"price\":\"92842.2\",\"size\":\"0.98649\"}],\"offset\":6961926,\"nonce\":3691008062},\"timestamp\":1765394040443,\"type\":\"update/order_book\"}"
    "msg": "{\"channel\":\"order_book:1\",\"offset\":6961928,\"order_book\":{\"code\":0,\"asks\":[{\"price\":\"92852.2\",\"size\":\"0.02153\"},{\"price\":\"92854.8\",\"size\":\"0.00000\"},{\"price\":\"92887.4\",\"size\":\"2.16068\"}],\"bids\":[{\"price\":\"92842.2\",\"size\":\"1.00849\"},{\"price\":\"92823.2\",\"size\":\"0.00000\"}],\"offset\":6961928,\"nonce\":3691008065},\"timestamp\":1765394040450,\"type\":\"update/order_book\"}"
    "msg": "{\"channel\":\"order_book:1\",\"offset\":6961929,\"order_book\":{\"code\":0,\"asks\":[{\"price\":\"92842.3\",\"size\":\"0.02120\"}],\"bids\":[],\"offset\":6961929,\"nonce\":3691008066},\"timestamp\":1765394040451,\"type\":\"update/order_book\"}"
    "msg": "{\"channel\":\"order_book:1\",\"offset\":6961930,\"order_book\":{\"code\":0,\"asks\":[{\"price\":\"92855.3\",\"size\":\"0.01076\"}],\"bids\":[],\"offset\":6961930,\"nonce\":3691008067},\"timestamp\":1765394040454,\"type\":\"update/order_book\"}"
    "msg": "{\"channel\":\"order_book:1\",\"offset\":6961931,\"order_book\":{\"code\":0,\"asks\":[{\"price\":\"92852.2\",\"size\":\"0.00000\"}],\"bids\":[{\"price\":\"92842.2\",\"size\":\"1.82826\"}],\"offset\":6961931,\"nonce\":3691008070},\"timestamp\":1765394040459,\"type\":\"update/order_book\"}"
    "msg": "{\"channel\":\"order_book:1\",\"offset\":6961932,\"order_book\":{\"code\":0,\"asks\":[{\"price\":\"92855.3\",\"size\":\"0.00000\"}],\"bids\":[{\"price\":\"92842.2\",\"size\":\"1.83326\"}],\"offset\":6961932,\"nonce\":3691008072},\"timestamp\":1765394040466,\"type\":\"update/order_book\"}"
    "msg": "{\"channel\":\"order_book:1\",\"offset\":6961933,\"order_book\":{\"code\":0,\"asks\":[],\"bids\":[{\"price\":\"92842.2\",\"size\":\"1.83826\"}],\"offset\":6961933,\"nonce\":3691008075},\"timestamp\":1765394040471,\"type\":\"update/order_book\"}"
    "msg": "{\"channel\":\"order_book:1\",\"offset\":6961934,\"order_book\":{\"code\":0,\"asks\":[{\"price\":\"92852.2\",\"size\":\"0.02153\"}],\"bids\":[{\"price\":\"92830.7\",\"size\":\"0.10780\"},{\"price\":\"92824.3\",\"size\":\"0.00000\"}],\"offset\":6961934,\"nonce\":3691008076},\"timestamp\":1765394040477,\"type\":\"update/order_book\"}"
    "msg": "{\"channel\":\"order_book:1\",\"offset\":6961935,\"order_book\":{\"code\":0,\"asks\":[{\"price\":\"92842.3\",\"size\":\"0.06428\"},{\"price\":\"92855.4\",\"size\":\"0.01076\"}],\"bids\":[],\"offset\":6961935,\"nonce\":3691008078},\"timestamp\":1765394040481,\"type\":\"update/order_book\"}"
    "msg": "{\"channel\":\"order_book:1\",\"offset\":6961936,\"order_book\":{\"code\":0,\"asks\":[{\"price\":\"92848.9\",\"size\":\"0.00000\"},{\"price\":\"92877.0\",\"size\":\"0.00000\"},{\"price\":\"92877.2\",\"size\":\"4.59696\"}],\"bids\":[{\"price\":\"92828.4\",\"size\":\"4.56973\"},{\"price\":\"92825.8\",\"size\":\"0.00000\"}],\"offset\":6961936,\"nonce\":3691008086},\"timestamp\":1765394040493,\"type\":\"update/order_book\"}"
    "msg": "{\"channel\":\"order_book:1\",\"offset\":6961937,\"order_book\":{\"code\":0,\"asks\":[{\"price\":\"92854.6\",\"size\":\"0.26354\"}],\"bids\":[],\"offset\":6961937,\"nonce\":3691008087},\"timestamp\":1765394040496,\"type\":\"update/order_book\"}"
    "msg": "{\"channel\":\"order_book:1\",\"offset\":6961938,\"order_book\":{\"code\":0,\"asks\":[{\"price\":\"92851.0\",\"size\":\"0.00000\"},{\"price\":\"92864.7\",\"size\":\"0.00000\"},{\"price\":\"92921.2\",\"size\":\"0.00000\"}],\"bids\":[{\"price\":\"92826.8\",\"size\":\"0.00000\"},{\"price\":\"92823.6\",\"size\":\"0.00000\"},{\"price\":\"92822.4\",\"size\":\"0.00000\"}],\"offset\":6961938,\"nonce\":3691008088},\"timestamp\":1765394040499,\"type\":\"update/order_book\"}"
    "msg": "{\"channel\":\"order_book:1\",\"offset\":6961939,\"order_book\":{\"code\":0,\"asks\":[],\"bids\":[{\"price\":\"92823.8\",\"size\":\"0.00000\"},{\"price\":\"92820.6\",\"size\":\"0.00000\"},{\"price\":\"92820.1\",\"size\":\"0.00000\"},{\"price\":\"92819.4\",\"size\":\"0.00108\"},{\"price\":\"92819.1\",\"size\":\"0.00000\"}],\"offset\":6961939,\"nonce\":3691008090},\"timestamp\":1765394040504,\"type\":\"update/order_book\"}"
    "msg": "{\"channel\":\"order_book:1\",\"offset\":6961940,\"order_book\":{\"code\":0,\"asks\":[{\"price\":\"92901.6\",\"size\":\"0.00000\"},{\"price\":\"93108.6\",\"size\":\"14.96250\"}],\"bids\":[{\"price\":\"92835.5\",\"size\":\"0.08083\"}],\"offset\":6961940,\"nonce\":3691008093},\"timestamp\":1765394040507,\"type\":\"update/order_book\"}"
    "msg": "{\"channel\":\"order_book:1\",\"offset\":6961941,\"order_book\":{\"code\":0,\"asks\":[{\"price\":\"92852.2\",\"size\":\"0.00000\"},{\"price\":\"92855.4\",\"size\":\"0.00000\"},{\"price\":\"92858.1\",\"size\":\"0.08084\"},{\"price\":\"92860.6\",\"size\":\"0.46850\"},{\"price\":\"92867.3\",\"size\":\"0.00000\"},{\"price\":\"92867.4\",\"size\":\"0.00000\"},{\"price\":\"92877.2\",\"size\":\"0.00000\"},{\"price\":\"92878.9\",\"size\":\"4.59688\"},{\"price\":\"92915.4\",\"size\":\"0.00000\"},{\"price\":\"93122.4\",\"size\":\"14.96250\"}],\"bids\":[{\"price\":\"92836.5\",\"size\":\"0.00000\"},{\"price\":\"92802.4\",\"size\":\"0.00000\"}],\"offset\":6961941,\"nonce\":3691008094},\"timestamp\":1765394040510,\"type\":\"update/order_book\"}"
    "msg": "{\"channel\":\"order_book:1\",\"offset\":6961942,\"order_book\":{\"code\":0,\"asks\":[],\"bids\":[{\"price\":\"92828.4\",\"size\":\"4.57042\"}],\"offset\":6961942,\"nonce\":3691008095},\"timestamp\":1765394040512,\"type\":\"update/order_book\"}"
    "msg": "{\"channel\":\"order_book:1\",\"offset\":6961943,\"order_book\":{\"code\":0,\"asks\":[{\"price\":\"92854.6\",\"size\":\"0.00000\"}],\"bids\":[],\"offset\":6961943,\"nonce\":3691008096},\"timestamp\":1765394040514,\"type\":\"update/order_book\"}"
    "msg": "{\"channel\":\"order_book:1\",\"offset\":6961944,\"order_book\":{\"code\":0,\"asks\":[{\"price\":\"92854.3\",\"size\":\"0.10780\"},{\"price\":\"92855.5\",\"size\":\"0.01076\"}],\"bids\":[{\"price\":\"92839.2\",\"size\":\"0.10780\"},{\"price\":\"92830.9\",\"size\":\"0.00000\"},{\"price\":\"92822.4\",\"size\":\"0.00108\"},{\"price\":\"92819.4\",\"size\":\"0.00000\"},{\"price\":\"92803.6\",\"size\":\"0.01078\"}],\"offset\":6961944,\"nonce\":3691008099},\"timestamp\":1765394040521,\"type\":\"update/order_book\"}"
    "msg": "{\"channel\":\"order_book:1\",\"offset\":6961945,\"order_book\":{\"code\":0,\"asks\":[{\"price\":\"92852.3\",\"size\":\"0.02153\"},{\"price\":\"92854.7\",\"size\":\"0.10780\"},{\"price\":\"92874.1\",\"size\":\"0.00000\"}],\"bids\":[],\"offset\":6961945,\"nonce\":3691008100},\"timestamp\":1765394040525,\"type\":\"update/order_book\"}"
    "msg": "{\"channel\":\"order_book:1\",\"offset\":6961946,\"order_book\":{\"code\":0,\"asks\":[{\"price\":\"92852.3\",\"size\":\"0.00000\"},{\"price\":\"92852.4\",\"size\":\"0.00000\"},{\"price\":\"92855.5\",\"size\":\"0.00000\"},{\"price\":\"92861.9\",\"size\":\"0.00000\"},{\"price\":\"92865.7\",\"size\":\"0.00000\"},{\"price\":\"92880.3\",\"size\":\"0.00000\"}],\"bids\":[{\"price\":\"92824.4\",\"size\":\"0.10780\"},{\"price\":\"92823.3\",\"size\":\"0.00000\"},{\"price\":\"92816.3\",\"size\":\"0.04332\"}],\"offset\":6961946,\"nonce\":3691008102},\"timestamp\":1765394040544,\"type\":\"update/order_book\"}"
    "msg": "{\"channel\":\"order_book:1\",\"offset\":6961947,\"order_book\":{\"code\":0,\"asks\":[{\"price\":\"92852.7\",\"size\":\"0.00000\"},{\"price\":\"92853.3\",\"size\":\"0.02153\"},{\"price\":\"92856.4\",\"size\":\"0.01076\"},{\"price\":\"92857.7\",\"size\":\"1.07758\"},{\"price\":\"92878.2\",\"size\":\"0.51000\"}],\"bids\":[{\"price\":\"92842.2\",\"size\":\"1.80307\"},{\"price\":\"92839.8\",\"size\":\"0.00215\"},{\"price\":\"92838.3\",\"size\":\"0.00000\"},{\"price\":\"92821.0\",\"size\":\"0.05386\"},{\"price\":\"92799.6\",\"size\":\"0.11759\"},{\"price\":\"92785.6\",\"size\":\"0.00000\"}],\"offset\":6961947,\"nonce\":3691008105},\"timestamp\":1765394040545,\"type\":\"update/order_book\"}"
    "msg": "{\"channel\":\"order_book:1\",\"offset\":6961948,\"order_book\":{\"code\":0,\"asks\":[{\"price\":\"92857.5\",\"size\":\"0.00000\"},{\"price\":\"92858.2\",\"size\":\"0.00000\"},{\"price\":\"92861.3\",\"size\":\"0.00000\"},{\"price\":\"92875.7\",\"size\":\"0.00309\"}],\"bids\":[{\"price\":\"92842.2\",\"size\":\"1.83012\"},{\"price\":\"92830.6\",\"size\":\"0.00000\"},{\"price\":\"92830.4\",\"size\":\"0.02815\"},{\"price\":\"92827.4\",\"size\":\"0.11979\"}],\"offset\":6961948,\"nonce\":3691008107},\"timestamp\":1765394040554,\"type\":\"update/order_book\"}"
    "msg": "{\"channel\":\"order_book:1\",\"offset\":6961949,\"order_book\":{\"code\":0,\"asks\":[{\"price\":\"92853.3\",\"size\":\"0.00000\"},{\"price\":\"92876.6\",\"size\":\"0.00000\"}],\"bids\":[{\"price\":\"92840.6\",\"size\":\"0.08084\"},{\"price\":\"92837.3\",\"size\":\"0.02906\"},{\"price\":\"92830.4\",\"size\":\"2.72211\"}],\"offset\":6961949,\"nonce\":3691008108},\"timestamp\":1765394040555,\"type\":\"update/order_book\"}"
    "msg": "{\"channel\":\"order_book:1\",\"offset\":6961950,\"order_book\":{\"code\":0,\"asks\":[{\"price\":\"92856.4\",\"size\":\"0.00000\"}],\"bids\":[{\"price\":\"92839.1\",\"size\":\"0.08079\"},{\"price\":\"92837.1\",\"size\":\"0.08072\"}],\"offset\":6961950,\"nonce\":3691008111},\"timestamp\":1765394040558,\"type\":\"update/order_book\"}"
    "msg": "{\"channel\":\"order_book:1\",\"offset\":6961951,\"order_book\":{\"code\":0,\"asks\":[{\"price\":\"92853.9\",\"size\":\"0.00000\"},{\"price\":\"92856.0\",\"size\":\"0.10780\"},{\"price\":\"92859.1\",\"size\":\"2.69396\"},{\"price\":\"92877.3\",\"size\":\"2.15445\"},{\"price\":\"92965.4\",\"size\":\"8.07918\"}],\"bids\":[{\"price\":\"92842.2\",\"size\":\"1.82512\"},{\"price\":\"92835.9\",\"size\":\"0.08081\"},{\"price\":\"92835.4\",\"size\":\"0.08081\"},{\"price\":\"92829.3\",\"size\":\"0.11088\"}],\"offset\":6961951,\"nonce\":3691008112},\"timestamp\":1765394040563,\"type\":\"update/order_book\"}"
    "msg": "{\"channel\":\"order_book:1\",\"offset\":6961952,\"order_book\":{\"code\":0,\"asks\":[{\"price\":\"92853.3\",\"size\":\"0.02153\"},{\"price\":\"92855.9\",\"size\":\"0.00000\"},{\"price\":\"92869.4\",\"size\":\"0.00000\"}],\"bids\":[],\"offset\":6961952,\"nonce\":3691008113},\"timestamp\":1765394040568,\"type\":\"update/order_book\"}"
    "msg": "{\"channel\":\"order_book:1\",\"offset\":6961953,\"order_book\":{\"code\":0,\"asks\":[{\"price\":\"92864.6\",\"size\":\"0.39558\"}],\"bids\":[],\"offset\":6961953,\"nonce\":3691008115},\"timestamp\":1765394040570,\"type\":\"update/order_book\"}"
    "msg": "{\"channel\":\"order_book:1\",\"offset\":6961954,\"order_book\":{\"code\":0,\"asks\":[{\"price\":\"92856.5\",\"size\":\"0.06460\"},{\"price\":\"92871.3\",\"size\":\"0.00000\"},{\"price\":\"92897.9\",\"size\":\"0.11419\"}],\"bids\":[{\"price\":\"92842.2\",\"size\":\"1.82012\"},{\"price\":\"92832.7\",\"size\":\"0.10780\"},{\"price\":\"92830.7\",\"size\":\"0.00000\"}],\"offset\":6961954,\"nonce\":3691008116},\"timestamp\":1765394040576,\"type\":\"update/order_book\"}"
    "msg": "{\"channel\":\"order_book:1\",\"offset\":6961955,\"order_book\":{\"code\":0,\"asks\":[{\"price\":\"92870.1\",\"size\":\"0.17159\"},{\"price\":\"92965.4\",\"size\":\"0.00000\"}],\"bids\":[],\"offset\":6961955,\"nonce\":3691008118},\"timestamp\":1765394040580,\"type\":\"update/order_book\"}"
    "msg": "{\"channel\":\"order_book:1\",\"offset\":6961956,\"order_book\":{\"code\":0,\"asks\":[{\"price\":\"92878.1\",\"size\":\"0.11088\"},{\"price\":\"92896.4\",\"size\":\"0.00000\"}],\"bids\":[{\"price\":\"92822.4\",\"size\":\"0.00000\"},{\"price\":\"92819.4\",\"size\":\"0.00108\"}],\"offset\":6961956,\"nonce\":3691008120},\"timestamp\":1765394040582,\"type\":\"update/order_book\"}"
    "msg": "{\"channel\":\"order_book:1\",\"offset\":6961957,\"order_book\":{\"code\":0,\"asks\":[],\"bids\":[{\"price\":\"92828.4\",\"size\":\"0.00000\"},{\"price\":\"92825.1\",\"size\":\"4.57279\"}],\"offset\":6961957,\"nonce\":3691008121},\"timestamp\":1765394040584,\"type\":\"update/order_book\"}"
    "msg": "{\"channel\":\"order_book:1\",\"offset\":6961958,\"order_book\":{\"code\":0,\"asks\":[{\"price\":\"92842.3\",\"size\":\"0.04308\"},{\"price\":\"92856.9\",\"size\":\"0.02834\"}],\"bids\":[],\"offset\":6961958,\"nonce\":3691008125},\"timestamp\":1765394040593,\"type\":\"update/order_book\"}"
    "msg": "{\"channel\":\"order_book:1\",\"offset\":6961959,\"order_book\":{\"code\":0,\"asks\":[{\"price\":\"92875.6\",\"size\":\"0.00150\"}],\"bids\":[{\"price\":\"92803.6\",\"size\":\"0.00000\"}],\"offset\":6961959,\"nonce\":3691008127},\"timestamp\":1765394040596,\"type\":\"update/order_book\"}"
    "msg": "{\"channel\":\"order_book:1\",\"offset\":6961960,\"order_book\":{\"code\":0,\"asks\":[{\"price\":\"92863.9\",\"size\":\"0.41232\"}],\"bids\":[],\"offset\":6961960,\"nonce\":3691008129},\"timestamp\":1765394040598,\"type\":\"update/order_book\"}"
    "msg": "{\"channel\":\"order_book:1\",\"offset\":6961961,\"order_book\":{\"code\":0,\"asks\":[{\"price\":\"92856.5\",\"size\":\"0.05384\"},{\"price\":\"92856.9\",\"size\":\"0.00000\"},{\"price\":\"92878.1\",\"size\":\"0.00000\"},{\"price\":\"92878.9\",\"size\":\"0.00000\"},{\"price\":\"92883.4\",\"size\":\"4.59665\"}],\"bids\":[{\"price\":\"92839.8\",\"size\":\"0.00000\"},{\"price\":\"92825.1\",\"size\":\"4.57325\"},{\"price\":\"92822.1\",\"size\":\"0.00500\"},{\"price\":\"92811.6\",\"size\":\"0.00000\"},{\"price\":\"92804.6\",\"size\":\"0.01078\"}],\"offset\":6961961,\"nonce\":3691008131},\"timestamp\":1765394040604,\"type\":\"update/order_book\"}"
    "msg": "{\"channel\":\"order_book:1\",\"offset\":6961962,\"order_book\":{\"code\":0,\"asks\":[{\"price\":\"92853.3\",\"size\":\"0.00000\"},{\"price\":\"92856.5\",\"size\":\"0.00000\"}],\"bids\":[{\"price\":\"92821.0\",\"size\":\"0.00000\"}],\"offset\":6961962,\"nonce\":3691008135},\"timestamp\":1765394040610,\"type\":\"update/order_book\"}"
    "msg": "{\"channel\":\"order_book:1\",\"offset\":6961963,\"order_book\":{\"code\":0,\"asks\":[{\"price\":\"92842.3\",\"size\":\"0.02154\"},{\"price\":\"92857.2\",\"size\":\"0.01076\"},{\"price\":\"92875.7\",\"size\":\"0.00000\"}],\"bids\":[{\"price\":\"92842.2\",\"size\":\"1.84918\"},{\"price\":\"92837.3\",\"size\":\"0.00000\"},{\"price\":\"92831.9\",\"size\":\"0.00000\"},{\"price\":\"92804.6\",\"size\":\"0.00000\"}],\"offset\":6961963,\"nonce\":3691008136},\"timestamp\":1765394040615,\"type\":\"update/order_book\"}"
    "msg": "{\"channel\":\"order_book:1\",\"offset\":6961964,\"order_book\":{\"code\":0,\"asks\":[{\"price\":\"92846.3\",\"size\":\"0.00000\"},{\"price\":\"92854.0\",\"size\":\"0.02153\"},{\"price\":\"92854.3\",\"size\":\"0.00000\"},{\"price\":\"92856.0\",\"size\":\"0.00000\"},{\"price\":\"92856.5\",\"size\":\"0.10780\"},{\"price\":\"92858.2\",\"size\":\"0.10780\"},{\"price\":\"92860.1\",\"size\":\"0.02153\"}],\"bids\":[{\"price\":\"92841.3\",\"size\":\"0.10780\"},{\"price\":\"92839.2\",\"size\":\"0.00000\"},{\"price\":\"92826.1\",\"size\":\"0.10780\"},{\"price\":\"92824.4\",\"size\":\"0.00000\"},{\"price\":\"92806.0\",\"size\":\"0.01078\"}],\"offset\":6961964,\"nonce\":3691008138},\"timestamp\":1765394040626,\"type\":\"update/order_book\"}"
    "msg": "{\"channel\":\"order_book:1\",\"offset\":6961965,\"order_book\":{\"code\":0,\"asks\":[{\"price\":\"92854.7\",\"size\":\"0.00000\"},{\"price\":\"92856.5\",\"size\":\"0.21560\"},{\"price\":\"92857.2\",\"size\":\"0.00000\"},{\"price\":\"92858.9\",\"size\":\"0.02834\"},{\"price\":\"92860.1\",\"size\":\"0.00000\"}],\"bids\":[],\"offset\":6961965,\"nonce\":3691008140},\"timestamp\":1765394040632,\"type\":\"update/order_book\"}"
    "msg": "{\"channel\":\"order_book:1\",\"offset\":6961966,\"order_book\":{\"code\":0,\"asks\":[{\"price\":\"92842.3\",\"size\":\"0.00000\"},{\"price\":\"92854.0\",\"size\":\"0.00000\"},{\"price\":\"92856.4\",\"size\":\"0.00861\"},{\"price\":\"92861.4\",\"size\":\"0.08081\"},{\"price\":\"92866.3\",\"size\":\"0.00000\"},{\"price\":\"92950.9\",\"size\":\"0.00000\"}],\"bids\":[{\"price\":\"92831.5\",\"size\":\"0.00021\"}],\"offset\":6961966,\"nonce\":3691008141},\"timestamp\":1765394040636,\"type\":\"update/order_book\"}"
    "msg": "{\"channel\":\"order_book:1\",\"offset\":6961967,\"order_book\":{\"code\":0,\"asks\":[{\"price\":\"92855.6\",\"size\":\"0.00000\"},{\"price\":\"92856.5\",\"size\":\"0.10780\"},{\"price\":\"92857.7\",\"size\":\"0.00000\"},{\"price\":\"92858.1\",\"size\":\"0.00000\"},{\"price\":\"92858.7\",\"size\":\"0.00000\"},{\"price\":\"92859.1\",\"size\":\"0.00000\"},{\"price\":\"92859.5\",\"size\":\"0.01076\"},{\"price\":\"92860.7\",\"size\":\"0.18846\"},{\"price\":\"92861.4\",\"size\":\"0.00000\"},{\"price\":\"92864.0\",\"size\":\"1.00000\"},{\"price\":\"92865.4\",\"size\":\"0.00000\"},{\"price\":\"92877.3\",\"size\":\"0.00000\"},{\"price\":\"92883.4\",\"size\":\"0.00000\"},{\"price\":\"92884.0\",\"size\":\"0.00000\"},{\"price\":\"92885.4\",\"size\":\"4.59655\"},{\"price\":\"92886.7\",\"size\":\"0.00000\"},{\"price\":\"92887.4\",\"size\":\"0.00000\"},{\"price\":\"92891.0\",\"size\":\"0.00000\"},{\"price\":\"92892.4\",\"size\":\"6.09310\"},{\"price\":\"92899.3\",\"size\":\"14.43102\"},{\"price\":\"92909.2\",\"size\":\"8.07918\"},{\"price\":\"92937.0\",\"size\":\"8.07918\"}],\"bids\":[{\"price\":\"92830.4\",\"size\":\"0.02815\"},{\"price\":\"92825.2\",\"size\":\"0.05386\"},{\"price\":\"92825.1\",\"size\":\"0.00000\"},{\"price\":\"92820.8\",\"size\":\"0.00000\"}],\"offset\":6961967,\"nonce\":3691008142},\"timestamp\":1765394040642,\"type\":\"update/order_book\"}"
    "msg": "{\"channel\":\"order_book:1\",\"offset\":6961968,\"order_book\":{\"code\":0,\"asks\":[{\"price\":\"92856.3\",\"size\":\"0.02153\"},{\"price\":\"92860.6\",\"size\":\"0.08083\"},{\"price\":\"92863.9\",\"size\":\"0.02465\"},{\"price\":\"92877.5\",\"size\":\"0.00308\"},{\"price\":\"92896.6\",\"size\":\"0.00000\"}],\"bids\":[{\"price\":\"92833.9\",\"size\":\"0.01722\"},{\"price\":\"92825.1\",\"size\":\"4.57432\"},{\"price\":\"92818.1\",\"size\":\"6.53254\"},{\"price\":\"92811.1\",\"size\":\"15.47180\"},{\"price\":\"92804.3\",\"size\":\"0.38767\"},{\"price\":\"92797.4\",\"size\":\"0.24121\"},{\"price\":\"92762.2\",\"size\":\"0.31949\"},{\"price\":\"92734.9\",\"size\":\"0.00000\"}],\"offset\":6961968,\"nonce\":3691008143},\"timestamp\":1765394040651,\"type\":\"update/order_book\"}"
    "msg": "{\"channel\":\"order_book:1\",\"offset\":6961969,\"order_book\":{\"code\":0,\"asks\":[{\"price\":\"92859.5\",\"size\":\"0.00000\"},{\"price\":\"92883.3\",\"size\":\"0.38767\"}],\"bids\":[{\"price\":\"92842.3\",\"size\":\"0.00500\"}],\"offset\":6961969,\"nonce\":3691008144},\"timestamp\":1765394040658,\"type\":\"update/order_book\"}"
    "msg": "{\"channel\":\"order_book:1\",\"offset\":6961970,\"order_book\":{\"code\":0,\"asks\":[{\"price\":\"92856.3\",\"size\":\"0.00000\"},{\"price\":\"92856.4\",\"size\":\"0.00000\"},{\"price\":\"92856.5\",\"size\":\"0.00000\"},{\"price\":\"92860.6\",\"size\":\"0.00000\"},{\"price\":\"92864.6\",\"size\":\"0.02828\"},{\"price\":\"92870.9\",\"size\":\"0.00000\"},{\"price\":\"92871.1\",\"size\":\"0.00000\"},{\"price\":\"92887.3\",\"size\":\"0.38767\"},{\"price\":\"92890.9\",\"size\":\"0.38767\"}],\"bids\":[{\"price\":\"92839.6\",\"size\":\"0.88638\"},{\"price\":\"92839.3\",\"size\":\"0.03768\"},{\"price\":\"92814.0\",\"size\":\"0.00000\"},{\"price\":\"92813.8\",\"size\":\"0.00000\"},{\"price\":\"92809.9\",\"size\":\"0.00000\"},{\"price\":\"92808.1\",\"size\":\"0.00000\"},{\"price\":\"92807.5\",\"size\":\"0.01077\"},{\"price\":\"92804.3\",\"size\":\"0.00000\"}],\"offset\":6961970,\"nonce\":3691008145},\"timestamp\":1765394040661,\"type\":\"update/order_book\"}"
    "msg": "{\"channel\":\"order_book:1\",\"offset\":6961971,\"order_book\":{\"code\":0,\"asks\":[{\"price\":\"92859.6\",\"size\":\"0.00000\"},{\"price\":\"92860.7\",\"size\":\"0.05384\"},{\"price\":\"92869.7\",\"size\":\"0.00500\"}],\"bids\":[{\"price\":\"92842.3\",\"size\":\"0.03000\"},{\"price\":\"92814.3\",\"size\":\"0.00000\"},{\"price\":\"92806.0\",\"size\":\"0.00000\"}],\"offset\":6961971,\"nonce\":3691008146},\"timestamp\":1765394040667,\"type\":\"update/order_book\"}"
    "msg": "{\"channel\":\"order_book:1\",\"offset\":6961972,\"order_book\":{\"code\":0,\"asks\":[{\"price\":\"92861.8\",\"size\":\"0.02153\"},{\"price\":\"92863.5\",\"size\":\"0.01076\"},{\"price\":\"92867.0\",\"size\":\"0.00000\"},{\"price\":\"92868.8\",\"size\":\"0.08815\"}],\"bids\":[{\"price\":\"92849.1\",\"size\":\"0.38767\"},{\"price\":\"92842.3\",\"size\":\"0.04719\"},{\"price\":\"92837.2\",\"size\":\"0.09815\"}],\"offset\":6961972,\"nonce\":3691008147},\"timestamp\":1765394040679,\"type\":\"update/order_book\"}"
    "msg": "{\"channel\":\"order_book:1\",\"offset\":6961973,\"order_book\":{\"code\":0,\"asks\":[{\"price\":\"92872.6\",\"size\":\"0.00000\"}],\"bids\":[{\"price\":\"92846.3\",\"size\":\"0.38767\"},{\"price\":\"92843.5\",\"size\":\"0.38767\"},{\"price\":\"92739.7\",\"size\":\"0.00000\"}],\"offset\":6961973,\"nonce\":3691008148},\"timestamp\":1765394040684,\"type\":\"update/order_book\"}"
    "msg": "{\"channel\":\"order_book:1\",\"offset\":6961974,\"order_book\":{\"code\":0,\"asks\":[{\"price\":\"92877.5\",\"size\":\"0.00000\"},{\"price\":\"92878.2\",\"size\":\"0.12233\"},{\"price\":\"92896.5\",\"size\":\"0.38767\"}],\"bids\":[],\"offset\":6961974,\"nonce\":3691008149},\"timestamp\":1765394040688,\"type\":\"update/order_book\"}"
    "msg": "{\"channel\":\"order_book:1\",\"offset\":6961975,\"order_book\":{\"code\":0,\"asks\":[{\"price\":\"92855.2\",\"size\":\"0.03768\"},{\"price\":\"92863.5\",\"size\":\"0.00000\"},{\"price\":\"92870.0\",\"size\":\"0.00000\"},{\"price\":\"92885.4\",\"size\":\"0.00000\"},{\"price\":\"92892.4\",\"size\":\"0.00000\"},{\"price\":\"92899.2\",\"size\":\"0.00000\"},{\"price\":\"92899.3\",\"size\":\"0.00000\"},{\"price\":\"92901.5\",\"size\":\"3.14750\"},{\"price\":\"92908.5\",\"size\":\"4.17227\"},{\"price\":\"92915.4\",\"size\":\"9.88169\"}],\"bids\":[{\"price\":\"92807.5\",\"size\":\"0.00000\"},{\"price\":\"92748.5\",\"size\":\"0.00000\"}],\"offset\":6961975,\"nonce\":3691008150},\"timestamp\":1765394040693,\"type\":\"update/order_book\"}"
    "msg": "{\"channel\":\"order_book:1\",\"offset\":6961976,\"order_book\":{\"code\":0,\"asks\":[{\"price\":\"92860.7\",\"size\":\"0.00000\"},{\"price\":\"92861.8\",\"size\":\"0.00000\"},{\"price\":\"92901.7\",\"size\":\"0.00000\"},{\"price\":\"92902.1\",\"size\":\"0.38767\"},{\"price\":\"92919.9\",\"size\":\"1.08034\"},{\"price\":\"92947.7\",\"size\":\"0.00000\"}],\"bids\":[{\"price\":\"92849.1\",\"size\":\"1.22806\"},{\"price\":\"92825.2\",\"size\":\"0.00000\"},{\"price\":\"92722.0\",\"size\":\"0.00000\"}],\"offset\":6961976,\"nonce\":3691008151},\"timestamp\":1765394040695,\"type\":\"update/order_book\"}"
    "msg": "{\"channel\":\"order_book:1\",\"offset\":6961977,\"order_book\":{\"code\":0,\"asks\":[],\"bids\":[{\"price\":\"92842.3\",\"size\":\"0.85361\"},{\"price\":\"92825.1\",\"size\":\"4.57536\"}],\"offset\":6961977,\"nonce\":3691008152},\"timestamp\":1765394040704,\"type\":\"update/order_book\"}"
    "msg": "{\"channel\":\"order_book:1\",\"offset\":6961978,\"order_book\":{\"code\":0,\"asks\":[{\"price\":\"92858.2\",\"size\":\"0.00000\"}],\"bids\":[{\"price\":\"92834.7\",\"size\":\"0.00000\"},{\"price\":\"92830.4\",\"size\":\"0.00000\"}],\"offset\":6961978,\"nonce\":3691008153},\"timestamp\":1765394040707,\"type\":\"update/order_book\"}"
    "msg": "{\"channel\":\"order_book:1\",\"offset\":6961979,\"order_book\":{\"code\":0,\"asks\":[{\"price\":\"92849.2\",\"size\":\"0.00000\"},{\"price\":\"92858.9\",\"size\":\"0.00000\"},{\"price\":\"92866.7\",\"size\":\"0.02153\"},{\"price\":\"92869.9\",\"size\":\"0.01076\"},{\"price\":\"92871.4\",\"size\":\"0.02153\"}],\"bids\":[{\"price\":\"92839.3\",\"size\":\"0.00000\"},{\"price\":\"92837.1\",\"size\":\"0.10887\"},{\"price\":\"92827.4\",\"size\":\"0.00000\"},{\"price\":\"92820.9\",\"size\":\"0.00000\"}],\"offset\":6961979,\"nonce\":3691008155},\"timestamp\":1765394040714,\"type\":\"update/order_book\"}"
    "msg": "{\"channel\":\"order_book:1\",\"offset\":6961980,\"order_book\":{\"code\":0,\"asks\":[{\"price\":\"92859.9\",\"size\":\"0.00000\"},{\"price\":\"92867.9\",\"size\":\"0.00000\"},{\"price\":\"92873.2\",\"size\":\"1.07758\"},{\"price\":\"92874.6\",\"size\":\"2.69396\"},{\"price\":\"92878.2\",\"size\":\"0.00000\"},{\"price\":\"92903.3\",\"size\":\"0.00000\"}],\"bids\":[{\"price\":\"92742.8\",\"size\":\"0.00000\"}],\"offset\":6961980,\"nonce\":3691008156},\"timestamp\":1765394040718,\"type\":\"update/order_book\"}"
    "msg": "{\"channel\":\"order_book:1\",\"offset\":6961981,\"order_book\":{\"code\":0,\"asks\":[{\"price\":\"92863.9\",\"size\":\"0.00000\"},{\"price\":\"92864.6\",\"size\":\"0.00000\"},{\"price\":\"92866.7\",\"size\":\"0.00000\"},{\"price\":\"92869.7\",\"size\":\"0.00000\"},{\"price\":\"92869.9\",\"size\":\"0.00000\"},{\"price\":\"92871.4\",\"size\":\"0.00000\"},{\"price\":\"92885.3\",\"size\":\"0.00000\"}],\"bids\":[{\"price\":\"92844.6\",\"size\":\"2.69396\"},{\"price\":\"92842.1\",\"size\":\"0.10780\"},{\"price\":\"92834.2\",\"size\":\"0.11979\"},{\"price\":\"92832.7\",\"size\":\"0.00000\"},{\"price\":\"92831.7\",\"size\":\"0.00500\"},{\"price\":\"92822.1\",\"size\":\"0.00000\"},{\"price\":\"92808.5\",\"size\":\"0.00000\"}],\"offset\":6961981,\"nonce\":3691008157},\"timestamp\":1765394040724,\"type\":\"update/order_book\"}"
    "msg": "{\"channel\":\"order_book:1\",\"offset\":6961982,\"order_book\":{\"code\":0,\"asks\":[{\"price\":\"92909.2\",\"size\":\"0.00000\"},{\"price\":\"92923.9\",\"size\":\"0.08000\"},{\"price\":\"92937.0\",\"size\":\"0.00000\"}],\"bids\":[{\"price\":\"92849.1\",\"size\":\"2.14874\"},{\"price\":\"92833.1\",\"size\":\"0.02628\"},{\"price\":\"92816.0\",\"size\":\"0.01077\"},{\"price\":\"92763.1\",\"size\":\"0.05390\"}],\"offset\":6961982,\"nonce\":3691008158},\"timestamp\":1765394040726,\"type\":\"update/order_book\"}"
    "msg": "{\"channel\":\"order_book:1\",\"offset\":6961983,\"order_book\":{\"code\":0,\"asks\":[{\"price\":\"92870.1\",\"size\":\"0.05095\"},{\"price\":\"92873.2\",\"size\":\"0.00000\"}],\"bids\":[{\"price\":\"92842.2\",\"size\":\"1.79107\"}],\"offset\":6961983,\"nonce\":3691008159},\"timestamp\":1765394040730,\"type\":\"update/order_book\"}"
    "msg": "{\"channel\":\"order_book:1\",\"offset\":6961984,\"order_book\":{\"code\":0,\"asks\":[{\"price\":\"92870.5\",\"size\":\"0.00000\"},{\"price\":\"92872.3\",\"size\":\"0.01076\"},{\"price\":\"92894.5\",\"size\":\"0.00000\"}],\"bids\":[{\"price\":\"92849.1\",\"size\":\"3.22632\"},{\"price\":\"92848.4\",\"size\":\"0.02154\"},{\"price\":\"92842.4\",\"size\":\"0.05811\"},{\"price\":\"92825.6\",\"size\":\"0.00108\"},{\"price\":\"92820.3\",\"size\":\"0.11629\"},{\"price\":\"92819.4\",\"size\":\"0.00000\"}],\"offset\":6961984,\"nonce\":3691008160},\"timestamp\":1765394040734,\"type\":\"update/order_book\"}"
    "msg": "{\"channel\":\"order_book:1\",\"offset\":6961985,\"order_book\":{\"code\":0,\"asks\":[{\"price\":\"92868.8\",\"size\":\"0.00000\"},{\"price\":\"92869.1\",\"size\":\"0.02153\"},{\"price\":\"92869.9\",\"size\":\"0.38767\"},{\"price\":\"92929.2\",\"size\":\"0.00000\"},{\"price\":\"93136.2\",\"size\":\"14.95737\"}],\"bids\":[{\"price\":\"92840.5\",\"size\":\"0.08000\"},{\"price\":\"92837.2\",\"size\":\"0.00000\"},{\"price\":\"92811.0\",\"size\":\"0.00000\"}],\"offset\":6961985,\"nonce\":3691008161},\"timestamp\":1765394040737,\"type\":\"update/order_book\"}"
    "msg": "{\"channel\":\"order_book:1\",\"offset\":6961986,\"order_book\":{\"code\":0,\"asks\":[{\"price\":\"92901.5\",\"size\":\"0.00000\"},{\"price\":\"92908.5\",\"size\":\"0.00000\"},{\"price\":\"92910.5\",\"size\":\"2.29761\"},{\"price\":\"92917.5\",\"size\":\"3.04567\"},{\"price\":\"92943.0\",\"size\":\"0.00000\"},{\"price\":\"93150.0\",\"size\":\"14.95737\"}],\"bids\":[{\"price\":\"92849.1\",\"size\":\"3.44164\"},{\"price\":\"92848.4\",\"size\":\"0.00000\"}],\"offset\":6961986,\"nonce\":3691008162},\"timestamp\":1765394040744,\"type\":\"update/order_book\"}"
    "msg": "{\"channel\":\"order_book:1\",\"offset\":6961987,\"order_book\":{\"code\":0,\"asks\":[{\"price\":\"92872.3\",\"size\":\"0.00000\"}],\"bids\":[{\"price\":\"92816.0\",\"size\":\"0.00000\"}],\"offset\":6961987,\"nonce\":3691008163},\"timestamp\":1765394040747,\"type\":\"update/order_book\"}"
    "msg": "{\"channel\":\"order_book:1\",\"offset\":6961988,\"order_book\":{\"code\":0,\"asks\":[{\"price\":\"92875.5\",\"size\":\"0.38767\"},{\"price\":\"92888.0\",\"size\":\"0.36721\"},{\"price\":\"92894.4\",\"size\":\"0.00214\"},{\"price\":\"92894.5\",\"size\":\"0.00214\"},{\"price\":\"92915.4\",\"size\":\"0.00000\"},{\"price\":\"92924.4\",\"size\":\"7.21342\"}],\"bids\":[{\"price\":\"92833.1\",\"size\":\"0.02842\"},{\"price\":\"92832.9\",\"size\":\"0.00214\"},{\"price\":\"92831.5\",\"size\":\"4.57682\"},{\"price\":\"92826.6\",\"size\":\"0.36745\"},{\"price\":\"92825.1\",\"size\":\"0.00000\"},{\"price\":\"92780.1\",\"size\":\"0.00000\"}],\"offset\":6961988,\"nonce\":3691008164},\"timestamp\":1765394040750,\"type\":\"update/order_book\"}"
    "msg": "{\"channel\":\"order_book:1\",\"offset\":6961989,\"order_book\":{\"code\":0,\"asks\":[{\"price\":\"92869.1\",\"size\":\"0.00000\"},{\"price\":\"92872.6\",\"size\":\"0.10780\"}],\"bids\":[{\"price\":\"92831.5\",\"size\":\"4.57661\"}],\"offset\":6961989,\"nonce\":3691008165},\"timestamp\":1765394040752,\"type\":\"update/order_book\"}"
    "msg": "{\"channel\":\"order_book:1\",\"offset\":6961990,\"order_book\":{\"code\":0,\"asks\":[{\"price\":\"92855.2\",\"size\":\"0.02844\"},{\"price\":\"92873.7\",\"size\":\"0.10780\"}],\"bids\":[{\"price\":\"92846.2\",\"size\":\"0.00021\"},{\"price\":\"92842.3\",\"size\":\"0.96141\"},{\"price\":\"92826.1\",\"size\":\"0.00000\"},{\"price\":\"92824.5\",\"size\":\"6.53209\"},{\"price\":\"92818.1\",\"size\":\"0.00000\"},{\"price\":\"92817.5\",\"size\":\"15.47073\"},{\"price\":\"92811.1\",\"size\":\"0.00000\"},{\"price\":\"92656.3\",\"size\":\"0.00000\"}],\"offset\":6961990,\"nonce\":3691008166},\"timestamp\":1765394040762,\"type\":\"update/order_book\"}"
    "msg": "{\"channel\":\"order_book:1\",\"offset\":6961991,\"order_book\":{\"code\":0,\"asks\":[{\"price\":\"92889.2\",\"size\":\"0.00308\"}],\"bids\":[{\"price\":\"92850.5\",\"size\":\"0.02153\"},{\"price\":\"92833.6\",\"size\":\"0.00000\"},{\"price\":\"92657.3\",\"size\":\"0.00000\"}],\"offset\":6961991,\"nonce\":3691008167},\"timestamp\":1765394040766,\"type\":\"update/order_book\"}"
    "msg": "{\"channel\":\"order_book:1\",\"offset\":6961992,\"order_book\":{\"code\":0,\"asks\":[{\"price\":\"92855.2\",\"size\":\"0.02761\"},{\"price\":\"92874.6\",\"size\":\"0.00000\"}],\"bids\":[{\"price\":\"92849.1\",\"size\":\"3.47069\"},{\"price\":\"92820.0\",\"size\":\"0.00000\"},{\"price\":\"92771.0\",\"size\":\"0.00000\"}],\"offset\":6961992,\"nonce\":3691008168},\"timestamp\":1765394040769,\"type\":\"update/order_book\"}"
    "msg": "{\"channel\":\"order_book:1\",\"offset\":6961993,\"order_book\":{\"code\":0,\"asks\":[{\"price\":\"92875.6\",\"size\":\"0.00000\"},{\"price\":\"92905.8\",\"size\":\"0.07297\"}],\"bids\":[{\"price\":\"92855.1\",\"size\":\"0.38767\"},{\"price\":\"92849.1\",\"size\":\"3.49975\"},{\"price\":\"92843.6\",\"size\":\"0.11088\"}],\"offset\":6961993,\"nonce\":3691008169},\"timestamp\":1765394040778,\"type\":\"update/order_book\"}"
    "msg": "{\"channel\":\"order_book:1\",\"offset\":6961994,\"order_book\":{\"code\":0,\"asks\":[{\"price\":\"92855.2\",\"size\":\"0.01911\"},{\"price\":\"92907.7\",\"size\":\"0.38767\"}],\"bids\":[{\"price\":\"92850.5\",\"size\":\"0.00000\"},{\"price\":\"92849.1\",\"size\":\"2.45032\"},{\"price\":\"92842.4\",\"size\":\"0.00000\"},{\"price\":\"92842.3\",\"size\":\"0.93941\"},{\"price\":\"92837.1\",\"size\":\"0.08072\"},{\"price\":\"92817.7\",\"size\":\"0.01077\"},{\"price\":\"92817.1\",\"size\":\"0.00000\"},{\"price\":\"92812.0\",\"size\":\"0.00000\"}],\"offset\":6961994,\"nonce\":3691008171},\"timestamp\":1765394040788,\"type\":\"update/order_book\"}"
    "msg": "{\"channel\":\"order_book:1\",\"offset\":6961995,\"order_book\":{\"code\":0,\"asks\":[{\"price\":\"92855.2\",\"size\":\"0.00000\"}],\"bids\":[{\"price\":\"92854.1\",\"size\":\"0.01076\"},{\"price\":\"92852.3\",\"size\":\"0.38767\"},{\"price\":\"92849.1\",\"size\":\"2.48799\"},{\"price\":\"92842.3\",\"size\":\"0.92422\"},{\"price\":\"92830.5\",\"size\":\"0.11629\"},{\"price\":\"92817.7\",\"size\":\"0.00000\"},{\"price\":\"92781.3\",\"size\":\"0.00000\"}],\"offset\":6961995,\"nonce\":3691008172},\"timestamp\":1765394040792,\"type\":\"update/order_book\"}"
    "msg": "{\"channel\":\"order_book:1\",\"offset\":6961996,\"order_book\":{\"code\":0,\"asks\":[{\"price\":\"92855.6\",\"size\":\"0.00021\"},{\"price\":\"92860.2\",\"size\":\"0.00000\"},{\"price\":\"92864.3\",\"size\":\"0.00000\"},{\"price\":\"92881.5\",\"size\":\"0.00500\"},{\"price\":\"92891.8\",\"size\":\"0.00000\"}],\"bids\":[{\"price\":\"92854.5\",\"size\":\"0.02153\"},{\"price\":\"92816.3\",\"size\":\"0.00000\"}],\"offset\":6961996,\"nonce\":3691008173},\"timestamp\":1765394040795,\"type\":\"update/order_book\"}"
    "msg": "{\"channel\":\"order_book:1\",\"offset\":6961997,\"order_book\":{\"code\":0,\"asks\":[{\"price\":\"92869.9\",\"size\":\"0.00000\"},{\"price\":\"92872.2\",\"size\":\"0.02834\"},{\"price\":\"92889.2\",\"size\":\"0.00000\"},{\"price\":\"92897.9\",\"size\":\"0.00000\"},{\"price\":\"92905.8\",\"size\":\"0.00000\"}],\"bids\":[{\"price\":\"92854.1\",\"size\":\"0.00000\"},{\"price\":\"92844.4\",\"size\":\"0.11979\"},{\"price\":\"92842.3\",\"size\":\"0.91922\"},{\"price\":\"92828.5\",\"size\":\"0.00108\"},{\"price\":\"92825.6\",\"size\":\"0.00000\"},{\"price\":\"92799.6\",\"size\":\"0.00000\"}],\"offset\":6961997,\"nonce\":3691008174},\"timestamp\":1765394040798,\"type\":\"update/order_book\"}"
    "msg": "{\"channel\":\"order_book:1\",\"offset\":6961998,\"order_book\":{\"code\":0,\"asks\":[{\"price\":\"92880.1\",\"size\":\"0.02828\"},{\"price\":\"92906.4\",\"size\":\"0.58658\"}],\"bids\":[{\"price\":\"92808.9\",\"size\":\"0.00000\"},{\"price\":\"92797.9\",\"size\":\"0.00000\"},{\"price\":\"92757.4\",\"size\":\"0.00000\"}],\"offset\":6961998,\"nonce\":3691008175},\"timestamp\":1765394040802,\"type\":\"update/order_book\"}"
    "msg": "{\"channel\":\"order_book:1\",\"offset\":6961999,\"order_book\":{\"code\":0,\"asks\":[{\"price\":\"92867.2\",\"size\":\"0.00021\"}],\"bids\":[{\"price\":\"92854.5\",\"size\":\"0.00000\"},{\"price\":\"92849.1\",\"size\":\"2.51427\"},{\"price\":\"92846.9\",\"size\":\"0.63214\"},{\"price\":\"92834.2\",\"size\":\"0.00000\"},{\"price\":\"92833.1\",\"size\":\"0.00214\"},{\"price\":\"92820.3\",\"size\":\"0.00000\"},{\"price\":\"92816.6\",\"size\":\"0.11759\"},{\"price\":\"92798.0\",\"size\":\"0.12098\"},{\"price\":\"92622.1\",\"size\":\"0.00000\"}],\"offset\":6961999,\"nonce\":3691008176},\"timestamp\":1765394040803,\"type\":\"update/order_book\"}"
    "msg": "{\"channel\":\"order_book:1\",\"offset\":6962000,\"order_book\":{\"code\":0,\"asks\":[{\"price\":\"92866.6\",\"size\":\"0.00000\"},{\"price\":\"92875.5\",\"size\":\"0.00000\"},{\"price\":\"92898.2\",\"size\":\"0.00000\"}],\"bids\":[{\"price\":\"92842.3\",\"size\":\"0.91422\"},{\"price\":\"92811.2\",\"size\":\"0.00000\"},{\"price\":\"92797.4\",\"size\":\"0.00000\"},{\"price\":\"92776.5\",\"size\":\"0.00000\"}],\"offset\":6962000,\"nonce\":3691008177},\"timestamp\":1765394040804,\"type\":\"update/order_book\"}"
    "msg": "{\"channel\":\"order_book:1\",\"offset\":6962001,\"order_book\":{\"code\":0,\"asks\":[{\"price\":\"92910.5\",\"size\":\"0.00000\"},{\"price\":\"92917.5\",\"size\":\"0.00000\"},{\"price\":\"92918.4\",\"size\":\"2.29740\"},{\"price\":\"92925.4\",\"size\":\"3.04539\"}],\"bids\":[{\"price\":\"92855.1\",\"size\":\"1.22449\"},{\"price\":\"92854.5\",\"size\":\"0.02153\"}],\"offset\":6962001,\"nonce\":3691008179},\"timestamp\":1765394040814,\"type\":\"update/order_book\"}"
    "msg": "{\"channel\":\"order_book:1\",\"offset\":6962002,\"order_book\":{\"code\":0,\"asks\":[{\"price\":\"92866.9\",\"size\":\"0.00000\"},{\"price\":\"92888.0\",\"size\":\"0.00000\"},{\"price\":\"92894.4\",\"size\":\"0.00000\"},{\"price\":\"92926.8\",\"size\":\"0.00000\"},{\"price\":\"92942.9\",\"size\":\"0.11088\"}],\"bids\":[{\"price\":\"92849.0\",\"size\":\"0.10780\"},{\"price\":\"92847.1\",\"size\":\"0.00468\"},{\"price\":\"92842.1\",\"size\":\"0.00000\"}],\"offset\":6962002,\"nonce\":3691008180},\"timestamp\":1765394040817,\"type\":\"update/order_book\"}"
    "msg": "{\"channel\":\"order_book:1\",\"offset\":6962003,\"order_book\":{\"code\":0,\"asks\":[{\"price\":\"92855.6\",\"size\":\"0.00000\"},{\"price\":\"92864.0\",\"size\":\"0.99691\"},{\"price\":\"92872.2\",\"size\":\"0.00000\"},{\"price\":\"92879.3\",\"size\":\"0.02465\"},{\"price\":\"92894.5\",\"size\":\"0.00000\"},{\"price\":\"92924.4\",\"size\":\"0.00000\"},{\"price\":\"92926.7\",\"size\":\"0.00000\"},{\"price\":\"92932.4\",\"size\":\"7.21276\"},{\"price\":\"92933.4\",\"size\":\"0.11731\"}],\"bids\":[{\"price\":\"92838.3\",\"size\":\"4.57818\"},{\"price\":\"92831.5\",\"size\":\"0.00000\"},{\"price\":\"92759.9\",\"size\":\"0.00000\"}],\"offset\":6962003,\"nonce\":3691008181},\"timestamp\":1765394040821,\"type\":\"update/order_book\"}"
    "msg": "{\"channel\":\"order_book:1\",\"offset\":6962004,\"order_book\":{\"code\":0,\"asks\":[{\"price\":\"92864.0\",\"size\":\"0.99334\"},{\"price\":\"92879.3\",\"size\":\"0.00000\"},{\"price\":\"92883.8\",\"size\":\"0.08814\"}],\"bids\":[{\"price\":\"92855.1\",\"size\":\"2.04066\"},{\"price\":\"92850.5\",\"size\":\"0.82957\"},{\"price\":\"92849.1\",\"size\":\"2.61240\"},{\"price\":\"92831.4\",\"size\":\"6.53160\"},{\"price\":\"92824.5\",\"size\":\"0.00000\"},{\"price\":\"92824.4\",\"size\":\"15.46958\"},{\"price\":\"92817.5\",\"size\":\"0.00000\"},{\"price\":\"92696.9\",\"size\":\"2.04294\"}],\"offset\":6962004,\"nonce\":3691008182},\"timestamp\":1765394040823,\"type\":\"update/order_book\"}"
    "msg": "{\"channel\":\"order_book:1\",\"offset\":6962005,\"order_book\":{\"code\":0,\"asks\":[{\"price\":\"92891.1\",\"size\":\"0.00000\"},{\"price\":\"92900.9\",\"size\":\"0.12233\"},{\"price\":\"92916.8\",\"size\":\"0.31946\"}],\"bids\":[{\"price\":\"92859.9\",\"size\":\"0.02153\"},{\"price\":\"92858.0\",\"size\":\"0.01076\"},{\"price\":\"92854.5\",\"size\":\"0.00000\"},{\"price\":\"92844.6\",\"size\":\"0.00000\"},{\"price\":\"92844.4\",\"size\":\"0.00000\"},{\"price\":\"92820.4\",\"size\":\"0.01077\"}],\"offset\":6962005,\"nonce\":3691008183},\"timestamp\":1765394040830,\"type\":\"update/order_book\"}"
    "msg": "{\"channel\":\"order_book:1\",\"offset\":6962006,\"order_book\":{\"code\":0,\"asks\":[{\"price\":\"92870.1\",\"size\":\"0.00000\"},{\"price\":\"92880.0\",\"size\":\"1.07758\"},{\"price\":\"92880.1\",\"size\":\"0.00000\"},{\"price\":\"92963.6\",\"size\":\"0.00000\"}],\"bids\":[{\"price\":\"92829.1\",\"size\":\"0.82625\"},{\"price\":\"92829.0\",\"size\":\"0.00000\"},{\"price\":\"92813.7\",\"size\":\"0.00000\"},{\"price\":\"92796.4\",\"size\":\"0.00000\"},{\"price\":\"92779.4\",\"size\":\"0.00000\"},{\"price\":\"92722.8\",\"size\":\"0.00000\"},{\"price\":\"92696.9\",\"size\":\"3.79503\"}],\"offset\":6962006,\"nonce\":3691008184},\"timestamp\":1765394040832,\"type\":\"update/order_book\"}"
    "msg": "{\"channel\":\"order_book:1\",\"offset\":6962007,\"order_book\":{\"code\":0,\"asks\":[{\"price\":\"92901.0\",\"size\":\"2.15445\"},{\"price\":\"92933.5\",\"size\":\"8.07918\"}],\"bids\":[{\"price\":\"92855.1\",\"size\":\"3.11824\"},{\"price\":\"92849.1\",\"size\":\"2.58425\"},{\"price\":\"92829.2\",\"size\":\"0.38767\"},{\"price\":\"92829.1\",\"size\":\"0.00000\"},{\"price\":\"92778.5\",\"size\":\"0.31945\"},{\"price\":\"92757.3\",\"size\":\"0.00000\"}],\"offset\":6962007,\"nonce\":3691008185},\"timestamp\":1765394040835,\"type\":\"update/order_book\"}"
    "msg": "{\"channel\":\"order_book:1\",\"offset\":6962008,\"order_book\":{\"code\":0,\"asks\":[{\"price\":\"92864.0\",\"size\":\"0.99045\"},{\"price\":\"92872.6\",\"size\":\"0.00000\"},{\"price\":\"92873.7\",\"size\":\"0.21560\"},{\"price\":\"92887.1\",\"size\":\"0.02828\"}],\"bids\":[{\"price\":\"92859.9\",\"size\":\"0.00000\"},{\"price\":\"92854.5\",\"size\":\"0.02153\"}],\"offset\":6962008,\"nonce\":3691008186},\"timestamp\":1765394040839,\"type\":\"update/order_book\"}"
    "msg": "{\"channel\":\"order_book:1\",\"offset\":6962009,\"order_book\":{\"code\":0,\"asks\":[{\"price\":\"92891.9\",\"size\":\"0.12064\"}],\"bids\":[{\"price\":\"92849.1\",\"size\":\"2.52614\"},{\"price\":\"92788.0\",\"size\":\"0.02094\"},{\"price\":\"92769.2\",\"size\":\"0.00000\"}],\"offset\":6962009,\"nonce\":3691008187},\"timestamp\":1765394040844,\"type\":\"update/order_book\"}"
    "msg": "{\"channel\":\"order_book:1\",\"offset\":6962010,\"order_book\":{\"code\":0,\"asks\":[{\"price\":\"92872.4\",\"size\":\"0.10780\"},{\"price\":\"92873.7\",\"size\":\"0.10780\"},{\"price\":\"92881.4\",\"size\":\"2.69396\"},{\"price\":\"92887.1\",\"size\":\"0.00000\"}],\"bids\":[{\"price\":\"92858.0\",\"size\":\"0.00000\"},{\"price\":\"92849.2\",\"size\":\"0.08626\"},{\"price\":\"92849.1\",\"size\":\"2.49986\"},{\"price\":\"92833.2\",\"size\":\"0.00108\"},{\"price\":\"92831.7\",\"size\":\"0.00000\"},{\"price\":\"92828.5\",\"size\":\"0.00000\"}],\"offset\":6962010,\"nonce\":3691008189},\"timestamp\":1765394040849,\"type\":\"update/order_book\"}"
    "msg": "{\"channel\":\"order_book:1\",\"offset\":6962012,\"order_book\":{\"code\":0,\"asks\":[{\"price\":\"92880.0\",\"size\":\"0.00000\"},{\"price\":\"92881.4\",\"size\":\"0.00000\"}],\"bids\":[{\"price\":\"92859.9\",\"size\":\"0.02153\"},{\"price\":\"92849.2\",\"size\":\"0.20605\"},{\"price\":\"92838.0\",\"size\":\"0.03631\"},{\"price\":\"92825.2\",\"size\":\"0.32682\"},{\"price\":\"92820.4\",\"size\":\"0.00000\"},{\"price\":\"92786.9\",\"size\":\"0.98046\"}],\"offset\":6962012,\"nonce\":3691008191},\"timestamp\":1765394040860,\"type\":\"update/order_book\"}"
    "msg": "{\"channel\":\"order_book:1\",\"offset\":6962013,\"order_book\":{\"code\":0,\"asks\":[{\"price\":\"92879.1\",\"size\":\"0.00000\"},{\"price\":\"92883.3\",\"size\":\"0.00000\"},{\"price\":\"92887.3\",\"size\":\"0.00000\"},{\"price\":\"92890.9\",\"size\":\"0.00000\"},{\"price\":\"92919.9\",\"size\":\"0.00000\"}],\"bids\":[{\"price\":\"92854.5\",\"size\":\"0.00000\"},{\"price\":\"92849.2\",\"size\":\"0.23233\"},{\"price\":\"92849.1\",\"size\":\"2.46219\"}],\"offset\":6962013,\"nonce\":3691008192},\"timestamp\":1765394040863,\"type\":\"update/order_book\"}"
    "msg": "{\"channel\":\"order_book:1\",\"offset\":6962014,\"order_book\":{\"code\":0,\"asks\":[{\"price\":\"92873.7\",\"size\":\"0.00000\"},{\"price\":\"92875.4\",\"size\":\"0.03767\"},{\"price\":\"92895.8\",\"size\":\"0.00000\"},{\"price\":\"92896.5\",\"size\":\"0.00000\"},{\"price\":\"92902.1\",\"size\":\"0.00000\"},{\"price\":\"92917.6\",\"size\":\"0.11419\"},{\"price\":\"92921.1\",\"size\":\"0.31946\"}],\"bids\":[{\"price\":\"92863.9\",\"size\":\"0.88253\"},{\"price\":\"92858.0\",\"size\":\"0.00000\"},{\"price\":\"92845.4\",\"size\":\"0.10780\"},{\"price\":\"92842.3\",\"size\":\"0.80642\"}],\"offset\":6962014,\"nonce\":3691008193},\"timestamp\":1765394040865,\"type\":\"update/order_book\"}"
    "msg": "{\"channel\":\"order_book:1\",\"offset\":6962015,\"order_book\":{\"code\":0,\"asks\":[{\"price\":\"92864.0\",\"size\":\"0.98045\"},{\"price\":\"92872.4\",\"size\":\"0.00000\"},{\"price\":\"92892.3\",\"size\":\"0.03327\"},{\"price\":\"92900.8\",\"size\":\"0.11088\"},{\"price\":\"92907.7\",\"size\":\"0.00000\"},{\"price\":\"92913.3\",\"size\":\"0.38767\"},{\"price\":\"92917.4\",\"size\":\"0.38767\"},{\"price\":\"92951.9\",\"size\":\"0.89836\"}],\"bids\":[{\"price\":\"92862.0\",\"size\":\"0.02153\"},{\"price\":\"92859.9\",\"size\":\"0.85581\"},{\"price\":\"92853.6\",\"size\":\"2.69396\"},{\"price\":\"92849.2\",\"size\":\"0.20328\"},{\"price\":\"92823.8\",\"size\":\"0.01077\"}],\"offset\":6962015,\"nonce\":3691008194},\"timestamp\":1765394040871,\"type\":\"update/order_book\"}"
    "msg": "{\"channel\":\"order_book:1\",\"offset\":6962016,\"order_book\":{\"code\":0,\"asks\":[{\"price\":\"92923.0\",\"size\":\"0.38767\"},{\"price\":\"92952.8\",\"size\":\"0.77936\"}],\"bids\":[{\"price\":\"92855.5\",\"size\":\"0.00500\"},{\"price\":\"92855.2\",\"size\":\"0.00700\"},{\"price\":\"92855.1\",\"size\":\"3.13824\"},{\"price\":\"92853.1\",\"size\":\"0.00468\"},{\"price\":\"92849.2\",\"size\":\"0.02628\"},{\"price\":\"92847.1\",\"size\":\"0.00000\"},{\"price\":\"92833.1\",\"size\":\"0.00000\"},{\"price\":\"92832.9\",\"size\":\"0.00000\"},{\"price\":\"92829.2\",\"size\":\"0.00000\"},{\"price\":\"92826.6\",\"size\":\"0.00000\"},{\"price\":\"92823.9\",\"size\":\"0.00000\"},{\"price\":\"92823.8\",\"size\":\"0.00000\"}],\"offset\":6962016,\"nonce\":3691008195},\"timestamp\":1765394040874,\"type\":\"update/order_book\"}"
    "msg": "{\"channel\":\"order_book:1\",\"offset\":6962017,\"order_book\":{\"code\":0,\"asks\":[{\"price\":\"92883.8\",\"size\":\"0.00000\"},{\"price\":\"92891.9\",\"size\":\"0.00000\"},{\"price\":\"92901.0\",\"size\":\"0.00000\"},{\"price\":\"92933.5\",\"size\":\"0.00000\"}],\"bids\":[{\"price\":\"92855.2\",\"size\":\"0.03515\"},{\"price\":\"92849.1\",\"size\":\"2.36406\"},{\"price\":\"92817.7\",\"size\":\"0.05131\"},{\"price\":\"92810.7\",\"size\":\"0.38738\"},{\"price\":\"92787.6\",\"size\":\"0.85615\"}],\"offset\":6962017,\"nonce\":3691008196},\"timestamp\":1765394040879,\"type\":\"update/order_book\"}"
    "msg": "{\"channel\":\"order_book:1\",\"offset\":6962018,\"order_book\":{\"code\":0,\"asks\":[{\"price\":\"92878.3\",\"size\":\"0.00000\"},{\"price\":\"92902.4\",\"size\":\"0.36715\"}],\"bids\":[{\"price\":\"92863.9\",\"size\":\"1.27020\"},{\"price\":\"92862.0\",\"size\":\"0.00000\"},{\"price\":\"92855.5\",\"size\":\"0.02019\"},{\"price\":\"92849.2\",\"size\":\"0.00000\"},{\"price\":\"92830.5\",\"size\":\"0.00000\"}],\"offset\":6962018,\"nonce\":3691008198},\"timestamp\":1765394040888,\"type\":\"update/order_book\"}"
    "msg": "{\"channel\":\"order_book:1\",\"offset\":6962019,\"order_book\":{\"code\":0,\"asks\":[{\"price\":\"92900.9\",\"size\":\"0.00000\"},{\"price\":\"92908.7\",\"size\":\"0.00214\"},{\"price\":\"92917.6\",\"size\":\"0.00000\"}],\"bids\":[{\"price\":\"92861.1\",\"size\":\"0.38767\"},{\"price\":\"92855.1\",\"size\":\"3.16729\"},{\"price\":\"92849.1\",\"size\":\"2.14874\"},{\"price\":\"92822.2\",\"size\":\"0.00000\"},{\"price\":\"92816.6\",\"size\":\"0.00000\"}],\"offset\":6962019,\"nonce\":3691008199},\"timestamp\":1765394040891,\"type\":\"update/order_book\"}"
    "msg": "{\"channel\":\"order_book:1\",\"offset\":6962020,\"order_book\":{\"code\":0,\"asks\":[{\"price\":\"92864.0\",\"size\":\"0.98045\"},{\"price\":\"92918.4\",\"size\":\"0.00000\"},{\"price\":\"92925.4\",\"size\":\"0.00000\"},{\"price\":\"92932.4\",\"size\":\"0.00000\"},{\"price\":\"92934.2\",\"size\":\"2.29700\"},{\"price\":\"92941.2\",\"size\":\"3.04486\"},{\"price\":\"92948.2\",\"size\":\"7.21151\"}],\"bids\":[{\"price\":\"92861.2\",\"size\":\"0.02153\"},{\"price\":\"92855.1\",\"size\":\"3.22263\"},{\"price\":\"92854.0\",\"size\":\"0.10780\"},{\"price\":\"92849.0\",\"size\":\"0.00000\"},{\"price\":\"92840.5\",\"size\":\"0.19629\"},{\"price\":\"92838.3\",\"size\":\"0.00000\"},{\"price\":\"92837.4\",\"size\":\"4.58075\"},{\"price\":\"92834.9\",\"size\":\"0.38767\"},{\"price\":\"92832.1\",\"size\":\"0.00000\"},{\"price\":\"92798.0\",\"size\":\"0.00000\"}],\"offset\":6962020,\"nonce\":3691008200},\"timestamp\":1765394040900,\"type\":\"update/order_book\"}"
    "msg": "{\"channel\":\"order_book:1\",\"offset\":6962021,\"order_book\":{\"code\":0,\"asks\":[{\"price\":\"92886.6\",\"size\":\"0.00000\"},{\"price\":\"92935.2\",\"size\":\"0.00000\"},{\"price\":\"92942.5\",\"size\":\"0.08000\"}],\"bids\":[{\"price\":\"92858.3\",\"size\":\"0.38767\"},{\"price\":\"92855.2\",\"size\":\"0.15494\"},{\"price\":\"92853.1\",\"size\":\"0.00000\"},{\"price\":\"92852.8\",\"size\":\"0.00468\"},{\"price\":\"92831.4\",\"size\":\"8.07918\"},{\"price\":\"92830.4\",\"size\":\"6.53167\"},{\"price\":\"92824.4\",\"size\":\"0.00000\"},{\"price\":\"92823.4\",\"size\":\"15.46974\"}],\"offset\":6962021,\"nonce\":3691008201},\"timestamp\":1765394040904,\"type\":\"update/order_book\"}"
    "msg": "{\"channel\":\"order_book:1\",\"offset\":6962022,\"order_book\":{\"code\":0,\"asks\":[{\"price\":\"92883.5\",\"size\":\"0.00000\"},{\"price\":\"92887.8\",\"size\":\"0.00000\"},{\"price\":\"92890.4\",\"size\":\"0.00000\"},{\"price\":\"92928.6\",\"size\":\"0.38767\"}],\"bids\":[{\"price\":\"92863.9\",\"size\":\"3.42465\"},{\"price\":\"92855.2\",\"size\":\"0.26582\"},{\"price\":\"92831.9\",\"size\":\"0.11759\"}],\"offset\":6962022,\"nonce\":3691008202},\"timestamp\":1765394040909,\"type\":\"update/order_book\"}"
    "msg": "{\"channel\":\"order_book:1\",\"offset\":6962023,\"order_book\":{\"code\":0,\"asks\":[{\"price\":\"92864.0\",\"size\":\"0.97845\"},{\"price\":\"92881.5\",\"size\":\"0.00000\"},{\"price\":\"92896.8\",\"size\":\"0.05135\"},{\"price\":\"92900.0\",\"size\":\"0.00500\"},{\"price\":\"92900.8\",\"size\":\"0.49855\"},{\"price\":\"92902.1\",\"size\":\"0.02828\"},{\"price\":\"92932.3\",\"size\":\"0.38767\"},{\"price\":\"92937.9\",\"size\":\"0.38767\"},{\"price\":\"92989.6\",\"size\":\"0.51355\"}],\"bids\":[{\"price\":\"92863.9\",\"size\":\"4.38391\"},{\"price\":\"92861.2\",\"size\":\"0.00000\"},{\"price\":\"92855.1\",\"size\":\"3.19358\"},{\"price\":\"92831.2\",\"size\":\"0.05102\"},{\"price\":\"92825.6\",\"size\":\"0.05102\"},{\"price\":\"92808.7\",\"size\":\"0.10205\"},{\"price\":\"92792.8\",\"size\":\"0.00000\"},{\"price\":\"92763.7\",\"size\":\"0.00000\"},{\"price\":\"92752.5\",\"size\":\"0.51023\"}],\"offset\":6962023,\"nonce\":3691008203},\"timestamp\":1765394040913,\"type\":\"update/order_book\"}"
    "msg": "{\"channel\":\"order_book:1\",\"offset\":6962025,\"order_book\":{\"code\":0,\"asks\":[{\"price\":\"92900.8\",\"size\":\"0.38767\"}],\"bids\":[{\"price\":\"92855.1\",\"size\":\"3.13824\"},{\"price\":\"92854.8\",\"size\":\"0.00500\"},{\"price\":\"92841.7\",\"size\":\"0.00000\"},{\"price\":\"92816.6\",\"size\":\"0.12098\"}],\"offset\":6962025,\"nonce\":3691008205},\"timestamp\":1765394040924,\"type\":\"update/order_book\"}"
    "msg": "{\"channel\":\"order_book:1\",\"offset\":6962026,\"order_book\":{\"code\":0,\"asks\":[{\"price\":\"92876.6\",\"size\":\"0.02834\"},{\"price\":\"92902.4\",\"size\":\"0.00000\"},{\"price\":\"92904.0\",\"size\":\"0.12064\"},{\"price\":\"92908.7\",\"size\":\"0.00000\"}],\"bids\":[{\"price\":\"92857.9\",\"size\":\"0.00468\"},{\"price\":\"92855.2\",\"size\":\"0.29488\"},{\"price\":\"92852.8\",\"size\":\"0.00000\"},{\"price\":\"92849.3\",\"size\":\"0.01047\"},{\"price\":\"92841.4\",\"size\":\"0.00108\"},{\"price\":\"92833.2\",\"size\":\"0.00000\"}],\"offset\":6962026,\"nonce\":3691008206},\"timestamp\":1765394040931,\"type\":\"update/order_book\"}"
    "msg": "{\"channel\":\"order_book:1\",\"offset\":6962027,\"order_book\":{\"code\":0,\"asks\":[{\"price\":\"92876.6\",\"size\":\"0.00000\"},{\"price\":\"92883.6\",\"size\":\"0.00000\"},{\"price\":\"92889.4\",\"size\":\"0.00000\"},{\"price\":\"92904.3\",\"size\":\"0.00000\"},{\"price\":\"92916.7\",\"size\":\"0.00214\"},{\"price\":\"93179.6\",\"size\":\"0.00000\"}],\"bids\":[{\"price\":\"92855.2\",\"size\":\"0.32393\"}],\"offset\":6962027,\"nonce\":3691008207},\"timestamp\":1765394040936,\"type\":\"update/order_book\"}"
    "msg": "{\"channel\":\"order_book:1\",\"offset\":6962028,\"order_book\":{\"code\":0,\"asks\":[{\"price\":\"92889.0\",\"size\":\"0.00000\"},{\"price\":\"92898.4\",\"size\":\"0.08812\"},{\"price\":\"92904.9\",\"size\":\"0.00307\"}],\"bids\":[{\"price\":\"92859.8\",\"size\":\"0.09812\"},{\"price\":\"92855.2\",\"size\":\"0.23042\"},{\"price\":\"92844.6\",\"size\":\"0.36738\"}],\"offset\":6962028,\"nonce\":3691008208},\"timestamp\":1765394040943,\"type\":\"update/order_book\"}"
    "msg": "{\"channel\":\"order_book:1\",\"offset\":6962029,\"order_book\":{\"code\":0,\"asks\":[{\"price\":\"92864.0\",\"size\":\"0.97745\"},{\"price\":\"92875.4\",\"size\":\"0.00000\"},{\"price\":\"92882.9\",\"size\":\"0.10780\"},{\"price\":\"92931.9\",\"size\":\"0.24872\"}],\"bids\":[{\"price\":\"92855.2\",\"size\":\"0.20227\"},{\"price\":\"92839.6\",\"size\":\"0.00000\"}],\"offset\":6962029,\"nonce\":3691008209},\"timestamp\":1765394040949,\"type\":\"update/order_book\"}"
    "msg": "{\"channel\":\"order_book:1\",\"offset\":6962030,\"order_book\":{\"code\":0,\"asks\":[{\"price\":\"92864.0\",\"size\":\"0.97545\"},{\"price\":\"92905.5\",\"size\":\"0.04171\"},{\"price\":\"92914.7\",\"size\":\"0.05192\"},{\"price\":\"92917.9\",\"size\":\"0.12233\"},{\"price\":\"92932.7\",\"size\":\"0.37536\"}],\"bids\":[{\"price\":\"92863.9\",\"size\":\"4.46495\"},{\"price\":\"92855.1\",\"size\":\"2.06066\"},{\"price\":\"92853.6\",\"size\":\"0.00000\"},{\"price\":\"92713.1\",\"size\":\"0.00000\"}],\"offset\":6962030,\"nonce\":3691008210},\"timestamp\":1765394040956,\"type\":\"update/order_book\"}"
    "msg": "{\"channel\":\"order_book:1\",\"offset\":6962031,\"order_book\":{\"code\":0,\"asks\":[{\"price\":\"92864.0\",\"size\":\"0.95542\"},{\"price\":\"92894.6\",\"size\":\"1.07758\"},{\"price\":\"92896.2\",\"size\":\"2.69396\"},{\"price\":\"92908.7\",\"size\":\"0.05192\"},{\"price\":\"92923.7\",\"size\":\"0.31944\"},{\"price\":\"92925.9\",\"size\":\"0.02094\"},{\"price\":\"92934.2\",\"size\":\"0.00000\"},{\"price\":\"92941.2\",\"size\":\"0.00000\"},{\"price\":\"92948.2\",\"size\":\"0.00000\"},{\"price\":\"92949.4\",\"size\":\"2.29661\"},{\"price\":\"92956.4\",\"size\":\"3.04434\"},{\"price\":\"92963.4\",\"size\":\"7.21027\"}],\"bids\":[{\"price\":\"92863.9\",\"size\":\"4.61289\"},{\"price\":\"92862.4\",\"size\":\"0.00468\"},{\"price\":\"92857.9\",\"size\":\"0.00000\"},{\"price\":\"92774.4\",\"size\":\"0.31944\"}],\"offset\":6962031,\"nonce\":3691008211},\"timestamp\":1765394040967,\"type\":\"update/order_book\"}"
    "msg": "{\"channel\":\"order_book:1\",\"offset\":6962032,\"order_book\":{\"code\":0,\"asks\":[{\"price\":\"92894.6\",\"size\":\"0.00000\"}],\"bids\":[{\"price\":\"92855.2\",\"size\":\"0.14416\"},{\"price\":\"92846.9\",\"size\":\"5.21430\"},{\"price\":\"92839.9\",\"size\":\"6.53100\"},{\"price\":\"92837.4\",\"size\":\"0.02578\"},{\"price\":\"92833.0\",\"size\":\"15.46815\"},{\"price\":\"92830.4\",\"size\":\"0.00000\"},{\"price\":\"92823.4\",\"size\":\"0.00000\"}],\"offset\":6962032,\"nonce\":3691008212},\"timestamp\":1765394041000,\"type\":\"update/order_book\"}"
    "msg": "{\"channel\":\"order_book:1\",\"offset\":6962033,\"order_book\":{\"code\":0,\"asks\":[{\"price\":\"92883.7\",\"size\":\"0.10780\"},{\"price\":\"92915.4\",\"size\":\"0.34154\"},{\"price\":\"92992.2\",\"size\":\"0.00000\"}],\"bids\":[{\"price\":\"92863.9\",\"size\":\"4.64194\"},{\"price\":\"92855.5\",\"size\":\"0.00500\"},{\"price\":\"92855.2\",\"size\":\"0.11788\"},{\"price\":\"92855.1\",\"size\":\"2.04066\"}],\"offset\":6962033,\"nonce\":3691008213},\"timestamp\":1765394041006,\"type\":\"update/order_book\"}"
    "msg": "{\"channel\":\"order_book:1\",\"offset\":6962035,\"order_book\":{\"code\":0,\"asks\":[{\"price\":\"92927.5\",\"size\":\"0.10557\"},{\"price\":\"93043.1\",\"size\":\"0.00000\"}],\"bids\":[],\"offset\":6962035,\"nonce\":3691008215},\"timestamp\":1765394041028,\"type\":\"update/order_book\"}"
    "msg": "{\"channel\":\"order_book:1\",\"offset\":6962036,\"order_book\":{\"code\":0,\"asks\":[],\"bids\":[{\"price\":\"92863.9\",\"size\":\"4.92689\"},{\"price\":\"92862.4\",\"size\":\"0.00468\"},{\"price\":\"92860.6\",\"size\":\"0.10780\"},{\"price\":\"92855.5\",\"size\":\"0.00000\"},{\"price\":\"92855.2\",\"size\":\"0.11088\"},{\"price\":\"92854.0\",\"size\":\"0.00000\"},{\"price\":\"92851.8\",\"size\":\"0.02000\"},{\"price\":\"92846.9\",\"size\":\"5.21538\"},{\"price\":\"92841.4\",\"size\":\"0.00000\"}],\"offset\":6962036,\"nonce\":3691008216},\"timestamp\":1765394041050,\"type\":\"update/order_book\"}"
    "msg": "{\"channel\":\"order_book:1\",\"offset\":6962037,\"order_book\":{\"code\":0,\"asks\":[{\"price\":\"92882.9\",\"size\":\"0.00000\"},{\"price\":\"92890.0\",\"size\":\"0.02834\"},{\"price\":\"92895.1\",\"size\":\"0.05382\"},{\"price\":\"92897.1\",\"size\":\"0.02465\"},{\"price\":\"92943.2\",\"size\":\"0.50000\"}],\"bids\":[{\"price\":\"92863.9\",\"size\":\"8.69843\"},{\"price\":\"92862.4\",\"size\":\"0.00000\"},{\"price\":\"92861.4\",\"size\":\"0.00468\"},{\"price\":\"92859.6\",\"size\":\"0.05384\"},{\"price\":\"92833.4\",\"size\":\"0.01077\"}],\"offset\":6962037,\"nonce\":3691008217},\"timestamp\":1765394041060,\"type\":\"update/order_book\"}"
    "msg": "{\"channel\":\"order_book:1\",\"offset\":6962038,\"order_book\":{\"code\":0,\"asks\":[{\"price\":\"92897.5\",\"size\":\"0.38767\"},{\"price\":\"92923.7\",\"size\":\"0.00000\"},{\"price\":\"92925.9\",\"size\":\"0.00000\"},{\"price\":\"92956.8\",\"size\":\"0.00000\"},{\"price\":\"92970.6\",\"size\":\"0.00000\"},{\"price\":\"92984.4\",\"size\":\"0.00000\"},{\"price\":\"93163.8\",\"size\":\"14.95059\"},{\"price\":\"93177.6\",\"size\":\"14.95059\"},{\"price\":\"93191.4\",\"size\":\"14.95059\"}],\"bids\":[{\"price\":\"92861.4\",\"size\":\"0.00468\"},{\"price\":\"92854.5\",\"size\":\"0.50000\"},{\"price\":\"92852.6\",\"size\":\"0.10780\"},{\"price\":\"92845.4\",\"size\":\"0.00000\"},{\"price\":\"92755.0\",\"size\":\"0.00538\"},{\"price\":\"92716.5\",\"size\":\"0.00000\"}],\"offset\":6962038,\"nonce\":3691008218},\"timestamp\":1765394041069,\"type\":\"update/order_book\"}"
    "msg": "{\"channel\":\"order_book:1\",\"offset\":6962039,\"order_book\":{\"code\":0,\"asks\":[{\"price\":\"92888.3\",\"size\":\"0.03767\"},{\"price\":\"92998.7\",\"size\":\"0.00538\"}],\"bids\":[],\"offset\":6962039,\"nonce\":3691008219},\"timestamp\":1765394041084,\"type\":\"update/order_book\"}"
    "msg": "{\"channel\":\"order_book:1\",\"offset\":6962040,\"order_book\":{\"code\":0,\"asks\":[{\"price\":\"92885.6\",\"size\":\"0.10780\"},{\"price\":\"92949.4\",\"size\":\"0.00000\"},{\"price\":\"92952.3\",\"size\":\"2.29653\"}],\"bids\":[{\"price\":\"92856.5\",\"size\":\"0.02075\"},{\"price\":\"92852.6\",\"size\":\"4.69183\"},{\"price\":\"92846.9\",\"size\":\"0.63322\"}],\"offset\":6962040,\"nonce\":3691008220},\"timestamp\":1765394041089,\"type\":\"update/order_book\"}"
    "msg": "{\"channel\":\"order_book:1\",\"offset\":6962041,\"order_book\":{\"code\":0,\"asks\":[{\"price\":\"92886.7\",\"size\":\"0.00020\"},{\"price\":\"92900.8\",\"size\":\"0.00000\"}],\"bids\":[{\"price\":\"92801.3\",\"size\":\"0.31937\"},{\"price\":\"92778.5\",\"size\":\"0.00000\"},{\"price\":\"92765.3\",\"size\":\"0.00000\"}],\"offset\":6962041,\"nonce\":3691008221},\"timestamp\":1765394041095,\"type\":\"update/order_book\"}"
    "msg": "{\"channel\":\"order_book:1\",\"offset\":6962042,\"order_book\":{\"code\":0,\"asks\":[{\"price\":\"92883.7\",\"size\":\"0.00000\"},{\"price\":\"92885.1\",\"size\":\"0.10780\"},{\"price\":\"92890.0\",\"size\":\"0.00000\"},{\"price\":\"92896.2\",\"size\":\"0.00000\"},{\"price\":\"92906.3\",\"size\":\"0.00000\"},{\"price\":\"92913.3\",\"size\":\"0.00000\"}],\"bids\":[{\"price\":\"92861.8\",\"size\":\"0.66571\"},{\"price\":\"92840.5\",\"size\":\"0.08000\"}],\"offset\":6962042,\"nonce\":3691008222},\"timestamp\":1765394041096,\"type\":\"update/order_book\"}"
    "msg": "{\"channel\":\"order_book:1\",\"offset\":6962043,\"order_book\":{\"code\":0,\"asks\":[{\"price\":\"92885.1\",\"size\":\"0.00000\"},{\"price\":\"92897.6\",\"size\":\"0.00000\"},{\"price\":\"92917.4\",\"size\":\"0.00000\"}],\"bids\":[{\"price\":\"92850.7\",\"size\":\"0.11629\"},{\"price\":\"92811.5\",\"size\":\"0.02093\"},{\"price\":\"92788.0\",\"size\":\"0.00000\"}],\"offset\":6962043,\"nonce\":3691008223},\"timestamp\":1765394041099,\"type\":\"update/order_book\"}"
    "msg": "{\"channel\":\"order_book:1\",\"offset\":6962044,\"order_book\":{\"code\":0,\"asks\":[{\"price\":\"92864.0\",\"size\":\"0.95542\"},{\"price\":\"92885.6\",\"size\":\"0.00000\"},{\"price\":\"92904.9\",\"size\":\"0.00000\"},{\"price\":\"92923.0\",\"size\":\"0.00000\"},{\"price\":\"92946.5\",\"size\":\"0.02093\"},{\"price\":\"92965.1\",\"size\":\"0.00020\"}],\"bids\":[{\"price\":\"92863.9\",\"size\":\"7.62085\"},{\"price\":\"92861.2\",\"size\":\"0.10780\"},{\"price\":\"92859.4\",\"size\":\"0.08000\"},{\"price\":\"92852.8\",\"size\":\"0.13460\"},{\"price\":\"92852.6\",\"size\":\"4.58403\"},{\"price\":\"92844.8\",\"size\":\"0.13460\"},{\"price\":\"92833.4\",\"size\":\"0.00000\"},{\"price\":\"92821.8\",\"size\":\"0.00000\"},{\"price\":\"92816.2\",\"size\":\"0.00000\"},{\"price\":\"92815.4\",\"size\":\"0.00000\"},{\"price\":\"92802.1\",\"size\":\"0.00000\"},{\"price\":\"92793.8\",\"size\":\"0.00000\"},{\"price\":\"92738.8\",\"size\":\"0.00269\"},{\"price\":\"92703.9\",\"size\":\"0.00000\"}],\"offset\":6962044,\"nonce\":3691008224},\"timestamp\":1765394041108,\"type\":\"update/order_book\"}"
    "msg": "{\"channel\":\"order_book:1\",\"offset\":6962045,\"order_book\":{\"code\":0,\"asks\":[{\"price\":\"92943.5\",\"size\":\"0.38767\"},{\"price\":\"92973.1\",\"size\":\"0.00020\"},{\"price\":\"92981.1\",\"size\":\"0.00020\"},{\"price\":\"92989.1\",\"size\":\"0.00020\"},{\"price\":\"92997.1\",\"size\":\"0.00020\"},{\"price\":\"93005.1\",\"size\":\"0.00020\"},{\"price\":\"93044.6\",\"size\":\"0.00000\"},{\"price\":\"93070.3\",\"size\":\"2.37568\"}],\"bids\":[{\"price\":\"92649.1\",\"size\":\"0.00000\"}],\"offset\":6962045,\"nonce\":3691008225},\"timestamp\":1765394041110,\"type\":\"update/order_book\"}"
    "msg": "{\"channel\":\"order_book:1\",\"offset\":6962046,\"order_book\":{\"code\":0,\"asks\":[{\"price\":\"92898.4\",\"size\":\"0.00000\"},{\"price\":\"92898.7\",\"size\":\"1.07758\"},{\"price\":\"92918.8\",\"size\":\"2.15445\"},{\"price\":\"92951.3\",\"size\":\"8.07918\"},{\"price\":\"93013.1\",\"size\":\"0.00020\"}],\"bids\":[{\"price\":\"92863.9\",\"size\":\"7.62063\"},{\"price\":\"92859.8\",\"size\":\"0.00000\"},{\"price\":\"92856.9\",\"size\":\"0.00214\"}],\"offset\":6962046,\"nonce\":3691008226},\"timestamp\":1765394041117,\"type\":\"update/order_book\"}"
    "msg": "{\"channel\":\"order_book:1\",\"offset\":6962048,\"order_book\":{\"code\":0,\"asks\":[{\"price\":\"92895.1\",\"size\":\"0.00000\"}],\"bids\":[{\"price\":\"92863.9\",\"size\":\"7.39102\"},{\"price\":\"92863.8\",\"size\":\"0.10780\"},{\"price\":\"92860.6\",\"size\":\"0.00000\"},{\"price\":\"92859.6\",\"size\":\"0.00000\"},{\"price\":\"92840.3\",\"size\":\"0.01077\"}],\"offset\":6962048,\"nonce\":3691008228},\"timestamp\":1765394041127,\"type\":\"update/order_book\"}"
    "msg": "{\"channel\":\"order_book:1\",\"offset\":6962049,\"order_book\":{\"code\":0,\"asks\":[{\"price\":\"92897.5\",\"size\":\"0.00000\"},{\"price\":\"92933.4\",\"size\":\"0.00000\"},{\"price\":\"93219.3\",\"size\":\"2.56283\"}],\"bids\":[],\"offset\":6962049,\"nonce\":3691008229},\"timestamp\":1765394041129,\"type\":\"update/order_book\"}"
    "msg": "{\"channel\":\"order_book:1\",\"offset\":6962050,\"order_book\":{\"code\":0,\"asks\":[],\"bids\":[{\"price\":\"92855.4\",\"size\":\"0.00108\"},{\"price\":\"92846.9\",\"size\":\"0.63214\"},{\"price\":\"92531.7\",\"size\":\"0.00000\"}],\"offset\":6962050,\"nonce\":3691008230},\"timestamp\":1765394041137,\"type\":\"update/order_book\"}"
    "msg": "{\"channel\":\"order_book:1\",\"offset\":6962051,\"order_book\":{\"code\":0,\"asks\":[{\"price\":\"92888.3\",\"size\":\"0.00000\"}],\"bids\":[],\"offset\":6962051,\"nonce\":3691008232},\"timestamp\":1765394041146,\"type\":\"update/order_book\"}"
    "msg": "{\"channel\":\"order_book:1\",\"offset\":6962052,\"order_book\":{\"code\":0,\"asks\":[{\"price\":\"92864.0\",\"size\":\"0.95127\"},{\"price\":\"92952.3\",\"size\":\"0.00000\"},{\"price\":\"92956.4\",\"size\":\"0.00000\"},{\"price\":\"92963.4\",\"size\":\"0.00000\"},{\"price\":\"92972.4\",\"size\":\"2.29601\"},{\"price\":\"92979.4\",\"size\":\"3.04355\"},{\"price\":\"92986.4\",\"size\":\"7.20840\"}],\"bids\":[{\"price\":\"92861.1\",\"size\":\"4.97391\"},{\"price\":\"92852.6\",\"size\":\"0.00000\"},{\"price\":\"92846.9\",\"size\":\"0.00000\"}],\"offset\":6962052,\"nonce\":3691008233},\"timestamp\":1765394041154,\"type\":\"update/order_book\"}"
    "msg": "{\"channel\":\"order_book:1\",\"offset\":6962053,\"order_book\":{\"code\":0,\"asks\":[{\"price\":\"92886.7\",\"size\":\"0.00000\"},{\"price\":\"92905.2\",\"size\":\"0.38767\"},{\"price\":\"92910.8\",\"size\":\"0.38767\"},{\"price\":\"93076.2\",\"size\":\"0.00000\"},{\"price\":\"93209.1\",\"size\":\"0.00000\"}],\"bids\":[{\"price\":\"92854.1\",\"size\":\"6.53000\"},{\"price\":\"92847.1\",\"size\":\"15.46580\"},{\"price\":\"92839.9\",\"size\":\"0.00000\"},{\"price\":\"92833.0\",\"size\":\"0.00000\"},{\"price\":\"92533.7\",\"size\":\"0.00000\"}],\"offset\":6962053,\"nonce\":3691008234},\"timestamp\":1765394041158,\"type\":\"update/order_book\"}"
    "msg": "{\"channel\":\"order_book:1\",\"offset\":6962054,\"order_book\":{\"code\":0,\"asks\":[{\"price\":\"92894.6\",\"size\":\"0.10780\"},{\"price\":\"92900.3\",\"size\":\"0.10780\"},{\"price\":\"92901.9\",\"size\":\"2.69396\"},{\"price\":\"92904.0\",\"size\":\"0.00000\"},{\"price\":\"92915.3\",\"size\":\"0.38767\"},{\"price\":\"92916.8\",\"size\":\"0.00000\"},{\"price\":\"92944.7\",\"size\":\"0.31939\"}],\"bids\":[],\"offset\":6962054,\"nonce\":3691008235},\"timestamp\":1765394041166,\"type\":\"update/order_book\"}"
    "msg": "{\"channel\":\"order_book:1\",\"offset\":6962055,\"order_book\":{\"code\":0,\"asks\":[{\"price\":\"92897.1\",\"size\":\"0.00000\"},{\"price\":\"92898.7\",\"size\":\"0.00000\"},{\"price\":\"92910.4\",\"size\":\"0.00000\"},{\"price\":\"92920.9\",\"size\":\"0.38767\"}],\"bids\":[{\"price\":\"92689.1\",\"size\":\"0.10769\"}],\"offset\":6962055,\"nonce\":3691008236},\"timestamp\":1765394041171,\"type\":\"update/order_book\"}"
    "msg": "{\"channel\":\"order_book:1\",\"offset\":6962056,\"order_book\":{\"code\":0,\"asks\":[{\"price\":\"92893.1\",\"size\":\"0.10780\"},{\"price\":\"92937.5\",\"size\":\"0.31939\"},{\"price\":\"92965.1\",\"size\":\"0.13460\"},{\"price\":\"93040.1\",\"size\":\"8.07918\"}],\"bids\":[],\"offset\":6962056,\"nonce\":3691008237},\"timestamp\":1765394041176,\"type\":\"update/order_book\"}"
    "msg": "{\"channel\":\"order_book:1\",\"offset\":6962057,\"order_book\":{\"code\":0,\"asks\":[{\"price\":\"93012.3\",\"size\":\"8.07918\"},{\"price\":\"93027.5\",\"size\":\"1.20176\"}],\"bids\":[{\"price\":\"92861.4\",\"size\":\"0.00000\"},{\"price\":\"92860.2\",\"size\":\"0.00468\"},{\"price\":\"92750.3\",\"size\":\"1.24372\"}],\"offset\":6962057,\"nonce\":3691008238},\"timestamp\":1765394041182,\"type\":\"update/order_book\"}"
    "msg": "{\"channel\":\"order_book:1\",\"offset\":6962058,\"order_book\":{\"code\":0,\"asks\":[{\"price\":\"92899.6\",\"size\":\"0.02834\"},{\"price\":\"92921.1\",\"size\":\"0.00000\"},{\"price\":\"92947.5\",\"size\":\"0.31939\"},{\"price\":\"92971.2\",\"size\":\"0.00269\"},{\"price\":\"93079.0\",\"size\":\"1.79657\"}],\"bids\":[{\"price\":\"92788.2\",\"size\":\"0.31939\"},{\"price\":\"92762.2\",\"size\":\"0.00000\"}],\"offset\":6962058,\"nonce\":3691008239},\"timestamp\":1765394041187,\"type\":\"update/order_book\"}"
    "msg": "{\"channel\":\"order_book:1\",\"offset\":6962059,\"order_book\":{\"code\":0,\"asks\":[{\"price\":\"92902.1\",\"size\":\"0.00000\"},{\"price\":\"92917.9\",\"size\":\"0.00000\"}],\"bids\":[{\"price\":\"92860.2\",\"size\":\"0.00468\"},{\"price\":\"92850.7\",\"size\":\"0.00000\"},{\"price\":\"92831.9\",\"size\":\"0.00000\"},{\"price\":\"92682.0\",\"size\":\"0.78026\"}],\"offset\":6962059,\"nonce\":3691008240},\"timestamp\":1765394041190,\"type\":\"update/order_book\"}"
    "msg": "{\"channel\":\"order_book:1\",\"offset\":6962060,\"order_book\":{\"code\":0,\"asks\":[{\"price\":\"92899.6\",\"size\":\"0.00000\"}],\"bids\":[{\"price\":\"92863.9\",\"size\":\"7.50731\"},{\"price\":\"92847.0\",\"size\":\"0.11759\"}],\"offset\":6962060,\"nonce\":3691008241},\"timestamp\":1765394041197,\"type\":\"update/order_book\"}"
    "msg": "{\"channel\":\"order_book:1\",\"offset\":6962061,\"order_book\":{\"code\":0,\"asks\":[{\"price\":\"92933.0\",\"size\":\"0.00538\"},{\"price\":\"92962.3\",\"size\":\"0.11731\"},{\"price\":\"93056.8\",\"size\":\"0.00000\"}],\"bids\":[{\"price\":\"92863.9\",\"size\":\"4.80835\"},{\"price\":\"92794.9\",\"size\":\"0.00538\"}],\"offset\":6962061,\"nonce\":3691008242},\"timestamp\":1765394041212,\"type\":\"update/order_book\"}"
    "msg": "{\"channel\":\"order_book:1\",\"offset\":6962062,\"order_book\":{\"code\":0,\"asks\":[{\"price\":\"92895.9\",\"size\":\"0.03767\"},{\"price\":\"92901.9\",\"size\":\"0.00000\"},{\"price\":\"92912.4\",\"size\":\"0.00306\"},{\"price\":\"92916.7\",\"size\":\"0.00000\"},{\"price\":\"92918.8\",\"size\":\"0.00000\"},{\"price\":\"92931.9\",\"size\":\"0.13453\"},{\"price\":\"92973.1\",\"size\":\"0.13460\"},{\"price\":\"92981.1\",\"size\":\"0.13460\"},{\"price\":\"92989.1\",\"size\":\"0.13460\"},{\"price\":\"92997.1\",\"size\":\"0.13460\"},{\"price\":\"93005.1\",\"size\":\"0.13460\"}],\"bids\":[{\"price\":\"92844.6\",\"size\":\"0.00000\"}],\"offset\":6962062,\"nonce\":3691008243},\"timestamp\":1765394041216,\"type\":\"update/order_book\"}"
    "msg": "{\"channel\":\"order_book:1\",\"offset\":6962063,\"order_book\":{\"code\":0,\"asks\":[{\"price\":\"92864.0\",\"size\":\"0.67912\"},{\"price\":\"92905.2\",\"size\":\"0.00000\"},{\"price\":\"92906.4\",\"size\":\"0.00000\"},{\"price\":\"92972.3\",\"size\":\"2.29601\"},{\"price\":\"92972.4\",\"size\":\"0.00000\"}],\"bids\":[{\"price\":\"92863.7\",\"size\":\"0.00108\"},{\"price\":\"92861.1\",\"size\":\"0.38767\"},{\"price\":\"92860.2\",\"size\":\"0.00000\"},{\"price\":\"92860.1\",\"size\":\"0.00468\"},{\"price\":\"92855.4\",\"size\":\"0.00000\"},{\"price\":\"92817.7\",\"size\":\"0.00000\"}],\"offset\":6962063,\"nonce\":3691008244},\"timestamp\":1765394041217,\"type\":\"update/order_book\"}"
    "msg": "{\"channel\":\"order_book:1\",\"offset\":6962064,\"order_book\":{\"code\":0,\"asks\":[{\"price\":\"92864.0\",\"size\":\"0.27670\"},{\"price\":\"92892.3\",\"size\":\"0.00000\"},{\"price\":\"92906.1\",\"size\":\"0.00861\"},{\"price\":\"92909.8\",\"size\":\"0.08811\"},{\"price\":\"92951.3\",\"size\":\"0.00000\"}],\"bids\":[{\"price\":\"92863.8\",\"size\":\"0.20592\"},{\"price\":\"92838.0\",\"size\":\"0.00000\"},{\"price\":\"92825.2\",\"size\":\"0.00000\"}],\"offset\":6962064,\"nonce\":3691008245},\"timestamp\":1765394041221,\"type\":\"update/order_book\"}"
    "msg": "{\"channel\":\"order_book:1\",\"offset\":6962065,\"order_book\":{\"code\":0,\"asks\":[{\"price\":\"92894.6\",\"size\":\"0.00000\"},{\"price\":\"92910.8\",\"size\":\"0.00000\"},{\"price\":\"92912.4\",\"size\":\"0.00000\"},{\"price\":\"92915.3\",\"size\":\"0.00000\"}],\"bids\":[{\"price\":\"92840.3\",\"size\":\"0.00000\"}],\"offset\":6962065,\"nonce\":3691008246},\"timestamp\":1765394041223,\"type\":\"update/order_book\"}"
    "msg": "{\"channel\":\"order_book:1\",\"offset\":6962066,\"order_book\":{\"code\":0,\"asks\":[{\"price\":\"92864.0\",\"size\":\"0.27470\"}],\"bids\":[{\"price\":\"92809.8\",\"size\":\"0.00000\"}],\"offset\":6962066,\"nonce\":3691008247},\"timestamp\":1765394041229,\"type\":\"update/order_book\"}"
    "msg": "{\"channel\":\"order_book:1\",\"offset\":6962067,\"order_book\":{\"code\":0,\"asks\":[{\"price\":\"92900.3\",\"size\":\"0.00000\"},{\"price\":\"92906.6\",\"size\":\"0.05381\"},{\"price\":\"92920.9\",\"size\":\"0.00000\"},{\"price\":\"92949.1\",\"size\":\"0.38767\"}],\"bids\":[{\"price\":\"92863.9\",\"size\":\"4.86219\"}],\"offset\":6962067,\"nonce\":3691008248},\"timestamp\":1765394041232,\"type\":\"update/order_book\"}"
    "msg": "{\"channel\":\"order_book:1\",\"offset\":6962068,\"order_book\":{\"code\":0,\"asks\":[{\"price\":\"92864.0\",\"size\":\"0.23970\"},{\"price\":\"92900.0\",\"size\":\"0.00000\"},{\"price\":\"92913.0\",\"size\":\"0.02451\"},{\"price\":\"92914.8\",\"size\":\"0.00500\"}],\"bids\":[{\"price\":\"92826.4\",\"size\":\"0.00000\"}],\"offset\":6962068,\"nonce\":3691008249},\"timestamp\":1765394041237,\"type\":\"update/order_book\"}"
    "msg": "{\"channel\":\"order_book:1\",\"offset\":6962069,\"order_book\":{\"code\":0,\"asks\":[{\"price\":\"92864.0\",\"size\":\"0.13884\"},{\"price\":\"92891.9\",\"size\":\"0.00000\"},{\"price\":\"92893.1\",\"size\":\"0.00000\"},{\"price\":\"92954.7\",\"size\":\"0.38767\"}],\"bids\":[{\"price\":\"92862.8\",\"size\":\"0.10780\"},{\"price\":\"92861.2\",\"size\":\"0.00000\"},{\"price\":\"92844.0\",\"size\":\"0.01077\"},{\"price\":\"92837.4\",\"size\":\"0.00000\"},{\"price\":\"92824.7\",\"size\":\"0.00000\"},{\"price\":\"92573.0\",\"size\":\"2.64475\"}],\"offset\":6962069,\"nonce\":3691008250},\"timestamp\":1765394041246,\"type\":\"update/order_book\"}"
    "msg": "{\"channel\":\"order_book:1\",\"offset\":6962070,\"order_book\":{\"code\":0,\"asks\":[{\"price\":\"92864.0\",\"size\":\"0.00000\"},{\"price\":\"92867.2\",\"size\":\"0.00000\"},{\"price\":\"92867.7\",\"size\":\"0.00000\"},{\"price\":\"92919.1\",\"size\":\"0.12064\"},{\"price\":\"93112.7\",\"size\":\"0.78786\"},{\"price\":\"93249.6\",\"size\":\"1.05048\"}],\"bids\":[{\"price\":\"92854.5\",\"size\":\"0.00000\"},{\"price\":\"92844.0\",\"size\":\"0.00000\"},{\"price\":\"92575.6\",\"size\":\"1.03492\"}],\"offset\":6962070,\"nonce\":3691008251},\"timestamp\":1765394041248,\"type\":\"update/order_book\"}"
    "msg": "{\"channel\":\"order_book:1\",\"offset\":6962071,\"order_book\":{\"code\":0,\"asks\":[{\"price\":\"92895.9\",\"size\":\"0.01767\"},{\"price\":\"92896.8\",\"size\":\"0.00000\"},{\"price\":\"92913.0\",\"size\":\"0.00000\"},{\"price\":\"92951.9\",\"size\":\"0.00000\"}],\"bids\":[{\"price\":\"92831.2\",\"size\":\"0.00000\"},{\"price\":\"92825.6\",\"size\":\"0.00000\"},{\"price\":\"92786.9\",\"size\":\"0.00000\"}],\"offset\":6962071,\"nonce\":3691008252},\"timestamp\":1765394041254,\"type\":\"update/order_book\"}"
    "msg": "{\"channel\":\"order_book:1\",\"offset\":6962072,\"order_book\":{\"code\":0,\"asks\":[{\"price\":\"92895.9\",\"size\":\"0.00000\"},{\"price\":\"92897.7\",\"size\":\"0.00000\"},{\"price\":\"92898.0\",\"size\":\"0.10610\"},{\"price\":\"92906.1\",\"size\":\"0.00000\"},{\"price\":\"92907.5\",\"size\":\"0.02451\"},{\"price\":\"92910.8\",\"size\":\"0.02828\"},{\"price\":\"92928.3\",\"size\":\"0.12233\"},{\"price\":\"92952.8\",\"size\":\"0.00000\"}],\"bids\":[{\"price\":\"92887.7\",\"size\":\"0.01076\"},{\"price\":\"92885.1\",\"size\":\"0.02153\"},{\"price\":\"92863.9\",\"size\":\"4.87627\"},{\"price\":\"92861.1\",\"size\":\"0.38968\"},{\"price\":\"92787.6\",\"size\":\"0.00000\"},{\"price\":\"92696.9\",\"size\":\"2.04294\"}],\"offset\":6962072,\"nonce\":3691008254},\"timestamp\":1765394041259,\"type\":\"update/order_book\"}"
    "msg": "{\"channel\":\"order_book:1\",\"offset\":6962073,\"order_book\":{\"code\":0,\"asks\":[{\"price\":\"92910.8\",\"size\":\"0.00000\"},{\"price\":\"92972.3\",\"size\":\"0.00000\"},{\"price\":\"92979.4\",\"size\":\"0.00000\"},{\"price\":\"92980.5\",\"size\":\"2.29579\"},{\"price\":\"92986.4\",\"size\":\"0.00000\"},{\"price\":\"92987.5\",\"size\":\"3.04326\"},{\"price\":\"92994.4\",\"size\":\"7.20773\"}],\"bids\":[{\"price\":\"92887.7\",\"size\":\"0.00000\"},{\"price\":\"92863.9\",\"size\":\"5.10453\"},{\"price\":\"92860.1\",\"size\":\"0.00468\"},{\"price\":\"92834.9\",\"size\":\"0.00000\"}],\"offset\":6962073,\"nonce\":3691008255},\"timestamp\":1765394041264,\"type\":\"update/order_book\"}"
    "msg": "{\"channel\":\"order_book:1\",\"offset\":6962074,\"order_book\":{\"code\":0,\"asks\":[{\"price\":\"92918.7\",\"size\":\"0.11088\"}],\"bids\":[{\"price\":\"92810.7\",\"size\":\"0.00000\"}],\"offset\":6962074,\"nonce\":3691008256},\"timestamp\":1765394041268,\"type\":\"update/order_book\"}"
    "msg": "{\"channel\":\"order_book:1\",\"offset\":6962075,\"order_book\":{\"code\":0,\"asks\":[{\"price\":\"92907.5\",\"size\":\"0.00000\"},{\"price\":\"92910.9\",\"size\":\"1.07758\"},{\"price\":\"92912.3\",\"size\":\"2.69396\"},{\"price\":\"92989.6\",\"size\":\"0.00000\"}],\"bids\":[{\"price\":\"92867.1\",\"size\":\"0.38767\"},{\"price\":\"92866.2\",\"size\":\"0.00108\"},{\"price\":\"92864.9\",\"size\":\"6.52924\"},{\"price\":\"92863.7\",\"size\":\"0.00000\"},{\"price\":\"92860.1\",\"size\":\"0.00000\"},{\"price\":\"92859.5\",\"size\":\"0.00468\"},{\"price\":\"92854.1\",\"size\":\"0.00000\"},{\"price\":\"92808.7\",\"size\":\"0.00000\"}],\"offset\":6962075,\"nonce\":3691008257},\"timestamp\":1765394041273,\"type\":\"update/order_book\"}"
    "msg": "{\"channel\":\"order_book:1\",\"offset\":6962076,\"order_book\":{\"code\":0,\"asks\":[{\"price\":\"92949.7\",\"size\":\"0.11419\"}],\"bids\":[{\"price\":\"92885.1\",\"size\":\"0.01953\"},{\"price\":\"92871.8\",\"size\":\"4.58919\"},{\"price\":\"92861.0\",\"size\":\"0.02000\"},{\"price\":\"92857.9\",\"size\":\"15.46400\"},{\"price\":\"92847.1\",\"size\":\"0.00000\"},{\"price\":\"92845.3\",\"size\":\"0.01077\"}],\"offset\":6962076,\"nonce\":3691008258},\"timestamp\":1765394041276,\"type\":\"update/order_book\"}"
    "msg": "{\"channel\":\"order_book:1\",\"offset\":6962077,\"order_book\":{\"code\":0,\"asks\":[{\"price\":\"92897.7\",\"size\":\"0.10780\"},{\"price\":\"92908.6\",\"size\":\"0.02834\"},{\"price\":\"92909.8\",\"size\":\"0.00000\"},{\"price\":\"92915.9\",\"size\":\"0.00000\"},{\"price\":\"92922.3\",\"size\":\"0.00000\"}],\"bids\":[{\"price\":\"92885.1\",\"size\":\"0.01453\"},{\"price\":\"92859.5\",\"size\":\"0.00000\"},{\"price\":\"92859.1\",\"size\":\"0.00468\"},{\"price\":\"92856.9\",\"size\":\"0.00000\"},{\"price\":\"92856.8\",\"size\":\"0.00000\"},{\"price\":\"92696.9\",\"size\":\"0.00000\"}],\"offset\":6962077,\"nonce\":3691008259},\"timestamp\":1765394041280,\"type\":\"update/order_book\"}"
    "msg": "{\"channel\":\"order_book:1\",\"offset\":6962078,\"order_book\":{\"code\":0,\"asks\":[],\"bids\":[{\"price\":\"92885.1\",\"size\":\"0.00953\"},{\"price\":\"92860.2\",\"size\":\"0.02000\"},{\"price\":\"92846.2\",\"size\":\"0.00000\"}],\"offset\":6962078,\"nonce\":3691008260},\"timestamp\":1765394041286,\"type\":\"update/order_book\"}"
    "msg": "{\"channel\":\"order_book:1\",\"offset\":6962079,\"order_book\":{\"code\":0,\"asks\":[{\"price\":\"92915.8\",\"size\":\"0.38767\"},{\"price\":\"92916.8\",\"size\":\"0.00306\"},{\"price\":\"92919.4\",\"size\":\"0.03245\"},{\"price\":\"92934.4\",\"size\":\"0.00214\"}],\"bids\":[{\"price\":\"92885.1\",\"size\":\"0.00453\"},{\"price\":\"92866.8\",\"size\":\"0.03236\"},{\"price\":\"92863.9\",\"size\":\"5.13812\"},{\"price\":\"92862.2\",\"size\":\"0.36731\"},{\"price\":\"92859.1\",\"size\":\"0.00468\"},{\"price\":\"92851.9\",\"size\":\"0.30229\"},{\"price\":\"92843.0\",\"size\":\"0.05093\"},{\"price\":\"92816.6\",\"size\":\"0.00000\"}],\"offset\":6962079,\"nonce\":3691008261},\"timestamp\":1765394041292,\"type\":\"update/order_book\"}"
    "msg": "{\"channel\":\"order_book:1\",\"offset\":6962080,\"order_book\":{\"code\":0,\"asks\":[{\"price\":\"92905.3\",\"size\":\"0.00000\"},{\"price\":\"92906.6\",\"size\":\"0.00000\"},{\"price\":\"92908.6\",\"size\":\"0.00000\"},{\"price\":\"92920.8\",\"size\":\"0.38767\"}],\"bids\":[{\"price\":\"92863.9\",\"size\":\"4.17886\"},{\"price\":\"92855.1\",\"size\":\"0.38767\"},{\"price\":\"92850.5\",\"size\":\"0.00000\"},{\"price\":\"92849.1\",\"size\":\"1.22806\"},{\"price\":\"92843.5\",\"size\":\"0.00000\"},{\"price\":\"92842.3\",\"size\":\"0.00000\"},{\"price\":\"92842.2\",\"size\":\"0.00000\"},{\"price\":\"92838.2\",\"size\":\"0.00000\"}],\"offset\":6962080,\"nonce\":3691008262},\"timestamp\":1765394041294,\"type\":\"update/order_book\"}"
    "msg": "{\"channel\":\"order_book:1\",\"offset\":6962081,\"order_book\":{\"code\":0,\"asks\":[],\"bids\":[{\"price\":\"92863.9\",\"size\":\"3.12456\"},{\"price\":\"92859.1\",\"size\":\"0.00000\"},{\"price\":\"92858.4\",\"size\":\"0.00468\"},{\"price\":\"92849.1\",\"size\":\"0.38767\"}],\"offset\":6962081,\"nonce\":3691008263},\"timestamp\":1765394041298,\"type\":\"update/order_book\"}"
    "msg": "{\"channel\":\"order_book:1\",\"offset\":6962082,\"order_book\":{\"code\":0,\"asks\":[{\"price\":\"92916.8\",\"size\":\"0.00000\"},{\"price\":\"92964.1\",\"size\":\"0.08000\"}],\"bids\":[{\"price\":\"92887.8\",\"size\":\"0.98405\"},{\"price\":\"92887.7\",\"size\":\"0.90382\"},{\"price\":\"92863.9\",\"size\":\"2.80493\"},{\"price\":\"92859.9\",\"size\":\"0.00000\"},{\"price\":\"92852.3\",\"size\":\"0.00000\"},{\"price\":\"92849.1\",\"size\":\"0.00000\"},{\"price\":\"92846.3\",\"size\":\"0.00000\"},{\"price\":\"92845.3\",\"size\":\"0.00000\"},{\"price\":\"92752.5\",\"size\":\"0.00000\"}],\"offset\":6962082,\"nonce\":3691008264},\"timestamp\":1765394041300,\"type\":\"update/order_book\"}"
    "msg": "{\"channel\":\"order_book:1\",\"offset\":6962083,\"order_book\":{\"code\":0,\"asks\":[],\"bids\":[{\"price\":\"92895.7\",\"size\":\"0.38767\"},{\"price\":\"92887.8\",\"size\":\"1.00810\"},{\"price\":\"92885.1\",\"size\":\"0.91275\"},{\"price\":\"92882.6\",\"size\":\"0.08000\"},{\"price\":\"92877.8\",\"size\":\"0.11088\"},{\"price\":\"92868.5\",\"size\":\"0.11088\"},{\"price\":\"92863.9\",\"size\":\"2.80727\"},{\"price\":\"92858.4\",\"size\":\"0.00000\"},{\"price\":\"92858.3\",\"size\":\"0.39235\"},{\"price\":\"92855.1\",\"size\":\"0.00000\"},{\"price\":\"92851.7\",\"size\":\"0.02000\"},{\"price\":\"92783.9\",\"size\":\"0.00000\"},{\"price\":\"92744.4\",\"size\":\"0.00000\"}],\"offset\":6962083,\"nonce\":3691008266},\"timestamp\":1765394041309,\"type\":\"update/order_book\"}"
    "msg": "{\"channel\":\"order_book:1\",\"offset\":6962084,\"order_book\":{\"code\":0,\"asks\":[{\"price\":\"92920.1\",\"size\":\"0.02828\"},{\"price\":\"92979.0\",\"size\":\"0.94547\"}],\"bids\":[{\"price\":\"92892.9\",\"size\":\"0.38767\"},{\"price\":\"92890.1\",\"size\":\"0.38767\"},{\"price\":\"92887.8\",\"size\":\"1.03716\"},{\"price\":\"92887.3\",\"size\":\"0.38767\"},{\"price\":\"92884.5\",\"size\":\"0.38767\"},{\"price\":\"92883.1\",\"size\":\"0.02815\"},{\"price\":\"92882.5\",\"size\":\"0.11979\"},{\"price\":\"92881.0\",\"size\":\"0.02628\"},{\"price\":\"92863.9\",\"size\":\"2.75343\"},{\"price\":\"92847.1\",\"size\":\"0.01077\"},{\"price\":\"92836.1\",\"size\":\"0.12098\"},{\"price\":\"92814.4\",\"size\":\"0.00000\"},{\"price\":\"92813.4\",\"size\":\"0.87813\"},{\"price\":\"92805.1\",\"size\":\"0.00000\"}],\"offset\":6962084,\"nonce\":3691008267},\"timestamp\":1765394041313,\"type\":\"update/order_book\"}"
    "msg": "{\"channel\":\"order_book:1\",\"offset\":6962085,\"order_book\":{\"code\":0,\"asks\":[{\"price\":\"92897.7\",\"size\":\"0.00000\"},{\"price\":\"92931.9\",\"size\":\"0.70441\"}],\"bids\":[{\"price\":\"92881.7\",\"size\":\"0.38767\"},{\"price\":\"92867.7\",\"size\":\"0.00500\"},{\"price\":\"92863.8\",\"size\":\"0.10780\"},{\"price\":\"92858.3\",\"size\":\"0.39235\"},{\"price\":\"92854.8\",\"size\":\"0.00000\"},{\"price\":\"92847.1\",\"size\":\"0.00000\"},{\"price\":\"92803.8\",\"size\":\"0.31933\"},{\"price\":\"92774.4\",\"size\":\"0.00000\"}],\"offset\":6962085,\"nonce\":3691008268},\"timestamp\":1765394041316,\"type\":\"update/order_book\"}"
    "msg": "{\"channel\":\"order_book:1\",\"offset\":6962086,\"order_book\":{\"code\":0,\"asks\":[{\"price\":\"92917.4\",\"size\":\"0.02451\"},{\"price\":\"92980.5\",\"size\":\"0.00000\"},{\"price\":\"92980.6\",\"size\":\"2.29580\"}],\"bids\":[{\"price\":\"92885.1\",\"size\":\"0.90822\"},{\"price\":\"92876.7\",\"size\":\"4.59092\"},{\"price\":\"92871.8\",\"size\":\"0.00000\"}],\"offset\":6962086,\"nonce\":3691008269},\"timestamp\":1765394041321,\"type\":\"update/order_book\"}"
    "msg": "{\"channel\":\"order_book:1\",\"offset\":6962087,\"order_book\":{\"code\":0,\"asks\":[{\"price\":\"92908.3\",\"size\":\"0.03766\"},{\"price\":\"92934.3\",\"size\":\"2.15445\"},{\"price\":\"92966.8\",\"size\":\"8.07918\"}],\"bids\":[{\"price\":\"92884.5\",\"size\":\"0.40920\"},{\"price\":\"92872.0\",\"size\":\"0.10780\"},{\"price\":\"92863.9\",\"size\":\"2.71006\"},{\"price\":\"92862.8\",\"size\":\"0.00000\"},{\"price\":\"92858.3\",\"size\":\"0.38767\"},{\"price\":\"92857.2\",\"size\":\"0.00468\"},{\"price\":\"92851.8\",\"size\":\"0.00000\"},{\"price\":\"92795.6\",\"size\":\"0.00000\"},{\"price\":\"92725.1\",\"size\":\"2.25633\"}],\"offset\":6962087,\"nonce\":3691008270},\"timestamp\":1765394041329,\"type\":\"update/order_book\"}"
    "msg": "{\"channel\":\"order_book:1\",\"offset\":6962088,\"order_book\":{\"code\":0,\"asks\":[{\"price\":\"92918.7\",\"size\":\"0.00000\"}],\"bids\":[{\"price\":\"92874.2\",\"size\":\"0.00108\"},{\"price\":\"92866.2\",\"size\":\"0.00000\"},{\"price\":\"92857.2\",\"size\":\"0.00000\"},{\"price\":\"92838.4\",\"size\":\"0.34927\"}],\"offset\":6962088,\"nonce\":3691008271},\"timestamp\":1765394041332,\"type\":\"update/order_book\"}"
    "msg": "{\"channel\":\"order_book:1\",\"offset\":6962089,\"order_book\":{\"code\":0,\"asks\":[{\"price\":\"92898.0\",\"size\":\"0.00000\"},{\"price\":\"92906.9\",\"size\":\"0.10780\"},{\"price\":\"92956.1\",\"size\":\"0.10778\"}],\"bids\":[{\"price\":\"92887.8\",\"size\":\"1.95637\"},{\"price\":\"92885.1\",\"size\":\"0.90801\"},{\"price\":\"92867.3\",\"size\":\"0.00021\"},{\"price\":\"92863.9\",\"size\":\"2.70842\"}],\"offset\":6962089,\"nonce\":3691008272},\"timestamp\":1765394041339,\"type\":\"update/order_book\"}"
    "msg": "{\"channel\":\"order_book:1\",\"offset\":6962090,\"order_book\":{\"code\":0,\"asks\":[{\"price\":\"92905.5\",\"size\":\"0.03971\"},{\"price\":\"92908.7\",\"size\":\"0.00000\"},{\"price\":\"92910.3\",\"size\":\"0.02834\"},{\"price\":\"92911.9\",\"size\":\"0.05381\"},{\"price\":\"92914.7\",\"size\":\"0.00000\"},{\"price\":\"92927.5\",\"size\":\"0.00000\"}],\"bids\":[{\"price\":\"92887.8\",\"size\":\"1.89826\"},{\"price\":\"92884.5\",\"size\":\"0.38767\"},{\"price\":\"92863.9\",\"size\":\"2.70608\"}],\"offset\":6962090,\"nonce\":3691008274},\"timestamp\":1765394041352,\"type\":\"update/order_book\"}"
    "msg": "{\"channel\":\"order_book:1\",\"offset\":6962091,\"order_book\":{\"code\":0,\"asks\":[{\"price\":\"92912.2\",\"size\":\"0.38767\"}],\"bids\":[{\"price\":\"92897.6\",\"size\":\"0.93509\"},{\"price\":\"92884.0\",\"size\":\"0.02153\"},{\"price\":\"92823.7\",\"size\":\"0.00000\"}],\"offset\":6962091,\"nonce\":3691008275},\"timestamp\":1765394041358,\"type\":\"update/order_book\"}"
    "msg": "{\"channel\":\"order_book:1\",\"offset\":6962092,\"order_book\":{\"code\":0,\"asks\":[{\"price\":\"92905.4\",\"size\":\"0.10780\"},{\"price\":\"92908.8\",\"size\":\"0.00000\"},{\"price\":\"92946.5\",\"size\":\"0.00000\"},{\"price\":\"92970.1\",\"size\":\"0.02093\"}],\"bids\":[{\"price\":\"92892.8\",\"size\":\"0.03766\"},{\"price\":\"92864.8\",\"size\":\"0.04259\"},{\"price\":\"92848.9\",\"size\":\"0.01077\"}],\"offset\":6962092,\"nonce\":3691008276},\"timestamp\":1765394041360,\"type\":\"update/order_book\"}"
    "msg": "{\"channel\":\"order_book:1\",\"offset\":6962095,\"order_book\":{\"code\":0,\"asks\":[{\"price\":\"92905.4\",\"size\":\"0.21548\"},{\"price\":\"92906.9\",\"size\":\"0.00000\"},{\"price\":\"92937.5\",\"size\":\"0.00000\"},{\"price\":\"92960.3\",\"size\":\"0.31933\"}],\"bids\":[{\"price\":\"92879.8\",\"size\":\"5.16744\"},{\"price\":\"92876.7\",\"size\":\"0.00000\"},{\"price\":\"92876.1\",\"size\":\"0.00108\"},{\"price\":\"92874.2\",\"size\":\"0.00000\"},{\"price\":\"92872.9\",\"size\":\"6.52868\"},{\"price\":\"92864.9\",\"size\":\"0.00000\"},{\"price\":\"92864.4\",\"size\":\"0.04694\"}],\"offset\":6962095,\"nonce\":3691008282},\"timestamp\":1765394041374,\"type\":\"update/order_book\"}"
    "msg": "{\"channel\":\"order_book:1\",\"offset\":6962096,\"order_book\":{\"code\":0,\"asks\":[{\"price\":\"92905.4\",\"size\":\"0.10768\"},{\"price\":\"92980.6\",\"size\":\"0.00000\"},{\"price\":\"92990.6\",\"size\":\"2.29553\"}],\"bids\":[{\"price\":\"92883.0\",\"size\":\"0.10780\"},{\"price\":\"92865.9\",\"size\":\"15.46267\"},{\"price\":\"92863.8\",\"size\":\"0.00000\"},{\"price\":\"92858.5\",\"size\":\"0.02000\"},{\"price\":\"92857.9\",\"size\":\"0.00000\"}],\"offset\":6962096,\"nonce\":3691008283},\"timestamp\":1765394041380,\"type\":\"update/order_book\"}"
    "msg": "{\"channel\":\"order_book:1\",\"offset\":6962097,\"order_book\":{\"code\":0,\"asks\":[{\"price\":\"92987.5\",\"size\":\"0.00000\"},{\"price\":\"92994.4\",\"size\":\"0.00000\"},{\"price\":\"92997.6\",\"size\":\"3.04292\"},{\"price\":\"93004.6\",\"size\":\"7.20691\"}],\"bids\":[],\"offset\":6962097,\"nonce\":3691008284},\"timestamp\":1765394041382,\"type\":\"update/order_book\"}"
    "msg": "{\"channel\":\"order_book:1\",\"offset\":6962098,\"order_book\":{\"code\":0,\"asks\":[{\"price\":\"92905.4\",\"size\":\"0.02721\"}],\"bids\":[{\"price\":\"92883.0\",\"size\":\"0.00000\"}],\"offset\":6962098,\"nonce\":3691008286},\"timestamp\":1765394041394,\"type\":\"update/order_book\"}"
    "msg": "{\"channel\":\"order_book:1\",\"offset\":6962100,\"order_book\":{\"code\":0,\"asks\":[{\"price\":\"92905.4\",\"size\":\"0.06568\"},{\"price\":\"92990.6\",\"size\":\"0.00000\"},{\"price\":\"92991.8\",\"size\":\"2.29550\"},{\"price\":\"93017.1\",\"size\":\"0.51371\"}],\"bids\":[{\"price\":\"92899.1\",\"size\":\"2.15445\"},{\"price\":\"92891.2\",\"size\":\"0.10780\"},{\"price\":\"92879.6\",\"size\":\"0.00108\"},{\"price\":\"92876.1\",\"size\":\"0.00000\"},{\"price\":\"92866.6\",\"size\":\"5.92473\"},{\"price\":\"92861.8\",\"size\":\"0.00000\"},{\"price\":\"92861.0\",\"size\":\"0.00000\"},{\"price\":\"92857.9\",\"size\":\"0.05087\"},{\"price\":\"92852.3\",\"size\":\"0.05087\"},{\"price\":\"92848.9\",\"size\":\"0.00000\"},{\"price\":\"92841.3\",\"size\":\"0.00000\"},{\"price\":\"92835.4\",\"size\":\"0.18256\"}],\"offset\":6962100,\"nonce\":3691008288},\"timestamp\":1765394041408,\"type\":\"update/order_book\"}"
    "msg": "{\"channel\":\"order_book:1\",\"offset\":6962101,\"order_book\":{\"code\":0,\"asks\":[{\"price\":\"92915.4\",\"size\":\"0.00000\"}],\"bids\":[{\"price\":\"92885.2\",\"size\":\"4.59317\"},{\"price\":\"92879.8\",\"size\":\"0.57481\"},{\"price\":\"92878.8\",\"size\":\"0.10780\"},{\"price\":\"92872.0\",\"size\":\"0.00000\"},{\"price\":\"92858.3\",\"size\":\"0.00000\"}],\"offset\":6962101,\"nonce\":3691008289},\"timestamp\":1765394041417,\"type\":\"update/order_book\"}"
    "msg": "{\"channel\":\"order_book:1\",\"offset\":6962102,\"order_book\":{\"code\":0,\"asks\":[{\"price\":\"92916.5\",\"size\":\"0.00000\"}],\"bids\":[{\"price\":\"92898.5\",\"size\":\"0.38767\"},{\"price\":\"92887.7\",\"size\":\"0.89306\"},{\"price\":\"92884.0\",\"size\":\"2.71549\"}],\"offset\":6962102,\"nonce\":3691008290},\"timestamp\":1765394041420,\"type\":\"update/order_book\"}"
    "msg": "{\"channel\":\"order_book:1\",\"offset\":6962103,\"order_book\":{\"code\":0,\"asks\":[{\"price\":\"92920.4\",\"size\":\"0.00000\"}],\"bids\":[{\"price\":\"92877.0\",\"size\":\"0.05000\"},{\"price\":\"92850.2\",\"size\":\"0.01077\"}],\"offset\":6962103,\"nonce\":3691008291},\"timestamp\":1765394041423,\"type\":\"update/order_book\"}"
    "msg": "{\"channel\":\"order_book:1\",\"offset\":6962104,\"order_book\":{\"code\":0,\"asks\":[{\"price\":\"92905.4\",\"size\":\"0.01431\"},{\"price\":\"92905.5\",\"size\":\"0.00000\"},{\"price\":\"92932.7\",\"size\":\"0.00000\"}],\"bids\":[{\"price\":\"92889.0\",\"size\":\"0.01076\"},{\"price\":\"92880.8\",\"size\":\"0.00108\"},{\"price\":\"92879.6\",\"size\":\"0.00000\"}],\"offset\":6962104,\"nonce\":3691008292},\"timestamp\":1765394041433,\"type\":\"update/order_book\"}"
    "msg": "{\"channel\":\"order_book:1\",\"offset\":6962105,\"order_book\":{\"code\":0,\"asks\":[{\"price\":\"92905.4\",\"size\":\"0.00000\"},{\"price\":\"92912.6\",\"size\":\"0.10780\"}],\"bids\":[{\"price\":\"92899.4\",\"size\":\"0.88692\"},{\"price\":\"92899.3\",\"size\":\"1.93187\"}],\"offset\":6962105,\"nonce\":3691008293},\"timestamp\":1765394041437,\"type\":\"update/order_book\"}"
    "msg": "{\"channel\":\"order_book:1\",\"offset\":6962106,\"order_book\":{\"code\":0,\"asks\":[{\"price\":\"92904.8\",\"size\":\"0.10780\"}],\"bids\":[],\"offset\":6962106,\"nonce\":3691008296},\"timestamp\":1765394041443,\"type\":\"update/order_book\"}"
    "msg": "{\"channel\":\"order_book:1\",\"offset\":6962107,\"order_book\":{\"code\":0,\"asks\":[],\"bids\":[{\"price\":\"92886.4\",\"size\":\"4.59427\"},{\"price\":\"92885.2\",\"size\":\"0.00000\"}],\"offset\":6962107,\"nonce\":3691008297},\"timestamp\":1765394041445,\"type\":\"update/order_book\"}"
    "msg": "{\"channel\":\"order_book:1\",\"offset\":6962108,\"order_book\":{\"code\":0,\"asks\":[{\"price\":\"92908.3\",\"size\":\"0.14546\"},{\"price\":\"92938.4\",\"size\":\"0.28304\"}],\"bids\":[{\"price\":\"92889.0\",\"size\":\"0.00000\"},{\"price\":\"92781.8\",\"size\":\"0.52023\"}],\"offset\":6962108,\"nonce\":3691008298},\"timestamp\":1765394041449,\"type\":\"update/order_book\"}"
    "msg": "{\"channel\":\"order_book:1\",\"offset\":6962109,\"order_book\":{\"code\":0,\"asks\":[{\"price\":\"92990.9\",\"size\":\"2.29553\"},{\"price\":\"92991.8\",\"size\":\"0.00000\"}],\"bids\":[],\"offset\":6962109,\"nonce\":3691008300},\"timestamp\":1765394041450,\"type\":\"update/order_book\"}"
    "msg": "{\"channel\":\"order_book:1\",\"offset\":6962110,\"order_book\":{\"code\":0,\"asks\":[{\"price\":\"92921.8\",\"size\":\"0.00306\"}],\"bids\":[],\"offset\":6962110,\"nonce\":3691008303},\"timestamp\":1765394041456,\"type\":\"update/order_book\"}"
    "msg": "{\"channel\":\"order_book:1\",\"offset\":6962112,\"order_book\":{\"code\":0,\"asks\":[{\"price\":\"92908.2\",\"size\":\"0.00000\"},{\"price\":\"92911.8\",\"size\":\"0.00861\"}],\"bids\":[],\"offset\":6962112,\"nonce\":3691008308},\"timestamp\":1765394041469,\"type\":\"update/order_book\"}"
    "msg": "{\"channel\":\"order_book:1\",\"offset\":6962113,\"order_book\":{\"code\":0,\"asks\":[{\"price\":\"92904.8\",\"size\":\"0.00000\"},{\"price\":\"92908.3\",\"size\":\"0.83084\"},{\"price\":\"92957.5\",\"size\":\"0.42506\"}],\"bids\":[{\"price\":\"92884.3\",\"size\":\"0.10780\"},{\"price\":\"92834.3\",\"size\":\"0.00000\"}],\"offset\":6962113,\"nonce\":3691008310},\"timestamp\":1765394041476,\"type\":\"update/order_book\"}"
    "msg": "{\"channel\":\"order_book:1\",\"offset\":6962114,\"order_book\":{\"code\":0,\"asks\":[{\"price\":\"92919.1\",\"size\":\"0.00000\"},{\"price\":\"92928.3\",\"size\":\"0.00000\"}],\"bids\":[{\"price\":\"92889.0\",\"size\":\"0.01076\"},{\"price\":\"91800.8\",\"size\":\"5.06524\"}],\"offset\":6962114,\"nonce\":3691008311},\"timestamp\":1765394041480,\"type\":\"update/order_book\"}"
    "msg": "{\"channel\":\"order_book:1\",\"offset\":6962115,\"order_book\":{\"code\":0,\"asks\":[{\"price\":\"92908.3\",\"size\":\"0.02269\"},{\"price\":\"92933.0\",\"size\":\"0.05782\"},{\"price\":\"92939.0\",\"size\":\"0.05244\"},{\"price\":\"92951.4\",\"size\":\"0.10487\"}],\"bids\":[{\"price\":\"92895.8\",\"size\":\"0.00000\"}],\"offset\":6962115,\"nonce\":3691008313},\"timestamp\":1765394041484,\"type\":\"update/order_book\"}"
    "msg": "{\"channel\":\"order_book:1\",\"offset\":6962116,\"order_book\":{\"code\":0,\"asks\":[{\"price\":\"92912.6\",\"size\":\"0.00000\"},{\"price\":\"92932.7\",\"size\":\"0.36703\"}],\"bids\":[{\"price\":\"92898.3\",\"size\":\"0.02905\"},{\"price\":\"92889.0\",\"size\":\"0.00000\"}],\"offset\":6962116,\"nonce\":3691008315},\"timestamp\":1765394041492,\"type\":\"update/order_book\"}"
    "msg": "{\"channel\":\"order_book:1\",\"offset\":6962118,\"order_book\":{\"code\":0,\"asks\":[],\"bids\":[{\"price\":\"92901.6\",\"size\":\"0.24237\"},{\"price\":\"92882.3\",\"size\":\"0.10780\"},{\"price\":\"92878.8\",\"size\":\"0.00000\"},{\"price\":\"92791.9\",\"size\":\"0.00000\"}],\"offset\":6962118,\"nonce\":3691008317},\"timestamp\":1765394041499,\"type\":\"update/order_book\"}"
    "msg": "{\"channel\":\"order_book:1\",\"offset\":6962119,\"order_book\":{\"code\":0,\"asks\":[{\"price\":\"92908.3\",\"size\":\"0.01853\"},{\"price\":\"92916.8\",\"size\":\"0.08084\"},{\"price\":\"92960.7\",\"size\":\"1.08034\"}],\"bids\":[{\"price\":\"92828.3\",\"size\":\"0.00000\"},{\"price\":\"92821.6\",\"size\":\"0.00000\"}],\"offset\":6962119,\"nonce\":3691008319},\"timestamp\":1765394041505,\"type\":\"update/order_book\"}"
    "msg": "{\"channel\":\"order_book:1\",\"offset\":6962120,\"order_book\":{\"code\":0,\"asks\":[],\"bids\":[{\"price\":\"92893.0\",\"size\":\"0.00861\"}],\"offset\":6962120,\"nonce\":3691008322},\"timestamp\":1765394041510,\"type\":\"update/order_book\"}"
    "msg": "{\"channel\":\"order_book:1\",\"offset\":6962121,\"order_book\":{\"code\":0,\"asks\":[{\"price\":\"92927.0\",\"size\":\"0.08083\"}],\"bids\":[{\"price\":\"92901.6\",\"size\":\"0.00000\"},{\"price\":\"92899.3\",\"size\":\"0.85429\"},{\"price\":\"92859.2\",\"size\":\"0.02000\"},{\"price\":\"92835.5\",\"size\":\"0.00000\"}],\"offset\":6962121,\"nonce\":3691008324},\"timestamp\":1765394041514,\"type\":\"update/order_book\"}"
    "msg": "{\"channel\":\"order_book:1\",\"offset\":6962122,\"order_book\":{\"code\":0,\"asks\":[{\"price\":\"92986.3\",\"size\":\"2.29564\"},{\"price\":\"92990.9\",\"size\":\"0.00000\"}],\"bids\":[],\"offset\":6962122,\"nonce\":3691008325},\"timestamp\":1765394041516,\"type\":\"update/order_book\"}"
    "msg": "{\"channel\":\"order_book:1\",\"offset\":6962124,\"order_book\":{\"code\":0,\"asks\":[{\"price\":\"92910.9\",\"size\":\"0.00000\"},{\"price\":\"92912.2\",\"size\":\"0.00000\"},{\"price\":\"92912.3\",\"size\":\"0.00000\"},{\"price\":\"92915.8\",\"size\":\"0.00000\"},{\"price\":\"92918.9\",\"size\":\"0.08083\"},{\"price\":\"92927.8\",\"size\":\"0.00000\"},{\"price\":\"92931.2\",\"size\":\"0.04447\"},{\"price\":\"92940.1\",\"size\":\"0.23253\"},{\"price\":\"93012.3\",\"size\":\"0.00000\"}],\"bids\":[{\"price\":\"92892.8\",\"size\":\"0.00000\"},{\"price\":\"92884.0\",\"size\":\"0.02153\"},{\"price\":\"92850.2\",\"size\":\"0.00000\"}],\"offset\":6962124,\"nonce\":3691008328},\"timestamp\":1765394041543,\"type\":\"update/order_book\"}"
    "msg": "{\"channel\":\"order_book:1\",\"offset\":6962125,\"order_book\":{\"code\":0,\"asks\":[{\"price\":\"92910.3\",\"size\":\"0.00000\"},{\"price\":\"92938.7\",\"size\":\"0.12233\"}],\"bids\":[{\"price\":\"92901.6\",\"size\":\"0.98927\"},{\"price\":\"92884.0\",\"size\":\"0.00000\"},{\"price\":\"92861.1\",\"size\":\"0.00000\"}],\"offset\":6962125,\"nonce\":3691008329},\"timestamp\":1765394041549,\"type\":\"update/order_book\"}"
    "msg": "{\"channel\":\"order_book:1\",\"offset\":6962126,\"order_book\":{\"code\":0,\"asks\":[{\"price\":\"92908.2\",\"size\":\"0.05127\"},{\"price\":\"92908.3\",\"size\":\"0.00000\"},{\"price\":\"92911.9\",\"size\":\"0.00000\"},{\"price\":\"92920.8\",\"size\":\"0.08810\"},{\"price\":\"92921.8\",\"size\":\"0.00000\"},{\"price\":\"92922.7\",\"size\":\"0.10780\"},{\"price\":\"92923.9\",\"size\":\"0.00000\"},{\"price\":\"92934.4\",\"size\":\"0.00000\"},{\"price\":\"92961.5\",\"size\":\"0.11088\"},{\"price\":\"92986.3\",\"size\":\"0.00000\"},{\"price\":\"92987.4\",\"size\":\"0.00000\"},{\"price\":\"92998.2\",\"size\":\"0.00000\"},{\"price\":\"92998.9\",\"size\":\"2.29532\"},{\"price\":\"93004.6\",\"size\":\"0.00000\"},{\"price\":\"93012.0\",\"size\":\"0.00000\"},{\"price\":\"93025.8\",\"size\":\"0.00000\"},{\"price\":\"93205.2\",\"size\":\"14.94321\"},{\"price\":\"93219.0\",\"size\":\"14.94321\"},{\"price\":\"93232.8\",\"size\":\"14.94321\"}],\"bids\":[{\"price\":\"92902.1\",\"size\":\"0.38767\"},{\"price\":\"92889.2\",\"size\":\"0.01076\"},{\"price\":\"92887.4\",\"size\":\"0.02153\"},{\"price\":\"92876.4\",\"size\":\"0.00000\"},{\"price\":\"92864.0\",\"size\":\"0.00000\"},{\"price\":\"92863.9\",\"size\":\"2.34414\"},{\"price\":\"92862.2\",\"size\":\"0.00000\"},{\"price\":\"92851.8\",\"size\":\"0.01077\"},{\"price\":\"92846.4\",\"size\":\"15.07142\"},{\"price\":\"92811.5\",\"size\":\"0.00000\"},{\"price\":\"92639.4\",\"size\":\"0.00000\"}],\"offset\":6962126,\"nonce\":3691008331},\"timestamp\":1765394041560,\"type\":\"update/order_book\"}"
    "msg": "{\"channel\":\"order_book:1\",\"offset\":6962127,\"order_book\":{\"code\":0,\"asks\":[{\"price\":\"92908.2\",\"size\":\"0.05044\"},{\"price\":\"92914.8\",\"size\":\"0.00000\"},{\"price\":\"92920.8\",\"size\":\"0.00000\"},{\"price\":\"92925.5\",\"size\":\"0.00500\"},{\"price\":\"92982.9\",\"size\":\"0.08000\"},{\"price\":\"92997.6\",\"size\":\"0.00000\"},{\"price\":\"92998.7\",\"size\":\"0.00000\"},{\"price\":\"93005.9\",\"size\":\"3.04263\"},{\"price\":\"93012.9\",\"size\":\"7.20623\"},{\"price\":\"93070.3\",\"size\":\"0.00000\"}],\"bids\":[{\"price\":\"92904.9\",\"size\":\"0.38767\"},{\"price\":\"92904.0\",\"size\":\"0.00215\"},{\"price\":\"92901.7\",\"size\":\"1.80449\"},{\"price\":\"92899.7\",\"size\":\"0.02905\"},{\"price\":\"92898.3\",\"size\":\"0.00000\"},{\"price\":\"92889.1\",\"size\":\"0.00000\"},{\"price\":\"92887.9\",\"size\":\"0.00000\"},{\"price\":\"92887.4\",\"size\":\"0.00000\"},{\"price\":\"92886.4\",\"size\":\"4.59681\"},{\"price\":\"92882.8\",\"size\":\"0.00108\"},{\"price\":\"92880.8\",\"size\":\"0.00000\"},{\"price\":\"92879.4\",\"size\":\"6.52822\"},{\"price\":\"92872.9\",\"size\":\"0.00000\"},{\"price\":\"92872.5\",\"size\":\"15.46158\"},{\"price\":\"92865.9\",\"size\":\"0.00000\"},{\"price\":\"92858.5\",\"size\":\"0.00000\"},{\"price\":\"92851.8\",\"size\":\"0.00000\"},{\"price\":\"92849.3\",\"size\":\"0.00000\"},{\"price\":\"92840.6\",\"size\":\"0.00000\"},{\"price\":\"92837.1\",\"size\":\"0.00000\"},{\"price\":\"92832.6\",\"size\":\"15.07142\"},{\"price\":\"92818.8\",\"size\":\"15.07142\"},{\"price\":\"92805.0\",\"size\":\"15.07142\"},{\"price\":\"92801.3\",\"size\":\"0.00000\"},{\"price\":\"92625.6\",\"size\":\"0.00000\"},{\"price\":\"92611.8\",\"size\":\"0.00000\"},{\"price\":\"92598.0\",\"size\":\"0.00000\"}],\"offset\":6962127,\"nonce\":3691008333},\"timestamp\":1765394041566,\"type\":\"update/order_book\"}"
    "msg": "{\"channel\":\"order_book:1\",\"offset\":6962128,\"order_book\":{\"code\":0,\"asks\":[{\"price\":\"92908.2\",\"size\":\"0.00000\"},{\"price\":\"92911.8\",\"size\":\"0.00000\"},{\"price\":\"92929.0\",\"size\":\"0.00000\"},{\"price\":\"92931.9\",\"size\":\"0.13453\"},{\"price\":\"92932.8\",\"size\":\"0.08081\"},{\"price\":\"92934.3\",\"size\":\"0.00000\"},{\"price\":\"92936.0\",\"size\":\"0.08072\"}],\"bids\":[{\"price\":\"92904.0\",\"size\":\"0.00000\"},{\"price\":\"92899.7\",\"size\":\"0.00000\"},{\"price\":\"92896.2\",\"size\":\"0.02152\"},{\"price\":\"92893.5\",\"size\":\"0.02906\"},{\"price\":\"92889.2\",\"size\":\"0.00000\"},{\"price\":\"92885.1\",\"size\":\"0.00000\"},{\"price\":\"92877.0\",\"size\":\"0.00000\"},{\"price\":\"92873.9\",\"size\":\"0.11629\"},{\"price\":\"92863.9\",\"size\":\"2.22785\"},{\"price\":\"92858.5\",\"size\":\"0.01077\"},{\"price\":\"92839.1\",\"size\":\"0.00000\"},{\"price\":\"92835.9\",\"size\":\"0.00000\"},{\"price\":\"92772.6\",\"size\":\"0.00000\"}],\"offset\":6962128,\"nonce\":3691008335},\"timestamp\":1765394041575,\"type\":\"update/order_book\"}"
    "msg": "{\"channel\":\"order_book:1\",\"offset\":6962129,\"order_book\":{\"code\":0,\"asks\":[{\"price\":\"92916.8\",\"size\":\"0.00000\"},{\"price\":\"92917.4\",\"size\":\"0.00000\"},{\"price\":\"92918.0\",\"size\":\"0.10780\"},{\"price\":\"92918.9\",\"size\":\"0.00000\"},{\"price\":\"92925.8\",\"size\":\"0.38767\"},{\"price\":\"92927.0\",\"size\":\"0.00000\"},{\"price\":\"92928.2\",\"size\":\"0.00000\"},{\"price\":\"92933.0\",\"size\":\"0.05244\"},{\"price\":\"92953.9\",\"size\":\"0.00538\"}],\"bids\":[{\"price\":\"92908.1\",\"size\":\"0.86560\"},{\"price\":\"92907.6\",\"size\":\"1.07758\"},{\"price\":\"92902.1\",\"size\":\"1.35309\"},{\"price\":\"92896.2\",\"size\":\"0.00000\"},{\"price\":\"92887.8\",\"size\":\"0.97905\"},{\"price\":\"92887.7\",\"size\":\"0.00000\"},{\"price\":\"92885.2\",\"size\":\"0.00108\"},{\"price\":\"92883.1\",\"size\":\"0.00000\"},{\"price\":\"92882.8\",\"size\":\"0.00000\"},{\"price\":\"92835.4\",\"size\":\"0.10175\"},{\"price\":\"92815.8\",\"size\":\"0.00538\"},{\"price\":\"92794.9\",\"size\":\"0.00000\"},{\"price\":\"92755.0\",\"size\":\"0.00000\"}],\"offset\":6962129,\"nonce\":3691008338},\"timestamp\":1765394041583,\"type\":\"update/order_book\"}"
    "msg": "{\"channel\":\"order_book:1\",\"offset\":6962130,\"order_book\":{\"code\":0,\"asks\":[{\"price\":\"92920.1\",\"size\":\"0.00000\"},{\"price\":\"92930.0\",\"size\":\"0.08079\"},{\"price\":\"92930.4\",\"size\":\"0.00305\"},{\"price\":\"92932.8\",\"size\":\"0.00000\"},{\"price\":\"92936.0\",\"size\":\"0.00000\"},{\"price\":\"92938.7\",\"size\":\"0.00000\"},{\"price\":\"92949.7\",\"size\":\"0.00000\"},{\"price\":\"92956.1\",\"size\":\"0.00000\"},{\"price\":\"92966.8\",\"size\":\"0.00000\"}],\"bids\":[{\"price\":\"92902.6\",\"size\":\"0.03766\"},{\"price\":\"92900.0\",\"size\":\"0.01076\"},{\"price\":\"92881.0\",\"size\":\"0.00000\"},{\"price\":\"92867.1\",\"size\":\"0.00000\"},{\"price\":\"92802.6\",\"size\":\"0.00000\"}],\"offset\":6962130,\"nonce\":3691008341},\"timestamp\":1765394041587,\"type\":\"update/order_book\"}"
    "msg": "{\"channel\":\"order_book:1\",\"offset\":6962131,\"order_book\":{\"code\":0,\"asks\":[{\"price\":\"92918.0\",\"size\":\"0.00000\"},{\"price\":\"92922.6\",\"size\":\"0.38767\"},{\"price\":\"92925.1\",\"size\":\"1.07758\"},{\"price\":\"92928.1\",\"size\":\"2.69396\"},{\"price\":\"92928.6\",\"size\":\"0.00000\"},{\"price\":\"92943.1\",\"size\":\"0.08084\"},{\"price\":\"92962.3\",\"size\":\"0.00000\"},{\"price\":\"92998.9\",\"size\":\"0.00000\"},{\"price\":\"93005.9\",\"size\":\"0.00000\"},{\"price\":\"93008.3\",\"size\":\"2.29507\"},{\"price\":\"93012.9\",\"size\":\"0.00000\"},{\"price\":\"93015.3\",\"size\":\"3.04231\"},{\"price\":\"93022.3\",\"size\":\"7.20546\"}],\"bids\":[{\"price\":\"92908.1\",\"size\":\"1.25327\"},{\"price\":\"92904.6\",\"size\":\"0.00215\"},{\"price\":\"92902.2\",\"size\":\"0.02905\"},{\"price\":\"92899.5\",\"size\":\"0.10780\"},{\"price\":\"92899.1\",\"size\":\"4.84841\"},{\"price\":\"92893.7\",\"size\":\"0.02815\"},{\"price\":\"92893.6\",\"size\":\"0.11979\"},{\"price\":\"92893.5\",\"size\":\"0.00000\"},{\"price\":\"92884.3\",\"size\":\"0.00000\"},{\"price\":\"92882.5\",\"size\":\"0.00000\"},{\"price\":\"92869.1\",\"size\":\"0.11759\"},{\"price\":\"92858.5\",\"size\":\"0.00000\"}],\"offset\":6962131,\"nonce\":3691008343},\"timestamp\":1765394041589,\"type\":\"update/order_book\"}"
    "msg": "{\"channel\":\"order_book:1\",\"offset\":6962132,\"order_book\":{\"code\":0,\"asks\":[{\"price\":\"92922.7\",\"size\":\"0.00000\"},{\"price\":\"92925.1\",\"size\":\"0.00000\"},{\"price\":\"92928.1\",\"size\":\"0.00000\"},{\"price\":\"92932.3\",\"size\":\"0.00000\"},{\"price\":\"92937.9\",\"size\":\"0.00000\"},{\"price\":\"92943.5\",\"size\":\"0.00000\"},{\"price\":\"92960.2\",\"size\":\"0.38767\"}],\"bids\":[{\"price\":\"92899.1\",\"size\":\"2.69396\"},{\"price\":\"92896.2\",\"size\":\"0.02152\"},{\"price\":\"92847.0\",\"size\":\"0.00000\"}],\"offset\":6962132,\"nonce\":3691008344},\"timestamp\":1765394041593,\"type\":\"update/order_book\"}"
    "msg": "{\"channel\":\"order_book:1\",\"offset\":6962133,\"order_book\":{\"code\":0,\"asks\":[{\"price\":\"92923.2\",\"size\":\"0.00000\"},{\"price\":\"92930.0\",\"size\":\"0.00000\"},{\"price\":\"92932.7\",\"size\":\"0.00000\"},{\"price\":\"92939.0\",\"size\":\"0.05244\"},{\"price\":\"92965.8\",\"size\":\"0.38767\"}],\"bids\":[{\"price\":\"92907.6\",\"size\":\"0.00000\"},{\"price\":\"92899.1\",\"size\":\"0.00000\"},{\"price\":\"92895.5\",\"size\":\"0.02628\"},{\"price\":\"92890.8\",\"size\":\"4.59777\"},{\"price\":\"92886.5\",\"size\":\"0.11629\"},{\"price\":\"92886.4\",\"size\":\"0.00000\"},{\"price\":\"92884.5\",\"size\":\"0.00000\"},{\"price\":\"92883.7\",\"size\":\"0.00500\"},{\"price\":\"92881.7\",\"size\":\"0.00000\"},{\"price\":\"92876.9\",\"size\":\"15.46084\"},{\"price\":\"92873.5\",\"size\":\"0.00000\"},{\"price\":\"92873.3\",\"size\":\"0.00000\"},{\"price\":\"92872.5\",\"size\":\"0.00000\"},{\"price\":\"92867.7\",\"size\":\"0.00000\"}],\"offset\":6962133,\"nonce\":3691008345},\"timestamp\":1765394041600,\"type\":\"update/order_book\"}"
    "msg": "{\"channel\":\"order_book:1\",\"offset\":6962134,\"order_book\":{\"code\":0,\"asks\":[{\"price\":\"92960.7\",\"size\":\"0.00000\"}],\"bids\":[{\"price\":\"92887.3\",\"size\":\"0.00000\"},{\"price\":\"92883.9\",\"size\":\"6.52791\"},{\"price\":\"92879.4\",\"size\":\"0.00000\"},{\"price\":\"92873.9\",\"size\":\"0.00000\"}],\"offset\":6962134,\"nonce\":3691008346},\"timestamp\":1765394041607,\"type\":\"update/order_book\"}"
    "msg": "{\"channel\":\"order_book:1\",\"offset\":6962135,\"order_book\":{\"code\":0,\"asks\":[{\"price\":\"92917.7\",\"size\":\"0.03766\"},{\"price\":\"92928.2\",\"size\":\"0.02834\"},{\"price\":\"92978.9\",\"size\":\"0.11088\"},{\"price\":\"93098.6\",\"size\":\"2.03811\"}],\"bids\":[{\"price\":\"92902.6\",\"size\":\"0.00000\"},{\"price\":\"92896.2\",\"size\":\"0.00000\"},{\"price\":\"92887.9\",\"size\":\"0.11088\"},{\"price\":\"92886.6\",\"size\":\"0.00108\"},{\"price\":\"92885.2\",\"size\":\"0.00000\"},{\"price\":\"92860.8\",\"size\":\"0.01077\"}],\"offset\":6962135,\"nonce\":3691008347},\"timestamp\":1765394041612,\"type\":\"update/order_book\"}"
    "msg": "{\"channel\":\"order_book:1\",\"offset\":6962136,\"order_book\":{\"code\":0,\"asks\":[{\"price\":\"92922.6\",\"size\":\"0.00000\"},{\"price\":\"92925.8\",\"size\":\"0.00000\"},{\"price\":\"92930.4\",\"size\":\"0.00000\"},{\"price\":\"92931.2\",\"size\":\"0.00000\"},{\"price\":\"92932.2\",\"size\":\"0.08809\"},{\"price\":\"92943.1\",\"size\":\"0.00000\"},{\"price\":\"92945.1\",\"size\":\"0.12064\"},{\"price\":\"92950.5\",\"size\":\"0.00214\"}],\"bids\":[{\"price\":\"92916.7\",\"size\":\"0.38767\"},{\"price\":\"92905.0\",\"size\":\"0.10780\"},{\"price\":\"92900.5\",\"size\":\"0.09808\"},{\"price\":\"92891.2\",\"size\":\"0.00000\"},{\"price\":\"92878.5\",\"size\":\"0.36725\"},{\"price\":\"92829.3\",\"size\":\"0.00000\"}],\"offset\":6962136,\"nonce\":3691008348},\"timestamp\":1765394041615,\"type\":\"update/order_book\"}"
    "msg": "{\"channel\":\"order_book:1\",\"offset\":6962137,\"order_book\":{\"code\":0,\"asks\":[{\"price\":\"92927.1\",\"size\":\"0.05380\"},{\"price\":\"92942.9\",\"size\":\"0.00000\"},{\"price\":\"92943.7\",\"size\":\"0.02828\"}],\"bids\":[{\"price\":\"92916.7\",\"size\":\"0.37716\"},{\"price\":\"92913.9\",\"size\":\"0.38767\"},{\"price\":\"92911.1\",\"size\":\"0.38767\"},{\"price\":\"92904.6\",\"size\":\"0.00000\"},{\"price\":\"92891.6\",\"size\":\"0.05382\"},{\"price\":\"92860.8\",\"size\":\"0.00000\"},{\"price\":\"92836.1\",\"size\":\"0.00000\"}],\"offset\":6962137,\"nonce\":3691008349},\"timestamp\":1765394041618,\"type\":\"update/order_book\"}"
    "msg": "{\"channel\":\"order_book:1\",\"offset\":6962138,\"order_book\":{\"code\":0,\"asks\":[{\"price\":\"92942.7\",\"size\":\"0.38767\"},{\"price\":\"92955.7\",\"size\":\"0.12233\"},{\"price\":\"92969.6\",\"size\":\"0.11419\"},{\"price\":\"92971.4\",\"size\":\"0.38767\"}],\"bids\":[{\"price\":\"92902.8\",\"size\":\"0.02152\"},{\"price\":\"92902.2\",\"size\":\"0.00000\"},{\"price\":\"92899.5\",\"size\":\"0.21868\"},{\"price\":\"92864.4\",\"size\":\"0.05771\"}],\"offset\":6962138,\"nonce\":3691008351},\"timestamp\":1765394041626,\"type\":\"update/order_book\"}"
    "msg": "{\"channel\":\"order_book:1\",\"offset\":6962139,\"order_book\":{\"code\":0,\"asks\":[{\"price\":\"92935.6\",\"size\":\"0.02451\"},{\"price\":\"92988.7\",\"size\":\"0.11731\"},{\"price\":\"93008.3\",\"size\":\"0.00000\"},{\"price\":\"93013.7\",\"size\":\"2.29493\"}],\"bids\":[{\"price\":\"92908.2\",\"size\":\"0.02905\"},{\"price\":\"92902.8\",\"size\":\"0.00000\"},{\"price\":\"92890.8\",\"size\":\"0.00000\"},{\"price\":\"92889.4\",\"size\":\"4.59893\"},{\"price\":\"92861.4\",\"size\":\"0.02000\"},{\"price\":\"92843.6\",\"size\":\"0.00000\"}],\"offset\":6962139,\"nonce\":3691008352},\"timestamp\":1765394041630,\"type\":\"update/order_book\"}"
    "msg": "{\"channel\":\"order_book:1\",\"offset\":6962140,\"order_book\":{\"code\":0,\"asks\":[{\"price\":\"92930.5\",\"size\":\"0.10780\"},{\"price\":\"93079.0\",\"size\":\"0.00000\"}],\"bids\":[{\"price\":\"92908.1\",\"size\":\"2.20939\"},{\"price\":\"92887.8\",\"size\":\"0.00000\"},{\"price\":\"92886.6\",\"size\":\"0.00000\"},{\"price\":\"92883.8\",\"size\":\"0.00108\"},{\"price\":\"92856.5\",\"size\":\"0.00000\"},{\"price\":\"92854.8\",\"size\":\"0.12098\"}],\"offset\":6962140,\"nonce\":3691008353},\"timestamp\":1765394041638,\"type\":\"update/order_book\"}"
    "msg": "{\"channel\":\"order_book:1\",\"offset\":6962141,\"order_book\":{\"code\":0,\"asks\":[{\"price\":\"92917.7\",\"size\":\"0.00000\"},{\"price\":\"92938.3\",\"size\":\"0.38767\"},{\"price\":\"92952.2\",\"size\":\"2.15445\"}],\"bids\":[{\"price\":\"92908.2\",\"size\":\"0.05811\"},{\"price\":\"92902.8\",\"size\":\"0.02152\"}],\"offset\":6962141,\"nonce\":3691008354},\"timestamp\":1765394041642,\"type\":\"update/order_book\"}"
    "msg": "{\"channel\":\"order_book:1\",\"offset\":6962142,\"order_book\":{\"code\":0,\"asks\":[{\"price\":\"92947.5\",\"size\":\"0.00000\"},{\"price\":\"92972.4\",\"size\":\"0.31929\"}],\"bids\":[{\"price\":\"92917.6\",\"size\":\"0.93998\"},{\"price\":\"92908.2\",\"size\":\"0.02906\"},{\"price\":\"92900.5\",\"size\":\"0.00000\"},{\"price\":\"92895.8\",\"size\":\"0.10780\"},{\"price\":\"92882.3\",\"size\":\"0.00000\"}],\"offset\":6962142,\"nonce\":3691008355},\"timestamp\":1765394041643,\"type\":\"update/order_book\"}"
    "msg": "{\"channel\":\"order_book:1\",\"offset\":6962143,\"order_book\":{\"code\":0,\"asks\":[{\"price\":\"92919.3\",\"size\":\"0.05125\"},{\"price\":\"92927.5\",\"size\":\"0.10780\"},{\"price\":\"92935.8\",\"size\":\"0.00305\"},{\"price\":\"92943.2\",\"size\":\"0.00000\"},{\"price\":\"92984.7\",\"size\":\"8.07918\"},{\"price\":\"93027.5\",\"size\":\"0.00000\"},{\"price\":\"93219.3\",\"size\":\"0.00000\"}],\"bids\":[{\"price\":\"92912.4\",\"size\":\"0.00215\"},{\"price\":\"92750.3\",\"size\":\"0.00000\"}],\"offset\":6962143,\"nonce\":3691008356},\"timestamp\":1765394041654,\"type\":\"update/order_book\"}"
    "msg": "{\"channel\":\"order_book:1\",\"offset\":6962145,\"order_book\":{\"code\":0,\"asks\":[{\"price\":\"92927.1\",\"size\":\"0.00000\"}],\"bids\":[{\"price\":\"92916.7\",\"size\":\"1.22927\"},{\"price\":\"92897.6\",\"size\":\"0.00000\"},{\"price\":\"92891.6\",\"size\":\"0.00000\"}],\"offset\":6962145,\"nonce\":3691008358},\"timestamp\":1765394041660,\"type\":\"update/order_book\"}"
    "msg": "{\"channel\":\"order_book:1\",\"offset\":6962146,\"order_book\":{\"code\":0,\"asks\":[{\"price\":\"92926.4\",\"size\":\"0.10780\"},{\"price\":\"92928.0\",\"size\":\"1.07758\"},{\"price\":\"92931.0\",\"size\":\"2.69396\"},{\"price\":\"92950.0\",\"size\":\"0.11088\"}],\"bids\":[{\"price\":\"92885.7\",\"size\":\"0.00108\"},{\"price\":\"92883.8\",\"size\":\"0.00000\"},{\"price\":\"92863.9\",\"size\":\"2.19665\"}],\"offset\":6962146,\"nonce\":3691008361},\"timestamp\":1765394041668,\"type\":\"update/order_book\"}"
    "msg": "{\"channel\":\"order_book:1\",\"offset\":6962147,\"order_book\":{\"code\":0,\"asks\":[{\"price\":\"92927.4\",\"size\":\"0.03765\"},{\"price\":\"92944.7\",\"size\":\"0.00000\"},{\"price\":\"92969.2\",\"size\":\"0.31929\"}],\"bids\":[{\"price\":\"92900.0\",\"size\":\"0.00000\"},{\"price\":\"92891.3\",\"size\":\"4.60011\"},{\"price\":\"92889.4\",\"size\":\"0.00000\"}],\"offset\":6962147,\"nonce\":3691008362},\"timestamp\":1765394041670,\"type\":\"update/order_book\"}"
    "msg": "{\"channel\":\"order_book:1\",\"offset\":6962149,\"order_book\":{\"code\":0,\"asks\":[{\"price\":\"92935.5\",\"size\":\"0.38767\"}],\"bids\":[{\"price\":\"92917.6\",\"size\":\"4.97833\"},{\"price\":\"92905.0\",\"size\":\"0.21560\"},{\"price\":\"92899.5\",\"size\":\"0.11088\"},{\"price\":\"92899.3\",\"size\":\"0.00000\"}],\"offset\":6962149,\"nonce\":3691008367},\"timestamp\":1765394041683,\"type\":\"update/order_book\"}"
    "msg": "{\"channel\":\"order_book:1\",\"offset\":6962150,\"order_book\":{\"code\":0,\"asks\":[{\"price\":\"92919.4\",\"size\":\"0.00000\"}],\"bids\":[{\"price\":\"92609.0\",\"size\":\"0.87467\"}],\"offset\":6962150,\"nonce\":3691008369},\"timestamp\":1765394041695,\"type\":\"update/order_book\"}"
    "msg": "{\"channel\":\"order_book:1\",\"offset\":6962151,\"order_book\":{\"code\":0,\"asks\":[],\"bids\":[{\"price\":\"92887.1\",\"size\":\"0.00108\"},{\"price\":\"92885.7\",\"size\":\"0.00000\"},{\"price\":\"92682.0\",\"size\":\"0.00000\"}],\"offset\":6962151,\"nonce\":3691008370},\"timestamp\":1765394041697,\"type\":\"update/order_book\"}"
    "msg": "{\"channel\":\"order_book:1\",\"offset\":6962153,\"order_book\":{\"code\":0,\"asks\":[{\"price\":\"92919.3\",\"size\":\"0.00000\"},{\"price\":\"92951.4\",\"size\":\"0.68832\"}],\"bids\":[{\"price\":\"92910.6\",\"size\":\"0.10780\"},{\"price\":\"92905.0\",\"size\":\"0.10780\"},{\"price\":\"92892.7\",\"size\":\"4.60083\"},{\"price\":\"92891.3\",\"size\":\"0.00000\"}],\"offset\":6962153,\"nonce\":3691008373},\"timestamp\":1765394041712,\"type\":\"update/order_book\"}"
    "msg": "{\"channel\":\"order_book:1\",\"offset\":6962154,\"order_book\":{\"code\":0,\"asks\":[{\"price\":\"92927.5\",\"size\":\"0.00000\"},{\"price\":\"93109.8\",\"size\":\"1.81082\"}],\"bids\":[{\"price\":\"92899.7\",\"size\":\"0.50000\"},{\"price\":\"92896.7\",\"size\":\"0.57405\"},{\"price\":\"92895.1\",\"size\":\"0.05382\"}],\"offset\":6962154,\"nonce\":3691008374},\"timestamp\":1765394041716,\"type\":\"update/order_book\"}"
    "msg": "{\"channel\":\"order_book:1\",\"offset\":6962155,\"order_book\":{\"code\":0,\"asks\":[{\"price\":\"92930.6\",\"size\":\"0.05380\"}],\"bids\":[{\"price\":\"92864.4\",\"size\":\"0.04694\"},{\"price\":\"92817.1\",\"size\":\"0.31928\"},{\"price\":\"92788.2\",\"size\":\"0.00000\"}],\"offset\":6962155,\"nonce\":3691008375},\"timestamp\":1765394041719,\"type\":\"update/order_book\"}"
    "msg": "{\"channel\":\"order_book:1\",\"offset\":6962156,\"order_book\":{\"code\":0,\"asks\":[],\"bids\":[{\"price\":\"92903.1\",\"size\":\"0.01076\"},{\"price\":\"92897.3\",\"size\":\"0.10780\"},{\"price\":\"92895.8\",\"size\":\"0.00000\"}],\"offset\":6962156,\"nonce\":3691008377},\"timestamp\":1765394041732,\"type\":\"update/order_book\"}"
    "msg": "{\"channel\":\"order_book:1\",\"offset\":6962157,\"order_book\":{\"code\":0,\"asks\":[{\"price\":\"92926.4\",\"size\":\"0.00000\"},{\"price\":\"92941.0\",\"size\":\"0.03766\"},{\"price\":\"93013.7\",\"size\":\"0.00000\"},{\"price\":\"93015.3\",\"size\":\"0.00000\"},{\"price\":\"93018.1\",\"size\":\"2.29482\"},{\"price\":\"93025.1\",\"size\":\"3.04197\"}],\"bids\":[{\"price\":\"92885.9\",\"size\":\"0.03194\"},{\"price\":\"92879.8\",\"size\":\"0.00000\"},{\"price\":\"92866.2\",\"size\":\"0.01077\"}],\"offset\":6962157,\"nonce\":3691008379},\"timestamp\":1765394041741,\"type\":\"update/order_book\"}"
    "msg": "{\"channel\":\"order_book:1\",\"offset\":6962158,\"order_book\":{\"code\":0,\"asks\":[{\"price\":\"93022.3\",\"size\":\"0.00000\"},{\"price\":\"93032.1\",\"size\":\"7.20466\"}],\"bids\":[],\"offset\":6962158,\"nonce\":3691008380},\"timestamp\":1765394041743,\"type\":\"update/order_book\"}"
    "msg": "{\"channel\":\"order_book:1\",\"offset\":6962159,\"order_book\":{\"code\":0,\"asks\":[{\"price\":\"92930.5\",\"size\":\"0.00000\"},{\"price\":\"92932.2\",\"size\":\"0.19589\"},{\"price\":\"92935.8\",\"size\":\"0.00000\"},{\"price\":\"92979.0\",\"size\":\"0.00000\"}],\"bids\":[{\"price\":\"92892.7\",\"size\":\"4.60146\"},{\"price\":\"92885.7\",\"size\":\"6.52778\"},{\"price\":\"92883.9\",\"size\":\"0.00000\"},{\"price\":\"92878.8\",\"size\":\"15.46053\"},{\"price\":\"92876.9\",\"size\":\"0.00000\"},{\"price\":\"92863.9\",\"size\":\"2.16306\"}],\"offset\":6962159,\"nonce\":3691008381},\"timestamp\":1765394041749,\"type\":\"update/order_book\"}"
    "msg": "{\"channel\":\"order_book:1\",\"offset\":6962160,\"order_book\":{\"code\":0,\"asks\":[{\"price\":\"92933.0\",\"size\":\"0.16024\"}],\"bids\":[{\"price\":\"92892.1\",\"size\":\"0.00108\"},{\"price\":\"92887.1\",\"size\":\"0.00000\"},{\"price\":\"92711.9\",\"size\":\"0.78383\"}],\"offset\":6962160,\"nonce\":3691008383},\"timestamp\":1765394041750,\"type\":\"update/order_book\"}"
    "msg": "{\"channel\":\"order_book:1\",\"offset\":6962161,\"order_book\":{\"code\":0,\"asks\":[{\"price\":\"92930.6\",\"size\":\"0.00000\"}],\"bids\":[{\"price\":\"92895.1\",\"size\":\"0.00000\"},{\"price\":\"92773.4\",\"size\":\"0.00269\"},{\"price\":\"92738.8\",\"size\":\"0.00000\"}],\"offset\":6962161,\"nonce\":3691008385},\"timestamp\":1765394041759,\"type\":\"update/order_book\"}"
    "msg": "{\"channel\":\"order_book:1\",\"offset\":6962163,\"order_book\":{\"code\":0,\"asks\":[],\"bids\":[{\"price\":\"92897.6\",\"size\":\"4.60201\"},{\"price\":\"92892.7\",\"size\":\"0.00000\"},{\"price\":\"92609.0\",\"size\":\"0.00000\"}],\"offset\":6962163,\"nonce\":3691008388},\"timestamp\":1765394041766,\"type\":\"update/order_book\"}"
    "msg": "{\"channel\":\"order_book:1\",\"offset\":6962164,\"order_book\":{\"code\":0,\"asks\":[{\"price\":\"92922.4\",\"size\":\"0.05238\"},{\"price\":\"92971.2\",\"size\":\"0.00000\"},{\"price\":\"93010.9\",\"size\":\"0.00269\"},{\"price\":\"93018.0\",\"size\":\"2.29483\"},{\"price\":\"93018.1\",\"size\":\"0.00000\"}],\"bids\":[{\"price\":\"92903.1\",\"size\":\"0.00000\"},{\"price\":\"92866.2\",\"size\":\"0.00000\"}],\"offset\":6962164,\"nonce\":3691008389},\"timestamp\":1765394041771,\"type\":\"update/order_book\"}"
    "msg": "{\"channel\":\"order_book:1\",\"offset\":6962165,\"order_book\":{\"code\":0,\"asks\":[],\"bids\":[{\"price\":\"92867.5\",\"size\":\"0.01077\"}],\"offset\":6962165,\"nonce\":3691008395},\"timestamp\":1765394041778,\"type\":\"update/order_book\"}"
    "msg": "{\"channel\":\"order_book:1\",\"offset\":6962166,\"order_book\":{\"code\":0,\"asks\":[{\"price\":\"92935.5\",\"size\":\"0.00000\"},{\"price\":\"93001.8\",\"size\":\"1.02411\"}],\"bids\":[{\"price\":\"92886.0\",\"size\":\"0.03338\"},{\"price\":\"92877.5\",\"size\":\"0.01000\"},{\"price\":\"92851.7\",\"size\":\"0.00000\"}],\"offset\":6962166,\"nonce\":3691008397},\"timestamp\":1765394041781,\"type\":\"update/order_book\"}"
    "msg": "{\"channel\":\"order_book:1\",\"offset\":6962167,\"order_book\":{\"code\":0,\"asks\":[{\"price\":\"92928.2\",\"size\":\"0.00000\"}],\"bids\":[],\"offset\":6962167,\"nonce\":3691008398},\"timestamp\":1765394041788,\"type\":\"update/order_book\"}"
    "msg": "{\"channel\":\"order_book:1\",\"offset\":6962168,\"order_book\":{\"code\":0,\"asks\":[{\"price\":\"92939.0\",\"size\":\"0.05549\"}],\"bids\":[{\"price\":\"92917.6\",\"size\":\"4.17201\"},{\"price\":\"92916.7\",\"size\":\"0.37716\"},{\"price\":\"92913.9\",\"size\":\"0.49547\"},{\"price\":\"92905.0\",\"size\":\"0.00000\"}],\"offset\":6962168,\"nonce\":3691008399},\"timestamp\":1765394041793,\"type\":\"update/order_book\"}"
    "msg": "{\"channel\":\"order_book:1\",\"offset\":6962169,\"order_book\":{\"code\":0,\"asks\":[],\"bids\":[{\"price\":\"92919.4\",\"size\":\"0.25756\"},{\"price\":\"92917.6\",\"size\":\"3.23203\"}],\"offset\":6962169,\"nonce\":3691008400},\"timestamp\":1765394041797,\"type\":\"update/order_book\"}"
    "msg": "{\"channel\":\"order_book:1\",\"offset\":6962170,\"order_book\":{\"code\":0,\"asks\":[{\"price\":\"92922.4\",\"size\":\"0.04982\"}],\"bids\":[{\"price\":\"92916.7\",\"size\":\"0.00000\"},{\"price\":\"92912.4\",\"size\":\"0.03765\"},{\"price\":\"92904.0\",\"size\":\"0.00000\"},{\"price\":\"92897.3\",\"size\":\"0.00000\"}],\"offset\":6962170,\"nonce\":3691008401},\"timestamp\":1765394041807,\"type\":\"update/order_book\"}"
    "msg": "{\"channel\":\"order_book:1\",\"offset\":6962171,\"order_book\":{\"code\":0,\"asks\":[{\"price\":\"92922.3\",\"size\":\"0.87493\"},{\"price\":\"92922.4\",\"size\":\"0.88490\"}],\"bids\":[{\"price\":\"92899.5\",\"size\":\"0.00000\"}],\"offset\":6962171,\"nonce\":3691008402},\"timestamp\":1765394041808,\"type\":\"update/order_book\"}"
    "msg": "{\"channel\":\"order_book:1\",\"offset\":6962172,\"order_book\":{\"code\":0,\"asks\":[{\"price\":\"92931.8\",\"size\":\"0.38767\"},{\"price\":\"93018.0\",\"size\":\"0.00000\"},{\"price\":\"93022.3\",\"size\":\"2.29471\"}],\"bids\":[{\"price\":\"92919.4\",\"size\":\"0.24716\"},{\"price\":\"92913.9\",\"size\":\"0.38767\"},{\"price\":\"92906.2\",\"size\":\"0.01076\"},{\"price\":\"92899.8\",\"size\":\"4.60310\"},{\"price\":\"92897.6\",\"size\":\"0.00000\"}],\"offset\":6962172,\"nonce\":3691008404},\"timestamp\":1765394041818,\"type\":\"update/order_book\"}"
    "msg": "{\"channel\":\"order_book:1\",\"offset\":6962173,\"order_book\":{\"code\":0,\"asks\":[],\"bids\":[{\"price\":\"92919.4\",\"size\":\"0.00000\"},{\"price\":\"92914.4\",\"size\":\"0.00021\"}],\"offset\":6962173,\"nonce\":3691008405},\"timestamp\":1765394041823,\"type\":\"update/order_book\"}"
    "msg": "{\"channel\":\"order_book:1\",\"offset\":6962174,\"order_book\":{\"code\":0,\"asks\":[{\"price\":\"92930.0\",\"size\":\"0.02834\"},{\"price\":\"93112.7\",\"size\":\"0.00000\"}],\"bids\":[{\"price\":\"92911.1\",\"size\":\"0.00000\"}],\"offset\":6962174,\"nonce\":3691008407},\"timestamp\":1765394041828,\"type\":\"update/order_book\"}"
    "msg": "{\"channel\":\"order_book:1\",\"offset\":6962175,\"order_book\":{\"code\":0,\"asks\":[{\"price\":\"92922.3\",\"size\":\"0.86832\"},{\"price\":\"92932.8\",\"size\":\"0.05380\"}],\"bids\":[{\"price\":\"92901.9\",\"size\":\"4.60356\"},{\"price\":\"92899.8\",\"size\":\"0.00000\"},{\"price\":\"92897.3\",\"size\":\"0.05382\"},{\"price\":\"92842.6\",\"size\":\"0.02093\"}],\"offset\":6962175,\"nonce\":3691008408},\"timestamp\":1765394041834,\"type\":\"update/order_book\"}"
    "msg": "{\"channel\":\"order_book:1\",\"offset\":6962176,\"order_book\":{\"code\":0,\"asks\":[],\"bids\":[{\"price\":\"92896.4\",\"size\":\"0.00108\"},{\"price\":\"92892.1\",\"size\":\"0.00000\"}],\"offset\":6962176,\"nonce\":3691008412},\"timestamp\":1765394041838,\"type\":\"update/order_book\"}"
    "msg": "{\"channel\":\"order_book:1\",\"offset\":6962177,\"order_book\":{\"code\":0,\"asks\":[{\"price\":\"92922.3\",\"size\":\"0.82358\"},{\"price\":\"92922.4\",\"size\":\"0.04982\"},{\"price\":\"92978.9\",\"size\":\"1.19122\"}],\"bids\":[{\"price\":\"92891.4\",\"size\":\"0.00215\"},{\"price\":\"92877.5\",\"size\":\"0.02000\"},{\"price\":\"92804.0\",\"size\":\"0.00000\"}],\"offset\":6962177,\"nonce\":3691008413},\"timestamp\":1765394041841,\"type\":\"update/order_book\"}"
    "msg": "{\"channel\":\"order_book:1\",\"offset\":6962178,\"order_book\":{\"code\":0,\"asks\":[],\"bids\":[{\"price\":\"92906.2\",\"size\":\"0.00000\"}],\"offset\":6962178,\"nonce\":3691008415},\"timestamp\":1765394041847,\"type\":\"update/order_book\"}"
    "msg": "{\"channel\":\"order_book:1\",\"offset\":6962179,\"order_book\":{\"code\":0,\"asks\":[{\"price\":\"92927.4\",\"size\":\"0.14545\"},{\"price\":\"92932.2\",\"size\":\"0.08809\"}],\"bids\":[{\"price\":\"92917.6\",\"size\":\"4.11414\"},{\"price\":\"92867.5\",\"size\":\"0.00000\"}],\"offset\":6962179,\"nonce\":3691008416},\"timestamp\":1765394041849,\"type\":\"update/order_book\"}"
    "msg": "{\"channel\":\"order_book:1\",\"offset\":6962180,\"order_book\":{\"code\":0,\"asks\":[{\"price\":\"92922.2\",\"size\":\"0.00937\"},{\"price\":\"92931.7\",\"size\":\"0.00860\"}],\"bids\":[],\"offset\":6962180,\"nonce\":3691008418},\"timestamp\":1765394041850,\"type\":\"update/order_book\"}"
    "msg": "{\"channel\":\"order_book:1\",\"offset\":6962181,\"order_book\":{\"code\":0,\"asks\":[{\"price\":\"92922.3\",\"size\":\"0.00000\"},{\"price\":\"92922.4\",\"size\":\"0.00000\"},{\"price\":\"92928.7\",\"size\":\"0.10780\"},{\"price\":\"92933.0\",\"size\":\"0.05244\"}],\"bids\":[{\"price\":\"92899.7\",\"size\":\"3.19396\"},{\"price\":\"92834.5\",\"size\":\"0.00000\"}],\"offset\":6962181,\"nonce\":3691008420},\"timestamp\":1765394041856,\"type\":\"update/order_book\"}"
    "msg": "{\"channel\":\"order_book:1\",\"offset\":6962183,\"order_book\":{\"code\":0,\"asks\":[{\"price\":\"92922.2\",\"size\":\"0.00000\"}],\"bids\":[{\"price\":\"92917.6\",\"size\":\"3.23203\"},{\"price\":\"92913.0\",\"size\":\"0.00860\"},{\"price\":\"92908.4\",\"size\":\"0.01076\"}],\"offset\":6962183,\"nonce\":3691008423},\"timestamp\":1765394041867,\"type\":\"update/order_book\"}"
    "msg": "{\"channel\":\"order_book:1\",\"offset\":6962184,\"order_book\":{\"code\":0,\"asks\":[{\"price\":\"92924.9\",\"size\":\"0.10780\"},{\"price\":\"92930.5\",\"size\":\"0.00000\"}],\"bids\":[],\"offset\":6962184,\"nonce\":3691008425},\"timestamp\":1765394041876,\"type\":\"update/order_book\"}"
    "msg": "{\"channel\":\"order_book:1\",\"offset\":6962185,\"order_book\":{\"code\":0,\"asks\":[{\"price\":\"92922.2\",\"size\":\"0.81570\"}],\"bids\":[],\"offset\":6962185,\"nonce\":3691008428},\"timestamp\":1765394041881,\"type\":\"update/order_book\"}"
    "msg": "{\"channel\":\"order_book:1\",\"offset\":6962186,\"order_book\":{\"code\":0,\"asks\":[{\"price\":\"92930.0\",\"size\":\"0.00000\"},{\"price\":\"93048.9\",\"size\":\"0.00538\"}],\"bids\":[{\"price\":\"92803.1\",\"size\":\"0.00538\"}],\"offset\":6962186,\"nonce\":3691008429},\"timestamp\":1765394041885,\"type\":\"update/order_book\"}"
    "msg": "{\"channel\":\"order_book:1\",\"offset\":6962187,\"order_book\":{\"code\":0,\"asks\":[{\"price\":\"92922.5\",\"size\":\"0.04121\"},{\"price\":\"92940.7\",\"size\":\"0.00305\"},{\"price\":\"93139.3\",\"size\":\"0.79505\"}],\"bids\":[{\"price\":\"92916.1\",\"size\":\"0.00000\"}],\"offset\":6962187,\"nonce\":3691008431},\"timestamp\":1765394041890,\"type\":\"update/order_book\"}"
    "msg": "{\"channel\":\"order_book:1\",\"offset\":6962188,\"order_book\":{\"code\":0,\"asks\":[{\"price\":\"92927.2\",\"size\":\"0.02834\"}],\"bids\":[],\"offset\":6962188,\"nonce\":3691008436},\"timestamp\":1765394041901,\"type\":\"update/order_book\"}"
    "msg": "{\"channel\":\"order_book:1\",\"offset\":6962189,\"order_book\":{\"code\":0,\"asks\":[{\"price\":\"92928.0\",\"size\":\"0.00000\"},{\"price\":\"93005.1\",\"size\":\"8.21378\"},{\"price\":\"93060.7\",\"size\":\"8.07918\"}],\"bids\":[{\"price\":\"92909.9\",\"size\":\"0.10780\"}],\"offset\":6962189,\"nonce\":3691008437},\"timestamp\":1765394041908,\"type\":\"update/order_book\"}"
    "msg": "{\"channel\":\"order_book:1\",\"offset\":6962191,\"order_book\":{\"code\":0,\"asks\":[{\"price\":\"92944.0\",\"size\":\"0.05157\"}],\"bids\":[],\"offset\":6962191,\"nonce\":3691008439},\"timestamp\":1765394041919,\"type\":\"update/order_book\"}"
    "msg": "{\"channel\":\"order_book:1\",\"offset\":6962192,\"order_book\":{\"code\":0,\"asks\":[],\"bids\":[{\"price\":\"92913.7\",\"size\":\"0.02905\"}],\"offset\":6962192,\"nonce\":3691008442},\"timestamp\":1765394041927,\"type\":\"update/order_book\"}"
    "msg": "{\"channel\":\"order_book:1\",\"offset\":6962193,\"order_book\":{\"code\":0,\"asks\":[],\"bids\":[{\"price\":\"92910.6\",\"size\":\"0.00000\"},{\"price\":\"92909.2\",\"size\":\"0.10780\"},{\"price\":\"92894.8\",\"size\":\"0.10780\"}],\"offset\":6962193,\"nonce\":3691008444},\"timestamp\":1765394041931,\"type\":\"update/order_book\"}"
    "msg": "{\"channel\":\"order_book:1\",\"offset\":6962194,\"order_book\":{\"code\":0,\"asks\":[],\"bids\":[{\"price\":\"92867.3\",\"size\":\"0.00000\"}],\"offset\":6962194,\"nonce\":3691008445},\"timestamp\":1765394041932,\"type\":\"update/order_book\"}"
    "msg": "{\"channel\":\"order_book:1\",\"offset\":6962196,\"order_book\":{\"code\":0,\"asks\":[{\"price\":\"92923.4\",\"size\":\"1.07758\"},{\"price\":\"92926.2\",\"size\":\"0.10780\"},{\"price\":\"92927.4\",\"size\":\"0.03765\"},{\"price\":\"92934.8\",\"size\":\"0.00860\"},{\"price\":\"92944.0\",\"size\":\"0.00000\"},{\"price\":\"92986.3\",\"size\":\"0.50000\"}],\"bids\":[{\"price\":\"92912.3\",\"size\":\"0.00860\"},{\"price\":\"92833.9\",\"size\":\"0.00861\"}],\"offset\":6962196,\"nonce\":3691008447},\"timestamp\":1765394041969,\"type\":\"update/order_book\"}"
    "msg": "{\"channel\":\"order_book:1\",\"offset\":6962197,\"order_book\":{\"code\":0,\"asks\":[{\"price\":\"92922.1\",\"size\":\"0.10764\"},{\"price\":\"92927.5\",\"size\":\"0.10780\"},{\"price\":\"92928.7\",\"size\":\"0.00000\"},{\"price\":\"92946.7\",\"size\":\"0.00000\"}],\"bids\":[{\"price\":\"92860.2\",\"size\":\"0.00000\"}],\"offset\":6962197,\"nonce\":3691008448},\"timestamp\":1765394041988,\"type\":\"update/order_book\"}"
    "msg": "{\"channel\":\"order_book:1\",\"offset\":6962198,\"order_book\":{\"code\":0,\"asks\":[],\"bids\":[{\"price\":\"92917.6\",\"size\":\"3.22703\"},{\"price\":\"92914.0\",\"size\":\"0.01500\"},{\"price\":\"92877.5\",\"size\":\"0.00000\"},{\"price\":\"92843.0\",\"size\":\"0.00000\"}],\"offset\":6962198,\"nonce\":3691008449},\"timestamp\":1765394042000,\"type\":\"update/order_book\"}"
    "msg": "{\"channel\":\"order_book:1\",\"offset\":6962199,\"order_book\":{\"code\":0,\"asks\":[],\"bids\":[{\"price\":\"92917.6\",\"size\":\"4.10533\"},{\"price\":\"92891.4\",\"size\":\"0.00000\"}],\"offset\":6962199,\"nonce\":3691008450},\"timestamp\":1765394042011,\"type\":\"update/order_book\"}"
    "msg": "{\"channel\":\"order_book:1\",\"offset\":6962200,\"order_book\":{\"code\":0,\"asks\":[{\"price\":\"92922.1\",\"size\":\"0.97020\"},{\"price\":\"92922.2\",\"size\":\"0.00000\"},{\"price\":\"92946.0\",\"size\":\"0.05249\"}],\"bids\":[{\"price\":\"92917.6\",\"size\":\"4.09462\"},{\"price\":\"92913.9\",\"size\":\"0.00000\"},{\"price\":\"92892.9\",\"size\":\"1.46801\"},{\"price\":\"92869.2\",\"size\":\"0.00000\"}],\"offset\":6962200,\"nonce\":3691008451},\"timestamp\":1765394042034,\"type\":\"update/order_book\"}"
    "msg": "{\"channel\":\"order_book:1\",\"offset\":6962201,\"order_book\":{\"code\":0,\"asks\":[{\"price\":\"92940.7\",\"size\":\"0.00000\"}],\"bids\":[{\"price\":\"92870.5\",\"size\":\"0.01077\"}],\"offset\":6962201,\"nonce\":3691008452},\"timestamp\":1765394042056,\"type\":\"update/order_book\"}"
    "msg": "{\"channel\":\"order_book:1\",\"offset\":6962202,\"order_book\":{\"code\":0,\"asks\":[{\"price\":\"92923.3\",\"size\":\"0.00020\"},{\"price\":\"92947.9\",\"size\":\"0.04642\"}],\"bids\":[{\"price\":\"92870.5\",\"size\":\"0.00000\"}],\"offset\":6962202,\"nonce\":3691008453},\"timestamp\":1765394042065,\"type\":\"update/order_book\"}"
    "msg": "{\"channel\":\"order_book:1\",\"offset\":6962203,\"order_book\":{\"code\":0,\"asks\":[{\"price\":\"92924.9\",\"size\":\"0.00000\"},{\"price\":\"92926.3\",\"size\":\"0.10780\"}],\"bids\":[{\"price\":\"92917.7\",\"size\":\"0.38767\"},{\"price\":\"92914.5\",\"size\":\"0.00215\"},{\"price\":\"92910.8\",\"size\":\"0.10780\"},{\"price\":\"92909.9\",\"size\":\"0.00000\"},{\"price\":\"92866.6\",\"size\":\"5.97704\"}],\"offset\":6962203,\"nonce\":3691008454},\"timestamp\":1765394042077,\"type\":\"update/order_book\"}"
    "msg": "{\"channel\":\"order_book:1\",\"offset\":6962204,\"order_book\":{\"code\":0,\"asks\":[{\"price\":\"92922.1\",\"size\":\"0.09682\"},{\"price\":\"92922.5\",\"size\":\"0.03120\"},{\"price\":\"92927.5\",\"size\":\"0.00000\"},{\"price\":\"92928.5\",\"size\":\"0.10780\"},{\"price\":\"92930.7\",\"size\":\"0.08086\"}],\"bids\":[{\"price\":\"92910.2\",\"size\":\"0.10780\"},{\"price\":\"92909.2\",\"size\":\"0.00000\"},{\"price\":\"92905.6\",\"size\":\"0.08082\"},{\"price\":\"92896.0\",\"size\":\"0.10780\"},{\"price\":\"92894.8\",\"size\":\"0.00000\"}],\"offset\":6962204,\"nonce\":3691008455},\"timestamp\":1765394042082,\"type\":\"update/order_book\"}"
    "msg": "{\"channel\":\"order_book:1\",\"offset\":6962205,\"order_book\":{\"code\":0,\"asks\":[{\"price\":\"92926.2\",\"size\":\"0.00000\"},{\"price\":\"92927.2\",\"size\":\"0.13614\"},{\"price\":\"93013.1\",\"size\":\"0.13452\"}],\"bids\":[{\"price\":\"92917.7\",\"size\":\"1.23831\"},{\"price\":\"92915.1\",\"size\":\"0.26290\"},{\"price\":\"92912.1\",\"size\":\"0.38767\"},{\"price\":\"92911.9\",\"size\":\"0.08081\"},{\"price\":\"92910.1\",\"size\":\"0.13452\"},{\"price\":\"92902.0\",\"size\":\"0.13452\"},{\"price\":\"92893.9\",\"size\":\"0.13452\"},{\"price\":\"92885.8\",\"size\":\"0.13452\"},{\"price\":\"92877.7\",\"size\":\"0.13452\"},{\"price\":\"92871.7\",\"size\":\"0.01077\"},{\"price\":\"92852.8\",\"size\":\"0.00000\"},{\"price\":\"92844.8\",\"size\":\"0.00000\"},{\"price\":\"92829.8\",\"size\":\"0.00000\"},{\"price\":\"92818.7\",\"size\":\"0.00000\"},{\"price\":\"92810.4\",\"size\":\"0.00000\"}],\"offset\":6962205,\"nonce\":3691008456},\"timestamp\":1765394042088,\"type\":\"update/order_book\"}"
    "msg": "{\"channel\":\"order_book:1\",\"offset\":6962206,\"order_book\":{\"code\":0,\"asks\":[],\"bids\":[{\"price\":\"92917.7\",\"size\":\"1.23631\"}],\"offset\":6962206,\"nonce\":3691008457},\"timestamp\":1765394042096,\"type\":\"update/order_book\"}"
    "msg": "{\"channel\":\"order_book:1\",\"offset\":6962207,\"order_book\":{\"code\":0,\"asks\":[{\"price\":\"92922.1\",\"size\":\"0.00000\"},{\"price\":\"92923.3\",\"size\":\"0.21523\"}],\"bids\":[],\"offset\":6962207,\"nonce\":3691008458},\"timestamp\":1765394042102,\"type\":\"update/order_book\"}"
    "msg": "{\"channel\":\"order_book:1\",\"offset\":6962209,\"order_book\":{\"code\":0,\"asks\":[{\"price\":\"92927.2\",\"size\":\"0.02834\"},{\"price\":\"92928.5\",\"size\":\"0.00000\"},{\"price\":\"92932.2\",\"size\":\"0.00000\"},{\"price\":\"93017.1\",\"size\":\"0.00000\"},{\"price\":\"93249.6\",\"size\":\"0.00000\"}],\"bids\":[],\"offset\":6962209,\"nonce\":3691008461},\"timestamp\":1765394042114,\"type\":\"update/order_book\"}"
    "msg": "{\"channel\":\"order_book:1\",\"offset\":6962210,\"order_book\":{\"code\":0,\"asks\":[{\"price\":\"92923.4\",\"size\":\"0.00000\"}],\"bids\":[],\"offset\":6962210,\"nonce\":3691008463},\"timestamp\":1765394042120,\"type\":\"update/order_book\"}"
