    "msg": "{\"channel\":\"order_book:1\",\"offset\":6962763,\"order_book\":{\"code\":0,\"asks\":[{\"price\":\"92975.2\",\"size\":\"0.03515\"},{\"price\":\"92996.8\",\"size\":\"0.00000\"},{\"price\":\"93015.3\",\"size\":\"8.07918\"}],\"bids\":[{\"price\":\"92964.4\",\"size\":\"0.38767\"},{\"price\":\"92960.9\",\"size\":\"0.00000\"},{\"price\":\"92956.3\",\"size\":\"0.38767\"},{\"price\":\"92859.4\",\"size\":\"0.00000\"},{\"price\":\"92757.9\",\"size\":\"0.00000\"}],\"offset\":6962763,\"nonce\":3691009378},\"timestamp\":1765394045927,\"type\":\"update/order_book\"}"
    "msg": "{\"channel\":\"order_book:1\",\"offset\":6962764,\"order_book\":{\"code\":0,\"asks\":[{\"price\":\"92975.2\",\"size\":\"0.03432\"}],\"bids\":[{\"price\":\"92947.1\",\"size\":\"0.00000\"},{\"price\":\"92933.6\",\"size\":\"0.11629\"},{\"price\":\"87412.5\",\"size\":\"0.00000\"}],\"offset\":6962764,\"nonce\":3691009379},\"timestamp\":1765394045936,\"type\":\"update/order_book\"}"
    "msg": "{\"channel\":\"order_book:1\",\"offset\":6962766,\"order_book\":{\"code\":0,\"asks\":[],\"bids\":[{\"price\":\"92960.3\",\"size\":\"0.05811\"},{\"price\":\"92929.5\",\"size\":\"0.00000\"},{\"price\":\"92840.8\",\"size\":\"0.52008\"}],\"offset\":6962766,\"nonce\":3691009381},\"timestamp\":1765394045943,\"type\":\"update/order_book\"}"
    "msg": "{\"channel\":\"order_book:1\",\"offset\":6962767,\"order_book\":{\"code\":0,\"asks\":[],\"bids\":[{\"price\":\"92970.0\",\"size\":\"0.38767\"},{\"price\":\"92961.0\",\"size\":\"0.01075\"},{\"price\":\"92926.7\",\"size\":\"0.00000\"}],\"offset\":6962767,\"nonce\":3691009382},\"timestamp\":1765394045947,\"type\":\"update/order_book\"}"
    "msg": "{\"channel\":\"order_book:1\",\"offset\":6962768,\"order_book\":{\"code\":0,\"asks\":[{\"price\":\"92988.7\",\"size\":\"0.00000\"}],\"bids\":[{\"price\":\"92963.3\",\"size\":\"0.02151\"}],\"offset\":6962768,\"nonce\":3691009383},\"timestamp\":1765394045951,\"type\":\"update/order_book\"}"
    "msg": "{\"channel\":\"order_book:1\",\"offset\":6962769,\"order_book\":{\"code\":0,\"asks\":[{\"price\":\"92991.3\",\"size\":\"0.02828\"}],\"bids\":[{\"price\":\"92961.0\",\"size\":\"0.00000\"},{\"price\":\"92934.7\",\"size\":\"0.00000\"}],\"offset\":6962769,\"nonce\":3691009384},\"timestamp\":1765394045957,\"type\":\"update/order_book\"}"
    "msg": "{\"channel\":\"order_book:1\",\"offset\":6962770,\"order_book\":{\"code\":0,\"asks\":[{\"price\":\"92975.2\",\"size\":\"0.00000\"}],\"bids\":[],\"offset\":6962770,\"nonce\":3691009385},\"timestamp\":1765394045967,\"type\":\"update/order_book\"}"
    "msg": "{\"channel\":\"order_book:1\",\"offset\":6962771,\"order_book\":{\"code\":0,\"asks\":[{\"price\":\"92986.4\",\"size\":\"0.10760\"}],\"bids\":[{\"price\":\"92963.3\",\"size\":\"0.00000\"},{\"price\":\"92961.1\",\"size\":\"0.01075\"},{\"price\":\"92960.2\",\"size\":\"1.98282\"}],\"offset\":6962771,\"nonce\":3691009387},\"timestamp\":1765394045976,\"type\":\"update/order_book\"}"
    "msg": "{\"channel\":\"order_book:1\",\"offset\":6962772,\"order_book\":{\"code\":0,\"asks\":[{\"price\":\"92985.4\",\"size\":\"0.00000\"},{\"price\":\"92991.5\",\"size\":\"0.00000\"},{\"price\":\"93004.1\",\"size\":\"0.00000\"},{\"price\":\"93170.6\",\"size\":\"2.15933\"}],\"bids\":[],\"offset\":6962772,\"nonce\":3691009388},\"timestamp\":1765394045981,\"type\":\"update/order_book\"}"
    "msg": "{\"channel\":\"order_book:1\",\"offset\":6962773,\"order_book\":{\"code\":0,\"asks\":[{\"price\":\"93002.1\",\"size\":\"0.00213\"},{\"price\":\"93016.1\",\"size\":\"0.00000\"}],\"bids\":[{\"price\":\"92971.1\",\"size\":\"1.07758\"},{\"price\":\"92960.2\",\"size\":\"1.96282\"},{\"price\":\"92939.3\",\"size\":\"0.00214\"}],\"offset\":6962773,\"nonce\":3691009389},\"timestamp\":1765394045985,\"type\":\"update/order_book\"}"
    "msg": "{\"channel\":\"order_book:1\",\"offset\":6962774,\"order_book\":{\"code\":0,\"asks\":[{\"price\":\"92990.9\",\"size\":\"0.00500\"},{\"price\":\"93009.4\",\"size\":\"0.00000\"},{\"price\":\"93016.4\",\"size\":\"0.00000\"},{\"price\":\"93018.3\",\"size\":\"2.29206\"},{\"price\":\"93023.3\",\"size\":\"0.00000\"},{\"price\":\"93025.3\",\"size\":\"3.03832\"},{\"price\":\"93032.2\",\"size\":\"7.19601\"}],\"bids\":[{\"price\":\"92960.2\",\"size\":\"1.95282\"},{\"price\":\"92947.8\",\"size\":\"0.00500\"},{\"price\":\"92928.1\",\"size\":\"0.00000\"},{\"price\":\"92926.9\",\"size\":\"0.01076\"},{\"price\":\"92878.2\",\"size\":\"0.00538\"},{\"price\":\"92857.5\",\"size\":\"0.00000\"}],\"offset\":6962774,\"nonce\":3691009390},\"timestamp\":1765394045988,\"type\":\"update/order_book\"}"
    "msg": "{\"channel\":\"order_book:1\",\"offset\":6962775,\"order_book\":{\"code\":0,\"asks\":[{\"price\":\"92979.4\",\"size\":\"0.00000\"},{\"price\":\"92981.6\",\"size\":\"1.07758\"},{\"price\":\"93002.3\",\"size\":\"0.00213\"},{\"price\":\"93053.3\",\"size\":\"0.11088\"}],\"bids\":[{\"price\":\"92963.8\",\"size\":\"0.11088\"},{\"price\":\"92963.4\",\"size\":\"0.02151\"},{\"price\":\"92960.3\",\"size\":\"0.16571\"},{\"price\":\"92958.1\",\"size\":\"0.23209\"},{\"price\":\"92947.5\",\"size\":\"4.69380\"},{\"price\":\"92940.5\",\"size\":\"6.52393\"},{\"price\":\"92939.5\",\"size\":\"0.00214\"},{\"price\":\"92935.9\",\"size\":\"0.00000\"},{\"price\":\"92928.9\",\"size\":\"0.00000\"}],\"offset\":6962775,\"nonce\":3691009392},\"timestamp\":1765394045993,\"type\":\"update/order_book\"}"
    "msg": "{\"channel\":\"order_book:1\",\"offset\":6962776,\"order_book\":{\"code\":0,\"asks\":[],\"bids\":[{\"price\":\"92960.2\",\"size\":\"1.94782\"},{\"price\":\"92942.5\",\"size\":\"0.00108\"},{\"price\":\"92933.5\",\"size\":\"15.45142\"},{\"price\":\"92930.9\",\"size\":\"0.00000\"},{\"price\":\"92921.9\",\"size\":\"0.00000\"}],\"offset\":6962776,\"nonce\":3691009393},\"timestamp\":1765394046001,\"type\":\"update/order_book\"}"
    "msg": "{\"channel\":\"order_book:1\",\"offset\":6962777,\"order_book\":{\"code\":0,\"asks\":[{\"price\":\"92985.6\",\"size\":\"2.69396\"},{\"price\":\"92995.3\",\"size\":\"0.00000\"},{\"price\":\"93016.2\",\"size\":\"0.00538\"}],\"bids\":[{\"price\":\"92963.4\",\"size\":\"0.00000\"},{\"price\":\"92953.4\",\"size\":\"0.10760\"},{\"price\":\"92946.2\",\"size\":\"0.00000\"},{\"price\":\"92912.5\",\"size\":\"0.00000\"}],\"offset\":6962777,\"nonce\":3691009394},\"timestamp\":1765394046005,\"type\":\"update/order_book\"}"
    "msg": "{\"channel\":\"order_book:1\",\"offset\":6962778,\"order_book\":{\"code\":0,\"asks\":[{\"price\":\"92986.9\",\"size\":\"0.38767\"}],\"bids\":[],\"offset\":6962778,\"nonce\":3691009395},\"timestamp\":1765394046013,\"type\":\"update/order_book\"}"
    "msg": "{\"channel\":\"order_book:1\",\"offset\":6962779,\"order_book\":{\"code\":0,\"asks\":[{\"price\":\"92978.2\",\"size\":\"0.02834\"},{\"price\":\"92983.4\",\"size\":\"0.10760\"}],\"bids\":[],\"offset\":6962779,\"nonce\":3691009396},\"timestamp\":1765394046019,\"type\":\"update/order_book\"}"
    "msg": "{\"channel\":\"order_book:1\",\"offset\":6962780,\"order_book\":{\"code\":0,\"asks\":[{\"price\":\"92978.2\",\"size\":\"0.00000\"},{\"price\":\"92985.8\",\"size\":\"0.00860\"},{\"price\":\"93006.4\",\"size\":\"0.00021\"}],\"bids\":[{\"price\":\"92963.1\",\"size\":\"0.02151\"},{\"price\":\"92937.7\",\"size\":\"0.00000\"}],\"offset\":6962780,\"nonce\":3691009397},\"timestamp\":1765394046024,\"type\":\"update/order_book\"}"
    "msg": "{\"channel\":\"order_book:1\",\"offset\":6962781,\"order_book\":{\"code\":0,\"asks\":[{\"price\":\"92980.7\",\"size\":\"0.00000\"},{\"price\":\"93006.5\",\"size\":\"0.00000\"},{\"price\":\"93037.6\",\"size\":\"0.31905\"},{\"price\":\"93037.7\",\"size\":\"0.11731\"}],\"bids\":[{\"price\":\"92949.8\",\"size\":\"0.02815\"},{\"price\":\"92935.5\",\"size\":\"0.00000\"}],\"offset\":6962781,\"nonce\":3691009398},\"timestamp\":1765394046030,\"type\":\"update/order_book\"}"
    "msg": "{\"channel\":\"order_book:1\",\"offset\":6962783,\"order_book\":{\"code\":0,\"asks\":[{\"price\":\"93005.9\",\"size\":\"0.60443\"}],\"bids\":[],\"offset\":6962783,\"nonce\":3691009400},\"timestamp\":1765394046035,\"type\":\"update/order_book\"}"
    "msg": "{\"channel\":\"order_book:1\",\"offset\":6962784,\"order_book\":{\"code\":0,\"asks\":[],\"bids\":[{\"price\":\"92967.3\",\"size\":\"0.79150\"},{\"price\":\"92967.2\",\"size\":\"1.24686\"},{\"price\":\"92964.7\",\"size\":\"0.01613\"},{\"price\":\"92964.5\",\"size\":\"0.13660\"},{\"price\":\"92960.3\",\"size\":\"1.00881\"},{\"price\":\"92957.4\",\"size\":\"2.69396\"},{\"price\":\"92877.7\",\"size\":\"0.00000\"}],\"offset\":6962784,\"nonce\":3691009401},\"timestamp\":1765394046039,\"type\":\"update/order_book\"}"
    "msg": "{\"channel\":\"order_book:1\",\"offset\":6962785,\"order_book\":{\"code\":0,\"asks\":[{\"price\":\"93000.9\",\"size\":\"0.11088\"},{\"price\":\"93020.3\",\"size\":\"0.00000\"},{\"price\":\"93049.5\",\"size\":\"0.31904\"}],\"bids\":[{\"price\":\"92963.1\",\"size\":\"0.00000\"},{\"price\":\"92885.5\",\"size\":\"0.31904\"},{\"price\":\"92853.9\",\"size\":\"0.00000\"},{\"price\":\"92792.8\",\"size\":\"0.00000\"}],\"offset\":6962785,\"nonce\":3691009402},\"timestamp\":1765394046044,\"type\":\"update/order_book\"}"
    "msg": "{\"channel\":\"order_book:1\",\"offset\":6962786,\"order_book\":{\"code\":0,\"asks\":[],\"bids\":[{\"price\":\"92970.1\",\"size\":\"0.79485\"},{\"price\":\"92964.7\",\"size\":\"0.00000\"}],\"offset\":6962786,\"nonce\":3691009403},\"timestamp\":1765394046050,\"type\":\"update/order_book\"}"
